File: V_7/NatR/RDSO NatR Tensile 50.is_tens_RawData/Specimen_RawData_2.csv
Time,Extension,Load,Tensile strain,Tensile stress,Corrected Position
(sec),(mm),(N),(mm/mm),(MPa),(mm)
0.00000,0.00000,0.01078,0.00000,0.00120,0.00000
0.06000,0.03162,0.15618,0.00027,0.01735,0.03162
0.12000,0.09569,0.47190,0.00083,0.05243,0.09569
0.18000,0.14769,0.53925,0.00128,0.05992,0.14769
0.24000,0.19881,0.79481,0.00173,0.08831,0.19881
0.30000,0.24944,1.05310,0.00217,0.11701,0.24944
0.36000,0.29975,0.96669,0.00261,0.10741,0.29975
0.42000,0.34981,1.26869,0.00304,0.14097,0.34981
0.48000,0.39981,1.46264,0.00348,0.16252,0.39981
0.54000,0.44987,1.67838,0.00391,0.18649,0.44987
0.60000,0.49987,1.72787,0.00435,0.19199,0.49987
0.66000,0.55000,1.88107,0.00478,0.20901,0.55000
0.72000,0.59994,2.07073,0.00522,0.23008,0.59994
0.78000,0.64994,2.16798,0.00565,0.24089,0.64994
0.84000,0.70000,2.04726,0.00609,0.22747,0.70000
0.90000,0.74994,2.34944,0.00652,0.26105,0.74994
0.96000,0.80000,2.50341,0.00696,0.27816,0.80000
1.02000,0.85000,2.77926,0.00739,0.30881,0.85000
1.08000,0.90000,2.65379,0.00783,0.29487,0.90000
1.14000,0.95000,2.83382,0.00826,0.31487,0.95000
1.20000,0.99994,3.17513,0.00870,0.35279,0.99994
1.26000,1.05000,3.10626,0.00913,0.34514,1.05000
1.32000,1.10000,3.25999,0.00957,0.36222,1.10000
1.38000,1.15000,3.47081,0.01000,0.38565,1.15000
1.44000,1.19994,3.50618,0.01043,0.38958,1.19994
1.50000,1.24994,3.52587,0.01087,0.39176,1.24994
1.56000,1.29994,3.40904,0.01130,0.37878,1.29994
1.62000,1.34994,3.54857,0.01174,0.39429,1.34994
1.68000,1.39994,3.68761,0.01217,0.40973,1.39994
1.74000,1.45000,3.71575,0.01261,0.41286,1.45000
1.80000,1.50006,3.90648,0.01304,0.43405,1.50006
1.86000,1.55006,4.04782,0.01348,0.44976,1.55006
1.92000,1.60006,3.89534,0.01391,0.43282,1.60006
1.98000,1.65000,4.06602,0.01435,0.45178,1.65000
2.04000,1.70000,4.13952,0.01478,0.45995,1.70000
2.10000,1.75000,4.25323,0.01522,0.47258,1.75000
2.16000,1.80006,4.33180,0.01565,0.48131,1.80006
2.22000,1.85000,4.28605,0.01609,0.47623,1.85000
2.28000,1.90006,4.39401,0.01652,0.48822,1.90006
2.34000,1.95000,4.63710,0.01696,0.51523,1.95000
2.40000,1.99987,4.68381,0.01739,0.52042,1.99987
2.46000,2.04994,4.46838,0.01783,0.49649,2.04994
2.52000,2.10000,4.93036,0.01826,0.54782,2.10000
2.58000,2.15000,4.97662,0.01870,0.55296,2.15000
2.64000,2.19994,4.95774,0.01913,0.55086,2.19994
2.70000,2.24994,5.25404,0.01956,0.58378,2.24994
2.76000,2.30000,5.14199,0.02000,0.57133,2.30000
2.82000,2.35000,5.16648,0.02043,0.57405,2.35000
2.88000,2.40006,5.33155,0.02087,0.59239,2.40006
2.94000,2.45000,5.49865,0.02130,0.61096,2.45000
3.00000,2.50000,5.50872,0.02174,0.61208,2.50000
3.06000,2.55000,5.52437,0.02217,0.61382,2.55000
3.12000,2.60006,5.49809,0.02261,0.61090,2.60006
3.18000,2.65012,5.63612,0.02304,0.62624,2.65012
3.24000,2.70000,5.72289,0.02348,0.63588,2.70000
3.30000,2.75000,6.09161,0.02391,0.67685,2.75000
3.36000,2.80006,6.19097,0.02435,0.68789,2.80006
3.42000,2.85000,6.03454,0.02478,0.67050,2.85000
3.48000,2.90000,6.14897,0.02522,0.68322,2.90000
3.54000,2.94994,6.26150,0.02565,0.69572,2.94994
3.60000,2.99994,6.28634,0.02609,0.69848,2.99994
3.66000,3.05000,6.53277,0.02652,0.72586,3.05000
3.72000,3.10000,6.29246,0.02696,0.69916,3.10000
3.78000,3.15006,6.45871,0.02739,0.71763,3.15006
3.84000,3.20000,6.79943,0.02783,0.75549,3.20000
3.90000,3.24994,6.58378,0.02826,0.73153,3.24994
3.96000,3.29994,6.73558,0.02870,0.74840,3.29994
4.02000,3.35000,6.79267,0.02913,0.75474,3.35000
4.08000,3.40006,6.83910,0.02957,0.75990,3.40006
4.14000,3.45006,7.07397,0.03000,0.78600,3.45006
4.20000,3.50000,7.01600,0.03043,0.77956,3.50000
4.26000,3.55000,7.09766,0.03087,0.78863,3.55000
4.32000,3.60000,7.34166,0.03130,0.81574,3.60000
4.38000,3.65006,7.40130,0.03174,0.82237,3.65006
4.44000,3.70000,7.45013,0.03217,0.82779,3.70000
4.50000,3.75000,7.52637,0.03261,0.83626,3.75000
4.56000,3.80000,7.55515,0.03304,0.83946,3.80000
4.62000,3.84994,7.48716,0.03348,0.83191,3.84994
4.68000,3.90006,7.85595,0.03391,0.87288,3.90006
4.74000,3.94994,7.68023,0.03435,0.85336,3.94994
4.80000,3.99994,7.92183,0.03478,0.88020,3.99994
4.86000,4.05000,8.04220,0.03522,0.89358,4.05000
4.92000,4.10000,7.92465,0.03565,0.88052,4.10000
4.98000,4.15000,8.07098,0.03609,0.89678,4.15000
5.04000,4.19994,8.09222,0.03652,0.89914,4.19994
5.10000,4.24994,8.05173,0.03696,0.89464,4.24994
5.16000,4.29994,8.30304,0.03739,0.92256,4.29994
5.22000,4.35006,8.36081,0.03783,0.92898,4.35006
5.28000,4.40006,8.46639,0.03826,0.94071,4.40006
5.34000,4.45006,8.52272,0.03870,0.94697,4.45006
5.40000,4.50000,8.70045,0.03913,0.96672,4.50000
5.46000,4.55000,8.56818,0.03957,0.95202,4.55000
5.52000,4.60000,8.56080,0.04000,0.95120,4.60000
5.58000,4.65006,8.81654,0.04044,0.97962,4.65006
5.64000,4.70000,8.76859,0.04087,0.97429,4.70000
5.70000,4.75000,8.80733,0.04130,0.97859,4.75000
5.76000,4.80000,8.85193,0.04174,0.98355,4.80000
5.82000,4.84994,8.90520,0.04217,0.98947,4.84994
5.88000,4.90000,9.03681,0.04261,1.00409,4.90000
5.94000,4.94994,9.15396,0.04304,1.01711,4.94994
6.00000,5.00000,9.24362,0.04348,1.02707,5.00000
6.06000,5.05006,9.36840,0.04391,1.04093,5.05006
6.12000,5.10006,9.16899,0.04435,1.01878,5.10006
6.18000,5.15000,9.38586,0.04478,1.04287,5.15000
6.24000,5.19994,9.55458,0.04522,1.06162,5.19994
6.30000,5.25000,9.71012,0.04565,1.07890,5.25000
6.36000,5.30006,9.81316,0.04609,1.09035,5.30006
6.42000,5.35006,9.78326,0.04652,1.08703,5.35006
6.48000,5.40006,9.56788,0.04696,1.06310,5.40006
6.54000,5.45000,9.92207,0.04739,1.10245,5.45000
6.60000,5.50000,10.08773,0.04783,1.12086,5.50000
6.66000,5.55000,10.00801,0.04826,1.11200,5.55000
6.72000,5.60006,10.06192,0.04870,1.11799,5.60006
6.78000,5.65006,10.10078,0.04913,1.12231,5.65006
6.84000,5.70000,10.07139,0.04957,1.11904,5.70000
6.90000,5.74994,10.24888,0.05000,1.13876,5.74994
6.96000,5.79987,10.20443,0.05043,1.13383,5.79987
7.02000,5.84994,10.27641,0.05087,1.14182,5.84994
7.08000,5.90006,10.56893,0.05130,1.17433,5.90006
7.14000,5.95000,10.44657,0.05174,1.16073,5.95000
7.20000,5.99994,10.56425,0.05217,1.17381,5.99994
7.26000,6.05000,10.76354,0.05261,1.19595,6.05000
7.32000,6.10006,10.48902,0.05304,1.16545,6.10006
7.38000,6.15000,10.49465,0.05348,1.16607,6.15000
7.44000,6.20006,10.65727,0.05391,1.18414,6.20006
7.50000,6.25000,10.77101,0.05435,1.19678,6.25000
7.56000,6.30006,10.73334,0.05478,1.19259,6.30006
7.62000,6.35006,11.03852,0.05522,1.22650,6.35006
7.68000,6.40006,10.91862,0.05565,1.21318,6.40006
7.74000,6.44994,11.08890,0.05609,1.23210,6.44994
7.80000,6.49994,11.09035,0.05652,1.23226,6.49994
7.86000,6.55000,11.08621,0.05696,1.23180,6.55000
7.92000,6.60000,11.28233,0.05739,1.25359,6.60000
7.98000,6.65012,11.32140,0.05783,1.25793,6.65012
8.04000,6.70000,11.31863,0.05826,1.25763,6.70000
8.10000,6.74981,11.39232,0.05869,1.26581,6.74981
8.16000,6.79994,11.59832,0.05913,1.28870,6.79994
8.22000,6.85000,11.43670,0.05957,1.27074,6.85000
8.28000,6.90006,11.42962,0.06000,1.26996,6.90006
8.34000,6.95000,11.59119,0.06043,1.28791,6.95000
8.40000,7.00000,11.63657,0.06087,1.29295,7.00000
8.46000,7.05000,11.72881,0.06130,1.30320,7.05000
8.52000,7.10000,11.76880,0.06174,1.30764,7.10000
8.58000,7.15006,11.94986,0.06217,1.32776,7.15006
8.64000,7.20000,12.00808,0.06261,1.33423,7.20000
8.70000,7.25006,11.94061,0.06304,1.32673,7.25006
8.76000,7.30000,12.02434,0.06348,1.33604,7.30000
8.82000,7.35000,12.17526,0.06391,1.35281,7.35000
8.88000,7.40006,12.42947,0.06435,1.38105,7.40006
8.94000,7.44994,12.21452,0.06478,1.35717,7.44994
9.00000,7.49987,12.48485,0.06522,1.38721,7.49987
9.06000,7.55000,12.12632,0.06565,1.34737,7.55000
9.12000,7.60000,12.24819,0.06609,1.36091,7.60000
9.18000,7.65000,12.31324,0.06652,1.36814,7.65000
9.24000,7.70000,12.57495,0.06696,1.39722,7.70000
9.30000,7.74994,12.33991,0.06739,1.37110,7.74994
9.36000,7.80000,12.71631,0.06783,1.41292,7.80000
9.42000,7.85006,12.69293,0.06826,1.41033,7.85006
9.48000,7.90006,12.78205,0.06870,1.42023,7.90006
9.54000,7.95000,12.64551,0.06913,1.40506,7.95000
9.60000,8.00000,12.88562,0.06957,1.43174,8.00000
9.66000,8.04994,12.73128,0.07000,1.41459,8.04994
9.72000,8.10000,13.17440,0.07043,1.46382,8.10000
9.78000,8.15006,13.11305,0.07087,1.45701,8.15006
9.84000,8.20006,13.14403,0.07130,1.46045,8.20006
9.90000,8.25000,13.06365,0.07174,1.45152,8.25000
9.96000,8.30000,13.01719,0.07217,1.44635,8.30000
10.02000,8.34994,13.26504,0.07261,1.47389,8.34994
10.08000,8.40000,13.18130,0.07304,1.46459,8.40000
10.14000,8.44994,13.21985,0.07348,1.46887,8.44994
10.20000,8.49994,13.45700,0.07391,1.49522,8.49994
10.26000,8.54994,13.53202,0.07435,1.50356,8.54994
10.32000,8.59994,13.37319,0.07478,1.48591,8.59994
10.38000,8.65006,13.61987,0.07522,1.51332,8.65006
10.44000,8.70000,13.60030,0.07565,1.51114,8.70000
10.50000,8.75000,13.63515,0.07609,1.51502,8.75000
10.56000,8.80000,13.59138,0.07652,1.51015,8.80000
10.62000,8.85006,13.80328,0.07696,1.53370,8.85006
10.68000,8.90012,13.63877,0.07739,1.51542,8.90012
10.74000,8.95006,13.74592,0.07783,1.52732,8.95006
10.80000,9.00000,13.77078,0.07826,1.53009,9.00000
10.86000,9.05000,13.96071,0.07870,1.55119,9.05000
10.92000,9.10000,13.84761,0.07913,1.53862,9.10000
10.98000,9.15006,13.94112,0.07957,1.54901,9.15006
11.04000,9.20000,14.28093,0.08000,1.58677,9.20000
11.10000,9.24994,14.01564,0.08043,1.55729,9.24994
11.16000,9.29994,14.19879,0.08087,1.57764,9.29994
11.22000,9.35000,14.44715,0.08130,1.60524,9.35000
11.28000,9.40006,14.33329,0.08174,1.59259,9.40006
11.34000,9.45000,14.29504,0.08217,1.58834,9.45000
11.40000,9.50000,14.39538,0.08261,1.59949,9.50000
11.46000,9.55000,14.55638,0.08304,1.61738,9.55000
11.52000,9.59994,14.41886,0.08348,1.60210,9.59994
11.58000,9.65000,14.50495,0.08391,1.61166,9.65000
11.64000,9.70000,14.45320,0.08435,1.60591,9.70000
11.70000,9.75000,14.60879,0.08478,1.62320,9.75000
11.76000,9.80006,14.52006,0.08522,1.61334,9.80006
11.82000,9.85012,14.54017,0.08565,1.61557,9.85012
11.88000,9.90006,14.76735,0.08609,1.64082,9.90006
11.94000,9.94994,14.70105,0.08652,1.63345,9.94994
12.00000,10.00000,14.62427,0.08696,1.62492,10.00000
12.06000,10.05000,14.80193,0.08739,1.64466,10.05000
12.12000,10.10000,14.85637,0.08783,1.65071,10.10000
12.18000,10.15000,15.04442,0.08826,1.67160,10.15000
12.24000,10.19994,14.98578,0.08870,1.66509,10.19994
12.30000,10.25000,15.03070,0.08913,1.67008,10.25000
12.36000,10.29994,15.03442,0.08956,1.67049,10.29994
12.42000,10.34994,15.36677,0.09000,1.70742,10.34994
12.48000,10.40006,15.23177,0.09044,1.69242,10.40006
12.54000,10.44994,15.27294,0.09087,1.69699,10.44994
12.60000,10.49994,15.28024,0.09130,1.69780,10.49994
12.66000,10.54994,15.28590,0.09174,1.69843,10.54994
12.72000,10.60000,15.36270,0.09217,1.70697,10.60000
12.78000,10.65006,15.57575,0.09261,1.73064,10.65006
12.84000,10.70006,15.64070,0.09304,1.73786,10.70006
12.90000,10.75000,15.51639,0.09348,1.72404,10.75000
12.96000,10.80000,15.72089,0.09391,1.74677,10.80000
13.02000,10.85006,15.58748,0.09435,1.73194,10.85006
13.08000,10.90000,15.54325,0.09478,1.72703,10.90000
13.14000,10.94994,15.71427,0.09522,1.74603,10.94994
13.20000,11.00000,15.67531,0.09565,1.74170,11.00000
13.26000,11.05000,15.51342,0.09609,1.72371,11.05000
13.32000,11.10000,15.87459,0.09652,1.76384,11.10000
13.38000,11.15000,15.84751,0.09696,1.76083,11.15000
13.44000,11.19994,16.08066,0.09739,1.78674,11.19994
13.50000,11.24994,15.75611,0.09783,1.75068,11.24994
13.56000,11.29994,15.81670,0.09826,1.75741,11.29994
13.62000,11.35000,15.77905,0.09870,1.75323,11.35000
13.68000,11.40012,15.94483,0.09913,1.77165,11.40012
13.74000,11.45006,16.37416,0.09957,1.81935,11.45006
13.80000,11.49994,16.15646,0.10000,1.79516,11.49994
13.86000,11.55000,16.24921,0.10043,1.80547,11.55000
13.92000,11.60006,16.32927,0.10087,1.81436,11.60006
13.98000,11.65006,16.28521,0.10130,1.80947,11.65006
14.04000,11.70000,16.38678,0.10174,1.82075,11.70000
14.10000,11.75000,16.27181,0.10217,1.80798,11.75000
14.16000,11.80000,16.22886,0.10261,1.80321,11.80000
14.22000,11.85000,16.31272,0.10304,1.81252,11.85000
14.28000,11.90006,16.57773,0.10348,1.84197,11.90006
14.34000,11.95000,16.58853,0.10391,1.84317,11.95000
14.40000,12.00000,16.58758,0.10435,1.84306,12.00000
14.46000,12.04994,16.65319,0.10478,1.85035,12.04994
14.52000,12.09993,16.71738,0.10522,1.85749,12.09993
14.58000,12.15006,16.67616,0.10565,1.85291,12.15006
14.64000,12.20000,16.87310,0.10609,1.87479,12.20000
14.70000,12.24994,16.71163,0.10652,1.85685,12.24994
14.76000,12.30006,16.85923,0.10696,1.87325,12.30006
14.82000,12.35006,16.84927,0.10739,1.87214,12.35006
14.88000,12.40006,17.05913,0.10783,1.89546,12.40006
14.94000,12.45000,16.81525,0.10826,1.86836,12.45000
15.00000,12.49994,16.96104,0.10870,1.88456,12.49994
15.06000,12.55000,16.96763,0.10913,1.88529,12.55000
15.12000,12.60006,17.16640,0.10957,1.90738,12.60006
15.18000,12.65006,17.09237,0.11000,1.89915,12.65006
15.24000,12.70000,17.10770,0.11043,1.90086,12.70000
15.30000,12.74994,17.16486,0.11087,1.90721,12.74994
15.36000,12.79994,17.10060,0.11130,1.90007,12.79994
15.42000,12.84994,17.21903,0.11174,1.91323,12.84994
15.48000,12.90000,17.25771,0.11217,1.91752,12.90000
15.54000,12.95000,17.35868,0.11261,1.92874,12.95000
15.60000,13.00000,17.25822,0.11304,1.91758,13.00000
15.66000,13.05000,17.39917,0.11348,1.93324,13.05000
15.72000,13.10000,17.32283,0.11391,1.92476,13.10000
15.78000,13.15000,17.43872,0.11435,1.93764,13.15000
15.84000,13.20000,17.62473,0.11478,1.95830,13.20000
15.90000,13.25000,17.42927,0.11522,1.93659,13.25000
15.96000,13.30000,17.65507,0.11565,1.96167,13.30000
16.02000,13.35006,17.67090,0.11609,1.96343,13.35006
16.08000,13.40000,17.79707,0.11652,1.97745,13.40000
16.14000,13.45000,17.71434,0.11696,1.96826,13.45000
16.20000,13.50000,17.57180,0.11739,1.95242,13.50000
16.26000,13.55006,17.78218,0.11783,1.97580,13.55006
16.32000,13.60000,17.76516,0.11826,1.97391,13.60000
16.38000,13.65006,17.81162,0.11870,1.97907,13.65006
16.44000,13.70000,17.81194,0.11913,1.97910,13.70000
16.50000,13.74993,17.79583,0.11956,1.97731,13.74993
16.56000,13.79994,17.87770,0.12000,1.98641,13.79994
16.62000,13.85000,17.92492,0.12043,1.99166,13.85000
16.68000,13.90000,18.08712,0.12087,2.00968,13.90000
16.74000,13.95000,18.21991,0.12130,2.02444,13.95000
16.80000,14.00000,18.11686,0.12174,2.01298,14.00000
16.86000,14.05000,18.19537,0.12217,2.02171,14.05000
16.92000,14.09994,18.03667,0.12261,2.00407,14.09994
16.98000,14.15006,18.17362,0.12304,2.01929,14.15006
17.04000,14.20000,18.22770,0.12348,2.02530,14.20000
17.10000,14.25000,18.15291,0.12391,2.01699,14.25000
17.16000,14.30006,18.35738,0.12435,2.03971,14.30006
17.22000,14.35000,18.30894,0.12478,2.03433,14.35000
17.28000,14.40006,18.23650,0.12522,2.02628,14.40006
17.34000,14.45000,18.50930,0.12565,2.05659,14.45000
17.40000,14.49994,18.42299,0.12609,2.04700,14.49994
17.46000,14.55000,18.42530,0.12652,2.04726,14.55000
17.52000,14.60006,18.56982,0.12696,2.06331,14.60006
17.58000,14.65006,18.57136,0.12739,2.06348,14.65006
17.64000,14.69987,18.45929,0.12782,2.05103,14.69987
17.70000,14.74987,18.55304,0.12826,2.06145,14.74987
17.76000,14.80000,18.68956,0.12870,2.07662,14.80000
17.82000,14.85000,18.62710,0.12913,2.06968,14.85000
17.88000,14.90006,18.69093,0.12957,2.07677,14.90006
17.94000,14.94994,18.69516,0.13000,2.07724,14.94994
18.00000,14.99994,19.03811,0.13043,2.11535,14.99994
18.06000,15.05000,18.70614,0.13087,2.07846,15.05000
18.12000,15.10006,18.90092,0.13130,2.10010,15.10006
18.18000,15.15006,18.94549,0.13174,2.10505,15.15006
18.24000,15.20000,18.86366,0.13217,2.09596,15.20000
18.30000,15.25000,18.87322,0.13261,2.09702,15.25000
18.36000,15.30006,19.16997,0.13304,2.13000,15.30006
18.42000,15.35006,19.04438,0.13348,2.11604,15.35006
18.48000,15.40000,19.10617,0.13391,2.12291,15.40000
18.54000,15.44994,19.27203,0.13435,2.14134,15.44994
18.60000,15.49994,18.96618,0.13478,2.10735,15.49994
18.66000,15.55000,19.11685,0.13522,2.12409,15.55000
18.72000,15.60000,19.09177,0.13565,2.12131,15.60000
18.78000,15.65000,19.06623,0.13609,2.11847,15.65000
18.84000,15.69993,19.38354,0.13652,2.15373,15.69993
18.90000,15.75000,19.45270,0.13696,2.16141,15.75000
18.96000,15.79993,19.12102,0.13739,2.12456,15.79993
19.02000,15.85000,19.25613,0.13783,2.13957,15.85000
19.08000,15.90006,19.32363,0.13826,2.14707,15.90006
19.14000,15.94994,19.37413,0.13870,2.15268,15.94994
19.20000,16.00000,19.54944,0.13913,2.17216,16.00000
19.26000,16.05000,19.55309,0.13957,2.17257,16.05000
19.32000,16.10006,19.55649,0.14000,2.17294,16.10006
19.38000,16.15012,19.47800,0.14044,2.16422,16.15012
19.44000,16.20006,19.58476,0.14087,2.17608,16.20006
19.50000,16.25000,19.64234,0.14130,2.18248,16.25000
19.56000,16.29987,19.61385,0.14174,2.17932,16.29987
19.62000,16.35000,19.78294,0.14217,2.19810,16.35000
19.68000,16.40006,19.58985,0.14261,2.17665,16.40006
19.74000,16.44993,19.68022,0.14304,2.18669,16.44993
19.80000,16.50000,19.68982,0.14348,2.18776,16.50000
19.86000,16.54994,19.96361,0.14391,2.21818,16.54994
19.92000,16.60000,19.74103,0.14435,2.19345,16.60000
19.98000,16.65000,19.82129,0.14478,2.20237,16.65000
20.04000,16.70000,19.76996,0.14522,2.19666,16.70000
20.10000,16.75000,19.92006,0.14565,2.21334,16.75000
20.16000,16.80000,19.83844,0.14609,2.20427,16.80000
20.22000,16.85000,19.63352,0.14652,2.18150,16.85000
20.28000,16.90006,19.99217,0.14696,2.22135,16.90006
20.34000,16.95006,20.07387,0.14739,2.23043,16.95006
20.40000,17.00000,20.08673,0.14783,2.23186,17.00000
20.46000,17.05000,20.29000,0.14826,2.25444,17.05000
20.52000,17.10000,20.19405,0.14870,2.24378,17.10000
20.58000,17.15006,20.03890,0.14913,2.22654,17.15006
20.64000,17.19994,20.21746,0.14956,2.24638,17.19994
20.70000,17.24993,20.17271,0.15000,2.24141,17.24993
20.76000,17.29993,20.23304,0.15043,2.24812,17.29993
20.82000,17.35006,20.12224,0.15087,2.23580,17.35006
20.88000,17.40006,20.28043,0.15130,2.25338,17.40006
20.94000,17.44993,20.35407,0.15174,2.26156,17.44993
21.00000,17.50000,20.37104,0.15217,2.26345,17.50000
21.06000,17.54993,20.41150,0.15261,2.26794,17.54993
21.12000,17.60000,20.36027,0.15304,2.26225,17.60000
21.18000,17.65000,20.43382,0.15348,2.27042,17.65000
21.24000,17.70000,20.50841,0.15391,2.27871,17.70000
21.30000,17.74994,20.54919,0.15435,2.28324,17.74994
21.36000,17.80012,20.40303,0.15478,2.26700,17.80012
21.42000,17.85006,20.39622,0.15522,2.26625,17.85006
21.48000,17.90000,20.61703,0.15565,2.29078,17.90000
21.54000,17.95000,20.38985,0.15609,2.26554,17.95000
21.60000,18.00000,20.74003,0.15652,2.30445,18.00000
21.66000,18.05000,20.33254,0.15696,2.25917,18.05000
21.72000,18.10000,20.55892,0.15739,2.28432,18.10000
21.78000,18.15000,20.63405,0.15783,2.29267,18.15000
21.84000,18.19994,20.69323,0.15826,2.29925,18.19994
21.90000,18.25000,20.58593,0.15870,2.28733,18.25000
21.96000,18.30000,20.68154,0.15913,2.29795,18.30000
22.02000,18.35000,20.78967,0.15957,2.30996,18.35000
22.08000,18.40000,20.70812,0.16000,2.30090,18.40000
22.14000,18.45006,20.89621,0.16044,2.32180,18.45006
22.20000,18.50006,20.79930,0.16087,2.31103,18.50006
22.26000,18.55000,20.72617,0.16130,2.30291,18.55000
22.32000,18.60006,20.79200,0.16174,2.31022,18.60006
22.38000,18.65006,20.91947,0.16217,2.32439,18.65006
22.44000,18.70006,20.92021,0.16261,2.32447,18.70006
22.50000,18.75006,20.77650,0.16304,2.30850,18.75006
22.56000,18.79987,21.06382,0.16348,2.34043,18.79987
22.62000,18.84994,20.85739,0.16391,2.31749,18.84994
22.68000,18.90000,20.99657,0.16435,2.33295,18.90000
22.74000,18.95000,21.06588,0.16478,2.34065,18.95000
22.80000,18.99993,21.25197,0.16522,2.36133,18.99993
22.86000,19.05000,20.89557,0.16565,2.32173,19.05000
22.92000,19.10000,21.18653,0.16609,2.35406,19.10000
22.98000,19.15000,21.07178,0.16652,2.34131,19.15000
23.04000,19.19993,21.25828,0.16696,2.36203,19.19993
23.10000,19.24993,21.15150,0.16739,2.35017,19.24993
23.16000,19.30000,21.21153,0.16783,2.35684,19.30000
23.22000,19.35006,21.22299,0.16826,2.35811,19.35006
23.28000,19.40012,21.31618,0.16870,2.36846,19.40012
23.34000,19.44994,21.29086,0.16913,2.36565,19.44994
23.40000,19.49994,21.21876,0.16956,2.35764,19.49994
23.46000,19.54993,21.34126,0.17000,2.37125,19.54993
23.52000,19.60006,21.14274,0.17044,2.34919,19.60006
23.58000,19.65006,21.40837,0.17087,2.37871,19.65006
23.64000,19.70000,21.39497,0.17130,2.37722,19.70000
23.70000,19.74993,21.28834,0.17174,2.36537,19.74993
23.76000,19.80006,21.31454,0.17217,2.36828,19.80006
23.82000,19.85006,21.32688,0.17261,2.36965,19.85006
23.88000,19.90006,21.45475,0.17304,2.38386,19.90006
23.94000,19.95000,21.60748,0.17348,2.40083,19.95000
24.00000,19.99993,21.42487,0.17391,2.38054,19.99993
24.06000,20.04993,21.53709,0.17435,2.39301,20.04993
24.12000,20.10000,21.45860,0.17478,2.38429,20.10000
24.18000,20.15000,21.63383,0.17522,2.40376,20.15000
24.24000,20.20000,21.50751,0.17565,2.38972,20.20000
24.30000,20.24994,21.53369,0.17609,2.39263,20.24994
24.36000,20.29993,21.61818,0.17652,2.40202,20.29993
24.42000,20.35006,21.58678,0.17696,2.39853,20.35006
24.48000,20.40006,22.00142,0.17739,2.44460,20.40006
24.54000,20.44993,21.82281,0.17783,2.42476,20.44993
24.60000,20.49993,21.66138,0.17826,2.40682,20.49993
24.66000,20.55006,21.66832,0.17870,2.40759,20.55006
24.72000,20.60006,21.87277,0.17913,2.43031,20.60006
24.78000,20.65012,21.74461,0.17957,2.41607,20.65012
24.84000,20.70000,21.80618,0.18000,2.42291,20.70000
24.90000,20.75000,21.97749,0.18043,2.44194,20.75000
24.96000,20.79993,21.70243,0.18087,2.41138,20.79993
25.02000,20.85000,21.87460,0.18130,2.43051,20.85000
25.08000,20.90000,21.81120,0.18174,2.42347,20.90000
25.14000,20.95000,21.80424,0.18217,2.42269,20.95000
25.20000,21.00000,21.99831,0.18261,2.44426,21.00000
25.26000,21.04987,21.94338,0.18304,2.43815,21.04987
25.32000,21.10000,21.98697,0.18348,2.44300,21.10000
25.38000,21.15000,22.18282,0.18391,2.46476,21.15000
25.44000,21.20000,22.02307,0.18435,2.44701,21.20000
25.50000,21.24993,22.01310,0.18478,2.44590,21.24993
25.56000,21.30000,21.93118,0.18522,2.43680,21.30000
25.62000,21.35006,22.00588,0.18565,2.44510,21.35006
25.68000,21.40012,22.10053,0.18609,2.45562,21.40012
25.74000,21.45000,21.94933,0.18652,2.43881,21.45000
25.80000,21.50006,22.21109,0.18696,2.46790,21.50006
25.86000,21.55006,22.11814,0.18739,2.45757,21.55006
25.92000,21.60006,22.15461,0.18783,2.46162,21.60006
25.98000,21.65006,22.21222,0.18826,2.46802,21.65006
26.04000,21.70000,22.36271,0.18870,2.48475,21.70000
26.10000,21.74993,22.23641,0.18913,2.47071,21.74993
26.16000,21.79994,22.48451,0.18956,2.49828,21.79994
26.22000,21.85000,22.53356,0.19000,2.50373,21.85000
26.28000,21.90006,22.40006,0.19044,2.48890,21.90006
26.34000,21.95000,22.27263,0.19087,2.47474,21.95000
26.40000,21.99993,22.20719,0.19130,2.46747,21.99993
26.46000,22.04994,22.41121,0.19174,2.49013,22.04994
26.52000,22.10000,22.28542,0.19217,2.47616,22.10000
26.58000,22.15006,22.50376,0.19261,2.50042,22.15006
26.64000,22.20000,22.56925,0.19304,2.50769,22.20000
26.70000,22.25006,22.60339,0.19348,2.51149,22.25006
26.76000,22.30000,22.31476,0.19391,2.47942,22.30000
26.82000,22.35000,22.74186,0.19435,2.52687,22.35000
26.88000,22.40000,22.61740,0.19478,2.51304,22.40000
26.94000,22.45000,22.54889,0.19522,2.50543,22.45000
27.00000,22.50000,22.53479,0.19565,2.50387,22.50000
27.06000,22.55006,22.56572,0.19609,2.50730,22.55006
27.12000,22.60006,22.86601,0.19652,2.54067,22.60006
27.18000,22.64993,22.64377,0.19696,2.51597,22.64993
27.24000,22.69994,22.70755,0.19739,2.52306,22.69994
27.30000,22.74993,22.85729,0.19783,2.53970,22.74993
27.36000,22.79993,22.71404,0.19826,2.52378,22.79993
27.42000,22.85006,22.65866,0.19870,2.51763,22.85006
27.48000,22.90006,22.95143,0.19913,2.55016,22.90006
27.54000,22.95000,22.76963,0.19957,2.52996,22.95000
27.60000,23.00000,22.84945,0.20000,2.53883,23.00000
27.66000,23.05000,22.81852,0.20043,2.53539,23.05000
27.72000,23.10006,22.84867,0.20087,2.53874,23.10006
27.78000,23.15012,22.86537,0.20131,2.54060,23.15012
27.84000,23.20000,22.98893,0.20174,2.55433,23.20000
27.90000,23.25000,22.92263,0.20217,2.54696,23.25000
27.96000,23.30000,22.96980,0.20261,2.55220,23.30000
28.02000,23.35000,23.11322,0.20304,2.56814,23.35000
28.08000,23.40006,22.83231,0.20348,2.53692,23.40006
28.14000,23.44993,23.17097,0.20391,2.57455,23.44993
28.20000,23.50000,23.00962,0.20435,2.55662,23.50000
28.26000,23.55000,23.11408,0.20478,2.56823,23.55000
28.32000,23.60000,23.09218,0.20522,2.56580,23.60000
28.38000,23.65000,23.29747,0.20565,2.58861,23.65000
28.44000,23.69993,23.06120,0.20609,2.56236,23.69993
28.50000,23.74993,23.07854,0.20652,2.56428,23.74993
28.56000,23.79999,23.16323,0.20696,2.57369,23.79999
28.62000,23.85006,23.14072,0.20739,2.57119,23.85006
28.68000,23.90000,23.36741,0.20783,2.59638,23.90000
28.74000,23.95000,23.21189,0.20826,2.57910,23.95000
28.80000,24.00000,23.28862,0.20870,2.58763,24.00000
28.86000,24.05006,23.45156,0.20913,2.60573,24.05006
28.92000,24.10012,23.30359,0.20957,2.58929,24.10012
28.98000,24.15012,23.47152,0.21000,2.60795,24.15012
29.04000,24.19993,23.26989,0.21043,2.58554,24.19993
29.10000,24.24987,23.44071,0.21087,2.60452,24.24987
29.16000,24.29993,23.32149,0.21130,2.59128,24.29993
29.22000,24.35000,23.42122,0.21174,2.60236,24.35000
29.28000,24.40000,23.33854,0.21217,2.59317,24.40000
29.34000,24.44993,23.61857,0.21261,2.62429,24.44993
29.40000,24.49987,23.52567,0.21304,2.61396,24.49987
29.46000,24.54993,23.59704,0.21348,2.62189,24.54993
29.52000,24.60000,23.73196,0.21391,2.63688,24.60000
29.58000,24.65006,23.68624,0.21435,2.63180,24.65006
29.64000,24.70000,23.57591,0.21478,2.61954,24.70000
29.70000,24.75000,23.48536,0.21522,2.60948,24.75000
29.76000,24.80000,23.48017,0.21565,2.60891,24.80000
29.82000,24.85006,23.77112,0.21609,2.64124,24.85006
29.88000,24.90006,23.57250,0.21652,2.61917,24.90006
29.94000,24.95000,23.55286,0.21696,2.61698,24.95000
30.00000,24.99999,23.67816,0.21739,2.63091,24.99999
30.06000,25.05000,23.57314,0.21783,2.61924,25.05000
30.12000,25.10000,23.75212,0.21826,2.63912,25.10000
30.18000,25.15012,23.79067,0.21870,2.64341,25.15012
30.24000,25.20000,23.79738,0.21913,2.64415,25.20000
30.30000,25.25000,23.69395,0.21957,2.63266,25.25000
30.36000,25.30000,23.91366,0.22000,2.65707,25.30000
30.42000,25.35006,23.70164,0.22044,2.63352,25.35006
30.48000,25.40000,23.80350,0.22087,2.64483,25.40000
30.54000,25.44994,24.04300,0.22130,2.67144,25.44994
30.60000,25.49987,24.00406,0.22174,2.66712,25.49987
30.66000,25.54987,24.02742,0.22217,2.66971,25.54987
30.72000,25.59993,23.91890,0.22261,2.65766,25.59993
30.78000,25.65006,24.03529,0.22304,2.67059,25.65006
30.84000,25.70006,24.04016,0.22348,2.67113,25.70006
30.90000,25.75006,24.14552,0.22391,2.68284,25.75006
30.96000,25.79993,24.11194,0.22435,2.67910,25.79993
31.02000,25.84993,24.03622,0.22478,2.67069,25.84993
31.08000,25.90006,24.01667,0.22522,2.66852,25.90006
31.14000,25.95000,24.06568,0.22565,2.67396,25.95000
31.20000,26.00000,23.96737,0.22609,2.66304,26.00000
31.26000,26.05000,24.19489,0.22652,2.68832,26.05000
31.32000,26.10000,24.24231,0.22696,2.69359,26.10000
31.38000,26.15006,24.24652,0.22739,2.69406,26.15006
31.44000,26.19999,24.17702,0.22783,2.68634,26.19999
31.50000,26.25000,24.37351,0.22826,2.70817,26.25000
31.56000,26.30000,24.31495,0.22870,2.70166,26.30000
31.62000,26.35000,24.26908,0.22913,2.69656,26.35000
31.68000,26.40000,24.32761,0.22957,2.70307,26.40000
31.74000,26.45000,24.29915,0.23000,2.69991,26.45000
31.80000,26.50000,24.43060,0.23043,2.71451,26.50000
31.86000,26.54999,24.34912,0.23087,2.70546,26.54999
31.92000,26.60000,24.32614,0.23130,2.70290,26.60000
31.98000,26.65006,24.35827,0.23174,2.70648,26.65006
32.04000,26.70000,24.33934,0.23217,2.70437,26.70000
32.10000,26.75000,24.37596,0.23261,2.70844,26.75000
32.16000,26.80000,24.58254,0.23304,2.73139,26.80000
32.22000,26.85006,24.66358,0.23348,2.74040,26.85006
32.28000,26.90012,24.69464,0.23391,2.74385,26.90012
32.34000,26.95006,24.58815,0.23435,2.73202,26.95006
32.40000,27.00000,24.55589,0.23478,2.72843,27.00000
32.46000,27.05000,24.72611,0.23522,2.74735,27.05000
32.52000,27.09993,24.66686,0.23565,2.74076,27.09993
32.58000,27.15000,24.56655,0.23609,2.72962,27.15000
32.64000,27.19993,24.70781,0.23652,2.74531,27.19993
32.70000,27.25000,24.71869,0.23696,2.74652,27.25000
32.76000,27.29993,24.81090,0.23739,2.75677,27.29993
32.82000,27.35000,24.84991,0.23783,2.76110,27.35000
32.88000,27.39993,24.66914,0.23826,2.74102,27.39993
32.94000,27.44993,24.73537,0.23870,2.74837,27.44993
33.00000,27.49993,24.63142,0.23913,2.73682,27.49993
33.06000,27.54994,24.77815,0.23956,2.75313,27.54994
33.12000,27.60000,24.92111,0.24000,2.76901,27.60000
33.18000,27.65012,24.89617,0.24044,2.76624,27.65012
33.24000,27.70000,24.84917,0.24087,2.76102,27.70000
33.30000,27.74999,24.87842,0.24130,2.76427,27.74999
33.36000,27.80000,24.87653,0.24174,2.76406,27.80000
33.42000,27.85006,25.06352,0.24217,2.78484,27.85006
33.48000,27.90006,24.91256,0.24261,2.76806,27.90006
33.54000,27.95000,25.11343,0.24304,2.79038,27.95000
33.60000,27.99993,25.15561,0.24348,2.79507,27.99993
33.66000,28.04993,25.07765,0.24391,2.78641,28.04993
33.72000,28.10000,25.06347,0.24435,2.78483,28.10000
33.78000,28.15000,25.04581,0.24478,2.78287,28.15000
33.84000,28.20000,25.15823,0.24522,2.79536,28.20000
33.90000,28.25000,25.00474,0.24565,2.77830,28.25000
33.96000,28.30000,25.03714,0.24609,2.78190,28.30000
34.02000,28.35000,25.11003,0.24652,2.79000,28.35000
34.08000,28.40000,25.15140,0.24696,2.79460,28.40000
34.14000,28.45000,25.22085,0.24739,2.80232,28.45000
34.20000,28.50006,25.30224,0.24783,2.81136,28.50006
34.26000,28.55006,25.06531,0.24826,2.78503,28.55006
34.32000,28.60012,25.38626,0.24870,2.82070,28.60012
34.38000,28.65006,25.33013,0.24913,2.81446,28.65006
34.44000,28.69993,25.11838,0.24956,2.79093,28.69993
34.50000,28.74993,25.43451,0.25000,2.82606,28.74993
34.56000,28.80000,25.37887,0.25043,2.81987,28.80000
34.62000,28.85000,25.32146,0.25087,2.81350,28.85000
34.68000,28.90006,25.49851,0.25130,2.83317,28.90006
34.74000,28.94993,25.59772,0.25174,2.84419,28.94993
34.80000,28.99981,25.66799,0.25217,2.85200,28.99981
34.86000,29.04993,25.40275,0.25261,2.82253,29.04993
34.92000,29.10000,25.62072,0.25304,2.84675,29.10000
34.98000,29.15006,25.49270,0.25348,2.83252,29.15006
35.04000,29.20000,25.76367,0.25391,2.86263,29.20000
35.10000,29.24993,25.47593,0.25435,2.83066,29.24993
35.16000,29.29999,25.56145,0.25478,2.84016,29.29999
35.22000,29.35006,25.64445,0.25522,2.84938,29.35006
35.28000,29.40012,25.68163,0.25565,2.85351,29.40012
35.34000,29.45000,25.65562,0.25609,2.85062,29.45000
35.40000,29.50006,25.73989,0.25652,2.85999,29.50006
35.46000,29.55000,25.67565,0.25696,2.85285,29.55000
35.52000,29.59999,25.70071,0.25739,2.85563,29.59999
35.58000,29.65006,25.88971,0.25783,2.87663,29.65006
35.64000,29.70000,25.78469,0.25826,2.86497,29.70000
35.70000,29.75000,25.82270,0.25870,2.86919,29.75000
35.76000,29.80000,25.82331,0.25913,2.86926,29.80000
35.82000,29.85000,25.83982,0.25957,2.87109,29.85000
35.88000,29.90006,25.77173,0.26000,2.86353,29.90006
35.94000,29.95000,25.90401,0.26043,2.87822,29.95000
36.00000,29.99993,25.93362,0.26087,2.88151,29.99993
36.06000,30.05000,25.97822,0.26130,2.88647,30.05000
36.12000,30.10006,25.94589,0.26174,2.88288,30.10006
36.18000,30.15006,26.11240,0.26217,2.90138,30.15006
36.24000,30.20006,25.95985,0.26261,2.88443,30.20006
36.30000,30.25000,26.10753,0.26304,2.90084,30.25000
36.36000,30.30000,26.13070,0.26348,2.90341,30.30000
36.42000,30.35000,26.08632,0.26391,2.89848,30.35000
36.48000,30.40000,26.28053,0.26435,2.92006,30.40000
36.54000,30.45000,26.28409,0.26478,2.92045,30.45000
36.60000,30.49999,26.03878,0.26522,2.89320,30.49999
36.66000,30.55000,26.24120,0.26565,2.91569,30.55000
36.72000,30.59993,26.31428,0.26609,2.92381,30.59993
36.78000,30.65000,26.32820,0.26652,2.92535,30.65000
36.84000,30.69993,26.32396,0.26696,2.92488,30.69993
36.90000,30.74993,26.13376,0.26739,2.90375,30.74993
36.96000,30.79993,26.22087,0.26783,2.91343,30.79993
37.02000,30.84993,26.31791,0.26826,2.92421,30.84993
37.08000,30.90000,26.22364,0.26870,2.91374,30.90000
37.14000,30.94994,26.36212,0.26913,2.92912,30.94994
37.20000,31.00000,26.41352,0.26957,2.93484,31.00000
37.26000,31.05000,26.25969,0.27000,2.91774,31.05000
37.32000,31.10006,26.44024,0.27044,2.93780,31.10006
37.38000,31.15006,26.34010,0.27087,2.92668,31.15006
37.44000,31.20000,26.50419,0.27130,2.94491,31.20000
37.50000,31.25000,26.38852,0.27174,2.93206,31.25000
37.56000,31.29999,26.53730,0.27217,2.94859,31.29999
37.62000,31.35006,26.41068,0.27261,2.93452,31.35006
37.68000,31.40006,26.44428,0.27304,2.93825,31.40006
37.74000,31.45000,26.53897,0.27348,2.94877,31.45000
37.80000,31.49999,26.44007,0.27391,2.93779,31.49999
37.86000,31.54999,26.77834,0.27435,2.97537,31.54999
37.92000,31.60000,26.62895,0.27478,2.95877,31.60000
37.98000,31.65000,26.77384,0.27522,2.97487,31.65000
38.04000,31.69993,26.67315,0.27565,2.96368,31.69993
38.10000,31.74993,26.68165,0.27609,2.96463,31.74993
38.16000,31.80000,26.48592,0.27652,2.94288,31.80000
38.22000,31.85000,26.89832,0.27696,2.98870,31.85000
38.28000,31.90006,26.55809,0.27739,2.95090,31.90006
38.34000,31.94993,26.74305,0.27783,2.97145,31.94993
38.40000,31.99999,27.16444,0.27826,3.01827,31.99999
38.46000,32.05006,26.83695,0.27870,2.98188,32.05006
38.52000,32.10012,26.90729,0.27913,2.98970,32.10012
38.58000,32.14999,26.98777,0.27957,2.99864,32.14999
38.64000,32.19993,26.77283,0.28000,2.97476,32.19993
38.70000,32.24999,26.87048,0.28043,2.98561,32.24999
38.76000,32.30000,26.81905,0.28087,2.97989,32.30000
38.82000,32.34999,26.92984,0.28130,2.99220,32.34999
38.88000,32.40006,26.96633,0.28174,2.99626,32.40006
38.94000,32.44993,26.98262,0.28217,2.99807,32.44993
39.00000,32.49993,26.86497,0.28261,2.98500,32.49993
39.06000,32.54993,26.89186,0.28304,2.98798,32.54993
39.12000,32.59999,27.12345,0.28348,3.01372,32.59999
39.18000,32.65006,27.12920,0.28391,3.01436,32.65006
39.24000,32.70000,26.88725,0.28435,2.98747,32.70000
39.30000,32.75000,27.13288,0.28478,3.01476,32.75000
39.36000,32.79999,26.83984,0.28522,2.98220,32.79999
39.42000,32.84999,27.12279,0.28565,3.01364,32.84999
39.48000,32.89999,27.19935,0.28609,3.02215,32.89999
39.54000,32.94999,27.27674,0.28652,3.03075,32.94999
39.60000,33.00000,27.21105,0.28696,3.02345,33.00000
39.66000,33.05006,27.28320,0.28739,3.03147,33.05006
39.72000,33.10006,27.34468,0.28783,3.03830,33.10006
39.78000,33.15006,27.25433,0.28826,3.02826,33.15006
39.84000,33.20000,27.29844,0.28870,3.03316,33.20000
39.90000,33.24999,27.40421,0.28913,3.04491,33.24999
39.96000,33.30006,27.32770,0.28957,3.03641,33.30006
40.02000,33.35000,27.47563,0.29000,3.05285,33.35000
40.08000,33.40006,27.51158,0.29044,3.05684,33.40006
40.14000,33.44993,27.21705,0.29087,3.02412,33.44993
40.20000,33.49993,27.26241,0.29130,3.02916,33.49993
40.26000,33.54999,27.39530,0.29174,3.04392,33.54999
40.32000,33.60000,27.74915,0.29217,3.08324,33.60000
40.38000,33.65012,27.34957,0.29261,3.03884,33.65012
40.44000,33.69999,27.58711,0.29304,3.06523,33.69999
40.50000,33.74993,27.59608,0.29348,3.06623,33.74993
40.56000,33.79993,27.71207,0.29391,3.07912,33.79993
40.62000,33.85000,27.42275,0.29435,3.04697,33.85000
40.68000,33.90006,27.84927,0.29478,3.09436,33.90006
40.74000,33.95006,27.57146,0.29522,3.06350,33.95006
40.80000,34.00000,27.55018,0.29565,3.06113,34.00000
40.86000,34.04993,27.61467,0.29609,3.06830,34.04993
40.92000,34.10000,27.55074,0.29652,3.06119,34.10000
40.98000,34.15006,27.54489,0.29696,3.06054,34.15006
41.04000,34.19999,27.67891,0.29739,3.07543,34.19999
41.10000,34.25000,27.70357,0.29783,3.07817,34.25000
41.16000,34.30000,27.69730,0.29826,3.07748,34.30000
41.22000,34.34999,27.63100,0.29870,3.07011,34.34999
41.28000,34.40006,27.62728,0.29913,3.06970,34.40006
41.34000,34.44999,27.74459,0.29957,3.08273,34.44999
41.40000,34.49993,27.90378,0.30000,3.10042,34.49993
41.46000,34.54993,27.64459,0.30043,3.07162,34.54993
41.52000,34.59999,27.79005,0.30087,3.08778,34.59999
41.58000,34.65006,27.76521,0.30130,3.08502,34.65006
41.64000,34.70000,27.79558,0.30174,3.08840,34.70000
41.70000,34.75000,27.83244,0.30217,3.09249,34.75000
41.76000,34.79999,27.91816,0.30261,3.10202,34.79999
41.82000,34.85006,27.94334,0.30304,3.10482,34.85006
41.88000,34.90012,27.98639,0.30348,3.10960,34.90012
41.94000,34.95006,28.07615,0.30391,3.11957,34.95006
42.00000,34.99993,27.88554,0.30435,3.09839,34.99993
42.06000,35.04993,28.03939,0.30478,3.11549,35.04993
42.12000,35.09999,27.92017,0.30522,3.10224,35.09999
42.18000,35.15000,28.17238,0.30565,3.13026,35.15000
42.24000,35.20000,28.11757,0.30609,3.12417,35.20000
42.30000,35.25006,28.07314,0.30652,3.11924,35.25006
42.36000,35.29999,28.24717,0.30696,3.13857,35.29999
42.42000,35.34993,28.11531,0.30739,3.12392,35.34993
42.48000,35.40000,28.19197,0.30783,3.13244,35.40000
42.54000,35.45006,28.19305,0.30826,3.13256,35.45006
42.60000,35.49999,28.15083,0.30870,3.12787,35.49999
42.66000,35.55000,28.15737,0.30913,3.12860,35.55000
42.72000,35.60000,28.25993,0.30957,3.13999,35.60000
42.78000,35.65006,28.22447,0.31000,3.13605,35.65006
42.84000,35.69999,28.31910,0.31043,3.14657,35.69999
42.90000,35.74993,28.27801,0.31087,3.14200,35.74993
42.96000,35.79993,28.19501,0.31130,3.13278,35.79993
43.02000,35.85000,28.40149,0.31174,3.15572,35.85000
43.08000,35.90006,28.32055,0.31217,3.14673,35.90006
43.14000,35.94993,28.39522,0.31261,3.15502,35.94993
43.20000,35.99993,28.46049,0.31304,3.16228,35.99993
43.26000,36.05000,28.36779,0.31348,3.15198,36.05000
43.32000,36.09999,28.36392,0.31391,3.15155,36.09999
43.38000,36.15006,28.43355,0.31435,3.15928,36.15006
43.44000,36.19999,28.32359,0.31478,3.14707,36.19999
43.50000,36.25000,28.56279,0.31522,3.17364,36.25000
43.56000,36.30000,28.53654,0.31565,3.17073,36.30000
43.62000,36.34999,28.60798,0.31609,3.17866,36.34999
43.68000,36.40000,28.52302,0.31652,3.16922,36.40000
43.74000,36.45000,28.52723,0.31696,3.16969,36.45000
43.80000,36.50000,28.56911,0.31739,3.17435,36.50000
43.86000,36.55006,28.71172,0.31783,3.19019,36.55006
43.92000,36.60006,28.68385,0.31826,3.18709,36.60006
43.98000,36.65006,28.70124,0.31870,3.18903,36.65006
44.04000,36.70000,29.04257,0.31913,3.22695,36.70000
44.10000,36.74999,28.59691,0.31957,3.17743,36.74999
44.16000,36.79999,28.75255,0.32000,3.19473,36.79999
44.22000,36.85012,28.78030,0.32044,3.19781,36.85012
44.28000,36.90006,28.77138,0.32087,3.19682,36.90006
44.34000,36.94987,29.05805,0.32130,3.22867,36.94987
44.40000,36.99993,28.79274,0.32174,3.19919,36.99993
44.46000,37.04993,28.82093,0.32217,3.20233,37.04993
44.52000,37.10000,28.81005,0.32261,3.20112,37.10000
44.58000,37.15000,28.83278,0.32304,3.20364,37.15000
44.64000,37.19999,28.93920,0.32348,3.21547,37.19999
44.70000,37.24993,28.98367,0.32391,3.22041,37.24993
44.76000,37.30000,28.92947,0.32435,3.21439,37.30000
44.82000,37.35006,28.83851,0.32478,3.20428,37.35006
44.88000,37.40006,28.90655,0.32522,3.21184,37.40006
44.94000,37.44999,28.97916,0.32565,3.21991,37.44999
45.00000,37.49999,29.10331,0.32609,3.23370,37.49999
45.06000,37.54999,29.26637,0.32652,3.25182,37.54999
45.12000,37.60006,29.03020,0.32696,3.22558,37.60006
45.18000,37.65006,29.12454,0.32739,3.23606,37.65006
45.24000,37.69999,29.16380,0.32783,3.24042,37.69999
45.30000,37.74999,29.09239,0.32826,3.23249,37.74999
45.36000,37.80000,29.05325,0.32870,3.22814,37.80000
45.42000,37.84999,29.28432,0.32913,3.25381,37.84999
45.48000,37.89999,29.39042,0.32957,3.26560,37.89999
45.54000,37.94987,29.06885,0.33000,3.22987,37.94987
45.60000,37.99993,29.24751,0.33043,3.24972,37.99993
45.66000,38.04993,29.25682,0.33087,3.25076,38.04993
45.72000,38.09999,29.48104,0.33130,3.27567,38.09999
45.78000,38.15006,29.25491,0.33174,3.25055,38.15006
45.84000,38.20000,29.35026,0.33217,3.26114,38.20000
45.90000,38.25000,29.33759,0.33261,3.25973,38.25000
45.96000,38.29993,29.50308,0.33304,3.27812,38.29993
46.02000,38.35006,29.39635,0.33348,3.26626,38.35006
46.08000,38.40012,29.43316,0.33391,3.27035,38.40012
46.14000,38.45006,29.40338,0.33435,3.26704,38.45006
46.20000,38.50000,29.33468,0.33478,3.25941,38.50000
46.26000,38.54993,29.37457,0.33522,3.26384,38.54993
46.32000,38.59999,29.50254,0.33565,3.27806,38.59999
46.38000,38.65006,29.38356,0.33609,3.26484,38.65006
46.44000,38.69993,29.52740,0.33652,3.28082,38.69993
46.50000,38.74993,29.52882,0.33696,3.28098,38.74993
46.56000,38.79993,29.64843,0.33739,3.29427,38.79993
46.62000,38.85000,29.49882,0.33783,3.27765,38.85000
46.68000,38.90006,29.74336,0.33826,3.30482,38.90006
46.74000,38.94999,29.47800,0.33870,3.27533,38.94999
46.80000,38.99999,29.56933,0.33913,3.28548,38.99999
46.86000,39.04999,29.63181,0.33957,3.29242,39.04999
46.92000,39.10006,29.83008,0.34000,3.31445,39.10006
46.98000,39.15005,29.85842,0.34044,3.31760,39.15005
47.04000,39.19999,29.63638,0.34087,3.29293,39.19999
47.10000,39.24999,29.71672,0.34130,3.30186,39.24999
47.16000,39.29999,29.97520,0.34174,3.33058,39.29999
47.22000,39.34999,29.80780,0.34217,3.31198,39.34999
47.28000,39.40005,29.89268,0.34261,3.32141,39.40005
47.34000,39.44999,29.98029,0.34304,3.33114,39.44999
47.40000,39.49999,29.78583,0.34348,3.30954,39.49999
47.46000,39.54993,29.59419,0.34391,3.28824,39.54993
47.52000,39.59999,29.94037,0.34435,3.32671,39.59999
47.58000,39.64999,29.77554,0.34478,3.30839,39.64999
47.64000,39.69993,29.80579,0.34522,3.31175,39.69993
47.70000,39.74999,29.91252,0.34565,3.32361,39.74999
47.76000,39.80000,30.12266,0.34609,3.34696,39.80000
47.82000,39.84999,30.02474,0.34652,3.33608,39.84999
47.88000,39.89999,30.03189,0.34696,3.33688,39.89999
47.94000,39.94999,29.81520,0.34739,3.31280,39.94999
48.00000,40.00005,30.22133,0.34783,3.35793,40.00005
48.06000,40.05006,29.85637,0.34826,3.31737,40.05006
48.12000,40.10005,30.20042,0.34870,3.35560,40.10005
48.18000,40.14993,30.07223,0.34913,3.34136,40.14993
48.24000,40.19999,30.16676,0.34957,3.35186,40.19999
48.30000,40.25000,29.98725,0.35000,3.33192,40.25000
48.36000,40.29999,30.21531,0.35043,3.35726,40.29999
48.42000,40.34999,30.37754,0.35087,3.37528,40.34999
48.48000,40.40000,30.20982,0.35130,3.35665,40.40000
48.54000,40.44993,30.21795,0.35174,3.35755,40.44993
48.60000,40.49993,30.45591,0.35217,3.38399,40.49993
48.66000,40.54999,30.30303,0.35261,3.36700,40.54999
48.72000,40.60006,30.36343,0.35304,3.37371,40.60006
48.78000,40.65000,30.29137,0.35348,3.36571,40.65000
48.84000,40.69999,30.28572,0.35391,3.36508,40.69999
48.90000,40.74999,30.29116,0.35435,3.36568,40.74999
48.96000,40.79993,30.34780,0.35478,3.37198,40.79993
49.02000,40.84993,30.57743,0.35522,3.39749,40.84993
49.08000,40.90006,30.24450,0.35565,3.36050,40.90006
49.14000,40.94999,30.42181,0.35609,3.38020,40.94999
49.20000,40.99999,30.67633,0.35652,3.40848,40.99999
49.26000,41.05006,30.49759,0.35696,3.38862,41.05006
49.32000,41.10005,30.44356,0.35739,3.38262,41.10005
49.38000,41.15005,30.63161,0.35783,3.40351,41.15005
49.44000,41.19999,30.58130,0.35826,3.39792,41.19999
49.50000,41.25000,30.46766,0.35870,3.38530,41.25000
49.56000,41.29999,30.63082,0.35913,3.40342,41.29999
49.62000,41.35000,30.61020,0.35957,3.40113,41.35000
49.68000,41.39993,30.52654,0.36000,3.39184,41.39993
49.74000,41.44993,30.70106,0.36043,3.41123,41.44993
49.80000,41.49993,30.81406,0.36087,3.42378,41.49993
49.86000,41.54999,30.55377,0.36130,3.39486,41.54999
49.92000,41.60006,30.48711,0.36174,3.38746,41.60006
49.98000,41.65012,30.62583,0.36217,3.40287,41.65012
50.04000,41.69993,30.56039,0.36261,3.39560,41.69993
50.10000,41.74993,30.73819,0.36304,3.41535,41.74993
50.16000,41.80000,30.81402,0.36348,3.42378,41.80000
50.22000,41.84999,30.56656,0.36391,3.39628,41.84999
50.28000,41.90006,30.80471,0.36435,3.42275,41.90006
50.34000,41.95006,30.84894,0.36478,3.42766,41.95006
50.40000,41.99999,30.93148,0.36522,3.43683,41.99999
50.46000,42.04999,31.02871,0.36565,3.44763,42.04999
50.52000,42.09999,30.72325,0.36609,3.41369,42.09999
50.58000,42.15006,30.77743,0.36652,3.41971,42.15006
50.64000,42.20000,30.87779,0.36696,3.43087,42.20000
50.70000,42.24993,30.84409,0.36739,3.42712,42.24993
50.76000,42.29999,30.81049,0.36783,3.42339,42.29999
50.82000,42.34999,31.13137,0.36826,3.45904,42.34999
50.88000,42.39999,31.03938,0.36870,3.44882,42.39999
50.94000,42.44993,31.10502,0.36913,3.45611,42.44993
51.00000,42.49993,30.93632,0.36956,3.43737,42.49993
51.06000,42.54993,30.93295,0.37000,3.43699,42.54993
51.12000,42.59999,31.21450,0.37043,3.46828,42.59999
51.18000,42.65000,31.07196,0.37087,3.45244,42.65000
51.24000,42.69999,30.99236,0.37130,3.44360,42.69999
51.30000,42.74999,31.06069,0.37174,3.45119,42.74999
51.36000,42.80006,31.19407,0.37217,3.46601,42.80006
51.42000,42.85006,31.20950,0.37261,3.46772,42.85006
51.48000,42.90012,31.20828,0.37304,3.46759,42.90012
51.54000,42.94999,31.19627,0.37348,3.46625,42.94999
51.60000,42.99993,31.37134,0.37391,3.48570,42.99993
51.66000,43.04993,31.26965,0.37435,3.47441,43.04993
51.72000,43.09999,31.30115,0.37478,3.47791,43.09999
51.78000,43.15006,31.37717,0.37522,3.48635,43.15006
51.84000,43.20005,31.25745,0.37565,3.47305,43.20005
51.90000,43.24999,31.37859,0.37609,3.48651,43.24999
51.96000,43.29993,31.39132,0.37652,3.48792,43.29993
52.02000,43.34999,31.43511,0.37696,3.49279,43.34999
52.08000,43.39999,31.43839,0.37739,3.49316,43.39999
52.14000,43.44999,31.32015,0.37783,3.48002,43.44999
52.20000,43.50000,31.27318,0.37826,3.47480,43.50000
52.26000,43.54999,31.46465,0.37870,3.49607,43.54999
52.32000,43.59999,31.42919,0.37913,3.49213,43.59999
52.38000,43.65006,31.41919,0.37957,3.49102,43.65006
52.44000,43.69999,31.41067,0.38000,3.49007,43.69999
52.50000,43.75000,31.47582,0.38043,3.49731,43.75000
52.56000,43.79999,31.74022,0.38087,3.52669,43.79999
52.62000,43.85006,31.64044,0.38130,3.51560,43.85006
52.68000,43.90012,31.55865,0.38174,3.50652,43.90012
52.74000,43.94999,31.75981,0.38217,3.52887,43.94999
52.80000,44.00000,31.56981,0.38261,3.50776,44.00000
52.86000,44.04993,31.53445,0.38304,3.50383,44.04993
52.92000,44.09999,31.51476,0.38348,3.50164,44.09999
52.98000,44.15006,31.59401,0.38391,3.51045,44.15006
53.04000,44.20000,31.75374,0.38435,3.52819,44.20000
53.10000,44.24987,31.91979,0.38478,3.54664,44.24987
53.16000,44.29987,31.63731,0.38522,3.51526,44.29987
53.22000,44.35000,31.80091,0.38565,3.53343,44.35000
53.28000,44.40005,31.83437,0.38609,3.53715,44.40005
53.34000,44.44999,31.88658,0.38652,3.54295,44.44999
53.40000,44.50005,31.75747,0.38696,3.52861,44.50005
53.46000,44.54999,31.71465,0.38739,3.52385,44.54999
53.52000,44.60000,32.10989,0.38783,3.56777,44.60000
53.58000,44.65005,31.86851,0.38826,3.54095,44.65005
53.64000,44.69999,31.97127,0.38870,3.55236,44.69999
53.70000,44.75005,31.73430,0.38913,3.52603,44.75005
53.76000,44.80006,31.86963,0.38957,3.54107,44.80006
53.82000,44.85006,31.93218,0.39000,3.54802,44.85006
53.88000,44.89993,31.83079,0.39043,3.53675,44.89993
53.94000,44.94993,31.82712,0.39087,3.53635,44.94993
54.00000,44.99993,31.96255,0.39130,3.55139,44.99993
54.06000,45.05000,32.00242,0.39174,3.55582,45.05000
54.12000,45.09999,31.93909,0.39217,3.54879,45.09999
54.18000,45.14999,31.98166,0.39261,3.55352,45.14999
54.24000,45.19999,31.87105,0.39304,3.54123,45.19999
54.30000,45.24999,31.85621,0.39348,3.53958,45.24999
54.36000,45.30000,31.89305,0.39391,3.54367,45.30000
54.42000,45.35005,31.86150,0.39435,3.54017,45.35005
54.48000,45.40006,32.15339,0.39478,3.57260,45.40006
54.54000,45.44999,32.01555,0.39522,3.55728,45.44999
54.60000,45.49993,31.47929,0.39565,3.49770,45.49993
54.66000,45.55006,28.76736,0.39609,3.19637,45.55006
54.72000,45.60005,-1.18277,0.39652,-0.13142,45.60005
54.78000,45.65006,-0.18236,0.39696,-0.02026,45.65006
54.84000,45.69999,-0.16651,0.39739,-0.01850,45.69999
54.90000,45.74993,-0.07658,0.39783,-0.00851,45.74993
54.96000,45.79999,0.08249,0.39826,0.00917,45.79999
55.02000,45.84999,-0.18084,0.39870,-0.02009,45.84999
55.08000,45.89993,-0.14043,0.39913,-0.01560,45.89993
55.14000,45.94993,0.04678,0.39956,0.00520,45.94993
55.20000,45.99993,0.02420,0.40000,0.00269,45.99993
55.26000,46.04999,-0.09113,0.40043,-0.01013,46.04999
55.32000,46.09999,-0.14330,0.40087,-0.01592,46.09999
55.38000,46.15000,0.01193,0.40130,0.00133,46.15000
55.44000,46.19999,0.06035,0.40174,0.00671,46.19999
55.50000,46.24993,0.02143,0.40217,0.00238,46.24993
55.56000,46.29999,-0.10999,0.40261,-0.01222,46.29999
55.62000,46.35012,-0.11369,0.40304,-0.01263,46.35012
55.68000,46.40006,-0.11116,0.40348,-0.01235,46.40006
55.74000,46.45005,0.07901,0.40391,0.00878,46.45005
55.80000,46.49993,-0.25659,0.40435,-0.02851,46.49993
55.86000,46.54999,0.00304,0.40478,0.00034,46.54999
55.92000,46.60005,-0.12001,0.40522,-0.01333,46.60005
55.98000,46.64999,-0.14484,0.40565,-0.01609,46.64999
56.04000,46.69999,-0.17369,0.40609,-0.01930,46.69999
56.10000,46.74993,-0.09569,0.40652,-0.01063,46.74993
56.16000,46.79999,-0.04445,0.40696,-0.00494,46.79999
56.22000,46.85000,-0.03274,0.40739,-0.00364,46.85000
56.28000,46.90005,-0.06620,0.40783,-0.00736,46.90005
56.34000,46.94999,-0.10276,0.40826,-0.01142,46.94999
56.40000,46.99999,0.04487,0.40870,0.00499,46.99999
56.46000,47.04993,-0.16336,0.40913,-0.01815,47.04993
56.52000,47.09999,-0.15544,0.40957,-0.01727,47.09999
56.58000,47.15005,-0.34929,0.41000,-0.03881,47.15005
56.64000,47.19993,0.09961,0.41043,0.01107,47.19993
56.70000,47.24999,-0.23876,0.41087,-0.02653,47.24999
56.76000,47.29999,-0.06172,0.41130,-0.00686,47.29999
56.82000,47.35006,-0.13997,0.41174,-0.01555,47.35006
56.88000,47.40012,-0.14038,0.41217,-0.01560,47.40012
56.94000,47.44993,-0.09551,0.41261,-0.01061,47.44993
57.00000,47.49993,-0.05709,0.41304,-0.00634,47.49993
57.06000,47.54993,-0.11947,0.41348,-0.01327,47.54993
57.12000,47.60006,-0.40555,0.41391,-0.04506,47.60006
57.18000,47.65006,0.01746,0.41435,0.00194,47.65006
57.24000,47.70000,-0.02941,0.41478,-0.00327,47.70000
57.30000,47.74993,-0.00468,0.41522,-0.00052,47.74993
57.36000,47.79993,0.00519,0.41565,0.00058,47.79993
57.42000,47.84993,-0.14516,0.41609,-0.01613,47.84993
57.48000,47.90006,-0.13335,0.41652,-0.01482,47.90006
57.54000,47.94999,-0.02109,0.41696,-0.00234,47.94999
57.56200,47.96843,0.04215,0.41712,0.00468,47.96843