File: V_7/NatR/RDSO NatR Tensile 50.is_tens_RawData/Specimen_RawData_3.csv
Time,Extension,Load,Tensile strain,Tensile stress,Corrected Position
(sec),(mm),(N),(mm/mm),(MPa),(mm)
0.00000,0.00000,0.17577,0.00000,0.01953,0.00000
0.06000,0.03150,0.28863,0.00027,0.03207,0.03150
0.12000,0.09562,0.70309,0.00083,0.07812,0.09562
0.18000,0.14762,0.82249,0.00128,0.09139,0.14762
0.24000,0.19881,0.90296,0.00173,0.10033,0.19881
0.30000,0.24944,1.09752,0.00217,0.12195,0.24944
0.36000,0.29975,1.32316,0.00261,0.14702,0.29975
0.42000,0.34981,1.40516,0.00304,0.15613,0.34981
0.48000,0.39987,1.48603,0.00348,0.16511,0.39987
0.54000,0.44987,1.74923,0.00391,0.19436,0.44987
0.60000,0.49987,1.70468,0.00435,0.18941,0.49987
0.66000,0.55000,1.81666,0.00478,0.20185,0.55000
0.72000,0.59994,2.00372,0.00522,0.22264,0.59994
0.78000,0.64994,2.03962,0.00565,0.22662,0.64994
0.84000,0.69994,2.31544,0.00609,0.25727,0.69994
0.90000,0.75000,2.37407,0.00652,0.26379,0.75000
0.96000,0.80000,2.47348,0.00696,0.27483,0.80000
1.02000,0.85000,2.55043,0.00739,0.28338,0.85000
1.08000,0.90006,2.85371,0.00783,0.31708,0.90006
1.14000,0.95000,2.89042,0.00826,0.32116,0.95000
1.20000,0.99994,2.80884,0.00870,0.31209,0.99994
1.26000,1.05000,2.93950,0.00913,0.32661,1.05000
1.32000,1.10000,3.03644,0.00957,0.33738,1.10000
1.38000,1.15006,3.29220,0.01000,0.36580,1.15006
1.44000,1.19994,3.05973,0.01043,0.33997,1.19994
1.50000,1.24994,3.18250,0.01087,0.35361,1.24994
1.56000,1.30000,3.45685,0.01130,0.38409,1.30000
1.62000,1.35000,3.49435,0.01174,0.38826,1.35000
1.68000,1.40000,3.57257,0.01217,0.39695,1.40000
1.74000,1.45000,3.62315,0.01261,0.40257,1.45000
1.80000,1.50006,3.74548,0.01304,0.41616,1.50006
1.86000,1.55006,3.77367,0.01348,0.41930,1.55006
1.92000,1.60006,4.10658,0.01391,0.45629,1.60006
1.98000,1.65000,4.03587,0.01435,0.44843,1.65000
2.04000,1.69994,4.08463,0.01478,0.45385,1.69994
2.10000,1.75000,4.21965,0.01522,0.46885,1.75000
2.16000,1.80006,4.24074,0.01565,0.47119,1.80006
2.22000,1.85000,4.26114,0.01609,0.47346,1.85000
2.28000,1.90006,4.47992,0.01652,0.49777,1.90006
2.34000,1.95000,4.47955,0.01696,0.49773,1.95000
2.40000,1.99987,4.73803,0.01739,0.52645,1.99987
2.46000,2.05000,4.70749,0.01783,0.52305,2.05000
2.52000,2.10000,4.87467,0.01826,0.54163,2.10000
2.58000,2.15000,4.92328,0.01870,0.54703,2.15000
2.64000,2.20000,4.77692,0.01913,0.53077,2.20000
2.70000,2.24994,5.06129,0.01956,0.56237,2.24994
2.76000,2.30000,5.23777,0.02000,0.58197,2.30000
2.82000,2.35006,5.10209,0.02044,0.56690,2.35006
2.88000,2.40006,5.30779,0.02087,0.58975,2.40006
2.94000,2.45000,5.31370,0.02130,0.59041,2.45000
3.00000,2.50000,5.28502,0.02174,0.58722,2.50000
3.06000,2.55000,5.77846,0.02217,0.64205,2.55000
3.12000,2.60006,5.67942,0.02261,0.63105,2.60006
3.18000,2.65006,5.73335,0.02304,0.63704,2.65006
3.24000,2.70000,5.92607,0.02348,0.65845,2.70000
3.30000,2.75000,5.92426,0.02391,0.65825,2.75000
3.36000,2.80000,5.96173,0.02435,0.66241,2.80000
3.42000,2.85000,5.86646,0.02478,0.65183,2.85000
3.48000,2.90006,6.14838,0.02522,0.68315,2.90006
3.54000,2.94994,6.17600,0.02565,0.68622,2.94994
3.60000,2.99994,6.32751,0.02609,0.70306,2.99994
3.66000,3.05000,6.34732,0.02652,0.70526,3.05000
3.72000,3.10000,6.53468,0.02696,0.72608,3.10000
3.78000,3.15006,6.50933,0.02739,0.72326,3.15006
3.84000,3.20000,6.36486,0.02783,0.70721,3.20000
3.90000,3.24994,6.64859,0.02826,0.73873,3.24994
3.96000,3.29994,6.84711,0.02870,0.76079,3.29994
4.02000,3.35000,6.83910,0.02913,0.75990,3.35000
4.08000,3.40006,6.93724,0.02957,0.77080,3.40006
4.14000,3.45006,6.83109,0.03000,0.75901,3.45006
4.20000,3.50000,7.08507,0.03043,0.78723,3.50000
4.26000,3.55000,7.19667,0.03087,0.79963,3.55000
4.32000,3.60000,7.17706,0.03130,0.79745,3.60000
4.38000,3.65006,7.41237,0.03174,0.82360,3.65006
4.44000,3.70000,7.55268,0.03217,0.83919,3.70000
4.50000,3.75000,7.45902,0.03261,0.82878,3.75000
4.56000,3.80000,7.47080,0.03304,0.83009,3.80000
4.62000,3.85000,7.63822,0.03348,0.84869,3.85000
4.68000,3.90006,7.76384,0.03391,0.86265,3.90006
4.74000,3.94994,7.82330,0.03435,0.86926,3.94994
4.80000,4.00000,7.93954,0.03478,0.88217,4.00000
4.86000,4.04994,7.85791,0.03522,0.87310,4.04994
4.92000,4.10000,7.98908,0.03565,0.88768,4.10000
4.98000,4.15000,8.10405,0.03609,0.90045,4.15000
5.04000,4.19994,8.22256,0.03652,0.91362,4.19994
5.10000,4.24994,8.08803,0.03696,0.89867,4.24994
5.16000,4.29994,8.18369,0.03739,0.90930,4.29994
5.22000,4.35000,8.30252,0.03783,0.92250,4.35000
5.28000,4.40006,8.27049,0.03826,0.91894,4.40006
5.34000,4.45000,8.51682,0.03870,0.94631,4.45000
5.40000,4.50006,8.64858,0.03913,0.96095,4.50006
5.46000,4.55000,8.58557,0.03957,0.95395,4.55000
5.52000,4.60006,8.87414,0.04000,0.98602,4.60006
5.58000,4.65000,8.88448,0.04043,0.98716,4.65000
5.64000,4.70000,8.86258,0.04087,0.98473,4.70000
5.70000,4.75000,8.94495,0.04130,0.99388,4.75000
5.76000,4.80000,8.96780,0.04174,0.99642,4.80000
5.82000,4.84994,8.90432,0.04217,0.98937,4.84994
5.88000,4.90000,9.13515,0.04261,1.01502,4.90000
5.94000,4.94994,9.05386,0.04304,1.00598,4.94994
6.00000,5.00000,9.06258,0.04348,1.00695,5.00000
6.06000,5.05006,9.31185,0.04391,1.03465,5.05006
6.12000,5.10006,9.34472,0.04435,1.03830,5.10006
6.18000,5.15000,9.24418,0.04478,1.02713,5.15000
6.24000,5.19994,9.50533,0.04522,1.05615,5.19994
6.30000,5.25000,9.57136,0.04565,1.06348,5.25000
6.36000,5.30006,9.57241,0.04609,1.06360,5.30006
6.42000,5.35006,9.84123,0.04652,1.09347,5.35006
6.48000,5.40006,9.70273,0.04696,1.07808,5.40006
6.54000,5.45000,9.64929,0.04739,1.07214,5.45000
6.60000,5.50000,9.81789,0.04783,1.09088,5.50000
6.66000,5.55000,9.96858,0.04826,1.10762,5.55000
6.72000,5.60000,10.09660,0.04870,1.12184,5.60000
6.78000,5.65006,10.13960,0.04913,1.12662,5.65006
6.84000,5.69994,10.07397,0.04956,1.11933,5.69994
6.90000,5.74994,10.07737,0.05000,1.11971,5.74994
6.96000,5.79994,10.25322,0.05043,1.13925,5.79994
7.02000,5.85000,10.20294,0.05087,1.13366,5.85000
7.08000,5.90000,10.51101,0.05130,1.16789,5.90000
7.14000,5.94994,10.39583,0.05174,1.15509,5.94994
7.20000,5.99994,10.62210,0.05217,1.18023,5.99994
7.26000,6.05000,10.62186,0.05261,1.18021,6.05000
7.32000,6.10006,10.47966,0.05304,1.16441,6.10006
7.38000,6.15006,10.66930,0.05348,1.18548,6.15006
7.44000,6.20000,10.79814,0.05391,1.19979,6.20000
7.50000,6.25000,10.99060,0.05435,1.22118,6.25000
7.56000,6.30006,10.73383,0.05478,1.19265,6.30006
7.62000,6.35006,10.79021,0.05522,1.19891,6.35006
7.68000,6.40006,10.83241,0.05565,1.20360,6.40006
7.74000,6.45000,11.03862,0.05609,1.22651,6.45000
7.80000,6.49994,10.82699,0.05652,1.20300,6.49994
7.86000,6.54994,11.02919,0.05696,1.22547,6.54994
7.92000,6.60000,11.21124,0.05739,1.24569,6.60000
7.98000,6.65012,11.23509,0.05783,1.24834,6.65012
8.04000,6.70000,11.60427,0.05826,1.28936,6.70000
8.10000,6.74981,11.38071,0.05869,1.26452,6.74981
8.16000,6.79994,11.22701,0.05913,1.24745,6.79994
8.22000,6.85000,11.54635,0.05957,1.28293,6.85000
8.28000,6.90006,11.64527,0.06000,1.29392,6.90006
8.34000,6.94987,11.55717,0.06043,1.28413,6.94987
8.40000,7.00006,11.65511,0.06087,1.29501,7.00006
8.46000,7.05006,11.67160,0.06130,1.29684,7.05006
8.52000,7.10006,11.83463,0.06174,1.31496,7.10006
8.58000,7.15012,11.84521,0.06217,1.31613,7.15012
8.64000,7.20000,12.05704,0.06261,1.33967,7.20000
8.70000,7.25000,11.99926,0.06304,1.33325,7.25000
8.76000,7.30000,12.12025,0.06348,1.34669,7.30000
8.82000,7.35006,12.05584,0.06391,1.33954,7.35006
8.88000,7.40006,11.95143,0.06435,1.32794,7.40006
8.94000,7.44987,12.24709,0.06478,1.36079,7.44987
9.00000,7.49994,12.29090,0.06522,1.36566,7.49994
9.06000,7.54987,12.42918,0.06565,1.38102,7.54987
9.12000,7.60000,12.23541,0.06609,1.35949,7.60000
9.18000,7.65000,12.53932,0.06652,1.39326,7.65000
9.24000,7.70000,12.40476,0.06696,1.37831,7.70000
9.30000,7.75000,12.41230,0.06739,1.37915,7.75000
9.36000,7.80000,12.52776,0.06783,1.39197,7.80000
9.42000,7.85006,12.42840,0.06826,1.38093,7.85006
9.48000,7.90006,12.61769,0.06870,1.40197,7.90006
9.54000,7.95000,12.65837,0.06913,1.40649,7.95000
9.60000,8.00000,12.54088,0.06957,1.39343,8.00000
9.66000,8.05000,12.99105,0.07000,1.44345,8.05000
9.72000,8.10000,12.80022,0.07043,1.42225,8.10000
9.78000,8.15006,13.00582,0.07087,1.44509,8.15006
9.84000,8.20006,13.03803,0.07130,1.44867,8.20006
9.90000,8.25006,13.13597,0.07174,1.45955,8.25006
9.96000,8.30000,13.11356,0.07217,1.45706,8.30000
10.02000,8.34994,13.22840,0.07261,1.46982,8.34994
10.08000,8.40000,13.41652,0.07304,1.49072,8.40000
10.14000,8.44994,13.31223,0.07348,1.47914,8.44994
10.20000,8.50000,13.37782,0.07391,1.48642,8.50000
10.26000,8.54994,13.38781,0.07435,1.48753,8.54994
10.32000,8.59994,13.55969,0.07478,1.50663,8.59994
10.38000,8.65006,13.55367,0.07522,1.50596,8.65006
10.44000,8.70000,13.64965,0.07565,1.51663,8.70000
10.50000,8.75000,13.35891,0.07609,1.48432,8.75000
10.56000,8.80000,13.75817,0.07652,1.52869,8.80000
10.62000,8.85006,13.77955,0.07696,1.53106,8.85006
10.68000,8.90006,13.52462,0.07739,1.50274,8.90006
10.74000,8.95006,13.57779,0.07783,1.50864,8.95006
10.80000,9.00000,13.87217,0.07826,1.54135,9.00000
10.86000,9.05000,13.94540,0.07870,1.54949,9.05000
10.92000,9.10006,13.85880,0.07913,1.53987,9.10006
10.98000,9.15006,14.03369,0.07957,1.55930,9.15006
11.04000,9.20000,14.12353,0.08000,1.56928,9.20000
11.10000,9.25000,14.15549,0.08043,1.57283,9.25000
11.16000,9.30000,14.13308,0.08087,1.57034,9.30000
11.22000,9.35000,14.23033,0.08130,1.58115,9.35000
11.28000,9.40000,14.25306,0.08174,1.58367,9.40000
11.34000,9.45000,14.10224,0.08217,1.56692,9.45000
11.40000,9.50000,14.51213,0.08261,1.61246,9.50000
11.46000,9.55000,14.28284,0.08304,1.58698,9.55000
11.52000,9.60000,14.41752,0.08348,1.60195,9.60000
11.58000,9.65000,14.31676,0.08391,1.59075,9.65000
11.64000,9.69994,14.78481,0.08435,1.64276,9.69994
11.70000,9.75000,14.58325,0.08478,1.62036,9.75000
11.76000,9.80006,14.61122,0.08522,1.62347,9.80006
11.82000,9.85012,14.50791,0.08565,1.61199,9.85012
11.88000,9.90006,14.62476,0.08609,1.62497,9.90006
11.94000,9.94994,14.58126,0.08652,1.62014,9.94994
12.00000,10.00000,14.74105,0.08696,1.63789,10.00000
12.06000,10.05000,14.86455,0.08739,1.65162,10.05000
12.12000,10.10000,14.76803,0.08783,1.64089,10.10000
12.18000,10.15000,14.81930,0.08826,1.64659,10.15000
12.24000,10.19994,15.07484,0.08870,1.67498,10.19994
12.30000,10.25000,15.06342,0.08913,1.67371,10.25000
12.36000,10.29994,15.15762,0.08956,1.68418,10.29994
12.42000,10.34994,15.20912,0.09000,1.68990,10.34994
12.48000,10.40006,15.13239,0.09044,1.68138,10.40006
12.54000,10.45000,15.25756,0.09087,1.69528,10.45000
12.60000,10.49994,15.40845,0.09130,1.71205,10.49994
12.66000,10.55000,15.24013,0.09174,1.69335,10.55000
12.72000,10.60000,15.36677,0.09217,1.70742,10.60000
12.78000,10.65006,15.51009,0.09261,1.72334,10.65006
12.84000,10.70006,15.43961,0.09304,1.71551,10.70006
12.90000,10.75000,15.53152,0.09348,1.72572,10.75000
12.96000,10.80006,15.34412,0.09391,1.70490,10.80006
13.02000,10.85006,15.31732,0.09435,1.70192,10.85006
13.08000,10.90000,15.85263,0.09478,1.76140,10.90000
13.14000,10.94994,15.64193,0.09522,1.73799,10.94994
13.20000,11.00000,15.56446,0.09565,1.72938,11.00000
13.26000,11.05000,15.68119,0.09609,1.74235,11.05000
13.32000,11.10006,15.79541,0.09652,1.75505,11.10006
13.38000,11.15006,16.13503,0.09696,1.79278,11.15006
13.44000,11.19994,15.84542,0.09739,1.76060,11.19994
13.50000,11.24994,15.78606,0.09783,1.75401,11.24994
13.56000,11.29994,15.85409,0.09826,1.76157,11.29994
13.62000,11.35000,16.18272,0.09870,1.79808,11.35000
13.68000,11.40012,16.03939,0.09913,1.78215,11.40012
13.74000,11.45006,15.93477,0.09957,1.77053,11.45006
13.80000,11.49994,16.22144,0.10000,1.80238,11.49994
13.86000,11.54994,16.20581,0.10043,1.80065,11.54994
13.92000,11.60006,16.23197,0.10087,1.80355,11.60006
13.98000,11.65006,16.31475,0.10130,1.81275,11.65006
14.04000,11.70000,16.23248,0.10174,1.80361,11.70000
14.10000,11.75000,16.36799,0.10217,1.81867,11.75000
14.16000,11.80000,16.39359,0.10261,1.82151,11.80000
14.22000,11.85000,16.42824,0.10304,1.82536,11.85000
14.28000,11.90000,16.45569,0.10348,1.82841,11.90000
14.34000,11.95000,16.57100,0.10391,1.84122,11.95000
14.40000,12.00000,16.44810,0.10435,1.82757,12.00000
14.46000,12.04994,16.71591,0.10478,1.85732,12.04994
14.52000,12.09993,16.80572,0.10522,1.86730,12.09993
14.58000,12.15000,16.72355,0.10565,1.85817,12.15000
14.64000,12.20000,16.63286,0.10609,1.84810,12.20000
14.70000,12.25000,16.78221,0.10652,1.86469,12.25000
14.76000,12.30000,16.79979,0.10696,1.86664,12.30000
14.82000,12.35006,16.96095,0.10739,1.88455,12.35006
14.88000,12.40012,17.03278,0.10783,1.89253,12.40012
14.94000,12.45000,16.79761,0.10826,1.86640,12.45000
15.00000,12.50000,17.03770,0.10870,1.89308,12.50000
15.06000,12.55000,17.00317,0.10913,1.88924,12.55000
15.12000,12.60006,17.23914,0.10957,1.91546,12.60006
15.18000,12.65006,17.11948,0.11000,1.90216,12.65006
15.24000,12.70000,17.08784,0.11043,1.89865,12.70000
15.30000,12.74994,17.11064,0.11087,1.90118,12.74994
15.36000,12.79994,17.11722,0.11130,1.90191,12.79994
15.42000,12.84994,17.28014,0.11174,1.92002,12.84994
15.48000,12.90006,17.44163,0.11217,1.93796,12.90006
15.54000,12.95000,17.39674,0.11261,1.93297,12.95000
15.60000,13.00006,17.45351,0.11304,1.93928,13.00006
15.66000,13.05000,17.44869,0.11348,1.93874,13.05000
15.72000,13.09994,17.50205,0.11391,1.94467,13.09994
15.78000,13.15000,17.62326,0.11435,1.95814,13.15000
15.84000,13.20000,17.65623,0.11478,1.96180,13.20000
15.90000,13.25000,17.69884,0.11522,1.96654,13.25000
15.96000,13.30000,17.59331,0.11565,1.95481,13.30000
16.02000,13.35006,17.69269,0.11609,1.96585,13.35006
16.08000,13.40006,17.56534,0.11652,1.95170,13.40006
16.14000,13.45000,17.73117,0.11696,1.97013,13.45000
16.20000,13.50000,17.65503,0.11739,1.96167,13.50000
16.26000,13.55000,17.80748,0.11783,1.97861,13.55000
16.32000,13.60006,17.78390,0.11826,1.97599,13.60006
16.38000,13.65000,17.98220,0.11870,1.99802,13.65000
16.44000,13.70000,17.87934,0.11913,1.98659,13.70000
16.50000,13.75000,17.98519,0.11957,1.99835,13.75000
16.56000,13.79994,18.01485,0.12000,2.00165,13.79994
16.62000,13.84994,18.01397,0.12043,2.00155,13.84994
16.68000,13.90000,17.93893,0.12087,1.99321,13.90000
16.74000,13.95000,18.03368,0.12130,2.00374,13.95000
16.80000,14.00000,18.20862,0.12174,2.02318,14.00000
16.86000,14.05000,18.27294,0.12217,2.03033,14.05000
16.92000,14.10000,18.12979,0.12261,2.01442,14.10000
16.98000,14.15006,18.22440,0.12304,2.02493,14.15006
17.04000,14.20000,18.20615,0.12348,2.02291,14.20000
17.10000,14.25000,18.27245,0.12391,2.03027,14.25000
17.16000,14.30006,18.36906,0.12435,2.04101,14.30006
17.22000,14.35000,18.19569,0.12478,2.02174,14.35000
17.28000,14.40000,18.30367,0.12522,2.03374,14.40000
17.34000,14.45000,18.56815,0.12565,2.06313,14.45000
17.40000,14.50000,18.42606,0.12609,2.04734,14.50000
17.46000,14.55000,18.50565,0.12652,2.05618,14.55000
17.52000,14.60006,18.55490,0.12696,2.06166,14.60006
17.58000,14.65000,18.62514,0.12739,2.06946,14.65000
17.64000,14.69987,18.50090,0.12782,2.05566,14.69987
17.70000,14.74994,18.91047,0.12826,2.10116,14.74994
17.76000,14.79994,18.66984,0.12870,2.07443,14.79994
17.82000,14.85000,18.63352,0.12913,2.07039,14.85000
17.88000,14.90006,18.84436,0.12957,2.09382,14.90006
17.94000,14.95000,18.85649,0.13000,2.09517,14.95000
18.00000,14.99994,18.77807,0.13043,2.08645,14.99994
18.06000,15.05000,18.89876,0.13087,2.09986,15.05000
18.12000,15.10006,18.89560,0.13130,2.09951,15.10006
18.18000,15.15006,18.76959,0.13174,2.08551,15.15006
18.24000,15.20000,18.85152,0.13217,2.09461,15.20000
18.30000,15.25000,18.98276,0.13261,2.10920,15.25000
18.36000,15.30000,18.86646,0.13304,2.09627,15.30000
18.42000,15.35006,19.15550,0.13348,2.12839,15.35006
18.48000,15.40000,19.10387,0.13391,2.12265,15.40000
18.54000,15.44994,19.14247,0.13435,2.12694,15.44994
18.60000,15.49994,18.85543,0.13478,2.09505,15.49994
18.66000,15.54994,19.23720,0.13522,2.13747,15.54994
18.72000,15.60000,19.13490,0.13565,2.12610,15.60000
18.78000,15.65000,19.02185,0.13609,2.11354,15.65000
18.84000,15.69993,19.23782,0.13652,2.13754,15.69993
18.90000,15.74993,19.37876,0.13696,2.15320,15.74993
18.96000,15.79993,19.24759,0.13739,2.13862,15.79993
19.02000,15.85000,19.28594,0.13783,2.14288,15.85000
19.08000,15.90006,19.08741,0.13826,2.12082,15.90006
19.14000,15.94994,19.44685,0.13870,2.16076,15.94994
19.20000,16.00000,19.38956,0.13913,2.15440,16.00000
19.26000,16.05000,19.47141,0.13957,2.16349,16.05000
19.32000,16.10006,19.42206,0.14000,2.15801,16.10006
19.38000,16.15012,19.57969,0.14044,2.17552,16.15012
19.44000,16.20012,19.48038,0.14087,2.16449,16.20012
19.50000,16.25000,19.44792,0.14130,2.16088,16.25000
19.56000,16.29987,19.42564,0.14174,2.15840,16.29987
19.62000,16.35000,19.60868,0.14217,2.17874,16.35000
19.68000,16.40000,19.67927,0.14261,2.18659,16.40000
19.74000,16.44993,19.43585,0.14304,2.15954,16.44993
19.80000,16.50000,19.54729,0.14348,2.17192,16.50000
19.86000,16.54994,19.85484,0.14391,2.20609,16.54994
19.92000,16.60000,19.80101,0.14435,2.20011,16.60000
19.98000,16.65000,19.87723,0.14478,2.20858,16.65000
20.04000,16.70000,19.67266,0.14522,2.18585,16.70000
20.10000,16.75000,19.75443,0.14565,2.19494,16.75000
20.16000,16.80000,19.88845,0.14609,2.20983,16.80000
20.22000,16.85006,19.81240,0.14652,2.20138,16.85006
20.28000,16.90006,19.79202,0.14696,2.19911,16.90006
20.34000,16.95006,20.07225,0.14739,2.23025,16.95006
20.40000,17.00000,19.86807,0.14783,2.20756,17.00000
20.46000,17.05000,20.05736,0.14826,2.22860,17.05000
20.52000,17.10000,19.95298,0.14870,2.21700,17.10000
20.58000,17.15006,20.00397,0.14913,2.22266,17.15006
20.64000,17.19994,20.28702,0.14956,2.25411,17.19994
20.70000,17.24993,20.02261,0.15000,2.22473,17.24993
20.76000,17.29993,20.29444,0.15043,2.25494,17.29993
20.82000,17.35000,20.10458,0.15087,2.23384,17.35000
20.88000,17.40006,20.28520,0.15130,2.25391,17.40006
20.94000,17.44993,20.13490,0.15174,2.23721,17.44993
21.00000,17.50000,20.03897,0.15217,2.22655,17.50000
21.06000,17.54993,20.35143,0.15261,2.26127,17.54993
21.12000,17.59993,20.22882,0.15304,2.24765,17.59993
21.18000,17.65000,20.25829,0.15348,2.25092,17.65000
21.24000,17.70000,20.21496,0.15391,2.24611,17.70000
21.30000,17.75006,20.27061,0.15435,2.25229,17.75006
21.36000,17.80012,20.60187,0.15478,2.28910,17.80012
21.42000,17.85006,20.51133,0.15522,2.27904,17.85006
21.48000,17.90000,20.33529,0.15565,2.25948,17.90000
21.54000,17.95000,20.46362,0.15609,2.27374,17.95000
21.60000,17.99993,20.56499,0.15652,2.28500,17.99993
21.66000,18.05000,20.59604,0.15696,2.28845,18.05000
21.72000,18.10000,20.55701,0.15739,2.28411,18.10000
21.78000,18.15000,20.63856,0.15783,2.29317,18.15000
21.84000,18.19994,20.63800,0.15826,2.29311,18.19994
21.90000,18.25000,20.51608,0.15870,2.27956,18.25000
21.96000,18.30000,20.61003,0.15913,2.29000,18.30000
22.02000,18.35000,20.60883,0.15957,2.28987,18.35000
22.08000,18.40006,20.65906,0.16000,2.29545,18.40006
22.14000,18.45006,20.54819,0.16044,2.28313,18.45006
22.20000,18.50006,20.81664,0.16087,2.31296,18.50006
22.26000,18.55000,20.75893,0.16130,2.30655,18.55000
22.32000,18.60006,20.72641,0.16174,2.30293,18.60006
22.38000,18.65006,20.77424,0.16217,2.30825,18.65006
22.44000,18.70006,20.84485,0.16261,2.31609,18.70006
22.50000,18.75006,20.91622,0.16304,2.32402,18.75006
22.56000,18.79993,20.80637,0.16348,2.31182,18.79993
22.62000,18.84994,20.88996,0.16391,2.32111,18.84994
22.68000,18.90000,20.96130,0.16435,2.32903,18.90000
22.74000,18.95000,21.04595,0.16478,2.33844,18.95000
22.80000,19.00000,21.00399,0.16522,2.33378,19.00000
22.86000,19.05000,20.98727,0.16565,2.33192,19.05000
22.92000,19.10000,21.09554,0.16609,2.34395,19.10000
22.98000,19.15000,21.12209,0.16652,2.34690,19.15000
23.04000,19.19993,21.01942,0.16696,2.33549,19.19993
23.10000,19.24993,21.04178,0.16739,2.33798,19.24993
23.16000,19.30000,21.07671,0.16783,2.34186,19.30000
23.22000,19.35012,21.21026,0.16826,2.35670,19.35012
23.28000,19.40006,21.10531,0.16870,2.34503,19.40006
23.34000,19.44987,21.32468,0.16913,2.36941,19.44987
23.40000,19.49994,21.42311,0.16956,2.38035,19.49994
23.46000,19.54993,21.31153,0.17000,2.36795,19.54993
23.52000,19.60006,21.24158,0.17044,2.36018,19.60006
23.58000,19.65006,21.38446,0.17087,2.37605,19.65006
23.64000,19.70000,21.21374,0.17130,2.35708,19.70000
23.70000,19.75000,21.38192,0.17174,2.37577,19.75000
23.76000,19.80006,21.23350,0.17217,2.35928,19.80006
23.82000,19.85006,21.20585,0.17261,2.35621,19.85006
23.88000,19.90006,21.35933,0.17304,2.37326,19.90006
23.94000,19.95000,21.47672,0.17348,2.38630,19.95000
24.00000,19.99993,21.42020,0.17391,2.38002,19.99993
24.06000,20.04993,21.24185,0.17435,2.36021,20.04993
24.12000,20.10000,21.79481,0.17478,2.42165,20.10000
24.18000,20.15000,21.55056,0.17522,2.39451,20.15000
24.24000,20.19993,21.38015,0.17565,2.37557,20.19993
24.30000,20.24994,21.51735,0.17609,2.39082,20.24994
24.36000,20.30000,21.71144,0.17652,2.41238,20.30000
24.42000,20.35000,21.57709,0.17696,2.39745,20.35000
24.48000,20.40006,21.62604,0.17739,2.40289,20.40006
24.54000,20.44993,21.51926,0.17783,2.39103,20.44993
24.60000,20.49993,21.88820,0.17826,2.43202,20.49993
24.66000,20.55006,21.72349,0.17870,2.41372,20.55006
24.72000,20.60006,21.70880,0.17913,2.41209,20.60006
24.78000,20.65012,21.57079,0.17957,2.39675,20.65012
24.84000,20.70000,21.75879,0.18000,2.41764,20.70000
24.90000,20.74993,21.90845,0.18043,2.43427,20.74993
24.96000,20.80000,21.79986,0.18087,2.42221,20.80000
25.02000,20.85000,21.89941,0.18130,2.43327,20.85000
25.08000,20.90000,21.97539,0.18174,2.44171,20.90000
25.14000,20.95000,21.66912,0.18217,2.40768,20.95000
25.20000,21.00000,22.09818,0.18261,2.45535,21.00000
25.26000,21.04987,21.90057,0.18304,2.43340,21.04987
25.32000,21.09993,21.86025,0.18348,2.42892,21.09993
25.38000,21.15006,22.00867,0.18391,2.44541,21.15006
25.44000,21.20000,21.91707,0.18435,2.43523,21.20000
25.50000,21.24993,22.10178,0.18478,2.45575,21.24993
25.56000,21.30000,22.08263,0.18522,2.45363,21.30000
25.62000,21.34999,22.03566,0.18565,2.44841,21.34999
25.68000,21.40012,22.18723,0.18609,2.46525,21.40012
25.74000,21.45006,22.15980,0.18652,2.46220,21.45006
25.80000,21.50000,22.24182,0.18696,2.47131,21.50000
25.86000,21.55006,22.14555,0.18739,2.46062,21.55006
25.92000,21.60000,22.16421,0.18783,2.46269,21.60000
25.98000,21.65006,22.19480,0.18826,2.46609,21.65006
26.04000,21.70000,22.20364,0.18870,2.46707,21.70000
26.10000,21.74993,22.36306,0.18913,2.48478,21.74993
26.16000,21.79994,22.28464,0.18956,2.47607,21.79994
26.22000,21.85000,22.13639,0.19000,2.45960,21.85000
26.28000,21.90000,22.44561,0.19043,2.49396,21.90000
26.34000,21.95000,22.45610,0.19087,2.49512,21.95000
26.40000,21.99993,22.46611,0.19130,2.49623,21.99993
26.46000,22.04994,22.32629,0.19174,2.48070,22.04994
26.52000,22.10000,22.49325,0.19217,2.49925,22.10000
26.58000,22.15006,22.45389,0.19261,2.49488,22.15006
26.64000,22.20000,22.67951,0.19304,2.51995,22.20000
26.70000,22.25006,22.47863,0.19348,2.49763,22.25006
26.76000,22.30000,22.45987,0.19391,2.49554,22.30000
26.82000,22.35000,22.42830,0.19435,2.49203,22.35000
26.88000,22.40006,22.71066,0.19478,2.52341,22.40006
26.94000,22.45000,22.66075,0.19522,2.51786,22.45000
27.00000,22.50000,22.91685,0.19565,2.54632,22.50000
27.06000,22.55000,22.43675,0.19609,2.49297,22.55000
27.12000,22.60006,22.71979,0.19652,2.52442,22.60006
27.18000,22.64993,22.48632,0.19696,2.49848,22.64993
27.24000,22.69994,22.63714,0.19739,2.51524,22.69994
27.30000,22.74993,22.92870,0.19783,2.54763,22.74993
27.36000,22.79993,22.58237,0.19826,2.50915,22.79993
27.42000,22.85000,22.80473,0.19870,2.53386,22.85000
27.48000,22.90006,23.01577,0.19913,2.55731,22.90006
27.54000,22.95000,22.86672,0.19957,2.54075,22.95000
27.60000,23.00000,22.74938,0.20000,2.52771,23.00000
27.66000,23.05006,22.86706,0.20044,2.54078,23.05006
27.72000,23.10006,22.96953,0.20087,2.55217,23.10006
27.78000,23.15012,22.69048,0.20131,2.52116,23.15012
27.84000,23.20000,23.00245,0.20174,2.55583,23.20000
27.90000,23.25000,23.04097,0.20217,2.56011,23.25000
27.96000,23.30000,22.91751,0.20261,2.54639,23.30000
28.02000,23.35000,23.12069,0.20304,2.56897,23.35000
28.08000,23.40000,23.01932,0.20348,2.55770,23.40000
28.14000,23.44999,23.08087,0.20391,2.56454,23.44999
28.20000,23.50000,22.99390,0.20435,2.55488,23.50000
28.26000,23.55000,23.26541,0.20478,2.58505,23.55000
28.32000,23.60000,23.14469,0.20522,2.57163,23.60000
28.38000,23.65000,23.34792,0.20565,2.59421,23.65000
28.44000,23.69993,23.18799,0.20609,2.57644,23.69993
28.50000,23.75000,23.33989,0.20652,2.59332,23.75000
28.56000,23.79999,23.21882,0.20696,2.57987,23.79999
28.62000,23.85000,23.30266,0.20739,2.58918,23.85000
28.68000,23.90000,23.36646,0.20783,2.59627,23.90000
28.74000,23.95000,23.37922,0.20826,2.59769,23.95000
28.80000,24.00000,23.24640,0.20870,2.58293,24.00000
28.86000,24.05006,23.32416,0.20913,2.59157,24.05006
28.92000,24.10006,23.29462,0.20957,2.58829,24.10006
28.98000,24.15012,23.24459,0.21000,2.58273,24.15012
29.04000,24.20000,23.56684,0.21043,2.61854,24.20000
29.10000,24.24987,23.51377,0.21087,2.61264,24.24987
29.16000,24.29993,23.47730,0.21130,2.60859,24.29993
29.22000,24.35000,23.44711,0.21174,2.60523,24.35000
29.28000,24.40000,23.26009,0.21217,2.58445,24.40000
29.34000,24.44993,23.43153,0.21261,2.60350,24.44993
29.40000,24.49993,23.56018,0.21304,2.61780,24.49993
29.46000,24.54993,23.56290,0.21348,2.61810,24.54993
29.52000,24.60000,23.48796,0.21391,2.60977,24.60000
29.58000,24.65006,23.51220,0.21435,2.61247,24.65006
29.64000,24.70006,23.55913,0.21478,2.61768,24.70006
29.70000,24.75000,23.60123,0.21522,2.62236,24.75000
29.76000,24.80000,23.65758,0.21565,2.62862,24.80000
29.82000,24.85000,23.52646,0.21609,2.61405,24.85000
29.88000,24.90006,23.89326,0.21652,2.65481,24.90006
29.94000,24.95000,23.73000,0.21696,2.63667,24.95000
30.00000,25.00006,24.01155,0.21739,2.66795,25.00006
30.06000,25.05000,23.82359,0.21783,2.64706,25.05000
30.12000,25.10000,23.71066,0.21826,2.63452,25.10000
30.18000,25.15006,23.96975,0.21870,2.66331,25.15006
30.24000,25.20000,23.68817,0.21913,2.63202,25.20000
30.30000,25.24993,23.93443,0.21956,2.65938,25.24993
30.36000,25.30000,23.92461,0.22000,2.65829,25.30000
30.42000,25.35000,23.92870,0.22043,2.65874,25.35000
30.48000,25.40000,23.98856,0.22087,2.66540,25.40000
30.54000,25.45000,24.11709,0.22130,2.67968,25.45000
30.60000,25.49987,23.97367,0.22174,2.66374,25.49987
30.66000,25.54993,24.00494,0.22217,2.66722,25.54993
30.72000,25.60000,24.11101,0.22261,2.67900,25.60000
30.78000,25.65006,24.09598,0.22304,2.67733,25.65006
30.84000,25.70006,23.93477,0.22348,2.65942,25.70006
30.90000,25.75006,24.12612,0.22391,2.68068,25.75006
30.96000,25.79993,24.01616,0.22435,2.66846,25.79993
31.02000,25.84993,24.25130,0.22478,2.69459,25.84993
31.08000,25.90006,24.32409,0.22522,2.70268,25.90006
31.14000,25.95006,24.34466,0.22565,2.70496,25.95006
31.20000,26.00000,24.29359,0.22609,2.69929,26.00000
31.26000,26.05000,24.30371,0.22652,2.70041,26.05000
31.32000,26.10000,24.23758,0.22696,2.69306,26.10000
31.38000,26.15006,24.29901,0.22739,2.69989,26.15006
31.44000,26.19993,24.39940,0.22783,2.71104,26.19993
31.50000,26.25000,24.38561,0.22826,2.70951,26.25000
31.56000,26.30000,24.23031,0.22870,2.69226,26.30000
31.62000,26.35000,24.32573,0.22913,2.70286,26.35000
31.68000,26.40000,24.47120,0.22957,2.71902,26.40000
31.74000,26.45000,24.61700,0.23000,2.73522,26.45000
31.80000,26.50000,24.64786,0.23043,2.73865,26.50000
31.86000,26.54999,24.39648,0.23087,2.71072,26.54999
31.92000,26.60000,24.55215,0.23130,2.72802,26.60000
31.98000,26.65006,24.50380,0.23174,2.72264,26.65006
32.04000,26.70000,24.47955,0.23217,2.71995,26.70000
32.10000,26.75000,24.57110,0.23261,2.73012,26.75000
32.16000,26.80000,24.61203,0.23304,2.73467,26.80000
32.22000,26.85006,24.55766,0.23348,2.72863,26.85006
32.28000,26.90012,24.68734,0.23391,2.74304,26.90012
32.34000,26.95006,24.65787,0.23435,2.73976,26.95006
32.40000,27.00000,24.67644,0.23478,2.74183,27.00000
32.46000,27.05000,24.83798,0.23522,2.75978,27.05000
32.52000,27.10000,24.81932,0.23565,2.75770,27.10000
32.58000,27.14993,24.75618,0.23609,2.75069,27.14993
32.64000,27.19993,24.93778,0.23652,2.77086,27.19993
32.70000,27.24993,24.83563,0.23696,2.75951,27.24993
32.76000,27.29993,24.73992,0.23739,2.74888,27.29993
32.82000,27.35000,24.87827,0.23783,2.76425,27.35000
32.88000,27.39993,24.80303,0.23826,2.75589,27.39993
32.94000,27.44993,25.05720,0.23870,2.78413,27.44993
33.00000,27.49993,24.84298,0.23913,2.76033,27.49993
33.06000,27.54994,25.09330,0.23956,2.78814,27.54994
33.12000,27.60006,24.96945,0.24000,2.77438,27.60006
33.18000,27.65012,25.00656,0.24044,2.77851,27.65012
33.24000,27.70000,25.17082,0.24087,2.79676,27.70000
33.30000,27.74999,25.15534,0.24130,2.79504,27.74999
33.36000,27.80000,24.94736,0.24174,2.77193,27.80000
33.42000,27.85006,24.96340,0.24217,2.77371,27.85006
33.48000,27.90000,25.28078,0.24261,2.80898,27.90000
33.54000,27.94993,25.09475,0.24304,2.78831,27.94993
33.60000,27.99993,25.15184,0.24348,2.79465,27.99993
33.66000,28.05000,25.00016,0.24391,2.77780,28.05000
33.72000,28.10000,25.09342,0.24435,2.78816,28.10000
33.78000,28.15000,25.27371,0.24478,2.80819,28.15000
33.84000,28.20000,25.30018,0.24522,2.81113,28.20000
33.90000,28.25000,25.26920,0.24565,2.80769,28.25000
33.96000,28.30000,25.28806,0.24609,2.80978,28.30000
34.02000,28.35006,25.33361,0.24652,2.81485,28.35006
34.08000,28.40006,25.35692,0.24696,2.81744,28.40006
34.14000,28.45000,25.33057,0.24739,2.81451,28.45000
34.20000,28.50006,25.52207,0.24783,2.83579,28.50006
34.26000,28.55006,25.37632,0.24826,2.81959,28.55006
34.32000,28.60012,25.36694,0.24870,2.81855,28.60012
34.38000,28.65006,25.44556,0.24913,2.82728,28.65006
34.44000,28.69993,25.51881,0.24956,2.83542,28.69993
34.50000,28.74993,25.41992,0.25000,2.82444,28.74993
34.56000,28.80000,25.57421,0.25043,2.84158,28.80000
34.62000,28.85000,25.39812,0.25087,2.82201,28.85000
34.68000,28.90006,25.51516,0.25130,2.83502,28.90006
34.74000,28.94999,25.62496,0.25174,2.84722,28.94999
34.80000,28.99981,25.61002,0.25217,2.84556,28.99981
34.86000,29.04993,25.59740,0.25261,2.84416,29.04993
34.92000,29.10000,25.70203,0.25304,2.85578,29.10000
34.98000,29.15000,25.80208,0.25348,2.86690,29.15000
35.04000,29.20000,25.74234,0.25391,2.86026,29.20000
35.10000,29.24993,25.75415,0.25435,2.86157,29.24993
35.16000,29.29999,25.76683,0.25478,2.86298,29.29999
35.22000,29.35006,25.76608,0.25522,2.86290,29.35006
35.28000,29.40006,25.78434,0.25565,2.86493,29.40006
35.34000,29.45000,25.90484,0.25609,2.87832,29.45000
35.40000,29.50000,25.89127,0.25652,2.87681,29.50000
35.46000,29.55000,25.76561,0.25696,2.86285,29.55000
35.52000,29.59999,25.84393,0.25739,2.87155,29.59999
35.58000,29.65000,25.83183,0.25783,2.87020,29.65000
35.64000,29.69993,25.74359,0.25826,2.86040,29.69993
35.70000,29.74994,25.83725,0.25870,2.87081,29.74994
35.76000,29.79993,25.90327,0.25913,2.87814,29.79993
35.82000,29.85000,26.02269,0.25957,2.89141,29.85000
35.88000,29.90006,26.24174,0.26000,2.91575,29.90006
35.94000,29.94993,25.95921,0.26043,2.88436,29.94993
36.00000,29.99987,26.10613,0.26087,2.90068,29.99987
36.06000,30.04993,26.05495,0.26130,2.89499,30.04993
36.12000,30.10006,26.10863,0.26174,2.90096,30.10006
36.18000,30.15006,26.07755,0.26217,2.89751,30.15006
36.24000,30.20006,26.26760,0.26261,2.91862,30.20006
36.30000,30.25000,26.18144,0.26304,2.90905,30.25000
36.36000,30.30000,26.29185,0.26348,2.92132,30.30000
36.42000,30.35000,26.22158,0.26391,2.91351,30.35000
36.48000,30.40006,26.19879,0.26435,2.91098,30.40006
36.54000,30.45000,26.08664,0.26478,2.89852,30.45000
36.60000,30.49999,26.32190,0.26522,2.92466,30.49999
36.66000,30.55000,26.42898,0.26565,2.93655,30.55000
36.72000,30.59993,26.46419,0.26609,2.94047,30.59993
36.78000,30.65000,26.33055,0.26652,2.92562,30.65000
36.84000,30.69993,26.36816,0.26696,2.92980,30.69993
36.90000,30.74993,26.56299,0.26739,2.95144,30.74993
36.96000,30.80000,26.31904,0.26783,2.92434,30.80000
37.02000,30.84993,26.49594,0.26826,2.94399,30.84993
37.08000,30.90000,26.37669,0.26870,2.93074,30.90000
37.14000,30.94994,26.38227,0.26913,2.93136,30.94994
37.20000,31.00000,26.50215,0.26957,2.94468,31.00000
37.26000,31.05000,26.43108,0.27000,2.93679,31.05000
37.32000,31.10006,26.40848,0.27044,2.93428,31.10006
37.38000,31.15006,26.50343,0.27087,2.94483,31.15006
37.44000,31.20000,26.55520,0.27130,2.95058,31.20000
37.50000,31.25000,26.63017,0.27174,2.95891,31.25000
37.56000,31.30006,26.62679,0.27217,2.95853,31.30006
37.62000,31.35006,26.34279,0.27261,2.92698,31.35006
37.68000,31.39999,26.56733,0.27304,2.95193,31.39999
37.74000,31.45000,26.80756,0.27348,2.97862,31.45000
37.80000,31.49999,26.61046,0.27391,2.95672,31.49999
37.86000,31.54999,26.77501,0.27435,2.97500,31.54999
37.92000,31.60000,26.74357,0.27478,2.97151,31.60000
37.98000,31.65005,26.65172,0.27522,2.96130,31.65005
38.04000,31.69993,26.80722,0.27565,2.97858,31.69993
38.10000,31.74993,26.82767,0.27609,2.98085,31.74993
38.16000,31.80000,26.92401,0.27652,2.99156,31.80000
38.22000,31.85000,26.74454,0.27696,2.97162,31.85000
38.28000,31.90006,26.83445,0.27739,2.98161,31.90006
38.34000,31.94993,26.88096,0.27783,2.98677,31.94993
38.40000,31.99999,27.01586,0.27826,3.00176,31.99999
38.46000,32.05006,26.85483,0.27870,2.98387,32.05006
38.52000,32.10012,26.95703,0.27913,2.99523,32.10012
38.58000,32.14999,27.08037,0.27957,3.00893,32.14999
38.64000,32.19993,26.97177,0.28000,2.99686,32.19993
38.70000,32.24999,27.00684,0.28043,3.00076,32.24999
38.76000,32.30006,26.85902,0.28087,2.98434,32.30006
38.82000,32.34999,27.12357,0.28130,3.01373,32.34999
38.88000,32.40006,27.20380,0.28174,3.02264,32.40006
38.94000,32.44993,26.98490,0.28217,2.99832,32.44993
39.00000,32.49993,26.97163,0.28261,2.99685,32.49993
39.06000,32.54993,27.23091,0.28304,3.02566,32.54993
39.12000,32.59999,27.09592,0.28348,3.01066,32.59999
39.18000,32.65006,27.24928,0.28391,3.02770,32.65006
39.24000,32.70000,27.11705,0.28435,3.01301,32.70000
39.30000,32.74993,27.19697,0.28478,3.02189,32.74993
39.36000,32.79999,27.28617,0.28522,3.03180,32.79999
39.42000,32.85006,27.29199,0.28565,3.03244,32.85006
39.48000,32.89999,27.08742,0.28609,3.00971,32.89999
39.54000,32.94999,27.36601,0.28652,3.04067,32.94999
39.60000,33.00000,27.48197,0.28696,3.05355,33.00000
39.66000,33.05006,27.33057,0.28739,3.03673,33.05006
39.72000,33.10006,27.37720,0.28783,3.04191,33.10006
39.78000,33.15006,27.41136,0.28826,3.04571,33.15006
39.84000,33.20000,27.38031,0.28870,3.04226,33.20000
39.90000,33.24999,27.44955,0.28913,3.04995,33.24999
39.96000,33.30000,27.45165,0.28957,3.05018,33.30000
40.02000,33.35006,27.23642,0.29000,3.02627,33.35006
40.08000,33.40000,27.40566,0.29043,3.04507,33.40000
40.14000,33.44993,27.38993,0.29087,3.04333,33.44993
40.20000,33.49993,27.70612,0.29130,3.07846,33.49993
40.26000,33.54999,27.60433,0.29174,3.06715,33.54999
40.32000,33.60000,27.67019,0.29217,3.07447,33.60000
40.38000,33.65012,27.65946,0.29261,3.07327,33.65012
40.44000,33.69999,27.58366,0.29304,3.06485,33.69999
40.50000,33.74993,27.67357,0.29348,3.07484,33.74993
40.56000,33.79993,27.62194,0.29391,3.06910,33.79993
40.62000,33.85000,27.65963,0.29435,3.07329,33.85000
40.68000,33.90006,27.64462,0.29478,3.07162,33.90006
40.74000,33.94999,27.68478,0.29522,3.07609,33.94999
40.80000,34.00000,27.89271,0.29565,3.09919,34.00000
40.86000,34.04993,27.85404,0.29609,3.09489,34.04993
40.92000,34.10000,27.76791,0.29652,3.08532,34.10000
40.98000,34.15006,27.67663,0.29696,3.07518,34.15006
41.04000,34.19999,27.81339,0.29739,3.09038,34.19999
41.10000,34.24993,27.85536,0.29783,3.09504,34.24993
41.16000,34.30000,27.66179,0.29826,3.07353,34.30000
41.22000,34.34999,27.91125,0.29870,3.10125,34.34999
41.28000,34.40006,27.83442,0.29913,3.09271,34.40006
41.34000,34.44999,27.89543,0.29957,3.09949,34.44999
41.40000,34.49993,28.00187,0.30000,3.11132,34.49993
41.46000,34.54999,27.94934,0.30043,3.10548,34.54999
41.52000,34.59999,27.93139,0.30087,3.10349,34.59999
41.58000,34.65006,27.93513,0.30130,3.10390,34.65006
41.64000,34.70000,27.92605,0.30174,3.10289,34.70000
41.70000,34.75000,28.03197,0.30217,3.11466,34.75000
41.76000,34.79999,28.10904,0.30261,3.12323,34.79999
41.82000,34.85006,28.12205,0.30304,3.12467,34.85006
41.88000,34.90012,28.05536,0.30348,3.11726,34.90012
41.94000,34.95000,28.18323,0.30391,3.13147,34.95000
42.00000,34.99999,28.19711,0.30435,3.13301,34.99999
42.06000,35.04993,27.98375,0.30478,3.10931,35.04993
42.12000,35.09999,28.03508,0.30522,3.11501,35.09999
42.18000,35.15000,28.15523,0.30565,3.12836,35.15000
42.24000,35.19993,28.22349,0.30609,3.13594,35.19993
42.30000,35.24999,28.36481,0.30652,3.15165,35.24999
42.36000,35.29999,28.13224,0.30696,3.12580,35.29999
42.42000,35.34993,28.29035,0.30739,3.14337,35.34993
42.48000,35.40000,28.24730,0.30783,3.13859,35.40000
42.54000,35.45006,28.29856,0.30826,3.14428,35.45006
42.60000,35.49999,28.53426,0.30870,3.17047,35.49999
42.66000,35.55000,28.44768,0.30913,3.16085,35.55000
42.72000,35.60000,28.44019,0.30957,3.16002,35.60000
42.78000,35.65006,28.44766,0.31000,3.16085,35.65006
42.84000,35.69999,28.35853,0.31043,3.15095,35.69999
42.90000,35.74993,28.50938,0.31087,3.16771,35.74993
42.96000,35.79993,28.38072,0.31130,3.15341,35.79993
43.02000,35.85000,28.53473,0.31174,3.17053,35.85000
43.08000,35.89999,28.36804,0.31217,3.15200,35.89999
43.14000,35.94993,28.43938,0.31261,3.15993,35.94993
43.20000,35.99993,28.48670,0.31304,3.16519,35.99993
43.26000,36.05000,28.53497,0.31348,3.17055,36.05000
43.32000,36.09999,28.66294,0.31391,3.18477,36.09999
43.38000,36.15006,28.49005,0.31435,3.16556,36.15006
43.44000,36.19999,28.45025,0.31478,3.16114,36.19999
43.50000,36.25000,28.62571,0.31522,3.18063,36.25000
43.56000,36.30000,28.63462,0.31565,3.18162,36.30000
43.62000,36.34999,28.79007,0.31609,3.19890,36.34999
43.68000,36.40006,28.72497,0.31652,3.19166,36.40006
43.74000,36.45000,28.76602,0.31696,3.19622,36.45000
43.80000,36.50000,28.65106,0.31739,3.18345,36.50000
43.86000,36.55006,28.65341,0.31783,3.18371,36.55006
43.92000,36.60006,28.75221,0.31826,3.19469,36.60006
43.98000,36.65006,28.45638,0.31870,3.16182,36.65006
44.04000,36.69993,28.81811,0.31913,3.20201,36.69993
44.10000,36.74999,28.81601,0.31957,3.20178,36.74999
44.16000,36.79999,28.85505,0.32000,3.20612,36.79999
44.22000,36.85012,28.81441,0.32044,3.20160,36.85012
44.28000,36.90006,29.08619,0.32087,3.23180,36.90006
44.34000,36.94993,28.86107,0.32130,3.20679,36.94993
44.40000,36.99993,28.81601,0.32174,3.20178,36.99993
44.46000,37.04993,28.83773,0.32217,3.20419,37.04993
44.52000,37.10000,28.61013,0.32261,3.17890,37.10000
44.58000,37.14993,28.90055,0.32304,3.21117,37.14993
44.64000,37.19993,28.85218,0.32348,3.20580,37.19993
44.70000,37.24999,28.86144,0.32391,3.20683,37.24999
44.76000,37.30000,29.05398,0.32435,3.22822,37.30000
44.82000,37.35006,29.13473,0.32478,3.23719,37.35006
44.88000,37.40012,29.07250,0.32522,3.23028,37.40012
44.94000,37.44999,29.04421,0.32565,3.22713,37.44999
45.00000,37.49999,29.18283,0.32609,3.24254,37.49999
45.06000,37.55006,29.16770,0.32652,3.24086,37.55006
45.12000,37.60006,28.96746,0.32696,3.21861,37.60006
45.18000,37.65006,29.03699,0.32739,3.22633,37.65006
45.24000,37.69999,29.09643,0.32783,3.23294,37.69999
45.30000,37.74999,29.29099,0.32826,3.25455,37.74999
45.36000,37.80000,29.10862,0.32870,3.23429,37.80000
45.42000,37.84999,29.04497,0.32913,3.22722,37.84999
45.48000,37.89999,29.24034,0.32957,3.24893,37.89999
45.54000,37.94987,29.27587,0.33000,3.25288,37.94987
45.60000,37.99993,29.29943,0.33043,3.25549,37.99993
45.66000,38.04993,29.40519,0.33087,3.26724,38.04993
45.72000,38.09999,29.36294,0.33130,3.26255,38.09999
45.78000,38.15006,29.42757,0.33174,3.26973,38.15006
45.84000,38.19993,29.25295,0.33217,3.25033,38.19993
45.90000,38.24993,29.33647,0.33261,3.25961,38.24993
45.96000,38.29993,29.47724,0.33304,3.27525,38.29993
46.02000,38.35006,29.39833,0.33348,3.26648,38.35006
46.08000,38.40012,29.34658,0.33391,3.26073,38.40012
46.14000,38.45006,29.47901,0.33435,3.27544,38.45006
46.20000,38.50000,29.42277,0.33478,3.26920,38.50000
46.26000,38.54993,29.30722,0.33522,3.25636,38.54993
46.32000,38.59999,29.55520,0.33565,3.28391,38.59999
46.38000,38.65006,29.42625,0.33609,3.26958,38.65006
46.44000,38.69993,29.59171,0.33652,3.28797,38.69993
46.50000,38.74993,29.21396,0.33696,3.24600,38.74993
46.56000,38.79993,29.54832,0.33739,3.28315,38.79993
46.62000,38.84993,29.50621,0.33783,3.27847,38.84993
46.68000,38.90000,29.55907,0.33826,3.28434,38.90000
46.74000,38.94999,29.46524,0.33870,3.27392,38.94999
46.80000,38.99993,29.51892,0.33913,3.27988,38.99993
46.86000,39.04999,29.62492,0.33957,3.29166,39.04999
46.92000,39.10006,29.55723,0.34000,3.28414,39.10006
46.98000,39.14999,29.52715,0.34043,3.28079,39.14999
47.04000,39.19999,29.48542,0.34087,3.27616,39.19999
47.10000,39.24999,29.57807,0.34130,3.28645,39.24999
47.16000,39.29999,29.60822,0.34174,3.28980,39.29999
47.22000,39.34999,29.55860,0.34217,3.28429,39.34999
47.28000,39.40005,29.68466,0.34261,3.29830,39.40005
47.34000,39.44999,29.56842,0.34304,3.28538,39.44999
47.40000,39.49999,29.57565,0.34348,3.28618,39.49999
47.46000,39.54993,29.31036,0.34391,3.25671,39.54993
47.52000,39.59999,29.09368,0.34435,3.23263,39.59999
47.58000,39.64999,28.95078,0.34478,3.21675,39.64999
47.64000,39.69999,28.10931,0.34522,3.12326,39.69999
47.70000,39.74993,25.54896,0.34565,2.83877,39.74993
47.76000,39.80000,-1.05263,0.34609,-0.11696,39.80000
47.82000,39.84999,-0.08633,0.34652,-0.00959,39.84999
47.88000,39.89999,-0.14433,0.34696,-0.01604,39.89999
47.94000,39.94999,-0.01570,0.34739,-0.00174,39.94999
48.00000,40.00005,0.01014,0.34783,0.00113,40.00005
48.06000,40.05006,-0.17827,0.34826,-0.01981,40.05006
48.12000,40.10005,0.01842,0.34870,0.00205,40.10005
48.18000,40.14993,0.02163,0.34913,0.00240,40.14993
48.24000,40.19993,-0.24040,0.34956,-0.02671,40.19993
48.30000,40.25000,0.05496,0.35000,0.00611,40.25000
48.36000,40.30006,-0.11518,0.35044,-0.01280,40.30006
48.42000,40.35006,-0.04697,0.35087,-0.00522,40.35006
48.48000,40.40000,0.01945,0.35130,0.00216,40.40000
48.54000,40.44993,-0.14499,0.35174,-0.01611,40.44993
48.60000,40.49993,-0.16206,0.35217,-0.01801,40.49993
48.66000,40.54999,0.01460,0.35261,0.00162,40.54999
48.72000,40.60006,-0.13458,0.35304,-0.01495,40.60006
48.78000,40.65000,-0.19943,0.35348,-0.02216,40.65000
48.84000,40.69999,0.00176,0.35391,0.00020,40.69999
48.90000,40.74993,0.01171,0.35435,0.00130,40.74993
48.96000,40.79999,-0.21792,0.35478,-0.02421,40.79999
49.02000,40.84999,0.02023,0.35522,0.00225,40.84999
49.08000,40.90006,-0.20146,0.35565,-0.02238,40.90006
49.14000,40.94993,-0.09089,0.35609,-0.01010,40.94993
49.20000,41.00006,0.00066,0.35652,0.00007,41.00006
49.26000,41.05006,-0.10460,0.35696,-0.01162,41.05006
49.32000,41.10000,0.01499,0.35739,0.00167,41.10000
49.38000,41.15005,0.06512,0.35783,0.00724,41.15005
49.44000,41.19999,-0.12488,0.35826,-0.01388,41.19999
49.50000,41.25000,0.04849,0.35870,0.00539,41.25000
49.56000,41.29999,-0.15099,0.35913,-0.01678,41.29999
49.62000,41.35000,-0.06439,0.35957,-0.00715,41.35000
49.68000,41.39993,0.03054,0.36000,0.00339,41.39993
49.74000,41.44993,0.06309,0.36043,0.00701,41.44993
49.80000,41.49993,-0.01927,0.36087,-0.00214,41.49993
49.86000,41.54999,0.07453,0.36130,0.00828,41.54999
49.92000,41.60006,-0.05569,0.36174,-0.00619,41.60006
49.94400,41.62006,-0.17964,0.36191,-0.01996,41.62006