File: V_7/NatR/RDSO NatR Tensile 50.is_tens_RawData/Specimen_RawData_4.csv
Time,Extension,Load,Tensile strain,Tensile stress,Corrected Position
(sec),(mm),(N),(mm/mm),(MPa),(mm)
0.00000,0.00000,-0.45460,0.00000,-0.05051,0.00000
0.07000,0.04262,-0.17278,0.00037,-0.01920,0.04262
0.14000,0.11356,0.32010,0.00099,0.03557,0.11356
0.21000,0.17325,0.30849,0.00151,0.03428,0.17325
0.28000,0.23269,0.56398,0.00202,0.06266,0.23269
0.35000,0.29144,0.68521,0.00253,0.07613,0.29144
0.42000,0.34981,0.98900,0.00304,0.10989,0.34981
0.49000,0.40819,1.16852,0.00355,0.12984,0.40819
0.56000,0.46662,1.43555,0.00406,0.15951,0.46662
0.63000,0.52500,1.62844,0.00457,0.18094,0.52500
0.70000,0.58325,1.61455,0.00507,0.17939,0.58325
0.77000,0.64162,1.77759,0.00558,0.19751,0.64162
0.84000,0.69994,1.93519,0.00609,0.21502,0.69994
0.91000,0.75831,2.18657,0.00659,0.24295,0.75831
0.98000,0.81662,2.09294,0.00710,0.23255,0.81662
1.05000,0.87500,2.23073,0.00761,0.24786,0.87500
1.12000,0.93337,2.43822,0.00812,0.27091,0.93337
1.19000,0.99162,2.62592,0.00862,0.29177,0.99162
1.26000,1.05000,2.71426,0.00913,0.30158,1.05000
1.33000,1.10831,2.62450,0.00964,0.29161,1.10831
1.40000,1.16669,2.95655,0.01015,0.32851,1.16669
1.47000,1.22500,3.06935,0.01065,0.34104,1.22500
1.54000,1.28337,3.06166,0.01116,0.34018,1.28337
1.61000,1.34162,3.33190,0.01167,0.37021,1.34162
1.68000,1.40000,3.24018,0.01217,0.36002,1.40000
1.75000,1.45837,3.32046,0.01268,0.36894,1.45837
1.82000,1.51675,3.47649,0.01319,0.38628,1.51675
1.89000,1.57500,3.72785,0.01370,0.41421,1.57500
1.96000,1.63331,3.64786,0.01420,0.40532,1.63331
2.03000,1.69162,3.72753,0.01471,0.41417,1.69162
2.10000,1.75000,3.76287,0.01522,0.41810,1.75000
2.17000,1.80837,4.02137,0.01572,0.44682,1.80837
2.24000,1.86669,3.99681,0.01623,0.44409,1.86669
2.31000,1.92500,4.19095,0.01674,0.46566,1.92500
2.38000,1.98325,4.29207,0.01725,0.47690,1.98325
2.45000,2.04162,4.54793,0.01775,0.50533,2.04162
2.52000,2.10000,4.59936,0.01826,0.51104,2.10000
2.59000,2.15837,4.76801,0.01877,0.52978,2.15837
2.66000,2.21669,4.83164,0.01928,0.53685,2.21669
2.73000,2.27500,4.67497,0.01978,0.51944,2.27500
2.80000,2.33331,4.92294,0.02029,0.54699,2.33331
2.87000,2.39169,5.05580,0.02080,0.56176,2.39169
2.94000,2.45000,5.08661,0.02130,0.56518,2.45000
3.01000,2.50831,5.23121,0.02181,0.58125,2.50831
3.08000,2.56662,5.36018,0.02232,0.59558,2.56662
3.15000,2.62500,5.48420,0.02283,0.60936,2.62500
3.22000,2.68337,5.61717,0.02333,0.62413,2.68337
3.29000,2.74169,5.65148,0.02384,0.62794,2.74169
3.36000,2.80000,5.73433,0.02435,0.63715,2.80000
3.43000,2.85837,5.80472,0.02486,0.64497,2.85837
3.50000,2.91675,6.09406,0.02536,0.67712,2.91675
3.57000,2.97500,6.01794,0.02587,0.66866,2.97500
3.64000,3.03337,5.94226,0.02638,0.66025,3.03337
3.71000,3.09169,6.41291,0.02688,0.71255,3.09169
3.78000,3.15006,6.24225,0.02739,0.69358,3.15006
3.85000,3.20831,6.54048,0.02790,0.72672,3.20831
3.92000,3.26656,6.60448,0.02840,0.73383,3.26656
3.99000,3.32487,6.65106,0.02891,0.73901,3.32487
4.06000,3.38337,6.60773,0.02942,0.73419,3.38337
4.13000,3.44169,6.98517,0.02993,0.77613,3.44169
4.20000,3.50000,6.77910,0.03043,0.75323,3.50000
4.27000,3.55825,6.94596,0.03094,0.77177,3.55825
4.34000,3.61662,6.97466,0.03145,0.77496,3.61662
4.41000,3.67500,7.18590,0.03196,0.79843,3.67500
4.48000,3.73337,7.31406,0.03246,0.81267,3.73337
4.55000,3.79175,7.25775,0.03297,0.80642,3.79175
4.62000,3.85000,7.19623,0.03348,0.79958,3.85000
4.69000,3.90837,7.41988,0.03399,0.82443,3.90837
4.76000,3.96662,7.53281,0.03449,0.83698,3.96662
4.83000,4.02500,7.67175,0.03500,0.85242,4.02500
4.90000,4.08331,7.72865,0.03551,0.85874,4.08331
4.97000,4.14162,7.97353,0.03601,0.88595,4.14162
5.04000,4.19994,7.84872,0.03652,0.87208,4.19994
5.11000,4.25825,7.94346,0.03703,0.88261,4.25825
5.18000,4.31662,8.12641,0.03754,0.90293,4.31662
5.25000,4.37494,7.99616,0.03804,0.88846,4.37494
5.32000,4.43337,8.19758,0.03855,0.91084,4.43337
5.39000,4.49169,8.22591,0.03906,0.91399,4.49169
5.46000,4.55000,8.24996,0.03957,0.91666,4.55000
5.53000,4.60837,8.59411,0.04007,0.95490,4.60837
5.60000,4.66675,8.57134,0.04058,0.95237,4.66675
5.67000,4.72506,8.75717,0.04109,0.97302,4.72506
5.74000,4.78337,8.94314,0.04159,0.99368,4.78337
5.81000,4.84162,8.66896,0.04210,0.96322,4.84162
5.88000,4.90000,8.94125,0.04261,0.99347,4.90000
5.95000,4.95831,8.98313,0.04312,0.99813,4.95831
6.02000,5.01669,8.90010,0.04362,0.98890,5.01669
6.09000,5.07500,9.21291,0.04413,1.02366,5.07500
6.16000,5.13331,9.41496,0.04464,1.04611,5.13331
6.23000,5.19156,9.37734,0.04514,1.04193,5.19156
6.30000,5.25000,9.23250,0.04565,1.02583,5.25000
6.37000,5.30831,9.51363,0.04616,1.05707,5.30831
6.44000,5.36669,9.50895,0.04667,1.05655,5.36669
6.51000,5.42506,9.65225,0.04717,1.07247,5.42506
6.58000,5.48337,9.67819,0.04768,1.07535,5.48337
6.65000,5.54169,9.94188,0.04819,1.10465,5.54169
6.72000,5.60006,9.90010,0.04870,1.10001,5.60006
6.79000,5.65837,10.15716,0.04920,1.12857,5.65837
6.86000,5.71669,10.11310,0.04971,1.12368,5.71669
6.93000,5.77494,10.20516,0.05022,1.13391,5.77494
7.00000,5.83325,10.30967,0.05072,1.14552,5.83325
7.07000,5.89169,10.25645,0.05123,1.13961,5.89169
7.14000,5.94994,10.20095,0.05174,1.13344,5.94994
7.21000,6.00831,10.42110,0.05225,1.15790,6.00831
7.28000,6.06656,10.53126,0.05275,1.17014,6.06656
7.35000,6.12500,10.64904,0.05326,1.18323,6.12500
7.42000,6.18337,10.76981,0.05377,1.19665,6.18337
7.49000,6.24169,10.74323,0.05428,1.19369,6.24169
7.56000,6.30006,10.62124,0.05478,1.18014,6.30006
7.63000,6.35844,11.06889,0.05529,1.22988,6.35844
7.70000,6.41675,10.79827,0.05580,1.19981,6.41675
7.77000,6.47500,11.05559,0.05630,1.22840,6.47500
7.84000,6.53331,10.96314,0.05681,1.21813,6.53331
7.91000,6.59169,11.12155,0.05732,1.23573,6.59169
7.98000,6.65012,11.27864,0.05783,1.25318,6.65012
8.05000,6.70831,11.31963,0.05833,1.25774,6.70831
8.12000,6.76650,11.34513,0.05884,1.26057,6.76650
8.19000,6.82494,11.31946,0.05935,1.25772,6.82494
8.26000,6.88331,11.40508,0.05985,1.26723,6.88331
8.33000,6.94169,11.51008,0.06036,1.27890,6.94169
8.40000,7.00000,11.64091,0.06087,1.29343,7.00000
8.47000,7.05831,11.90940,0.06138,1.32327,7.05831
8.54000,7.11669,11.94097,0.06188,1.32677,7.11669
8.61000,7.17506,11.89410,0.06239,1.32157,7.17506
8.68000,7.23344,11.82178,0.06290,1.31353,7.23344
8.75000,7.29169,11.92177,0.06341,1.32464,7.29169
8.82000,7.35006,12.06659,0.06391,1.34073,7.35006
8.89000,7.40837,12.11974,0.06442,1.34664,7.40837
8.96000,7.46656,12.27699,0.06493,1.36411,7.46656
9.03000,7.52500,12.34603,0.06543,1.37178,7.52500
9.10000,7.58331,12.31449,0.06594,1.36828,7.58331
9.17000,7.64169,12.24305,0.06645,1.36034,7.64169
9.24000,7.70000,12.55511,0.06696,1.39501,7.70000
9.31000,7.75831,12.51754,0.06746,1.39084,7.75831
9.38000,7.81662,12.69398,0.06797,1.41044,7.81662
9.45000,7.87500,12.55350,0.06848,1.39483,7.87500
9.52000,7.93337,12.68986,0.06899,1.40998,7.93337
9.59000,7.99162,12.96345,0.06949,1.44038,7.99162
9.66000,8.05000,12.85050,0.07000,1.42783,8.05000
9.73000,8.10837,12.79917,0.07051,1.42213,8.10837
9.80000,8.16675,13.03063,0.07102,1.44785,8.16675
9.87000,8.22512,13.09490,0.07152,1.45499,8.22512
9.94000,8.28337,13.27358,0.07203,1.47484,8.28337
10.01000,8.34162,13.01425,0.07254,1.44603,8.34162
10.08000,8.40000,13.19646,0.07304,1.46627,8.40000
10.15000,8.45837,13.33903,0.07355,1.48211,8.45837
10.22000,8.51662,13.24914,0.07406,1.47213,8.51662
10.29000,8.57487,13.45857,0.07456,1.49540,8.57487
10.36000,8.63325,13.55673,0.07507,1.50630,8.63325
10.43000,8.69169,13.51375,0.07558,1.50153,8.69169
10.50000,8.75000,13.68300,0.07609,1.52033,8.75000
10.57000,8.80831,13.86389,0.07659,1.54043,8.80831
10.64000,8.86669,13.81219,0.07710,1.53469,8.86669
10.71000,8.92512,14.02840,0.07761,1.55871,8.92512
10.78000,8.98337,13.79537,0.07812,1.53282,8.98337
10.85000,9.04169,13.88496,0.07862,1.54277,9.04169
10.92000,9.10000,13.92405,0.07913,1.54712,9.10000
10.99000,9.15837,14.11251,0.07964,1.56806,9.15837
11.06000,9.21675,14.04474,0.08015,1.56053,9.21675
11.13000,9.27500,14.18774,0.08065,1.57642,9.27500
11.20000,9.33325,14.24571,0.08116,1.58286,9.33325
11.27000,9.39162,14.37958,0.08167,1.59773,9.39162
11.34000,9.45000,14.25068,0.08217,1.58341,9.45000
11.41000,9.50831,14.34096,0.08268,1.59344,9.50831
11.48000,9.56662,14.45016,0.08319,1.60557,9.56662
11.55000,9.62494,14.50880,0.08370,1.61209,9.62494
11.62000,9.68331,14.48700,0.08420,1.60967,9.68331
11.69000,9.74169,14.51644,0.08471,1.61294,9.74169
11.76000,9.80006,14.70323,0.08522,1.63369,9.80006
11.83000,9.85844,14.85077,0.08573,1.65009,9.85844
11.90000,9.91669,14.69368,0.08623,1.63263,9.91669
11.97000,9.97506,15.02617,0.08674,1.66957,9.97506
12.04000,10.03344,14.82686,0.08725,1.64743,10.03344
12.11000,10.09169,14.95965,0.08775,1.66218,10.09169
12.18000,10.15000,14.92155,0.08826,1.65795,10.15000
12.25000,10.20831,15.05179,0.08877,1.67242,10.20831
12.32000,10.26662,15.15681,0.08927,1.68409,10.26662
12.39000,10.32481,15.06719,0.08978,1.67413,10.32481
12.46000,10.38331,15.11334,0.09029,1.67926,10.38331
12.53000,10.44162,15.27422,0.09080,1.69714,10.44162
12.60000,10.49994,15.42807,0.09130,1.71423,10.49994
12.67000,10.55831,15.56409,0.09181,1.72934,10.55831
12.74000,10.61662,15.43042,0.09232,1.71449,10.61662
12.81000,10.67506,15.61342,0.09283,1.73482,10.67506
12.88000,10.73337,15.45531,0.09333,1.71726,10.73337
12.95000,10.79175,15.63243,0.09384,1.73694,10.79175
13.02000,10.85006,15.55361,0.09435,1.72818,10.85006
13.09000,10.90831,15.60318,0.09485,1.73369,10.90831
13.16000,10.96669,15.67306,0.09536,1.74145,10.96669
13.23000,11.02500,15.96257,0.09587,1.77362,11.02500
13.30000,11.08325,15.99972,0.09638,1.77775,11.08325
13.37000,11.14169,15.99639,0.09688,1.77738,11.14169
13.44000,11.19994,16.00263,0.09739,1.77807,11.19994
13.51000,11.25825,15.80438,0.09790,1.75604,11.25825
13.58000,11.31656,16.03748,0.09840,1.78194,11.31656
13.65000,11.37500,16.08220,0.09891,1.78691,11.37500
13.72000,11.43337,16.04738,0.09942,1.78304,11.43337
13.79000,11.49169,16.16136,0.09993,1.79571,11.49169
13.86000,11.54994,16.47957,0.10043,1.83106,11.54994
13.93000,11.60837,16.52829,0.10094,1.83648,11.60837
14.00000,11.66675,16.21625,0.10145,1.80181,11.66675
14.07000,11.72512,16.49696,0.10196,1.83300,11.72512
14.14000,11.78337,16.45565,0.10246,1.82841,11.78337
14.21000,11.84162,16.58538,0.10297,1.84282,11.84162
14.28000,11.90006,16.58094,0.10348,1.84233,11.90006
14.35000,11.95831,16.79316,0.10399,1.86591,11.95831
14.42000,12.01662,16.67247,0.10449,1.85250,12.01662
14.49000,12.07487,16.77222,0.10500,1.86358,12.07487
14.56000,12.13331,16.85527,0.10551,1.87281,12.13331
14.63000,12.19162,16.77281,0.10601,1.86365,12.19162
14.70000,12.24994,17.07963,0.10652,1.89774,12.24994
14.77000,12.30831,17.06599,0.10703,1.89622,12.30831
14.84000,12.36669,17.04348,0.10754,1.89372,12.36669
14.91000,12.42506,17.07096,0.10804,1.89677,12.42506
14.98000,12.48343,17.16344,0.10855,1.90705,12.48343
15.05000,12.54169,17.13268,0.10906,1.90363,12.54169
15.12000,12.60006,17.06075,0.10957,1.89564,12.60006
15.19000,12.65844,17.18614,0.11007,1.90957,12.65844
15.26000,12.71675,17.32422,0.11058,1.92491,12.71675
15.33000,12.77494,17.52172,0.11109,1.94686,12.77494
15.40000,12.83325,17.31092,0.11159,1.92344,12.83325
15.47000,12.89162,17.37798,0.11210,1.93089,12.89162
15.54000,12.95000,17.36520,0.11261,1.92947,12.95000
15.61000,13.00837,17.42231,0.11312,1.93581,13.00837
15.68000,13.06662,17.58427,0.11362,1.95381,13.06662
15.75000,13.12487,17.49165,0.11413,1.94352,13.12487
15.82000,13.18331,17.61329,0.11464,1.95703,13.18331
15.89000,13.24169,17.63531,0.11515,1.95948,13.24169
15.96000,13.30000,17.72583,0.11565,1.96954,13.30000
16.03000,13.35837,17.67420,0.11616,1.96380,13.35837
16.10000,13.41675,17.85460,0.11667,1.98384,13.41675
16.17000,13.47506,17.89119,0.11717,1.98791,13.47506
16.24000,13.53337,17.94302,0.11768,1.99367,13.53337
16.31000,13.59169,17.91992,0.11819,1.99110,13.59169
16.38000,13.65000,17.98553,0.11870,1.99839,13.65000
16.45000,13.70831,18.12001,0.11920,2.01333,13.70831
16.52000,13.76662,17.97723,0.11971,1.99747,13.76662
16.59000,13.82487,18.15575,0.12022,2.01731,13.82487
16.66000,13.88331,18.25876,0.12072,2.02875,13.88331
16.73000,13.94162,18.23221,0.12123,2.02580,13.94162
16.80000,14.00000,18.26170,0.12174,2.02908,14.00000
16.87000,14.05825,18.30260,0.12225,2.03362,14.05825
16.94000,14.11662,18.37244,0.12275,2.04138,14.11662
17.01000,14.17506,18.55615,0.12326,2.06179,14.17506
17.08000,14.23344,18.42963,0.12377,2.04774,14.23344
17.15000,14.29169,18.50502,0.12428,2.05611,14.29169
17.22000,14.35000,18.54785,0.12478,2.06087,14.35000
17.29000,14.40837,18.46372,0.12529,2.05152,14.40837
17.36000,14.46669,18.59431,0.12580,2.06603,14.46669
17.43000,14.52500,18.67418,0.12630,2.07491,14.52500
17.50000,14.58337,18.66845,0.12681,2.07427,14.58337
17.57000,14.64162,18.80449,0.12732,2.08939,14.64162
17.64000,14.69987,18.94973,0.12782,2.10553,14.69987
17.71000,14.75825,18.85661,0.12833,2.09518,14.75825
17.78000,14.81656,18.94395,0.12884,2.10488,14.81656
17.85000,14.87494,19.10757,0.12935,2.12306,14.87494
17.92000,14.93331,19.01717,0.12985,2.11302,14.93331
17.99000,14.99169,19.00948,0.13036,2.11216,14.99169
18.06000,15.05000,19.06121,0.13087,2.11791,15.05000
18.13000,15.10844,19.13338,0.13138,2.12593,15.10844
18.20000,15.16675,19.17436,0.13188,2.13048,15.16675
18.27000,15.22506,19.04118,0.13239,2.11569,15.22506
18.34000,15.28337,19.33431,0.13290,2.14826,15.28337
18.41000,15.34169,19.22337,0.13341,2.13593,15.34169
18.48000,15.40000,19.35731,0.13391,2.15081,15.40000
18.55000,15.45831,19.43338,0.13442,2.15926,15.45831
18.62000,15.51662,19.34467,0.13493,2.14941,15.51662
18.69000,15.57494,19.41530,0.13543,2.15726,15.57494
18.76000,15.63325,19.51924,0.13594,2.16880,15.63325
18.83000,15.69162,19.47266,0.13645,2.16363,15.69162
18.90000,15.74993,19.68103,0.13696,2.18678,15.74993
18.97000,15.80825,19.71642,0.13746,2.19071,15.80825
19.04000,15.86668,19.60584,0.13797,2.17843,15.86668
19.11000,15.92506,19.72117,0.13848,2.19124,15.92506
19.18000,15.98337,19.88458,0.13899,2.20940,15.98337
19.25000,16.04169,19.78622,0.13949,2.19847,16.04169
19.32000,16.10006,19.70209,0.14000,2.18912,16.10006
19.39000,16.15850,19.75289,0.14051,2.19477,16.15850
19.46000,16.21681,19.97490,0.14102,2.21943,16.21681
19.53000,16.27494,20.05413,0.14152,2.22824,16.27494
19.60000,16.33325,19.92648,0.14203,2.21405,16.33325
19.67000,16.39162,20.02405,0.14254,2.22489,16.39162
19.74000,16.44993,20.02851,0.14304,2.22539,16.44993
19.81000,16.50831,20.10228,0.14355,2.23359,16.50831
19.88000,16.56650,19.93268,0.14406,2.21474,16.56650
19.95000,16.62494,20.14786,0.14456,2.23865,16.62494
20.02000,16.68337,20.08102,0.14507,2.23122,16.68337
20.09000,16.74169,20.34503,0.14558,2.26056,16.74169
20.16000,16.80006,20.25452,0.14609,2.25050,16.80006
20.23000,16.85837,20.08883,0.14659,2.23209,16.85837
20.30000,16.91675,20.31361,0.14710,2.25707,16.91675
20.37000,16.97506,20.43955,0.14761,2.27106,16.97506
20.44000,17.03337,20.31895,0.14812,2.25766,17.03337
20.51000,17.09162,20.38241,0.14862,2.26471,17.09162
20.58000,17.15006,20.34550,0.14913,2.26061,17.15006
20.65000,17.20831,20.52245,0.14964,2.28027,17.20831
20.72000,17.26662,20.44878,0.15014,2.27209,17.26662
20.79000,17.32487,20.76134,0.15065,2.30682,17.32487
20.86000,17.38337,20.55696,0.15116,2.28411,17.38337
20.93000,17.44162,20.87404,0.15167,2.31934,17.44162
21.00000,17.49994,20.71103,0.15217,2.30123,17.49994
21.07000,17.55825,20.71098,0.15268,2.30122,17.55825
21.14000,17.61662,20.88514,0.15319,2.32057,17.61662
21.21000,17.67500,20.74164,0.15370,2.30463,17.67500
21.28000,17.73337,20.91614,0.15420,2.32402,17.73337
21.35000,17.79181,20.87613,0.15471,2.31957,17.79181
21.42000,17.85006,20.98675,0.15522,2.33186,17.85006
21.49000,17.90837,21.06632,0.15572,2.34070,17.90837
21.56000,17.96668,20.91215,0.15623,2.32357,17.96668
21.63000,18.02500,20.96331,0.15674,2.32926,18.02500
21.70000,18.08331,21.00585,0.15725,2.33398,18.08331
21.77000,18.14162,21.10637,0.15775,2.34515,18.14162
21.84000,18.19994,21.13840,0.15826,2.34871,18.19994
21.91000,18.25825,21.10245,0.15877,2.34472,18.25825
21.98000,18.31656,21.14107,0.15927,2.34901,18.31656
22.05000,18.37500,21.31809,0.15978,2.36868,18.37500
22.12000,18.43337,21.23874,0.16029,2.35986,18.43337
22.19000,18.49175,21.17626,0.16080,2.35292,18.49175
22.26000,18.55000,21.32953,0.16130,2.36995,18.55000
22.33000,18.60837,21.33220,0.16181,2.37024,18.60837
22.40000,18.66675,21.49810,0.16232,2.38868,18.66675
22.47000,18.72512,21.28924,0.16283,2.36547,18.72512
22.54000,18.78331,21.31187,0.16333,2.36799,18.78331
22.61000,18.84156,21.40846,0.16384,2.37872,18.84156
22.68000,18.90000,21.45103,0.16435,2.38345,18.90000
22.75000,18.95837,21.34124,0.16486,2.37125,18.95837
22.82000,19.01662,21.24597,0.16536,2.36066,19.01662
22.89000,19.07494,21.68561,0.16587,2.40951,19.07494
22.96000,19.13325,21.64916,0.16638,2.40546,19.13325
23.03000,19.19162,21.44282,0.16688,2.38254,19.19162
23.10000,19.24993,21.51885,0.16739,2.39098,19.24993
23.17000,19.30831,21.51089,0.16790,2.39010,19.30831
23.24000,19.36675,21.62599,0.16841,2.40289,19.36675
23.31000,19.42506,21.55987,0.16891,2.39554,19.42506
23.38000,19.48331,21.55514,0.16942,2.39502,19.48331
23.45000,19.54168,21.88842,0.16993,2.43205,19.54168
23.52000,19.60006,21.79515,0.17044,2.42168,19.60006
23.59000,19.65843,21.65622,0.17094,2.40625,19.65843
23.66000,19.71675,21.95035,0.17145,2.43893,19.71675
23.73000,19.77506,21.75207,0.17196,2.41690,19.77506
23.80000,19.83331,21.72232,0.17246,2.41359,19.83331
23.87000,19.89168,21.96503,0.17297,2.44056,19.89168
23.94000,19.95000,21.79175,0.17348,2.42131,19.95000
24.01000,20.00825,21.79288,0.17398,2.42143,20.00825
24.08000,20.06656,21.69496,0.17449,2.41055,20.06656
24.15000,20.12493,22.03923,0.17500,2.44880,20.12493
24.22000,20.18331,22.04687,0.17551,2.44965,20.18331
24.29000,20.24162,21.74649,0.17601,2.41628,20.24162
24.36000,20.30000,21.96179,0.17652,2.44020,20.30000
24.43000,20.35837,22.05060,0.17703,2.45007,20.35837
24.50000,20.41675,22.03568,0.17754,2.44841,20.41675
24.57000,20.47500,22.20577,0.17804,2.46731,20.47500
24.64000,20.53337,22.28280,0.17855,2.47587,20.53337
24.71000,20.59175,22.25123,0.17906,2.47236,20.59175
24.78000,20.65012,22.11567,0.17957,2.45730,20.65012
24.85000,20.70831,22.38444,0.18007,2.48716,20.70831
24.92000,20.76662,22.25336,0.18058,2.47260,20.76662
24.99000,20.82493,22.20688,0.18109,2.46743,20.82493
25.06000,20.88331,22.18667,0.18159,2.46519,20.88331
25.13000,20.94168,22.24236,0.18210,2.47137,20.94168
25.20000,21.00000,22.45189,0.18261,2.49465,21.00000
25.27000,21.05818,22.26788,0.18311,2.47421,21.05818
25.34000,21.11662,22.47187,0.18362,2.49687,21.11662
25.41000,21.17506,22.34853,0.18413,2.48317,21.17506
25.48000,21.23337,22.45485,0.18464,2.49498,21.23337
25.55000,21.29168,22.42661,0.18515,2.49185,21.29168
25.62000,21.34999,22.46609,0.18565,2.49623,21.34999
25.69000,21.40844,22.51507,0.18616,2.50167,21.40844
25.76000,21.46675,22.64781,0.18667,2.51642,21.46675
25.83000,21.52506,22.34804,0.18717,2.48312,21.52506
25.90000,21.58331,22.73439,0.18768,2.52604,21.58331
25.97000,21.64169,22.79094,0.18819,2.53233,21.64169
26.04000,21.70000,22.55945,0.18870,2.50661,21.70000
26.11000,21.75831,22.66116,0.18920,2.51791,21.75831
26.18000,21.81656,22.70787,0.18971,2.52310,21.81656
26.25000,21.87487,22.79403,0.19022,2.53267,21.87487
26.32000,21.93337,22.85280,0.19072,2.53920,21.93337
26.39000,21.99162,22.76836,0.19123,2.52982,21.99162
26.46000,22.04994,22.69934,0.19174,2.52215,22.04994
26.53000,22.10831,22.68097,0.19225,2.52011,22.10831
26.60000,22.16681,22.90526,0.19275,2.54503,22.16681
26.67000,22.22506,23.05542,0.19326,2.56171,22.22506
26.74000,22.28337,22.86010,0.19377,2.54001,22.28337
26.81000,22.34169,23.14133,0.19428,2.57126,22.34169
26.88000,22.40000,22.96490,0.19478,2.55166,22.40000
26.95000,22.45837,22.94908,0.19529,2.54990,22.45837
27.02000,22.51668,23.14151,0.19580,2.57128,22.51668
27.09000,22.57500,23.13798,0.19630,2.57089,22.57500
27.16000,22.63318,23.09142,0.19681,2.56571,22.63318
27.23000,22.69156,23.34882,0.19732,2.59431,22.69156
27.30000,22.74993,23.08643,0.19783,2.56516,22.74993
27.37000,22.80825,23.24733,0.19833,2.58304,22.80825
27.44000,22.86662,23.23519,0.19884,2.58169,22.86662
27.51000,22.92500,23.34642,0.19935,2.59405,22.92500
27.58000,22.98337,23.23979,0.19986,2.58220,22.98337
27.65000,23.04175,23.36832,0.20036,2.59648,23.04175
27.72000,23.10006,23.33452,0.20087,2.59272,23.10006
27.79000,23.15850,23.32419,0.20138,2.59158,23.15850
27.86000,23.21668,23.28005,0.20188,2.58667,23.21668
27.93000,23.27500,23.27322,0.20239,2.58591,23.27500
28.00000,23.33337,23.40591,0.20290,2.60066,23.33337
28.07000,23.39168,23.51125,0.20341,2.61236,23.39168
28.14000,23.44999,23.51181,0.20391,2.61242,23.44999
28.21000,23.50831,23.52629,0.20442,2.61403,23.50831
28.28000,23.56656,23.45142,0.20493,2.60571,23.56656
28.35000,23.62493,23.41047,0.20543,2.60116,23.62493
28.42000,23.68331,23.49949,0.20594,2.61105,23.68331
28.49000,23.74168,23.64931,0.20645,2.62770,23.74168
28.56000,23.79999,23.61110,0.20696,2.62346,23.79999
28.63000,23.85837,23.86860,0.20746,2.65207,23.85837
28.70000,23.91668,23.50123,0.20797,2.61125,23.91668
28.77000,23.97500,23.86113,0.20848,2.65124,23.97500
28.84000,24.03337,23.68173,0.20899,2.63130,24.03337
28.91000,24.09175,23.74908,0.20949,2.63879,24.09175
28.98000,24.15012,23.80727,0.21000,2.64525,24.15012
29.05000,24.20831,23.72408,0.21051,2.63601,24.20831
29.12000,24.26662,23.93037,0.21101,2.65893,24.26662
29.19000,24.32493,24.01533,0.21152,2.66837,24.32493
29.26000,24.38325,23.77127,0.21203,2.64125,24.38325
29.33000,24.44162,24.15544,0.21254,2.68394,24.44162
29.40000,24.49993,23.89845,0.21304,2.65538,24.49993
29.47000,24.55825,23.74948,0.21355,2.63883,24.55825
29.54000,24.61656,24.02049,0.21406,2.66894,24.61656
29.61000,24.67506,24.04437,0.21457,2.67160,24.67506
29.68000,24.73337,24.20295,0.21507,2.68922,24.73337
29.75000,24.79168,24.16575,0.21558,2.68508,24.79168
29.82000,24.85006,24.19747,0.21609,2.68861,24.85006
29.89000,24.90843,24.17378,0.21660,2.68598,24.90843
29.96000,24.96675,24.31679,0.21710,2.70187,24.96675
30.03000,25.02506,24.14937,0.21761,2.68326,25.02506
30.10000,25.08331,24.32418,0.21812,2.70269,25.08331
30.17000,25.14168,24.15456,0.21862,2.68384,25.14168
30.24000,25.20000,24.28965,0.21913,2.69885,25.20000
30.31000,25.25831,24.24689,0.21964,2.69410,25.25831
30.38000,25.31662,24.20126,0.22014,2.68903,25.31662
30.45000,25.37493,24.37385,0.22065,2.70821,25.37493
30.52000,25.43337,24.21226,0.22116,2.69025,25.43337
30.59000,25.49156,24.47348,0.22167,2.71928,25.49156
30.66000,25.54993,24.37415,0.22217,2.70824,25.54993
30.73000,25.60831,24.23832,0.22268,2.69315,25.60831
30.80000,25.66675,24.53823,0.22319,2.72647,25.66675
30.87000,25.72512,24.45722,0.22370,2.71747,25.72512
30.94000,25.78337,24.51152,0.22420,2.72350,25.78337
31.01000,25.84162,24.71974,0.22471,2.74664,25.84162
31.08000,25.90006,24.54901,0.22522,2.72767,25.90006
31.15000,25.95837,24.51578,0.22572,2.72398,25.95837
31.22000,26.01668,24.63982,0.22623,2.73776,26.01668
31.29000,26.07487,24.60157,0.22674,2.73351,26.07487
31.36000,26.13331,24.69491,0.22725,2.74388,26.13331
31.43000,26.19162,24.60711,0.22775,2.73412,26.19162
31.50000,26.25000,24.74972,0.22826,2.74997,26.25000
31.57000,26.30831,24.73152,0.22877,2.74795,26.30831
31.64000,26.36662,24.76622,0.22927,2.75180,26.36662
31.71000,26.42500,24.81381,0.22978,2.75709,26.42500
31.78000,26.48337,24.73306,0.23029,2.74812,26.48337
31.85000,26.54168,25.06869,0.23080,2.78541,26.54168
31.92000,26.60000,24.86049,0.23130,2.76228,26.60000
31.99000,26.65837,24.97371,0.23181,2.77486,26.65837
32.06000,26.71675,24.88079,0.23232,2.76453,26.71675
32.13000,26.77506,24.95263,0.23283,2.77251,26.77506
32.20000,26.83331,24.90421,0.23333,2.76713,26.83331
32.27000,26.89175,25.06259,0.23384,2.78473,26.89175
32.34000,26.95006,25.17251,0.23435,2.79695,26.95006
32.41000,27.00831,25.11816,0.23485,2.79091,27.00831
32.48000,27.06656,25.15710,0.23536,2.79523,27.06656
32.55000,27.12493,25.02968,0.23587,2.78108,27.12493
32.62000,27.18325,25.20777,0.23638,2.80086,27.18325
32.69000,27.24162,25.20934,0.23688,2.80104,27.24162
32.76000,27.29993,25.12681,0.23739,2.79187,27.29993
32.83000,27.35831,25.28039,0.23790,2.80893,27.35831
32.90000,27.41662,25.43691,0.23841,2.82632,27.41662
32.97000,27.47500,25.39062,0.23891,2.82118,27.47500
33.04000,27.53337,25.28588,0.23942,2.80954,27.53337
33.11000,27.59168,25.32389,0.23993,2.81377,27.59168
33.18000,27.65012,25.28367,0.24044,2.80930,27.65012
33.25000,27.70837,25.45570,0.24094,2.82841,27.70837
33.32000,27.76668,25.35499,0.24145,2.81722,27.76668
33.39000,27.82493,25.38115,0.24196,2.82013,27.82493
33.46000,27.88331,25.38759,0.24246,2.82084,27.88331
33.53000,27.94162,25.46547,0.24297,2.82950,27.94162
33.60000,27.99993,25.54916,0.24348,2.83879,27.99993
33.67000,28.05831,25.40086,0.24399,2.82232,28.05831
33.74000,28.11662,25.55408,0.24449,2.83934,28.11662
33.81000,28.17499,25.63385,0.24500,2.84821,28.17499
33.88000,28.23337,25.57845,0.24551,2.84205,28.23337
33.95000,28.29168,25.79786,0.24601,2.86643,28.29168
34.02000,28.35006,25.70678,0.24652,2.85631,28.35006
34.09000,28.40837,25.70521,0.24703,2.85613,28.40837
34.16000,28.46675,25.77773,0.24754,2.86419,28.46675
34.23000,28.52512,25.78895,0.24804,2.86544,28.52512
34.30000,28.58337,25.71690,0.24855,2.85743,28.58337
34.37000,28.64168,25.99382,0.24906,2.88820,28.64168
34.44000,28.69993,25.92847,0.24956,2.88094,28.69993
34.51000,28.75824,26.02411,0.25007,2.89157,28.75824
34.58000,28.81662,25.82128,0.25058,2.86903,28.81662
34.65000,28.87500,25.85552,0.25109,2.87284,28.87500
34.72000,28.93331,25.88948,0.25159,2.87661,28.93331
34.79000,28.99156,25.86473,0.25210,2.87386,28.99156
34.86000,29.04993,25.98382,0.25261,2.88709,29.04993
34.93000,29.10831,25.98608,0.25312,2.88734,29.10831
35.00000,29.16669,25.98020,0.25362,2.88669,29.16669
35.07000,29.22506,26.14637,0.25413,2.90515,29.22506
35.14000,29.28337,26.39425,0.25464,2.93269,29.28337
35.21000,29.34168,26.12379,0.25515,2.90264,29.34168
35.28000,29.40012,26.08125,0.25565,2.89792,29.40012
35.35000,29.45837,26.32214,0.25616,2.92468,29.45837
35.42000,29.51668,26.30537,0.25667,2.92282,29.51668
35.49000,29.57493,26.31181,0.25717,2.92353,29.57493
35.56000,29.63331,26.39197,0.25768,2.93244,29.63331
35.63000,29.69162,26.38658,0.25819,2.93184,29.69162
35.70000,29.75000,26.16254,0.25870,2.90695,29.75000
35.77000,29.80831,26.22898,0.25920,2.91433,29.80831
35.84000,29.86662,26.45339,0.25971,2.93927,29.86662
35.91000,29.92500,26.35004,0.26022,2.92778,29.92500
35.98000,29.98331,26.42021,0.26072,2.93558,29.98331
36.05000,30.04168,26.50710,0.26123,2.94523,30.04168
36.12000,30.10006,26.52410,0.26174,2.94712,30.10006
36.19000,30.15843,26.62868,0.26225,2.95874,30.15843
36.26000,30.21675,26.50703,0.26275,2.94523,30.21675
36.33000,30.27500,26.53199,0.26326,2.94800,30.27500
36.40000,30.33331,26.63886,0.26377,2.95987,30.33331
36.47000,30.39168,26.56250,0.26428,2.95139,30.39168
36.54000,30.45000,26.73044,0.26478,2.97005,30.45000
36.61000,30.50837,26.82529,0.26529,2.98059,30.50837
36.68000,30.56662,26.87866,0.26580,2.98652,30.56662
36.75000,30.62493,26.86947,0.26630,2.98550,30.62493
36.82000,30.68325,26.66681,0.26681,2.96298,30.68325
36.89000,30.74162,26.80178,0.26732,2.97798,30.74162
36.96000,30.79993,26.77790,0.26783,2.97532,30.79993
37.03000,30.85825,26.86242,0.26833,2.98471,30.85825
37.10000,30.91675,26.79076,0.26884,2.97675,30.91675
37.17000,30.97500,26.67742,0.26935,2.96416,30.97500
37.24000,31.03337,26.89421,0.26986,2.98825,31.03337
37.31000,31.09175,26.83450,0.27036,2.98161,31.09175
37.38000,31.15006,27.11958,0.27087,3.01329,31.15006
37.45000,31.20831,27.05350,0.27138,3.00594,31.20831
37.52000,31.26668,26.90388,0.27188,2.98932,31.26668
37.59000,31.32500,26.98862,0.27239,2.99874,31.32500
37.66000,31.38331,27.17402,0.27290,3.01934,31.38331
37.73000,31.44162,26.93690,0.27341,2.99299,31.44162
37.80000,31.49999,27.14955,0.27391,3.01662,31.49999
37.87000,31.55831,27.16168,0.27442,3.01796,31.55831
37.94000,31.61662,27.41871,0.27493,3.04652,31.61662
38.01000,31.67500,27.29966,0.27543,3.03330,31.67500
38.08000,31.73337,27.35440,0.27594,3.03938,31.73337
38.15000,31.79168,27.23013,0.27645,3.02557,31.79168
38.22000,31.85000,27.18732,0.27696,3.02081,31.85000
38.29000,31.90837,27.26564,0.27746,3.02952,31.90837
38.36000,31.96662,27.22967,0.27797,3.02552,31.96662
38.43000,32.02506,27.44857,0.27848,3.04984,32.02506
38.50000,32.08343,27.25153,0.27899,3.02795,32.08343
38.57000,32.14168,27.31124,0.27949,3.03458,32.14168
38.64000,32.19993,27.20635,0.28000,3.02293,32.19993
38.71000,32.25831,27.35408,0.28051,3.03934,32.25831
38.78000,32.31662,27.40994,0.28101,3.04555,32.31662
38.85000,32.37493,27.50958,0.28152,3.05662,32.37493
38.92000,32.43337,27.63521,0.28203,3.07058,32.43337
38.99000,32.49162,27.45925,0.28254,3.05103,32.49162
39.06000,32.54993,27.47384,0.28304,3.05265,32.54993
39.13000,32.60837,27.54247,0.28355,3.06027,32.60837
39.20000,32.66674,27.64822,0.28406,3.07202,32.66674
39.27000,32.72500,27.71846,0.28457,3.07983,32.72500
39.34000,32.78337,27.68966,0.28507,3.07663,32.78337
39.41000,32.84168,27.85554,0.28558,3.09506,32.84168
39.48000,32.89999,27.74202,0.28609,3.08245,32.89999
39.55000,32.95837,27.88466,0.28659,3.09830,32.95837
39.62000,33.01675,27.67624,0.28710,3.07514,33.01675
39.69000,33.07499,27.86345,0.28761,3.09594,33.07499
39.76000,33.13331,27.87709,0.28812,3.09745,33.13331
39.83000,33.19168,27.91375,0.28862,3.10153,33.19168
39.90000,33.24999,27.88639,0.28913,3.09849,33.24999
39.97000,33.30831,27.88926,0.28964,3.09881,33.30831
40.04000,33.36668,28.06447,0.29015,3.11827,33.36668
40.11000,33.42500,28.08943,0.29065,3.12105,33.42500
40.18000,33.48331,27.97880,0.29116,3.10876,33.48331
40.25000,33.54168,28.07552,0.29167,3.11950,33.54168
40.32000,33.60000,28.01218,0.29217,3.11246,33.60000
40.39000,33.65849,28.07375,0.29268,3.11931,33.65849
40.46000,33.71675,28.14081,0.29319,3.12676,33.71675
40.53000,33.77493,28.10765,0.29370,3.12307,33.77493
40.60000,33.83331,28.26192,0.29420,3.14021,33.83331
40.67000,33.89168,28.10170,0.29471,3.12241,33.89168
40.74000,33.94999,28.17284,0.29522,3.13032,33.94999
40.81000,34.00831,28.10118,0.29572,3.12235,34.00831
40.88000,34.06656,28.07713,0.29623,3.11968,34.06656
40.95000,34.12499,28.25695,0.29674,3.13966,34.12499
41.02000,34.18337,28.41778,0.29725,3.15753,34.18337
41.09000,34.24162,28.30331,0.29775,3.14481,34.24162
41.16000,34.29993,28.35175,0.29826,3.15019,34.29993
41.23000,34.35837,28.39145,0.29877,3.15461,34.35837
41.30000,34.41668,28.37504,0.29928,3.15278,34.41668
41.37000,34.47500,28.42231,0.29978,3.15803,34.47500
41.44000,34.53331,28.60842,0.30029,3.17871,34.53331
41.51000,34.59162,28.56691,0.30080,3.17410,34.59162
41.58000,34.65006,28.65431,0.30130,3.18381,34.65006
41.65000,34.70837,28.53000,0.30181,3.17000,34.70837
41.72000,34.76668,28.50406,0.30232,3.16712,34.76668
41.79000,34.82499,28.60932,0.30283,3.17881,34.82499
41.86000,34.88337,28.58501,0.30333,3.17611,34.88337
41.93000,34.94168,28.56140,0.30384,3.17349,34.94168
42.00000,34.99999,28.58057,0.30435,3.17562,34.99999
42.07000,35.05825,28.59480,0.30485,3.17720,35.05825
42.14000,35.11662,28.77851,0.30536,3.19761,35.11662
42.21000,35.17500,28.76663,0.30587,3.19629,35.17500
42.28000,35.23337,28.82117,0.30638,3.20235,35.23337
42.35000,35.29174,29.13686,0.30688,3.23743,35.29174
42.42000,35.34993,28.53164,0.30739,3.17018,35.34993
42.49000,35.40837,29.04607,0.30790,3.22734,35.40837
42.56000,35.46675,28.62620,0.30841,3.18069,35.46675
42.63000,35.52499,28.88176,0.30891,3.20908,35.52499
42.70000,35.58331,28.96868,0.30942,3.21874,35.58331
42.77000,35.64168,28.97145,0.30993,3.21905,35.64168
42.84000,35.70006,28.80653,0.31044,3.20073,35.70006
42.91000,35.75825,29.05937,0.31094,3.22882,35.75825
42.98000,35.81656,28.96795,0.31145,3.21866,35.81656
43.05000,35.87499,28.92063,0.31196,3.21340,35.87499
43.12000,35.93324,29.20260,0.31246,3.24473,35.93324
43.19000,35.99162,29.13446,0.31297,3.23716,35.99162
43.26000,36.05000,29.16042,0.31348,3.24005,36.05000
43.33000,36.10831,29.15798,0.31399,3.23977,36.10831
43.40000,36.16675,29.18709,0.31449,3.24301,36.16675
43.47000,36.22506,29.25420,0.31500,3.25047,36.22506
43.54000,36.28337,29.11918,0.31551,3.23546,36.28337
43.61000,36.34162,29.40502,0.31601,3.26722,36.34162
43.68000,36.40000,29.26848,0.31652,3.25205,36.40000
43.75000,36.45837,29.28702,0.31703,3.25411,36.45837
43.82000,36.51668,29.37643,0.31754,3.26405,36.51668
43.89000,36.57499,29.34217,0.31804,3.26024,36.57499
43.96000,36.63331,29.20120,0.31855,3.24458,36.63331
44.03000,36.69162,29.40462,0.31906,3.26718,36.69162
44.10000,36.74999,29.55397,0.31957,3.28377,36.74999
44.17000,36.80837,29.60474,0.32007,3.28942,36.80837
44.24000,36.86674,29.33742,0.32058,3.25971,36.86674
44.31000,36.92500,29.38378,0.32109,3.26486,36.92500
44.38000,36.98331,29.41687,0.32159,3.26854,36.98331
44.45000,37.04168,29.57675,0.32210,3.28631,37.04168
44.52000,37.10000,29.44153,0.32261,3.27128,37.10000
44.59000,37.15837,29.67251,0.32312,3.29695,37.15837
44.66000,37.21662,29.62282,0.32362,3.29142,37.21662
44.73000,37.27499,29.44641,0.32413,3.27182,37.27499
44.80000,37.33331,29.52867,0.32464,3.28096,37.33331
44.87000,37.39174,29.50249,0.32515,3.27805,37.39174
44.94000,37.45006,29.73844,0.32565,3.30427,37.45006
45.01000,37.50831,29.54721,0.32616,3.28302,37.50831
45.08000,37.56662,29.63950,0.32667,3.29328,37.56662
45.15000,37.62500,29.65421,0.32717,3.29491,37.62500
45.22000,37.68331,29.88754,0.32768,3.32084,37.68331
45.29000,37.74168,29.82012,0.32819,3.31335,37.74168
45.36000,37.80000,29.79722,0.32870,3.31080,37.80000
45.43000,37.85831,29.86449,0.32920,3.31828,37.85831
45.50000,37.91662,29.95727,0.32971,3.32859,37.91662
45.57000,37.97499,29.99349,0.33022,3.33261,37.97499
45.64000,38.03331,29.86070,0.33072,3.31786,38.03331
45.71000,38.09162,30.01825,0.33123,3.33536,38.09162
45.78000,38.15006,29.92063,0.33174,3.32451,38.15006
45.85000,38.20831,29.98298,0.33225,3.33144,38.20831
45.92000,38.26662,29.94848,0.33275,3.32761,38.26662
45.99000,38.32499,29.91083,0.33326,3.32343,38.32499
46.06000,38.38337,30.24288,0.33377,3.36032,38.38337
46.13000,38.44174,29.95665,0.33428,3.32852,38.44174
46.20000,38.50000,30.20896,0.33478,3.35655,38.50000
46.27000,38.55824,30.07928,0.33529,3.34214,38.55824
46.34000,38.61662,30.12572,0.33580,3.34730,38.61662
46.41000,38.67500,30.32444,0.33630,3.36938,38.67500
46.48000,38.73331,29.99491,0.33681,3.33277,38.73331
46.55000,38.79162,30.35016,0.33732,3.37224,38.79162
46.62000,38.85000,30.16407,0.33783,3.35156,38.85000
46.69000,38.90837,30.33938,0.33833,3.37104,38.90837
46.76000,38.96668,30.14896,0.33884,3.34988,38.96668
46.83000,39.02499,30.25687,0.33935,3.36187,39.02499
46.90000,39.08331,30.43352,0.33985,3.38150,39.08331
46.97000,39.14168,30.27923,0.34036,3.36436,39.14168
47.04000,39.19999,30.44219,0.34087,3.38247,39.19999
47.11000,39.25831,30.42142,0.34138,3.38016,39.25831
47.18000,39.31662,30.60565,0.34188,3.40063,39.31662
47.25000,39.37500,30.51929,0.34239,3.39103,39.37500
47.32000,39.43331,30.46203,0.34290,3.38467,39.43331
47.39000,39.49168,30.36901,0.34341,3.37433,39.49168
47.46000,39.54993,30.67559,0.34391,3.40840,39.54993
47.53000,39.60831,30.75798,0.34442,3.41755,39.60831
47.60000,39.66675,30.35716,0.34493,3.37302,39.66675
47.67000,39.72506,30.65311,0.34544,3.40590,39.72506
47.74000,39.78331,30.45914,0.34594,3.38435,39.78331
47.81000,39.84168,30.74270,0.34645,3.41586,39.84168
47.88000,39.89999,30.72438,0.34696,3.41382,39.89999
47.95000,39.95837,30.64615,0.34746,3.40513,39.95837
48.02000,40.01674,30.64757,0.34797,3.40529,40.01674
48.09000,40.07499,30.69308,0.34848,3.41034,40.07499
48.16000,40.13325,30.57797,0.34898,3.39755,40.13325
48.23000,40.19162,30.86271,0.34949,3.42919,40.19162
48.30000,40.25000,30.67706,0.35000,3.40856,40.25000
48.37000,40.30831,30.68152,0.35051,3.40906,40.30831
48.44000,40.36662,30.72791,0.35101,3.41421,40.36662
48.51000,40.42499,31.00113,0.35152,3.44457,40.42499
48.58000,40.48337,30.84032,0.35203,3.42670,40.48337
48.65000,40.54168,30.99569,0.35254,3.44397,40.54168
48.72000,40.60006,30.87451,0.35304,3.43050,40.60006
48.79000,40.65837,30.95768,0.35355,3.43974,40.65837
48.86000,40.71668,31.28351,0.35406,3.47595,40.71668
48.93000,40.77499,31.13015,0.35457,3.45891,40.77499
49.00000,40.83330,31.09273,0.35507,3.45475,40.83330
49.07000,40.89168,31.18711,0.35558,3.46523,40.89168
49.14000,40.94993,31.02322,0.35609,3.44702,40.94993
49.21000,41.00837,31.14528,0.35659,3.46059,41.00837
49.28000,41.06668,31.07313,0.35710,3.45257,41.06668
49.35000,41.12493,31.27744,0.35761,3.47527,41.12493
49.42000,41.18337,31.14014,0.35812,3.46002,41.18337
49.49000,41.24168,31.21846,0.35862,3.46872,41.24168
49.56000,41.29999,31.13392,0.35913,3.45932,41.29999
49.63000,41.35831,31.23507,0.35964,3.47056,41.35831
49.70000,41.41668,31.23634,0.36015,3.47070,41.41668
49.77000,41.47499,31.26799,0.36065,3.47422,41.47499
49.84000,41.53337,31.28620,0.36116,3.47624,41.53337
49.91000,41.59174,31.27675,0.36167,3.47519,41.59174
49.98000,41.65005,31.43506,0.36217,3.49278,41.65005
50.05000,41.70830,31.47812,0.36268,3.49757,41.70830
50.12000,41.76662,31.48713,0.36319,3.49857,41.76662
50.19000,41.82493,31.28909,0.36370,3.47657,41.82493
50.26000,41.88324,31.39284,0.36420,3.48809,41.88324
50.33000,41.94168,31.37947,0.36471,3.48661,41.94168
50.40000,41.99999,31.35135,0.36522,3.48348,41.99999
50.47000,42.05831,31.56599,0.36572,3.50733,42.05831
50.54000,42.11668,31.47822,0.36623,3.49758,42.11668
50.61000,42.17506,31.54709,0.36674,3.50523,42.17506
50.68000,42.23337,31.83275,0.36725,3.53697,42.23337
50.75000,42.29162,31.48698,0.36775,3.49855,42.29162
50.82000,42.34999,31.46484,0.36826,3.49609,42.34999
50.89000,42.40837,31.59112,0.36877,3.51012,42.40837
50.96000,42.46662,31.68208,0.36927,3.52023,42.46662
51.03000,42.52493,31.77760,0.36978,3.53084,42.52493
51.10000,42.58330,31.58030,0.37029,3.50892,42.58330
51.17000,42.64162,31.91475,0.37080,3.54608,42.64162
51.24000,42.69999,31.86630,0.37130,3.54070,42.69999
51.31000,42.75837,31.80121,0.37181,3.53347,42.75837
51.38000,42.81668,31.99126,0.37232,3.55458,42.81668
51.45000,42.87506,31.79792,0.37283,3.53310,42.87506
51.52000,42.93337,31.81575,0.37333,3.53508,42.93337
51.59000,42.99162,31.92895,0.37384,3.54766,42.99162
51.66000,43.04993,31.95437,0.37435,3.55049,43.04993
51.73000,43.10837,31.83030,0.37486,3.53670,43.10837
51.80000,43.16675,31.92924,0.37536,3.54769,43.16675
51.87000,43.22506,32.02373,0.37587,3.55819,43.22506
51.94000,43.28337,31.94218,0.37638,3.54913,43.28337
52.01000,43.34162,31.96559,0.37688,3.55173,43.34162
52.08000,43.39999,32.21604,0.37739,3.57956,43.39999
52.15000,43.45837,32.01212,0.37790,3.55690,43.45837
52.22000,43.51668,32.03897,0.37841,3.55989,43.51668
52.29000,43.57493,32.15740,0.37891,3.57305,43.57493
52.36000,43.63331,32.05572,0.37942,3.56175,43.63331
52.43000,43.69168,32.15545,0.37993,3.57283,43.69168
52.50000,43.75000,32.24636,0.38043,3.58293,43.75000
52.57000,43.80831,32.15353,0.38094,3.57261,43.80831
52.64000,43.86668,32.38454,0.38145,3.59828,43.86668
52.71000,43.92506,32.18219,0.38196,3.57580,43.92506
52.78000,43.98331,32.22152,0.38246,3.58017,43.98331
52.85000,44.04168,32.30577,0.38297,3.58953,44.04168
52.92000,44.09999,32.25419,0.38348,3.58380,44.09999
52.99000,44.15837,32.43043,0.38399,3.60338,44.15837
53.06000,44.21668,32.56528,0.38449,3.61836,44.21668
53.13000,44.27487,32.57057,0.38500,3.61895,44.27487
53.20000,44.33325,32.43479,0.38551,3.60387,44.33325
53.27000,44.39168,32.57111,0.38601,3.61901,44.39168
53.34000,44.44999,32.33614,0.38652,3.59290,44.44999
53.41000,44.50837,32.51208,0.38703,3.61245,44.50837
53.48000,44.56656,32.57777,0.38754,3.61975,44.56656
53.55000,44.62493,32.54613,0.38804,3.61624,44.62493
53.62000,44.68337,32.59486,0.38855,3.62165,44.68337
53.69000,44.74175,32.44552,0.38906,3.60506,44.74175
53.76000,44.80006,32.78129,0.38957,3.64237,44.80006
53.83000,44.85837,32.76253,0.39007,3.64028,44.85837
53.90000,44.91656,32.61054,0.39058,3.62339,44.91656
53.97000,44.97499,32.67490,0.39109,3.63054,44.97499
54.04000,45.03337,32.74989,0.39159,3.63888,45.03337
54.11000,45.09162,32.69812,0.39210,3.63312,45.09162
54.18000,45.14999,32.68671,0.39261,3.63186,45.14999
54.25000,45.20830,32.75685,0.39312,3.63965,45.20830
54.32000,45.26662,32.99358,0.39362,3.66595,45.26662
54.39000,45.32500,32.84458,0.39413,3.64940,45.32500
54.46000,45.38337,33.02875,0.39464,3.66986,45.38337
54.53000,45.44162,32.83777,0.39514,3.64864,45.44162
54.60000,45.49993,32.80079,0.39565,3.64453,45.49993
54.67000,45.55831,32.79907,0.39616,3.64434,45.55831
54.74000,45.61668,32.91531,0.39667,3.65726,45.61668
54.81000,45.67499,32.82562,0.39717,3.64729,45.67499
54.88000,45.73337,33.04394,0.39768,3.67155,45.73337
54.95000,45.79168,32.87661,0.39819,3.65296,45.79168
55.02000,45.84999,32.86006,0.39870,3.65112,45.84999
55.09000,45.90830,33.27249,0.39920,3.69694,45.90830
55.16000,45.96668,33.12774,0.39971,3.68086,45.96668
55.23000,46.02499,33.16012,0.40022,3.68446,46.02499
55.30000,46.08330,33.16027,0.40072,3.68447,46.08330
55.37000,46.14162,32.98795,0.40123,3.66533,46.14162
55.44000,46.19993,33.07793,0.40174,3.67533,46.19993
55.51000,46.25831,33.22326,0.40225,3.69147,46.25831
55.58000,46.31668,33.28542,0.40275,3.69838,46.31668
55.65000,46.37506,33.26107,0.40326,3.69567,46.37506
55.72000,46.43331,33.37682,0.40377,3.70854,46.43331
55.79000,46.49162,33.41669,0.40427,3.71297,46.49162
55.86000,46.54999,33.23634,0.40478,3.69293,46.54999
55.93000,46.60837,33.34214,0.40529,3.70468,46.60837
56.00000,46.66668,33.31779,0.40580,3.70198,46.66668
56.07000,46.72505,33.32416,0.40630,3.70268,46.72505
56.14000,46.78330,33.39132,0.40681,3.71015,46.78330
56.21000,46.84168,33.50496,0.40732,3.72277,46.84168
56.28000,46.90005,33.37172,0.40783,3.70797,46.90005
56.35000,46.95836,33.38750,0.40833,3.70972,46.95836
56.42000,47.01662,33.23688,0.40884,3.69299,47.01662
56.49000,47.07493,33.36781,0.40935,3.70753,47.07493
56.56000,47.13336,33.51608,0.40986,3.72401,47.13336
56.63000,47.19162,33.45597,0.41036,3.71733,47.19162
56.70000,47.24993,33.26803,0.41087,3.69645,47.24993
56.77000,47.30830,33.69329,0.41138,3.74370,47.30830
56.84000,47.36668,33.47772,0.41188,3.71975,47.36668
56.91000,47.42499,33.44412,0.41239,3.71601,47.42499
56.98000,47.48330,33.56114,0.41290,3.72902,47.48330
57.05000,47.54161,33.70652,0.41341,3.74517,47.54161
57.12000,47.59999,33.83980,0.41391,3.75998,47.59999
57.19000,47.65843,33.61272,0.41442,3.73475,47.65843
57.26000,47.71668,33.44936,0.41493,3.71660,47.71668
57.33000,47.77493,33.03345,0.41543,3.67038,47.77493
57.40000,47.83324,32.78080,0.41594,3.64231,47.83324
57.47000,47.89168,-0.55083,0.41645,-0.06120,47.89168
57.54000,47.94999,0.12895,0.41696,0.01433,47.94999
57.61000,48.00831,-0.18285,0.41746,-0.02032,48.00831
57.68000,48.06655,-0.16451,0.41797,-0.01828,48.06655
57.75000,48.12500,-0.03326,0.41848,-0.00370,48.12500
57.82000,48.18337,-0.08927,0.41899,-0.00992,48.18337
57.89000,48.24175,-0.08415,0.41949,-0.00935,48.24175
57.96000,48.30006,0.13029,0.42000,0.01448,48.30006
58.03000,48.35837,-0.03923,0.42051,-0.00436,48.35837
58.10000,48.41674,-0.01127,0.42102,-0.00125,48.41674
58.17000,48.47506,0.04350,0.42152,0.00483,48.47506
58.24000,48.53343,-0.14952,0.42203,-0.01661,48.53343
58.31000,48.59168,0.04039,0.42254,0.00449,48.59168
58.38000,48.64999,-0.00507,0.42304,-0.00056,48.64999
58.45000,48.70831,-0.09652,0.42355,-0.01072,48.70831
58.52000,48.76662,-0.12177,0.42406,-0.01353,48.76662
58.59000,48.82493,-0.00730,0.42456,-0.00081,48.82493
58.66000,48.88331,0.05422,0.42507,0.00602,48.88331
58.73000,48.94162,-0.09201,0.42558,-0.01022,48.94162
58.80000,48.99999,-0.21163,0.42609,-0.02351,48.99999
58.87000,49.05831,-0.27447,0.42659,-0.03050,49.05831
58.94000,49.11668,-0.05559,0.42710,-0.00618,49.11668
59.01000,49.17506,-0.06098,0.42761,-0.00678,49.17506
59.08000,49.23343,-0.02194,0.42812,-0.00244,49.23343
59.15000,49.29168,-0.14114,0.42862,-0.01568,49.29168
59.22000,49.34999,-0.00666,0.42913,-0.00074,49.34999
59.29000,49.40837,0.17820,0.42964,0.01980,49.40837
59.36000,49.46662,0.04428,0.43014,0.00492,49.46662
59.43000,49.52499,-0.08310,0.43065,-0.00923,49.52499
59.50000,49.58337,-0.01837,0.43116,-0.00204,49.58337
59.57000,49.64162,-0.09052,0.43167,-0.01006,49.64162
59.57600,49.64662,-0.13316,0.43171,-0.01480,49.64662