File: V_8/NatR/RDSO NatR Tensile 50.is_tens_RawData/Specimen_RawData_11.csv
Time,Extension,Load,Tensile strain,Tensile stress,Corrected Position
(sec),(mm),(N),(mm/mm),(MPa),(mm)
0.00000,0.00000,0.12306,0.00000,0.01367,0.00000
0.06000,0.03169,0.25247,0.00028,0.02805,0.03169
0.12000,0.09562,0.38744,0.00083,0.04305,0.09562
0.18000,0.14769,0.58041,0.00128,0.06449,0.14769
0.24000,0.19881,0.94300,0.00173,0.10478,0.19881
0.30000,0.24944,0.91550,0.00217,0.10172,0.24944
0.36000,0.29975,1.05544,0.00261,0.11727,0.29975
0.42000,0.34981,1.19524,0.00304,0.13280,0.34981
0.48000,0.39981,1.49934,0.00348,0.16659,0.39981
0.54000,0.44987,1.68268,0.00391,0.18696,0.44987
0.60000,0.49994,1.59133,0.00435,0.17681,0.49994
0.66000,0.54994,1.78251,0.00478,0.19806,0.54994
0.72000,0.59994,1.91047,0.00522,0.21227,0.59994
0.78000,0.64994,2.13359,0.00565,0.23707,0.64994
0.84000,0.70000,2.02531,0.00609,0.22503,0.70000
0.90000,0.75000,2.35313,0.00652,0.26146,0.75000
0.96000,0.80000,2.34411,0.00696,0.26046,0.80000
1.02000,0.85000,2.37909,0.00739,0.26434,0.85000
1.08000,0.90000,2.76042,0.00783,0.30671,0.90000
1.14000,0.95000,2.69723,0.00826,0.29969,0.95000
1.20000,0.99994,2.73913,0.00870,0.30435,0.99994
1.26000,1.05000,3.18088,0.00913,0.35343,1.05000
1.32000,1.10000,3.04003,0.00957,0.33778,1.10000
1.38000,1.15000,2.78620,0.01000,0.30958,1.15000
1.44000,1.19994,3.06819,0.01043,0.34091,1.19994
1.50000,1.24994,3.18783,0.01087,0.35420,1.24994
1.56000,1.29994,3.23738,0.01130,0.35971,1.29994
1.62000,1.34994,3.34766,0.01174,0.37196,1.34994
1.68000,1.39994,3.24696,0.01217,0.36077,1.39994
1.74000,1.45000,3.39158,0.01261,0.37684,1.45000
1.80000,1.50012,3.53208,0.01304,0.39245,1.50012
1.86000,1.55006,3.78326,0.01348,0.42036,1.55006
1.92000,1.60006,3.75559,0.01391,0.41729,1.60006
1.98000,1.65000,4.03611,0.01435,0.44846,1.65000
2.04000,1.70000,3.88926,0.01478,0.43214,1.70000
2.10000,1.75000,4.12482,0.01522,0.45831,1.75000
2.16000,1.80006,4.04799,0.01565,0.44978,1.80006
2.22000,1.84994,4.13491,0.01609,0.45943,1.84994
2.28000,1.90006,4.50181,0.01652,0.50020,1.90006
2.34000,1.94994,4.28719,0.01696,0.47635,1.94994
2.40000,1.99987,4.41455,0.01739,0.49051,1.99987
2.46000,2.04994,4.51832,0.01783,0.50204,2.04994
2.52000,2.10000,4.48388,0.01826,0.49821,2.10000
2.58000,2.14994,4.74684,0.01870,0.52743,2.14994
2.64000,2.20000,4.60803,0.01913,0.51200,2.20000
2.70000,2.25000,4.85353,0.01957,0.53928,2.25000
2.76000,2.30000,4.75079,0.02000,0.52787,2.30000
2.82000,2.35006,4.89947,0.02044,0.54439,2.35006
2.88000,2.40006,5.13713,0.02087,0.57079,2.40006
2.94000,2.45000,5.07250,0.02130,0.56361,2.45000
3.00000,2.50000,5.09116,0.02174,0.56568,2.50000
3.06000,2.55000,5.27122,0.02217,0.58569,2.55000
3.12000,2.60006,5.38829,0.02261,0.59870,2.60006
3.18000,2.65012,5.30970,0.02304,0.58997,2.65012
3.24000,2.70000,5.49027,0.02348,0.61003,2.70000
3.30000,2.75000,5.64586,0.02391,0.62732,2.75000
3.36000,2.80006,5.59098,0.02435,0.62122,2.80006
3.42000,2.85006,5.68294,0.02478,0.63144,2.85006
3.48000,2.90006,5.67780,0.02522,0.63087,2.90006
3.54000,2.94994,5.69411,0.02565,0.63268,2.94994
3.60000,2.99994,5.93023,0.02609,0.65891,2.99994
3.66000,3.04994,6.08585,0.02652,0.67621,3.04994
3.72000,3.10000,5.98267,0.02696,0.66474,3.10000
3.78000,3.15006,6.02712,0.02739,0.66968,3.15006
3.84000,3.20000,6.26118,0.02783,0.69569,3.20000
3.90000,3.24994,6.22613,0.02826,0.69179,3.24994
3.96000,3.29994,6.31934,0.02870,0.70215,3.29994
4.02000,3.35000,6.45233,0.02913,0.71693,3.35000
4.08000,3.40006,6.30276,0.02957,0.70031,3.40006
4.14000,3.45006,6.65282,0.03000,0.73920,3.45006
4.20000,3.50000,6.59519,0.03043,0.73280,3.50000
4.26000,3.55000,6.81801,0.03087,0.75756,3.55000
4.32000,3.60000,6.81074,0.03130,0.75675,3.60000
4.38000,3.65000,6.70772,0.03174,0.74530,3.65000
4.44000,3.70006,6.86792,0.03217,0.76310,3.70006
4.50000,3.75000,7.08704,0.03261,0.78745,3.75000
4.56000,3.80000,7.10767,0.03304,0.78974,3.80000
4.62000,3.84994,7.04800,0.03348,0.78311,3.84994
4.68000,3.90000,7.27923,0.03391,0.80880,3.90000
4.74000,3.95000,7.35730,0.03435,0.81748,3.95000
4.80000,4.00000,7.40592,0.03478,0.82288,4.00000
4.86000,4.05000,7.41052,0.03522,0.82339,4.05000
4.92000,4.10000,7.57148,0.03565,0.84128,4.10000
4.98000,4.15000,7.55218,0.03609,0.83913,4.15000
5.04000,4.19987,7.55740,0.03652,0.83971,4.19987
5.10000,4.25000,7.53308,0.03696,0.83701,4.25000
5.16000,4.30000,7.45385,0.03739,0.82821,4.30000
5.22000,4.35000,7.75002,0.03783,0.86111,4.35000
5.28000,4.40006,7.92675,0.03826,0.88075,4.40006
5.34000,4.45000,7.80838,0.03870,0.86760,4.45000
5.40000,4.50000,7.86099,0.03913,0.87344,4.50000
5.46000,4.55000,8.25694,0.03957,0.91744,4.55000
5.52000,4.60000,8.11783,0.04000,0.90198,4.60000
5.58000,4.65000,8.26926,0.04043,0.91881,4.65000
5.64000,4.70000,8.38686,0.04087,0.93187,4.70000
5.70000,4.75000,8.37694,0.04130,0.93077,4.75000
5.76000,4.80000,8.38596,0.04174,0.93177,4.80000
5.82000,4.84994,8.38934,0.04217,0.93215,4.84994
5.88000,4.90000,8.43839,0.04261,0.93760,4.90000
5.94000,4.95000,8.62842,0.04304,0.95871,4.95000
6.00000,4.99994,8.60589,0.04348,0.95621,4.99994
6.06000,5.05006,8.62834,0.04391,0.95871,5.05006
6.12000,5.10006,8.67831,0.04435,0.96426,5.10006
6.18000,5.14994,8.76745,0.04478,0.97416,5.14994
6.24000,5.19994,8.70130,0.04522,0.96681,5.19994
6.30000,5.25000,9.03904,0.04565,1.00434,5.25000
6.36000,5.30006,8.74740,0.04609,0.97193,5.30006
6.42000,5.35006,8.98290,0.04652,0.99810,5.35006
6.48000,5.40006,9.08501,0.04696,1.00945,5.40006
6.54000,5.45000,9.14452,0.04739,1.01606,5.45000
6.60000,5.50000,9.09458,0.04783,1.01051,5.50000
6.66000,5.55000,9.14552,0.04826,1.01617,5.55000
6.72000,5.60000,9.32735,0.04870,1.03637,5.60000
6.78000,5.65006,9.34961,0.04913,1.03885,5.65006
6.84000,5.70000,9.49352,0.04957,1.05484,5.70000
6.90000,5.74994,9.48047,0.05000,1.05339,5.74994
6.96000,5.79994,9.63491,0.05043,1.07055,5.79994
7.02000,5.84994,9.69072,0.05087,1.07675,5.84994
7.08000,5.90006,9.72596,0.05130,1.08066,5.90006
7.14000,5.94994,9.62611,0.05174,1.06957,5.94994
7.20000,6.00000,9.62435,0.05217,1.06937,6.00000
7.26000,6.05000,9.95074,0.05261,1.10564,6.05000
7.32000,6.10006,9.82457,0.05304,1.09162,6.10006
7.38000,6.15006,9.95794,0.05348,1.10644,6.15006
7.44000,6.20000,9.83615,0.05391,1.09291,6.20000
7.50000,6.25000,10.09718,0.05435,1.12191,6.25000
7.56000,6.30006,10.31975,0.05478,1.14664,6.30006
7.62000,6.35006,10.10614,0.05522,1.12290,6.35006
7.68000,6.40006,10.15490,0.05565,1.12832,6.40006
7.74000,6.45000,10.25791,0.05609,1.13977,6.45000
7.80000,6.49994,10.43677,0.05652,1.15964,6.49994
7.86000,6.55000,10.48507,0.05696,1.16501,6.55000
7.92000,6.60000,10.49827,0.05739,1.16647,6.60000
7.98000,6.65012,10.45693,0.05783,1.16188,6.65012
8.04000,6.69994,10.47321,0.05826,1.16369,6.69994
8.10000,6.74981,10.84697,0.05869,1.20522,6.74981
8.16000,6.79994,10.70115,0.05913,1.18902,6.79994
8.22000,6.85000,10.73142,0.05957,1.19238,6.85000
8.28000,6.90006,10.73123,0.06000,1.19236,6.90006
8.34000,6.95000,10.85488,0.06043,1.20610,6.95000
8.40000,7.00000,11.02426,0.06087,1.22492,7.00000
8.46000,7.05000,11.08902,0.06130,1.23211,7.05000
8.52000,7.10006,11.01724,0.06174,1.22414,7.10006
8.58000,7.15012,11.16644,0.06217,1.24072,7.15012
8.64000,7.20006,11.18573,0.06261,1.24286,7.20006
8.70000,7.25000,11.35575,0.06304,1.26175,7.25000
8.76000,7.30000,11.42036,0.06348,1.26893,7.30000
8.82000,7.35000,11.37116,0.06391,1.26346,7.35000
8.88000,7.40000,11.41233,0.06435,1.26804,7.40000
8.94000,7.44994,11.30993,0.06478,1.25666,7.44994
9.00000,7.49987,11.48480,0.06522,1.27609,7.49987
9.06000,7.54994,11.52638,0.06565,1.28071,7.54994
9.12000,7.60000,11.73054,0.06609,1.30339,7.60000
9.18000,7.65000,11.55981,0.06652,1.28442,7.65000
9.24000,7.70000,11.85035,0.06696,1.31671,7.70000
9.30000,7.74994,11.92632,0.06739,1.32515,7.74994
9.36000,7.80000,11.80210,0.06783,1.31134,7.80000
9.42000,7.85006,11.90105,0.06826,1.32234,7.85006
9.48000,7.90006,12.30535,0.06870,1.36726,7.90006
9.54000,7.95000,12.24424,0.06913,1.36047,7.95000
9.60000,7.99994,12.13935,0.06956,1.34882,7.99994
9.66000,8.05000,12.19599,0.07000,1.35511,8.05000
9.72000,8.10000,12.14564,0.07043,1.34952,8.10000
9.78000,8.15006,12.33327,0.07087,1.37036,8.15006
9.84000,8.20006,12.37000,0.07130,1.37444,8.20006
9.90000,8.25006,12.46488,0.07174,1.38499,8.25006
9.96000,8.30000,12.47042,0.07217,1.38560,8.30000
10.02000,8.34994,12.51558,0.07261,1.39062,8.34994
10.08000,8.40000,12.63047,0.07304,1.40339,8.40000
10.14000,8.45000,12.81613,0.07348,1.42401,8.45000
10.20000,8.49994,12.82444,0.07391,1.42494,8.49994
10.26000,8.54994,12.75713,0.07435,1.41746,8.54994
10.32000,8.60000,12.72721,0.07478,1.41413,8.60000
10.38000,8.65000,12.88860,0.07522,1.43207,8.65000
10.44000,8.70000,12.91569,0.07565,1.43508,8.70000
10.50000,8.75000,12.95701,0.07609,1.43967,8.75000
10.56000,8.80000,13.18098,0.07652,1.46455,8.80000
10.62000,8.85006,13.05010,0.07696,1.45001,8.85006
10.68000,8.90012,13.14434,0.07739,1.46048,8.90012
10.74000,8.95006,13.25291,0.07783,1.47255,8.95006
10.80000,9.00000,13.18933,0.07826,1.46548,9.00000
10.86000,9.05000,13.19242,0.07870,1.46582,9.05000
10.92000,9.10006,13.21713,0.07913,1.46857,9.10006
10.98000,9.15006,13.40600,0.07957,1.48956,9.15006
11.04000,9.20000,13.56434,0.08000,1.50715,9.20000
11.10000,9.24994,13.31245,0.08043,1.47916,9.24994
11.16000,9.30000,13.61878,0.08087,1.51320,9.30000
11.22000,9.35000,13.63928,0.08130,1.51548,9.35000
11.28000,9.40000,13.64785,0.08174,1.51643,9.40000
11.34000,9.45000,13.65383,0.08217,1.51709,9.45000
11.40000,9.50000,13.55834,0.08261,1.50648,9.50000
11.46000,9.55000,13.67107,0.08304,1.51901,9.55000
11.52000,9.59994,13.53392,0.08348,1.50377,9.59994
11.58000,9.65000,13.86492,0.08391,1.54055,9.65000
11.64000,9.70000,13.93469,0.08435,1.54830,9.70000
11.70000,9.75006,14.11289,0.08478,1.56810,9.75006
11.76000,9.80006,13.97635,0.08522,1.55293,9.80006
11.82000,9.85012,14.14662,0.08565,1.57185,9.85012
11.88000,9.90006,13.97420,0.08609,1.55269,9.90006
11.94000,9.94994,14.11460,0.08652,1.56829,9.94994
12.00000,10.00000,14.21269,0.08696,1.57919,10.00000
12.06000,10.05006,14.27262,0.08739,1.58585,10.05006
12.12000,10.10000,14.30801,0.08783,1.58978,10.10000
12.18000,10.15000,14.28384,0.08826,1.58709,10.15000
12.24000,10.19994,14.48467,0.08870,1.60941,10.19994
12.30000,10.25000,14.51903,0.08913,1.61323,10.25000
12.36000,10.29994,14.53531,0.08956,1.61503,10.29994
12.42000,10.34994,14.47374,0.09000,1.60819,10.34994
12.48000,10.40006,14.64809,0.09044,1.62757,10.40006
12.54000,10.44994,14.75206,0.09087,1.63912,10.44994
12.60000,10.49994,14.79502,0.09130,1.64389,10.49994
12.66000,10.54994,14.68258,0.09174,1.63140,10.54994
12.72000,10.60000,14.83636,0.09217,1.64848,10.60000
12.78000,10.65006,14.76499,0.09261,1.64055,10.65006
12.84000,10.70006,14.92663,0.09304,1.65851,10.70006
12.90000,10.75000,14.86790,0.09348,1.65199,10.75000
12.96000,10.80000,15.14992,0.09391,1.68332,10.80000
13.02000,10.85000,14.89754,0.09435,1.65528,10.85000
13.08000,10.90000,15.12900,0.09478,1.68100,10.90000
13.14000,10.94994,15.02761,0.09522,1.66973,10.94994
13.20000,10.99994,15.33941,0.09565,1.70438,10.99994
13.26000,11.05000,15.26223,0.09609,1.69580,11.05000
13.32000,11.10000,15.30184,0.09652,1.70020,11.10000
13.38000,11.15006,15.08215,0.09696,1.67579,11.15006
13.44000,11.19994,15.30551,0.09739,1.70061,11.19994
13.50000,11.24994,15.52067,0.09783,1.72452,11.24994
13.56000,11.29994,15.46906,0.09826,1.71878,11.29994
13.62000,11.35000,15.53230,0.09870,1.72581,11.35000
13.68000,11.40012,15.22075,0.09913,1.69119,11.40012
13.74000,11.45006,15.47127,0.09957,1.71903,11.45006
13.80000,11.49994,15.61190,0.10000,1.73466,11.49994
13.86000,11.54994,15.50416,0.10043,1.72268,11.54994
13.92000,11.60006,15.61648,0.10087,1.73516,11.60006
13.98000,11.65006,15.73949,0.10130,1.74883,11.65006
14.04000,11.70000,15.79416,0.10174,1.75491,11.70000
14.10000,11.75000,15.69918,0.10217,1.74435,11.75000
14.16000,11.80000,15.81204,0.10261,1.75689,11.80000
14.22000,11.85000,15.92426,0.10304,1.76936,11.85000
14.28000,11.90006,15.94811,0.10348,1.77201,11.90006
14.34000,11.95000,16.03905,0.10391,1.78212,11.95000
14.40000,12.00000,15.95443,0.10435,1.77271,12.00000
14.46000,12.04994,15.97958,0.10478,1.77551,12.04994
14.52000,12.10000,16.19040,0.10522,1.79893,12.10000
14.58000,12.15000,15.94742,0.10565,1.77194,12.15000
14.64000,12.20000,16.24355,0.10609,1.80484,12.20000
14.70000,12.24994,16.33529,0.10652,1.81503,12.24994
14.76000,12.30000,16.18406,0.10696,1.79823,12.30000
14.82000,12.35006,16.28829,0.10739,1.80981,12.35006
14.88000,12.40012,16.20434,0.10783,1.80048,12.40012
14.94000,12.45000,16.49316,0.10826,1.83257,12.45000
15.00000,12.50000,16.52963,0.10870,1.83663,12.50000
15.06000,12.55000,16.33811,0.10913,1.81535,12.55000
15.12000,12.60006,16.41339,0.10957,1.82371,12.60006
15.18000,12.65006,16.50144,0.11000,1.83349,12.65006
15.24000,12.70000,16.45718,0.11043,1.82858,12.70000
15.30000,12.75000,16.78989,0.11087,1.86554,12.75000
15.36000,12.79994,16.87037,0.11130,1.87449,12.79994
15.42000,12.84994,16.66849,0.11174,1.85205,12.84994
15.48000,12.90000,16.71701,0.11217,1.85745,12.90000
15.54000,12.95000,16.76670,0.11261,1.86297,12.95000
15.60000,13.00006,16.87569,0.11304,1.87508,13.00006
15.66000,13.05000,16.78291,0.11348,1.86477,13.05000
15.72000,13.09994,16.94487,0.11391,1.88276,13.09994
15.78000,13.15000,17.05165,0.11435,1.89463,13.15000
15.84000,13.20000,17.06373,0.11478,1.89597,13.20000
15.90000,13.25000,16.94402,0.11522,1.88267,13.25000
15.96000,13.30000,17.01445,0.11565,1.89049,13.30000
16.02000,13.35000,16.99856,0.11609,1.88873,13.35000
16.08000,13.40006,17.22745,0.11652,1.91416,13.40006
16.14000,13.45006,17.00103,0.11696,1.88900,13.45006
16.20000,13.50000,17.32177,0.11739,1.92464,13.50000
16.26000,13.55000,17.15136,0.11783,1.90571,13.55000
16.32000,13.60000,17.18281,0.11826,1.90920,13.60000
16.38000,13.65000,17.16694,0.11870,1.90744,13.65000
16.44000,13.70000,17.36806,0.11913,1.92978,13.70000
16.50000,13.75000,17.19429,0.11957,1.91048,13.75000
16.56000,13.79994,17.52688,0.12000,1.94743,13.79994
16.62000,13.85000,17.30764,0.12043,1.92307,13.85000
16.68000,13.90000,17.59879,0.12087,1.95542,13.90000
16.74000,13.95000,17.35552,0.12130,1.92839,13.95000
16.80000,14.00000,17.36348,0.12174,1.92928,14.00000
16.86000,14.05000,17.62286,0.12217,1.95810,14.05000
16.92000,14.10000,17.65262,0.12261,1.96140,14.10000
16.98000,14.15000,17.68904,0.12304,1.96545,14.15000
17.04000,14.20000,17.70148,0.12348,1.96683,14.20000
17.10000,14.25000,17.79031,0.12391,1.97670,14.25000
17.16000,14.30006,17.69886,0.12435,1.96654,14.30006
17.22000,14.35006,17.72967,0.12478,1.96996,14.35006
17.28000,14.40006,17.67956,0.12522,1.96440,14.40006
17.34000,14.45000,18.02119,0.12565,2.00235,14.45000
17.40000,14.50000,17.94784,0.12609,1.99420,14.50000
17.46000,14.55000,17.99736,0.12652,1.99971,14.55000
17.52000,14.60006,17.83442,0.12696,1.98160,14.60006
17.58000,14.65006,18.14046,0.12739,2.01561,14.65006
17.64000,14.69981,17.87659,0.12782,1.98629,14.69981
17.70000,14.74987,17.93392,0.12826,1.99266,14.74987
17.76000,14.80000,18.15385,0.12870,2.01710,14.80000
17.82000,14.85000,18.21312,0.12913,2.02368,14.85000
17.88000,14.90006,18.29314,0.12957,2.03257,14.90006
17.94000,14.95000,18.10076,0.13000,2.01120,14.95000
18.00000,15.00000,18.16897,0.13043,2.01877,15.00000
18.06000,15.05000,18.22312,0.13087,2.02479,15.05000
18.12000,15.10006,18.40734,0.13130,2.04526,15.10006
18.18000,15.15006,18.24876,0.13174,2.02764,15.15006
18.24000,15.20006,18.46744,0.13217,2.05194,15.20006
18.30000,15.25000,18.44995,0.13261,2.04999,15.25000
18.36000,15.30006,18.59149,0.13304,2.06572,15.30006
18.42000,15.35006,18.32946,0.13348,2.03661,15.35006
18.48000,15.40000,18.66738,0.13391,2.07415,15.40000
18.54000,15.44994,18.66609,0.13435,2.07401,15.44994
18.60000,15.49994,18.71642,0.13478,2.07960,15.49994
18.66000,15.54994,18.68514,0.13522,2.07613,15.54994
18.72000,15.60000,18.76226,0.13565,2.08470,15.60000
18.78000,15.65000,18.79055,0.13609,2.08784,15.65000
18.84000,15.69993,18.65154,0.13652,2.07239,15.69993
18.90000,15.74993,18.43193,0.13696,2.04799,15.74993
18.96000,15.80000,18.92586,0.13739,2.10287,15.80000
19.02000,15.85000,18.92104,0.13783,2.10234,15.85000
19.08000,15.90006,18.79459,0.13826,2.08829,15.90006
19.14000,15.94994,18.92797,0.13870,2.10311,15.94994
19.20000,16.00000,18.79606,0.13913,2.08845,16.00000
19.26000,16.05000,19.01256,0.13957,2.11251,16.05000
19.32000,16.10006,19.05119,0.14000,2.11680,16.10006
19.38000,16.15012,19.13382,0.14044,2.12598,16.15012
19.44000,16.20006,19.12748,0.14087,2.12528,16.20006
19.50000,16.25000,19.07477,0.14130,2.11942,16.25000
19.56000,16.29987,19.00948,0.14174,2.11216,16.29987
19.62000,16.35000,19.04477,0.14217,2.11609,16.35000
19.68000,16.40000,19.22044,0.14261,2.13560,16.40000
19.74000,16.44993,19.13308,0.14304,2.12590,16.44993
19.80000,16.50000,19.20636,0.14348,2.13404,16.50000
19.86000,16.54994,19.22826,0.14391,2.13647,16.54994
19.92000,16.60000,19.23328,0.14435,2.13703,16.60000
19.98000,16.65000,19.31052,0.14478,2.14561,16.65000
20.04000,16.70000,19.29671,0.14522,2.14408,16.70000
20.10000,16.75000,19.25174,0.14565,2.13908,16.75000
20.16000,16.80006,19.26218,0.14609,2.14024,16.80006
20.22000,16.85000,19.14506,0.14652,2.12723,16.85000
20.28000,16.90006,19.33337,0.14696,2.14815,16.90006
20.34000,16.95000,19.32813,0.14739,2.14757,16.95000
20.40000,17.00000,19.57779,0.14783,2.17531,17.00000
20.46000,17.05000,19.45291,0.14826,2.16143,17.05000
20.52000,17.10000,19.50716,0.14870,2.16746,17.10000
20.58000,17.15006,19.56922,0.14913,2.17436,17.15006
20.64000,17.20000,19.64169,0.14957,2.18241,17.20000
20.70000,17.24993,19.57576,0.15000,2.17508,17.24993
20.76000,17.29993,19.62496,0.15043,2.18055,17.29993
20.82000,17.35000,19.65663,0.15087,2.18407,17.35000
20.88000,17.40006,19.72890,0.15130,2.19210,17.40006
20.94000,17.44993,19.66246,0.15174,2.18472,17.44993
21.00000,17.50000,19.57868,0.15217,2.17541,17.50000
21.06000,17.54993,19.71063,0.15261,2.19007,17.54993
21.12000,17.60000,19.66545,0.15304,2.18505,17.60000
21.18000,17.65000,19.67622,0.15348,2.18625,17.65000
21.24000,17.70000,19.86899,0.15391,2.20767,17.70000
21.30000,17.75006,20.04166,0.15435,2.22685,17.75006
21.36000,17.80012,19.90064,0.15478,2.21118,17.80012
21.42000,17.85006,20.03024,0.15522,2.22558,17.85006
21.48000,17.90000,19.90064,0.15565,2.21118,17.90000
21.54000,17.94994,19.83576,0.15609,2.20397,17.94994
21.60000,18.00000,20.04531,0.15652,2.22726,18.00000
21.66000,18.05000,20.07391,0.15696,2.23043,18.05000
21.72000,18.10006,20.12248,0.15739,2.23583,18.10006
21.78000,18.15000,20.05716,0.15783,2.22857,18.15000
21.84000,18.20000,20.19086,0.15826,2.24343,18.20000
21.90000,18.24994,19.94374,0.15870,2.21597,18.24994
21.96000,18.30000,20.02961,0.15913,2.22551,18.30000
22.02000,18.35000,19.95579,0.15957,2.21731,18.35000
22.08000,18.40000,20.21753,0.16000,2.24639,18.40000
22.14000,18.45006,20.23002,0.16044,2.24778,18.45006
22.20000,18.50006,20.17457,0.16087,2.24162,18.50006
22.26000,18.55000,20.10536,0.16130,2.23393,18.55000
22.32000,18.60006,20.28990,0.16174,2.25443,18.60006
22.38000,18.65006,20.08937,0.16217,2.23215,18.65006
22.44000,18.70000,20.46396,0.16261,2.27377,18.70000
22.50000,18.75006,20.22429,0.16304,2.24714,18.75006
22.56000,18.79987,20.39362,0.16348,2.26596,18.79987
22.62000,18.84994,20.34437,0.16391,2.26049,18.84994
22.68000,18.90000,20.30469,0.16435,2.25608,18.90000
22.74000,18.94994,20.34189,0.16478,2.26021,18.94994
22.80000,19.00000,20.31233,0.16522,2.25693,19.00000
22.86000,19.05000,20.41137,0.16565,2.26793,19.05000
22.92000,19.10000,20.45205,0.16609,2.27245,19.10000
22.98000,19.15000,20.44226,0.16652,2.27136,19.15000
23.04000,19.19993,20.59307,0.16696,2.28812,19.19993
23.10000,19.24993,20.40591,0.16739,2.26732,19.24993
23.16000,19.30000,20.67103,0.16783,2.29678,19.30000
23.22000,19.35012,20.56528,0.16826,2.28503,19.35012
23.28000,19.40012,20.51394,0.16870,2.27933,19.40012
23.34000,19.44994,20.45857,0.16913,2.27317,19.44994
23.40000,19.49987,20.83843,0.16956,2.31538,19.49987
23.46000,19.55000,20.64059,0.17000,2.29340,19.55000
23.52000,19.60006,20.77541,0.17044,2.30838,19.60006
23.58000,19.65006,20.58651,0.17087,2.28739,19.65006
23.64000,19.70000,20.73074,0.17130,2.30342,19.70000
23.70000,19.75000,20.63655,0.17174,2.29295,19.75000
23.76000,19.80006,20.66405,0.17217,2.29601,19.80006
23.82000,19.85006,20.71080,0.17261,2.30120,19.85006
23.88000,19.90006,20.66390,0.17304,2.29599,19.90006
23.94000,19.95000,20.73784,0.17348,2.30420,19.95000
24.00000,19.99993,20.79606,0.17391,2.31067,19.99993
24.06000,20.04993,20.65518,0.17435,2.29502,20.04993
24.12000,20.10000,20.94082,0.17478,2.32676,20.10000
24.18000,20.15000,20.83154,0.17522,2.31462,20.15000
24.24000,20.20000,20.85131,0.17565,2.31681,20.20000
24.30000,20.24994,20.85219,0.17609,2.31691,20.24994
24.36000,20.29993,20.88645,0.17652,2.32072,20.29993
24.42000,20.35006,20.86664,0.17696,2.31852,20.35006
24.48000,20.40006,21.08804,0.17739,2.34312,20.40006
24.54000,20.44993,21.03658,0.17783,2.33740,20.44993
24.60000,20.49993,21.07709,0.17826,2.34190,20.49993
24.66000,20.55006,21.07619,0.17870,2.34180,20.55006
24.72000,20.60012,21.20944,0.17913,2.35660,20.60012
24.78000,20.65012,21.21745,0.17957,2.35749,20.65012
24.84000,20.69993,21.12020,0.18000,2.34669,20.69993
24.90000,20.75000,21.38350,0.18043,2.37594,20.75000
24.96000,20.79993,21.28431,0.18087,2.36492,20.79993
25.02000,20.85000,21.16793,0.18130,2.35199,20.85000
25.08000,20.90000,21.04322,0.18174,2.33814,20.90000
25.14000,20.95000,21.37116,0.18217,2.37457,20.95000
25.20000,21.00000,21.24042,0.18261,2.36005,21.00000
25.26000,21.04981,21.20687,0.18304,2.35632,21.04981
25.32000,21.09993,21.24243,0.18348,2.36027,21.09993
25.38000,21.15000,21.30702,0.18391,2.36745,21.15000
25.44000,21.20000,21.40344,0.18435,2.37816,21.20000
25.50000,21.25000,21.33356,0.18478,2.37040,21.25000
25.56000,21.30000,21.41091,0.18522,2.37899,21.30000
25.62000,21.35006,21.32137,0.18565,2.36904,21.35006
25.68000,21.40012,21.51100,0.18609,2.39011,21.40012
25.74000,21.45000,21.57289,0.18652,2.39699,21.45000
25.80000,21.50006,21.53175,0.18696,2.39242,21.50006
25.86000,21.55006,21.34189,0.18739,2.37132,21.55006
25.92000,21.60006,21.54737,0.18783,2.39415,21.60006
25.98000,21.65006,21.55692,0.18826,2.39521,21.65006
26.04000,21.70000,21.56667,0.18870,2.39630,21.70000
26.10000,21.74993,21.62136,0.18913,2.40237,21.74993
26.16000,21.79994,21.61333,0.18956,2.40148,21.79994
26.22000,21.84993,21.59790,0.19000,2.39977,21.84993
26.28000,21.90006,21.66850,0.19044,2.40761,21.90006
26.34000,21.95000,21.65273,0.19087,2.40586,21.95000
26.40000,21.99993,21.64076,0.19130,2.40453,21.99993
26.46000,22.04994,21.65241,0.19174,2.40582,22.04994
26.52000,22.10000,21.65102,0.19217,2.40567,22.10000
26.58000,22.15006,21.81606,0.19261,2.42401,22.15006
26.64000,22.20000,21.86894,0.19304,2.42988,22.20000
26.70000,22.25000,22.00670,0.19348,2.44519,22.25000
26.76000,22.30000,21.95417,0.19391,2.43935,22.30000
26.82000,22.35000,21.94572,0.19435,2.43841,22.35000
26.88000,22.40006,21.83637,0.19478,2.42626,22.40006
26.94000,22.45000,21.71039,0.19522,2.41227,22.45000
27.00000,22.50000,22.04559,0.19565,2.44951,22.50000
27.06000,22.55000,21.81217,0.19609,2.42357,22.55000
27.12000,22.60006,21.96962,0.19652,2.44107,22.60006
27.18000,22.64993,21.72307,0.19696,2.41367,22.64993
27.24000,22.69994,22.18764,0.19739,2.46529,22.69994
27.30000,22.74993,22.04261,0.19783,2.44918,22.74993
27.36000,22.80000,22.07011,0.19826,2.45223,22.80000
27.42000,22.85000,22.06144,0.19870,2.45127,22.85000
27.48000,22.90006,22.18101,0.19913,2.46456,22.90006
27.54000,22.95000,22.03947,0.19957,2.44883,22.95000
27.60000,23.00000,22.06198,0.20000,2.45133,23.00000
27.66000,23.05000,22.12705,0.20043,2.45856,23.05000
27.72000,23.10006,22.29198,0.20087,2.47689,23.10006
27.78000,23.15012,22.16158,0.20131,2.46240,23.15012
27.84000,23.20000,22.40816,0.20174,2.48980,23.20000
27.90000,23.25000,22.23048,0.20217,2.47005,23.25000
27.96000,23.30000,22.06605,0.20261,2.45178,23.30000
28.02000,23.35000,22.35531,0.20304,2.48392,23.35000
28.08000,23.40000,22.12078,0.20348,2.45786,23.40000
28.14000,23.44999,22.34385,0.20391,2.48265,23.44999
28.20000,23.49993,22.44512,0.20435,2.49390,23.49993
28.26000,23.55000,22.60549,0.20478,2.51172,23.55000
28.32000,23.60006,22.38913,0.20522,2.48768,23.60006
28.38000,23.65000,22.41174,0.20565,2.49019,23.65000
28.44000,23.69993,22.55849,0.20609,2.50650,23.69993
28.50000,23.74993,22.40735,0.20652,2.48971,23.74993
28.56000,23.79999,22.52356,0.20696,2.50262,23.79999
28.62000,23.85006,22.53064,0.20739,2.50340,23.85006
28.68000,23.90000,22.67974,0.20783,2.51997,23.90000
28.74000,23.95000,22.47972,0.20826,2.49775,23.95000
28.80000,23.99993,22.62616,0.20870,2.51402,23.99993
28.86000,24.05006,22.67489,0.20913,2.51943,24.05006
28.92000,24.10006,22.63889,0.20957,2.51543,24.10006
28.98000,24.15012,22.94900,0.21000,2.54989,24.15012
29.04000,24.20000,22.79571,0.21043,2.53286,24.20000
29.10000,24.24987,22.69280,0.21087,2.52142,24.24987
29.16000,24.29993,22.88635,0.21130,2.54293,24.29993
29.22000,24.35000,22.74166,0.21174,2.52685,24.35000
29.28000,24.40000,22.86727,0.21217,2.54081,24.40000
29.34000,24.44993,22.95285,0.21261,2.55032,24.44993
29.40000,24.49993,23.09467,0.21304,2.56607,24.49993
29.46000,24.54993,22.84511,0.21348,2.53835,24.54993
29.52000,24.60000,22.81151,0.21391,2.53461,24.60000
29.58000,24.65006,22.85079,0.21435,2.53898,24.65006
29.64000,24.70006,23.00423,0.21478,2.55603,24.70006
29.70000,24.75000,23.06225,0.21522,2.56247,24.75000
29.76000,24.80000,23.09168,0.21565,2.56574,24.80000
29.82000,24.85006,23.28365,0.21609,2.58707,24.85006
29.88000,24.90006,23.02411,0.21652,2.55823,24.90006
29.94000,24.95000,22.99781,0.21696,2.55531,24.95000
30.00000,24.99999,23.19776,0.21739,2.57753,24.99999
30.06000,25.04993,23.19031,0.21783,2.57670,25.04993
30.12000,25.10000,23.14743,0.21826,2.57194,25.10000
30.18000,25.15006,23.17248,0.21870,2.57472,25.15006
30.24000,25.20000,23.21419,0.21913,2.57935,25.20000
30.30000,25.24993,23.40517,0.21956,2.60057,25.24993
30.36000,25.30000,23.25889,0.22000,2.58432,25.30000
30.42000,25.35000,23.40671,0.22043,2.60075,25.35000
30.48000,25.40000,23.31911,0.22087,2.59101,25.40000
30.54000,25.45000,23.18316,0.22130,2.57591,25.45000
30.60000,25.49987,23.41837,0.22174,2.60204,25.49987
30.66000,25.54993,23.18174,0.22217,2.57575,25.54993
30.72000,25.59993,23.51543,0.22261,2.61283,25.59993
30.78000,25.65006,23.27206,0.22304,2.58578,25.65006
30.84000,25.70006,23.47914,0.22348,2.60879,25.70006
30.90000,25.75006,23.38648,0.22391,2.59850,25.75006
30.96000,25.79993,23.38090,0.22435,2.59788,25.79993
31.02000,25.84993,23.46664,0.22478,2.60740,25.84993
31.08000,25.90006,23.46182,0.22522,2.60687,25.90006
31.14000,25.95000,23.48611,0.22565,2.60957,25.95000
31.20000,26.00000,23.62402,0.22609,2.62489,26.00000
31.26000,26.05000,23.70440,0.22652,2.63382,26.05000
31.32000,26.10000,23.64712,0.22696,2.62746,26.10000
31.38000,26.15006,23.60764,0.22739,2.62307,26.15006
31.44000,26.19999,23.51543,0.22783,2.61283,26.19999
31.50000,26.25000,23.79647,0.22826,2.64405,26.25000
31.56000,26.30000,23.92652,0.22870,2.65850,26.30000
31.62000,26.35000,23.77964,0.22913,2.64218,26.35000
31.68000,26.40000,23.72779,0.22957,2.63642,26.40000
31.74000,26.45000,23.94082,0.23000,2.66009,26.45000
31.80000,26.50000,23.64065,0.23043,2.62674,26.50000
31.86000,26.54999,23.66681,0.23087,2.62965,26.54999
31.92000,26.60000,23.78003,0.23130,2.64223,26.60000
31.98000,26.65006,23.68486,0.23174,2.63165,26.65006
32.04000,26.70000,23.86529,0.23217,2.65170,26.70000
32.10000,26.75000,24.01951,0.23261,2.66883,26.75000
32.16000,26.80000,23.85591,0.23304,2.65066,26.80000
32.22000,26.85006,23.78256,0.23348,2.64251,26.85006
32.28000,26.90006,24.02392,0.23391,2.66932,26.90006
32.34000,26.95012,24.00787,0.23435,2.66754,26.95012
32.40000,27.00000,24.07400,0.23478,2.67489,27.00000
32.46000,27.05000,24.06932,0.23522,2.67437,27.05000
32.52000,27.10000,24.23902,0.23565,2.69322,27.10000
32.58000,27.14993,24.12918,0.23609,2.68102,27.14993
32.64000,27.19993,24.00290,0.23652,2.66699,27.19993
32.70000,27.24993,24.19499,0.23696,2.68833,27.24993
32.76000,27.29993,24.31421,0.23739,2.70158,27.29993
32.82000,27.35000,24.34387,0.23783,2.70487,27.35000
32.88000,27.39993,24.33564,0.23826,2.70396,27.39993
32.94000,27.44993,24.22800,0.23870,2.69200,27.44993
33.00000,27.49993,24.26711,0.23913,2.69635,27.49993
33.06000,27.55000,24.32099,0.23957,2.70233,27.55000
33.12000,27.60000,24.26726,0.24000,2.69636,27.60000
33.18000,27.65012,24.45631,0.24044,2.71737,27.65012
33.24000,27.70006,24.25110,0.24087,2.69457,27.70006
33.30000,27.74999,24.41638,0.24130,2.71293,27.74999
33.36000,27.80000,24.31918,0.24174,2.70213,27.80000
33.42000,27.85006,24.41673,0.24217,2.71297,27.85006
33.48000,27.90006,24.50002,0.24261,2.72222,27.90006
33.54000,27.94993,24.61974,0.24304,2.73553,27.94993
33.60000,27.99993,24.53176,0.24348,2.72575,27.99993
33.66000,28.05000,24.42966,0.24391,2.71441,28.05000
33.72000,28.10000,24.67550,0.24435,2.74172,28.10000
33.78000,28.15000,24.43059,0.24478,2.71451,28.15000
33.84000,28.20000,24.57119,0.24522,2.73013,28.20000
33.90000,28.25000,24.59960,0.24565,2.73329,28.25000
33.96000,28.30000,24.49684,0.24609,2.72187,28.30000
34.02000,28.35000,24.77016,0.24652,2.75224,28.35000
34.08000,28.40000,24.54185,0.24696,2.72687,28.40000
34.14000,28.45000,24.83817,0.24739,2.75980,28.45000
34.20000,28.50006,24.81248,0.24783,2.75694,28.50006
34.26000,28.55006,24.60230,0.24826,2.73359,28.55006
34.32000,28.60012,24.66191,0.24870,2.74021,28.60012
34.38000,28.65006,24.80249,0.24913,2.75583,28.65006
34.44000,28.69993,24.80403,0.24956,2.75600,28.69993
34.50000,28.74993,24.61342,0.25000,2.73482,28.74993
34.56000,28.80000,24.95083,0.25043,2.77231,28.80000
34.62000,28.85000,24.74266,0.25087,2.74918,28.85000
34.68000,28.90006,24.94030,0.25130,2.77114,28.90006
34.74000,28.94993,24.92396,0.25174,2.76933,28.94993
34.80000,28.99981,25.01857,0.25217,2.77984,28.99981
34.86000,29.04993,24.98700,0.25261,2.77633,29.04993
34.92000,29.10000,25.28219,0.25304,2.80913,29.10000
34.98000,29.15000,25.04532,0.25348,2.78281,29.15000
35.04000,29.20000,24.92355,0.25391,2.76928,29.20000
35.10000,29.25000,25.06398,0.25435,2.78489,29.25000
35.16000,29.29999,25.04716,0.25478,2.78302,29.29999
35.22000,29.35006,25.06861,0.25522,2.78540,29.35006
35.28000,29.40006,25.19395,0.25565,2.79933,29.40006
35.34000,29.45000,25.23571,0.25609,2.80397,29.45000
35.40000,29.50000,25.16464,0.25652,2.79607,29.50000
35.46000,29.55000,25.25261,0.25696,2.80585,29.55000
35.52000,29.59999,25.40027,0.25739,2.82225,29.59999
35.58000,29.65000,25.25584,0.25783,2.80620,29.65000
35.64000,29.70000,25.19834,0.25826,2.79982,29.70000
35.70000,29.75000,25.50852,0.25870,2.83428,29.75000
35.76000,29.80000,25.36850,0.25913,2.81872,29.80000
35.82000,29.85000,25.25513,0.25957,2.80613,29.85000
35.88000,29.90006,25.51329,0.26000,2.83481,29.90006
35.94000,29.95000,25.21673,0.26043,2.80186,29.95000
36.00000,29.99993,25.26206,0.26087,2.80690,29.99993
36.06000,30.04993,25.43860,0.26130,2.82651,30.04993
36.12000,30.10006,25.40686,0.26174,2.82298,30.10006
36.18000,30.15006,25.56886,0.26217,2.84099,30.15006
36.24000,30.20006,25.39295,0.26261,2.82144,30.20006
36.30000,30.25000,25.51207,0.26304,2.83467,30.25000
36.36000,30.30000,25.60509,0.26348,2.84501,30.30000
36.42000,30.35000,25.40066,0.26391,2.82230,30.35000
36.48000,30.40006,25.42052,0.26435,2.82450,30.40006
36.54000,30.45000,25.69176,0.26478,2.85464,30.45000
36.60000,30.50006,25.56632,0.26522,2.84070,30.50006
36.66000,30.55000,25.75052,0.26565,2.86117,30.55000
36.72000,30.59987,25.68603,0.26609,2.85400,30.59987
36.78000,30.65000,25.74844,0.26652,2.86094,30.65000
36.84000,30.70000,25.64579,0.26696,2.84953,30.70000
36.90000,30.74993,25.67018,0.26739,2.85224,30.74993
36.96000,30.80000,25.62955,0.26783,2.84773,30.80000
37.02000,30.84993,25.76761,0.26826,2.86307,30.84993
37.08000,30.90000,25.86611,0.26870,2.87401,30.90000
37.14000,30.95000,25.83665,0.26913,2.87074,30.95000
37.20000,31.00000,25.93312,0.26957,2.88146,31.00000
37.26000,31.05000,25.82438,0.27000,2.86938,31.05000
37.32000,31.10006,25.89291,0.27044,2.87699,31.10006
37.38000,31.15006,26.00936,0.27087,2.88993,31.15006
37.44000,31.20000,25.90660,0.27130,2.87851,31.20000
37.50000,31.25000,26.06983,0.27174,2.89665,31.25000
37.56000,31.29999,25.96822,0.27217,2.88536,31.29999
37.62000,31.35006,26.09927,0.27261,2.89992,31.35006
37.68000,31.40006,25.93523,0.27304,2.88169,31.40006
37.74000,31.45000,26.11911,0.27348,2.90212,31.45000
37.80000,31.49999,26.14955,0.27391,2.90551,31.49999
37.86000,31.54999,26.34629,0.27435,2.92737,31.54999
37.92000,31.60000,26.16317,0.27478,2.90702,31.60000
37.98000,31.65005,26.29422,0.27522,2.92158,31.65005
38.04000,31.69993,26.05621,0.27565,2.89513,31.69993
38.10000,31.74993,26.16140,0.27609,2.90682,31.74993
38.16000,31.80000,26.20556,0.27652,2.91173,31.80000
38.22000,31.85000,26.13248,0.27696,2.90361,31.85000
38.28000,31.90000,26.38657,0.27739,2.93184,31.90000
38.34000,31.94993,26.28548,0.27783,2.92061,31.94993
38.40000,31.99999,26.29253,0.27826,2.92139,31.99999
38.46000,32.05006,26.04384,0.27870,2.89376,32.05006
38.52000,32.10012,26.34808,0.27913,2.92756,32.10012
38.58000,32.14999,26.39490,0.27957,2.93277,32.14999
38.64000,32.19987,26.23196,0.28000,2.91466,32.19987
38.70000,32.24993,26.43166,0.28043,2.93685,32.24993
38.76000,32.30006,26.45726,0.28087,2.93970,32.30006
38.82000,32.34999,26.40130,0.28130,2.93348,32.34999
38.88000,32.39999,26.40279,0.28174,2.93364,32.39999
38.94000,32.44993,26.43066,0.28217,2.93674,32.44993
39.00000,32.49993,26.39762,0.28261,2.93307,32.49993
39.06000,32.55000,26.62409,0.28304,2.95823,32.55000
39.12000,32.59999,26.73726,0.28348,2.97081,32.59999
39.18000,32.65006,26.74650,0.28391,2.97183,32.65006
39.24000,32.70000,26.70102,0.28435,2.96678,32.70000
39.30000,32.74993,26.68155,0.28478,2.96462,32.74993
39.36000,32.79999,26.61826,0.28522,2.95758,32.79999
39.42000,32.84999,26.69999,0.28565,2.96667,32.84999
39.48000,32.89993,26.69289,0.28609,2.96588,32.89993
39.54000,32.94999,26.66085,0.28652,2.96232,32.94999
39.60000,33.00000,26.63744,0.28696,2.95972,33.00000
39.66000,33.05006,26.70530,0.28739,2.96726,33.05006
39.72000,33.10006,26.73163,0.28783,2.97018,33.10006
39.78000,33.15006,26.60286,0.28826,2.95587,33.15006
39.84000,33.20000,26.71708,0.28870,2.96856,33.20000
39.90000,33.24999,27.02805,0.28913,3.00312,33.24999
39.96000,33.30000,26.85303,0.28957,2.98367,33.30000
40.02000,33.35006,27.01423,0.29000,3.00158,33.35006
40.08000,33.40000,27.05376,0.29043,3.00597,33.40000
40.14000,33.44993,26.85330,0.29087,2.98370,33.44993
40.20000,33.49993,26.88742,0.29130,2.98749,33.49993
40.26000,33.54999,26.97368,0.29174,2.99708,33.54999
40.32000,33.60000,26.93145,0.29217,2.99238,33.60000
40.38000,33.65012,27.08519,0.29261,3.00946,33.65012
40.44000,33.70006,26.91225,0.29304,2.99025,33.70006
40.50000,33.74993,27.14421,0.29348,3.01602,33.74993
40.56000,33.79993,27.09608,0.29391,3.01068,33.79993
40.62000,33.85006,26.88703,0.29435,2.98745,33.85006
40.68000,33.90006,27.09145,0.29478,3.01016,33.90006
40.74000,33.94999,27.21261,0.29522,3.02362,33.94999
40.80000,34.00000,27.23460,0.29565,3.02607,34.00000
40.86000,34.05000,27.26833,0.29609,3.02981,34.05000
40.92000,34.10000,26.99878,0.29652,2.99986,34.10000
40.98000,34.15006,27.13284,0.29696,3.01476,34.15006
41.04000,34.19993,27.21031,0.29739,3.02337,34.19993
41.10000,34.25000,27.07193,0.29783,3.00799,34.25000
41.16000,34.29993,27.25474,0.29826,3.02830,34.29993
41.22000,34.34999,27.21291,0.29870,3.02366,34.34999
41.28000,34.39999,27.25736,0.29913,3.02860,34.39999
41.34000,34.44999,27.17237,0.29957,3.01915,34.44999
41.40000,34.49993,27.33945,0.30000,3.03772,34.49993
41.46000,34.54993,27.36309,0.30043,3.04034,34.54993
41.52000,34.59999,27.50815,0.30087,3.05646,34.59999
41.58000,34.65006,27.42172,0.30130,3.04686,34.65006
41.64000,34.70000,27.31934,0.30174,3.03548,34.70000
41.70000,34.75000,27.41719,0.30217,3.04635,34.75000
41.76000,34.79999,27.69609,0.30261,3.07734,34.79999
41.82000,34.85006,27.46989,0.30304,3.05221,34.85006
41.88000,34.90012,27.39096,0.30348,3.04344,34.90012
41.94000,34.95000,27.52519,0.30391,3.05835,34.95000
42.00000,34.99999,27.42382,0.30435,3.04709,34.99999
42.06000,35.04999,27.37886,0.30478,3.04210,35.04999
42.12000,35.09993,27.66631,0.30522,3.07403,35.09993
42.18000,35.15000,27.73521,0.30565,3.08169,35.15000
42.24000,35.20000,27.72046,0.30609,3.08005,35.20000
42.30000,35.25006,27.59022,0.30652,3.06558,35.25006
42.36000,35.29999,27.60337,0.30696,3.06704,35.29999
42.42000,35.34993,27.67123,0.30739,3.07458,35.34993
42.48000,35.40000,27.49519,0.30783,3.05502,35.40000
42.54000,35.45006,27.72872,0.30826,3.08097,35.45006
42.60000,35.49999,27.65306,0.30870,3.07256,35.49999
42.66000,35.55000,27.74975,0.30913,3.08331,35.55000
42.72000,35.60005,27.79940,0.30957,3.08882,35.60005
42.78000,35.65006,27.88365,0.31000,3.09818,35.65006
42.84000,35.69999,27.80006,0.31043,3.08890,35.69999
42.90000,35.74993,27.77792,0.31087,3.08644,35.74993
42.96000,35.79993,27.92141,0.31130,3.10238,35.79993
43.02000,35.85000,27.85207,0.31174,3.09468,35.85000
43.08000,35.89999,27.81997,0.31217,3.09111,35.89999
43.14000,35.94993,27.83741,0.31261,3.09305,35.94993
43.20000,35.99993,27.86395,0.31304,3.09599,35.99993
43.26000,36.05000,27.95665,0.31348,3.10629,36.05000
43.32000,36.09999,28.06047,0.31391,3.11783,36.09999
43.38000,36.15006,28.03875,0.31435,3.11542,36.15006
43.44000,36.19999,27.78492,0.31478,3.08721,36.19999
43.50000,36.25000,28.18937,0.31522,3.13215,36.25000
43.56000,36.30000,28.12241,0.31565,3.12471,36.30000
43.62000,36.34993,28.08477,0.31609,3.12053,36.34993
43.68000,36.40000,28.20345,0.31652,3.13372,36.40000
43.74000,36.45000,28.16179,0.31696,3.12909,36.45000
43.80000,36.50000,28.06189,0.31739,3.11799,36.50000
43.86000,36.55012,28.39879,0.31783,3.15542,36.55012
43.92000,36.60006,28.26113,0.31826,3.14013,36.60006
43.98000,36.65006,28.17438,0.31870,3.13049,36.65006
44.04000,36.69993,28.19622,0.31913,3.13291,36.69993
44.10000,36.74993,28.21452,0.31956,3.13495,36.74993
44.16000,36.80006,28.14700,0.32000,3.12744,36.80006
44.22000,36.85012,28.34584,0.32044,3.14954,36.85012
44.28000,36.90006,28.52321,0.32087,3.16925,36.90006
44.34000,36.94987,28.31790,0.32130,3.14643,36.94987
44.40000,36.99993,28.20311,0.32174,3.13368,36.99993
44.46000,37.04999,28.26216,0.32217,3.14024,37.04999
44.52000,37.09993,28.32904,0.32261,3.14767,37.09993
44.58000,37.15000,28.27753,0.32304,3.14195,37.15000
44.64000,37.19993,28.43896,0.32348,3.15988,37.19993
44.70000,37.24993,28.39433,0.32391,3.15493,37.24993
44.76000,37.30000,28.45277,0.32435,3.16142,37.30000
44.82000,37.35006,28.37734,0.32478,3.15304,37.35006
44.88000,37.40012,28.53330,0.32522,3.17037,37.40012
44.94000,37.44999,28.54909,0.32565,3.17212,37.44999
45.00000,37.49999,28.44807,0.32609,3.16090,37.49999
45.06000,37.54999,28.65311,0.32652,3.18368,37.54999
45.12000,37.60006,28.60932,0.32696,3.17881,37.60006
45.18000,37.65006,28.64946,0.32739,3.18327,37.65006
45.24000,37.69999,28.61405,0.32783,3.17934,37.69999
45.30000,37.74999,28.57163,0.32826,3.17463,37.74999
45.36000,37.80000,28.58492,0.32870,3.17610,37.80000
45.42000,37.84999,28.59901,0.32913,3.17767,37.84999
45.48000,37.89999,28.69528,0.32957,3.18836,37.89999
45.54000,37.94987,28.60934,0.33000,3.17882,37.94987
45.60000,37.99993,28.66670,0.33043,3.18519,37.99993
45.66000,38.04993,28.48642,0.33087,3.16516,38.04993
45.72000,38.10006,28.76031,0.33130,3.19559,38.10006
45.78000,38.15006,28.61012,0.33174,3.17890,38.15006
45.84000,38.20000,28.70748,0.33217,3.18972,38.20000
45.90000,38.24993,28.63388,0.33261,3.18154,38.24993
45.96000,38.29999,28.92234,0.33304,3.21359,38.29999
46.02000,38.34999,28.97659,0.33348,3.21962,38.34999
46.08000,38.40012,28.79851,0.33391,3.19983,38.40012
46.14000,38.45006,28.72499,0.33435,3.19167,38.45006
46.20000,38.50000,28.82687,0.33478,3.20299,38.50000
46.26000,38.54987,28.91097,0.33522,3.21233,38.54987
46.32000,38.59999,29.06605,0.33565,3.22956,38.59999
46.38000,38.65006,28.93870,0.33609,3.21541,38.65006
46.44000,38.70000,28.93422,0.33652,3.21491,38.70000
46.50000,38.74993,29.18883,0.33696,3.24320,38.74993
46.56000,38.79993,29.32649,0.33739,3.25850,38.79993
46.62000,38.85000,29.04969,0.33783,3.22774,38.85000
46.68000,38.90006,29.20617,0.33826,3.24513,38.90006
46.74000,38.94999,29.15008,0.33870,3.23890,38.94999
46.80000,38.99999,29.14122,0.33913,3.23791,38.99999
46.86000,39.04999,29.05013,0.33957,3.22779,39.04999
46.92000,39.10000,29.22782,0.34000,3.24753,39.10000
46.98000,39.15005,29.08719,0.34044,3.23191,39.15005
47.04000,39.19999,29.21947,0.34087,3.24661,39.19999
47.10000,39.24993,29.36609,0.34130,3.26290,39.24993
47.16000,39.29999,29.15048,0.34174,3.23894,39.29999
47.22000,39.34999,29.24229,0.34217,3.24914,39.34999
47.28000,39.40005,29.29984,0.34261,3.25554,39.40005
47.34000,39.44999,29.24667,0.34304,3.24963,39.44999
47.40000,39.49999,29.20732,0.34348,3.24526,39.49999
47.46000,39.54993,29.34966,0.34391,3.26107,39.54993
47.52000,39.59999,29.26132,0.34435,3.25126,39.59999
47.58000,39.65006,29.43342,0.34478,3.27038,39.65006
47.64000,39.69993,29.42852,0.34522,3.26984,39.69993
47.70000,39.74999,29.30247,0.34565,3.25583,39.74999
47.76000,39.80000,29.58644,0.34609,3.28738,39.80000
47.82000,39.84999,29.35365,0.34652,3.26152,39.84999
47.88000,39.89999,29.76013,0.34696,3.30668,39.89999
47.94000,39.94999,29.45830,0.34739,3.27314,39.94999
48.00000,40.00005,29.40734,0.34783,3.26748,40.00005
48.06000,40.05006,29.26059,0.34826,3.25118,40.05006
48.12000,40.10005,29.55463,0.34870,3.28385,40.10005
48.18000,40.14993,29.56672,0.34913,3.28519,40.14993
48.24000,40.19993,29.58519,0.34956,3.28724,40.19993
48.30000,40.25000,29.58460,0.35000,3.28718,40.25000
48.36000,40.29999,29.62411,0.35043,3.29157,40.29999
48.42000,40.34999,29.62465,0.35087,3.29163,40.34999
48.48000,40.40000,29.83650,0.35130,3.31517,40.40000
48.54000,40.44993,29.66770,0.35174,3.29641,40.44993
48.60000,40.49993,29.72442,0.35217,3.30271,40.49993
48.66000,40.54999,29.84093,0.35261,3.31566,40.54999
48.72000,40.59999,29.77034,0.35304,3.30782,40.59999
48.78000,40.65000,29.71825,0.35348,3.30203,40.65000
48.84000,40.69999,29.82939,0.35391,3.31438,40.69999
48.90000,40.74993,29.90029,0.35435,3.32225,40.74993
48.96000,40.79999,29.86064,0.35478,3.31785,40.79999
49.02000,40.84993,29.56996,0.35522,3.28555,40.84993
49.08000,40.90006,29.98401,0.35565,3.33156,40.90006
49.14000,40.94999,29.83466,0.35609,3.31496,40.94999
49.20000,40.99999,30.03071,0.35652,3.33675,40.99999
49.26000,41.05006,29.86319,0.35696,3.31813,41.05006
49.32000,41.10000,29.98165,0.35739,3.33130,41.10000
49.38000,41.15005,30.05003,0.35783,3.33889,41.15005
49.44000,41.19999,30.05221,0.35826,3.33913,41.19999
49.50000,41.25000,29.89557,0.35870,3.32173,41.25000
49.56000,41.29999,29.97943,0.35913,3.33105,41.29999
49.62000,41.35000,30.09162,0.35957,3.34351,41.35000
49.68000,41.39993,30.06421,0.36000,3.34047,41.39993
49.74000,41.44993,30.30090,0.36043,3.36677,41.44993
49.80000,41.49993,30.09267,0.36087,3.34363,41.49993
49.86000,41.54999,30.32935,0.36130,3.36993,41.54999
49.92000,41.60006,30.31628,0.36174,3.36847,41.60006
49.98000,41.65005,30.16791,0.36217,3.35199,41.65005
50.04000,41.69993,30.25000,0.36261,3.36111,41.69993
50.10000,41.74993,30.31941,0.36304,3.36882,41.74993
50.16000,41.80000,30.35238,0.36348,3.37249,41.80000
50.22000,41.84999,30.23462,0.36391,3.35940,41.84999
50.28000,41.90006,30.43756,0.36435,3.38195,41.90006
50.34000,41.95006,30.20190,0.36478,3.35577,41.95006
50.40000,41.99999,30.45529,0.36522,3.38392,41.99999
50.46000,42.04999,30.44250,0.36565,3.38250,42.04999
50.52000,42.09999,30.38407,0.36609,3.37601,42.09999
50.58000,42.15006,30.28302,0.36652,3.36478,42.15006
50.64000,42.20000,30.50726,0.36696,3.38970,42.20000
50.70000,42.24999,30.42257,0.36739,3.38029,42.24999
50.76000,42.29999,30.49535,0.36783,3.38837,42.29999
50.82000,42.34999,30.62795,0.36826,3.40311,42.34999
50.88000,42.40006,30.38113,0.36870,3.37568,42.40006
50.94000,42.44993,30.69280,0.36913,3.41031,42.44993
51.00000,42.49993,30.69275,0.36956,3.41031,42.49993
51.06000,42.54993,30.57191,0.37000,3.39688,42.54993
51.12000,42.59999,30.63731,0.37043,3.40415,42.59999
51.18000,42.65000,30.70431,0.37087,3.41159,42.65000
51.24000,42.69999,30.70456,0.37130,3.41162,42.69999
51.30000,42.74999,30.83569,0.37174,3.42619,42.74999
51.36000,42.80006,30.42311,0.37217,3.38035,42.80006
51.42000,42.85006,30.77401,0.37261,3.41933,42.85006
51.48000,42.90012,30.94952,0.37304,3.43884,42.90012
51.54000,42.94999,30.78788,0.37348,3.42088,42.94999
51.60000,42.99993,30.80973,0.37391,3.42330,42.99993
51.66000,43.04999,30.66513,0.37435,3.40724,43.04999
51.72000,43.09999,30.88349,0.37478,3.43150,43.09999
51.78000,43.15006,30.87340,0.37522,3.43038,43.15006
51.84000,43.20005,31.00306,0.37565,3.44478,43.20005
51.90000,43.24999,30.96451,0.37609,3.44050,43.24999
51.96000,43.29987,30.87330,0.37652,3.43037,43.29987
52.02000,43.34999,30.92826,0.37696,3.43647,43.34999
52.08000,43.39999,30.65812,0.37739,3.40646,43.39999
52.14000,43.44999,31.17450,0.37783,3.46383,43.44999
52.20000,43.50000,30.89363,0.37826,3.43263,43.50000
52.26000,43.55005,31.10891,0.37870,3.45655,43.55005
52.32000,43.59999,31.14001,0.37913,3.46000,43.59999
52.38000,43.65006,31.16161,0.37957,3.46240,43.65006
52.44000,43.69999,30.95314,0.38000,3.43924,43.69999
52.50000,43.75006,31.20927,0.38044,3.46770,43.75006
52.56000,43.79999,31.03353,0.38087,3.44817,43.79999
52.62000,43.84999,31.08829,0.38130,3.45425,43.84999
52.68000,43.90012,31.13815,0.38174,3.45979,43.90012
52.74000,43.95006,31.23127,0.38217,3.47014,43.95006
52.80000,44.00000,31.28686,0.38261,3.47632,44.00000
52.86000,44.04999,31.17885,0.38304,3.46432,44.04999
52.92000,44.09993,31.16093,0.38348,3.46233,44.09993
52.98000,44.14999,31.08941,0.38391,3.45438,44.14999
53.04000,44.20000,31.18855,0.38435,3.46539,44.20000
53.10000,44.24987,31.17910,0.38478,3.46434,44.24987
53.16000,44.29987,31.24493,0.38522,3.47166,44.29987
53.22000,44.35000,31.23832,0.38565,3.47092,44.35000
53.28000,44.40005,31.18204,0.38609,3.46467,44.40005
53.34000,44.44999,31.36210,0.38652,3.48468,44.44999
53.40000,44.50005,31.35641,0.38696,3.48405,44.50005
53.46000,44.54999,31.36308,0.38739,3.48479,44.54999
53.52000,44.60006,31.38732,0.38783,3.48748,44.60006
53.58000,44.65005,31.33961,0.38826,3.48218,44.65005
53.64000,44.69999,31.58663,0.38870,3.50963,44.69999
53.70000,44.75005,31.60108,0.38913,3.51123,44.75005
53.76000,44.80012,31.45286,0.38957,3.49476,44.80012
53.82000,44.85006,31.54162,0.39000,3.50462,44.85006
53.88000,44.89993,31.61622,0.39043,3.51291,44.89993
53.94000,44.94993,31.77889,0.39087,3.53099,44.94993
54.00000,44.99993,31.40633,0.39130,3.48959,44.99993
54.06000,45.05000,31.41500,0.39174,3.49056,45.05000
54.12000,45.09999,31.50170,0.39217,3.50019,45.09999
54.18000,45.14999,31.59261,0.39261,3.51029,45.14999
54.24000,45.19999,31.44762,0.39304,3.49418,45.19999
54.30000,45.24999,31.77237,0.39348,3.53026,45.24999
54.36000,45.30000,31.72648,0.39391,3.52516,45.30000
54.42000,45.35005,31.77889,0.39435,3.53099,45.35005
54.48000,45.40006,31.70164,0.39478,3.52240,45.40006
54.54000,45.44999,31.80456,0.39522,3.53384,45.44999
54.60000,45.49999,31.48646,0.39565,3.49850,45.49999
54.66000,45.54999,31.68063,0.39609,3.52007,45.54999
54.72000,45.60005,31.71830,0.39652,3.52426,45.60005
54.78000,45.65006,31.87827,0.39696,3.54203,45.65006
54.84000,45.69999,31.59618,0.39739,3.51069,45.69999
54.90000,45.74993,31.76537,0.39783,3.52949,45.74993
54.96000,45.79999,31.67358,0.39826,3.51929,45.79999
55.02000,45.84999,31.75155,0.39870,3.52795,45.84999
55.08000,45.89993,31.68249,0.39913,3.52028,45.89993
55.14000,45.94993,31.71712,0.39956,3.52412,45.94993
55.20000,45.99999,31.78516,0.40000,3.53168,45.99999
55.26000,46.04999,31.81905,0.40043,3.53545,46.04999
55.32000,46.10006,31.79814,0.40087,3.53313,46.10006
55.38000,46.15006,31.83830,0.40130,3.53759,46.15006
55.44000,46.19993,31.69057,0.40174,3.52117,46.19993
55.50000,46.24999,30.86703,0.40217,3.42967,46.24999
55.56000,46.29999,4.70068,0.40261,0.52230,46.29999
55.62000,46.35012,-0.65407,0.40304,-0.07267,46.35012
55.68000,46.40012,-0.31381,0.40348,-0.03487,46.40012
55.74000,46.44999,-0.17744,0.40391,-0.01972,46.44999
55.80000,46.49993,-0.16155,0.40435,-0.01795,46.49993
55.86000,46.54999,-0.03388,0.40478,-0.00376,46.54999
55.92000,46.60005,-0.12856,0.40522,-0.01428,46.60005
55.98000,46.64999,-0.10040,0.40565,-0.01116,46.64999
56.04000,46.69999,-0.29125,0.40609,-0.03236,46.69999
56.10000,46.74993,-0.18692,0.40652,-0.02077,46.74993
56.16000,46.79999,-0.41038,0.40696,-0.04560,46.79999
56.22000,46.85000,-0.23113,0.40739,-0.02568,46.85000
56.28000,46.90005,-0.25106,0.40783,-0.02790,46.90005
56.34000,46.94999,-0.22540,0.40826,-0.02504,46.94999
56.40000,46.99999,-0.13965,0.40870,-0.01552,46.99999
56.46000,47.04999,-0.11318,0.40913,-0.01258,47.04999
56.52000,47.09999,-0.24335,0.40957,-0.02704,47.09999
56.58000,47.15005,-0.11604,0.41000,-0.01289,47.15005
56.64000,47.19993,-0.08741,0.41043,-0.00971,47.19993
56.70000,47.24999,-0.27458,0.41087,-0.03051,47.24999
56.76000,47.29999,-0.28383,0.41130,-0.03154,47.29999
56.82000,47.35006,-0.12347,0.41174,-0.01372,47.35006
56.88000,47.40012,-0.17860,0.41217,-0.01984,47.40012
56.94000,47.44999,-0.18318,0.41261,-0.02035,47.44999
57.00000,47.49993,-0.18991,0.41304,-0.02110,47.49993
57.06000,47.54993,-0.33727,0.41348,-0.03747,47.54993
57.12000,47.59999,0.00590,0.41391,0.00066,47.59999
57.18000,47.65006,-0.21061,0.41435,-0.02340,47.65006
57.24000,47.70000,-0.07363,0.41478,-0.00818,47.70000
57.30000,47.74993,-0.24857,0.41522,-0.02762,47.74993
57.36000,47.79993,-0.19246,0.41565,-0.02138,47.79993
57.42000,47.84993,0.00164,0.41609,0.00018,47.84993
57.48000,47.90006,-0.22160,0.41652,-0.02462,47.90006
57.54000,47.94999,-0.19738,0.41696,-0.02193,47.94999
57.60000,47.99999,-0.27695,0.41739,-0.03077,47.99999
57.66000,48.04999,-0.28577,0.41783,-0.03175,48.04999
57.67800,48.06487,-0.30965,0.41796,-0.03441,48.06487