File: V_8/EPR/RDSO EPR Tensile 500.is_tens_RawData/Specimen_RawData_2.csv
Time,Extension,Load,Tensile strain,Tensile stress,Corrected Position
(sec),(mm),(N),(mm/mm),(MPa),(mm)
0.00000,0.00000,-0.11298,0.00000,-0.01255,0.00000
0.04000,0.09775,0.69949,0.00085,0.07772,0.09775
0.08000,0.41794,1.50542,0.00363,0.16727,0.41794
0.12000,0.83500,1.81927,0.00726,0.20214,0.83500
0.16000,1.27400,2.20173,0.01108,0.24464,1.27400
0.20000,1.65137,2.73713,0.01436,0.30413,1.65137
0.24000,1.98456,3.45989,0.01726,0.38443,1.98456
0.28000,2.32162,4.07292,0.02019,0.45255,2.32162
0.32000,2.66081,4.21096,0.02314,0.46788,2.66081
0.36000,2.99675,4.61097,0.02606,0.51233,2.99675
0.40000,3.33131,4.94140,0.02897,0.54904,3.33131
0.44000,3.66537,5.42723,0.03187,0.60303,3.66537
0.48000,3.99931,5.80268,0.03478,0.64474,3.99931
0.52000,4.33300,6.02457,0.03768,0.66940,4.33300
0.56000,4.66644,6.48902,0.04058,0.72100,4.66644
0.60000,4.99987,6.56460,0.04348,0.72940,4.99987
0.64000,5.33325,7.11002,0.04638,0.79000,5.33325
0.68000,5.66656,7.44866,0.04927,0.82763,5.66656
0.72000,6.00000,7.64087,0.05217,0.84899,6.00000
0.76000,6.33331,7.77424,0.05507,0.86380,6.33331
0.80000,6.66662,8.14247,0.05797,0.90472,6.66662
0.84000,7.00006,8.20370,0.06087,0.91152,7.00006
0.88000,7.33325,8.49982,0.06377,0.94442,7.33325
0.92000,7.66662,8.62989,0.06667,0.95888,7.66662
0.96000,8.00006,8.70354,0.06957,0.96706,8.00006
1.00000,8.33331,8.94619,0.07246,0.99402,8.33331
1.04000,8.66669,9.26519,0.07536,1.02947,8.66669
1.08000,9.00000,9.32767,0.07826,1.03641,9.00000
1.12000,9.33331,9.59340,0.08116,1.06593,9.33331
1.16000,9.66675,9.84441,0.08406,1.09382,9.66675
1.20000,10.00006,9.76327,0.08696,1.08481,10.00006
1.24000,10.33331,9.94342,0.08985,1.10482,10.33331
1.28000,10.66669,10.22728,0.09275,1.13636,10.66669
1.32000,10.99994,10.35355,0.09565,1.15039,10.99994
1.36000,11.33337,10.62244,0.09855,1.18027,11.33337
1.40000,11.66669,10.80576,0.10145,1.20064,11.66669
1.44000,12.00000,10.84355,0.10435,1.20484,12.00000
1.48000,12.33337,11.25796,0.10725,1.25088,12.33337
1.52000,12.66669,11.31493,0.11015,1.25721,12.66669
1.56000,13.00000,11.07139,0.11304,1.23015,13.00000
1.60000,13.33331,11.38825,0.11594,1.26536,13.33331
1.64000,13.66662,11.35882,0.11884,1.26209,13.66662
1.68000,14.00000,11.64179,0.12174,1.29353,14.00000
1.72000,14.33337,11.67088,0.12464,1.29676,14.33337
1.76000,14.66669,11.90147,0.12754,1.32239,14.66669
1.80000,15.00012,11.70821,0.13044,1.30091,15.00012
1.84000,15.33337,12.02150,0.13333,1.33572,15.33337
1.88000,15.66662,12.19328,0.13623,1.35481,15.66662
1.92000,16.00006,12.24449,0.13913,1.36050,16.00006
1.96000,16.33331,12.45274,0.14203,1.38364,16.33331
2.00000,16.66668,12.72640,0.14493,1.41404,16.66668
2.04000,17.00006,12.53251,0.14783,1.39250,17.00006
2.08000,17.33319,12.66410,0.15072,1.40712,17.33319
2.12000,17.66669,12.82743,0.15362,1.42527,17.66669
2.16000,18.00000,12.68131,0.15652,1.40903,18.00000
2.20000,18.33331,12.89965,0.15942,1.43329,18.33331
2.24000,18.66675,13.13673,0.16232,1.45964,18.66675
2.28000,19.00000,13.02279,0.16522,1.44698,19.00000
2.32000,19.33337,13.34857,0.16812,1.48317,19.33337
2.36000,19.66675,13.39961,0.17102,1.48885,19.66675
2.40000,20.00006,13.13210,0.17391,1.45912,20.00006
2.44000,20.33337,13.56366,0.17681,1.50707,20.33337
2.48000,20.66668,13.60465,0.17971,1.51163,20.66668
2.52000,21.00000,13.55832,0.18261,1.50648,21.00000
2.56000,21.33337,13.70171,0.18551,1.52241,21.33337
2.60000,21.66662,13.88145,0.18841,1.54238,21.66662
2.64000,22.00000,13.76353,0.19130,1.52928,22.00000
2.68000,22.33337,13.98336,0.19420,1.55371,22.33337
2.72000,22.66662,13.82544,0.19710,1.53616,22.66662
2.76000,23.00000,14.06560,0.20000,1.56284,23.00000
2.80000,23.33331,14.34938,0.20290,1.59438,23.33331
2.84000,23.66662,14.34950,0.20580,1.59439,23.66662
2.88000,24.00006,14.35019,0.20870,1.59447,24.00006
2.92000,24.33331,14.28482,0.21159,1.58720,24.33331
2.96000,24.66675,14.37069,0.21449,1.59674,24.66675
3.00000,25.00012,14.36750,0.21739,1.59639,25.00012
3.04000,25.33331,14.60541,0.22029,1.62282,25.33331
3.08000,25.66668,14.61646,0.22319,1.62405,25.66668
3.12000,26.00000,14.56162,0.22609,1.61796,26.00000
3.16000,26.33331,14.86889,0.22899,1.65210,26.33331
3.20000,26.66668,14.91664,0.23188,1.65740,26.66668
3.24000,27.00000,14.86418,0.23478,1.65158,27.00000
3.28000,27.33331,14.90200,0.23768,1.65578,27.33331
3.32000,27.66668,15.19570,0.24058,1.68841,27.66668
3.36000,27.99993,15.05450,0.24348,1.67272,27.99993
3.40000,28.33331,15.29812,0.24638,1.69979,28.33331
3.44000,28.66668,15.12455,0.24928,1.68051,28.66668
3.48000,29.00000,15.26518,0.25217,1.69613,29.00000
3.52000,29.33343,15.56275,0.25507,1.72919,29.33343
3.56000,29.66668,15.55623,0.25797,1.72847,29.66668
3.60000,30.00006,15.53313,0.26087,1.72590,30.00006
3.64000,30.33337,15.51442,0.26377,1.72382,30.33337
3.68000,30.66662,15.73208,0.26667,1.74801,30.66662
3.72000,31.00006,15.71900,0.26957,1.74656,31.00006
3.76000,31.33331,15.97371,0.27246,1.77486,31.33331
3.80000,31.66662,15.99222,0.27536,1.77691,31.66662
3.84000,32.00006,15.99763,0.27826,1.77751,32.00006
3.88000,32.33331,16.06856,0.28116,1.78540,32.33331
3.92000,32.66668,16.14791,0.28406,1.79421,32.66668
3.96000,33.00000,16.13669,0.28696,1.79297,33.00000
4.00000,33.33325,16.29616,0.28985,1.81068,33.33325
4.04000,33.66668,16.45574,0.29275,1.82842,33.66668
4.08000,34.00012,16.30914,0.29565,1.81213,34.00012
4.12000,34.33324,16.48640,0.29855,1.83182,34.33324
4.16000,34.66674,16.63181,0.30145,1.84798,34.66674
4.20000,35.00006,16.56355,0.30435,1.84039,35.00006
4.24000,35.33331,16.61824,0.30725,1.84647,35.33331
4.28000,35.66675,16.81461,0.31015,1.86829,35.66675
4.32000,35.99999,16.84170,0.31304,1.87130,35.99999
4.36000,36.33331,16.93824,0.31594,1.88203,36.33331
4.40000,36.66668,16.99256,0.31884,1.88806,36.66668
4.44000,36.99999,16.93388,0.32174,1.88154,36.99999
4.48000,37.33337,17.19167,0.32464,1.91019,37.33337
4.52000,37.66662,17.42782,0.32754,1.93642,37.66662
4.56000,37.99993,17.34019,0.33043,1.92669,37.99993
4.60000,38.33337,17.31158,0.33333,1.92351,38.33337
4.64000,38.66662,17.39936,0.33623,1.93326,38.66662
4.68000,38.99999,17.49757,0.33913,1.94417,38.99999
4.72000,39.33343,17.56183,0.34203,1.95131,39.33343
4.76000,39.66668,17.63741,0.34493,1.95971,39.66668
4.80000,40.00005,17.56068,0.34783,1.95119,40.00005
4.84000,40.33337,18.01595,0.35072,2.00177,40.33337
4.88000,40.66668,18.02501,0.35362,2.00278,40.66668
4.92000,41.00006,18.08920,0.35652,2.00991,41.00006
4.96000,41.33331,18.10747,0.35942,2.01194,41.33331
5.00000,41.66662,18.25719,0.36232,2.02858,41.66662
5.04000,41.99999,18.08587,0.36522,2.00954,41.99999
5.08000,42.33331,18.59786,0.36812,2.06643,42.33331
5.12000,42.66662,18.38349,0.37101,2.04261,42.66662
5.16000,42.99993,18.48192,0.37391,2.05355,42.99993
5.20000,43.33324,18.76121,0.37681,2.08458,43.33324
5.24000,43.66674,18.82408,0.37971,2.09156,43.66674
5.28000,44.00006,18.63102,0.38261,2.07011,44.00006
5.32000,44.33337,18.79158,0.38551,2.08795,44.33337
5.36000,44.66674,18.95136,0.38841,2.10571,44.66674
5.40000,44.99999,18.87074,0.39130,2.09675,44.99999
5.44000,45.33337,18.99217,0.39420,2.11024,45.33337
5.48000,45.66668,19.05129,0.39710,2.11681,45.66668
5.52000,45.99999,19.35099,0.40000,2.15011,45.99999
5.56000,46.33337,19.31170,0.40290,2.14574,46.33337
5.60000,46.66662,19.52788,0.40580,2.16976,46.66662
5.64000,46.99999,19.51179,0.40870,2.16798,46.99999
5.68000,47.33337,19.51248,0.41159,2.16805,47.33337
5.72000,47.66662,19.49705,0.41449,2.16634,47.66662
5.76000,47.99999,19.73976,0.41739,2.19331,47.99999
5.80000,48.33330,19.88087,0.42029,2.20899,48.33330
5.84000,48.66662,20.12537,0.42319,2.23615,48.66662
5.88000,49.00006,19.81659,0.42609,2.20184,49.00006
5.92000,49.33337,20.12042,0.42899,2.23560,49.33337
5.96000,49.66674,20.33232,0.43188,2.25915,49.66674
6.00000,50.00005,20.22728,0.43478,2.24748,50.00005
6.04000,50.33331,20.36570,0.43768,2.26286,50.33331
6.08000,50.66674,20.52041,0.44058,2.28005,50.66674
6.12000,51.00005,20.53036,0.44348,2.28115,51.00005
6.16000,51.33324,20.67512,0.44638,2.29724,51.33324
6.20000,51.66668,20.65680,0.44928,2.29520,51.66668
6.24000,51.99999,20.80466,0.45217,2.31163,51.99999
6.28000,52.33331,20.89488,0.45507,2.32165,52.33331
6.32000,52.66674,21.12899,0.45797,2.34767,52.66674
6.36000,52.99993,21.25532,0.46087,2.36170,52.99993
6.40000,53.33330,21.25576,0.46377,2.36175,53.33330
6.44000,53.66668,21.19098,0.46667,2.35455,53.66668
6.48000,53.99999,21.24430,0.46957,2.36048,53.99999
6.52000,54.33343,21.32860,0.47246,2.36984,54.33343
6.56000,54.66668,21.50334,0.47536,2.38926,54.66668
6.60000,55.00006,21.49562,0.47826,2.38840,55.00006
6.64000,55.33337,21.64098,0.48116,2.40455,55.33337
6.68000,55.66662,21.95640,0.48406,2.43960,55.66662
6.72000,56.00005,21.70637,0.48696,2.41182,56.00005
6.76000,56.33337,22.08177,0.48986,2.45353,56.33337
6.80000,56.66662,22.30214,0.49275,2.47802,56.66662
6.84000,56.99999,22.02255,0.49565,2.44695,56.99999
6.88000,57.33330,22.38149,0.49855,2.48683,57.33330
6.92000,57.66662,22.48325,0.50145,2.49814,57.66662
6.96000,58.00006,22.31383,0.50435,2.47931,58.00006
7.00000,58.33324,22.71310,0.50725,2.52368,58.33324
7.04000,58.66662,22.68163,0.51014,2.52018,58.66662
7.08000,59.00005,22.70397,0.51304,2.52266,59.00005
7.12000,59.33337,22.85069,0.51594,2.53897,59.33337
7.16000,59.66675,23.01907,0.51884,2.55767,59.66675
7.20000,59.99999,23.16541,0.52174,2.57393,59.99999
7.24000,60.33331,23.35595,0.52464,2.59511,60.33331
7.28000,60.66674,23.23974,0.52754,2.58219,60.66674
7.32000,60.99999,23.29577,0.53043,2.58842,60.99999
7.36000,61.33337,23.51845,0.53333,2.61316,61.33337
7.40000,61.66668,23.55624,0.53623,2.61736,61.66668
7.44000,61.99999,23.55055,0.53913,2.61673,61.99999
7.48000,62.33336,23.63049,0.54203,2.62561,62.33336
7.52000,62.66668,24.00019,0.54493,2.66669,62.66668
7.56000,62.99999,24.02536,0.54783,2.66948,62.99999
7.60000,63.33330,23.96134,0.55072,2.66237,63.33330
7.64000,63.66661,24.14655,0.55362,2.68295,63.66661
7.68000,63.99999,24.27324,0.55652,2.69703,63.99999
7.72000,64.33337,24.43498,0.55942,2.71500,64.33337
7.76000,64.66668,24.41389,0.56232,2.71265,64.66668
7.80000,65.00005,24.62687,0.56522,2.73632,65.00005
7.84000,65.33330,24.61303,0.56812,2.73478,65.33330
7.88000,65.66667,24.67729,0.57101,2.74192,65.66667
7.92000,66.00005,24.63718,0.57391,2.73746,66.00005
7.96000,66.33330,25.01277,0.57681,2.77920,66.33330
8.00000,66.66661,25.02203,0.57971,2.78023,66.66661
8.04000,66.99999,25.03611,0.58261,2.78179,66.99999
8.08000,67.33330,25.21225,0.58551,2.80136,67.33330
8.12000,67.66674,25.21184,0.58841,2.80132,67.66674
8.16000,67.99999,25.35303,0.59130,2.81700,67.99999
8.20000,68.33324,25.56877,0.59420,2.84097,68.33324
8.24000,68.66674,25.92742,0.59710,2.88082,68.66674
8.28000,69.00005,25.64812,0.60000,2.84979,69.00005
8.32000,69.33337,25.75400,0.60290,2.86156,69.33337
8.36000,69.66674,25.99536,0.60580,2.88837,69.66674
8.40000,69.99999,25.80019,0.60870,2.86669,69.99999
8.44000,70.33330,26.12376,0.61159,2.90264,70.33330
8.48000,70.66668,26.21306,0.61449,2.91256,70.66668
8.52000,70.99999,26.26397,0.61739,2.91822,70.99999
8.56000,71.33336,26.71138,0.62029,2.96793,71.33336
8.60000,71.66661,26.69948,0.62319,2.96661,71.66661
8.64000,71.99999,26.65892,0.62609,2.96210,71.99999
8.68000,72.33337,26.87523,0.62899,2.98614,72.33337
8.72000,72.66662,26.95546,0.63188,2.99505,72.66662
8.76000,72.99999,27.01647,0.63478,3.00183,72.99999
8.80000,73.33330,27.03270,0.63768,3.00363,73.33330
8.84000,73.66662,27.13133,0.64058,3.01459,73.66662
8.88000,74.00006,27.14110,0.64348,3.01568,74.00006
8.92000,74.33336,27.55598,0.64638,3.06178,74.33336
8.96000,74.66674,27.50879,0.64928,3.05653,74.66674
9.00000,75.00011,27.41587,0.65217,3.04621,75.00011
9.04000,75.33330,27.79239,0.65507,3.08804,75.33330
9.08000,75.66668,27.70695,0.65797,3.07855,75.66668
9.12000,76.00005,27.79354,0.66087,3.08817,76.00005
9.16000,76.33337,27.94054,0.66377,3.10450,76.33337
9.20000,76.66667,28.15290,0.66667,3.12810,76.66667
9.24000,76.99993,27.95626,0.66956,3.10625,76.99993
9.28000,77.33336,28.29674,0.67246,3.14408,77.33336
9.32000,77.66668,28.36465,0.67536,3.15163,77.66668
9.36000,77.99999,28.56274,0.67826,3.17364,77.99999
9.40000,78.33330,28.66330,0.68116,3.18481,78.33330
9.44000,78.66661,28.73462,0.68406,3.19274,78.66661
9.48000,78.99999,28.90057,0.68696,3.21117,78.99999
9.52000,79.33336,28.97064,0.68986,3.21896,79.33336
9.56000,79.66674,29.01874,0.69275,3.22430,79.66674
9.60000,79.99999,29.25398,0.69565,3.25044,79.99999
9.64000,80.33336,29.30053,0.69855,3.25561,80.33336
9.68000,80.66662,29.50283,0.70145,3.27809,80.66662
9.72000,81.00005,29.36353,0.70435,3.26261,81.00005
9.76000,81.33330,29.72631,0.70725,3.30292,81.33330
9.80000,81.66661,29.51997,0.71014,3.28000,81.66661
9.84000,82.00006,29.81852,0.71304,3.31317,82.00006
9.88000,82.33330,30.00497,0.71594,3.33389,82.33330
9.92000,82.66667,29.98864,0.71884,3.33207,82.66667
9.96000,83.00005,30.06997,0.72174,3.34111,83.00005
10.00000,83.33330,30.26864,0.72464,3.36318,83.33330
10.04000,83.66668,30.19818,0.72754,3.35535,83.66668
10.08000,83.99999,30.36739,0.73043,3.37415,83.99999
10.12000,84.33330,30.54542,0.73333,3.39394,84.33330
10.16000,84.66673,30.75702,0.73623,3.41745,84.66673
10.20000,85.00005,30.84754,0.73913,3.42750,85.00005
10.24000,85.33323,30.99586,0.74203,3.44398,85.33323
10.28000,85.66667,31.02089,0.74493,3.44677,85.66667
10.32000,86.00005,31.01741,0.74783,3.44638,86.00005
10.36000,86.33336,31.16338,0.75072,3.46260,86.33336
10.40000,86.66667,31.30871,0.75362,3.47875,86.66667
10.44000,86.99992,31.32742,0.75652,3.48082,86.99992
10.48000,87.33337,31.47368,0.75942,3.49708,87.33337
10.52000,87.66667,31.42029,0.76232,3.49114,87.66667
10.56000,87.99999,31.63993,0.76522,3.51555,87.99999
10.60000,88.33330,32.05065,0.76812,3.56118,88.33330
10.64000,88.66661,31.91707,0.77101,3.54634,88.66661
10.68000,89.00005,31.84962,0.77391,3.53885,89.00005
10.72000,89.33342,32.21175,0.77681,3.57908,89.33342
10.76000,89.66668,32.29737,0.77971,3.58860,89.66668
10.80000,90.00004,32.24819,0.78261,3.58313,90.00004
10.84000,90.33330,32.47895,0.78551,3.60877,90.33330
10.88000,90.66661,32.51725,0.78841,3.61303,90.66661
10.92000,91.00011,32.77896,0.79131,3.64211,91.00011
10.96000,91.33336,32.79400,0.79420,3.64378,91.33336
11.00000,91.66667,32.97670,0.79710,3.66408,91.66667
11.04000,92.00005,32.87002,0.80000,3.65222,92.00005
11.08000,92.33324,33.16029,0.80290,3.68448,92.33324
11.12000,92.66674,33.24851,0.80580,3.69428,92.66674
11.16000,93.00006,33.19428,0.80870,3.68825,93.00006
11.20000,93.33336,33.36680,0.81159,3.70742,93.33336
11.24000,93.66661,33.73764,0.81449,3.74863,93.66661
11.28000,93.99999,33.70096,0.81739,3.74455,93.99999
11.32000,94.33337,34.04804,0.82029,3.78312,94.33337
11.36000,94.66674,33.77962,0.82319,3.75329,94.66674
11.40000,94.99999,33.83046,0.82609,3.75894,94.99999
11.44000,95.33330,34.13327,0.82899,3.79259,95.33330
11.48000,95.66667,34.19279,0.83188,3.79920,95.66667
11.52000,95.99999,34.18309,0.83478,3.79812,95.99999
11.56000,96.33343,34.48697,0.83768,3.83189,96.33343
11.60000,96.66661,34.43623,0.84058,3.82625,96.66661
11.64000,96.99998,34.49109,0.84348,3.83234,96.99998
11.68000,97.33336,34.78905,0.84638,3.86545,97.33336
11.72000,97.66667,35.03484,0.84928,3.89276,97.66667
11.76000,98.00005,34.94354,0.85217,3.88262,98.00005
11.80000,98.33324,35.05771,0.85507,3.89530,98.33324
11.84000,98.66661,35.38350,0.85797,3.93150,98.66661
11.88000,99.00011,35.29910,0.86087,3.92212,99.00011
11.92000,99.33336,35.31972,0.86377,3.92441,99.33336
11.96000,99.66673,35.52746,0.86667,3.94750,99.66673
12.00000,100.00011,35.39991,0.86957,3.93332,100.00011
12.04000,100.33330,35.71467,0.87246,3.96830,100.33330
12.08000,100.66668,35.77766,0.87536,3.97530,100.66668
12.12000,101.00004,35.84241,0.87826,3.98249,101.00004
12.16000,101.33330,36.30519,0.88116,4.03391,101.33330
12.20000,101.66674,36.20111,0.88406,4.02235,101.66674
12.24000,101.99999,36.38460,0.88696,4.04273,101.99999
12.28000,102.33330,36.41800,0.88985,4.04644,102.33330
12.32000,102.66673,36.40478,0.89275,4.04498,102.66673
12.36000,102.99992,36.73786,0.89565,4.08198,102.99992
12.40000,103.33336,36.83352,0.89855,4.09261,103.33336
12.44000,103.66667,36.88569,0.90145,4.09841,103.66667
12.48000,103.99998,37.06089,0.90435,4.11788,103.99998
12.52000,104.33336,36.91493,0.90725,4.10166,104.33336
12.56000,104.66667,37.09004,0.91014,4.12112,104.66667
12.60000,105.00005,37.23434,0.91304,4.13715,105.00005
12.64000,105.33337,37.34847,0.91594,4.14983,105.33337
12.68000,105.66667,37.44746,0.91884,4.16083,105.66667
12.72000,106.00011,37.59176,0.92174,4.17686,106.00011
12.76000,106.33335,37.74400,0.92464,4.19378,106.33335
12.80000,106.66661,37.91181,0.92754,4.21242,106.66661
12.84000,107.00005,37.90388,0.93044,4.21154,107.00005
12.88000,107.33330,38.16966,0.93333,4.24107,107.33330
12.92000,107.66667,38.30220,0.93623,4.25580,107.66667
12.96000,108.00004,38.16510,0.93913,4.24057,108.00004
13.00000,108.33323,38.25141,0.94203,4.25016,108.33323
13.04000,108.66667,38.58611,0.94493,4.28734,108.66667
13.08000,109.00005,38.40154,0.94783,4.26684,109.00005
13.12000,109.33329,38.81716,0.95072,4.31302,109.33329
13.16000,109.66673,38.78130,0.95362,4.30903,109.66673
13.20000,110.00005,38.66663,0.95652,4.29629,110.00005
13.24000,110.33336,38.93824,0.95942,4.32647,110.33336
13.28000,110.66668,39.07573,0.96232,4.34175,110.66668
13.32000,110.99998,39.14847,0.96522,4.34983,110.99998
13.36000,111.33336,39.27764,0.96812,4.36418,111.33336
13.40000,111.66668,39.34508,0.97101,4.37168,111.66668
13.44000,111.99999,39.44903,0.97391,4.38322,111.99999
13.48000,112.33336,39.60812,0.97681,4.40090,112.33336
13.52000,112.66661,39.64647,0.97971,4.40516,112.66661
13.56000,112.99998,39.76026,0.98261,4.41781,112.99998
13.60000,113.33336,39.82766,0.98551,4.42530,113.33336
13.64000,113.66662,39.93297,0.98841,4.43700,113.66662
13.68000,113.99998,40.11440,0.99130,4.45716,113.99998
13.72000,114.33336,40.15829,0.99420,4.46203,114.33336
13.76000,114.66667,40.21736,0.99710,4.46860,114.66667
13.80000,115.00005,40.33570,1.00000,4.48174,115.00005
13.84000,115.33330,40.53031,1.00290,4.50337,115.33330
13.88000,115.66667,40.78100,1.00580,4.53122,115.66667
13.92000,116.00011,40.88279,1.00870,4.54253,116.00011
13.96000,116.33329,40.78242,1.01159,4.53138,116.33329
14.00000,116.66667,41.17163,1.01449,4.57463,116.66667
14.04000,117.00004,41.01224,1.01739,4.55692,117.00004
14.08000,117.33330,41.26019,1.02029,4.58447,117.33330
14.12000,117.66673,41.11227,1.02319,4.56803,117.66673
14.16000,117.99999,41.17619,1.02609,4.57513,117.99999
14.20000,118.33330,41.50055,1.02899,4.61117,118.33330
14.24000,118.66674,41.75668,1.03188,4.63963,118.66674
14.28000,118.99998,41.73748,1.03478,4.63750,118.99998
14.32000,119.33330,41.72455,1.03768,4.63606,119.33330
14.36000,119.66674,42.01692,1.04058,4.66855,119.66674
14.40000,120.00005,42.03681,1.04348,4.67076,120.00005
14.44000,120.33342,42.04494,1.04638,4.67166,120.33342
14.48000,120.66667,42.41020,1.04928,4.71224,120.66667
14.52000,120.99999,42.48044,1.05217,4.72005,120.99999
14.56000,121.33342,42.41417,1.05507,4.71269,121.33342
14.60000,121.66668,42.45468,1.05797,4.71719,121.66668
14.64000,121.99998,42.59075,1.06087,4.73231,121.99998
14.68000,122.33336,42.83355,1.06377,4.75928,122.33336
14.72000,122.66668,42.89042,1.06667,4.76560,122.66668
14.76000,122.99999,42.99015,1.06957,4.77668,122.99999
14.80000,123.33330,43.25813,1.07246,4.80646,123.33330
14.84000,123.66655,43.14552,1.07536,4.79395,123.66655
14.88000,124.00005,43.23805,1.07826,4.80423,124.00005
14.92000,124.33336,43.42830,1.08116,4.82537,124.33336
14.96000,124.66673,43.33802,1.08406,4.81534,124.66673
15.00000,125.00010,43.35669,1.08696,4.81741,125.00010
15.04000,125.33329,43.66611,1.08985,4.85179,125.33329
15.08000,125.66673,43.57637,1.09275,4.84182,125.66673
15.12000,126.00005,43.37236,1.09565,4.81915,126.00005
15.16000,126.33330,43.86253,1.09855,4.87361,126.33330
15.20000,126.66667,43.64480,1.10145,4.84942,126.66667
15.24000,126.99998,43.68065,1.10435,4.85341,126.99998
15.28000,127.33336,43.99277,1.10725,4.88809,127.33336
15.32000,127.66667,43.93394,1.11014,4.88155,127.66667
15.36000,127.99992,44.04778,1.11304,4.89420,127.99992
15.40000,128.33335,44.55450,1.11594,4.95050,128.33335
15.44000,128.66667,44.46285,1.11884,4.94032,128.66667
15.48000,128.99998,44.47764,1.12174,4.94196,128.99998
15.52000,129.33335,44.62185,1.12464,4.95798,129.33335
15.56000,129.66667,44.93499,1.12754,4.99278,129.66667
15.60000,130.00004,44.84271,1.13044,4.98252,130.00004
15.64000,130.33335,45.09854,1.13333,5.01095,130.33335
15.68000,130.66666,45.25362,1.13623,5.02818,130.66666
15.72000,131.00005,45.48678,1.13913,5.05409,131.00005
15.76000,131.33335,45.36222,1.14203,5.04025,131.33335
15.80000,131.66660,45.54693,1.14493,5.06077,131.66660
15.84000,132.00005,45.64391,1.14783,5.07155,132.00005
15.88000,132.33329,45.81893,1.15072,5.09099,132.33329
15.92000,132.66667,45.70592,1.15362,5.07844,132.66667
15.96000,133.00004,45.88167,1.15652,5.09796,133.00004
16.00000,133.33322,45.98228,1.15942,5.10914,133.33322
16.04000,133.66667,46.18144,1.16232,5.13127,133.66667
16.08000,134.00011,46.17640,1.16522,5.13071,134.00011
16.12000,134.33336,46.38746,1.16812,5.15416,134.33336
16.16000,134.66679,46.52398,1.17102,5.16933,134.66679
16.20000,134.99998,46.42616,1.17391,5.15846,134.99998
16.24000,135.33336,46.53083,1.17681,5.17009,135.33336
16.28000,135.66679,46.75939,1.17971,5.19549,135.66679
16.32000,135.99998,46.65446,1.18261,5.18383,135.99998
16.36000,136.33328,46.72280,1.18551,5.19142,136.33328
16.40000,136.66667,47.23466,1.18841,5.24830,136.66667
16.44000,136.99998,47.06675,1.19130,5.22964,136.99998
16.48000,137.33335,47.29344,1.19420,5.25483,137.33335
16.52000,137.66666,47.51293,1.19710,5.27921,137.66666
16.56000,137.99992,47.36603,1.20000,5.26289,137.99992
16.60000,138.33336,47.69132,1.20290,5.29904,138.33336
16.64000,138.66660,47.56206,1.20580,5.28467,138.66660
16.68000,139.00004,47.50813,1.20870,5.27868,139.00004
16.72000,139.33341,47.74711,1.21159,5.30523,139.33341
16.76000,139.66667,47.91307,1.21449,5.32367,139.66667
16.80000,140.00005,48.05810,1.21739,5.33979,140.00005
16.84000,140.33330,47.91591,1.22029,5.32399,140.33330
16.88000,140.66666,48.35395,1.22319,5.37266,140.66666
16.92000,141.00011,48.19467,1.22609,5.35496,141.00011
16.96000,141.33330,48.43566,1.22899,5.38174,141.33330
17.00000,141.66667,48.30110,1.23188,5.36679,141.66667
17.04000,142.00004,48.50869,1.23478,5.38985,142.00004
17.08000,142.33328,48.80185,1.23768,5.42243,142.33328
17.12000,142.66673,48.97676,1.24058,5.44186,142.66673
17.16000,142.99998,48.73974,1.24348,5.41553,142.99998
17.20000,143.33323,48.99464,1.24638,5.44385,143.33323
17.24000,143.66673,49.09809,1.24928,5.45534,143.66673
17.28000,144.00004,48.86048,1.25217,5.42894,144.00004
17.32000,144.33342,49.30710,1.25507,5.47857,144.33342
17.36000,144.66673,49.49284,1.25797,5.49920,144.66673
17.40000,145.00004,49.22535,1.26087,5.46948,145.00004
17.44000,145.33341,49.74490,1.26377,5.52721,145.33341
17.48000,145.66674,49.67613,1.26667,5.51957,145.66674
17.52000,146.00004,49.62686,1.26957,5.51410,146.00004
17.56000,146.33335,49.86413,1.27246,5.54046,146.33335
17.60000,146.66661,50.21249,1.27536,5.57917,146.66661
17.64000,146.99997,50.16811,1.27826,5.57423,146.99997
17.68000,147.33336,50.12554,1.28116,5.56950,147.33336
17.72000,147.66661,50.47851,1.28406,5.60872,147.66661
17.76000,147.99997,50.46215,1.28696,5.60691,147.99997
17.80000,148.33330,50.61983,1.28985,5.62443,148.33330
17.84000,148.66667,50.66078,1.29275,5.62897,148.66667
17.88000,149.00004,50.47758,1.29565,5.60862,149.00004
17.92000,149.33328,50.79136,1.29855,5.64348,149.33328
17.96000,149.66667,50.89359,1.30145,5.65484,149.66667
18.00000,150.00003,50.95212,1.30435,5.66135,150.00003
18.04000,150.33329,51.22030,1.30725,5.69114,150.33329
18.08000,150.66673,51.15030,1.31015,5.68337,150.66673
18.12000,151.00004,51.42808,1.31304,5.71423,151.00004
18.16000,151.33335,51.40183,1.31594,5.71131,151.33335
18.20000,151.66673,51.59021,1.31884,5.73225,151.66673
18.24000,151.99998,51.69964,1.32174,5.74440,151.99998
18.28000,152.33335,51.56327,1.32464,5.72925,152.33335
18.32000,152.66674,51.61049,1.32754,5.73450,152.66674
18.36000,152.99991,51.65477,1.33043,5.73942,152.99991
18.40000,153.33329,52.02341,1.33333,5.78038,153.33329
18.44000,153.66666,52.06314,1.33623,5.78479,153.66666
18.48000,153.99999,51.87279,1.33913,5.76364,153.99999
18.52000,154.33341,52.32671,1.34203,5.81408,154.33341
18.56000,154.66667,52.39881,1.34493,5.82209,154.66667
18.60000,154.99997,52.38623,1.34783,5.82069,154.99997
18.64000,155.33336,52.56741,1.35072,5.84082,155.33336
18.68000,155.66661,52.60596,1.35362,5.84511,155.66661
18.72000,156.00003,52.73478,1.35652,5.85942,156.00003
18.76000,156.33328,52.65087,1.35942,5.85010,156.33328
18.80000,156.66660,52.82608,1.36232,5.86957,156.66660
18.84000,157.00003,53.03411,1.36522,5.89268,157.00003
18.88000,157.33328,52.87404,1.36812,5.87489,157.33328
18.92000,157.66660,53.22299,1.37101,5.91367,157.66660
18.96000,157.99997,53.42058,1.37391,5.93562,157.99997
19.00000,158.33322,53.42725,1.37681,5.93636,158.33322
19.04000,158.66667,53.57316,1.37971,5.95257,158.66667
19.08000,159.00003,53.44743,1.38261,5.93860,159.00003
19.12000,159.33335,53.58095,1.38551,5.95344,159.33335
19.16000,159.66678,53.79153,1.38841,5.97684,159.66678
19.20000,160.00004,53.66143,1.39130,5.96238,160.00004
19.24000,160.33323,53.88831,1.39420,5.98759,160.33323
19.28000,160.66672,54.12989,1.39710,6.01443,160.66672
19.32000,161.00004,54.06740,1.40000,6.00749,161.00004
19.36000,161.33334,54.26616,1.40290,6.02957,161.33334
19.40000,161.66667,54.21120,1.40580,6.02347,161.66667
19.44000,161.99997,54.21723,1.40870,6.02414,161.99997
19.48000,162.33342,54.47399,1.41159,6.05267,162.33342
19.52000,162.66666,54.62241,1.41449,6.06916,162.66666
19.56000,162.99997,54.40562,1.41739,6.04507,162.99997
19.60000,163.33329,54.69447,1.42029,6.07716,163.33329
19.64000,163.66655,54.96201,1.42319,6.10689,163.66655
19.68000,164.00004,54.88726,1.42609,6.09858,164.00004
19.72000,164.33341,54.99022,1.42899,6.11002,164.33341
19.76000,164.66666,54.93619,1.43188,6.10402,164.66666
19.80000,165.00004,55.18517,1.43478,6.13169,165.00004
19.84000,165.33334,55.28940,1.43768,6.14327,165.33334
19.88000,165.66666,55.35195,1.44058,6.15022,165.66666
19.92000,166.00003,55.48617,1.44348,6.16513,166.00003
19.96000,166.33328,55.53495,1.44638,6.17055,166.33328
20.00000,166.66668,55.79040,1.44928,6.19893,166.66668
20.04000,167.00003,55.83492,1.45217,6.20388,167.00003
20.08000,167.33328,55.93568,1.45507,6.21508,167.33328
20.12000,167.66673,55.87773,1.45797,6.20864,167.66673
20.16000,167.99998,55.85814,1.46087,6.20646,167.99998
20.20000,168.33322,56.11368,1.46377,6.23485,168.33322
20.24000,168.66671,55.83374,1.46667,6.20375,168.66671
20.28000,169.00005,56.05118,1.46957,6.22791,169.00005
20.32000,169.33341,56.42124,1.47246,6.26903,169.33341
20.36000,169.66680,56.60952,1.47536,6.28995,169.66680
20.40000,169.99992,56.32127,1.47826,6.25792,169.99992
20.44000,170.33335,56.64856,1.48116,6.29428,170.33335
20.48000,170.66667,56.73904,1.48406,6.30434,170.66667
20.52000,171.00003,56.73277,1.48696,6.30364,171.00003
20.56000,171.33335,56.80737,1.48986,6.31193,171.33335
20.60000,171.66661,57.04890,1.49275,6.33877,171.66661
20.64000,171.99997,56.98400,1.49565,6.33156,171.99997
20.68000,172.33334,57.36591,1.49855,6.37399,172.33334
20.72000,172.66667,57.13388,1.50145,6.34821,172.66667
20.76000,173.00004,57.16146,1.50435,6.35127,173.00004
20.80000,173.33334,57.48165,1.50725,6.38685,173.33334
20.84000,173.66659,57.59779,1.51014,6.39975,173.66659
20.88000,174.00010,57.40426,1.51304,6.37825,174.00010
20.92000,174.33334,57.45172,1.51594,6.38352,174.33334
20.96000,174.66666,57.68155,1.51884,6.40906,174.66666
21.00000,175.00004,57.67200,1.52174,6.40800,175.00004
21.04000,175.33328,57.83031,1.52464,6.42559,175.33328
21.08000,175.66673,57.98583,1.52754,6.44287,175.66673
21.12000,176.00004,57.99822,1.53044,6.44425,176.00004
21.16000,176.33328,58.06900,1.53333,6.45211,176.33328
21.20000,176.66671,58.08222,1.53623,6.45358,176.66671
21.24000,176.99996,58.08134,1.53913,6.45348,176.99996
21.28000,177.33330,58.39802,1.54203,6.48867,177.33330
21.32000,177.66671,58.44298,1.54493,6.49366,177.66671
21.36000,177.99998,58.42902,1.54783,6.49211,177.99998
21.40000,178.33328,58.64136,1.55072,6.51571,178.33328
21.44000,178.66660,58.65659,1.55362,6.51740,178.66660
21.48000,179.00003,58.74212,1.55652,6.52690,179.00003
21.52000,179.33341,59.01666,1.55942,6.55741,179.33341
21.56000,179.66667,58.93809,1.56232,6.54868,179.66667
21.60000,180.00003,59.04933,1.56522,6.56104,180.00003
21.64000,180.33335,58.92026,1.56812,6.54670,180.33335
21.68000,180.66667,59.22341,1.57101,6.58038,180.66667
21.72000,181.00003,59.10405,1.57391,6.56712,181.00003
21.76000,181.33340,59.45211,1.57681,6.60579,181.33340
21.80000,181.66659,59.25079,1.57971,6.58342,181.66659
21.84000,181.99997,59.57276,1.58261,6.61920,181.99997
21.88000,182.33335,59.55326,1.58551,6.61703,182.33335
21.92000,182.66659,59.70760,1.58841,6.63418,182.66659
21.96000,183.00004,59.51687,1.59130,6.61299,183.00004
22.00000,183.33329,59.92788,1.59420,6.65865,183.33329
22.04000,183.66667,59.98068,1.59710,6.66452,183.66667
22.08000,184.00004,59.82712,1.60000,6.64746,184.00004
22.12000,184.33334,60.07904,1.60290,6.67545,184.33334
22.16000,184.66678,60.27546,1.60580,6.69727,184.66678
22.20000,184.99997,60.21350,1.60870,6.69039,184.99997
22.24000,185.33329,60.05376,1.61159,6.67264,185.33329
22.28000,185.66666,60.30759,1.61449,6.70084,185.66666
22.32000,185.99996,60.30744,1.61739,6.70083,185.99996
22.36000,186.33336,60.51836,1.62029,6.72426,186.33336
22.40000,186.66672,60.53491,1.62319,6.72610,186.66672
22.44000,186.99991,60.65037,1.62609,6.73893,186.99991
22.48000,187.33334,60.51346,1.62899,6.72372,187.33334
22.52000,187.66666,60.67187,1.63188,6.74132,187.66666
22.56000,187.99998,60.75788,1.63478,6.75088,187.99998
22.60000,188.33334,60.95538,1.63768,6.77282,188.33334
22.64000,188.66658,61.00529,1.64058,6.77837,188.66658
22.68000,188.99998,61.15993,1.64348,6.79555,188.99998
22.72000,189.33333,61.11423,1.64638,6.79047,189.33333
22.76000,189.66665,61.30330,1.64928,6.81148,189.66665
22.80000,190.00009,61.16733,1.65217,6.79637,190.00009
22.84000,190.33335,61.29894,1.65507,6.81099,190.33335
22.88000,190.66665,61.45255,1.65797,6.82806,190.66665
22.92000,191.00003,61.30551,1.66087,6.81172,191.00003
22.96000,191.33329,61.43467,1.66377,6.82607,191.33329
23.00000,191.66665,61.57055,1.66667,6.84117,191.66665
23.04000,191.99997,61.73846,1.66956,6.85983,191.99997
23.08000,192.33329,61.86199,1.67246,6.87355,192.33329
23.12000,192.66665,61.99243,1.67536,6.88805,192.66665
23.16000,192.99997,61.80390,1.67826,6.86710,192.99997
23.20000,193.33327,62.11313,1.68116,6.90146,193.33327
23.24000,193.66672,62.33741,1.68406,6.92638,193.66672
23.28000,194.00002,62.24719,1.68696,6.91635,194.00002
23.32000,194.33334,62.29352,1.68986,6.92150,194.33334
23.36000,194.66678,62.18038,1.69275,6.90893,194.66678
23.40000,195.00002,62.20536,1.69565,6.91171,195.00002
23.44000,195.33334,62.55828,1.69855,6.95092,195.33334
23.48000,195.66659,62.41956,1.70145,6.93551,195.66659
23.52000,195.99997,62.45458,1.70435,6.93940,195.99997
23.56000,196.33340,62.77365,1.70725,6.97485,196.33340
23.60000,196.66664,62.64831,1.71014,6.96092,196.66664
23.64000,196.99998,62.59193,1.71304,6.95466,196.99998
23.68000,197.33334,62.77002,1.71594,6.97445,197.33334
23.72000,197.66659,62.88969,1.71884,6.98774,197.66659
23.76000,197.99998,62.94724,1.72174,6.99414,197.99998
23.80000,198.33328,63.17002,1.72464,7.01889,198.33328
23.84000,198.66660,63.28635,1.72754,7.03182,198.66660
23.88000,199.00009,62.98966,1.73044,6.99885,199.00009
23.92000,199.33335,63.20421,1.73333,7.02269,199.33335
23.96000,199.66671,63.51279,1.73623,7.05698,199.66671
24.00000,200.00003,63.51965,1.73913,7.05774,200.00003
24.04000,200.33328,63.48385,1.74203,7.05376,200.33328
24.08000,200.66671,63.55585,1.74493,7.06176,200.66671
24.12000,201.00003,63.58303,1.74783,7.06478,201.00003
24.16000,201.33335,63.50755,1.75072,7.05639,201.33335
24.20000,201.66665,63.53420,1.75362,7.05936,201.66665
24.24000,201.99997,63.76667,1.75652,7.08519,201.99997
24.28000,202.33333,63.86468,1.75942,7.09608,202.33333
24.32000,202.66667,63.87511,1.76232,7.09723,202.66667
24.36000,202.99997,63.95177,1.76522,7.10575,202.99997
24.40000,203.33327,64.13247,1.76812,7.12583,203.33327
24.44000,203.66672,64.15279,1.77102,7.12809,203.66672
24.48000,203.99997,64.06203,1.77391,7.11800,203.99997
24.52000,204.33340,64.09049,1.77681,7.12117,204.33340
24.56000,204.66665,64.46006,1.77971,7.16223,204.66665
24.60000,205.00004,64.28549,1.78261,7.14283,205.00004
24.64000,205.33340,64.34500,1.78551,7.14944,205.33340
24.68000,205.66659,64.42239,1.78841,7.15804,205.66659
24.72000,206.00004,64.53799,1.79130,7.17089,206.00004
24.76000,206.33329,64.45081,1.79420,7.16120,206.33329
24.80000,206.66659,64.66603,1.79710,7.18511,206.66659
24.84000,207.00004,64.65247,1.80000,7.18361,207.00004
24.88000,207.33329,64.76728,1.80290,7.19636,207.33329
24.92000,207.66672,65.03164,1.80580,7.22574,207.66672
24.96000,208.00002,64.94004,1.80870,7.21556,208.00002
25.00000,208.33328,65.10717,1.81159,7.23413,208.33328
25.04000,208.66666,65.21880,1.81449,7.24653,208.66666
25.08000,209.00004,65.01675,1.81739,7.22408,209.00004
25.12000,209.33334,65.19014,1.82029,7.24335,209.33334
25.16000,209.66671,65.09252,1.82319,7.23250,209.66671
25.20000,210.00003,65.19230,1.82609,7.24359,210.00003
25.24000,210.33334,65.49971,1.82899,7.27775,210.33334
25.28000,210.66673,65.50025,1.83188,7.27781,210.66673
25.32000,210.99998,65.46978,1.83478,7.27442,210.99998
25.36000,211.33328,65.57764,1.83768,7.28640,211.33328
25.40000,211.66665,65.59797,1.84058,7.28866,211.66665
25.44000,211.99998,65.57666,1.84348,7.28630,211.99998
25.48000,212.33335,65.67051,1.84638,7.29672,212.33335
25.52000,212.66665,65.95892,1.84928,7.32877,212.66665
25.56000,212.99995,65.72385,1.85217,7.30265,212.99995
25.60000,213.33335,65.82525,1.85507,7.31392,213.33335
25.64000,213.66665,65.82466,1.85797,7.31385,213.66665
25.68000,214.00005,65.83798,1.86087,7.31533,214.00005
25.72000,214.33335,66.25595,1.86377,7.36177,214.33335
25.76000,214.66665,66.32502,1.86667,7.36945,214.66665
25.80000,215.00010,66.27691,1.86957,7.36410,215.00010
25.84000,215.33335,66.24973,1.87246,7.36108,215.33335
25.88000,215.66667,66.37703,1.87536,7.37523,215.66667
25.92000,216.00002,66.25820,1.87826,7.36202,216.00002
25.96000,216.33327,66.46310,1.88116,7.38479,216.33327
26.00000,216.66666,66.54729,1.88406,7.39414,216.66666
26.04000,216.99997,66.54352,1.88696,7.39372,216.99997
26.08000,217.33321,66.68910,1.88985,7.40990,217.33321
26.12000,217.66672,66.90021,1.89275,7.43336,217.66672
26.16000,217.99996,67.02335,1.89565,7.44704,217.99996
26.20000,218.33329,66.99607,1.89855,7.44401,218.33329
26.24000,218.66672,67.10212,1.90145,7.45579,218.66672
26.28000,218.99998,67.07454,1.90435,7.45273,218.99998
26.32000,219.33334,67.18499,1.90725,7.46500,219.33334
26.36000,219.66673,66.90864,1.91015,7.43429,219.66673
26.40000,220.00004,67.23707,1.91304,7.47079,220.00004
26.44000,220.33341,67.47125,1.91594,7.49681,220.33341
26.48000,220.66666,67.49060,1.91884,7.49896,220.66666
26.52000,220.99990,67.41046,1.92174,7.49005,220.99990
26.56000,221.33341,67.79507,1.92464,7.53279,221.33341
26.60000,221.66666,67.73698,1.92754,7.52633,221.66666
26.64000,222.00003,67.64499,1.93044,7.51611,222.00003
26.68000,222.33335,67.69627,1.93333,7.52181,222.33335
26.72000,222.66665,67.87858,1.93623,7.54207,222.66665
26.76000,222.99998,67.85326,1.93913,7.53925,222.99998
26.80000,223.33328,67.74173,1.94203,7.52686,223.33328
26.84000,223.66665,68.01637,1.94493,7.55737,223.66665
26.88000,224.00003,68.15979,1.94783,7.57331,224.00003
26.92000,224.33333,68.49439,1.95072,7.61049,224.33333
26.96000,224.66673,68.49042,1.95362,7.61005,224.66673
27.00000,225.00008,68.39608,1.95652,7.59956,225.00008
27.04000,225.33327,68.39324,1.95942,7.59925,225.33327
27.08000,225.66667,68.51168,1.96232,7.61241,225.66667
27.12000,226.00003,68.63982,1.96522,7.62665,226.00003
27.16000,226.33329,68.60392,1.96812,7.62266,226.33329
27.20000,226.66672,68.84795,1.97101,7.64977,226.66672
27.24000,226.99997,68.67890,1.97391,7.63099,226.99997
27.28000,227.33334,68.92533,1.97681,7.65837,227.33334
27.32000,227.66672,68.78715,1.97971,7.64302,227.66672
27.36000,227.99997,68.94434,1.98261,7.66048,227.99997
27.40000,228.33334,69.16398,1.98551,7.68489,228.33334
27.44000,228.66666,69.33625,1.98841,7.70403,228.66666
27.48000,229.00004,69.02041,1.99130,7.66893,229.00004
27.52000,229.33342,69.45449,1.99420,7.71717,229.33342
27.56000,229.66672,69.46233,1.99710,7.71804,229.66672
27.60000,230.00002,69.60575,2.00000,7.73397,230.00002
27.64000,230.33336,69.63553,2.00290,7.73728,230.33336
27.68000,230.66666,69.68579,2.00580,7.74287,230.66666
27.72000,231.00004,69.51597,2.00870,7.72400,231.00004
27.76000,231.33334,69.86565,2.01159,7.76285,231.33334
27.80000,231.66658,70.05722,2.01449,7.78413,231.66658
27.84000,232.00003,69.98193,2.01739,7.77577,232.00003
27.88000,232.33334,70.26196,2.02029,7.80688,232.33334
27.92000,232.66666,70.39162,2.02319,7.82129,232.66666
27.96000,233.00003,70.19153,2.02609,7.79906,233.00003
28.00000,233.33322,70.51138,2.02898,7.83460,233.33322
28.04000,233.66665,70.66396,2.03188,7.85155,233.66665
28.08000,234.00003,70.51094,2.03478,7.83455,234.00003
28.12000,234.33335,71.00228,2.03768,7.88914,234.33335
28.16000,234.66678,70.86254,2.04058,7.87362,234.66678
28.20000,234.99997,70.82825,2.04348,7.86981,234.99997
28.24000,235.33335,71.25483,2.04638,7.91720,235.33335
28.28000,235.66671,71.38003,2.04928,7.93111,235.66671
28.32000,236.00005,71.10549,2.05217,7.90061,236.00005
28.36000,236.33335,71.39850,2.05507,7.93317,236.33335
28.40000,236.66665,71.69328,2.05797,7.96592,236.66665
28.44000,236.99997,71.52272,2.06087,7.94697,236.99997
28.48000,237.33340,71.83341,2.06377,7.98149,237.33340
28.52000,237.66667,71.77591,2.06667,7.97510,237.66667
28.56000,237.99991,71.68505,2.06956,7.96500,237.99991
28.60000,238.33334,71.82058,2.07246,7.98006,238.33334
28.64000,238.66666,72.02385,2.07536,8.00265,238.66666
28.68000,239.00002,71.69602,2.07826,7.96622,239.00002
28.72000,239.33334,71.87853,2.08116,7.98650,239.33334
28.76000,239.66666,72.13891,2.08406,8.01544,239.66666
28.80000,240.00004,71.94254,2.08696,7.99362,240.00004
28.84000,240.33329,72.27695,2.08985,8.03077,240.33329
28.88000,240.66664,72.30105,2.09275,8.03345,240.66664
28.92000,241.00004,72.23575,2.09565,8.02619,241.00004
28.96000,241.33323,72.69741,2.09855,8.07749,241.33323
29.00000,241.66666,72.68120,2.10145,8.07569,241.66666
29.04000,242.00004,72.64515,2.10435,8.07168,242.00004
29.08000,242.33328,72.59979,2.10725,8.06664,242.33328
29.12000,242.66671,72.78774,2.11015,8.08753,242.66671
29.16000,242.99996,72.90387,2.11304,8.10043,242.99996
29.20000,243.33321,72.95854,2.11594,8.10650,243.33321
29.24000,243.66671,73.17034,2.11884,8.13004,243.66671
29.28000,244.00003,73.00997,2.12174,8.11222,244.00003
29.32000,244.33335,73.26835,2.12464,8.14093,244.33335
29.36000,244.66671,73.18635,2.12754,8.13182,244.66671
29.40000,245.00003,73.42578,2.13043,8.15842,245.00003
29.44000,245.33335,73.68999,2.13333,8.18778,245.33335
29.48000,245.66665,73.48348,2.13623,8.16483,245.66665
29.52000,246.00003,73.55827,2.13913,8.17314,246.00003
29.56000,246.33333,73.63802,2.14203,8.18200,246.33333
29.60000,246.66660,73.87103,2.14493,8.20789,246.66660
29.64000,247.00003,73.87407,2.14783,8.20823,247.00003
29.68000,247.33340,73.86505,2.15073,8.20723,247.33340
29.72000,247.66667,73.96860,2.15362,8.21873,247.66667
29.76000,247.99997,74.17697,2.15652,8.24189,247.99997
29.80000,248.33329,74.26578,2.15942,8.25175,248.33329
29.84000,248.66659,74.19617,2.16232,8.24402,248.66659
29.88000,249.00010,74.32293,2.16522,8.25810,249.00010
29.92000,249.33329,74.35248,2.16812,8.26139,249.33329
29.96000,249.66672,74.44662,2.17102,8.27185,249.66672
30.00000,250.00010,74.73032,2.17391,8.30337,250.00010
30.04000,250.33329,74.87678,2.17681,8.31964,250.33329
30.08000,250.66672,75.04449,2.17971,8.33828,250.66672
30.12000,250.99996,74.89926,2.18261,8.32214,250.99996
30.16000,251.33327,75.01604,2.18551,8.33512,251.33327
30.20000,251.66670,75.16171,2.18841,8.35130,251.66670
30.24000,251.99994,75.39545,2.19130,8.37727,251.99994
30.28000,252.33334,75.13482,2.19420,8.34831,252.33334
30.32000,252.66672,75.46403,2.19710,8.38489,252.66672
30.36000,253.00002,75.58350,2.20000,8.39817,253.00002
30.40000,253.33334,75.58012,2.20290,8.39779,253.33334
30.44000,253.66664,75.76752,2.20580,8.41861,253.66664
30.48000,253.99996,75.96918,2.20870,8.44102,253.99996
30.52000,254.33341,76.04486,2.21159,8.44943,254.33341
30.56000,254.66666,76.10540,2.21449,8.45616,254.66666
30.60000,254.99998,76.13612,2.21739,8.45957,254.99998
30.64000,255.33333,76.41331,2.22029,8.49037,255.33333
30.68000,255.66658,76.45044,2.22319,8.49449,255.66658
30.72000,256.00001,76.42276,2.22609,8.49142,256.00001
30.76000,256.33339,76.82099,2.22899,8.53567,256.33339
30.80000,256.66658,76.79135,2.23188,8.53237,256.66658
30.84000,257.00003,76.70671,2.23478,8.52297,257.00003
30.88000,257.33327,76.94829,2.23768,8.54981,257.33327
30.92000,257.66665,77.00305,2.24058,8.55589,257.66665
30.96000,258.00003,77.03876,2.24348,8.55986,258.00003
31.00000,258.33322,77.11179,2.24638,8.56798,258.33322
31.04000,258.66671,77.18825,2.24928,8.57647,258.66671
31.08000,259.00001,76.93629,2.25217,8.54848,259.00001
31.12000,259.33325,77.07976,2.25507,8.56442,259.33325
31.16000,259.66672,77.26148,2.25797,8.58461,259.66672
31.20000,260.00002,77.22313,2.26087,8.58035,260.00002
31.24000,260.33327,77.52065,2.26377,8.61341,260.33327
31.28000,260.66670,77.50820,2.26667,8.61202,260.66670
31.32000,261.00000,77.24566,2.26957,8.58285,261.00000
31.36000,261.33332,77.60798,2.27246,8.62311,261.33332
31.40000,261.66672,78.06004,2.27536,8.67334,261.66672
31.44000,261.99996,77.69037,2.27826,8.63226,261.99996
31.48000,262.33340,77.88899,2.28116,8.65433,262.33340
31.52000,262.66664,77.94513,2.28406,8.66057,262.66664
31.56000,262.99996,77.87959,2.28696,8.65329,262.99996
31.60000,263.33332,78.28888,2.28986,8.69876,263.33332
31.64000,263.66657,78.32024,2.29275,8.70225,263.66657
31.68000,264.00004,78.31975,2.29565,8.70219,264.00004
31.72000,264.33339,78.47012,2.29855,8.71890,264.33339
31.76000,264.66671,78.61521,2.30145,8.73502,264.66671
31.80000,265.00007,78.57759,2.30435,8.73084,265.00007
31.84000,265.33334,78.90430,2.30725,8.76714,265.33334
31.88000,265.66664,79.25266,2.31014,8.80585,265.66664
31.92000,266.00009,78.99345,2.31304,8.77705,266.00009
31.96000,266.33335,79.27936,2.31594,8.80882,266.33335
32.00000,266.66665,79.32119,2.31884,8.81347,266.66665
32.04000,267.00003,79.24541,2.32174,8.80505,267.00003
32.08000,267.33333,79.53739,2.32464,8.83749,267.33333
32.12000,267.66671,79.64040,2.32754,8.84893,267.66671
32.16000,267.99995,79.57732,2.33043,8.84192,267.99995
32.20000,268.33320,79.84559,2.33333,8.87173,268.33320
32.24000,268.66673,80.01908,2.33623,8.89101,268.66673
32.28000,269.00003,79.86401,2.33913,8.87378,269.00003
32.32000,269.33340,80.21384,2.34203,8.91265,269.33340
32.36000,269.66676,80.45385,2.34493,8.93932,269.66676
32.40000,270.00001,80.24759,2.34783,8.91640,270.00001
32.44000,270.33333,80.30882,2.35072,8.92320,270.33333
32.48000,270.66663,80.17808,2.35362,8.90868,270.66663
32.52000,271.00002,80.50984,2.35652,8.94554,271.00002
32.56000,271.33346,80.80584,2.35942,8.97843,271.33346
32.60000,271.66659,80.48692,2.36232,8.94299,271.66659
32.64000,271.99997,80.60824,2.36522,8.95647,271.99997
32.68000,272.33338,80.84414,2.36812,8.98268,272.33338
32.72000,272.66664,80.86687,2.37101,8.98521,272.66664
32.76000,273.00004,80.82034,2.37391,8.98004,273.00004
32.80000,273.33329,80.80535,2.37681,8.97837,273.33329
32.84000,273.66659,80.98291,2.37971,8.99810,273.66659
32.88000,274.00007,80.85487,2.38261,8.98387,274.00007
32.92000,274.33334,80.88720,2.38551,8.98747,274.33334
32.96000,274.66670,81.09763,2.38841,9.01085,274.66670
33.00000,275.00007,81.30281,2.39130,9.03365,275.00007
33.04000,275.33326,81.34788,2.39420,9.03865,275.33326
33.08000,275.66671,81.35635,2.39710,9.03959,275.66671
33.12000,276.00003,81.33813,2.40000,9.03757,276.00003
33.16000,276.33328,81.54601,2.40290,9.06067,276.33328
33.20000,276.66671,81.61478,2.40580,9.06831,276.66671
33.24000,277.00001,81.78803,2.40870,9.08756,277.00001
33.28000,277.33326,81.94183,2.41159,9.10465,277.33326
33.32000,277.66673,82.01923,2.41449,9.11325,277.66673
33.36000,277.99997,81.93708,2.41739,9.10412,277.99997
33.40000,278.33333,38.89239,2.42029,4.32138,278.33333
33.44000,278.66671,-4.10949,2.42319,-0.45661,278.66671
33.48000,279.00001,-1.61674,2.42609,-0.17964,279.00001
33.52000,279.33339,-0.40815,2.42899,-0.04535,279.33339
33.56000,279.66669,-0.48953,2.43188,-0.05439,279.66669
33.60000,280.00010,-0.56920,2.43478,-0.06324,280.00010
33.64000,280.33335,-0.60611,2.43768,-0.06735,280.33335
33.68000,280.66665,-0.56555,2.44058,-0.06284,280.66665
33.72000,281.00008,-0.58326,2.44348,-0.06481,281.00008
33.76000,281.33338,-0.54086,2.44638,-0.06010,281.33338
33.80000,281.66665,-0.45733,2.44928,-0.05081,281.66665
33.84000,282.00001,-0.55149,2.45217,-0.06128,282.00001
33.88000,282.33325,-0.62903,2.45507,-0.06989,282.33325
33.92000,282.66666,-0.52497,2.45797,-0.05833,282.66666
33.96000,283.00002,-0.46742,2.46087,-0.05194,283.00002
34.00000,283.33327,-0.49543,2.46377,-0.05505,283.33327
34.04000,283.66664,-0.60508,2.46667,-0.06723,283.66664
34.08000,284.00002,-0.57261,2.46957,-0.06362,284.00002
34.12000,284.33327,-0.57412,2.47246,-0.06379,284.33327
34.16000,284.66677,-0.56105,2.47536,-0.06234,284.66677
34.20000,285.00004,-0.60229,2.47826,-0.06692,285.00004
34.24000,285.33334,-0.70990,2.48116,-0.07888,285.33334
34.28000,285.66672,-0.56011,2.48406,-0.06223,285.66672
34.32000,286.00002,-0.67402,2.48696,-0.07489,286.00002
34.36000,286.33339,-0.51968,2.48986,-0.05774,286.33339
34.40000,286.66670,-0.36012,2.49275,-0.04001,286.66670
34.44000,287.00003,-0.64943,2.49565,-0.07216,287.00003
34.48000,287.33334,-0.43923,2.49855,-0.04880,287.33334
34.52000,287.66666,-0.42142,2.50145,-0.04682,287.66666
34.56000,287.99996,-0.72984,2.50435,-0.08109,287.99996
34.60000,288.33333,-0.53168,2.50725,-0.05908,288.33333
34.64000,288.66658,-0.44442,2.51014,-0.04938,288.66658
34.68000,288.99996,-0.75923,2.51304,-0.08436,288.99996
34.72000,289.33335,-0.59707,2.51594,-0.06634,289.33335
34.76000,289.66671,-0.58608,2.51884,-0.06512,289.66671
34.80000,290.00014,-0.62237,2.52174,-0.06915,290.00014
34.84000,290.33333,-0.64512,2.52464,-0.07168,290.33333
34.88000,290.66665,-0.59854,2.52754,-0.06650,290.66665
34.92000,291.00006,-0.68703,2.53044,-0.07634,291.00006
34.96000,291.33333,-0.62036,2.53333,-0.06893,291.33333
35.00000,291.66667,-0.50599,2.53623,-0.05622,291.66667
35.04000,292.00003,-0.70126,2.53913,-0.07792,292.00003
35.08000,292.33327,-0.54150,2.54203,-0.06017,292.33327
35.12000,292.66670,-0.56002,2.54493,-0.06222,292.66670
35.16000,292.99995,-0.69619,2.54783,-0.07735,292.99995
35.20000,293.33327,-0.58620,2.55072,-0.06513,293.33327
35.24000,293.66663,-0.51192,2.55362,-0.05688,293.66663
35.28000,293.99995,-0.54072,2.55652,-0.06008,293.99995
35.32000,294.33334,-0.66232,2.55942,-0.07359,294.33334
35.36000,294.66677,-0.77924,2.56232,-0.08658,294.66677
35.40000,294.99996,-0.65225,2.56522,-0.07247,294.99996
35.44000,295.33332,-0.55299,2.56812,-0.06144,295.33332
35.48000,295.66670,-0.53839,2.57101,-0.05982,295.66670
35.52000,295.99994,-0.63795,2.57391,-0.07088,295.99994
35.56000,296.33341,-0.45955,2.57681,-0.05106,296.33341
35.60000,296.66666,-0.35980,2.57971,-0.03998,296.66666
35.64000,297.00002,-0.63959,2.58261,-0.07107,297.00002
35.68000,297.33334,-0.47770,2.58551,-0.05308,297.33334
35.72000,297.66664,-0.69305,2.58841,-0.07701,297.66664
35.76000,297.99996,-0.68725,2.59130,-0.07636,297.99996
35.80000,298.33326,-0.63440,2.59420,-0.07049,298.33326
35.84000,298.66656,-0.74779,2.59710,-0.08309,298.66656
35.88000,299.00003,-0.75355,2.60000,-0.08373,299.00003
35.92000,299.33328,-0.46435,2.60290,-0.05159,299.33328
35.96000,299.66665,-0.46203,2.60580,-0.05134,299.66665
36.00000,300.00007,-0.34508,2.60870,-0.03834,300.00007
36.04000,300.33326,-0.37080,2.61159,-0.04120,300.33326
36.08000,300.66669,-0.52139,2.61449,-0.05793,300.66669
36.12000,301.00003,-0.64549,2.61739,-0.07172,301.00003
36.15400,301.28334,-0.55309,2.61986,-0.06145,301.28334