File: V_8/FR/RDSO FR Tensile 50.is_tens_RawData/Specimen_RawData_4.csv
Time,Extension,Load
(sec),(mm),(N)
0.00000,0.00000,0.06974
0.20000,0.16462,1.12230
0.40000,0.33306,1.45810
0.60000,0.49994,2.10010
0.80000,0.66669,2.27199
1.00000,0.83337,2.66193
1.20000,1.00000,3.16908
1.40000,1.16681,3.58734
1.60000,1.33337,3.96204
1.80000,1.49987,4.15177
2.00000,1.66669,4.46875
2.20000,1.83344,4.70846
2.40000,1.99994,4.91974
2.60000,2.16662,5.13833
2.80000,2.33331,5.57428
3.00000,2.49994,5.79508
3.20000,2.66675,5.89259
3.40000,2.83331,6.02126
3.60000,2.99994,6.40307
3.80000,3.16675,6.76797
4.00000,3.33337,6.83338
4.20000,3.49994,6.94202
4.40000,3.66681,7.13375
4.60000,3.83331,7.24052
4.80000,3.99994,7.49478
5.00000,4.16675,7.73797
5.20000,4.33337,7.69999
5.40000,4.49994,7.97376
5.60000,4.66675,8.27530
5.80000,4.83331,8.44744
6.00000,4.99987,8.41608
6.20000,5.16675,8.75516
6.40000,5.33331,8.82596
6.60000,5.50000,9.00388
6.80000,5.66675,9.08586
7.00000,5.83331,9.24275
7.20000,5.99994,9.15103
7.40000,6.16675,9.48834
7.60000,6.33337,9.77107
7.80000,6.49994,9.68591
8.00000,6.66675,9.86500
8.20000,6.83331,10.05948
8.40000,6.99987,10.34295
8.60000,7.16675,10.31428
8.80000,7.33337,9.96820
9.00000,7.49994,10.24946
9.20000,7.66669,10.42350
9.40000,7.83325,10.45168
9.60000,7.99987,10.65121
9.80000,8.16681,10.85769
10.00000,8.33337,11.10156
10.20000,8.49987,10.85764
10.40000,8.66669,10.97279
10.60000,8.83331,11.16869
10.80000,8.99987,11.06261
11.00000,9.16675,11.17673
11.20000,9.33337,11.34294
11.40000,9.49994,11.41751
11.60000,9.66669,11.53311
11.80000,9.83337,11.68398
12.00000,10.00000,11.68790
12.20000,10.16675,11.82265
12.40000,10.33337,12.03251
12.60000,10.49994,11.79212
12.80000,10.66669,11.79633
13.00000,10.83331,12.09097
13.20000,10.99994,11.93946
13.40000,11.16675,12.32303
13.60000,11.33331,12.09700
13.80000,11.49987,12.03800
14.00000,11.66675,12.41103
14.20000,11.83337,12.44666
14.40000,11.99987,12.36836
14.60000,12.16669,12.57376
14.80000,12.33337,12.56607
15.00000,12.50000,12.59640
15.20000,12.66675,12.65251
15.40000,12.83331,12.54294
15.60000,12.99994,12.64913
15.80000,13.16675,12.73492
16.00000,13.33331,13.09204
16.20000,13.49994,13.03456
16.40000,13.66675,13.10296
16.60000,13.83331,13.22135
16.80000,13.99987,13.17945
17.00000,14.16669,13.11217
17.20000,14.33337,13.21576
17.40000,14.50000,13.46767
17.60000,14.66675,13.29965
17.80000,14.83331,13.46938
18.00000,14.99994,13.30484
18.20000,15.16675,13.53083
18.40000,15.33331,13.38907
18.60000,15.50000,13.32665
18.80000,15.66675,13.62716
19.00000,15.83337,13.78083
19.20000,15.99994,13.55474
19.40000,16.16675,13.89490
19.60000,16.33337,13.72756
19.80000,16.49987,13.89191
20.00000,16.66675,14.06331
20.20000,16.83337,13.93547
20.40000,16.99987,13.95169
20.60000,17.16669,14.12956
20.80000,17.33337,14.10584
21.00000,17.49987,13.92498
21.20000,17.66675,14.18253
21.40000,17.83337,14.08085
21.60000,17.99993,14.26597
21.80000,18.16675,14.42802
22.00000,18.33331,14.30199
22.20000,18.49987,14.30385
22.40000,18.66681,14.29224
22.60000,18.83337,14.41944
22.80000,18.99993,14.62245
23.00000,19.16668,14.33991
23.20000,19.33331,14.45139
23.40000,19.50000,14.56722
23.60000,19.66669,14.60197
23.80000,19.83337,14.59182
24.00000,19.99993,14.54258
24.20000,20.16675,14.64783
24.40000,20.33331,14.59976
24.60000,20.49993,14.77101
24.80000,20.66675,14.76180
25.00000,20.83337,14.89866
25.20000,20.99993,15.00293
25.40000,21.16675,14.88538
25.60000,21.33331,14.97319
25.80000,21.49994,15.10652
26.00000,21.66675,15.12842
26.20000,21.83337,14.90792
26.40000,21.99993,15.25847
26.60000,22.16668,15.34324
26.80000,22.33331,15.23338
27.00000,22.49993,15.30291
27.20000,22.66675,15.34034
27.40000,22.83331,15.16909
27.60000,22.99994,15.30644
27.80000,23.16675,15.56976
28.00000,23.33337,15.43874
28.20000,23.49993,15.37396
28.40000,23.66675,15.56898
28.60000,23.83331,15.63929
28.80000,23.99993,15.60352
29.00000,24.16675,15.79825
29.20000,24.33343,15.77963
29.40000,24.49993,15.69932
29.60000,24.66668,15.76111
29.80000,24.83331,15.61190
30.00000,24.99999,15.71784
30.20000,25.16675,15.65512
30.40000,25.33331,15.74302
30.60000,25.49981,15.92766
30.80000,25.66668,15.82907
31.00000,25.83337,15.85680
31.20000,25.99993,16.14193
31.40000,26.16675,16.08504
31.60000,26.33331,15.98165
31.80000,26.49987,16.08769
32.00000,26.66668,15.91962
32.20000,26.83337,15.94089
32.40000,26.99994,16.35680
32.60000,27.16674,16.23587
32.80000,27.33337,16.33950
33.00000,27.49993,16.37669
33.20000,27.66668,16.32338
33.40000,27.83337,16.36008
33.60000,28.00000,16.39414
33.80000,28.16675,16.43804
34.00000,28.33331,16.50424
34.20000,28.49987,16.73929
34.40000,28.66675,16.75933
34.60000,28.83337,16.37027
34.80000,28.99987,16.69490
35.00000,29.16669,16.78084
35.20000,29.33337,16.64247
35.40000,29.49993,16.56284
35.60000,29.66675,16.80515
35.80000,29.83337,16.60988
36.00000,29.99993,16.75571
36.20000,30.16668,16.83298
36.40000,30.33337,16.79280
36.60000,30.49999,16.86664
36.80000,30.66675,17.00100
37.00000,30.83331,17.05828
37.20000,30.99993,16.97949
37.40000,31.16675,16.92441
37.60000,31.33337,16.84111
37.80000,31.49993,17.08322
38.00000,31.66674,17.15236
38.20000,31.83331,17.36806
38.40000,31.99993,17.20454
38.60000,32.16675,17.37746
38.80000,32.33331,17.28515
39.00000,32.49993,17.35806
39.20000,32.66668,17.43945
39.40000,32.83331,17.46655
39.60000,32.99993,17.45194
39.80000,33.16681,17.45954
40.00000,33.33331,17.36967
40.20000,33.49993,17.55264
40.40000,33.66675,17.66299
40.60000,33.83337,17.81288
40.80000,33.99987,17.76672
41.00000,34.16675,17.77015
41.20000,34.33343,17.58620
41.40000,34.49987,18.06278
41.60000,34.66674,17.79788
41.80000,34.83337,17.87442
42.00000,34.99993,17.88569
42.20000,35.16668,17.87775
42.40000,35.33331,17.93312
42.60000,35.49987,18.11329
42.80000,35.66675,17.96865
43.00000,35.83337,18.09017
43.20000,35.99993,18.10325
43.40000,36.16675,18.27009
43.60000,36.33331,18.26686
43.80000,36.49993,18.30978
44.00000,36.66674,18.29141
44.20000,36.83337,18.27578
44.40000,36.99993,18.55611
44.60000,37.16668,18.42219
44.80000,37.33331,18.30018
45.00000,37.49993,18.56042
45.20000,37.66675,18.51044
45.40000,37.83331,18.34893
45.60000,37.99993,18.55919
45.80000,38.16674,18.69110
46.00000,38.33331,18.62774
46.20000,38.49993,18.66753
46.40000,38.66674,18.72560
46.60000,38.83331,18.72868
46.80000,38.99987,18.77950
47.00000,39.16668,18.77700
47.20000,39.33337,18.61255
47.40000,39.49993,18.84496
47.60000,39.66675,19.07742
47.80000,39.83330,19.12254
48.00000,39.99987,18.84364
48.20000,40.16681,18.90038
48.40000,40.33331,18.97079
48.60000,40.49993,18.92081
48.80000,40.66675,18.99524
49.00000,40.83330,19.12906
49.20000,40.99987,19.11794
49.40000,41.16674,19.34657
49.60000,41.33331,19.33408
49.80000,41.49993,19.37259
50.00000,41.66674,19.28689
50.20000,41.83331,19.26391
50.40000,41.99993,19.26259
50.60000,42.16681,19.37014
50.80000,42.33337,19.52233
51.00000,42.49987,19.52910
51.20000,42.66668,19.38729
51.40000,42.83337,19.61705
51.60000,42.99993,19.61842
51.80000,43.16675,19.84417
52.00000,43.33337,19.97465
52.20000,43.49987,19.70491
52.40000,43.66674,19.75592
52.60000,43.83331,19.74239
52.80000,43.99993,19.91384
53.00000,44.16674,19.72848
53.20000,44.33337,19.87043
53.40000,44.49987,20.11724
53.60000,44.66674,20.05491
53.80000,44.83337,20.15228
54.00000,44.99999,20.03272
54.20000,45.16668,19.87381
54.40000,45.33337,20.06256
54.60000,45.49993,20.08485
54.80000,45.66681,20.19726
55.00000,45.83331,20.26419
55.20000,45.99987,20.16801
55.40000,46.16668,20.26449
55.60000,46.33330,20.22372
55.80000,46.49993,20.45588
56.00000,46.66674,20.31961
56.20000,46.83331,20.34597
56.40000,46.99986,20.43672
56.60000,47.16674,20.60317
56.80000,47.33331,20.76247
57.00000,47.49993,20.69603
57.20000,47.66668,20.49439
57.40000,47.83330,20.64717
57.60000,47.99987,20.84366
57.80000,48.16681,20.68863
58.00000,48.33330,20.82313
58.20000,48.49993,20.94990
58.40000,48.66675,20.71680
58.60000,48.83330,20.65075
58.80000,48.99987,20.91545
59.00000,49.16674,20.96842
59.20000,49.33331,21.09636
59.40000,49.49987,20.92451
59.60000,49.66674,21.14624
59.80000,49.83330,21.33876
60.00000,49.99993,21.13727
60.20000,50.16674,21.16863
60.40000,50.33331,21.38511
60.60000,50.49993,21.44303
60.80000,50.66674,21.35512
61.00000,50.83337,21.52246
61.20000,50.99987,21.54103
61.40000,51.16674,21.47233
61.60000,51.33336,21.61272
61.80000,51.49987,21.46488
62.00000,51.66674,21.42833
62.20000,51.83337,21.73100
62.40000,51.99993,21.74036
62.60000,52.16668,21.76716
62.80000,52.33331,21.63869
63.00000,52.49986,21.73958
63.20000,52.66674,21.88506
63.40000,52.83337,21.92186
63.60000,52.99993,21.89608
63.80000,53.16674,21.88653
64.00000,53.33330,21.97541
64.20000,53.49993,21.91652
64.40000,53.66674,22.02799
64.60001,53.83337,22.04431
64.80000,53.99987,22.08826
65.00000,54.16675,22.16068
65.20000,54.33330,22.20253
65.40000,54.49993,22.30670
65.60001,54.66668,22.53093
65.80000,54.83337,22.25359
66.00000,54.99993,22.39779
66.20001,55.16674,22.51892
66.40000,55.33330,22.55346
66.60001,55.49993,22.62736
66.80000,55.66674,22.70125
67.00000,55.83324,22.73418
67.20001,55.99987,22.45919
67.40000,56.16674,22.54112
67.60001,56.33337,22.68425
67.80000,56.49993,22.89612
68.00000,56.66674,22.86942
68.20001,56.83331,22.69610
68.40000,56.99987,22.65357
68.60001,57.16674,22.99564
68.80000,57.33337,22.88245
69.00000,57.49993,22.93326
69.20001,57.66674,23.02612
69.40000,57.83324,23.22677
69.60001,57.99993,23.02965
69.80000,58.16680,23.31968
70.00000,58.33331,23.25862
70.20001,58.49987,23.41067
70.40000,58.66674,23.34805
70.60001,58.83330,23.22839
70.80000,58.99993,23.30037
71.00000,59.16681,23.64107
71.20001,59.33330,23.37725
71.40000,59.49981,23.37426
71.60001,59.66668,23.37196
71.80000,59.83337,23.59055
72.00000,59.99999,23.49715
72.20001,60.16674,23.70197
72.40000,60.33331,23.52097
72.60001,60.49987,23.68105
72.80000,60.66674,23.72598
73.00000,60.83337,23.64425
73.20001,60.99987,23.75406
73.40000,61.16681,24.01783
73.60001,61.33331,24.11205
73.80000,61.49987,24.09044
74.00000,61.66674,23.77552
74.20001,61.83343,24.18330
74.40000,61.99993,24.16017
74.60001,62.16668,24.17394
74.80000,62.33331,24.17046
75.00000,62.49993,24.14968
75.20001,62.66674,24.17487
75.40000,62.83330,24.23539
75.60001,62.99987,24.35622
75.80000,63.16674,24.37445
76.00000,63.33330,24.40772
76.20001,63.49993,24.42467
76.40000,63.66674,24.60504
76.60001,63.83331,24.48200
76.80000,63.99993,24.62430
77.00000,64.16667,24.64880
77.20001,64.33337,24.78448
77.40000,64.49993,24.84529
77.60001,64.66674,24.62121
77.80000,64.83330,24.81358
78.00000,64.99992,24.99424
78.20001,65.16674,24.94475
78.40000,65.33337,24.96759
78.60001,65.49987,24.78658
78.80000,65.66674,24.88703
79.00000,65.83330,25.19725
79.20001,65.99993,25.08087
79.40000,66.16674,25.17981
79.60001,66.33336,25.32205
79.80000,66.49987,25.09073
80.00000,66.66668,25.31039
80.20001,66.83336,25.20401
80.40000,66.99986,25.53883
80.60001,67.16674,25.29011
80.80000,67.33330,25.63644
81.00001,67.49993,25.59724
81.20001,67.66674,25.64913
81.40000,67.83336,25.59925
81.60001,67.99986,25.51781
81.80000,68.16674,25.78544
82.00001,68.33330,25.72434
82.20001,68.49993,25.70504
82.40000,68.66674,25.84714
82.60001,68.83337,25.84032
82.80000,68.99986,25.90270
83.00001,69.16674,25.94616
83.20001,69.33330,26.00369
83.40000,69.49992,26.12516
83.60001,69.66680,25.99100
83.80000,69.83336,26.17142
84.00001,69.99987,26.14555
84.20001,70.16668,26.33738
84.40000,70.33330,26.40010
84.60001,70.49993,26.18269
84.80000,70.66674,26.39446
85.00001,70.83336,26.61296
85.20001,70.99986,26.54308
85.40000,71.16674,26.41911
85.60001,71.33336,26.48472
85.80000,71.49993,26.66044
86.00001,71.66674,26.71267
86.20001,71.83337,26.46145
86.40000,71.99986,26.76662
86.60001,72.16667,26.66088
86.80000,72.33343,26.90627
87.00001,72.49992,26.65808
87.20001,72.66674,26.87750
87.40000,72.83330,26.98261
87.60001,72.99987,27.17258
87.80000,73.16674,27.09952
88.00001,73.33330,27.06483
88.20001,73.49993,27.11623
88.40000,73.66674,27.05493
88.60001,73.83336,27.34291
88.80000,73.99987,27.10349
89.00001,74.16674,27.30111
89.20001,74.33336,27.31120
89.40000,74.49986,27.44811
89.60001,74.66668,27.54028
89.80000,74.83337,27.30885
90.00001,74.99993,27.54861
90.20001,75.16674,27.54219
90.40000,75.33330,27.46849
90.60001,75.49986,27.81326
90.80000,75.66674,27.78518
91.00001,75.83336,27.87568
91.20001,75.99999,28.00798
91.40000,76.16674,27.72099
91.60001,76.33330,27.89219
91.80000,76.49980,27.91998
92.00001,76.66674,28.07526
92.20001,76.83337,28.05301
92.40000,76.99999,28.20565
92.60001,77.16674,27.85902
92.80000,77.33330,28.09554
93.00001,77.49987,28.07070
93.20001,77.66674,28.16571
93.40000,77.83336,28.38087
93.60001,77.99999,28.51405
93.80000,78.16673,28.33594
94.00001,78.33336,28.43472
94.20001,78.49980,28.71980
94.40000,78.66674,28.62528
94.60001,78.83336,28.59201
94.80000,78.99993,28.44325
95.00001,79.16667,28.65365
95.20001,79.33330,28.59701
95.40000,79.49992,28.75812
95.60001,79.66674,28.62298
95.80000,79.83330,28.91492
96.00001,79.99986,28.81266
96.20001,80.16674,28.92511
96.40000,80.33336,28.81236
96.60001,80.49992,29.11905
96.80000,80.66674,28.98901
97.00001,80.83330,28.97588
97.20001,80.99986,29.18339
97.40000,81.16674,29.34073
97.60001,81.33336,29.27139
97.80000,81.49993,29.18251
98.00001,81.66668,29.28291
98.20001,81.83336,29.52482
98.40000,81.99993,29.53060
98.60001,82.16674,29.54422
98.80000,82.33336,29.43966
99.00001,82.49993,29.45627
99.20001,82.66667,29.57598
99.40000,82.83329,29.76688
99.60001,82.99992,29.73430
99.80000,83.16667,29.57911
100.00001,83.33337,29.77055
100.20001,83.49986,29.90599
100.40000,83.66674,29.86341
100.60001,83.83336,30.02486
100.80000,83.99987,30.10287
101.00001,84.16673,30.02104
101.20001,84.33335,29.97689
101.40000,84.49992,29.95176
101.60001,84.66673,30.04397
101.80000,84.83330,30.07739
102.00001,84.99986,30.21278
102.20001,85.16674,30.26089
102.40000,85.33330,30.36384
102.60001,85.49985,30.50080
102.80000,85.66674,30.43676
103.00001,85.83331,30.67901
103.20001,85.99993,30.67396
103.40000,86.16674,30.80528
103.60001,86.33330,30.62354
103.80000,86.49993,30.67073
104.00001,86.66680,30.86604
104.20001,86.83336,30.57827
104.40000,86.99981,30.78284
104.60001,87.16667,30.98923
104.80000,87.33329,30.76006
105.00001,87.49993,30.96556
105.20001,87.66674,31.11501
105.40000,87.83337,31.38182
105.60001,87.99986,31.10717
105.80000,88.16673,31.14250
106.00001,88.33330,31.23673
106.20001,88.49998,31.15803
106.40000,88.66673,31.26828
106.60001,88.83336,31.27245
106.80000,88.99986,31.57345
107.00001,89.16673,31.34105
107.20001,89.33336,31.41425
107.40000,89.49992,31.47546
107.60001,89.66668,31.62829
107.80000,89.83336,31.56615
108.00001,89.99993,31.81394
108.20001,90.16674,31.86946
108.40000,90.33336,31.94659
108.60001,90.49992,31.77014
108.80000,90.66674,32.25558
109.00001,90.83330,32.00799
109.20001,90.99992,32.14072
109.40000,91.16674,32.01960
109.60001,91.33336,32.09418
109.80000,91.49986,32.21672
110.00001,91.66674,32.18380
110.20001,91.83336,32.28282
110.40000,91.99993,32.30311
110.60001,92.16674,32.30120
110.80000,92.33336,32.03704
111.00001,92.49986,32.43193
111.20001,92.66668,32.46525
111.40000,92.83336,32.44908
111.60001,92.99998,32.65067
111.80000,93.16674,32.29238
112.00001,93.33324,32.61264
112.20001,93.49986,32.72456
112.40000,93.66673,32.55365
112.60001,93.83336,32.97715
112.80000,93.99986,33.02894
113.00001,94.16673,32.92325
113.20001,94.33329,32.83388
113.40001,94.49986,32.97314
113.60001,94.66667,33.01224
113.80000,94.83336,32.97857
114.00001,94.99992,33.16668
114.20001,95.16673,33.22524
114.40001,95.33330,33.26454
114.60001,95.49987,33.28330
114.80000,95.66680,33.16438
115.00001,95.83335,33.39885
115.20001,95.99986,33.18697
115.40001,96.16673,33.46514
115.60001,96.33336,33.56324
115.80000,96.49992,33.48793
116.00001,96.66674,33.47916
116.20001,96.83336,33.61440
116.40001,96.99985,33.75934
116.60001,97.16667,33.65688
116.80000,97.33336,33.80339
117.00001,97.49993,33.63027
117.20001,97.66674,34.19470
117.40001,97.83329,33.86111
117.60001,97.99986,33.79133
117.80000,98.16674,34.04359
118.00001,98.33336,34.15408
118.20001,98.49992,34.08284
118.40001,98.66673,34.19387
118.60001,98.83337,34.19059
118.80000,98.99992,34.16153
119.00001,99.16673,34.13262
119.20001,99.33342,34.37585
119.40001,99.49992,34.19980
119.60001,99.66668,34.42598
119.80000,99.83336,34.37860
120.00001,99.99992,34.57381
120.20001,100.16673,34.48792
120.40001,100.33330,34.65074
120.60001,100.49992,34.80254
120.80000,100.66668,34.56793
121.00001,100.83336,34.78250
121.20001,100.99986,34.72973
121.40001,101.16667,34.75600
121.60001,101.33336,34.86502
121.80000,101.49992,34.94156
122.00001,101.66674,35.07890
122.20001,101.83336,34.92593
122.40001,101.99992,35.10306
122.60001,102.16674,35.20660
122.80000,102.33330,35.03064
123.00001,102.49992,35.22875
123.20001,102.66673,35.12158
123.40001,102.83336,35.32983
123.60001,102.99992,35.26241
123.80000,103.16667,35.48849
124.00001,103.33324,35.47262
124.20001,103.49993,35.31322
124.40001,103.66674,35.39931
124.60001,103.83330,35.39490
124.80000,103.99986,35.81973
125.00001,104.16668,35.76304
125.20001,104.33336,35.65103
125.40001,104.49992,35.70316
125.60001,104.66673,35.90999
125.80000,104.83329,36.09482
126.00001,104.99992,35.98785
126.20001,105.16667,35.93797
126.40001,105.33337,36.08727
126.60001,105.49992,36.04420
126.80000,105.66680,36.00809
127.00001,105.83330,36.24730
127.20001,105.99992,36.28322
127.40001,106.16673,36.29851
127.60001,106.33335,36.38588
127.80000,106.49987,36.45320
128.00000,106.66673,36.36917
128.20002,106.83330,36.26985
128.40001,106.99986,36.37701
128.60001,107.16673,36.59491
128.80000,107.33336,36.52861
129.00000,107.49992,36.57737
129.20002,107.66674,36.62759
129.40001,107.83330,36.54375
129.60001,107.99993,36.94918
129.80000,108.16674,36.64631
130.00000,108.33336,36.78606
130.20002,108.49993,36.84643
130.40001,108.66667,36.74451
130.60001,108.83336,37.05762
130.80000,108.99986,36.96794
131.00000,109.16674,37.01959
131.20002,109.33336,37.05879
131.40002,109.49986,37.28576
131.60000,109.66667,37.18595
131.80000,109.83337,37.27973
132.00000,109.99999,37.34701
132.20002,110.16673,37.41056
132.40002,110.33324,37.49866
132.60000,110.49992,37.31991
132.80000,110.66673,37.42624
133.00000,110.83336,37.59808
133.20002,110.99992,37.64552
133.40002,111.16673,37.63503
133.60000,111.33330,37.65551
133.80000,111.49986,37.63082
134.00000,111.66673,37.88184
134.20002,111.83336,38.06633
134.40002,111.99992,37.84651
134.60000,112.16667,37.73700
134.80000,112.33330,38.27276
135.00000,112.49986,38.00517
135.20002,112.66674,38.18138
135.40002,112.83336,38.09117
135.60000,112.99992,38.28389
135.80000,113.16674,38.11998
136.00000,113.33330,38.45112
136.20002,113.49992,38.14943
136.40002,113.66673,38.29569
136.60000,113.83330,38.32264
136.80000,113.99986,38.45587
137.00000,114.16674,38.47582
137.20002,114.33336,38.64124
137.40002,114.49993,38.52457
137.60000,114.66667,38.71102
137.80000,114.83336,38.43539
138.00000,114.99986,38.79103
138.20002,115.16673,38.81112
138.40002,115.33336,39.06465
138.60000,115.49992,38.82239
138.80000,115.66673,38.92887
139.00000,115.83329,39.11786
139.20002,115.99992,39.22958
139.40002,116.16673,39.28010
139.60000,116.33337,38.99487
139.80000,116.49992,39.11051
140.00000,116.66667,39.14927
140.20002,116.83336,39.13114
140.40002,116.99992,39.26863
140.60000,117.16673,39.44386
140.80000,117.33335,39.67759
141.00000,117.49987,39.52471
141.20002,117.66667,39.47478
141.40002,117.83335,39.55945
141.60000,117.99992,39.56753
141.80000,118.16667,39.67945
142.00000,118.33330,39.59022
142.20002,118.49992,39.75339
142.40002,118.66674,39.78000
142.60000,118.83330,39.91230
142.80000,118.99985,39.86673
143.00000,119.16674,39.71845
143.20002,119.33336,40.07008
143.40002,119.49993,40.15803
143.60000,119.66674,40.12231
143.80000,119.83336,40.15421
144.00000,119.99992,40.09820
144.20002,120.16667,40.21237
144.40002,120.33329,40.29587
144.60000,120.49992,40.42670
144.80000,120.66673,40.50569
145.00000,120.83329,40.36795
145.20002,120.99986,40.44840
145.40002,121.16673,40.45767
145.60000,121.33330,40.60515
145.80000,121.49992,40.44096
146.00000,121.66673,40.49588
146.20002,121.83330,40.67013
146.40002,121.99992,40.88960
146.60000,122.16668,40.89876
146.80000,122.33336,40.86196
147.00000,122.49999,40.99069
147.20002,122.66673,40.88715
147.40002,122.83330,40.89376
147.60000,122.99986,41.00367
147.80000,123.16674,40.99554
148.00000,123.33336,41.12235
148.20002,123.49992,41.22383
148.40002,123.66674,41.13254
148.60000,123.83330,41.23191
148.80000,123.99986,41.27871
149.00000,124.16674,41.42679
149.20002,124.33336,41.33574
149.40002,124.49986,41.39013
149.60000,124.66667,41.46123
149.80000,124.83330,41.58010
150.00000,124.99992,41.41316
150.20002,125.16673,41.52684
150.40002,125.33336,41.74298
150.60000,125.49992,41.58731
150.80000,125.66673,41.63023
151.00000,125.83329,41.77532
151.20002,125.99997,41.86381
151.40002,126.16667,41.81188
151.60000,126.33336,42.06432
151.80000,126.49992,42.02453
152.00000,126.66672,41.88444
152.20002,126.83335,41.96608
152.40002,126.99991,41.99425
152.60000,127.16673,42.09725
152.80000,127.33328,42.01532
153.00000,127.49985,41.95917
153.20002,127.66673,41.99734
153.40002,127.83336,42.03419
153.60000,127.99992,42.02233
153.80000,128.16667,41.06051
154.00000,128.33335,0.11016
154.20002,128.49986,0.23129
154.40002,128.66673,0.16049
154.60000,128.83335,0.08870
154.80000,128.99986,0.27113
155.00000,129.16672,0.17323
155.20002,129.33329,0.08899
155.40002,129.49991,0.30847
155.60000,129.66673,0.11991
155.80000,129.83336,0.41798
156.00000,129.99984,0.27490
156.20002,130.16673,0.08993
156.40002,130.33330,0.18332
156.60000,130.49997,0.39539
156.80000,130.66674,0.26353
157.00000,130.83323,0.38951
157.20002,130.99985,0.12991
157.40002,131.16673,0.23232
157.60000,131.33335,0.27274
157.78802,131.49003,0.32429