File: V_8/FR/RDSO FR Tensile 50.is_tens_RawData/Specimen_RawData_3.csv
Time,Extension,Load
(sec),(mm),(N)
0.00000,0.00000,-0.08187
0.20000,0.16469,0.96002
0.40000,0.33306,1.69389
0.60000,0.49994,2.04149
0.80000,0.66669,2.59651
1.00000,0.83337,3.01164
1.20000,0.99994,3.48816
1.40000,1.16675,3.84121
1.60000,1.33331,4.31366
1.80000,1.49987,4.39579
2.00000,1.66669,4.79327
2.20000,1.83344,4.93875
2.40000,1.99994,5.26284
2.60000,2.16662,5.75945
2.80000,2.33331,5.96432
3.00000,2.49994,6.11705
3.20000,2.66675,6.33652
3.40000,2.83331,6.49651
3.60000,2.99994,6.98925
3.80000,3.16675,7.06417
4.00000,3.33337,7.25655
4.20000,3.49987,7.31118
4.40000,3.66681,7.84386
4.60000,3.83331,7.87610
4.80000,3.99994,7.81524
5.00000,4.16669,7.92015
5.20000,4.33337,8.35762
5.40000,4.49994,8.73556
5.60000,4.66669,8.67911
5.80000,4.83331,8.76221
6.00000,4.99987,9.14961
6.20000,5.16675,9.15029
6.40000,5.33337,9.40431
6.60000,5.50000,9.58962
6.80000,5.66675,9.82130
7.00000,5.83331,9.80130
7.20000,5.99994,10.03567
7.40000,6.16675,10.13695
7.60000,6.33337,10.28199
7.80000,6.49994,10.39386
8.00000,6.66675,10.47652
8.20000,6.83331,10.51283
8.40000,6.99987,10.48387
8.60000,7.16675,10.75729
8.80000,7.33337,10.81379
9.00000,7.49994,10.95667
9.20000,7.66662,11.23862
9.40000,7.83325,11.25430
9.60000,7.99987,11.28752
9.80000,8.16681,11.23489
10.00000,8.33337,11.41825
10.20000,8.49981,11.50733
10.40000,8.66669,11.63135
10.60000,8.83331,11.65070
10.80000,8.99987,11.70965
11.00000,9.16675,11.61493
11.20000,9.33337,11.98469
11.40000,9.49987,12.19392
11.60000,9.66669,12.06338
11.80000,9.83337,12.08372
12.00000,10.00000,12.32529
12.20000,10.16675,12.30495
12.40000,10.33337,12.40609
12.60000,10.49994,12.51178
12.80000,10.66662,12.80833
13.00000,10.83337,12.57759
13.20000,10.99994,12.72155
13.40000,11.16669,12.69425
13.60000,11.33331,12.80494
13.80000,11.49987,12.94954
14.00000,11.66675,12.99815
14.20000,11.83337,13.12712
14.40000,11.99987,13.04666
14.60000,12.16669,13.23080
14.80000,12.33337,13.09571
15.00000,12.49994,13.22164
15.20000,12.66675,13.54386
15.40000,12.83337,13.16137
15.60000,12.99994,13.40024
15.80000,13.16675,13.44812
16.00000,13.33331,13.50285
16.20000,13.49994,13.44464
16.40000,13.66675,13.61545
16.60000,13.83331,13.64417
16.80000,13.99987,13.72697
17.00000,14.16675,13.76946
17.20000,14.33337,13.65485
17.40000,14.50000,14.13064
17.60000,14.66669,14.05233
17.80000,14.83331,14.01607
18.00000,14.99994,14.05949
18.20000,15.16669,14.08766
18.40000,15.33331,14.36990
18.60000,15.50000,14.09884
18.80000,15.66675,14.25588
19.00000,15.83337,14.18287
19.20000,15.99994,14.29817
19.40000,16.16675,14.30630
19.60000,16.33337,14.45462
19.80000,16.49987,14.42351
20.00000,16.66675,14.49015
20.20000,16.83337,14.29023
20.40000,16.99987,14.44654
20.60000,17.16669,14.61524
20.80000,17.33337,14.66081
21.00000,17.49994,14.78111
21.20000,17.66669,14.60652
21.40000,17.83337,14.99568
21.60000,17.99993,15.01974
21.80000,18.16675,14.92478
22.00000,18.33331,15.06095
22.20000,18.49987,14.94570
22.40000,18.66675,15.14229
22.60000,18.83337,14.88817
22.80000,18.99993,14.91762
23.00000,19.16662,15.03160
23.20000,19.33331,15.28331
23.40000,19.49994,15.43898
23.60000,19.66675,15.32197
23.80000,19.83337,15.17605
24.00000,19.99993,15.30168
24.20000,20.16675,15.35681
24.40000,20.33331,15.21809
24.60000,20.49993,15.41953
24.80000,20.66675,15.61229
25.00000,20.83337,15.41791
25.20000,20.99987,15.46833
25.40000,21.16675,15.45192
25.60000,21.33337,15.68300
25.80000,21.50000,15.55991
26.00000,21.66675,15.72798
26.20000,21.83337,15.75939
26.40000,21.99987,15.79379
26.60000,22.16668,15.73469
26.80000,22.33337,15.76552
27.00000,22.49993,15.78257
27.20000,22.66675,15.68810
27.40000,22.83325,15.95892
27.60000,22.99994,15.97793
27.80000,23.16675,16.14100
28.00000,23.33331,16.07818
28.20000,23.49993,16.04222
28.40000,23.66675,15.96220
28.60000,23.83331,16.12758
28.80000,23.99987,16.06054
29.00000,24.16675,16.28305
29.20000,24.33337,16.39482
29.40000,24.49993,16.28996
29.60000,24.66668,16.16457
29.80000,24.83331,16.47067
30.00000,24.99999,16.34719
30.20000,25.16675,16.34376
30.40000,25.33331,16.43353
30.60000,25.49981,16.53976
30.80000,25.66668,16.54623
31.00000,25.83337,16.68304
31.20000,25.99993,16.50032
31.40000,26.16675,16.66785
31.60000,26.33331,16.53555
31.80000,26.49987,16.66692
32.00000,26.66668,16.57445
32.20000,26.83337,16.58729
32.40000,26.99994,17.02550
32.60000,27.16674,16.93612
32.80000,27.33331,16.70523
33.00000,27.49993,16.85934
33.20000,27.66668,16.85767
33.40000,27.83337,17.01193
33.60000,28.00000,16.81617
33.80000,28.16675,17.02177
34.00000,28.33331,17.09527
34.20000,28.49987,16.94303
34.40000,28.66675,17.12928
34.60000,28.83331,17.25683
34.80000,28.99987,17.18161
35.00000,29.16669,17.24325
35.20000,29.33337,17.14712
35.40000,29.49993,17.31254
35.60000,29.66675,17.30568
35.80000,29.83337,17.27995
36.00000,29.99993,17.28760
36.20000,30.16668,17.32352
36.40000,30.33331,17.42578
36.60000,30.49993,17.45905
36.80000,30.66675,17.44058
37.00000,30.83331,17.53137
37.20000,30.99993,17.58782
37.40000,31.16675,17.63133
37.60000,31.33337,17.60433
37.80000,31.49993,17.43283
38.00000,31.66674,17.74864
38.20000,31.83331,17.57694
38.40000,31.99993,17.84919
38.60000,32.16675,17.77657
38.80000,32.33337,17.70895
39.00000,32.49993,17.83297
39.20000,32.66668,17.89544
39.40000,32.83324,17.98810
39.60000,32.99993,17.88358
39.80000,33.16674,18.02652
40.00000,33.33331,17.95797
40.20000,33.49993,17.88265
40.40000,33.66675,18.26529
40.60000,33.83337,18.05195
40.80000,33.99981,18.03578
41.00000,34.16675,18.28612
41.20000,34.33337,18.34168
41.40000,34.49987,18.25427
41.60000,34.66668,18.28803
41.80000,34.83337,18.32801
42.00000,34.99993,18.44983
42.20000,35.16668,18.36270
42.40000,35.33331,18.39333
42.60000,35.49987,18.11192
42.80000,35.66675,18.50794
43.00000,35.83337,18.57816
43.20000,35.99993,18.39078
43.40000,36.16675,18.53636
43.60000,36.33337,18.58590
43.80000,36.49993,18.52813
44.00000,36.66674,18.62260
44.20000,36.83337,18.83340
44.40000,36.99993,18.66097
44.60000,37.16668,18.58987
44.80000,37.33331,18.68679
45.00000,37.49993,18.89288
45.20000,37.66675,18.95124
45.40000,37.83331,18.93659
45.60000,37.99993,18.91199
45.80000,38.16674,19.20947
46.00000,38.33331,18.93341
46.20000,38.49993,18.90876
46.40000,38.66674,19.06213
46.60000,38.83331,19.10191
46.80000,38.99987,19.14582
47.00000,39.16668,19.01102
47.20000,39.33343,19.04375
47.40000,39.49993,19.26298
47.60000,39.66675,19.13279
47.80000,39.83330,19.15964
48.00000,39.99987,19.39298
48.20000,40.16681,19.15582
48.40000,40.33324,19.57560
48.60000,40.49993,19.47637
48.80000,40.66675,19.35770
49.00000,40.83325,19.52812
49.20000,40.99987,19.40959
49.40000,41.16681,19.40395
49.60000,41.33331,19.72990
49.80000,41.49993,19.39587
50.00000,41.66674,19.63866
50.20000,41.83331,19.77174
50.40000,41.99993,19.69604
50.60000,42.16681,19.80781
50.80000,42.33337,19.91443
51.00000,42.49987,20.14904
51.20000,42.66668,19.82677
51.40000,42.83337,19.94187
51.60000,42.99993,19.95069
51.80000,43.16675,20.00381
52.00000,43.33337,20.09975
52.20000,43.49981,20.07035
52.40000,43.66668,20.22676
52.60000,43.83337,20.06765
52.80000,43.99993,20.11602
53.00000,44.16674,20.39487
53.20000,44.33331,20.30388
53.40000,44.49993,20.18158
53.60000,44.66674,20.28438
53.80000,44.83337,20.43976
54.00000,44.99999,20.49934
54.20000,45.16668,20.40693
54.40000,45.33337,20.51194
54.60000,45.49993,20.52095
54.80000,45.66681,20.79682
55.00000,45.83331,20.50263
55.20000,45.99987,20.93471
55.40000,46.16668,20.75159
55.60000,46.33330,20.60347
55.80000,46.49993,20.44485
56.00000,46.66674,20.80201
56.20000,46.83337,20.80500
56.40000,46.99986,20.87468
56.60000,47.16674,20.96239
56.80000,47.33337,20.86944
57.00000,47.49993,21.15462
57.20000,47.66674,21.12105
57.40000,47.83330,20.85724
57.60000,47.99993,21.14021
57.80000,48.16674,21.11331
58.00000,48.33330,21.03334
58.20000,48.49993,21.25448
58.40000,48.66675,21.15721
58.60000,48.83330,21.28687
58.80000,48.99987,21.16750
59.00000,49.16674,21.35708
59.20000,49.33331,21.33812
59.40000,49.49987,21.30686
59.60000,49.66674,21.41324
59.80000,49.83330,21.60228
60.00000,49.99993,21.50384
60.20000,50.16674,21.67941
60.40000,50.33331,21.73575
60.60000,50.49993,21.48630
60.80000,50.66674,21.52368
61.00000,50.83337,21.72468
61.20000,50.99987,21.66480
61.40000,51.16674,21.65794
61.60000,51.33336,21.89226
61.80000,51.49987,22.02760
62.00000,51.66674,21.69347
62.20000,51.83337,22.03451
62.40000,51.99993,22.19283
62.60000,52.16668,21.97654
62.80000,52.33331,22.05131
63.00000,52.49986,22.03970
63.20000,52.66674,22.15858
63.40000,52.83337,22.15921
63.60000,52.99993,21.99345
63.80000,53.16674,22.14373
64.00000,53.33330,22.35693
64.20000,53.49993,22.23800
64.40000,53.66674,22.32145
64.60001,53.83337,22.39554
64.80000,53.99987,22.42700
65.00000,54.16675,22.48668
65.20000,54.33330,22.44454
65.40000,54.49993,22.50353
65.60001,54.66668,22.44444
65.80000,54.83337,22.60634
66.00000,54.99993,22.83556
66.20001,55.16674,22.70909
66.40000,55.33330,22.60879
66.60001,55.49993,22.63701
66.80000,55.66674,22.74579
67.00000,55.83324,22.84913
67.20001,55.99987,22.74937
67.40000,56.16674,22.62697
67.60001,56.33337,22.81444
67.80000,56.49993,22.82791
68.00000,56.66668,23.01720
68.20001,56.83336,23.01637
68.40000,56.99987,22.98461
68.60001,57.16674,23.24701
68.80000,57.33337,23.34129
69.00000,57.49993,23.09207
69.20001,57.66674,23.25632
69.40000,57.83324,23.42321
69.60001,57.99993,23.41586
69.80000,58.16680,23.43924
70.00000,58.33331,23.27219
70.20001,58.49987,23.53258
70.40000,58.66674,23.60290
70.60001,58.83330,23.54017
70.80000,58.99993,23.53199
71.00000,59.16674,23.75543
71.20001,59.33337,23.65077
71.40000,59.49981,23.67037
71.60001,59.66668,23.91718
71.80000,59.83337,23.79870
72.00000,59.99999,23.87960
72.20001,60.16674,23.86828
72.40000,60.33331,23.89415
72.60001,60.49993,23.96020
72.80000,60.66674,23.92179
73.00000,60.83337,23.96192
73.20001,60.99987,24.01582
73.40000,61.16681,24.10348
73.60001,61.33331,24.12014
73.80000,61.49987,24.19138
74.00000,61.66674,24.33701
74.20001,61.83343,24.52600
74.40000,61.99993,24.23828
74.60001,62.16668,24.39743
74.80000,62.33331,24.59259
75.00000,62.49993,24.30869
75.20001,62.66674,24.51532
75.40000,62.83330,24.50459
75.60001,62.99987,24.84964
75.80000,63.16674,24.49846
76.00000,63.33336,24.46725
76.20001,63.49993,24.75939
76.40000,63.66674,24.96024
76.60001,63.83331,24.72607
76.80000,63.99986,24.66879
77.00000,64.16667,24.90506
77.20001,64.33337,24.95607
77.40000,64.49993,24.99155
77.60001,64.66674,24.99900
77.80000,64.83330,24.88434
78.00000,64.99992,25.16947
78.20001,65.16674,25.12385
78.40000,65.33337,25.08681
78.60001,65.49993,25.23101
78.80000,65.66674,25.34954
79.00000,65.83330,25.31260
79.20001,65.99993,25.36620
79.40000,66.16674,25.28192
79.60001,66.33336,25.35101
79.80000,66.49987,25.55730
80.00000,66.66668,25.37566
80.20001,66.83336,25.68279
80.40000,66.99986,25.54177
80.60001,67.16674,25.66098
80.80000,67.33330,25.83621
81.00001,67.49993,25.62698
81.20001,67.66674,25.79652
81.40000,67.83336,25.67720
81.60001,67.99986,25.83072
81.80000,68.16674,25.68446
82.00001,68.33330,26.11325
82.20001,68.49993,26.20135
82.40000,68.66674,26.00540
82.60001,68.83337,26.18019
82.80000,68.99986,26.30906
83.00001,69.16674,26.40328
83.20001,69.33337,26.24109
83.40000,69.49992,26.14790
83.60001,69.66674,26.40074
83.80000,69.83336,26.39887
84.00001,69.99987,26.45052
84.20001,70.16668,26.42597
84.40000,70.33330,26.41352
84.60001,70.49993,26.55313
84.80000,70.66680,26.55920
85.00001,70.83336,26.45336
85.20001,70.99986,26.62540
85.40000,71.16674,26.61668
85.60001,71.33331,26.68797
85.80000,71.49993,26.86653
86.00001,71.66680,26.79974
86.20001,71.83337,26.98535
86.40000,71.99986,26.83331
86.60001,72.16674,27.12843
86.80000,72.33337,27.12755
87.00001,72.49992,27.21374
87.20001,72.66668,27.18718
87.40000,72.83330,27.02063
87.60001,72.99987,27.08713
87.80000,73.16674,27.29503
88.00001,73.33330,27.23300
88.20001,73.49993,27.42718
88.40000,73.66674,27.52847
88.60001,73.83336,27.39578
88.80000,73.99987,27.32443
89.00001,74.16674,27.56056
89.20001,74.33336,27.45639
89.40000,74.49993,27.72907
89.60001,74.66668,27.49525
89.80000,74.83331,27.77508
90.00001,74.99993,27.75117
90.20001,75.16674,27.83266
90.40000,75.33330,27.82286
90.60001,75.49986,27.79170
90.80000,75.66674,27.95168
91.00001,75.83336,28.12254
91.20001,75.99999,27.94217
91.40000,76.16674,27.87985
91.60001,76.33330,28.14376
91.80000,76.49980,28.25435
92.00001,76.66667,28.32192
92.20001,76.83343,28.13950
92.40000,76.99999,28.15091
92.60001,77.16674,28.29590
92.80000,77.33330,28.47289
93.00001,77.49987,28.50558
93.20001,77.66674,28.39797
93.40000,77.83336,28.64135
93.60001,77.99999,28.62930
93.80000,78.16680,28.58760
94.00001,78.33330,28.74856
94.20001,78.49980,28.70598
94.40000,78.66674,28.81070
94.60001,78.83336,28.69035
94.80000,78.99993,28.80423
95.00001,79.16667,28.86004
95.20001,79.33330,28.76454
95.40000,79.49986,29.09827
95.60001,79.66674,29.03374
95.80000,79.83330,29.13228
96.00001,79.99986,29.06118
96.20001,80.16674,29.12919
96.40000,80.33330,29.02566
96.60001,80.49992,29.40678
96.80000,80.66680,29.13169
97.00001,80.83330,29.28859
97.20001,80.99986,29.46989
97.40000,81.16674,29.33313
97.60001,81.33336,29.45387
97.80000,81.49993,29.54011
98.00001,81.66668,29.65241
98.20001,81.83336,29.52399
98.40000,81.99993,29.57206
98.60001,82.16674,29.62365
98.80000,82.33336,29.64649
99.00001,82.49993,29.74983
99.20001,82.66667,29.74262
99.40000,82.83329,29.92784
99.60001,82.99992,29.95229
99.80000,83.16674,29.97082
100.00001,83.33330,30.15496
100.20001,83.49986,30.09361
100.40000,83.66674,30.16128
100.60001,83.83336,30.14158
100.80000,83.99992,30.18828
101.00001,84.16673,30.25560
101.20001,84.33335,30.41838
101.40000,84.49992,30.41877
101.60001,84.66673,30.45283
101.80000,84.83324,30.36517
102.00001,84.99986,30.56249
102.20001,85.16674,30.44611
102.40000,85.33330,30.68955
102.60001,85.49985,30.69254
102.80000,85.66679,30.93891
103.00001,85.83331,30.69822
103.20001,85.99993,31.05621
103.40000,86.16667,30.60923
103.60001,86.33330,30.94307
103.80000,86.49986,31.02637
104.00001,86.66680,31.03935
104.20001,86.83336,31.08086
104.40000,86.99981,31.07728
104.60001,87.16667,31.13789
104.80000,87.33329,31.22051
105.00001,87.49993,31.20801
105.20001,87.66667,31.46938
105.40000,87.83337,31.38481
105.60001,87.99993,31.41852
105.80000,88.16673,31.43008
106.00001,88.33330,31.59800
106.20001,88.49998,31.54606
106.40000,88.66673,31.51848
106.60001,88.83336,31.65876
106.80000,88.99986,31.59232
107.00001,89.16673,31.77754
107.20001,89.33336,31.69845
107.40000,89.49986,31.82654
107.60001,89.66668,31.70629
107.80000,89.83336,31.85079
108.00001,89.99993,31.88578
108.20001,90.16680,32.06698
108.40000,90.33336,32.16846
108.60001,90.49992,32.15332
108.80000,90.66674,32.30865
109.00001,90.83330,32.28841
109.20001,90.99992,32.29498
109.40000,91.16674,32.25279
109.60001,91.33336,32.21060
109.80000,91.49986,32.41870
110.00001,91.66674,32.28493
110.20001,91.83336,32.54963
110.40000,91.99993,32.40576
110.60001,92.16674,32.79688
110.80000,92.33336,32.67409
111.00001,92.49986,32.62435
111.20001,92.66668,32.88572
111.40000,92.83336,32.76106
111.60001,92.99998,32.81653
111.80000,93.16674,33.07206
112.00001,93.33324,32.76008
112.20001,93.49986,33.04080
112.40000,93.66673,32.85412
112.60001,93.83336,33.06422
112.80000,93.99986,33.15615
113.00001,94.16673,33.36018
113.20001,94.33329,33.29306
113.40001,94.49986,33.31515
113.60001,94.66667,33.39272
113.80000,94.83336,33.46617
114.00001,94.99992,33.48087
114.20001,95.16673,33.53668
114.40001,95.33330,33.54134
114.60001,95.49987,33.54183
114.80000,95.66673,33.61582
115.00001,95.83335,33.67545
115.20001,95.99992,33.72999
115.40001,96.16673,33.76919
115.60001,96.33336,33.72229
115.80000,96.49992,33.89413
116.00001,96.66674,33.82666
116.20001,96.83336,33.80182
116.40001,96.99985,34.11875
116.60001,97.16667,34.14923
116.80000,97.33336,34.19627
117.00001,97.49993,34.29236
117.20001,97.66674,34.12463
117.40001,97.83329,34.29892
117.60001,97.99986,34.21582
117.80000,98.16674,34.42828
118.00001,98.33336,34.33283
118.20001,98.49992,34.49580
118.40001,98.66673,34.58807
118.60001,98.83329,34.51584
118.80000,98.99992,34.58415
119.00001,99.16673,34.63977
119.20001,99.33342,34.87345
119.40001,99.49992,34.70881
119.60001,99.66668,35.07430
119.80000,99.83336,34.87996
120.00001,99.99992,34.94695
120.20001,100.16673,34.83003
120.40001,100.33336,35.09983
120.60001,100.49992,35.12335
120.80000,100.66673,35.10556
121.00001,100.83342,35.29445
121.20001,100.99986,35.16108
121.40001,101.16674,35.30185
121.60001,101.33336,35.24442
121.80000,101.49992,35.54719
122.00001,101.66674,35.56018
122.20001,101.83336,35.48614
122.40001,101.99992,35.35472
122.60001,102.16674,35.47928
122.80000,102.33330,35.61594
123.00001,102.49992,35.68587
123.20001,102.66673,35.73119
123.40001,102.83336,35.81366
123.60001,102.99992,35.79915
123.80000,103.16667,35.81679
124.00001,103.33324,35.97756
124.20001,103.49993,36.01068
124.40001,103.66680,36.10016
124.60001,103.83330,36.16195
124.80000,103.99986,36.29616
125.00001,104.16668,36.21472
125.20001,104.33330,36.16861
125.40001,104.49992,36.34276
125.60001,104.66673,36.51607
125.80000,104.83336,36.32551
126.00001,104.99992,36.37696
126.20001,105.16667,36.57374
126.40001,105.33337,36.52896
126.60001,105.49992,36.53537
126.80000,105.66674,36.65376
127.00001,105.83330,36.60206
127.20001,105.99992,36.67532
127.40001,106.16673,36.72280
127.60001,106.33335,36.65155
127.80000,106.49987,36.89792
128.00000,106.66673,36.74759
128.20002,106.83335,36.99921
128.40001,106.99986,36.94384
128.60001,107.16673,37.04845
128.80000,107.33336,37.07168
129.00000,107.49992,37.04669
129.20002,107.66674,37.16679
129.40001,107.83330,37.18658
129.60001,107.99993,37.16875
129.80000,108.16674,37.35465
130.00000,108.33330,37.33564
130.20002,108.49993,37.33750
130.40001,108.66667,37.34324
130.60001,108.83329,37.34760
130.80000,108.99992,37.33104
131.00000,109.16674,37.63875
131.20002,109.33336,37.66502
131.40002,109.49986,37.59362
131.60000,109.66667,37.86891
131.80000,109.83342,37.83710
132.00000,109.99999,37.82187
132.20002,110.16673,37.79663
132.40002,110.33324,37.82113
132.60000,110.49992,37.76404
132.80000,110.66673,38.04775
133.00000,110.83336,37.98528
133.20002,110.99992,38.07377
133.40002,111.16673,38.21004
133.60000,111.33330,38.25527
133.80000,111.49986,38.15634
134.00000,111.66673,38.18074
134.20002,111.83330,38.14928
134.40002,111.99992,38.29721
134.60000,112.16667,38.34572
134.80000,112.33330,38.47038
135.00000,112.49992,38.54241
135.20002,112.66674,38.70896
135.40002,112.83336,38.58318
135.60000,112.99992,38.76913
135.80000,113.16674,38.70450
136.00000,113.33330,38.63066
136.20002,113.49992,38.65947
136.40002,113.66680,38.79780
136.60000,113.83330,39.00075
136.80000,113.99986,38.81936
137.00000,114.16674,39.12835
137.20002,114.33336,38.98659
137.40002,114.49993,39.15348
137.60000,114.66667,39.18906
137.80000,114.83336,39.20851
138.00000,114.99993,39.18881
138.20002,115.16673,39.50266
138.40002,115.33336,39.50585
138.60000,115.49998,39.42303
138.80000,115.66667,39.49727
139.00000,115.83329,39.41255
139.20002,115.99992,39.45390
139.40002,116.16673,39.74516
139.60000,116.33337,39.46762
139.80000,116.49992,39.70861
140.00000,116.66667,39.80881
140.20002,116.83336,39.79215
140.40002,116.99999,39.75153
140.60000,117.16673,39.94322
140.80000,117.33330,39.66220
141.00000,117.49987,39.96595
141.20002,117.66667,40.00657
141.40002,117.83335,40.11374
141.60000,117.99992,40.22967
141.80000,118.16673,40.03156
142.00000,118.33330,40.13456
142.20002,118.49992,40.06072
142.40002,118.66674,40.18278
142.60000,118.83330,40.40578
142.80000,118.99993,40.54915
143.00000,119.16674,40.25299
143.20002,119.33336,40.37461
143.40002,119.49993,40.60325
143.60000,119.66674,40.63451
143.80000,119.83336,40.63333
144.00000,119.99992,40.58737
144.20002,120.16674,40.76950
144.40002,120.33329,40.59457
144.60000,120.49992,40.70227
144.80000,120.66673,40.77587
145.00000,120.83329,40.73363
145.20002,120.99986,40.92169
145.40002,121.16673,40.92601
145.60000,121.33330,40.93571
145.80000,121.49992,41.17076
146.00000,121.66673,40.99456
146.20002,121.83330,40.94522
146.40002,121.99992,40.89680
146.60000,122.16668,41.08947
146.80000,122.33330,41.18845
147.00000,122.49999,41.34603
147.20002,122.66673,41.34809
147.40002,122.83336,41.18982
147.60000,122.99986,40.91180
147.80000,123.16674,35.56180
148.00000,123.33342,-0.11514
148.20002,123.49992,0.10928
148.40002,123.66674,0.02804
148.60000,123.83330,0.28436
148.80000,123.99986,0.23898
149.00000,124.16674,0.19042
149.20002,124.33336,0.24996
149.40002,124.49986,-0.00141
149.60000,124.66667,0.21909
149.80000,124.83330,-0.17085
150.00000,124.99992,0.33282
150.16802,125.14010,0.36379