File: EPR/EPR/RDSO EPR Tensile 50.is_tens_RawData/Specimen_RawData_9.csv
Time,Extension,Load
(sec),(mm),(N)
0.00000,0.00000,-0.00067
0.20000,0.16469,0.53750
0.40000,0.33300,1.02843
0.60000,0.49987,1.44914
0.80000,0.66669,1.80297
1.00000,0.83337,1.93845
1.20000,0.99987,2.19467
1.40000,1.16675,2.55791
1.60000,1.33331,2.87307
1.80000,1.49994,3.02311
2.00000,1.66669,3.19099
2.20000,1.83337,3.59685
2.40000,1.99994,3.61111
2.60000,2.16675,3.79976
2.80000,2.33331,4.10630
3.00000,2.49994,4.23983
3.20000,2.66675,4.38531
3.40000,2.83337,4.38212
3.60000,2.99994,4.69273
3.80000,3.16669,5.08209
4.00000,3.33331,5.06498
4.20000,3.49994,5.27985
4.40000,3.66669,5.31895
4.60000,3.83331,5.38716
4.80000,3.99994,5.65573
5.00000,4.16669,5.84443
5.20000,4.33337,6.23603
5.40000,4.49994,6.15195
5.60000,4.66675,6.25088
5.80000,4.83325,6.28523
6.00000,4.99994,6.38739
6.20000,5.16675,6.77189
6.40000,5.33337,6.86592
6.60000,5.49994,6.70913
6.80000,5.66675,7.03493
7.00000,5.83325,7.22534
7.20000,5.99987,7.13895
7.40000,6.16675,7.50679
7.60000,6.33337,7.51963
7.80000,6.49994,7.58549
8.00000,6.66669,7.67320
8.20000,6.83325,7.81471
8.40000,6.99987,8.02580
8.60000,7.16675,7.99586
8.80000,7.33331,8.08328
9.00000,7.49994,8.28290
9.20000,7.66675,8.46592
9.40000,7.83331,8.43230
9.60000,7.99987,8.46347
9.80000,8.16681,8.56661
10.00000,8.33337,8.81499
10.20000,8.49987,8.98571
10.40000,8.66669,8.84905
10.60000,8.83331,8.88560
10.80000,8.99994,9.11526
11.00000,9.16675,9.19293
11.20000,9.33331,9.22042
11.40000,9.49994,9.24516
11.60000,9.66675,9.24477
11.80000,9.83337,9.40608
12.00000,9.99994,9.47982
12.20000,10.16669,9.50613
12.40000,10.33331,9.62021
12.60000,10.49987,9.91896
12.80000,10.66675,9.79881
13.00000,10.83337,9.92557
13.20000,10.99994,10.15798
13.40000,11.16669,9.92734
13.60000,11.33331,10.06606
13.80000,11.49994,10.19012
14.00000,11.66675,10.19909
14.20000,11.83331,10.44164
14.40000,11.99994,10.21114
14.60000,12.16669,10.36442
14.80000,12.33331,10.59153
15.00000,12.50000,10.56634
15.20000,12.66675,10.62353
15.40000,12.83331,10.92390
15.60000,12.99987,10.76852
15.80000,13.16669,10.96457
16.00000,13.33337,10.95967
16.20000,13.49994,11.00857
16.40000,13.66668,11.17968
16.60000,13.83331,11.13273
16.80000,13.99994,11.12739
17.00000,14.16675,11.23656
17.20000,14.33331,11.32702
17.40000,14.49994,11.55261
17.60000,14.66675,11.52674
17.80000,14.83331,11.45241
18.00000,14.99987,11.46098
18.20000,15.16681,11.69657
18.40000,15.33331,11.64591
18.60000,15.49987,11.52821
18.80000,15.66668,11.97818
19.00000,15.83337,11.55653
19.20000,15.99994,11.96676
19.40000,16.16675,11.81079
19.60000,16.33331,12.03585
19.80000,16.49993,12.03639
20.00000,16.66675,12.02816
20.20000,16.83337,12.05207
20.40000,16.99987,12.05349
20.60000,17.16675,12.37733
20.80000,17.33331,12.34577
21.00000,17.49987,12.24606
21.20000,17.66675,12.41006
21.40000,17.83331,12.49919
21.60000,17.99993,12.32181
21.80000,18.16669,12.41775
22.00000,18.33331,12.43010
22.20000,18.49987,12.64952
22.40000,18.66675,12.59435
22.60000,18.83331,12.68304
22.80000,19.00000,12.68020
23.00000,19.16668,12.74801
23.20000,19.33331,12.73219
23.40000,19.49994,12.59366
23.60000,19.66681,12.65197
23.80000,19.83331,12.84685
24.00000,19.99993,12.68387
24.20000,20.16668,12.92064
24.40000,20.33331,13.14952
24.60000,20.49993,12.84072
24.80000,20.66675,13.18676
25.00000,20.83337,13.06313
25.20000,20.99987,13.11894
25.40000,21.16668,13.18328
25.60000,21.33325,13.10052
25.80000,21.50000,13.17240
26.00000,21.66675,13.26281
26.20000,21.83331,13.62051
26.40000,21.99987,13.28427
26.60000,22.16675,13.21474
26.80000,22.33331,13.45557
27.00000,22.49993,13.45283
27.20000,22.66675,13.47081
27.40000,22.83331,13.90696
27.60000,22.99987,13.62335
27.80000,23.16675,13.55372
28.00000,23.33337,13.68313
28.20000,23.49993,13.65226
28.40000,23.66669,13.90686
28.60000,23.83331,13.79151
28.80000,23.99993,13.68857
29.00000,24.16675,13.65260
29.20000,24.33331,14.01147
29.40000,24.49993,13.78010
29.60000,24.66675,14.05856
29.80000,24.83325,14.03911
30.00000,24.99993,13.93450
30.20000,25.16675,14.11129
30.40000,25.33331,14.02872
30.60000,25.49975,14.32419
30.80000,25.66675,14.07223
31.00000,25.83337,14.34443
31.20000,25.99993,14.10918
31.40000,26.16675,14.15014
31.60000,26.33331,14.48633
31.80000,26.49993,14.40141
32.00000,26.66681,14.38838
32.20000,26.83331,14.53651
32.40000,27.00000,14.50730
32.60000,27.16674,14.46619
32.80000,27.33325,14.40931
33.00000,27.49987,14.45664
33.20000,27.66675,14.57718
33.40000,27.83337,14.79170
33.60000,27.99987,14.71203
33.80000,28.16668,14.70771
34.00000,28.33331,14.76622
34.20000,28.49993,14.89793
34.40000,28.66668,14.60349
34.60000,28.83331,14.80268
34.80000,28.99993,14.80057
35.00000,29.16675,14.94698
35.20000,29.33331,14.86941
35.40000,29.50000,14.89773
35.60000,29.66675,14.95296
35.80000,29.83331,15.02641
36.00000,29.99993,14.92248
36.20000,30.16675,14.93106
36.40000,30.33337,14.98951
36.60000,30.49993,15.16278
36.80000,30.66675,15.00926
37.00000,30.83331,15.37151
37.20000,30.99987,15.21834
37.40000,31.16668,15.25676
37.60000,31.33331,15.32722
37.80000,31.49993,15.31188
38.00000,31.66668,15.21320
38.20000,31.83324,15.52645
38.40000,31.99993,15.48240
38.60000,32.16681,15.35637
38.80000,32.33331,15.38700
39.00000,32.49987,15.49034
39.20000,32.66674,15.76645
39.40000,32.83331,15.58986
39.60000,33.00000,15.76253
39.80000,33.16681,15.82903
40.00000,33.33325,15.72211
40.20000,33.49987,15.86754
40.40000,33.66675,15.84819
40.60000,33.83337,15.80732
40.80000,33.99987,15.92649
41.00000,34.16675,16.01037
41.20000,34.33331,16.01983
41.40000,34.49993,15.91326
41.60000,34.66674,15.99430
41.80000,34.83331,16.16840
42.00000,34.99993,16.11264
42.20000,35.16675,16.14645
42.40000,35.33331,16.10695
42.60000,35.49987,16.25797
42.80000,35.66675,16.28414
43.00000,35.83337,16.33960
43.20000,35.99987,16.03443
43.40000,36.16675,16.40835
43.60000,36.33331,16.35156
43.80000,36.49993,16.59220
44.00000,36.66674,16.41854
44.20000,36.83331,16.42653
44.40000,36.99993,16.56344
44.60000,37.16674,16.54246
44.80000,37.33331,16.64585
45.00000,37.49987,16.65198
45.20000,37.66681,16.84141
45.40000,37.83331,16.76414
45.60000,37.99987,16.90198
45.80000,38.16674,16.92251
46.00000,38.33337,16.54923
46.20000,38.49993,16.78384
46.40000,38.66674,16.83847
46.60000,38.83325,16.77619
46.80000,38.99993,16.85989
47.00000,39.16674,16.84788
47.20000,39.33337,17.20367
47.40000,39.49993,17.02452
47.60000,39.66675,17.13100
47.80000,39.83324,17.12586
48.00000,39.99987,17.18818
48.20000,40.16674,17.32470
48.40000,40.33337,17.34719
48.60000,40.49993,17.26213
48.80000,40.66675,17.20230
49.00000,40.83330,17.33891
49.20000,40.99993,17.71645
49.40000,41.16674,17.63379
49.60000,41.33337,17.53510
49.80000,41.49993,17.54588
50.00000,41.66668,17.68289
50.20000,41.83318,17.60890
50.40000,41.99993,17.69386
50.60000,42.16681,17.71890
50.80000,42.33331,17.68107
51.00000,42.49981,18.04406
51.20000,42.66674,17.81847
51.40000,42.83343,17.90539
51.60000,42.99993,17.94763
51.80000,43.16675,18.20988
52.00000,43.33331,17.98174
52.20000,43.49993,18.06357
52.40000,43.66674,18.26432
52.60000,43.83337,17.95836
52.80000,43.99993,18.00903
53.00000,44.16674,18.21155
53.20000,44.33331,18.22311
53.40000,44.49993,18.23747
53.60000,44.66681,18.38471
53.80000,44.83331,18.40132
54.00000,44.99993,18.58154
54.20000,45.16668,18.26628
54.40000,45.33330,18.42185
54.60000,45.49987,18.53396
54.80000,45.66674,18.68552
55.00000,45.83331,18.63956
55.20000,45.99987,18.52642
55.40000,46.16668,18.84737
55.60000,46.33330,18.84879
55.80000,46.49993,18.89936
56.00000,46.66674,18.77911
56.20000,46.83331,18.96110
56.40000,46.99993,19.05567
56.60000,47.16674,18.85124
56.80000,47.33331,18.93576
57.00000,47.49993,19.03509
57.20000,47.66674,19.06071
57.40000,47.83337,19.04837
57.60000,47.99987,19.05758
57.80000,48.16668,19.11427
58.00000,48.33330,19.16797
58.20000,48.49993,19.27563
58.40000,48.66668,19.33389
58.60000,48.83330,19.53650
58.80000,48.99993,19.22320
59.00000,49.16674,19.44223
59.20000,49.33331,19.57266
59.40000,49.49993,19.48099
59.60000,49.66674,19.77312
59.80000,49.83330,19.60525
60.00000,49.99999,19.69350
60.20000,50.16674,19.67189
60.40000,50.33324,19.84491
60.60000,50.49987,19.92541
60.80000,50.66674,20.03512
61.00000,50.83337,20.07545
61.20000,50.99993,19.99004
61.40000,51.16674,19.87519
61.60000,51.33331,20.02449
61.80000,51.49987,20.06080
62.00000,51.66674,19.94619
62.20000,51.83330,20.20016
62.40000,51.99999,20.24283
62.60000,52.16674,20.18756
62.80000,52.33324,20.21961
63.00000,52.49986,20.21025
63.20000,52.66680,20.43996
63.40000,52.83337,20.54487
63.60000,52.99993,20.44187
63.80000,53.16668,20.54066
64.00000,53.33337,20.60171
64.20000,53.49993,20.57388
64.40000,53.66674,20.58691
64.60001,53.83337,20.80462
64.80000,53.99993,20.96083
65.00000,54.16675,20.67398
65.20000,54.33330,21.01012
65.40000,54.49993,20.81594
65.60001,54.66674,20.99802
65.80000,54.83331,20.88365
66.00000,54.99987,20.97244
66.20001,55.16674,21.16800
66.40000,55.33330,21.10518
66.60001,55.49993,21.15938
66.80000,55.66674,21.22861
67.00000,55.83331,21.26448
67.20001,55.99987,21.25096
67.40000,56.16674,21.38752
67.60001,56.33330,21.46758
67.80000,56.49993,21.20887
68.00000,56.66662,21.48498
68.20001,56.83331,21.43804
68.40000,56.99993,21.49948
68.60001,57.16681,21.46979
68.80000,57.33330,21.63340
69.00000,57.49993,21.85429
69.20001,57.66668,21.70524
69.40000,57.83331,21.87125
69.60001,57.99986,21.81524
69.80000,58.16668,21.83028
70.00000,58.33337,21.81024
70.20001,58.49993,22.08062
70.40000,58.66668,21.91432
70.60001,58.83330,21.98262
70.80000,58.99999,22.21567
71.00000,59.16681,22.05710
71.20001,59.33330,22.24551
71.40000,59.49987,22.38334
71.60001,59.66680,22.29549
71.80000,59.83330,22.26716
72.00000,59.99993,22.51726
72.20001,60.16674,22.50310
72.40000,60.33331,22.37227
72.60001,60.49987,22.67034
72.80000,60.66674,22.57753
73.00000,60.83330,22.62437
73.20001,60.99993,22.96438
73.40000,61.16668,22.72512
73.60001,61.33324,22.68298
73.80000,61.49993,22.75780
74.00000,61.66680,22.86707
74.20001,61.83330,22.90186
74.40000,61.99993,22.88167
74.60001,62.16674,22.99075
74.80000,62.33331,23.02377
75.00000,62.49993,23.03416
75.20001,62.66674,23.12814
75.40000,62.83336,23.19547
75.60001,62.99987,23.30709
75.80000,63.16674,23.19297
76.00000,63.33336,23.24065
76.20001,63.49993,23.41082
76.40000,63.66668,23.33899
76.60001,63.83331,23.57473
76.80000,63.99993,23.38769
77.00000,64.16680,23.56101
77.20001,64.33330,23.59874
77.40000,64.49993,23.80831
77.60001,64.66674,23.74294
77.80000,64.83330,23.62750
78.00000,64.99987,23.79179
78.20001,65.16674,23.96060
78.40000,65.33337,23.86637
78.60001,65.49993,23.93747
78.80000,65.66674,24.01837
79.00000,65.83330,23.95496
79.20001,65.99999,24.17767
79.40000,66.16668,24.10946
79.60001,66.33336,24.12534
79.80000,66.49987,24.30546
80.00000,66.66668,24.41194
80.20001,66.83331,24.49367
80.40000,66.99999,24.52013
80.60001,67.16674,24.73387
80.80000,67.33330,24.51905
81.00001,67.49993,24.45932
81.20001,67.66680,24.65145
81.40000,67.83336,24.69065
81.60001,67.99999,24.70564
81.80000,68.16674,24.82692
82.00001,68.33337,24.80467
82.20001,68.49987,24.79997
82.40000,68.66667,24.80281
82.60001,68.83330,25.02429
82.80000,68.99992,25.11077
83.00001,69.16674,24.98224
83.20001,69.33330,25.11513
83.40000,69.49992,24.96573
83.60001,69.66674,25.18800
83.80000,69.83330,25.22671
84.00001,69.99987,25.10759
84.20001,70.16674,25.23058
84.40000,70.33330,25.33010
84.60001,70.49993,25.40683
84.80000,70.66674,25.39943
85.00001,70.83336,25.66996
85.20001,70.99986,25.56167
85.40000,71.16674,25.75101
85.60001,71.33336,25.66060
85.80000,71.49993,25.87032
86.00001,71.66674,25.84332
86.20001,71.83324,25.96342
86.40000,71.99993,25.80593
86.60001,72.16674,26.10326
86.80000,72.33337,26.12188
87.00001,72.49986,26.16726
87.20001,72.66680,26.28794
87.40000,72.83330,26.21101
87.60001,72.99987,26.35792
87.80000,73.16674,26.31896
88.00001,73.33336,26.10429
88.20001,73.49993,26.36551
88.40000,73.66668,26.37840
88.60001,73.83330,26.58929
88.80000,73.99999,26.45254
89.00001,74.16680,26.42598
89.20001,74.33336,26.51055
89.40000,74.49993,26.74982
89.60001,74.66674,26.72787
89.80000,74.83331,26.68715
90.00001,74.99993,26.62791
90.20001,75.16667,26.88922
90.40000,75.33330,26.75040
90.60001,75.49993,26.96409
90.80000,75.66668,27.14828
91.00001,75.83336,27.04441
91.20001,75.99992,27.23070
91.40000,76.16674,27.15902
91.60001,76.33330,27.34340
91.80000,76.49987,27.30807
92.00001,76.66674,27.46193
92.20001,76.83337,27.22477
92.40000,76.99993,27.57615
92.60001,77.16674,27.45287
92.80000,77.33324,27.45164
93.00001,77.49987,27.54886
93.20001,77.66680,27.62363
93.40000,77.83336,27.78004
93.60001,77.99986,27.70727
93.80000,78.16668,27.80322
94.00001,78.33330,28.02127
94.20001,78.49992,27.89132
94.40000,78.66674,27.95894
94.60001,78.83330,28.02597
94.80000,78.99993,28.03768
95.00001,79.16674,28.04322
95.20001,79.33330,28.18292
95.40000,79.49992,28.13700
95.60001,79.66674,28.20325
95.80000,79.83330,28.33516
96.00001,79.99986,28.31105
96.20001,80.16674,28.38239
96.40000,80.33343,28.52895
96.60001,80.49986,28.52214
96.80000,80.66674,28.58663
97.00001,80.83336,28.50739
97.20001,80.99993,28.57555
97.40000,81.16674,28.91341
97.60001,81.33336,28.76699
97.80000,81.49993,28.80958
98.00001,81.66674,28.70094
98.20001,81.83330,28.98735
98.40000,81.99993,28.90880
98.60001,82.16674,29.08618
98.80000,82.33336,29.01047
99.00001,82.49993,29.06447
99.20001,82.66673,29.19996
99.40000,82.83337,29.38787
99.60001,82.99992,29.49293
99.80000,83.16674,29.33363
100.00001,83.33330,29.36352
100.20001,83.49992,29.39860
100.40000,83.66668,29.45657
100.60001,83.83336,29.46118
100.80000,83.99992,29.39027
101.00001,84.16680,29.49337
101.20001,84.33324,29.65473
101.40000,84.49992,29.82412
101.60001,84.66673,29.87635
101.80000,84.83330,29.93466
102.00001,84.99992,29.79148
102.20001,85.16674,30.01933
102.40000,85.33330,30.03139
102.60001,85.49993,29.98959
102.80000,85.66667,30.01977
103.00001,85.83336,30.19279
103.20001,85.99993,30.29084
103.40000,86.16667,30.26286
103.60001,86.33330,30.44720
103.80000,86.49993,30.38786
104.00001,86.66674,30.58313
104.20001,86.83329,30.39212
104.40000,86.99986,30.34239
104.60001,87.16674,30.63967
104.80000,87.33329,30.81529
105.00001,87.49993,30.62561
105.20001,87.66674,30.79549
105.40000,87.83330,30.64594
105.60001,87.99986,30.94597
105.80000,88.16668,30.84076
106.00001,88.33336,30.90476
106.20001,88.49992,31.01084
106.40000,88.66673,31.01609
106.60001,88.83336,31.06009
106.80000,88.99992,31.20341
107.00001,89.16673,31.31876
107.20001,89.33330,31.23590
107.40000,89.49992,31.25393
107.60001,89.66674,31.47683
107.80000,89.83330,31.63378
108.00001,89.99986,31.64103
108.20001,90.16680,31.53436
108.40000,90.33336,31.39633
108.60001,90.49992,31.57699
108.80000,90.66661,31.77005
109.00001,90.83330,31.66176
109.20001,90.99992,31.84414
109.40000,91.16674,31.81601
109.60001,91.33330,31.90122
109.80000,91.49992,32.00128
110.00001,91.66674,32.11398
110.20001,91.83330,32.07679
110.40000,91.99993,32.19841
110.60001,92.16674,32.07870
110.80000,92.33330,32.14617
111.00001,92.49986,32.26838
111.20001,92.66674,32.09012
111.40000,92.83336,32.21830
111.60001,92.99998,32.54518
111.80000,93.16668,32.47780
112.00001,93.33330,32.26882
112.20001,93.49986,32.63357
112.40000,93.66673,32.66175
112.60001,93.83336,32.57080
112.80000,93.99992,32.63681
113.00001,94.16673,32.68174
113.20001,94.33329,32.89886
113.40001,94.49992,32.89822
113.60001,94.66680,32.90248
113.80000,94.83330,32.99935
114.00001,94.99992,33.11926
114.20001,95.16673,33.03532
114.40001,95.33330,33.24896
114.60001,95.49987,33.13038
114.80000,95.66673,33.08741
115.00001,95.83330,33.32780
115.20001,95.99986,33.29605
115.40001,96.16673,33.34539
115.60001,96.33330,33.56329
115.80000,96.49992,33.58363
116.00001,96.66667,33.45353
116.20001,96.83323,33.71578
116.40001,96.99985,33.68536
116.60001,97.16674,33.76468
116.80000,97.33336,33.70878
117.00001,97.49993,33.81560
117.20001,97.66674,34.00616
117.40001,97.83336,33.87043
117.60001,97.99986,34.00699
117.80000,98.16674,33.98092
118.00001,98.33342,34.03286
118.20001,98.49992,34.14556
118.40001,98.66673,34.06800
118.60001,98.83337,34.13429
118.80000,98.99992,34.30613
119.00001,99.16667,34.48346
119.20001,99.33330,34.39791
119.40001,99.49986,34.27379
119.60001,99.66680,34.48876
119.80000,99.83330,34.57088
120.00001,99.99992,34.63757
120.20001,100.16673,34.76688
120.40001,100.33330,34.80642
120.60001,100.49986,34.76717
120.80000,100.66673,34.68093
121.00001,100.83336,34.70896
121.20001,100.99999,34.89688
121.40001,101.16667,34.94406
121.60001,101.33330,34.86811
121.80000,101.49992,34.90373
122.00001,101.66674,34.99796
122.20001,101.83323,35.23796
122.40001,101.99992,35.36282
122.60001,102.16667,35.28824
122.80000,102.33330,35.12384
123.00001,102.49986,35.39672
123.20001,102.66673,35.62202
123.40001,102.83336,35.44028
123.60001,102.99992,35.57508
123.80000,103.16667,35.62717
124.00001,103.33336,35.52314
124.20001,103.49993,35.87016
124.40001,103.66674,35.76368
124.60001,103.83336,35.64750
124.80000,103.99993,36.07885
125.00001,104.16673,36.05430
125.20001,104.33324,35.93851
125.40001,104.49992,35.90240
125.60001,104.66680,36.08620
125.80000,104.83329,36.21551
126.00001,104.99986,36.18562
126.20001,105.16673,36.30876
126.40001,105.33329,36.01299
126.60001,105.49992,36.17234
126.80000,105.66667,36.52960
127.00001,105.83330,36.52936
127.20001,105.99986,36.32708
127.40001,106.16673,36.58139
127.60001,106.33330,36.76323
127.80000,106.49992,36.51176
128.00000,106.66673,36.65857
128.20002,106.83324,36.87250
128.40001,106.99992,36.75465
128.60001,107.16680,36.69870
128.80000,107.33336,36.91680
129.00000,107.49985,36.85114
129.20002,107.66667,36.95590
129.40001,107.83330,36.92797
129.60001,107.99993,37.07222
129.80000,108.16674,37.02955
130.00000,108.33336,37.23133
130.20002,108.49986,37.14999
130.40001,108.66667,37.31757
130.60001,108.83329,37.14705
130.80000,108.99998,37.28895
131.00000,109.16680,37.51053
131.20002,109.33336,37.60216
131.40002,109.49992,37.57256
131.60000,109.66667,37.66380
131.80000,109.83337,37.65081
132.00000,109.99992,37.75058
132.20002,110.16673,37.68046
132.40002,110.33324,37.89175
132.60000,110.49986,37.79090
132.80000,110.66673,37.83157
133.00000,110.83336,37.95804
133.20002,110.99986,38.06334
133.40002,111.16668,37.92536
133.60000,111.33323,38.03017
133.80000,111.49992,38.25650
134.00000,111.66673,38.09098
134.20002,111.83336,38.39870
134.40002,111.99986,38.35181
134.60000,112.16674,38.35984
134.80000,112.33330,38.42403
135.00000,112.49992,38.68795
135.20002,112.66680,38.50821
135.40002,112.83336,38.44294
135.60000,112.99986,38.57123
135.80000,113.16667,38.75743
136.00000,113.33336,38.74366
136.20002,113.49992,38.60347
136.40002,113.66673,38.78531
136.60000,113.83324,38.98611
136.80000,113.99992,39.00105
137.00000,114.16674,38.96068
137.20002,114.33329,39.01693
137.40002,114.49986,39.14977
137.60000,114.66674,39.09391
137.80000,114.83330,39.22591
138.00000,114.99986,39.30578
138.20002,115.16673,39.34342
138.40002,115.33336,39.30005
138.60000,115.49986,39.36797
138.80000,115.66673,39.49825
139.00000,115.83329,39.53505
139.20002,115.99992,39.55671
139.40002,116.16667,39.53814
139.60000,116.33329,39.59327
139.80000,116.49986,39.64692
140.00000,116.66667,39.74218
140.20002,116.83330,39.61257
140.40002,116.99992,39.89917
140.60000,117.16673,39.82910
140.80000,117.33330,39.84601
141.00000,117.49992,39.98409
141.20002,117.66673,40.09826
141.40002,117.83343,39.89731
141.60000,117.99992,40.01971
141.80000,118.16661,40.16054
142.00000,118.33330,40.35301
142.20002,118.49992,40.22585
142.40002,118.66674,40.24496
142.60000,118.83330,40.28936
142.80000,118.99993,40.63314
143.00000,119.16674,40.56768
143.20002,119.33330,40.63696
143.40002,119.49986,40.56175
143.60000,119.66679,40.59590
143.80000,119.83329,40.67509
144.00000,119.99986,40.64975
144.20002,120.16667,40.78377
144.40002,120.33336,40.87775
144.60000,120.49992,41.08031
144.80000,120.66667,40.83977
145.00000,120.83337,40.92998
145.20002,120.99992,41.09619
145.40002,121.16667,41.03729
145.60000,121.33336,41.32664
145.80000,121.49992,41.24520
146.00000,121.66673,41.21139
146.20002,121.83324,41.22050
146.40002,121.99992,41.28479
146.60000,122.16673,41.41390
146.80000,122.33330,41.53126
147.00000,122.49992,41.58050
147.20002,122.66673,41.41224
147.40002,122.83330,41.57952
147.60000,122.99992,41.72735
147.80000,123.16674,41.62421
148.00000,123.33336,41.79458
148.20002,123.49992,41.68874
148.40002,123.66667,41.74034
148.60000,123.83330,41.77572
148.80000,123.99992,41.93154
149.00000,124.16679,42.16738
149.20002,124.33330,42.09442
149.40002,124.49986,42.13548
149.60000,124.66667,42.09770
149.80000,124.83330,42.25651
150.00000,124.99986,42.28228
150.20002,125.16673,42.48078
150.40002,125.33336,42.41541
150.60000,125.49992,42.44721
150.80000,125.66666,42.69623
151.00000,125.83335,42.45373
151.20002,125.99992,42.44903
151.40002,126.16673,42.85220
151.60000,126.33336,42.64571
151.80000,126.49992,42.73122
152.00000,126.66667,42.78953
152.20002,126.83335,42.87140
152.40002,126.99998,42.81525
152.60000,127.16673,43.18231
152.80000,127.33328,42.89439
153.00000,127.49985,43.10376
153.20002,127.66679,42.92378
153.40002,127.83336,42.92986
153.60000,127.99992,43.20284
153.80000,128.16667,43.12846
154.00000,128.33335,43.14536
154.20002,128.49991,43.23851
154.40002,128.66673,43.06907
154.60000,128.83330,43.42020
154.80000,128.99998,43.30780
155.00000,129.16666,43.49272
155.20002,129.33329,43.60038
155.40002,129.49991,43.73865
155.60000,129.66673,43.51835
155.80000,129.83330,43.70224
156.00000,129.99992,43.77075
156.20002,130.16673,44.10145
156.40002,130.33335,43.87757
156.60000,130.49997,44.04461
156.80000,130.66666,43.74306
157.00000,130.83328,43.89173
157.20002,130.99991,44.12271
157.40002,131.16673,44.05284
157.60000,131.33324,44.11708
157.80000,131.49992,44.12600
158.00000,131.66673,44.05916
158.20002,131.83328,44.25972
158.40002,131.99992,44.36036
158.60000,132.16673,44.35081
158.80000,132.33329,44.48977
159.00000,132.49992,44.38545
159.20002,132.66672,44.32876
159.40002,132.83329,44.59115
159.60000,132.99986,44.54215
159.80000,133.16673,44.48958
160.00000,133.33336,44.71777
160.20002,133.49992,44.85051
160.40002,133.66672,44.65706
160.60000,133.83329,44.87667
160.80000,133.99991,44.78848
161.00002,134.16673,44.83649
161.20002,134.33329,45.02622
161.40002,134.49985,45.05758
161.60000,134.66673,45.15161
161.80000,134.83335,45.07718
162.00002,134.99992,45.19552
162.20002,135.16666,45.45414
162.40002,135.33329,45.22820
162.60000,135.49991,45.30376
162.80000,135.66673,45.40083
163.00002,135.83335,45.48716
163.20002,135.99998,45.57649
163.40002,136.16673,45.57277
163.60000,136.33335,45.39495
163.80000,136.49992,45.65984
164.00002,136.66679,45.56742
164.20002,136.83329,45.52676
164.40002,136.99985,45.69443
164.60000,137.16673,45.79596
164.80000,137.33329,45.63162
165.00002,137.49997,45.90136
165.20002,137.66673,46.01803
165.40002,137.83336,45.98344
165.60000,137.99985,45.99730
165.80000,138.16667,46.17042
166.00002,138.33336,46.12592
166.20002,138.49998,46.10182
166.40002,138.66673,46.18899
166.60000,138.83329,46.21829
166.80000,138.99991,46.32781
167.00002,139.16673,46.49156
167.20002,139.33330,46.35118
167.40002,139.49998,46.51229
167.60000,139.66672,46.44986
167.80000,139.83329,46.43335
168.00002,139.99986,46.69810
168.20002,140.16673,46.78042
168.40002,140.33335,46.53414
168.60000,140.49992,46.71686
168.80000,140.66666,46.71579
169.00002,140.83323,46.83794
169.20002,140.99997,46.92639
169.40002,141.16674,46.86690
169.60000,141.33330,46.86509
169.80000,141.49985,47.06648
170.00002,141.66673,46.88239
170.20002,141.83329,47.16482
170.40002,141.99992,47.11768
170.60000,142.16674,47.08147
170.80000,142.33328,47.22872
171.00002,142.49985,47.50169
171.20002,142.66673,47.27581
171.40002,142.83336,47.33225
171.60000,142.99992,47.38096
171.80000,143.16672,47.21916
172.00002,143.33335,47.44892
172.20002,143.49985,47.35097
172.40002,143.66667,47.62596
172.60000,143.83336,47.72881
172.80000,143.99998,47.71484
173.00002,144.16672,47.71896
173.20002,144.33323,47.65404
173.40002,144.49986,47.61993
173.60000,144.66680,47.75301
173.80000,144.83330,47.94142
174.00002,144.99985,47.78834
174.20002,145.16673,48.00497
174.40002,145.33335,47.84749
174.60000,145.49998,48.12090
174.80000,145.66674,48.13732
175.00002,145.83336,48.05039
175.20002,145.99991,48.15937
175.40002,146.16667,47.99174
175.60000,146.33330,48.29147
175.80000,146.49997,48.42936
176.00002,146.66672,48.42799
176.20002,146.83323,48.42617
176.40002,146.99991,48.31348
176.60000,147.16673,48.46287
176.80000,147.33336,48.36605
177.00002,147.49992,48.66378
177.20002,147.66673,48.51771
177.40002,147.83329,48.85576
177.60000,147.99992,48.60532
177.80000,148.16673,48.69381
178.00002,148.33336,48.76359
178.20002,148.49992,48.80142
178.40002,148.66672,48.84360
178.60000,148.83324,48.88790
178.80000,148.99998,48.99438
179.00002,149.16680,48.88442
179.20002,149.33328,49.07204
179.40002,149.49991,48.92930
179.60000,149.66673,49.15387
179.80000,149.83329,49.30033
180.00002,149.99992,49.29127
180.20002,150.16672,49.19170
180.40002,150.33334,49.27058
180.60000,150.49991,49.37770
180.80000,150.66673,49.28240
181.00002,150.83335,49.49486
181.20002,150.99992,49.41357
181.40002,151.16672,49.64612
181.60000,151.33323,49.45120
181.80000,151.49985,49.63857
182.00002,151.66673,49.67150
182.20002,151.83336,49.84516
182.40002,151.99984,49.69350
182.60000,152.16673,49.82394
182.80000,152.33329,49.74363
183.00002,152.49992,49.78504
183.20002,152.66674,49.88299
183.40002,152.83336,49.97237
183.60000,152.99985,49.98339
183.80000,153.16673,49.85608
184.00002,153.33329,50.03650
184.20002,153.49992,50.00265
184.40002,153.66673,50.16753
184.60000,153.83336,50.38656
184.80000,153.99992,50.32462
185.00002,154.16673,50.16483
185.20002,154.33329,50.25161
185.40002,154.49992,50.31830
185.60000,154.66672,50.40101
185.80000,154.83329,50.41076
186.00002,154.99986,50.52611
186.20002,155.16668,50.66463
186.40002,155.33336,50.60186
186.60000,155.49992,50.52993
186.80000,155.66672,50.63406
187.00002,155.83329,50.66816
187.20002,155.99991,50.71290
187.40002,156.16673,50.90067
187.60000,156.33335,50.98607
187.80000,156.49999,50.90944
188.00002,156.66673,50.92845
188.20002,156.83329,50.85583
188.40002,156.99992,51.16076
188.60000,157.16679,50.92659
188.80000,157.33328,51.12391
189.00002,157.49991,50.97808
189.20002,157.66667,50.97765
189.40002,157.83329,51.11690
189.60000,157.99992,51.22254
189.80000,158.16679,51.25974
190.00002,158.33335,51.15145
190.20002,158.49985,51.33873
190.40002,158.66667,51.44432
190.60000,158.83336,51.56354
190.80000,158.99997,51.67286
191.00002,159.16672,51.53433
191.20002,159.33329,51.62954
191.40002,159.49991,51.74214
191.60000,159.66672,51.66394
191.80000,159.83336,51.85675
192.00002,159.99991,51.86214
192.20002,160.16671,51.58084
192.40002,160.33335,51.81138
192.60000,160.49985,51.82853
192.80000,160.66672,52.06147
193.00002,160.83336,51.91442
193.20002,160.99991,51.68256
193.40002,161.16666,52.00963
193.60000,161.33329,51.94750
193.80000,161.49985,51.90134
194.00002,161.66680,52.20490
194.20002,161.83328,52.06270
194.40002,161.99986,52.43696
194.60000,162.16673,52.11106
194.80000,162.33329,52.35160
195.00002,162.49992,52.26384
195.20002,162.66678,52.46655
195.40002,162.83335,52.40197
195.60000,162.99985,52.38644
195.80000,163.16667,52.30721
196.00002,163.33336,52.51889
196.20002,163.49992,52.42642
196.40002,163.66672,52.64241
196.60000,163.83329,52.65633
196.80000,163.99991,52.65403
197.00002,164.16673,52.78579
197.20002,164.33328,52.70425
197.40002,164.49990,52.78187
197.60000,164.66666,52.84268
197.80000,164.83329,52.68960
198.00002,164.99985,52.90672
198.20002,165.16672,53.11036
198.40002,165.33334,52.97689
198.60000,165.49991,53.12163
198.80000,165.66673,53.05549
199.00002,165.83329,53.02050
199.20002,165.99992,53.19474
199.40002,166.16672,53.26658
199.60000,166.33328,53.17578
199.80000,166.49991,53.25991
200.00002,166.66673,53.30852
200.20002,166.83329,53.36879
200.40002,166.99985,53.38079
200.60000,167.16672,53.55323
200.80000,167.33328,53.45650
201.00002,167.49991,53.57728
201.20002,167.66673,53.56494
201.40002,167.83329,53.46532
201.60000,167.99990,53.62746
201.80000,168.16666,53.59438
202.00002,168.33330,53.48325
202.20002,168.49991,53.63838
202.40002,168.66678,53.73291
202.60000,168.83329,53.85457
202.80000,168.99997,53.84879
203.00002,169.16666,53.92053
203.20002,169.33329,54.09403
203.40002,169.49985,54.14779
203.60000,169.66673,53.87001
203.80000,169.83334,53.98667
204.00002,169.99984,54.20272
204.20002,170.16666,54.26303
204.40002,170.33329,54.00098
204.60000,170.49992,54.23701
204.80000,170.66672,54.08085
205.00002,170.83328,54.16548
205.20002,170.99991,54.26485
205.40002,171.16673,54.21345
205.60000,171.33335,54.35535
205.80000,171.49990,54.32286
206.00002,171.66672,54.38387
206.20002,171.83322,54.37225
206.40002,171.99986,54.45217
206.60000,172.16671,54.58129
206.80000,172.33334,54.44605
207.00002,172.49990,54.60951
207.20002,172.66672,54.54218
207.40002,172.83330,54.59320
207.60000,172.99986,54.80252
207.80000,173.16671,54.87700
208.00002,173.33329,54.79032
208.20002,173.49990,54.93870
208.40002,173.66672,54.88911
208.60000,173.83330,54.92654
208.80000,173.99991,54.90038
209.00002,174.16673,55.18845
209.20002,174.33329,55.04973
209.40002,174.49992,55.10363
209.60000,174.66674,54.95991
209.80000,174.83328,55.16924
210.00002,174.99991,55.08089
210.20002,175.16673,55.20908
210.40002,175.33328,55.22941
210.60000,175.49979,55.29600
210.80000,175.66673,55.26890
211.00002,175.83327,55.31320
211.20002,175.99991,55.38229
211.40002,176.16672,55.28958
211.60000,176.33328,55.59882
211.80000,176.49991,55.36955
212.00002,176.66671,55.60901
212.20002,176.83329,55.45447
212.40002,176.99996,55.63841
212.60000,177.16678,55.65737
212.80000,177.33330,55.70618
213.00002,177.49984,55.68452
213.20002,177.66679,55.74165
213.40002,177.83340,55.73871
213.60000,177.99990,55.70975
213.80000,178.16665,55.74317
214.00002,178.33328,55.87611
214.20002,178.49991,55.98455
214.40002,178.66673,55.94241
214.60000,178.83329,55.96470
214.80000,178.99984,55.91796
215.00002,179.16674,56.03065
215.20002,179.33328,56.06814
215.40002,179.49991,56.16330
215.60000,179.66673,56.18270
215.80000,179.83329,56.11934
216.00002,179.99986,56.17182
216.20002,180.16672,56.20804
216.40002,180.33335,56.25586
216.60000,180.49991,56.41501
216.80000,180.66673,56.55530
217.00002,180.83328,56.51100
217.20002,180.99992,56.27203
217.40002,181.16672,56.66373
217.60000,181.33329,56.57656
217.80000,181.49985,56.55402
218.00002,181.66665,56.66579
218.20002,181.83323,56.79260
218.40002,181.99991,56.53315
218.60000,182.16671,56.65639
218.80000,182.33329,56.65060
219.00002,182.49985,56.86067
219.20002,182.66672,56.82024
219.40002,182.83328,56.88217
219.60000,182.99991,56.96371
219.80000,183.16673,56.88610
220.00002,183.33334,57.11145
220.20002,183.49992,56.88433
220.40002,183.66667,57.13173
220.60000,183.83328,56.83337
220.80000,183.99991,57.05779
221.00002,184.16673,56.92221
221.20002,184.33329,57.20832
221.40002,184.49992,57.33587
221.60000,184.66672,57.23532
221.80000,184.83328,57.12076
222.00002,184.99985,57.28888
222.20002,185.16673,57.40382
222.40002,185.33329,57.26060
222.60000,185.49992,57.37022
222.80000,185.66672,57.33875
223.00002,185.83329,57.34532
223.20002,185.99985,57.12791
223.40002,186.16665,57.56053
223.60000,186.33328,57.48433
223.80000,186.49997,57.69268
224.00002,186.66672,57.44955
224.20002,186.83329,57.58547
224.40002,186.99991,57.80768
224.60000,187.16680,57.85982
224.80000,187.33328,57.88952
225.00002,187.49991,57.86105
225.20002,187.66671,57.90911
225.40002,187.83335,57.81268
225.60000,187.99985,58.02014
225.80002,188.16672,57.79195
226.00002,188.33334,58.00104
226.20002,188.49984,58.07929
226.40002,188.66673,58.21777
226.60000,188.83321,58.10898
226.80002,188.99985,58.10766
227.00002,189.16678,58.24672
227.20002,189.33333,58.27504
227.40002,189.49991,58.35178
227.60000,189.66673,58.50662
227.80002,189.83327,58.51250
228.00002,189.99984,58.55273
228.20002,190.16672,58.75755
228.40002,190.33335,58.47271
228.60000,190.49991,58.56875
228.80002,190.66665,58.63485
229.00002,190.83329,58.63162
229.20002,190.99990,58.78009
229.40002,191.16672,58.86868
229.60000,191.33329,58.83374
229.80002,191.49985,58.81331
230.00002,191.66665,58.76294
230.20002,191.83334,58.88191
230.40002,191.99997,58.81899
230.60000,192.16672,59.03979
230.80002,192.33329,58.93992
231.00002,192.49983,58.93296
231.20002,192.66665,58.98153
231.40002,192.83334,59.42752
231.60000,192.99991,59.22584
231.80002,193.16673,59.39160
232.00002,193.33322,59.18238
232.20002,193.49985,59.45903
232.40002,193.66672,59.53233
232.60000,193.83334,59.58800
232.80002,193.99991,59.50391
233.00002,194.16671,59.61108
233.20002,194.33321,59.52439
233.40002,194.49979,59.73558
233.60000,194.66672,59.70236
233.80002,194.83335,59.70011
234.00002,194.99986,59.75543
234.20002,195.16671,59.73607
234.40002,195.33329,59.92869
234.60000,195.49990,59.92933
234.80002,195.66672,59.96804
235.00002,195.83330,60.04786
235.20002,195.99991,60.07721
235.40002,196.16671,60.03806
235.60000,196.33334,59.99719
235.80002,196.49984,60.08245
236.00002,196.66672,60.14444
236.20002,196.83328,60.13954
236.40002,196.99983,60.27007
236.60000,197.16673,60.26066
236.80002,197.33334,60.18070
237.00002,197.49992,60.14483
237.20002,197.66673,60.35764
237.40002,197.83327,60.27076
237.60000,197.99985,60.39581
237.80002,198.16678,60.39179
238.00002,198.33334,60.22240
238.20002,198.49991,60.55427
238.40002,198.66666,60.63870
238.60000,198.83327,60.45573
238.80002,198.99990,60.67633
239.00002,199.16672,60.58686
239.20002,199.33328,60.64620
239.40002,199.49991,60.56544
239.60000,199.66671,60.79726
239.80002,199.83329,61.01840
240.00002,199.99985,60.91996
240.20002,200.16672,61.04790
240.40002,200.33328,60.94901
240.60000,200.49991,61.37149
240.80002,200.66665,61.10788
241.00002,200.83334,60.96347
241.20002,200.99990,61.11321
241.40002,201.16672,61.10057
241.60000,201.33328,61.04942
241.80002,201.49991,61.29064
242.00002,201.66673,61.12796
242.20002,201.83329,61.41285
242.40002,201.99992,61.29868
242.60000,202.16672,61.33489
242.80002,202.33328,61.38114
243.00002,202.49991,61.46410
243.20002,202.66678,61.61546
243.40002,202.83334,61.37619
243.60000,202.99979,61.62580
243.80002,203.16666,61.64981
244.00002,203.33327,61.73605
244.20002,203.49991,61.59302
244.40002,203.66672,61.74894
244.60000,203.83328,61.90064
244.80002,203.99997,61.90398
245.00002,204.16671,61.99561
245.20002,204.33329,61.98879
245.40002,204.49990,62.16220
245.60000,204.66678,62.28705
245.80002,204.83335,61.95224
246.00002,204.99984,62.13089
246.20002,205.16671,61.99090
246.40002,205.33334,62.16284
246.60000,205.49990,62.22399
246.80002,205.66665,62.36697
247.00002,205.83328,62.25329
247.20002,205.99984,62.20571
247.40002,206.16673,62.21037
247.60000,206.33329,62.22512
247.80002,206.49992,62.59507
248.00002,206.66672,62.45057
248.20002,206.83328,62.43199
248.40002,206.99991,62.68924
248.60000,207.16678,62.54362
248.80002,207.33334,62.82096
249.00002,207.49992,62.60266
249.20002,207.66666,62.58243
249.40002,207.83335,62.85682
249.60000,207.99991,62.80885
249.80002,208.16673,62.78798
250.00002,208.33328,62.89759
250.20002,208.49984,62.78401
250.40002,208.66666,62.90803
250.60000,208.83335,62.88456
250.80002,208.99996,63.03004
251.00002,209.16665,62.85153
251.20002,209.33323,62.99338
251.40002,209.49984,63.08178
251.60000,209.66671,62.92523
251.80002,209.83335,62.82713
252.00002,209.99990,63.19120
252.20002,210.16680,63.21114
252.40002,210.33334,63.19017
252.60000,210.49984,63.25608
252.80002,210.66673,63.22702
253.00002,210.83329,63.24809
253.20002,210.99998,63.31924
253.40002,211.16672,63.38744
253.60000,211.33328,63.43429
253.80002,211.49985,63.35119
254.00002,211.66679,63.39920
254.20002,211.83334,63.30782
254.40002,211.99990,63.37245
254.60000,212.16666,63.77224
254.80002,212.33328,63.74014
255.00002,212.49991,63.59844
255.20002,212.66671,63.73177
255.40002,212.83329,63.87597
255.60000,212.99984,63.71001
255.80002,213.16666,63.76905
256.00000,213.33335,63.58060
256.20002,213.49991,63.86010
256.40003,213.66671,63.73774
256.60000,213.83328,64.14748
256.80002,213.99984,64.12131
257.00000,214.16672,64.11740
257.20002,214.33335,64.01435
257.40003,214.49991,64.14057
257.60000,214.66672,64.11715
257.80002,214.83328,64.16928
258.00000,214.99984,64.04644
258.20002,215.16679,64.11127
258.40003,215.33335,64.22466
258.60000,215.49990,64.33143
258.80002,215.66667,64.16414
259.00000,215.83334,64.36837
259.20002,215.99991,64.30997
259.40003,216.16671,64.45848
259.60000,216.33334,64.47044
259.80002,216.49985,64.35745
260.00000,216.66672,64.51267
260.20002,216.83328,64.47691
260.40003,216.99991,64.57103
260.60000,217.16671,64.57834
260.80002,217.33329,64.62341
261.00000,217.49984,64.68967
261.20002,217.66672,64.90203
261.40003,217.83330,64.71956
261.60000,217.99991,64.71539
261.80002,218.16671,64.82098
262.00000,218.33329,64.93800
262.20000,218.49990,64.88846
262.40003,218.66672,64.78272
262.60000,218.83328,64.87934
262.80003,218.99998,64.90036
263.00000,219.16673,65.03673
263.20000,219.33323,64.87968
263.40003,219.49992,64.89982
263.60000,219.66673,64.92104
263.80003,219.83327,64.90909
264.00000,219.99985,64.97867
264.20000,220.16672,65.08161
264.40003,220.33328,64.92864
264.60000,220.49991,65.18569
264.80003,220.66671,64.95720
265.00000,220.83335,65.02492
265.20000,220.99990,65.07157
265.40003,221.16672,65.31167
265.60000,221.33328,64.89316
265.80003,221.49991,65.20597
266.00000,221.66671,65.22386
266.20000,221.83329,65.09881
266.40003,221.99985,65.25507
266.60000,222.16678,65.09205
266.80003,222.33335,65.22102
267.00000,222.49991,65.27207
267.20000,222.66671,65.28717
267.40003,222.83329,65.22043
267.60000,222.99984,65.17006
267.80003,223.16664,65.21700
268.00000,223.33335,65.07025
268.20000,223.49983,64.98195
268.40003,223.66665,65.19426
268.60000,223.83329,65.14188
268.80003,223.99992,65.00645
269.00000,224.16672,64.81667
269.20000,224.33333,64.91771
269.40003,224.49991,64.65316
269.60000,224.66673,64.45608
269.80003,224.83328,64.14733
270.00000,224.99992,63.97882
270.20000,225.16672,63.94208
270.40003,225.33335,63.67899
270.60000,225.49985,63.28258
270.80003,225.66667,62.52318
271.00000,225.83336,62.29288
271.20000,225.99991,61.50223
271.40003,226.16671,60.65742
271.60000,226.33322,59.89234
271.80003,226.49990,59.00490
272.00000,226.66672,57.83767
272.20000,226.83335,56.91937
272.40003,226.99989,55.88204
272.60000,227.16671,54.56840
272.80003,227.33323,53.19474
273.00000,227.49985,51.73626
273.20000,227.66672,49.84560
273.40003,227.83333,46.21839
273.60000,227.99991,-0.03556
273.80003,228.16673,0.14128
274.00000,228.33329,-0.17437
274.20000,228.49992,0.15608
274.40003,228.66672,-0.16776
274.60000,228.83333,0.00580
274.80003,228.99991,-0.10582
275.00000,229.16673,0.09219
275.20000,229.33329,0.08660
275.40003,229.49992,0.05945
275.60000,229.66672,0.02560
275.80003,229.83322,0.00521
276.00000,229.99991,-0.05893
276.20000,230.16673,0.04823
276.40003,230.33328,0.13589
276.60000,230.49990,0.00693
276.80003,230.66672,-0.20059
277.00000,230.83329,0.05514
277.20000,230.99991,0.03544
277.40003,231.16671,-0.14860
277.60000,231.33334,-0.24699
277.80003,231.49984,-0.07211
278.00000,231.66666,-0.02125
278.20000,231.83329,0.01423
278.40003,231.99985,0.03878
278.60000,232.16672,-0.14610
278.80003,232.33328,-0.28301
279.00000,232.49984,0.19915
279.20000,232.66666,0.17451
279.40003,232.83329,-0.02909
279.60000,232.99992,-0.17771
279.80003,233.16672,-0.06138
280.00000,233.33328,0.04921
280.20000,233.49985,0.20126
280.40003,233.66665,0.00531
280.60000,233.83334,-0.02233
280.80003,233.99998,-0.16418
281.00000,234.16672,-0.07657
281.20000,234.33328,0.04554
281.40003,234.49991,-0.00939
281.60000,234.66665,-0.03796
281.80003,234.83329,-0.00042
282.00000,234.99990,0.10988
282.17603,235.14673,0.10939