File: EPR/EPR/RDSO EPR Tensile 50.is_tens_RawData/Specimen_RawData_16.csv
Time,Extension,Load
(sec),(mm),(N)
0.00000,-0.00006,3.15306
0.20000,0.16469,3.98620
0.40000,0.33300,4.16251
0.60000,0.49987,4.48600
0.80000,0.66669,4.67666
1.00000,0.83331,4.82493
1.20000,0.99994,4.92328
1.40000,1.16675,5.31248
1.60000,1.33331,5.34276
1.80000,1.49994,5.49290
2.00000,1.66669,5.86677
2.20000,1.83337,5.70791
2.40000,1.99994,6.23167
2.60000,2.16675,6.26710
2.80000,2.33331,6.38612
3.00000,2.49994,6.56335
3.20000,2.66681,6.64856
3.40000,2.83337,6.91840
3.60000,2.99994,7.03836
3.80000,3.16669,7.15659
4.00000,3.33331,7.12494
4.20000,3.49994,7.46534
4.40000,3.66669,7.56084
4.60000,3.83331,7.74464
4.80000,3.99994,7.60984
5.00000,4.16669,7.93696
5.20000,4.33337,8.12483
5.40000,4.49994,8.17270
5.60000,4.66675,8.16927
5.80000,4.83325,8.22807
6.00000,4.99994,8.41006
6.20000,5.16675,8.35229
6.40000,5.33337,8.45911
6.60000,5.49994,8.85669
6.80000,5.66675,8.93543
7.00000,5.83331,8.88962
7.20000,5.99994,9.03304
7.40000,6.16675,9.23080
7.60000,6.33337,9.11468
7.80000,6.49994,9.31753
8.00000,6.66675,9.22831
8.20000,6.83325,9.42994
8.40000,6.99987,9.48849
8.60000,7.16675,9.45861
8.80000,7.33331,9.60747
9.00000,7.49994,9.77166
9.20000,7.66675,9.73100
9.40000,7.83331,9.73903
9.60000,7.99987,9.85433
9.80000,8.16681,9.91269
10.00000,8.33337,10.02539
10.20000,8.49994,10.18307
10.40000,8.66669,10.20865
10.60000,8.83331,10.19243
10.80000,8.99994,10.42106
11.00000,9.16675,10.51676
11.20000,9.33331,10.53092
11.40000,9.49987,10.61187
11.60000,9.66675,10.66248
11.80000,9.83331,10.69634
12.00000,9.99994,10.71623
12.20000,10.16675,10.73353
12.40000,10.33331,10.62162
12.60000,10.49987,10.97990
12.80000,10.66675,10.87568
13.00000,10.83337,11.13690
13.20000,10.99994,11.04742
13.40000,11.16669,11.29012
13.60000,11.33331,11.36833
13.80000,11.49994,11.52581
14.00000,11.66675,11.56579
14.20000,11.83331,11.54139
14.40000,11.99994,11.60945
14.60000,12.16669,11.56477
14.80000,12.33331,11.59657
15.00000,12.50000,11.74116
15.20000,12.66675,11.61357
15.40000,12.83331,11.68942
15.60000,12.99994,11.86876
15.80000,13.16669,11.72666
16.00000,13.33337,12.10455
16.20000,13.49994,12.01297
16.40000,13.66668,12.03149
16.60000,13.83331,12.09093
16.80000,13.99994,12.08808
17.00000,14.16675,12.16496
17.20000,14.33325,12.05217
17.40000,14.49994,12.29741
17.60000,14.66675,12.11508
17.80000,14.83331,12.20044
18.00000,14.99987,12.42907
18.20000,15.16681,12.20024
18.40000,15.33331,12.32328
18.60000,15.49987,12.56372
18.80000,15.66668,12.48077
19.00000,15.83337,12.57304
19.20000,15.99994,12.69994
19.40000,16.16675,12.74302
19.60000,16.33331,12.63615
19.80000,16.49987,12.83038
20.00000,16.66675,12.90589
20.20000,16.83337,13.02094
20.40000,16.99987,12.96915
20.60000,17.16681,12.93750
20.80000,17.33331,12.91104
21.00000,17.49994,13.01041
21.20000,17.66675,13.04838
21.40000,17.83331,13.13560
21.60000,17.99993,12.93186
21.80000,18.16675,13.02908
22.00000,18.33331,13.21430
22.20000,18.49987,13.12433
22.40000,18.66675,13.25614
22.60000,18.83331,13.25046
22.80000,19.00000,13.37203
23.00000,19.16668,13.34037
23.20000,19.33331,13.27045
23.40000,19.49994,13.66534
23.60000,19.66681,13.30999
23.80000,19.83331,13.54519
24.00000,19.99993,13.59591
24.20000,20.16668,13.45969
24.40000,20.33331,13.62687
24.60000,20.49993,13.73732
24.80000,20.66675,13.74781
25.00000,20.83337,13.72875
25.20000,20.99987,13.81538
25.40000,21.16668,13.86590
25.60000,21.33331,13.88123
25.80000,21.50000,13.73908
26.00000,21.66675,13.75864
26.20000,21.83331,14.12731
26.40000,21.99993,14.09090
26.60000,22.16675,14.02083
26.80000,22.33331,14.03568
27.00000,22.49993,14.08218
27.20000,22.66675,14.25696
27.40000,22.83331,14.05420
27.60000,22.99987,14.22443
27.80000,23.16675,14.27431
28.00000,23.33337,14.19743
28.20000,23.49993,14.25407
28.40000,23.66669,14.37775
28.60000,23.83331,14.46894
28.80000,23.99993,14.43096
29.00000,24.16675,14.64563
29.20000,24.33331,14.48276
29.40000,24.49993,14.54268
29.60000,24.66675,14.55336
29.80000,24.83325,14.43532
30.00000,24.99993,14.65122
30.20000,25.16681,14.74485
30.40000,25.33331,14.67341
30.60000,25.49981,14.77773
30.80000,25.66675,14.90685
31.00000,25.83337,14.82330
31.20000,25.99993,15.07462
31.40000,26.16668,14.87813
31.60000,26.33331,14.91523
31.80000,26.49993,14.75637
32.00000,26.66681,14.87789
32.20000,26.83331,14.87882
32.40000,26.99994,14.99559
32.60000,27.16674,15.09849
32.80000,27.33325,15.06012
33.00000,27.49987,14.98971
33.20000,27.66675,15.36392
33.40000,27.83337,15.07384
33.60000,27.99987,15.29135
33.80000,28.16675,15.28724
34.00000,28.33331,15.21467
34.20000,28.49993,15.19786
34.40000,28.66675,15.32830
34.60000,28.83331,15.42497
34.80000,28.99993,15.33952
35.00000,29.16681,15.49240
35.20000,29.33331,15.48250
35.40000,29.50000,15.67580
35.60000,29.66675,15.68404
35.80000,29.83331,15.62401
36.00000,29.99993,15.63562
36.20000,30.16675,15.88778
36.40000,30.33337,15.86759
36.60000,30.49993,15.64155
36.80000,30.66675,15.73504
37.00000,30.83331,15.90120
37.20000,30.99987,16.08765
37.40000,31.16668,15.79424
37.60000,31.33331,15.97774
37.80000,31.49993,15.93281
38.00000,31.66668,16.00018
38.20000,31.83331,16.15762
38.40000,31.99993,16.16360
38.60000,32.16681,16.36009
38.80000,32.33337,16.25679
39.00000,32.49987,16.36464
39.20000,32.66674,16.28227
39.40000,32.83331,16.31104
39.60000,33.00000,16.21725
39.80000,33.16681,16.51267
40.00000,33.33325,16.52948
40.20000,33.49987,16.50419
40.40000,33.66675,16.50272
40.60000,33.83337,16.55481
40.80000,33.99993,16.65801
41.00000,34.16675,16.38488
41.20000,34.33324,16.73366
41.40000,34.49993,16.64678
41.60000,34.66674,16.58857
41.80000,34.83331,16.78658
42.00000,34.99993,16.70921
42.20000,35.16675,16.71279
42.40000,35.33331,17.02198
42.60000,35.49993,16.88306
42.80000,35.66675,17.03310
43.00000,35.83343,17.05789
43.20000,35.99987,17.04368
43.40000,36.16668,17.15663
43.60000,36.33331,17.07000
43.80000,36.49993,17.11312
44.00000,36.66674,17.25232
44.20000,36.83331,17.08945
44.40000,36.99993,17.24052
44.60000,37.16674,17.24169
44.80000,37.33331,17.56646
45.00000,37.49987,17.17172
45.20000,37.66681,17.52932
45.40000,37.83331,17.51246
45.60000,37.99987,17.51550
45.80000,38.16674,17.34101
46.00000,38.33337,17.75345
46.20000,38.49993,17.55754
46.40000,38.66674,17.48821
46.60000,38.83325,17.69607
46.80000,38.99993,17.53010
47.00000,39.16674,17.61414
47.20000,39.33337,17.90020
47.40000,39.49993,17.82969
47.60000,39.66675,17.85958
47.80000,39.83324,17.98419
48.00000,39.99987,18.13525
48.20000,40.16674,18.10517
48.40000,40.33337,18.07954
48.60000,40.49993,18.23178
48.80000,40.66668,18.01574
49.00000,40.83330,17.93695
49.20000,40.99993,18.19439
49.40000,41.16674,18.45713
49.60000,41.33331,18.09404
49.80000,41.49993,18.22399
50.00000,41.66668,18.28166
50.20000,41.83318,18.37408
50.40000,41.99993,18.38839
50.60000,42.16681,18.54259
50.80000,42.33331,18.47031
51.00000,42.49987,18.77896
51.20000,42.66674,18.64735
51.40000,42.83343,18.64451
51.60000,42.99993,18.85403
51.80000,43.16675,18.75339
52.00000,43.33331,18.73290
52.20000,43.49993,18.75917
52.40000,43.66674,18.95041
52.60000,43.83337,18.82684
52.80000,43.99993,19.03146
53.00000,44.16674,18.90994
53.20000,44.33331,19.00711
53.40000,44.49993,19.11981
53.60000,44.66681,19.18365
53.80000,44.83331,19.22912
54.00000,44.99987,19.28621
54.20000,45.16668,19.29748
54.40000,45.33330,19.25456
54.60000,45.49987,19.37534
54.80000,45.66674,19.45134
55.00000,45.83331,19.43252
55.20000,45.99987,19.45987
55.40000,46.16668,19.47128
55.60000,46.33337,19.59427
55.80000,46.49993,19.61176
56.00000,46.66674,19.72206
56.20000,46.83331,19.74720
56.40000,46.99993,19.55914
56.60000,47.16674,19.83957
56.80000,47.33331,19.93507
57.00000,47.49993,19.85711
57.20000,47.66674,20.01396
57.40000,47.83330,19.98583
57.60000,47.99987,20.10818
57.80000,48.16674,19.94325
58.00000,48.33330,20.02140
58.20000,48.49993,20.28110
58.40000,48.66668,20.23225
58.60000,48.83330,20.08158
58.80000,48.99993,20.28826
59.00000,49.16674,20.20853
59.20000,49.33331,20.45260
59.40000,49.49993,20.23838
59.60000,49.66674,20.64698
59.80000,49.83337,20.46833
60.00000,49.99999,20.55374
60.20000,50.16674,20.56275
60.40000,50.33324,20.57133
60.60000,50.49987,20.74146
60.80000,50.66674,20.58760
61.00000,50.83337,20.81143
61.20000,50.99993,20.82652
61.40000,51.16674,20.90566
61.60000,51.33331,21.07265
61.80000,51.49987,21.01654
62.00000,51.66674,21.09421
62.20000,51.83330,21.06241
62.40000,51.99999,21.04251
62.60000,52.16674,21.11910
62.80000,52.33324,21.23376
63.00000,52.49986,21.16354
63.20000,52.66680,21.54643
63.40000,52.83337,21.20215
63.60000,52.99993,21.47004
63.80000,53.16674,21.45730
64.00000,53.33337,21.55598
64.20000,53.49987,21.65481
64.40000,53.66674,21.58102
64.60001,53.83330,21.81289
64.80000,53.99993,21.56044
65.00000,54.16675,21.61875
65.20000,54.33330,21.80005
65.40000,54.49993,21.99022
65.60001,54.66674,21.88418
65.80000,54.83331,21.91054
66.00000,54.99987,21.80426
66.20001,55.16680,21.99649
66.40000,55.33330,21.96787
66.60001,55.49987,22.37937
66.80000,55.66674,22.18960
67.00000,55.83331,22.24129
67.20001,55.99987,22.21772
67.40000,56.16674,22.23252
67.60001,56.33337,22.50065
67.80000,56.49993,22.18725
68.00000,56.66662,22.52735
68.20001,56.83331,22.43778
68.40000,56.99993,22.50065
68.60001,57.16681,22.64642
68.80000,57.33330,22.58826
69.00000,57.49993,22.79646
69.20001,57.66674,22.74339
69.40000,57.83331,22.67788
69.60001,57.99986,22.88775
69.80000,58.16668,23.01363
70.00000,58.33331,23.06763
70.20001,58.49993,22.99403
70.40000,58.66668,23.08203
70.60001,58.83330,23.14799
70.80000,58.99999,23.11285
71.00000,59.16674,23.12172
71.20001,59.33330,23.18214
71.40000,59.49987,23.27921
71.60001,59.66680,23.37461
71.80000,59.83330,23.51735
72.00000,59.99993,23.31370
72.20001,60.16674,23.47364
72.40000,60.33331,23.50564
72.60001,60.49987,23.56208
72.80000,60.66674,23.47261
73.00000,60.83337,23.70825
73.20001,60.99993,23.67562
73.40000,61.16668,23.52529
73.60001,61.33324,23.92802
73.80000,61.49993,23.71501
74.00000,61.66680,23.79474
74.20001,61.83330,23.90547
74.40000,61.99993,23.93894
74.60001,62.16681,24.06664
74.80000,62.33331,24.09329
75.00000,62.49993,24.12793
75.20001,62.66674,24.45550
75.40000,62.83336,24.10966
75.60001,62.99987,24.22030
75.80000,63.16674,24.35088
76.00000,63.33336,24.37323
76.20001,63.49993,24.53733
76.40000,63.66668,24.44565
76.60001,63.83331,24.57442
76.80000,63.99993,24.53875
77.00000,64.16680,24.50945
77.20001,64.33330,24.63665
77.40000,64.49999,24.89831
77.60001,64.66674,24.75381
77.80000,64.83330,24.90928
78.00000,64.99992,24.78237
78.20001,65.16674,25.05712
78.40000,65.33337,25.04110
78.60001,65.49993,25.23190
78.80000,65.66674,25.23322
79.00000,65.83330,25.25248
79.20001,65.99993,25.03963
79.40000,66.16668,25.13228
79.60001,66.33330,25.16418
79.80000,66.49987,25.45921
80.00000,66.66668,25.40271
80.20001,66.83331,25.60126
80.40000,66.99993,25.45764
80.60001,67.16674,25.57127
80.80000,67.33330,25.65521
81.00001,67.49993,25.79329
81.20001,67.66680,25.66584
81.40000,67.83336,25.82691
81.60001,67.99993,25.78045
81.80000,68.16674,25.85954
82.00001,68.33337,25.88154
82.20001,68.49993,25.97415
82.40000,68.66667,26.04535
82.60001,68.83330,26.08793
82.80000,68.99992,26.21307
83.00001,69.16674,26.34199
83.20001,69.33330,26.24855
83.40000,69.49992,26.30686
83.60001,69.66674,26.24620
83.80000,69.83330,26.13286
84.00001,69.99987,26.36032
84.20001,70.16674,26.48757
84.40000,70.33330,26.68220
84.60001,70.49993,26.52721
84.80000,70.66674,26.63653
85.00001,70.83336,26.47116
85.20001,70.99986,26.83958
85.40000,71.16674,26.94062
85.60001,71.33336,27.00677
85.80000,71.49993,27.19753
86.00001,71.66680,26.94464
86.20001,71.83324,26.95057
86.40000,71.99986,27.19582
86.60001,72.16674,27.11913
86.80000,72.33337,27.07841
87.00001,72.49992,27.05293
87.20001,72.66680,27.40637
87.40000,72.83330,27.31557
87.60001,72.99987,27.39559
87.80000,73.16674,27.50348
88.00001,73.33343,27.36026
88.20001,73.49993,27.57527
88.40000,73.66668,27.72212
88.60001,73.83330,27.46977
88.80000,73.99999,27.73844
89.00001,74.16680,27.72751
89.20001,74.33336,27.63044
89.40000,74.49993,28.04939
89.60001,74.66674,27.88764
89.80000,74.83331,28.03817
90.00001,74.99986,28.10775
90.20001,75.16674,28.16601
90.40000,75.33330,28.05659
90.60001,75.49986,28.19899
90.80000,75.66668,28.22172
91.00001,75.83336,28.37730
91.20001,75.99992,28.37499
91.40000,76.16674,28.24715
91.60001,76.33330,28.53366
91.80000,76.49987,28.52126
92.00001,76.66674,28.60887
92.20001,76.83337,28.51562
92.40000,76.99993,28.55870
92.60001,77.16674,28.61313
92.80000,77.33324,28.64160
93.00001,77.49987,28.66865
93.20001,77.66680,29.00783
93.40000,77.83336,29.05643
93.60001,77.99986,28.88195
93.80000,78.16673,28.96927
94.00001,78.33330,29.15037
94.20001,78.49992,29.07520
94.40000,78.66674,29.14753
94.60001,78.83330,29.19417
94.80000,78.99993,29.33368
95.00001,79.16674,29.30717
95.20001,79.33330,29.41144
95.40000,79.49992,29.60391
95.60001,79.66674,29.48680
95.80000,79.83330,29.70093
96.00001,79.99986,29.60759
96.20001,80.16674,29.95818
96.40000,80.33336,29.94799
96.60001,80.49986,29.58612
96.80000,80.66667,29.98332
97.00001,80.83330,29.93456
97.20001,80.99993,29.91104
97.40000,81.16674,30.02208
97.60001,81.33336,30.02408
97.80000,81.49993,30.14639
98.00001,81.66674,30.12537
98.20001,81.83330,29.99209
98.40000,81.99993,30.45117
98.60001,82.16674,30.31201
98.80000,82.33336,30.30799
99.00001,82.49993,30.33891
99.20001,82.66673,30.47714
99.40000,82.83337,30.60949
99.60001,82.99992,30.52976
99.80000,83.16674,30.73086
100.00001,83.33330,30.85150
100.20001,83.49992,30.86061
100.40000,83.66668,30.78162
100.60001,83.83330,30.75031
100.80000,83.99992,30.91133
101.00001,84.16673,30.84557
101.20001,84.33324,31.02226
101.40000,84.49999,31.04059
101.60001,84.66673,31.17029
101.80000,84.83330,30.90104
102.00001,84.99992,31.14290
102.20001,85.16674,31.24325
102.40000,85.33330,31.41882
102.60001,85.49985,31.41990
102.80000,85.66674,31.40270
103.00001,85.83336,31.48208
103.20001,85.99993,31.45169
103.40000,86.16674,31.63456
103.60001,86.33330,31.75912
103.80000,86.49986,31.57611
104.00001,86.66674,31.85340
104.20001,86.83329,31.98011
104.40000,86.99986,31.76887
104.60001,87.16674,31.86795
104.80000,87.33329,31.91073
105.00001,87.49986,32.01416
105.20001,87.66680,32.19228
105.40000,87.83337,32.14401
105.60001,87.99986,32.18224
105.80000,88.16668,32.31115
106.00001,88.33336,32.53116
106.20001,88.49992,32.31414
106.40000,88.66673,32.44811
106.60001,88.83330,32.49162
106.80000,88.99992,32.49005
107.00001,89.16673,32.46884
107.20001,89.33330,32.88509
107.40000,89.49992,32.63710
107.60001,89.66668,32.60598
107.80000,89.83330,32.73936
108.00001,89.99986,33.00435
108.20001,90.16674,33.02190
108.40000,90.33336,32.97407
108.60001,90.49992,32.99813
108.80000,90.66661,33.15086
109.00001,90.83330,32.94056
109.20001,90.99992,33.13151
109.40000,91.16674,33.39773
109.60001,91.33330,33.25200
109.80000,91.49992,33.34946
110.00001,91.66674,33.16801
110.20001,91.83330,33.39474
110.40000,91.99993,33.40434
110.60001,92.16674,33.56467
110.80000,92.33330,33.59230
111.00001,92.49986,33.84598
111.20001,92.66674,33.72245
111.40000,92.83336,33.81726
111.60001,92.99993,33.78277
111.80000,93.16668,33.96612
112.00001,93.33330,34.08015
112.20001,93.49986,34.02615
112.40000,93.66667,34.10474
112.60001,93.83336,34.25174
112.80000,93.99999,34.11009
113.00001,94.16673,34.13586
113.20001,94.33329,34.30574
113.40001,94.49992,34.24444
113.60001,94.66680,34.39164
113.80000,94.83336,34.27972
114.00001,94.99992,34.46690
114.20001,95.16673,34.43157
114.40001,95.33330,34.62924
114.60001,95.49987,34.77242
114.80000,95.66667,34.72601
115.00001,95.83335,34.80843
115.20001,95.99986,34.58289
115.40001,96.16667,34.87507
115.60001,96.33330,35.04025
115.80000,96.49992,34.98787
116.00001,96.66667,34.75698
116.20001,96.83323,35.06093
116.40001,96.99985,35.23517
116.60001,97.16674,35.02991
116.80000,97.33336,35.30059
117.00001,97.49993,35.07259
117.20001,97.66674,35.50006
117.40001,97.83336,35.44416
117.60001,97.99986,35.39849
117.80000,98.16674,35.55411
118.00001,98.33336,35.53554
118.20001,98.49992,35.40255
118.40001,98.66673,35.62903
118.60001,98.83337,35.70861
118.80000,98.99992,35.82905
119.00001,99.16673,35.67230
119.20001,99.33330,35.81425
119.40001,99.49986,35.94577
119.60001,99.66673,36.02176
119.80000,99.83330,36.13549
120.00001,99.99992,36.10899
120.20001,100.16673,36.11727
120.40001,100.33330,36.24011
120.60001,100.49986,36.45600
120.80000,100.66673,36.40872
121.00001,100.83342,36.35055
121.20001,100.99992,36.51269
121.40001,101.16667,36.56934
121.60001,101.33330,36.63833
121.80000,101.49992,36.53764
122.00001,101.66674,36.77842
122.20001,101.83323,36.87309
122.40001,101.99992,36.66219
122.60001,102.16674,36.88049
122.80000,102.33330,36.81669
123.00001,102.49986,36.83301
123.20001,102.66673,36.91822
123.40001,102.83336,37.11471
123.60001,102.99986,37.29317
123.80000,103.16667,37.17140
124.00001,103.33336,37.25078
124.20001,103.49998,37.54267
124.40001,103.66674,37.25979
124.60001,103.83336,37.22804
124.80000,103.99993,37.53792
125.00001,104.16673,37.31781
125.20001,104.33330,37.51837
125.40001,104.49992,37.62514
125.60001,104.66680,37.73441
125.80000,104.83329,37.73313
126.00001,104.99986,37.80178
126.20001,105.16667,37.89733
126.40001,105.33329,37.86847
126.60001,105.49992,38.00136
126.80000,105.66674,37.92894
127.00001,105.83330,37.87063
127.20001,105.99986,38.07285
127.40001,106.16673,38.10431
127.60001,106.33335,38.21279
127.80000,106.49992,38.01508
128.00000,106.66667,38.31398
128.20002,106.83324,38.22588
128.40001,106.99992,38.34960
128.60001,107.16680,38.53678
128.80000,107.33336,38.49925
129.00000,107.49985,38.40056
129.20002,107.66667,38.60117
129.40001,107.83330,38.69671
129.60001,107.99993,38.69093
129.80000,108.16674,38.60670
130.00000,108.33336,38.84244
130.20002,108.49986,38.83147
130.40001,108.66674,38.96734
130.60001,108.83336,38.98439
130.80000,108.99998,39.10356
131.00000,109.16674,38.95965
131.20002,109.33336,39.11723
131.40002,109.49992,39.23277
131.60000,109.66667,39.28216
131.80000,109.83337,39.30476
132.00000,109.99992,39.28697
132.20002,110.16673,39.37982
132.40002,110.33324,39.34302
132.60000,110.49986,39.45357
132.80000,110.66673,39.59400
133.00000,110.83336,39.66922
133.20002,110.99986,39.82567
133.40002,111.16668,39.59508
133.60000,111.33330,39.67578
133.80000,111.49992,39.67784
134.00000,111.66673,39.83356
134.20002,111.83336,40.03500
134.40002,111.99986,39.88903
134.60000,112.16674,39.79897
134.80000,112.33330,40.00526
135.00000,112.49992,40.30107
135.20002,112.66680,40.10306
135.40002,112.83336,40.17019
135.60000,112.99986,40.26001
135.80000,113.16667,40.41279
136.00000,113.33336,40.26442
136.20002,113.49992,40.64456
136.40002,113.66667,40.47644
136.60000,113.83324,40.72369
136.80000,113.99992,40.70576
137.00000,114.16674,40.75358
137.20002,114.33329,40.59796
137.40002,114.49993,40.70835
137.60000,114.66674,40.82169
137.80000,114.83330,40.71281
138.00000,114.99993,41.07453
138.20002,115.16673,41.08115
138.40002,115.33336,41.12804
138.60000,115.49986,41.01720
138.80000,115.66673,41.07487
139.00000,115.83329,41.43860
139.20002,115.99992,41.09575
139.40002,116.16673,41.21384
139.60000,116.33329,41.30811
139.80000,116.49992,41.35251
140.00000,116.66667,41.44610
140.20002,116.83330,41.53150
140.40002,116.99992,41.58736
140.60000,117.16680,41.74367
140.80000,117.33330,41.76920
141.00000,117.49987,41.75534
141.20002,117.66673,41.81237
141.40002,117.83343,41.89832
141.60000,117.99992,41.87107
141.80000,118.16661,41.95119
142.00000,118.33330,41.96545
142.20002,118.49998,42.11147
142.40002,118.66674,42.03488
142.60000,118.83330,42.24832
142.80000,118.99993,42.31482
143.00000,119.16674,42.30776
143.20002,119.33330,42.52105
143.40002,119.49986,42.26239
143.60000,119.66674,42.54521
143.80000,119.83329,42.65831
144.00000,119.99992,42.50297
144.20002,120.16661,42.45574
144.40002,120.33336,42.46598
144.60000,120.49992,42.65120
144.80000,120.66667,42.62043
145.00000,120.83329,42.74802
145.20002,120.99992,42.88032
145.40002,121.16673,42.78066
145.60000,121.33336,43.01752
145.80000,121.49992,42.90482
146.00000,121.66673,43.11714
146.20002,121.83324,43.05481
146.40002,121.99992,43.14056
146.60000,122.16673,43.23591
146.80000,122.33330,43.20465
147.00000,122.49992,43.22347
147.20002,122.66673,43.23866
147.40002,122.83330,43.28928
147.60000,122.99986,43.49909
147.80000,123.16674,43.42765
148.00000,123.33330,43.50414
148.20002,123.49992,43.75350
148.40002,123.66667,43.64644
148.60000,123.83330,43.56240
148.80000,123.99992,43.62541
149.00000,124.16679,43.56123
149.20002,124.33330,43.82886
149.40002,124.49986,43.81656
149.60000,124.66667,43.89369
149.80000,124.83336,43.86443
150.00000,124.99986,43.84537
150.20002,125.16679,44.09454
150.40002,125.33336,43.94969
150.60000,125.49992,44.02623
150.80000,125.66666,44.22958
151.00000,125.83329,44.26315
151.20002,125.99992,44.43327
151.40002,126.16673,44.28427
151.60000,126.33330,44.35928
151.80000,126.49985,44.51594
152.00000,126.66667,44.57434
152.20002,126.83329,44.42377
152.40002,126.99991,44.64373
152.60000,127.16680,44.56881
152.80000,127.33328,44.65843
153.00000,127.49985,44.61918
153.20002,127.66679,44.84409
153.40002,127.83336,45.02147
153.60000,127.99992,44.80949
153.80000,128.16667,44.95738
154.00000,128.33335,45.04249
154.20002,128.49991,45.03823
154.40002,128.66673,45.16224
154.60000,128.83330,45.20801
154.80000,128.99992,45.43968
155.00000,129.16666,45.35883
155.20002,129.33329,45.21002
155.40002,129.49991,45.47967
155.60000,129.66673,45.64852
155.80000,129.83330,45.39656
156.00000,129.99992,45.57291
156.20002,130.16673,45.61290
156.40002,130.33335,45.86329
156.60000,130.49997,45.81311
156.80000,130.66666,45.60942
157.00000,130.83328,45.78185
157.20002,130.99985,45.97481
157.40002,131.16673,45.69335
157.60000,131.33329,45.99215
157.80000,131.49998,46.21442
158.00000,131.66673,46.01602
158.20002,131.83328,45.89195
158.40002,131.99992,46.07521
158.60000,132.16673,46.15949
158.80000,132.33329,46.19070
159.00000,132.49992,46.26337
159.20002,132.66672,46.34976
159.40002,132.83329,46.28018
159.60000,132.99986,46.38670
159.80000,133.16673,46.50327
160.00000,133.33336,46.61882
160.20002,133.49992,46.67227
160.40002,133.66672,46.67335
160.60000,133.83335,46.77101
160.80000,133.99998,46.86862
161.00002,134.16673,46.83721
161.20002,134.33329,46.89856
161.40002,134.49985,46.96083
161.60000,134.66673,46.97656
161.80000,134.83335,47.05144
162.00002,134.99992,46.85749
162.20002,135.16666,47.10274
162.40002,135.33336,47.16487
162.60000,135.49991,47.43349
162.80000,135.66673,47.23352
163.00002,135.83330,47.29839
163.20002,135.99992,47.25077
163.40002,136.16673,47.48454
163.60000,136.33328,47.31530
163.80000,136.49992,47.43324
164.00002,136.66679,47.36930
164.20002,136.83329,47.64654
164.40002,136.99985,47.82769
164.60000,137.16673,47.89546
164.80000,137.33329,47.65800
165.00002,137.49997,47.79025
165.20002,137.66673,48.15251
165.40002,137.83336,48.00100
165.60000,137.99985,47.99708
165.80000,138.16667,48.03663
166.00002,138.33336,48.02947
166.20002,138.49998,48.23850
166.40002,138.66673,48.18838
166.60000,138.83329,48.21121
166.80000,138.99999,48.24311
167.00002,139.16679,48.38609
167.20002,139.33330,48.36243
167.40002,139.49992,48.45847
167.60000,139.66672,48.49438
167.80000,139.83329,48.52569
168.00002,139.99986,48.54632
168.20002,140.16673,48.65339
168.40002,140.33335,48.54221
168.60000,140.49992,48.67171
168.80000,140.66666,48.60816
169.00002,140.83323,48.86448
169.20002,140.99997,48.96532
169.40002,141.16674,48.79588
169.60000,141.33330,48.89226
169.80000,141.49985,49.10497
170.00002,141.66673,49.00094
170.20002,141.83335,49.09982
170.40002,141.99997,49.12741
170.60000,142.16679,48.95625
170.80000,142.33328,49.23492
171.00002,142.49985,49.25937
171.20002,142.66673,49.30959
171.40002,142.83336,49.30288
171.60000,142.99992,49.39607
171.80000,143.16672,49.53999
172.00002,143.33329,49.50888
172.20002,143.49985,49.69306
172.40002,143.66667,49.81895
172.60000,143.83336,49.67194
172.80000,143.99992,49.63637
173.00002,144.16672,49.64941
173.20002,144.33323,49.83551
173.40002,144.49986,49.81071
173.60000,144.66673,49.97608
173.80000,144.83330,49.77445
174.00002,144.99985,49.96570
174.20002,145.16673,50.12064
174.40002,145.33329,49.88774
174.60000,145.49992,50.12891
174.80000,145.66674,50.14440
175.00002,145.83329,50.27254
175.20002,145.99991,50.38695
175.40002,146.16667,50.42958
175.60000,146.33330,50.33996
175.80000,146.49992,50.39425
176.00002,146.66672,50.54140
176.20002,146.83323,50.60701
176.40002,146.99985,50.45217
176.60000,147.16673,50.68443
176.80000,147.33336,50.60113
177.00002,147.49992,50.69952
177.20002,147.66673,50.91277
177.40002,147.83329,50.54380
177.60000,147.99992,50.88494
177.80000,148.16673,50.96882
178.00002,148.33336,50.92884
178.20002,148.49992,51.04434
178.40002,148.66672,51.07765
178.60000,148.83324,51.15840
178.80000,148.99998,51.06486
179.00002,149.16673,51.08936
179.20002,149.33328,51.21368
179.40002,149.49991,51.27850
179.60000,149.66673,51.19535
179.80000,149.83329,51.44319
180.00002,149.99986,51.45730
180.20002,150.16672,51.33961
180.40002,150.33329,51.69412
180.60000,150.49986,51.65365
180.80000,150.66673,51.43133
181.00002,150.83335,51.55388
181.20002,150.99998,51.66707
181.40002,151.16672,51.82765
181.60000,151.33323,51.61660
181.80000,151.49985,51.83872
182.00002,151.66673,51.75556
182.20002,151.83336,52.01384
182.40002,151.99984,51.92324
182.60000,152.16673,52.21146
182.80000,152.33329,52.03682
183.00002,152.49992,52.19461
183.20002,152.66674,52.07299
183.40002,152.83336,52.03045
183.60000,152.99985,52.27217
183.80000,153.16673,52.36493
184.00002,153.33329,52.43059
184.20002,153.49992,52.33842
184.40002,153.66673,52.49517
184.60000,153.83336,52.66231
184.80000,153.99992,52.45651
185.00002,154.16673,52.60371
185.20002,154.33329,52.49664
185.40002,154.49992,52.65271
185.60000,154.66680,52.67730
185.80000,154.83329,52.93058
186.00002,154.99986,52.96336
186.20002,155.16673,52.89085
186.40002,155.33336,53.12663
186.60000,155.49992,53.00830
186.80000,155.66672,52.94675
187.00002,155.83323,53.11649
187.20002,155.99991,53.13579
187.40002,156.16673,53.28005
187.60000,156.33335,53.26834
187.80000,156.49999,53.16745
188.00002,156.66673,53.22634
188.20002,156.83329,53.58385
188.40002,156.99992,53.19097
188.60000,157.16679,53.25124
188.80000,157.33328,53.20062
189.00002,157.49991,53.16907
189.20002,157.66673,53.38996
189.40002,157.83329,53.45086
189.60000,157.99992,53.52348
189.80000,158.16679,53.55004
190.00002,158.33328,53.62628
190.20002,158.49991,53.95767
190.40002,158.66667,53.85173
190.60000,158.83336,53.85457
190.80000,158.99992,53.74011
191.00002,159.16672,53.77152
191.20002,159.33329,53.97163
191.40002,159.49985,54.05410
191.60000,159.66672,54.04925
191.80000,159.83330,54.12956
192.00002,159.99991,54.24162
192.20002,160.16671,54.16332
192.40002,160.33335,54.13083
192.60000,160.49985,54.42072
192.80000,160.66672,54.36868
193.00002,160.83336,54.43576
193.20002,160.99991,54.45796
193.40002,161.16666,54.50485
193.60000,161.33329,54.64837
193.80000,161.49985,54.32806
194.00002,161.66680,54.70354
194.20002,161.83328,54.85917
194.40002,161.99986,54.61628
194.60000,162.16673,54.83193
194.80000,162.33329,54.85118
195.00002,162.49992,54.99176
195.20002,162.66678,54.82208
195.40002,162.83328,54.90680
195.60000,162.99985,55.00666
195.80000,163.16667,55.21799
196.00002,163.33336,55.02410
196.20002,163.49992,55.11220
196.40002,163.66672,55.13234
196.60000,163.83329,55.20711
196.80000,163.99991,55.33515
197.00002,164.16673,55.30007
197.20002,164.33328,55.42433
197.40002,164.49990,55.40645
197.60000,164.66672,55.53424
197.80000,164.83329,55.30325
198.00002,164.99985,55.52248
198.20002,165.16672,55.50229
198.40002,165.33334,55.51905
198.60000,165.49984,55.91271
198.80000,165.66673,55.79242
199.00002,165.83329,55.88630
199.20002,165.99992,55.81496
199.40002,166.16672,55.91462
199.60000,166.33328,55.86842
199.80000,166.49991,55.82491
200.00002,166.66673,55.84524
200.20002,166.83334,56.15257
200.40002,166.99992,56.09857
200.60000,167.16672,55.92070
200.80000,167.33328,56.13625
201.00002,167.49986,56.25189
201.20002,167.66673,56.29084
201.40002,167.83336,56.36307
201.60000,167.99998,56.14948
201.80000,168.16672,56.31373
202.00002,168.33322,56.21592
202.20002,168.49991,56.39688
202.40002,168.66671,56.33955
202.60000,168.83334,56.55049
202.80000,168.99997,56.47577
203.00002,169.16666,56.52487
203.20002,169.33335,56.57676
203.40002,169.49991,56.56618
203.60000,169.66673,56.51105
203.80000,169.83334,56.64085
204.00002,169.99984,56.76061
204.20002,170.16666,56.90692
204.40002,170.33329,56.75433
204.60000,170.49985,56.86841
204.80000,170.66672,56.83264
205.00002,170.83328,56.92284
205.20002,170.99986,56.88776
205.40002,171.16673,57.08072
205.60000,171.33322,57.18337
205.80000,171.49990,56.94274
206.00002,171.66678,57.24953
206.20002,171.83328,57.15349
206.40002,171.99986,57.18289
206.60000,172.16671,57.27026
206.80000,172.33329,57.25399
207.00002,172.49998,57.45748
207.20002,172.66672,57.43323
207.40002,172.83330,57.51172
207.60000,172.99986,57.45185
207.80000,173.16671,57.52491
208.00002,173.33334,57.50923
208.20002,173.49990,57.69366
208.40002,173.66672,57.66328
208.60000,173.83330,57.69748
208.80000,173.99991,57.93038
209.00002,174.16673,57.97266
209.20002,174.33329,57.69312
209.40002,174.49992,57.98668
209.60000,174.66674,58.15088
209.80000,174.83335,58.17019
210.00002,174.99991,57.98545
210.20002,175.16673,57.99035
210.40002,175.33328,58.20096
210.60000,175.49979,58.35016
210.80000,175.66673,58.19292
211.00002,175.83327,58.32464
211.20002,175.99998,58.35952
211.40002,176.16672,58.43380
211.60000,176.33323,58.40617
211.80000,176.49986,58.39338
212.00002,176.66671,58.44826
212.20002,176.83329,58.53954
212.40002,176.99996,58.52779
212.60000,177.16678,58.67547
212.80000,177.33330,58.61020
213.00002,177.49984,58.85197
213.20002,177.66679,58.72217
213.40002,177.83340,58.77474
213.60000,177.99990,58.77083
213.80000,178.16665,58.88965
214.00002,178.33328,58.81301
214.20002,178.49991,58.84491
214.40002,178.66673,59.21677
214.60000,178.83329,58.91738
214.80000,178.99984,59.18659
215.00002,179.16674,59.03214
215.20002,179.33328,59.24019
215.40002,179.49991,59.23529
215.60000,179.66673,59.01886
215.80000,179.83329,59.13617
216.00002,179.99986,59.25127
216.20002,180.16672,59.39386
216.40002,180.33335,59.30727
216.60000,180.49991,59.51611
216.80000,180.66673,59.57702
217.00002,180.83328,59.54835
217.20002,180.99992,59.37892
217.40002,181.16672,59.38386
217.60000,181.33329,59.59035
217.80000,181.49985,59.82849
218.00002,181.66665,59.56016
218.20002,181.83330,59.74768
218.40002,181.99991,59.79830
218.60000,182.16671,59.56977
218.80000,182.33329,59.86195
219.00002,182.49985,59.74729
219.20002,182.66665,59.99406
219.40002,182.83328,60.00199
219.60000,182.99991,59.90106
219.80000,183.16673,59.87494
220.00002,183.33329,60.06795
220.20002,183.49992,59.93555
220.40002,183.66672,60.11563
220.60000,183.83328,60.23528
220.80000,183.99991,60.20701
221.00002,184.16673,60.30854
221.20002,184.33321,60.28458
221.40002,184.49992,60.36200
221.60000,184.66672,60.40659
221.80000,184.83328,60.37763
222.00002,184.99985,60.42785
222.20002,185.16673,60.56770
222.40002,185.33321,60.64390
222.60000,185.49992,60.62258
222.80000,185.66672,60.54295
223.00002,185.83329,60.71049
223.20002,185.99991,60.61327
223.40002,186.16673,60.88022
223.60000,186.33328,60.75571
223.80000,186.49997,60.92829
224.00002,186.66672,60.98067
224.20002,186.83329,60.92358
224.40002,186.99985,61.14061
224.60000,187.16672,61.14403
224.80000,187.33328,61.21141
225.00002,187.49991,61.06618
225.20002,187.66671,61.05265
225.40002,187.83335,61.28795
225.60000,187.99985,61.19411
225.80002,188.16665,61.29951
226.00002,188.33334,61.30750
226.20002,188.49991,61.38575
226.40002,188.66673,61.34087
226.60000,188.83329,61.38423
226.80002,188.99985,61.66094
227.00002,189.16672,61.49208
227.20002,189.33328,61.75982
227.40002,189.49991,61.57715
227.60000,189.66679,61.69484
227.80002,189.83327,61.76104
228.00002,189.99984,61.82087
228.20002,190.16672,61.83763
228.40002,190.33335,61.68186
228.60000,190.49991,61.87002
228.80002,190.66665,62.00202
229.00002,190.83329,61.99614
229.20002,190.99990,62.12364
229.40002,191.16672,61.91152
229.60000,191.33329,62.08395
229.80002,191.49985,61.84943
230.00002,191.66665,62.13859
230.20002,191.83328,62.04235
230.40002,191.99997,62.15887
230.60000,192.16672,61.98036
230.80002,192.33329,62.17617
231.00002,192.49983,62.25746
231.20002,192.66672,62.41019
231.40002,192.83339,62.31185
231.60000,192.99991,62.38936
231.80002,193.16673,62.28975
232.00002,193.33327,62.25173
232.20002,193.49985,62.33414
232.40002,193.66672,62.41499
232.60000,193.83334,62.57953
232.80002,193.99991,62.75613
233.00002,194.16679,62.65896
233.20002,194.33321,62.52098
233.40002,194.49979,62.70742
233.60000,194.66672,62.78720
233.80002,194.83335,62.78142
234.00002,194.99991,62.82507
234.20002,195.16665,62.80469
234.40002,195.33329,62.82497
234.60000,195.49990,62.97467
234.80002,195.66672,63.05469
235.00002,195.83330,63.00363
235.20002,195.99991,63.17371
235.40002,196.16665,63.08095
235.60000,196.33334,62.96820
235.80002,196.49984,63.09334
236.00002,196.66672,63.20580
236.20002,196.83328,63.31095
236.40002,196.99983,63.16062
236.60000,197.16673,63.45948
236.80002,197.33334,63.41645
237.00002,197.49992,63.52116
237.20002,197.66673,63.35682
237.40002,197.83327,63.48250
237.60000,197.99991,63.75470
237.80002,198.16678,63.56267
238.00002,198.33341,63.54400
238.20002,198.49991,63.48221
238.40002,198.66666,63.78111
238.60000,198.83327,63.71241
238.80002,198.99990,63.90807
239.00002,199.16672,63.91831
239.20002,199.33328,63.93061
239.40002,199.49991,64.04590
239.60000,199.66666,64.12303
239.80002,199.83329,64.02013
240.00002,199.99985,64.04875
240.20002,200.16672,63.98666
240.40002,200.33328,64.11475
240.60000,200.49991,64.07276
240.80002,200.66665,64.08648
241.00002,200.83334,64.37023
241.20002,200.99990,64.26871
241.40002,201.16672,64.08089
241.60000,201.33328,64.24239
241.80002,201.49991,64.18374
242.00002,201.66673,64.24073
242.20002,201.83329,64.29982
242.40002,201.99992,64.34172
242.60000,202.16666,64.33025
242.80002,202.33328,64.34274
243.00002,202.49991,64.46843
243.20002,202.66678,64.58187
243.40002,202.83334,64.64125
243.60000,202.99979,64.57642
243.80002,203.16666,64.61567
244.00002,203.33327,64.77042
244.20002,203.49991,64.72343
244.40002,203.66672,65.01316
244.60000,203.83328,64.89032
244.80002,203.99997,64.95554
245.00002,204.16671,64.99552
245.20002,204.33329,65.05662
245.40002,204.49990,64.94897
245.60000,204.66678,64.99993
245.80002,204.83328,64.98562
246.00002,204.99984,65.09185
246.20002,205.16671,65.18657
246.40002,205.33334,65.04781
246.60000,205.49990,65.23969
246.80002,205.66665,65.23660
247.00002,205.83328,65.38639
247.20002,205.99984,65.28099
247.40002,206.16673,65.39085
247.60000,206.33329,65.30212
247.80002,206.49984,65.39286
248.00002,206.66672,65.39105
248.20002,206.83333,65.69803
248.40002,206.99991,65.62257
248.60000,207.16678,65.63659
248.80002,207.33334,65.59856
249.00002,207.49992,65.68005
249.20002,207.66666,65.72312
249.40002,207.83335,65.74600
249.60000,207.99991,65.79005
249.80002,208.16673,65.67304
250.00002,208.33328,65.71645
250.20002,208.49984,65.91084
250.40002,208.66666,65.88815
250.60000,208.83329,66.00335
250.80002,208.99996,65.94690
251.00002,209.16665,65.96851
251.20002,209.33323,65.98385
251.40002,209.49984,66.19455
251.60000,209.66671,65.93798
251.80002,209.83329,66.19616
252.00002,209.99990,66.40280
252.20002,210.16672,66.35042
252.40002,210.33334,66.31279
252.60000,210.49984,66.52035
252.80002,210.66673,66.09557
253.00002,210.83329,66.52466
253.20002,210.99992,66.56386
253.40002,211.16672,66.72953
253.60000,211.33328,66.38467
253.80002,211.49985,66.56425
254.00002,211.66673,66.65451
254.20002,211.83334,66.74766
254.40002,211.99984,66.78588
254.60000,212.16666,66.74031
254.80002,212.33328,66.85203
255.00002,212.49996,66.71096
255.20002,212.66671,66.87815
255.40002,212.83329,66.67161
255.60000,212.99984,66.83287
255.80002,213.16672,66.86624
256.00000,213.33335,66.98678
256.20002,213.49991,66.88354
256.40003,213.66671,67.03426
256.60000,213.83328,67.27504
256.80002,213.99984,67.06738
257.00000,214.16672,67.02088
257.20002,214.33335,67.07605
257.40003,214.49991,66.99089
257.60000,214.66672,67.02191
257.80002,214.83328,67.19640
258.00000,214.99991,67.09424
258.20002,215.16679,67.41881
258.40003,215.33335,67.07218
258.60000,215.49985,67.40523
258.80002,215.66667,67.33423
259.00000,215.83334,67.53734
259.20002,215.99991,67.49025
259.40003,216.16671,67.49094
259.60000,216.33327,67.70683
259.80002,216.49985,67.39666
260.00000,216.66672,67.78807
260.20002,216.83328,67.60780
260.40003,216.99991,67.89685
260.60000,217.16671,67.81938
260.80002,217.33329,67.76950
261.00000,217.49984,67.63593
261.20002,217.66672,67.78283
261.40003,217.83330,67.80517
261.60000,217.99991,68.08187
261.80002,218.16671,67.94076
262.00000,218.33329,68.01758
262.20000,218.49990,68.13808
262.40003,218.66672,68.14220
262.60000,218.83335,68.02165
262.80003,218.99998,68.03038
263.00000,219.16673,68.19585
263.20000,219.33323,67.96378
263.40003,219.49984,68.21726
263.60000,219.66679,68.22579
263.80003,219.83327,68.30022
264.00000,219.99985,68.33790
264.20000,220.16672,68.28096
264.40003,220.33328,68.43933
264.60000,220.49991,68.46476
264.80003,220.66671,68.32482
265.00000,220.83327,68.28518
265.20000,220.99990,68.44026
265.40003,221.16672,68.32721
265.60000,221.33328,68.53826
265.80003,221.49997,68.61789
266.00000,221.66671,68.55600
266.20000,221.83329,68.53909
266.40003,221.99990,68.85396
266.60000,222.16678,68.67718
266.80003,222.33335,68.73686
267.00000,222.49991,68.86930
267.20000,222.66671,69.00885
267.40003,222.83329,68.85960
267.60000,222.99984,68.74239
267.80003,223.16672,68.61627
268.00000,223.33335,68.87131
268.20000,223.49991,68.82594
268.40003,223.66673,68.84539
268.60000,223.83329,68.91125
268.80003,223.99992,69.14375
269.00000,224.16672,68.94707
269.20000,224.33328,68.98813
269.40003,224.49985,69.11028
269.60000,224.66673,69.17379
269.80003,224.83328,68.97813
270.00000,224.99992,69.23160
270.20000,225.16672,69.37155
270.40003,225.33335,69.13767
270.60000,225.49985,69.27478
270.80003,225.66667,69.49934
271.00000,225.83336,69.41300
271.20000,225.99991,69.55143
271.40003,226.16671,69.40860
271.60000,226.33322,69.67118
271.80003,226.49985,69.54300
272.00000,226.66672,69.66849
272.20000,226.83335,69.67726
272.40003,226.99989,69.75047
272.60000,227.16671,69.70583
272.80003,227.33329,69.72954
273.00000,227.49985,69.87620
273.20000,227.66672,69.78986
273.40003,227.83333,70.01114
273.60000,227.99991,69.83734
273.80003,228.16673,69.63497
274.00000,228.33329,69.91334
274.20000,228.49992,69.89531
274.40003,228.66672,69.76262
274.60000,228.83333,69.75468
274.80003,228.99991,69.72636
275.00000,229.16667,67.30895
275.20000,229.33329,0.12232
275.40003,229.49997,-0.10847
275.60000,229.66672,0.00634
275.80003,229.83322,0.10821
276.00000,229.99985,0.04720
276.20000,230.16673,0.05490
276.40003,230.33328,0.12017
276.60000,230.49990,-0.07902
276.80003,230.66672,0.08244
277.00000,230.83329,-0.06579
277.20000,230.99991,-0.04026
277.26603,231.05497,0.09312