File: EPR/EPR/RDSO EPR Tensile 50.is_tens_RawData/Specimen_RawData_6.csv
Time,Extension,Load
(sec),(mm),(N)
0.00000,0.00000,2.94943
0.30000,0.24925,3.51934
0.60000,0.49994,4.03276
0.90000,0.74994,4.13566
1.20000,0.99994,4.58127
1.50000,1.24994,4.60067
1.80000,1.49987,5.06348
2.10000,1.74994,5.49443
2.40000,1.99994,5.62575
2.70000,2.24987,6.06420
3.00000,2.49994,6.06714
3.30000,2.74994,6.41886
3.60000,2.99994,6.60393
3.90000,3.24987,6.81997
4.20000,3.49994,7.04052
4.50000,3.74994,7.13651
4.80000,3.99994,7.20286
5.10000,4.24994,7.52444
5.40000,4.49994,7.52880
5.70000,4.75000,7.87871
6.00000,4.99987,8.07476
6.30000,5.24994,8.21740
6.60000,5.50000,8.47122
6.90000,5.74994,8.38669
7.20000,5.99994,8.65605
7.50000,6.24994,8.71230
7.80000,6.49994,9.04275
8.10000,6.74994,9.23429
8.40000,6.99987,9.30265
8.70000,7.24994,9.43686
9.00000,7.49994,9.66285
9.30000,7.74994,9.69048
9.60000,7.99987,9.89011
9.90000,8.25000,10.25212
10.20000,8.49981,10.00447
10.50000,8.74994,10.42406
10.80000,8.99987,10.31572
11.10000,9.24994,10.40431
11.40000,9.49994,10.71624
11.70000,9.74987,10.84472
12.00000,10.00000,10.84031
12.30000,10.24994,11.06454
12.60000,10.49994,11.23584
12.90000,10.74994,11.21526
13.20000,10.99994,11.43502
13.50000,11.24987,11.55159
13.80000,11.49987,11.55434
14.10000,11.74994,11.51205
14.40000,11.99987,11.60682
14.70000,12.24994,11.97304
15.00000,12.49994,11.72010
15.30000,12.74987,12.14885
15.60000,12.99994,12.18291
15.90000,13.24987,12.25925
16.20000,13.49994,12.15223
16.50000,13.74987,12.32471
16.80000,13.99987,12.27091
17.10000,14.24994,12.48749
17.40000,14.50000,12.47558
17.70000,14.74994,12.78546
18.00000,14.99994,12.74131
18.30000,15.24994,12.95073
18.60000,15.50000,12.86185
18.90000,15.74987,12.93079
19.20000,15.99994,13.04281
19.50000,16.24993,13.21524
19.80000,16.49987,13.07074
20.10000,16.74994,13.25164
20.40000,16.99987,13.52697
20.70000,17.24993,13.45588
21.00000,17.49994,13.60121
21.30000,17.74987,13.64154
21.60000,17.99993,13.72072
21.90000,18.24994,13.73625
22.20000,18.49987,13.73895
22.50000,18.74994,13.82328
22.80000,18.99993,13.89516
23.10000,19.24993,13.78868
23.40000,19.49994,13.95440
23.70000,19.74993,13.92422
24.00000,19.99993,14.06146
24.30000,20.24987,14.19518
24.60000,20.49993,14.05191
24.90000,20.74993,14.14369
25.20000,20.99993,14.20709
25.50000,21.24987,14.27608
25.80000,21.49994,14.14618
26.10000,21.74993,14.43901
26.40000,21.99987,14.42808
26.70000,22.24993,14.48703
27.00000,22.49993,14.58390
27.30000,22.74993,14.45944
27.60000,22.99994,14.63506
27.90000,23.24993,14.83654
28.20000,23.49993,14.87163
28.50000,23.74987,14.89098
28.80000,23.99993,14.71987
29.10000,24.25000,14.89598
29.40000,24.49993,14.72909
29.70000,24.74987,15.01054
30.00000,24.99999,15.05018
30.30000,25.24993,15.20943
30.60000,25.49981,15.26416
30.90000,25.74987,15.33884
31.20000,25.99993,15.32497
31.50000,26.24993,15.43532
31.80000,26.49987,15.62177
32.10000,26.74993,15.58747
32.40000,26.99994,15.56605
32.70000,27.24993,15.82335
33.00000,27.49993,15.66283
33.30000,27.74987,15.64235
33.60000,28.00000,15.71472
33.90000,28.24987,15.81115
34.20000,28.49987,15.81532
34.50000,28.74993,15.98583
34.80000,28.99987,15.90650
35.10000,29.24993,16.03189
35.40000,29.49993,16.08545
35.70000,29.74994,16.17003
36.00000,29.99993,16.16057
36.30000,30.24987,16.30928
36.60000,30.49993,16.22726
36.90000,30.74993,16.34981
37.20000,30.99993,16.35735
37.50000,31.24993,16.52420
37.80000,31.49993,16.57418
38.10000,31.74993,16.70853
38.40000,31.99993,16.76797
38.70000,32.24999,16.77483
39.00000,32.49993,16.73568
39.30000,32.74993,16.74572
39.60000,32.99993,16.74509
39.90000,33.24993,16.96260
40.20000,33.49993,16.97328
40.50000,33.74987,17.22764
40.80000,33.99981,16.97304
41.10000,34.24987,16.96030
41.40000,34.49987,17.24444
41.70000,34.74993,17.32755
42.00000,34.99993,17.33196
42.30000,35.24987,17.22308
42.60000,35.49987,17.35558
42.90000,35.75000,17.45171
43.20000,35.99993,17.45392
43.50000,36.24987,17.52017
43.80000,36.49993,17.67819
44.10000,36.74993,17.80638
44.40000,36.99993,17.82990
44.70000,37.24993,17.84891
45.00000,37.49993,17.92162
45.30000,37.74993,17.91378
45.60000,37.99993,17.86268
45.90000,38.24987,18.21641
46.20000,38.49993,18.05755
46.50000,38.74987,18.24870
46.80000,38.99987,18.32827
47.10000,39.24993,18.30005
47.40000,39.49993,18.33665
47.70000,39.74987,18.40564
48.00000,39.99987,18.62149
48.30000,40.24993,18.33004
48.60000,40.49993,18.59606
48.90000,40.74987,18.75609
49.20000,40.99987,18.69278
49.50000,41.24993,18.83562
49.80000,41.49993,19.00075
50.10000,41.74993,18.73242
50.40000,41.99993,18.92592
50.70000,42.24993,18.90245
51.00000,42.49987,19.17435
51.30000,42.74987,19.27137
51.60000,42.99993,19.37290
51.90000,43.24993,19.26495
52.20000,43.49987,19.32150
52.50000,43.74993,19.51015
52.80000,43.99987,19.35747
53.10000,44.24993,19.47614
53.40000,44.49987,19.51084
53.70000,44.74993,19.90553
54.00000,44.99999,19.60893
54.30000,45.24987,19.67489
54.60000,45.49993,20.03234
54.90000,45.74993,20.07688
55.20000,45.99987,20.06747
55.50000,46.24993,20.04680
55.80000,46.49993,20.16003
56.10000,46.74993,20.26303
56.40000,46.99986,20.36383
56.70000,47.24993,20.34256
57.00000,47.49993,20.38999
57.30000,47.74987,20.45957
57.60000,47.99993,20.44345
57.90000,48.24993,20.65214
58.20000,48.49993,20.77072
58.50000,48.74987,20.61171
58.80000,48.99987,20.85716
59.10000,49.24993,20.95785
59.40000,49.49987,21.10960
59.70000,49.74993,21.05423
60.00000,49.99993,21.05781
60.30000,50.24993,21.21735
60.60000,50.49993,21.36690
60.90000,50.74987,21.42604
61.20000,50.99993,21.61190
61.50000,51.24993,21.69383
61.80000,51.49987,21.51738
62.10000,51.74993,21.50278
62.40000,51.99993,21.66291
62.70000,52.24986,21.82265
63.00000,52.49986,21.98660
63.30000,52.74993,21.99224
63.60000,52.99993,21.87008
63.90000,53.24987,22.05883
64.20000,53.49993,22.01144
64.50000,53.74993,21.91908
64.80000,53.99993,22.24635
65.10001,54.24987,22.25086
65.40000,54.49993,22.31980
65.70001,54.74993,22.48194
66.00000,54.99993,22.55132
66.30000,55.24993,22.54035
66.60001,55.49993,22.58200
66.90000,55.74993,22.64923
67.20001,55.99987,22.75325
67.50000,56.24993,22.79402
67.80000,56.49987,23.03476
68.10001,56.74993,23.02089
68.40000,56.99987,22.96846
68.70001,57.24987,22.97346
69.00000,57.49993,23.40083
69.30000,57.74980,23.30303
69.60001,57.99993,23.43185
69.90000,58.24993,23.37952
70.20001,58.49987,23.36036
70.50000,58.74987,23.59487
70.80000,58.99993,23.70213
71.10001,59.24999,23.75207
71.40000,59.49981,23.80793
71.70001,59.74993,23.99819
72.00000,59.99999,24.10776
72.30000,60.24987,23.98972
72.60001,60.49993,24.07145
72.90000,60.74993,24.16680
73.20001,60.99987,24.40175
73.50000,61.24993,24.46526
73.80000,61.49987,24.42924
74.10001,61.74993,24.70031
74.40000,61.99987,24.56262
74.70001,62.24987,24.56262
75.00000,62.49993,24.60265
75.30000,62.74993,24.65832
75.60001,62.99987,24.78905
75.90000,63.24986,24.91767
76.20001,63.49993,25.29247
76.50000,63.74992,25.17237
76.80000,63.99986,25.18448
77.10001,64.24987,25.30649
77.40000,64.49993,25.40718
77.70001,64.74993,25.43222
78.00000,64.99992,25.60490
78.30000,65.24993,25.42281
78.60001,65.49987,25.69109
78.90000,65.74986,25.78287
79.20001,65.99993,25.85298
79.50000,66.24993,25.84211
79.80000,66.49987,25.78090
80.10001,66.74992,26.34357
80.40000,66.99986,26.18652
80.70001,67.24992,26.23106
81.00001,67.49993,26.16154
81.30000,67.74993,26.28526
81.60001,67.99986,26.49228
81.90000,68.24993,26.51953
82.20001,68.49993,26.69073
82.50001,68.74993,26.59303
82.80000,68.99980,26.63311
83.10001,69.24986,26.93020
83.40000,69.49992,26.76585
83.70001,69.74999,26.96410
84.00001,69.99987,27.05245
84.30000,70.24986,27.28677
84.60001,70.49993,27.14099
84.90000,70.74993,27.20714
85.20001,70.99986,27.22978
85.50001,71.24993,27.35414
85.80000,71.49993,27.51653
86.10001,71.74992,27.48776
86.40000,71.99986,27.47890
86.70001,72.24993,27.94925
87.00001,72.49992,27.78598
87.30000,72.74986,28.00074
87.60001,72.99987,27.83419
87.90000,73.24993,28.20360
88.20001,73.49993,28.29690
88.50001,73.74987,28.33968
88.80000,73.99987,28.45433
89.10001,74.24993,28.34124
89.40000,74.49986,28.34031
89.70001,74.74986,28.61633
90.00001,74.99993,28.63608
90.30000,75.24987,28.75426
90.60001,75.49986,28.65053
90.90000,75.74987,28.78557
91.20001,75.99992,28.94056
91.50001,76.24993,29.23079
91.80000,76.49980,29.16694
92.10001,76.74999,29.39567
92.40000,76.99999,29.34216
92.70001,77.24993,29.43914
93.00001,77.49987,29.62920
93.30000,77.74992,29.69609
93.60001,77.99999,29.70790
93.90000,78.24986,29.86793
94.20001,78.49980,29.85240
94.50001,78.74993,29.82594
94.80000,78.99993,29.93399
95.10001,79.24993,30.07927
95.40000,79.49992,29.94971
95.70001,79.74993,30.11729
96.00001,79.99986,30.27473
96.30000,80.24986,30.38062
96.60001,80.49986,30.56128
96.90000,80.74986,30.48636
97.20001,80.99986,30.50037
97.50001,81.24992,30.71916
97.80000,81.49993,30.59259
98.10001,81.74992,31.01914
98.40000,81.99993,30.89634
98.70001,82.24999,31.02987
99.00001,82.49986,31.06078
99.30000,82.74986,31.05054
99.60001,82.99992,31.11395
99.90000,83.24986,31.44499
100.20001,83.49986,31.22944
100.50001,83.74986,31.37977
100.80000,83.99987,31.40021
101.10001,84.24993,31.73586
101.40000,84.49992,31.61335
101.70001,84.74993,31.93514
102.00001,84.99992,31.90530
102.30000,85.24993,32.09728
102.60001,85.49985,32.02491
102.90000,85.74992,32.22669
103.20001,85.99993,32.14995
103.50001,86.24992,32.48604
103.80000,86.49993,32.58635
104.10001,86.74992,32.69258
104.40000,86.99981,32.67038
104.70001,87.24992,32.62172
105.00001,87.49993,32.61761
105.30000,87.74986,32.88833
105.60001,87.99986,33.02024
105.90000,88.24993,32.98398
106.20001,88.49992,32.99388
106.50001,88.74992,33.08619
106.80000,88.99986,33.23089
107.10001,89.24986,33.32203
107.40000,89.49992,33.34903
107.70001,89.74986,33.51146
108.00001,89.99986,33.66307
108.30000,90.24986,33.75676
108.60001,90.49992,33.46452
108.90000,90.74987,33.95766
109.20001,90.99992,33.72270
109.50001,91.24992,34.00528
109.80000,91.49986,34.12362
110.10001,91.74986,34.01063
110.40000,91.99993,34.24749
110.70001,92.24986,34.21770
111.00001,92.49986,34.37161
111.30000,92.74987,34.40586
111.60001,92.99998,34.48416
111.90000,93.24992,34.59549
112.20001,93.49986,34.67756
112.50001,93.74992,34.79114
112.80000,93.99986,34.87204
113.10001,94.24992,35.08348
113.40001,94.49986,34.83563
113.70001,94.74993,35.07035
114.00001,94.99992,35.01282
114.30000,95.24986,35.08989
114.60001,95.49987,35.13022
114.90001,95.74998,35.33127
115.20001,95.99992,35.64031
115.50001,96.24992,35.40198
115.80000,96.49992,35.53045
116.10001,96.74992,35.62992
116.40001,96.99985,35.90898
116.70001,97.24986,36.00908
117.00001,97.49993,35.92519
117.30000,97.74987,36.11262
117.60001,97.99986,36.13301
117.90001,98.24986,36.31719
118.20001,98.49992,36.17490
118.50001,98.74986,36.32337
118.80000,98.99992,36.56004
119.10001,99.24993,36.78122
119.40001,99.49992,36.62540
119.70001,99.74986,36.73835
120.00001,99.99992,36.84007
120.30000,100.24992,36.84458
120.60001,100.49992,36.85463
120.90001,100.74986,36.99971
121.20001,100.99986,37.28607
121.50001,101.24993,37.30905
121.80000,101.49992,37.39191
122.10001,101.74992,37.39108
122.40001,101.99992,37.60050
122.70001,102.24992,37.54484
123.00001,102.49992,37.79812
123.30000,102.74986,37.59741
123.60001,102.99992,37.83849
123.90001,103.24992,37.94693
124.20001,103.49993,38.00622
124.50001,103.74999,38.14249
124.80000,103.99986,38.11240
125.10001,104.24992,38.35304
125.40001,104.49992,38.56447
125.70001,104.74992,38.55066
126.00001,104.99992,38.50842
126.30000,105.24986,38.53777
126.60001,105.49992,38.70006
126.90001,105.74985,38.74332
127.20001,105.99992,38.80257
127.50001,106.24993,39.05776
127.80000,106.49992,38.91571
128.10001,106.74986,39.15071
128.40001,106.99986,39.03556
128.70002,107.24992,39.19084
129.00000,107.49992,39.38326
129.30000,107.74986,39.45603
129.60001,107.99993,39.48910
129.90001,108.24999,39.40423
130.20002,108.49993,39.60288
130.50000,108.74992,39.68966
130.80000,108.99992,39.73508
131.10000,109.24992,40.09155
131.40002,109.49986,39.91222
131.70002,109.74986,39.85758
132.00000,109.99999,40.04221
132.30000,110.24985,40.15682
132.60000,110.49992,40.23282
132.90002,110.74992,40.17681
133.20002,110.99992,40.26452
133.50000,111.24986,40.52628
133.80000,111.49986,40.45156
134.10000,111.74999,40.43181
134.40002,111.99992,40.75315
134.70002,112.24986,40.63428
135.00000,112.49992,40.75820
135.30000,112.74986,40.89927
135.60000,112.99992,41.05764
135.90002,113.24992,41.16730
136.20002,113.49992,41.11903
136.50000,113.74986,41.21855
136.80000,113.99986,41.34208
137.10000,114.24992,41.39226
137.40002,114.49993,41.52451
137.70002,114.74986,41.40176
138.00000,114.99986,41.62476
138.30000,115.24992,41.75456
138.60000,115.49992,41.57895
138.90002,115.74986,41.75284
139.20002,115.99992,42.05194
139.50000,116.24992,42.02455
139.80000,116.49992,42.13700
140.10000,116.74993,42.12279
140.40002,116.99992,42.38529
140.70002,117.24993,42.32654
141.00000,117.49987,42.50377
141.30000,117.74986,42.58565
141.60000,117.99992,42.70878
141.90002,118.24986,42.74637
142.20002,118.49985,42.72309
142.50000,118.74992,42.75215
142.80000,118.99993,42.82379
143.10000,119.24986,43.04375
143.40002,119.49993,43.39042
143.70002,119.74992,43.30967
144.00000,119.99992,43.35882
144.30000,120.24986,43.30477
144.60000,120.49992,43.41267
144.90002,120.74992,43.61151
145.20002,120.99986,43.51669
145.50000,121.24993,43.54835
145.80000,121.49992,43.79080
146.10000,121.74992,43.73141
146.40002,121.99986,43.95470
146.70002,122.24986,44.00797
147.00000,122.49999,43.99493
147.30000,122.74992,44.23199
147.60000,122.99986,44.28408
147.90002,123.24993,44.40633
148.20002,123.49992,44.43627
148.50000,123.74992,44.36013
148.80000,123.99986,44.50850
149.10000,124.24992,44.80936
149.40002,124.49986,44.65315
149.70002,124.74992,44.82406
150.00000,124.99992,44.68338
150.30000,125.24992,44.87541
150.60000,125.49992,45.01192
150.90002,125.74992,45.21615
151.20002,125.99997,45.15961
151.50000,126.24991,45.52069
151.80000,126.49992,45.40377
152.10000,126.74992,45.49031
152.40002,126.99998,45.59585
152.70002,127.24985,45.47355
153.00000,127.49991,45.63300
153.30000,127.74984,45.84546
153.60000,127.99992,45.79871
153.90002,128.24985,45.68043
154.20002,128.49986,45.98109
154.50000,128.74993,46.15333
154.80000,128.99986,46.28969
155.10000,129.24986,46.13936
155.40002,129.49985,46.28126
155.70002,129.74991,46.51328
156.00000,129.99984,46.62103
156.30000,130.24986,46.43385
156.60000,130.49997,46.63803
156.90002,130.74991,46.60741
157.20002,130.99985,46.74176
157.50000,131.24992,46.71878
157.80000,131.49998,46.68831
158.10000,131.74991,46.76161
158.40002,131.99992,47.27165
158.70002,132.24992,47.19011
159.00000,132.49986,47.19109
159.30000,132.74985,47.16885
159.60000,132.99991,47.55977
159.90002,133.24991,47.42556
160.20002,133.49985,47.51890
160.50000,133.74992,47.42669
160.80000,133.99991,47.52174
161.10000,134.24992,47.76346
161.40002,134.49985,47.69648
161.70002,134.74992,48.02390
162.00002,134.99998,47.96485
162.30000,135.24991,47.97671
162.60000,135.49991,48.18599
162.90002,135.74985,48.10318
163.20002,135.99992,48.25875
163.50002,136.24991,48.39438
163.80000,136.49992,48.34602
164.10000,136.74991,48.28795
164.40002,136.99993,48.61263
164.70002,137.24986,48.58592
165.00002,137.49997,48.83215
165.30000,137.74991,48.66824
165.60000,137.99985,48.71328
165.90002,138.24992,48.99370
166.20002,138.49986,48.90976
166.50002,138.74992,49.08362
166.80000,138.99985,49.24208
167.10000,139.24993,49.16922
167.40002,139.49992,49.39349
167.70002,139.74986,49.53814
168.00002,139.99991,49.58611
168.30000,140.24991,49.57964
168.60000,140.49992,49.35978
168.90002,140.74986,49.75354
169.20002,140.99992,49.75187
169.50002,141.24999,49.73022
169.80000,141.49985,49.97355
170.10000,141.74992,49.97330
170.40002,141.99992,50.11864
170.70002,142.24998,50.23717
171.00002,142.49991,50.04857
171.30000,142.74985,50.20042
171.60000,142.99992,50.23256
171.90002,143.24992,50.35766
172.20002,143.49991,50.33487
172.50002,143.74998,50.35070
172.80000,143.99998,50.77200
173.10000,144.24986,50.70178
173.40002,144.49986,50.66204
173.70002,144.74998,50.68772
174.00002,144.99992,50.59952
174.30000,145.24986,51.06326
174.60000,145.49986,51.02322
174.90002,145.74992,51.21628
175.20002,145.99991,51.15003
175.50002,146.24985,51.15287
175.80000,146.49992,51.25671
176.10000,146.74991,51.26562
176.40002,146.99985,51.32781
176.70002,147.24985,51.39273
177.00002,147.49992,51.43326
177.30000,147.74986,51.53012
177.60000,147.99992,51.76929
177.90002,148.24991,51.80712
178.20002,148.49998,51.99352
178.50002,148.74992,52.08451
178.80000,148.99986,52.05173
179.10000,149.24991,52.05310
179.40002,149.49991,52.12126
179.70002,149.74984,52.37346
180.00002,149.99986,52.26679
180.30000,150.24992,52.32706
180.60000,150.49991,52.34808
180.90002,150.74993,52.69779
181.20002,150.99992,52.75998
181.50002,151.24992,52.50361
181.80000,151.49985,52.69637
182.10000,151.74999,52.79687
182.40002,151.99992,52.92657
182.70002,152.24986,52.81559
183.00002,152.49992,53.14374
183.30000,152.74986,53.06907
183.60000,152.99991,53.08528
183.90002,153.24992,53.11904
184.20002,153.49992,53.48787
184.50002,153.74998,53.41334
184.80000,153.99985,53.41907
185.10000,154.24985,53.53750
185.40002,154.49998,53.47336
185.70002,154.74992,53.46464
186.00002,154.99991,53.78819
186.30000,155.24991,53.86223
186.60000,155.49992,53.68210
186.90002,155.74986,53.89897
187.20002,155.99986,53.76677
187.50002,156.24992,54.03230
187.80000,156.49991,54.15966
188.10000,156.74992,54.16549
188.40002,156.99985,53.91534
188.70002,157.24991,54.26834
189.00002,157.49991,54.26981
189.30000,157.74984,54.35502
189.60000,157.99992,54.51554
189.90002,158.24990,54.48246
190.20002,158.49991,54.72291
190.50002,158.74991,54.57488
190.80000,158.99984,54.85986
191.10000,159.24992,54.77166
191.40002,159.49985,54.90921
191.70002,159.74991,54.87809
192.00002,159.99991,55.18699
192.30000,160.24992,55.27636
192.60000,160.49985,55.24050
192.90002,160.74991,55.38691
193.20002,160.99999,55.42600
193.50002,161.24984,55.53087
193.80000,161.49985,55.47148
194.10000,161.74996,55.67919
194.40002,161.99991,55.61632
194.70002,162.24984,55.61711
195.00002,162.49992,55.73799
195.30000,162.74991,55.93134
195.60000,162.99991,56.00646
195.90002,163.24991,56.09932
196.20002,163.49992,55.99955
196.50002,163.74992,55.96359
196.80000,163.99985,56.21701
197.10000,164.24986,56.26493
197.40002,164.49990,56.24779
197.70002,164.74985,56.23205
198.00002,164.99985,56.49592
198.30000,165.24991,56.44677
198.60000,165.49991,56.44094
198.90002,165.74990,56.40620
199.20002,165.99992,56.66546
199.50002,166.24991,56.71519
199.80000,166.49991,56.78855
200.10000,166.74984,56.68530
200.40002,166.99998,57.04334
200.70002,167.24985,57.01203
201.00002,167.49986,57.16296
201.30000,167.74984,57.16683
201.60000,167.99990,57.22357
201.90002,168.24985,57.37498
202.20002,168.49985,57.25689
202.50002,168.74991,57.28574
202.80000,168.99984,57.45235
203.10000,169.24992,57.46817
203.40002,169.49985,57.59660
203.70002,169.74986,57.52354
204.00002,169.99992,57.69843
204.30000,170.24990,57.71308
204.60000,170.49998,57.74384
204.90002,170.74991,57.85478
205.20002,170.99986,57.96807
205.50002,171.24990,57.83930
205.80000,171.49990,58.07754
206.10000,171.74991,58.15324
206.40002,171.99991,58.40520
206.70002,172.24984,58.15917
207.00002,172.49990,58.27682
207.30000,172.74985,58.49261
207.60000,172.99991,58.47737
207.90002,173.24992,58.55548
208.20002,173.49990,58.40368
208.50002,173.74985,58.71757
208.80000,173.99983,58.71404
209.10000,174.24991,58.94043
209.40002,174.49984,58.69826
209.70002,174.74985,58.90750
210.00002,174.99998,58.79725
210.30000,175.24991,58.92533
210.60000,175.49986,59.03254
210.90002,175.74985,59.06949
211.20002,175.99991,59.17308
211.50002,176.24991,59.19914
211.80000,176.49986,59.18552
212.10000,176.74992,59.58075
212.40002,176.99985,59.42895
212.70002,177.24991,59.42283
213.00002,177.49984,59.45306
213.30000,177.74992,59.66836
213.60000,177.99990,59.64896
213.90002,178.24979,59.68253
214.20002,178.49991,59.82987
214.50002,178.74992,60.04449
214.80000,178.99992,59.85197
215.10000,179.24985,60.14195
215.40002,179.49985,59.96472
215.70002,179.74997,60.12162
216.00002,179.99992,60.00808
216.30000,180.24985,60.17287
216.60000,180.49991,60.05463
216.90002,180.74991,60.19252
217.20002,180.99984,59.96589
217.50002,181.24992,60.41022
217.80000,181.49991,60.21996
218.10000,181.74985,60.49073
218.40002,181.99991,60.34716
218.70002,182.24992,60.48519
219.00002,182.49990,60.85666
219.30000,182.74985,60.67071
219.60000,182.99984,60.97995
219.90002,183.24992,60.74832
220.20002,183.49985,60.87738
220.50002,183.74991,60.90909
220.80000,183.99991,61.14463
221.10000,184.24984,61.06255
221.40002,184.49984,61.14929
221.70002,184.74985,61.12141
222.00002,184.99991,61.36278
222.30000,185.24984,61.36817
222.60000,185.49992,61.44182
222.90002,185.74992,61.49425
223.20002,185.99991,61.77080
223.50002,186.24991,61.72440
223.80000,186.49984,61.59695
224.10000,186.74992,61.91770
224.40002,186.99991,61.76311
224.70002,187.24985,61.99057
225.00002,187.49991,62.08602
225.30002,187.74984,62.06260
225.60000,187.99985,62.01894
225.90002,188.24991,61.95940
226.20002,188.49997,62.16378
226.50002,188.74984,62.30157
226.80002,188.99985,62.07548
227.10000,189.24996,62.27805
227.40002,189.49991,62.26653
227.70002,189.74984,62.39726
228.00002,189.99984,62.31524
228.30002,190.24990,62.32082
228.60000,190.49991,62.49997
228.90002,190.74984,62.62962
229.20002,190.99990,62.63305
229.50002,191.24985,62.83718
229.80002,191.49985,62.86330
230.10000,191.74986,62.57509
230.40002,191.99990,62.99256
230.70002,192.24990,62.87658
231.00002,192.49983,62.94170
231.30002,192.74991,62.96292
231.60000,192.99991,63.19429
231.90002,193.24984,63.17004
232.20002,193.49990,63.30420
232.50002,193.74991,63.23844
232.80002,193.99991,63.36261
233.10000,194.24984,63.33879
233.40002,194.49985,63.47188
233.70002,194.74998,63.55087
234.00002,194.99991,63.63711
234.30002,195.24978,63.67067
234.60000,195.49990,63.88465
234.90002,195.74990,63.73324
235.20002,195.99983,63.72526
235.50002,196.24986,63.88407
235.80002,196.49990,63.82061
236.10000,196.74990,63.78200
236.40002,196.99983,64.19644
236.70002,197.24978,64.22231
237.00002,197.49992,64.01102
237.30002,197.74990,64.46594
237.60000,197.99991,64.24990
237.90002,198.24991,64.25906
238.20002,198.49991,64.40317
238.50002,198.74990,64.38803
238.80002,198.99985,64.56654
239.10000,199.24983,64.49412
239.40002,199.49991,64.72525
239.70002,199.74984,64.76038
240.00002,199.99990,64.74372
240.30002,200.24991,64.70212
240.60000,200.49984,64.87269
240.90002,200.74992,65.11710
241.20002,200.99990,64.89763
241.50002,201.24990,64.82374
241.80002,201.49983,64.91390
242.10000,201.74991,65.17849
242.40002,201.99992,64.99087
242.70002,202.24990,64.91399
243.00002,202.49991,65.20349
243.30002,202.74984,65.35391
243.60000,202.99992,65.51375
243.90002,203.24990,65.50170
244.20002,203.49991,65.20652
244.50002,203.74991,65.45985
244.80002,203.99984,65.47009
245.10000,204.24992,65.60739
245.40002,204.49990,65.66492
245.70002,204.74985,65.55996
246.00002,204.99984,65.80388
246.30002,205.24984,65.90507
246.60000,205.49998,65.83406
246.90002,205.74979,66.06647
247.20002,205.99991,66.12625
247.50002,206.24990,65.94583
247.80002,206.49992,65.94809
248.10000,206.74990,66.15555
248.40002,206.99985,66.17011
248.70002,207.24989,66.47268
249.00002,207.49992,66.16937
249.30002,207.74985,66.20710
249.60000,207.99991,66.49600
249.90002,208.24991,66.52536
250.20002,208.49984,66.36934
250.50002,208.74985,66.49938
250.80002,208.99991,66.68250
251.10000,209.24985,66.71033
251.40002,209.49984,66.78893
251.70002,209.74990,66.88311
252.00002,209.99990,66.78564
252.30002,210.24991,66.78437
252.60000,210.49984,66.67480
252.90002,210.74990,66.77530
253.20002,210.99992,66.91735
253.50002,211.24985,67.04127
253.80002,211.49991,67.20042
254.10000,211.74997,67.36830
254.40002,211.99984,67.43636
254.70002,212.24983,67.55072
255.00002,212.49991,67.34591
255.30002,212.74991,67.17578
255.60000,212.99984,67.59076
255.90002,213.24985,67.61785
256.20002,213.49985,67.54146
256.50000,213.74991,67.59590
256.80002,213.99984,67.90152
257.10000,214.24985,67.71556
257.40003,214.49991,67.76750
257.70002,214.74991,67.73511
258.00000,214.99991,67.92538
258.30002,215.24996,67.77470
258.60000,215.49990,67.78916
258.90003,215.74991,67.96350
259.20002,215.99986,68.06870
259.50000,216.24990,67.95943
259.80002,216.49990,68.20585
260.10000,216.74983,68.29253
260.40003,216.99991,68.05513
260.70002,217.24992,68.08492
261.00000,217.49990,68.23667
261.30002,217.74985,68.21252
261.60000,217.99991,68.51480
261.90003,218.24986,68.49353
262.20000,218.49984,68.48206
262.50000,218.74990,68.54042
262.80003,218.99991,68.43988
263.10000,219.24986,68.62069
263.40003,219.49984,68.64861
263.70000,219.74990,68.59977
264.00000,219.99991,68.77146
264.30003,220.24991,68.57188
264.60000,220.49997,69.05855
264.90003,220.74990,68.94472
265.20000,220.99990,68.83839
265.50000,221.24991,69.21354
265.80003,221.49984,69.00926
266.10000,221.74992,68.96995
266.40003,221.99985,69.06703
266.70000,222.24991,69.03277
267.00000,222.49991,69.16723
267.30003,222.74986,69.51812
267.60000,222.99990,69.46682
267.90003,223.24990,69.43555
268.20000,223.49998,69.59127
268.50000,223.74991,69.33912
268.80003,223.99984,69.74685
269.10000,224.24996,69.71873
269.40003,224.49991,69.75626
269.70000,224.74984,69.84245
270.00000,224.99992,69.97372
270.30003,225.24990,69.99043
270.60000,225.49991,70.09524
270.90003,225.74984,70.26762
271.20000,225.99991,70.26831
271.50000,226.24984,70.02330
271.80003,226.49985,70.19055
272.10000,226.74991,70.48008
272.40003,226.99989,70.57504
272.70000,227.24984,70.31530
273.00000,227.49985,70.82862
273.30003,227.74991,70.56113
273.60000,227.99991,70.65570
273.90003,228.24984,70.98199
274.20000,228.49984,70.73400
274.50000,228.74996,70.82872
274.80003,228.99985,71.01203
275.10000,229.24984,71.01325
275.40003,229.49992,71.11899
275.70000,229.74990,71.27530
276.00000,229.99991,71.13403
276.30003,230.24984,71.28368
276.60000,230.49990,71.26281
276.90003,230.74985,71.50350
277.20000,230.99985,71.57248
277.50000,231.24991,71.54946
277.80003,231.49984,71.45817
278.10000,231.74984,71.33695
278.40003,231.99985,71.55504
278.70000,232.24996,71.47733
279.00000,232.49991,71.45949
279.30003,232.74984,71.84973
279.60000,232.99992,71.83341
279.90003,233.24991,71.63932
280.20000,233.49985,71.95047
280.50000,233.74990,72.19111
280.80003,233.99990,71.95625
281.10000,234.24983,72.13775
281.40003,234.49978,72.13873
281.70000,234.74991,72.20615
282.00000,234.99990,72.33522
282.30003,235.24985,72.39647
282.60000,235.49991,72.46365
282.90003,235.74991,72.69596
283.20000,235.99990,72.85016
283.50000,236.24985,72.72839
283.80003,236.49983,72.87544
284.10000,236.74997,72.71791
284.40003,236.99991,72.86202
284.70000,237.24996,72.80899
285.00000,237.49990,72.79067
285.30003,237.74991,72.81831
285.60000,237.99991,72.73148
285.90003,238.24990,73.01661
286.20000,238.49990,72.93777
286.50000,238.74991,72.84570
286.80003,238.99985,73.03704
287.10000,239.24991,73.03435
287.40003,239.49990,73.20673
287.70000,239.74985,73.24054
288.00000,239.99991,73.24926
288.30003,240.24991,73.46922
288.60000,240.49990,73.49916
288.90003,240.74990,73.46437
289.20000,240.99983,73.48897
289.50000,241.24991,73.87479
289.80003,241.49992,73.81526
290.10000,241.74990,73.89630
290.40003,241.99998,73.91243
290.70000,242.24991,74.13052
291.00000,242.49991,74.15473
291.30003,242.74984,74.08672
291.60000,242.99990,74.03835
291.90003,243.24991,74.05193
292.20000,243.49991,74.09225
292.50000,243.74984,74.17448
292.80003,243.99990,74.10171
293.10000,244.24991,74.12886
293.40003,244.49991,74.13685
293.70000,244.74991,74.27958
294.00000,244.99990,74.48391
294.30003,245.24990,74.51689
294.60000,245.49991,74.53188
294.90003,245.74997,74.40056
295.20000,245.99977,74.32137
295.50000,246.24985,74.50958
295.80003,246.49991,74.56819
296.10000,246.74989,74.49989
296.40003,246.99984,74.77854
296.70000,247.24985,74.80407
297.00000,247.49996,75.09048
297.30003,247.74991,74.92971
297.60000,247.99984,74.81143
297.90003,248.24984,74.81236
298.20000,248.49990,74.66330
298.50000,248.74985,74.55633
298.80003,248.99984,74.99473
299.10000,249.24992,74.73087
299.40003,249.49985,75.00341
299.70000,249.74985,74.84842
300.00000,249.99997,74.87410
300.30003,250.24995,75.03339
300.60000,250.49990,74.98322
300.90003,250.74989,75.12684
301.20000,250.99991,75.10391
301.50000,251.24988,75.08078
301.80003,251.49990,74.96940
302.10000,251.74990,74.90585
302.40003,251.99994,74.98758
302.70000,252.24984,74.82637
303.00000,252.49988,75.14110
303.30003,252.74990,75.23934
303.60000,252.99991,75.44970
303.90003,253.24984,75.36287
304.20000,253.49990,75.65059
304.50000,253.74992,75.70949
304.80003,253.99989,75.64839
305.10000,254.24991,75.66520
305.40003,254.49982,76.09022
305.70000,254.74995,76.08880
306.00000,254.99990,76.11781
306.30003,255.24989,76.37349
306.60000,255.49997,76.30131
306.90003,255.74982,76.64319
307.20000,255.99984,76.61937
307.50000,256.24996,76.64010
307.80003,256.49983,76.67543
308.10000,256.74984,76.92317
308.40003,256.99997,76.70987
308.70000,257.24990,77.06331
309.00000,257.49991,76.89853
309.30003,257.74984,77.05087
309.60000,257.99984,77.34021
309.90003,258.24988,77.31218
310.20000,258.49983,77.23804
310.50000,258.74991,77.13892
310.80003,258.99990,77.28048
311.10000,259.24990,77.50470
311.40003,259.49989,77.76107
311.70000,259.74989,77.77175
312.00000,259.99997,77.91772
312.30003,260.24988,77.94393
312.60000,260.49990,78.23465
312.90003,260.74996,78.09363
313.20000,260.99995,78.15263
313.50000,261.24984,78.43281
313.80003,261.49988,78.35259
314.10000,261.74990,78.52503
314.40003,261.99996,78.56976
314.70000,262.24984,78.56560
315.00000,262.49995,78.80251
315.30003,262.74988,79.00429
315.60000,262.99983,79.04957
315.90003,263.24986,78.91232
316.20000,263.49990,79.14615
316.50000,263.74996,78.94216
316.80003,263.99989,79.08362
317.10000,264.24989,79.18245
317.40003,264.49991,79.20191
317.70000,264.74988,79.33656
318.00000,264.99990,79.21259
318.30003,265.24989,79.40306
318.60000,265.49995,79.58538
318.90003,265.74984,79.48807
319.20000,265.99983,79.59793
319.50000,266.24991,79.59371
319.80003,266.49982,79.94254
320.10000,266.74990,79.93559
320.40003,266.99990,79.92162
320.70000,267.24989,80.14432
321.00000,267.49989,80.12090
321.30003,267.74982,80.21243
321.60000,267.99995,80.30235
321.90003,268.24990,80.28226
322.20000,268.49983,80.22072
322.50003,268.74989,80.36810
322.80003,268.99997,80.42612
323.10000,269.24983,80.80176
323.40003,269.49991,80.48752
323.70000,269.74989,80.77049
324.00003,269.99990,80.66662
324.30003,270.24984,80.69082
324.60000,270.49994,80.92004
324.90003,270.74983,81.13010
325.20000,270.99987,80.97590
325.50003,271.24984,81.03686
325.80003,271.49985,81.19851
326.10000,271.74989,81.33624
326.40003,271.99984,81.15500
326.70000,272.24997,81.32664
327.00003,272.49996,81.57585
327.30003,272.74990,81.40793
327.60000,272.99983,81.53763
327.90003,273.24989,81.37496
328.20000,273.49992,81.43307
328.50003,273.74988,40.05030
328.80003,273.99991,0.65300
329.10000,274.24989,0.43622
329.40003,274.49990,0.55044
329.70000,274.74990,0.46028
330.00003,274.99983,0.49267
330.30003,275.24991,0.66270
330.60000,275.49982,0.51796
330.90003,275.74990,0.79417
331.20000,275.99990,0.47768
331.50003,276.24989,0.47057
331.80003,276.49984,0.33960
332.10000,276.74988,0.49811
332.40003,276.99996,0.55108
332.40403,277.00325,0.52433