File: EPR/EPR/RDSO EPR Tensile 50.is_tens_RawData/Specimen_RawData_10.csv
Time,Extension,Load
(sec),(mm),(N)
0.00000,-0.00006,5.02868
0.30000,0.24937,5.64838
0.60000,0.49987,5.92140
0.90000,0.74994,6.14210
1.20000,0.99987,6.34099
1.50000,1.24994,6.81541
1.80000,1.49994,7.10166
2.10000,1.74994,7.09608
2.40000,1.99994,7.27703
2.70000,2.24987,7.65570
3.00000,2.49994,7.74866
3.30000,2.75000,7.88708
3.60000,3.00000,8.06446
3.90000,3.24987,8.32877
4.20000,3.49994,8.44789
4.50000,3.74994,8.61684
4.80000,3.99994,8.66103
5.10000,4.24987,8.82739
5.40000,4.49994,8.98718
5.70000,4.74994,9.16059
6.00000,4.99994,9.08616
6.30000,5.24994,9.48016
6.60000,5.49994,9.61820
6.90000,5.74987,9.63780
7.20000,5.99987,9.83880
7.50000,6.24987,9.76407
7.80000,6.49994,9.92082
8.10000,6.74987,10.07929
8.40000,6.99987,10.13132
8.70000,7.25000,10.19052
9.00000,7.49994,10.40602
9.30000,7.74994,10.50505
9.60000,7.99987,10.73392
9.90000,8.25000,10.72471
10.20000,8.49994,10.95854
10.50000,8.74987,11.20202
10.80000,8.99994,10.99558
11.10000,9.24987,11.10093
11.40000,9.49994,11.39547
11.70000,9.75000,11.30198
12.00000,9.99994,11.58843
12.30000,10.24994,11.59446
12.60000,10.49987,11.67423
12.90000,10.75000,11.95985
13.20000,10.99994,11.83794
13.50000,11.24987,11.99851
13.80000,11.49994,12.05378
14.10000,11.74994,12.23528
14.40000,11.99994,12.22264
14.70000,12.24994,12.41183
15.00000,12.50000,12.49919
15.30000,12.74994,12.60013
15.60000,12.99994,12.25385
15.90000,13.24994,12.59572
16.20000,13.49994,12.72415
16.50000,13.74987,12.74973
16.80000,13.99994,12.90491
17.10000,14.24994,12.84601
17.40000,14.49994,12.90721
17.70000,14.74994,13.04956
18.00000,14.99994,13.04392
18.30000,15.24994,13.18397
18.60000,15.49994,13.17598
18.90000,15.74987,13.23742
19.20000,15.99994,13.40985
19.50000,16.24993,13.41716
19.80000,16.49993,13.46366
20.10000,16.75000,13.60380
20.40000,16.99987,13.32891
20.70000,17.24993,13.71679
21.00000,17.49987,13.78073
21.30000,17.74994,13.86452
21.60000,17.99993,13.76525
21.90000,18.24994,13.75192
22.20000,18.49987,14.01020
22.50000,18.75000,14.15828
22.80000,19.00000,14.09125
23.10000,19.24987,14.16925
23.40000,19.49994,14.24829
23.70000,19.74993,14.23727
24.00000,19.99993,14.17425
24.30000,20.24994,14.36898
24.60000,20.49993,14.39823
24.90000,20.74993,14.38476
25.20000,20.99987,14.74931
25.50000,21.24993,14.66523
25.80000,21.50000,14.73373
26.10000,21.74993,14.81150
26.40000,21.99987,14.81399
26.70000,22.25000,14.73687
27.00000,22.49993,14.93056
27.30000,22.74987,14.92919
27.60000,22.99987,14.95536
27.90000,23.24993,15.02459
28.20000,23.49993,15.11838
28.50000,23.74987,15.00676
28.80000,23.99993,15.26073
29.10000,24.24994,15.12024
29.40000,24.49993,15.33766
29.70000,24.74993,15.33937
30.00000,24.99987,15.30453
30.30000,25.25000,15.45349
30.60000,25.49981,15.64964
30.90000,25.74987,15.50602
31.20000,26.00000,15.49573
31.50000,26.24987,15.63753
31.80000,26.49993,15.77571
32.10000,26.74993,15.66605
32.40000,26.99994,15.73720
32.70000,27.24993,15.96289
33.00000,27.49987,16.04198
33.30000,27.74999,15.85612
33.60000,27.99993,16.05962
33.90000,28.24993,16.04879
34.20000,28.49993,16.13753
34.50000,28.74987,16.19702
34.80000,28.99993,16.30780
35.10000,29.24987,16.10632
35.40000,29.50000,16.47533
35.70000,29.75000,16.48675
36.00000,29.99993,16.46980
36.30000,30.24993,16.57010
36.60000,30.49993,16.66736
36.90000,30.74993,16.70524
37.20000,30.99987,16.81598
37.50000,31.24987,16.78550
37.80000,31.49993,16.73841
38.10000,31.74993,17.04956
38.40000,31.99993,16.83083
38.70000,32.24993,17.09410
39.00000,32.49987,17.23385
39.30000,32.74987,17.26281
39.60000,33.00000,17.17221
39.90000,33.24993,17.41442
40.20000,33.49987,17.14306
40.50000,33.74993,17.48321
40.80000,33.99987,17.43392
41.10000,34.24993,17.52770
41.40000,34.49993,17.48787
41.70000,34.74993,17.47856
42.00000,34.99993,17.76682
42.30000,35.24993,17.97752
42.60000,35.49993,17.76423
42.90000,35.74993,17.97698
43.20000,35.99987,17.87732
43.50000,36.24987,18.13422
43.80000,36.49993,18.17857
44.10000,36.74993,18.22443
44.40000,36.99993,18.28534
44.70000,37.24993,18.20032
45.00000,37.49993,18.30523
45.30000,37.74999,18.44880
45.60000,37.99987,18.27784
45.90000,38.24987,18.67567
46.20000,38.49993,18.73467
46.50000,38.74993,18.60546
46.80000,38.99993,18.66078
47.10000,39.24993,18.55450
47.40000,39.49993,18.79102
47.70000,39.74993,19.01357
48.00000,39.99987,18.99633
48.30000,40.25000,19.04650
48.60000,40.49993,19.16552
48.90000,40.74987,19.12088
49.20000,40.99993,19.22016
49.50000,41.24993,19.34173
49.80000,41.49993,19.36368
50.10000,41.74987,19.42243
50.40000,41.99993,19.56561
50.70000,42.24999,19.61774
51.00000,42.49987,19.55301
51.30000,42.74993,19.88602
51.60000,42.99993,19.80017
51.90000,43.24987,19.76249
52.20000,43.49993,19.91552
52.50000,43.74993,19.96638
52.80000,43.99993,20.02072
53.10000,44.24987,20.07080
53.40000,44.49993,20.51572
53.70000,44.74993,20.32133
54.00000,44.99987,20.42232
54.30000,45.24993,20.32868
54.60000,45.49993,20.71505
54.90000,45.74993,20.57157
55.20000,45.99993,20.63591
55.50000,46.24987,20.73969
55.80000,46.49993,20.67452
56.10000,46.74986,20.86224
56.40000,46.99993,21.00860
56.70000,47.24993,20.88238
57.00000,47.49993,21.35258
57.30000,47.74993,21.09014
57.60000,47.99987,21.13346
57.90000,48.24993,21.29712
58.20000,48.49993,21.21235
58.50000,48.74987,21.60420
58.80000,48.99993,21.37816
59.10000,49.24993,21.73679
59.40000,49.49993,21.67035
59.70000,49.74993,21.57509
60.00000,49.99993,21.88506
60.30000,50.24993,22.03687
60.60000,50.49987,21.85983
60.90000,50.74987,21.93196
61.20000,50.99993,22.15848
61.50000,51.24987,22.25599
61.80000,51.49987,22.29505
62.10000,51.74993,22.18200
62.40000,51.99999,22.45753
62.70000,52.24993,22.38094
63.00000,52.49986,22.59056
63.30000,52.74993,22.57518
63.60000,52.99993,22.66401
63.90000,53.24987,22.69753
64.20000,53.49993,22.85703
64.50000,53.74993,22.86232
64.80000,53.99993,23.16102
65.10001,54.24987,23.12829
65.40000,54.49993,23.21472
65.70001,54.74993,23.37378
66.00000,54.99987,23.22595
66.30000,55.24993,23.40225
66.60001,55.49993,23.44370
66.90000,55.74987,23.54655
67.20001,55.99993,23.56282
67.50000,56.24993,23.70678
67.80000,56.49993,23.88690
68.10001,56.74987,24.00793
68.40000,56.99993,24.15817
68.70001,57.24993,24.17463
69.00000,57.49993,23.91812
69.30000,57.74993,24.00372
69.60001,57.99993,24.14954
69.90000,58.24987,24.31257
70.20001,58.49993,24.38788
70.50000,58.74987,24.48627
70.80000,58.99999,24.37788
71.10001,59.24993,24.82927
71.40000,59.49987,24.73333
71.70001,59.74993,24.86685
72.00000,59.99993,25.00038
72.30000,60.24987,25.02840
72.60001,60.49987,25.10925
72.90000,60.74993,25.09534
73.20001,60.99993,25.40051
73.50000,61.24993,25.33068
73.80000,61.49993,25.40399
74.10001,61.74993,25.33098
74.40000,61.99993,25.50292
74.70001,62.24993,25.53021
75.00000,62.49993,25.67089
75.30000,62.74993,25.87478
75.60001,62.99987,25.97101
75.90000,63.24993,25.95043
76.20001,63.49993,26.27501
76.50000,63.74992,26.10493
76.80000,63.99993,25.94813
77.10001,64.24993,26.27952
77.40000,64.49993,26.25752
77.70001,64.74993,26.44122
78.00000,64.99992,26.43186
78.30000,65.24986,26.54657
78.60001,65.49993,26.64922
78.90000,65.74993,26.82479
79.20001,65.99999,26.81793
79.50000,66.24993,26.77339
79.80000,66.49987,27.03877
80.10001,66.74992,26.96282
80.40000,66.99993,27.08493
80.70001,67.24987,27.35683
81.00001,67.49986,27.36085
81.30000,67.74993,27.54043
81.60001,67.99993,27.52264
81.90000,68.24993,27.58997
82.20001,68.49993,27.58272
82.50001,68.74993,27.86893
82.80000,68.99992,27.79763
83.10001,69.24993,27.77950
83.40000,69.49992,27.96776
83.70001,69.74999,27.89333
84.00001,69.99987,28.10099
84.30000,70.24986,28.27910
84.60001,70.49993,28.23868
84.90000,70.74993,28.45648
85.20001,70.99986,28.70143
85.50001,71.24986,28.67483
85.80000,71.49993,28.61725
86.10001,71.74987,28.91899
86.40000,71.99986,28.67017
86.70001,72.24993,28.85745
87.00001,72.49986,29.13792
87.30000,72.74986,29.25538
87.60001,72.99987,29.10382
87.90000,73.24993,29.37807
88.20001,73.49993,29.20554
88.50001,73.74987,29.44564
88.80000,73.99999,29.41164
89.10001,74.24999,29.43839
89.40000,74.49993,29.69255
89.70001,74.74986,29.56378
90.00001,74.99993,29.91354
90.30000,75.24999,29.94931
90.60001,75.49986,29.92530
90.90000,75.74980,30.05246
91.20001,75.99992,30.03065
91.50001,76.24993,30.24164
91.80000,76.49987,30.16031
92.10001,76.74999,30.28344
92.40000,76.99993,30.58018
92.70001,77.24986,30.59199
93.00001,77.49987,30.74017
93.30000,77.74992,30.70856
93.60001,77.99986,30.90358
93.90000,78.24986,30.98928
94.20001,78.49992,31.05597
94.50001,78.74993,31.22081
94.80000,78.99993,31.12732
95.10001,79.24986,31.44709
95.40000,79.49992,31.28113
95.70001,79.74993,31.44483
96.00001,79.99986,31.41686
96.30000,80.24992,31.20611
96.60001,80.49986,31.77318
96.90000,80.74986,31.72252
97.20001,80.99993,31.91357
97.50001,81.24986,32.01122
97.80000,81.49993,31.90739
98.10001,81.74987,32.01353
98.40000,81.99993,32.24392
98.70001,82.24992,32.20365
99.00001,82.49993,32.18914
99.30000,82.74986,32.26250
99.60001,82.99992,32.57232
99.90000,83.24993,32.46374
100.20001,83.49992,32.82521
100.50001,83.74986,32.95678
100.80000,83.99992,32.71672
101.10001,84.24980,32.82673
101.40000,84.49992,32.93840
101.70001,84.74999,33.13533
102.00001,84.99992,33.06742
102.30000,85.24986,33.27488
102.60001,85.49993,33.39454
102.90000,85.74999,33.54350
103.20001,85.99993,33.66982
103.50001,86.24979,33.60019
103.80000,86.49993,33.54762
104.10001,86.74992,33.77517
104.40000,86.99986,33.82148
104.70001,87.24992,34.04080
105.00001,87.49993,34.14762
105.30000,87.74993,34.10577
105.60001,87.99986,34.35445
105.90000,88.24993,34.08656
106.20001,88.49992,34.30349
106.50001,88.74992,34.57710
106.80000,88.99992,34.57186
107.10001,89.24992,34.69328
107.40000,89.49992,34.61170
107.70001,89.74986,34.93921
108.00001,89.99986,34.72342
108.30000,90.24998,34.88928
108.60001,90.49992,34.96513
108.90000,90.74987,35.08498
109.20001,90.99992,35.15045
109.50001,91.24986,35.11537
109.80000,91.49992,35.25859
110.10001,91.74986,35.65309
110.40000,91.99993,35.45087
110.70001,92.24992,35.51021
111.00001,92.49986,35.81195
111.30000,92.74987,35.89579
111.60001,92.99993,36.00829
111.90000,93.24992,35.93004
112.20001,93.49986,35.83165
112.50001,93.74992,36.22526
112.80000,93.99992,36.23413
113.10001,94.24986,36.23438
113.40001,94.49992,36.36662
113.70001,94.74985,36.58409
114.00001,94.99992,36.45478
114.30000,95.24986,36.48624
114.60001,95.49987,36.70717
114.90001,95.74993,36.67807
115.20001,95.99986,36.85711
115.50001,96.24992,36.95928
115.80000,96.49992,37.04425
116.10001,96.74992,37.12882
116.40001,96.99993,37.05316
116.70001,97.24992,37.19394
117.00001,97.49993,37.28508
117.30000,97.74992,37.34251
117.60001,97.99986,37.46530
117.90001,98.24986,37.48809
118.20001,98.49992,37.63509
118.50001,98.74992,37.82604
118.80000,98.99992,37.94408
119.10001,99.24993,38.01479
119.40001,99.49986,38.04061
119.70001,99.74992,38.06006
120.00001,99.99986,38.03595
120.30000,100.24992,38.41835
120.60001,100.49986,38.35680
120.90001,100.74992,38.42271
121.20001,100.99992,38.72857
121.50001,101.24986,38.49797
121.80000,101.49992,38.94990
122.10001,101.74992,38.64899
122.40001,101.99992,38.76448
122.70001,102.24992,38.93236
123.00001,102.49986,39.22185
123.30000,102.74992,39.28976
123.60001,102.99986,39.24448
123.90001,103.24992,39.12953
124.20001,103.49993,39.42676
124.50001,103.74992,39.30137
124.80000,103.99993,39.80745
125.10001,104.24986,39.62801
125.40001,104.49992,39.84292
125.70001,104.74992,39.78976
126.00001,104.99986,39.87085
126.30000,105.24992,39.79157
126.60001,105.49992,40.21983
126.90001,105.74993,40.15529
127.20001,105.99986,40.30024
127.50001,106.24993,40.19444
127.80000,106.49992,40.33708
128.10001,106.74986,40.41269
128.40001,106.99992,40.55087
128.70002,107.24999,40.68773
129.00000,107.49985,40.73741
129.30000,107.74992,40.72580
129.60001,107.99993,40.85129
129.90001,108.24992,40.95502
130.20002,108.49986,41.03323
130.50000,108.74987,41.25240
130.80000,108.99998,41.44850
131.10000,109.24992,41.34942
131.40002,109.49992,41.28263
131.70002,109.74992,41.37206
132.00000,109.99992,41.64484
132.30000,110.24993,41.76999
132.60000,110.49986,41.77302
132.90002,110.74992,41.65464
133.20002,110.99986,41.86088
133.50000,111.24986,41.96035
133.80000,111.49992,42.14880
134.10000,111.74992,41.93997
134.40002,111.99992,42.25048
134.70002,112.24986,42.21873
135.00000,112.49992,42.53144
135.30000,112.74992,42.44217
135.60000,112.99986,42.40297
135.90002,113.24992,42.64360
136.20002,113.49992,42.70054
136.50000,113.74992,42.85607
136.80000,113.99992,42.93628
137.10000,114.24992,43.03859
137.40002,114.49993,43.05971
137.70002,114.74986,43.03472
138.00000,114.99993,43.19946
138.30000,115.24992,43.28731
138.60000,115.49986,43.45475
138.90002,115.74992,43.52237
139.20002,115.99992,43.61405
139.50000,116.24992,43.55343
139.80000,116.49986,43.81225
140.10000,116.74993,43.78226
140.40002,116.99992,43.75761
140.70002,117.24993,43.92730
141.00000,117.49992,43.86561
141.30000,117.74993,44.11571
141.60000,117.99992,44.30837
141.90002,118.24986,44.19019
142.20002,118.49998,44.23674
142.50000,118.74992,44.61521
142.80000,118.99998,44.50981
143.10000,119.24992,44.68964
143.40002,119.49993,44.59169
143.70002,119.74992,44.65230
144.00000,119.99986,44.93895
144.30000,120.24986,44.96492
144.60000,120.49992,44.77343
144.90002,120.74999,44.96899
145.20002,120.99992,45.18047
145.50000,121.24985,45.27156
145.80000,121.49992,45.40381
146.10000,121.74986,45.37020
146.40002,121.99992,45.44101
146.70002,122.24992,45.53352
147.00000,122.49992,45.50818
147.30000,122.74992,45.70805
147.60000,122.99986,45.60373
147.90002,123.24998,45.66356
148.20002,123.49992,45.87769
148.50000,123.74992,46.03856
148.80000,123.99998,45.84594
149.10000,124.24992,46.16586
149.40002,124.49986,46.24990
149.70002,124.74986,46.26562
150.00000,124.99986,46.47931
150.30000,125.24992,46.40179
150.60000,125.49986,46.41841
150.90002,125.74986,46.61793
151.20002,125.99992,46.60691
151.50000,126.24991,46.76586
151.80000,126.49992,46.81957
152.10000,126.74986,46.97720
152.40002,126.99998,47.27267
152.70002,127.24985,47.09828
153.00000,127.49985,47.01900
153.30000,127.74998,47.34886
153.60000,127.99992,47.34279
153.90002,128.24985,47.40120
154.20002,128.49991,47.48704
154.50000,128.74998,47.71803
154.80000,128.99992,47.64041
155.10000,129.24992,47.90158
155.40002,129.49991,47.98630
155.70002,129.74991,47.72293
156.00000,129.99992,48.05740
156.30000,130.24992,48.23189
156.60000,130.49997,48.05662
156.90002,130.74991,48.29387
157.20002,130.99991,48.30270
157.50000,131.24998,48.45871
157.80000,131.49992,48.69509
158.10000,131.74986,48.46131
158.40002,131.99985,48.56734
158.70002,132.24992,48.63021
159.00000,132.49992,48.76819
159.30000,132.74992,48.66176
159.60000,132.99986,48.83194
159.90002,133.24991,49.06983
160.20002,133.49992,49.07689
160.50000,133.74992,49.15867
160.80000,133.99991,49.10849
161.10000,134.24992,49.42469
161.40002,134.49985,49.40485
161.70002,134.74998,49.42572
162.00002,134.99992,49.71433
162.30000,135.24991,49.79209
162.60000,135.49991,49.79337
162.90002,135.74985,49.75240
163.20002,135.99998,49.76191
163.50002,136.24991,49.84962
163.80000,136.49992,49.77107
164.10000,136.74985,50.14602
164.40002,136.99985,50.22461
164.70002,137.24992,50.35941
165.00002,137.49992,50.18497
165.30000,137.74998,50.08134
165.60000,137.99985,50.35559
165.90002,138.24992,50.64004
166.20002,138.49998,50.54204
166.50002,138.74992,50.63200
166.80000,138.99991,50.68198
167.10000,139.24993,50.83515
167.40002,139.49998,50.87646
167.70002,139.74992,50.98892
168.00002,139.99986,50.84510
168.30000,140.24991,51.12572
168.60000,140.49985,51.21740
168.90002,140.74991,51.23700
169.20002,140.99997,51.50596
169.50002,141.24991,51.37484
169.80000,141.49985,51.40125
170.10000,141.74986,51.67251
170.40002,141.99997,51.59171
170.70002,142.24998,51.53938
171.00002,142.49985,51.94015
171.30000,142.74992,51.99473
171.60000,142.99992,51.98626
171.90002,143.24998,51.92662
172.20002,143.49985,52.15271
172.50002,143.74991,52.19951
172.80000,143.99998,52.29084
173.10000,144.24986,52.33430
173.40002,144.49986,52.40903
173.70002,144.74991,52.34802
174.00002,144.99985,52.56083
174.30000,145.24992,52.73963
174.60000,145.49992,52.66290
174.90002,145.74997,52.93229
175.20002,145.99991,52.83798
175.50002,146.24985,52.95562
175.80000,146.49992,53.14305
176.10000,146.74991,53.11355
176.40002,146.99991,53.09674
176.70002,147.24992,53.09742
177.00002,147.49992,53.24310
177.30000,147.74992,53.31151
177.60000,147.99992,53.40427
177.90002,148.24991,53.57023
178.20002,148.49992,53.49094
178.50002,148.74986,53.64784
178.80000,148.99998,53.57866
179.10000,149.24991,53.66122
179.40002,149.49985,53.83272
179.70002,149.74984,53.89186
180.00002,149.99986,54.16994
180.30000,150.24997,53.96359
180.60000,150.49991,54.12250
180.90002,150.74993,54.08776
181.20002,150.99992,54.16778
181.50002,151.24992,54.14343
181.80000,151.49991,54.38303
182.10000,151.74999,54.47050
182.40002,151.99984,54.51024
182.70002,152.24992,54.44399
183.00002,152.49992,54.81173
183.30000,152.74991,54.60652
183.60000,152.99985,54.83119
183.90002,153.24985,54.94085
184.20002,153.49992,54.92713
184.50002,153.74991,54.85804
184.80000,153.99992,55.31585
185.10000,154.24985,55.13200
185.40002,154.49998,55.43849
185.70002,154.74992,55.25920
186.00002,154.99991,55.53997
186.30000,155.24991,55.75930
186.60000,155.49992,55.64968
186.90002,155.74992,55.63209
187.20002,155.99991,55.88218
187.50002,156.24992,55.86107
187.80000,156.49999,55.94525
188.10000,156.74978,55.93667
188.40002,156.99992,55.80589
188.70002,157.24996,55.97181
189.00002,157.49991,56.06667
189.30000,157.74991,56.08745
189.60000,157.99992,56.16413
189.90002,158.24990,56.27100
190.20002,158.49985,56.51732
190.50002,158.74984,56.51086
190.80000,158.99992,56.49772
191.10000,159.24985,56.57323
191.40002,159.49991,56.67177
191.70002,159.74991,56.67314
192.00002,159.99991,56.64413
192.30000,160.24992,56.97537
192.60000,160.49985,56.91044
192.90002,160.74991,57.05132
193.20002,160.99991,57.15633
193.50002,161.24984,57.12605
193.80000,161.49985,57.17279
194.10000,161.74991,57.31161
194.40002,161.99986,57.36570
194.70002,162.24990,57.32577
195.00002,162.49992,57.50898
195.30000,162.74991,57.50849
195.60000,162.99985,57.41137
195.90002,163.24991,57.77568
196.20002,163.49992,57.70248
196.50002,163.74992,57.76001
196.80000,163.99985,57.61859
197.10000,164.24997,57.87741
197.40002,164.49990,58.06420
197.70002,164.74985,57.91911
198.00002,164.99985,57.91808
198.30000,165.24991,58.16764
198.60000,165.49984,58.11335
198.90002,165.74984,58.20517
199.20002,165.99992,58.25270
199.50002,166.24985,58.44282
199.80000,166.49991,58.51377
200.10000,166.74984,58.75201
200.40002,166.99992,58.78499
200.70002,167.24991,58.63030
201.00002,167.49991,58.83061
201.30000,167.74997,58.91263
201.60000,167.99990,58.90077
201.90002,168.24992,59.18242
202.20002,168.49991,58.82477
202.50002,168.74991,58.97760
202.80000,168.99997,59.22883
203.10000,169.24992,59.09354
203.40002,169.49991,59.28356
203.70002,169.74991,59.43556
204.00002,169.99992,59.35324
204.30000,170.24990,59.57893
204.60000,170.49985,59.47167
204.90002,170.74991,59.61960
205.20002,170.99986,59.59030
205.50002,171.24984,59.71040
205.80000,171.49990,59.74117
206.10000,171.74983,60.02615
206.40002,171.99991,59.95339
206.70002,172.24992,60.20819
207.00002,172.49998,60.25248
207.30000,172.74993,60.01831
207.60000,172.99986,60.31824
207.90002,173.24992,60.28536
208.20002,173.49990,60.36141
208.50002,173.74985,60.59205
208.80000,173.99991,60.57191
209.10000,174.24991,60.58465
209.40002,174.49992,60.47538
209.70002,174.74985,60.61768
210.00002,174.99991,60.75223
210.30000,175.24991,60.79182
210.60000,175.49979,60.61004
210.90002,175.74990,60.95749
211.20002,175.99991,60.82348
211.50002,176.24991,60.92285
211.80000,176.49986,61.07872
212.10000,176.74984,60.96298
212.40002,176.99996,60.96906
212.70002,177.24991,61.23679
213.00002,177.49984,61.11243
213.30000,177.74992,61.21499
213.60000,177.99990,61.36590
213.90002,178.24985,61.44504
214.20002,178.49991,61.67794
214.50002,178.74992,61.66598
214.80000,178.99984,61.44450
215.10000,179.24991,61.73061
215.40002,179.49991,61.82861
215.70002,179.74991,61.78206
216.00002,179.99986,61.84934
216.30000,180.24990,61.92779
216.60000,180.49991,62.18406
216.90002,180.74991,61.85855
217.20002,180.99992,62.16436
217.50002,181.24985,62.33664
217.80000,181.49985,62.50932
218.10000,181.74985,62.23203
218.40002,181.99991,62.31459
218.70002,182.24992,62.42994
219.00002,182.49985,62.44620
219.30000,182.74985,62.41646
219.60000,182.99991,62.52847
219.90002,183.24992,62.60845
220.20002,183.49992,62.72423
220.50002,183.74985,62.46330
220.80000,183.99991,62.90813
221.10000,184.24990,62.80973
221.40002,184.49992,63.01725
221.70002,184.74991,62.89250
222.00002,184.99985,63.02004
222.30000,185.24984,63.07585
222.60000,185.49992,63.12882
222.90002,185.74998,63.25975
223.20002,185.99985,63.53508
223.50002,186.24986,63.37010
223.80000,186.49997,63.29733
224.10000,186.74992,63.52783
224.40002,186.99985,63.42346
224.70002,187.24985,63.53582
225.00002,187.49991,63.65224
225.30002,187.74997,63.73343
225.60000,187.99977,63.74725
225.90002,188.24991,63.95134
226.20002,188.49991,63.81497
226.50002,188.74990,64.01288
226.80002,188.99985,63.94648
227.10000,189.24991,64.05394
227.40002,189.49991,64.25019
227.70002,189.74984,64.27395
228.00002,189.99984,64.22166
228.30002,190.24990,64.16237
228.60000,190.49991,64.30325
228.90002,190.74984,64.46995
229.20002,190.99990,64.70578
229.50002,191.24992,64.66311
229.80002,191.49985,64.54938
230.10000,191.74986,64.65674
230.40002,191.99997,64.63880
230.70002,192.24998,64.83608
231.00002,192.49983,64.92080
231.30002,192.74997,64.78418
231.60000,192.99991,64.78134
231.90002,193.24984,65.02791
232.20002,193.49985,64.86092
232.50002,193.74983,65.19603
232.80002,193.99991,65.13556
233.10000,194.24984,65.12983
233.40002,194.49979,65.39536
233.70002,194.74998,65.28149
234.00002,194.99991,65.43250
234.30002,195.24992,65.67951
234.60000,195.49990,65.52291
234.90002,195.74990,65.43603
235.20002,195.99991,65.66638
235.50002,196.24986,65.58950
235.80002,196.49984,65.76148
236.10000,196.74990,65.71263
236.40002,196.99983,65.87840
236.70002,197.24991,65.64393
237.00002,197.49992,66.19322
237.30002,197.74990,66.05176
237.60000,197.99985,66.22546
237.90002,198.24991,66.25183
238.20002,198.49986,66.25741
238.50002,198.74979,66.16319
238.80002,198.99990,66.33620
239.10000,199.24991,66.60394
239.40002,199.49991,66.50785
239.70002,199.74992,66.60767
240.00002,199.99985,66.25222
240.30002,200.24991,66.54686
240.60000,200.49991,66.86046
240.90002,200.74992,66.76202
241.20002,200.99990,66.92141
241.50002,201.24985,66.90769
241.80002,201.49991,67.27578
242.10000,201.74991,67.06846
242.40002,201.99992,67.22379
242.70002,202.24985,67.34237
243.00002,202.49985,67.44875
243.30002,202.74997,67.34874
243.60000,202.99979,67.33046
243.90002,203.24990,67.32130
244.20002,203.49991,67.35006
244.50002,203.74991,67.22619
244.80002,203.99997,67.24770
245.10000,204.24992,67.36295
245.40002,204.49990,67.47285
245.70002,204.74985,67.65670
246.00002,204.99984,67.53739
246.30002,205.24992,67.82634
246.60000,205.49985,67.77612
246.90002,205.74985,67.96060
247.20002,205.99984,67.97942
247.50002,206.24990,67.79292
247.80002,206.49992,68.06590
248.10000,206.74979,68.17899
248.40002,206.99985,68.06252
248.70002,207.24989,68.24666
249.00002,207.49992,68.32824
249.30002,207.74990,68.29748
249.60000,207.99991,68.46358
249.90002,208.24991,68.37911
250.20002,208.49979,68.59862
250.50002,208.74992,68.47926
250.80002,208.99996,68.57226
251.10000,209.24991,68.55566
251.40002,209.49984,68.55428
251.70002,209.74990,68.62930
252.00002,209.99990,68.88430
252.30002,210.24985,68.78673
252.60000,210.49984,68.79169
252.90002,210.74984,69.02806
253.20002,210.99992,69.00444
253.50002,211.24985,68.92610
253.80002,211.49985,69.25332
254.10000,211.74997,69.38998
254.40002,211.99990,69.42074
254.70002,212.24990,69.34578
255.00002,212.49996,69.72910
255.30002,212.74991,69.63184
255.60000,212.99990,69.49762
255.90002,213.24992,69.54834
256.20002,213.49991,69.51473
256.50000,213.74986,69.64506
256.80002,213.99984,69.97552
257.10000,214.24990,69.83249
257.40003,214.49991,69.66462
257.70002,214.74991,69.73248
258.00000,214.99984,70.08557
258.30002,215.24990,69.89374
258.60000,215.49990,69.91991
258.90003,215.74983,69.94387
259.20002,215.99991,69.86748
259.50000,216.24984,70.06627
259.80002,216.49985,70.04662
260.10000,216.74991,70.25370
260.40003,216.99991,70.46685
260.70002,217.24992,70.66652
261.00000,217.49984,70.44146
261.30002,217.74998,70.50384
261.60000,217.99991,70.55044
261.90003,218.24991,70.66054
262.20000,218.49984,70.78426
262.50000,218.74985,70.98027
262.80003,218.99998,71.05803
263.10000,219.24991,70.94322
263.40003,219.49992,71.30621
263.70000,219.74990,71.39583
264.00000,219.99985,71.23805
264.30003,220.24991,71.62197
264.60000,220.49991,71.50696
264.90003,220.74990,71.61682
265.20000,220.99990,71.81165
265.50000,221.24983,71.78700
265.80003,221.49997,72.00921
266.10000,221.74992,72.00284
266.40003,221.99985,72.05174
266.70000,222.24991,72.13779
267.00000,222.49991,72.05606
267.30003,222.74991,72.45031
267.60000,222.99984,72.20722
267.90003,223.24990,72.26690
268.20000,223.49991,72.33266
268.50000,223.74984,72.41949
268.80003,223.99992,72.50465
269.10000,224.24990,72.51195
269.40003,224.49991,72.39543
269.70000,224.74984,72.69756
270.00000,224.99992,72.86176
270.30003,225.24990,72.72157
270.60000,225.49985,72.82565
270.90003,225.74991,72.75102
271.20000,225.99991,72.85706
271.50000,226.24992,73.06521
271.80003,226.49985,73.01043
272.10000,226.74991,73.07942
272.40003,226.99989,73.52233
272.70000,227.24992,73.42399
273.00000,227.49985,73.23225
273.30003,227.74996,73.46735
273.60000,227.99991,73.69780
273.90003,228.24984,73.71304
274.20000,228.49992,73.65693
274.50000,228.74990,73.71049
274.80003,228.99985,73.78996
275.10000,229.24984,74.13056
275.40003,229.49997,74.04609
275.70000,229.74990,74.25689
276.00000,229.99985,73.99537
276.30003,230.24991,74.13095
276.60000,230.49990,74.20686
276.90003,230.74992,74.09303
277.20000,230.99991,74.13257
277.50000,231.24991,74.29858
277.80003,231.49990,74.15683
278.10000,231.74979,74.43451
278.40003,231.99990,74.56754
278.70000,232.24996,74.55897
279.00000,232.49984,74.56656
279.30003,232.74990,74.69935
279.60000,232.99992,74.62453
279.90003,233.24991,74.51291
280.20000,233.49985,74.61552
280.50000,233.74984,74.71881
280.80003,233.99990,74.81200
281.10000,234.24983,75.09664
281.40003,234.49991,75.23649
281.70000,234.74991,75.30039
282.00000,234.99990,75.36153
282.30003,235.24992,75.51089
282.60000,235.49991,75.50457
282.90003,235.74997,75.20386
283.20000,235.99990,75.36325
283.50000,236.24985,75.67019
283.80003,236.49991,75.59051
284.10000,236.74991,75.81263
284.40003,236.99984,75.76074
284.70000,237.24990,75.65318
285.00000,237.49990,75.56273
285.30003,237.74991,75.79479
285.60000,237.99991,75.74599
285.90003,238.24990,75.61271
286.20000,238.49990,75.79989
286.50000,238.74991,75.80788
286.80003,238.99991,75.97967
287.10000,239.24997,76.21423
287.40003,239.49990,76.19708
287.70000,239.74990,76.20943
288.00000,239.99991,76.33893
288.30003,240.24997,76.24736
288.60000,240.49990,76.46702
288.90003,240.74990,76.41548
289.20000,240.99983,76.53488
289.50000,241.24991,76.63078
289.80003,241.49992,76.54381
290.10000,241.74985,76.86343
290.40003,241.99991,77.03576
290.70000,242.24984,77.09638
291.00000,242.49991,76.83158
291.30003,242.74990,76.85093
291.60000,242.99996,77.27827
291.90003,243.24983,77.20226
292.20000,243.49984,77.32423
292.50000,243.74992,77.43384
292.80003,243.99996,77.50445
293.10000,244.24985,77.26998
293.40003,244.49984,77.23857
293.70000,244.74997,77.28865
294.00000,244.99984,77.31639
294.30003,245.24990,77.27371
294.60000,245.49991,77.30316
294.90003,245.74991,77.44021
295.20000,245.99992,77.68207
295.50000,246.24985,77.55643
295.80003,246.49991,77.85989
296.10000,246.74984,77.83701
296.40003,246.99984,77.82486
296.70000,247.24998,78.08505
297.00000,247.49991,77.99729
297.30003,247.74991,78.10043
297.60000,247.99984,78.06902
297.90003,248.24992,77.97396
298.20000,248.49990,78.04594
298.50000,248.74991,77.98367
298.80003,248.99989,78.28183
299.10000,249.24992,78.27972
299.40003,249.49985,78.18647
299.70000,249.74991,78.13762
300.00000,249.99991,78.32784
300.30003,250.24995,78.01282
300.60000,250.49984,-0.04942
300.90003,250.74989,-0.01875
301.20000,250.99991,0.03442
301.50000,251.24988,0.15736
301.80003,251.49990,0.02912
302.10000,251.74985,-0.07794
302.40003,251.99989,0.09694
302.70000,252.24989,-0.25076
302.99803,252.49828,0.09630