File: EPR/EPR/RDSO EPR Tensile 50.is_tens_RawData/Specimen_RawData_14.csv
Time,Extension,Load
(sec),(mm),(N)
0.00000,0.00000,4.69959
0.30000,0.24937,5.14324
0.60000,0.49987,5.61060
0.90000,0.74987,6.07149
1.20000,0.99994,6.01490
1.50000,1.24994,6.66811
1.80000,1.49994,6.69825
2.10000,1.75000,6.79963
2.40000,1.99994,7.31447
2.70000,2.24987,7.29492
3.00000,2.49994,7.50743
3.30000,2.75000,7.64311
3.60000,2.99994,7.93020
3.90000,3.24987,7.87630
4.20000,3.49994,8.01188
4.50000,3.74994,8.28227
4.80000,3.99994,8.52099
5.10000,4.24987,8.66471
5.40000,4.49994,8.86174
5.70000,4.74994,8.82190
6.00000,4.99994,8.92039
6.30000,5.24994,9.06519
6.60000,5.49994,9.44469
6.90000,5.74987,9.36418
7.20000,5.99987,9.44332
7.50000,6.24987,9.50084
7.80000,6.49994,9.63902
8.10000,6.74987,9.93581
8.40000,6.99987,9.95816
8.70000,7.25000,10.11702
9.00000,7.50000,10.11932
9.30000,7.74994,10.21065
9.60000,7.99987,10.43473
9.90000,8.25000,10.52548
10.20000,8.49994,10.57355
10.50000,8.74987,10.88808
10.80000,8.99994,10.61466
11.10000,9.24987,10.79522
11.40000,9.49994,10.96824
11.70000,9.74994,11.01097
12.00000,9.99994,11.10441
12.30000,10.24994,11.25087
12.60000,10.49987,11.21657
12.90000,10.74994,11.32320
13.20000,10.99994,11.28640
13.50000,11.24987,11.51591
13.80000,11.49994,11.61141
14.10000,11.74994,11.65017
14.40000,11.99994,11.58265
14.70000,12.24994,11.66698
15.00000,12.50000,11.85328
15.30000,12.75000,11.97029
15.60000,12.99994,12.04124
15.90000,13.24994,12.15605
16.20000,13.49994,12.26595
16.50000,13.74987,12.17609
16.80000,13.99994,12.35655
17.10000,14.24987,12.38821
17.40000,14.49994,12.47802
17.70000,14.74987,12.60689
18.00000,14.99994,12.56265
18.30000,15.24994,12.55618
18.60000,15.49994,12.58626
18.90000,15.74987,12.61047
19.20000,15.99994,12.75443
19.50000,16.24993,12.98635
19.80000,16.49993,13.05568
20.10000,16.74994,12.98664
20.40000,16.99987,13.03001
20.70000,17.24993,13.02530
21.00000,17.49994,13.20788
21.30000,17.74994,13.05965
21.60000,17.99993,13.34331
21.90000,18.24994,13.45523
22.20000,18.49987,13.42215
22.50000,18.74994,13.31303
22.80000,18.99993,13.45351
23.10000,19.24987,13.65084
23.40000,19.49994,13.62374
23.70000,19.74993,13.49649
24.00000,19.99993,13.72385
24.30000,20.24994,13.86438
24.60000,20.49993,13.76476
24.90000,20.74993,13.70655
25.20000,20.99987,13.87952
25.50000,21.24993,14.10119
25.80000,21.50000,14.09948
26.10000,21.74993,14.13221
26.40000,21.99993,14.10590
26.70000,22.25000,14.23516
27.00000,22.49993,14.04337
27.30000,22.74987,14.01608
27.60000,22.99987,14.41097
27.90000,23.24993,14.30979
28.20000,23.49993,14.62000
28.50000,23.74987,14.38569
28.80000,23.99993,14.48138
29.10000,24.24994,14.47957
29.40000,24.49993,14.59624
29.70000,24.74993,14.55420
30.00000,24.99987,14.62579
30.30000,25.25000,14.95016
30.60000,25.49981,14.81742
30.90000,25.74987,14.93595
31.20000,25.99993,14.80483
31.50000,26.24993,14.91062
31.80000,26.49993,15.08624
32.10000,26.74993,15.10574
32.40000,26.99994,14.92272
32.70000,27.24993,15.15910
33.00000,27.49987,15.32830
33.30000,27.74999,15.19193
33.60000,27.99987,15.25759
33.90000,28.24993,15.22966
34.20000,28.49993,15.43678
34.50000,28.74993,15.42233
34.80000,28.99993,15.46946
35.10000,29.24987,15.54644
35.40000,29.49993,15.60711
35.70000,29.74994,15.57070
36.00000,29.99993,15.77375
36.30000,30.24993,15.68668
36.60000,30.49993,15.90032
36.90000,30.74993,15.75298
37.20000,30.99993,15.90414
37.50000,31.24987,16.05663
37.80000,31.49993,16.01336
38.10000,31.74987,16.08309
38.40000,31.99993,16.12910
38.70000,32.24993,16.22529
39.00000,32.49987,16.27164
39.30000,32.74987,16.50709
39.60000,33.00000,16.50037
39.90000,33.24993,16.34838
40.20000,33.49987,16.47416
40.50000,33.74993,16.79354
40.80000,33.99987,16.71254
41.10000,34.24993,16.74238
41.40000,34.49993,16.68025
41.70000,34.74993,16.77056
42.00000,34.99993,16.96411
42.30000,35.24993,17.15290
42.60000,35.49987,16.90903
42.90000,35.74993,17.05770
43.20000,35.99987,16.97606
43.50000,36.24987,17.04153
43.80000,36.49993,17.31416
44.10000,36.74993,17.21420
44.40000,36.99987,17.51438
44.70000,37.24987,17.36743
45.00000,37.49987,17.51266
45.30000,37.74999,17.44313
45.60000,37.99987,17.57185
45.90000,38.24987,17.60405
46.20000,38.49993,17.80470
46.50000,38.74993,17.81788
46.80000,38.99993,17.86874
47.10000,39.24993,18.02167
47.40000,39.49993,18.15265
47.70000,39.74993,17.98223
48.00000,39.99987,18.09963
48.30000,40.24993,17.91407
48.60000,40.49993,18.19552
48.90000,40.74981,18.19454
49.20000,40.99993,18.13447
49.50000,41.24993,18.53215
49.80000,41.49999,18.39975
50.10000,41.74987,18.51113
50.40000,41.99993,18.54930
50.70000,42.24999,18.70385
51.00000,42.49987,18.70208
51.30000,42.74993,18.60384
51.60000,42.99993,18.74844
51.90000,43.24987,18.83286
52.20000,43.49993,18.98751
52.50000,43.74993,19.07458
52.80000,43.99993,19.16155
53.10000,44.24987,19.10315
53.40000,44.49993,19.03788
53.70000,44.74993,19.25152
54.00000,44.99987,19.49622
54.30000,45.24993,19.35809
54.60000,45.49987,19.42802
54.90000,45.74993,19.45658
55.20000,45.99987,19.47976
55.50000,46.24987,19.74063
55.80000,46.49993,19.82354
56.10000,46.74986,19.89234
56.40000,46.99993,20.08633
56.70000,47.24999,19.86431
57.00000,47.49993,20.01915
57.30000,47.74987,20.25097
57.60000,47.99987,20.04889
57.90000,48.24993,20.10637
58.20000,48.49993,20.18844
58.50000,48.74987,20.35916
58.80000,48.99993,20.49406
59.10000,49.24993,20.59220
59.40000,49.49987,20.60053
59.70000,49.74993,20.58569
60.00000,49.99993,20.71279
60.30000,50.24993,20.77992
60.60000,50.49987,20.76238
60.90000,50.74993,20.94745
61.20000,50.99993,20.88797
61.50000,51.24993,21.04437
61.80000,51.49987,21.18079
62.10000,51.74993,21.11023
62.40000,51.99999,21.09088
62.70000,52.24993,21.18667
63.00000,52.49986,21.25272
63.30000,52.74993,21.36116
63.60000,52.99993,21.47332
63.90000,53.24987,21.68549
64.20000,53.49993,21.65932
64.50000,53.74987,21.81504
64.80000,53.99993,21.82656
65.10001,54.24987,21.91250
65.40000,54.49993,21.87639
65.70001,54.74993,21.97434
66.00000,54.99980,21.91696
66.30000,55.24993,22.13212
66.60001,55.49993,22.20621
66.90000,55.74987,22.17946
67.20001,55.99987,22.38800
67.50000,56.24993,22.57150
67.80000,56.49993,22.47110
68.10001,56.74981,22.74702
68.40000,56.99993,22.56258
68.70001,57.24993,22.75834
69.00000,57.49993,23.03921
69.30000,57.74993,23.08595
69.60001,57.99993,22.74815
69.90000,58.24987,23.17494
70.20001,58.49993,23.20919
70.50000,58.74987,23.13015
70.80000,58.99999,23.29822
71.10001,59.24993,23.18890
71.40000,59.49987,23.44159
71.70001,59.74993,23.49397
72.00000,59.99993,23.70943
72.30000,60.24987,23.47041
72.60001,60.49987,23.70502
72.90000,60.74993,23.81639
73.20001,60.99993,23.71972
73.50000,61.24987,24.10015
73.80000,61.49993,23.86642
74.10001,61.74993,23.95105
74.40000,61.99993,24.19046
74.70001,62.24993,24.31021
75.00000,62.49993,24.29703
75.30000,62.74993,24.28023
75.60001,62.99987,24.35525
75.90000,63.24993,24.54105
76.20001,63.49993,24.65591
76.50000,63.74992,24.57359
76.80000,63.99993,24.60945
77.10001,64.24987,24.94780
77.40000,64.49993,24.67575
77.70001,64.74993,24.99117
78.00000,64.99992,25.04203
78.30000,65.24986,25.09735
78.60001,65.49993,25.23043
78.90000,65.74993,25.22063
79.20001,65.99993,25.28835
79.50000,66.24986,25.43642
79.80000,66.49980,25.44177
80.10001,66.74992,25.64517
80.40000,66.99999,25.61802
80.70001,67.24992,25.84900
81.00001,67.49993,25.90393
81.30000,67.74993,26.03349
81.60001,67.99993,26.04054
81.90000,68.24993,26.11943
82.20001,68.49987,26.45425
82.50001,68.74993,26.21200
82.80000,68.99992,26.19142
83.10001,69.24986,26.61678
83.40000,69.49992,26.41123
83.70001,69.74999,26.56808
84.00001,69.99987,26.70420
84.30000,70.24986,26.77574
84.60001,70.49993,26.59356
84.90000,70.74993,26.79157
85.20001,70.99986,26.97081
85.50001,71.24986,27.05969
85.80000,71.49993,27.02622
86.10001,71.74987,26.86658
86.40000,71.99986,27.20508
86.70001,72.24993,27.32356
87.00001,72.49986,27.37555
87.30000,72.74986,27.44630
87.60001,72.99987,27.40901
87.90000,73.24999,27.63510
88.20001,73.49993,27.83051
88.50001,73.74987,27.87515
88.80000,73.99999,27.83928
89.10001,74.24999,27.93949
89.40000,74.49993,27.88804
89.70001,74.74986,28.31144
90.00001,74.99986,28.37960
90.30000,75.24999,28.18193
90.60001,75.49986,28.28596
90.90000,75.74980,28.57026
91.20001,75.99992,28.36309
91.50001,76.24993,28.58922
91.80000,76.49993,28.75087
92.10001,76.74993,28.65224
92.40000,76.99993,28.77856
92.70001,77.24986,28.93041
93.00001,77.49993,28.72721
93.30000,77.74992,28.93090
93.60001,77.99986,28.92649
93.90000,78.24986,29.30658
94.20001,78.49992,29.21456
94.50001,78.74999,29.38434
94.80000,78.99993,29.29722
95.10001,79.24993,29.66315
95.40000,79.49992,29.44177
95.70001,79.74993,29.55227
96.00001,79.99986,30.04912
96.30000,80.24992,29.84190
96.60001,80.49986,30.07897
96.90000,80.74986,30.10214
97.20001,80.99993,30.21460
97.50001,81.24986,30.13291
97.80000,81.49993,30.05358
98.10001,81.74987,30.29158
98.40000,81.99993,30.42583
98.70001,82.24992,30.23699
99.00001,82.49993,30.75271
99.30000,82.74986,30.58685
99.60001,82.99992,30.63237
99.90000,83.24993,30.82509
100.20001,83.49992,30.89354
100.50001,83.74986,31.00011
100.80000,83.99999,30.97527
101.10001,84.24980,31.09199
101.40000,84.49992,31.10987
101.70001,84.74993,31.25006
102.00001,84.99992,31.30695
102.30000,85.24993,31.43342
102.60001,85.49985,31.56670
102.90000,85.74999,31.41475
103.20001,85.99993,31.72384
103.50001,86.24987,31.81003
103.80000,86.49993,31.77431
104.10001,86.74992,31.96575
104.40000,86.99986,31.86055
104.70001,87.24992,31.95473
105.00001,87.49993,32.19365
105.30000,87.74993,32.41415
105.60001,87.99993,32.32850
105.90000,88.24993,32.48942
106.20001,88.49992,32.51343
106.50001,88.74986,32.66939
106.80000,88.99992,32.67547
107.10001,89.24992,32.77219
107.40000,89.49992,32.69022
107.70001,89.74986,32.79709
108.00001,89.99986,33.04287
108.30000,90.24998,33.09505
108.60001,90.49992,33.07771
108.90000,90.74987,33.23039
109.20001,90.99992,33.28507
109.50001,91.24986,33.33412
109.80000,91.49992,33.52537
110.10001,91.74986,33.46882
110.40000,91.99993,33.87190
110.70001,92.24992,33.76238
111.00001,92.49986,33.88263
111.30000,92.74987,33.81520
111.60001,92.99998,33.93574
111.90000,93.24992,33.99180
112.20001,93.49986,33.70157
112.50001,93.74999,34.15644
112.80000,93.99992,34.44799
113.10001,94.24986,34.37464
113.40001,94.49992,34.36067
113.70001,94.74985,34.68221
114.00001,94.99992,34.43427
114.30000,95.24986,34.76835
114.60001,95.49992,34.65682
114.90001,95.74993,34.71141
115.20001,95.99986,34.73973
115.50001,96.24992,34.98449
115.80000,96.49992,35.01565
116.10001,96.74992,35.24360
116.40001,96.99985,35.17828
116.70001,97.24992,35.16035
117.00001,97.49993,35.25624
117.30000,97.74992,35.57273
117.60001,97.99986,35.49281
117.90001,98.24986,35.62746
118.20001,98.49992,35.62428
118.50001,98.74992,35.65422
118.80000,98.99992,35.94660
119.10001,99.24993,35.92171
119.40001,99.49986,36.06395
119.70001,99.74992,35.92421
120.00001,99.99992,36.27554
120.30000,100.24992,36.25236
120.60001,100.49986,36.30988
120.90001,100.74992,36.34727
121.20001,100.99992,36.42758
121.50001,101.24986,36.54244
121.80000,101.49992,36.86652
122.10001,101.74992,36.79160
122.40001,101.99992,36.83178
122.70001,102.24992,36.73486
123.00001,102.49986,36.95193
123.30000,102.74992,37.10593
123.60001,102.99986,37.30296
123.90001,103.24992,37.26920
124.20001,103.49993,37.28224
124.50001,103.74992,37.42487
124.80000,103.99993,37.66738
125.10001,104.24986,37.58756
125.40001,104.49992,37.58393
125.70001,104.74992,37.79972
126.00001,104.99986,37.89934
126.30000,105.24992,37.69320
126.60001,105.49992,37.92570
126.90001,105.74993,38.02507
127.20001,105.99992,38.31035
127.50001,106.24993,38.11582
127.80000,106.49992,38.16909
128.10001,106.74986,38.31422
128.40001,106.99992,38.34014
128.70002,107.24999,38.35984
129.00000,107.49985,38.55119
129.30000,107.74992,38.67325
129.60001,107.99993,38.72827
129.90001,108.24992,38.88007
130.20002,108.49986,39.01330
130.50000,108.74987,39.05672
130.80000,108.99998,39.02795
131.10000,109.24992,39.15648
131.40002,109.49992,39.21136
131.70002,109.74992,39.41927
132.00000,109.99992,39.47562
132.30000,110.24993,39.31470
132.60000,110.49992,39.68793
132.90002,110.74992,39.46043
133.20002,110.99986,39.64609
133.50000,111.24986,39.62193
133.80000,111.49992,39.92333
134.10000,111.74992,39.98370
134.40002,111.99992,40.09674
134.70002,112.24986,39.94028
135.00000,112.49992,40.22870
135.30000,112.74992,40.15422
135.60000,112.99986,40.21262
135.90002,113.24992,40.32008
136.20002,113.49992,40.60678
136.50000,113.74992,40.49967
136.80000,113.99992,40.52872
137.10000,114.24992,40.73437
137.40002,114.49993,40.91278
137.70002,114.74986,40.79587
138.00000,114.99993,40.93606
138.30000,115.24992,40.82600
138.60000,115.49986,41.02896
138.90002,115.74992,40.96575
139.20002,115.99992,41.14617
139.50000,116.24992,41.35226
139.80000,116.49992,41.55826
140.10000,116.74993,41.32139
140.40002,116.99992,41.60221
140.70002,117.24993,41.66493
141.00000,117.49992,41.89268
141.30000,117.74993,41.86642
141.60000,117.99992,41.73387
141.90002,118.24986,42.03027
142.20002,118.49992,42.07467
142.50000,118.74992,41.86196
142.80000,118.99998,42.09461
143.10000,119.24986,42.25014
143.40002,119.49986,42.32373
143.70002,119.74992,42.43584
144.00000,119.99986,42.46960
144.30000,120.24986,42.69741
144.60000,120.49992,42.59509
144.90002,120.74992,42.71897
145.20002,120.99992,42.72122
145.50000,121.24985,42.97553
145.80000,121.49992,43.03237
146.10000,121.74986,42.97274
146.40002,121.99992,43.14468
146.70002,122.24992,42.99851
147.00000,122.49992,43.31853
147.30000,122.74992,43.23660
147.60000,122.99986,43.39512
147.90002,123.24998,43.30848
148.20002,123.49992,43.61679
148.50000,123.74992,43.60782
148.80000,123.99998,43.62199
149.10000,124.24992,43.78800
149.40002,124.49986,43.71352
149.70002,124.74986,44.04074
150.00000,124.99986,44.21253
150.30000,125.24992,44.03383
150.60000,125.49992,44.07567
150.90002,125.74992,44.28534
151.20002,125.99992,44.38359
151.50000,126.24986,44.41181
151.80000,126.49985,44.48629
152.10000,126.74986,44.58263
152.40002,126.99998,44.82542
152.70002,127.24985,44.81915
153.00000,127.49985,44.86991
153.30000,127.74998,44.81101
153.60000,127.99992,44.78392
153.90002,128.24985,45.07145
154.20002,128.49991,45.23055
154.50000,128.74993,45.23555
154.80000,128.99992,45.28406
155.10000,129.24992,45.32424
155.40002,129.49991,45.37740
155.70002,129.74985,45.43184
156.00000,129.99992,45.56057
156.30000,130.24992,45.63504
156.60000,130.49997,45.71624
156.90002,130.74986,45.99480
157.20002,130.99991,45.79523
157.50000,131.24998,45.89479
157.80000,131.49992,46.01024
158.10000,131.74991,46.17532
158.40002,131.99992,46.15753
158.70002,132.24992,46.17003
159.00000,132.49992,46.58746
159.30000,132.74992,46.40523
159.60000,132.99986,46.57815
159.90002,133.24991,46.52557
160.20002,133.49992,46.63699
160.50000,133.74992,46.84407
160.80000,133.99998,46.90772
161.10000,134.24992,46.84162
161.40002,134.49985,46.96299
161.70002,134.74998,47.16742
162.00002,134.99992,46.98690
162.30000,135.24991,47.05756
162.60000,135.49991,47.10534
162.90002,135.74985,47.40948
163.20002,135.99992,47.28830
163.50002,136.24986,47.46338
163.80000,136.49992,47.60067
164.10000,136.74991,47.56368
164.40002,136.99993,47.62170
164.70002,137.24992,47.64262
165.00002,137.49997,47.79070
165.30000,137.74991,47.83876
165.60000,137.99985,47.81760
165.90002,138.24992,48.09253
166.20002,138.49998,48.12551
166.50002,138.74992,48.15947
166.80000,138.99991,48.28177
167.10000,139.24985,48.29005
167.40002,139.49998,48.45366
167.70002,139.74986,48.54632
168.00002,139.99986,48.43862
168.30000,140.24991,48.50026
168.60000,140.49992,48.61776
168.90002,140.74991,48.61169
169.20002,140.99997,48.83625
169.50002,141.24999,48.75820
169.80000,141.49985,48.89035
170.10000,141.74986,49.06841
170.40002,141.99997,49.21424
170.70002,142.24991,48.97301
171.00002,142.49985,49.23707
171.30000,142.74985,49.28333
171.60000,142.99992,49.29636
171.90002,143.24998,49.50407
172.20002,143.49985,49.71855
172.50002,143.74991,49.67332
172.80000,143.99998,49.94517
173.10000,144.24986,49.77279
173.40002,144.49986,49.80380
173.70002,144.74991,50.03587
174.00002,144.99985,50.13901
174.30000,145.24992,50.10491
174.60000,145.49998,49.97187
174.90002,145.74997,50.14382
175.20002,145.99991,50.41307
175.50002,146.24985,50.40920
175.80000,146.49992,50.21726
176.10000,146.74991,50.39685
176.40002,146.99985,50.51607
176.70002,147.24985,50.57045
177.00002,147.49992,50.42679
177.30000,147.74992,50.67796
177.60000,147.99992,50.97696
177.90002,148.24991,51.02797
178.20002,148.49992,51.06236
178.50002,148.74986,50.94011
178.80000,148.99998,51.10063
179.10000,149.24991,51.12955
179.40002,149.49991,51.30462
179.70002,149.74984,51.27644
180.00002,149.99992,51.57961
180.30000,150.24992,51.41713
180.60000,150.49986,51.59891
180.90002,150.74993,51.58461
181.20002,150.99992,51.74738
181.50002,151.24992,51.69593
181.80000,151.49985,51.74988
182.10000,151.74999,51.90688
182.40002,151.99992,51.95754
182.70002,152.24992,51.87228
183.00002,152.49992,52.09552
183.30000,152.74991,52.02512
183.60000,152.99985,52.16560
183.90002,153.24985,52.26688
184.20002,153.49992,52.38855
184.50002,153.74991,52.35816
184.80000,153.99992,52.29486
185.10000,154.24985,52.43289
185.40002,154.49992,52.59645
185.70002,154.74992,52.58082
186.00002,154.99991,52.76746
186.30000,155.24991,52.79132
186.60000,155.49992,52.87168
186.90002,155.74992,52.77775
187.20002,155.99991,53.12707
187.50002,156.24985,53.29514
187.80000,156.49999,53.15525
188.10000,156.74986,53.38271
188.40002,156.99992,53.13168
188.70002,157.24991,53.61094
189.00002,157.49991,53.59193
189.30000,157.74991,53.55013
189.60000,157.99992,53.60697
189.90002,158.24990,53.70983
190.20002,158.49985,53.84271
190.50002,158.74991,53.69978
190.80000,158.99992,54.01314
191.10000,159.24985,53.94365
191.40002,159.49991,54.14558
191.70002,159.74991,53.86060
192.00002,159.99991,54.20610
192.30000,160.24992,54.21482
192.60000,160.49985,54.04832
192.90002,160.74991,54.46903
193.20002,160.99991,54.32928
193.50002,161.24984,54.36290
193.80000,161.49985,54.61402
194.10000,161.74991,54.53136
194.40002,161.99986,54.55640
194.70002,162.24990,54.63460
195.00002,162.49992,54.82168
195.30000,162.74991,54.63578
195.60000,162.99985,54.94869
195.90002,163.24991,55.04468
196.20002,163.49992,55.01254
196.50002,163.74992,55.08942
196.80000,163.99991,55.21662
197.10000,164.24991,55.38146
197.40002,164.49990,55.50729
197.70002,164.74985,55.45839
198.00002,164.99985,55.61308
198.30000,165.24991,55.45986
198.60000,165.49991,55.66076
198.90002,165.74990,55.66071
199.20002,165.99992,55.94584
199.50002,166.24985,55.86102
199.80000,166.49991,56.05530
200.10000,166.74984,55.75567
200.40002,166.99992,55.98337
200.70002,167.24991,56.26355
201.00002,167.49986,56.19936
201.30000,167.74997,56.24503
201.60000,167.99990,56.15134
201.90002,168.24985,56.28849
202.20002,168.49991,56.40325
202.50002,168.74991,56.41467
202.80000,168.99997,56.40717
203.10000,169.24985,56.49620
203.40002,169.49985,56.85037
203.70002,169.74991,56.77976
204.00002,169.99984,56.84308
204.30000,170.24990,56.91579
204.60000,170.49985,56.95847
204.90002,170.74991,56.86326
205.20002,170.99986,57.03138
205.50002,171.24984,57.03618
205.80000,171.49990,57.13261
206.10000,171.74983,57.16549
206.40002,171.99986,57.21449
206.70002,172.24997,57.39084
207.00002,172.49998,57.44803
207.30000,172.74993,57.70875
207.60000,172.99986,57.56577
207.90002,173.24992,57.69954
208.20002,173.49990,57.55073
208.50002,173.74985,57.62085
208.80000,173.99991,57.76873
209.10000,174.24986,57.85840
209.40002,174.49992,57.95728
209.70002,174.74990,58.08150
210.00002,174.99991,58.11868
210.30000,175.24991,57.86511
210.60000,175.49979,58.11795
210.90002,175.74990,58.24059
211.20002,175.99991,58.36035
211.50002,176.24991,58.34551
211.80000,176.49986,58.57399
212.10000,176.74984,58.59766
212.40002,176.99996,58.53102
212.70002,177.24991,58.99485
213.00002,177.49984,58.74682
213.30000,177.74992,58.90592
213.60000,177.99990,58.90175
213.90002,178.24985,58.98250
214.20002,178.49991,59.05914
214.50002,178.74992,58.97138
214.80000,178.99984,59.21535
215.10000,179.24991,59.15925
215.40002,179.49991,59.42316
215.70002,179.74991,59.41532
216.00002,179.99986,59.52405
216.30000,180.24990,59.39856
216.60000,180.49991,59.47647
216.90002,180.74991,59.50999
217.20002,180.99992,59.50342
217.50002,181.24985,59.68903
217.80000,181.49985,59.74896
218.10000,181.74985,59.75234
218.40002,181.99991,59.80065
218.70002,182.24992,59.95314
219.00002,182.49985,59.94951
219.30000,182.74985,60.01964
219.60000,182.99991,60.09730
219.90002,183.24992,60.22514
220.20002,183.49992,60.14791
220.50002,183.74985,60.41972
220.80000,183.99991,60.30746
221.10000,184.24990,60.45113
221.40002,184.49992,60.52218
221.70002,184.74985,60.54520
222.00002,184.99985,60.60950
222.30000,185.24991,60.69495
222.60000,185.49992,60.59102
222.90002,185.74992,60.83362
223.20002,185.99985,60.87145
223.50002,186.24986,60.91138
223.80000,186.49997,61.10988
224.10000,186.74992,60.89712
224.40002,186.99985,61.02154
224.70002,187.24985,61.13389
225.00002,187.49991,60.95181
225.30002,187.74997,61.25247
225.60000,187.99985,61.36399
225.90002,188.24991,61.26266
226.20002,188.49991,61.42387
226.50002,188.74984,61.38526
226.80002,188.99985,61.52795
227.10000,189.24991,61.45783
227.40002,189.49986,61.81964
227.70002,189.74984,61.79073
228.00002,189.99984,61.99722
228.30002,190.24990,61.85355
228.60000,190.49991,61.98193
228.90002,190.74984,62.14863
229.20002,190.99990,62.02760
229.50002,191.24992,62.31224
229.80002,191.49985,62.13736
230.10000,191.74978,62.20224
230.40002,191.99997,62.10668
230.70002,192.24990,62.35379
231.00002,192.49983,62.43018
231.30002,192.74991,62.33419
231.60000,192.99991,62.61677
231.90002,193.24990,62.93899
232.20002,193.49985,62.56601
232.50002,193.74991,62.76960
232.80002,193.99997,63.00583
233.10000,194.24984,62.90142
233.40002,194.49979,63.31541
233.70002,194.74998,63.03018
234.00002,194.99991,63.01715
234.30002,195.24992,63.26151
234.60000,195.49990,63.02979
234.90002,195.74990,63.18591
235.20002,195.99991,63.14724
235.50002,196.24986,63.36912
235.80002,196.49984,63.29356
236.10000,196.74990,63.22477
236.40002,196.99983,63.43776
236.70002,197.24991,63.55958
237.00002,197.49984,63.57134
237.30002,197.74990,63.46158
237.60000,197.99985,63.57511
237.90002,198.24991,63.58149
238.20002,198.49991,63.85167
238.50002,198.74984,63.92821
238.80002,198.99990,63.88871
239.10000,199.24991,63.85892
239.40002,199.49991,64.18516
239.70002,199.74984,64.20687
240.00002,199.99985,64.11441
240.30002,200.24991,64.30516
240.60000,200.49991,64.08956
240.90002,200.74992,64.48269
241.20002,200.99990,64.36244
241.50002,201.24985,64.58549
241.80002,201.49991,64.48519
242.10000,201.74991,64.50146
242.40002,201.99992,64.69599
242.70002,202.24990,64.65208
243.00002,202.49985,64.90698
243.30002,202.74997,65.05314
243.60000,202.99979,64.94721
243.90002,203.24990,64.89179
244.20002,203.49991,65.17515
244.50002,203.74984,65.11543
244.80002,203.99997,65.05417
245.10000,204.24984,65.21685
245.40002,204.49990,65.29221
245.70002,204.74991,65.27168
246.00002,204.99984,65.47567
246.30002,205.24992,65.36248
246.60000,205.49990,65.41824
246.90002,205.74985,65.76448
247.20002,205.99984,65.76683
247.50002,206.24990,65.79035
247.80002,206.49992,65.88139
248.10000,206.74979,66.13143
248.40002,206.99985,66.00859
248.70002,207.24989,65.79020
249.00002,207.49992,66.09356
249.30002,207.74990,66.17397
249.60000,207.99991,66.09831
249.90002,208.24984,66.24404
250.20002,208.49979,66.23551
250.50002,208.74992,66.05975
250.80002,208.99996,66.37732
251.10000,209.24985,66.34983
251.40002,209.49984,66.21204
251.70002,209.74990,66.20219
252.00002,209.99990,66.55352
252.30002,210.24985,66.50868
252.60000,210.49984,66.52961
252.90002,210.74984,66.66671
253.20002,210.99992,66.75452
253.50002,211.24985,66.60860
253.80002,211.49985,66.80313
254.10000,211.74990,66.75217
254.40002,211.99990,66.80984
254.70002,212.24990,66.86604
255.00002,212.49996,67.15882
255.30002,212.74991,67.26833
255.60000,212.99990,67.29533
255.90002,213.24985,67.32150
256.20002,213.49996,67.52161
256.50000,213.74991,67.42660
256.80002,213.99984,67.67292
257.10000,214.24990,67.77626
257.40003,214.49991,67.55954
257.70002,214.74991,67.66018
258.00000,214.99984,67.71776
258.30002,215.24990,68.14415
258.60000,215.49985,68.13019
258.90003,215.74983,67.98887
259.20002,215.99991,68.13793
259.50000,216.24984,68.29537
259.80002,216.49985,68.13533
260.10000,216.74983,68.32898
260.40003,216.99991,68.42272
260.70002,217.24992,68.41458
261.00000,217.49984,68.55443
261.30002,217.74998,68.46490
261.60000,217.99991,68.49073
261.90003,218.24991,68.73651
262.20000,218.49990,68.79982
262.50000,218.74985,68.81374
262.80003,218.99998,68.81775
263.10000,219.24991,68.63964
263.40003,219.49992,68.97147
263.70000,219.74990,69.04452
264.00000,219.99985,68.97828
264.30003,220.24991,69.05810
264.60000,220.49991,69.15531
264.90003,220.74990,69.12337
265.20000,220.99990,69.10146
265.50000,221.24983,69.30927
265.80003,221.49997,69.09392
266.10000,221.74992,69.14081
266.40003,221.99990,69.18633
266.70000,222.24991,68.97264
267.00000,222.49991,69.11372
267.30003,222.74991,69.06849
267.60000,222.99984,69.15629
267.90003,223.24990,69.16840
268.20000,223.49991,69.35680
268.50000,223.74984,69.37562
268.80003,223.99992,69.48258
269.10000,224.24990,69.44402
269.40003,224.49985,69.62493
269.70000,224.74984,69.87248
270.00000,224.99992,69.96876
270.30003,225.24990,69.76806
270.60000,225.49985,69.69882
270.90003,225.74984,70.11365
271.20000,225.99991,70.04525
271.50000,226.24992,70.00924
271.80003,226.49990,70.21381
272.10000,226.74991,70.13031
272.40003,226.99989,70.02021
272.70000,227.24984,70.51521
273.00000,227.49990,70.49129
273.30003,227.74991,70.61105
273.60000,227.99991,70.52403
273.90003,228.24984,70.65893
274.20000,228.49992,70.79308
274.50000,228.74990,70.92686
274.80003,228.99991,71.22311
275.10000,229.24984,70.91505
275.40003,229.49997,71.04935
275.70000,229.74990,71.13667
276.00000,229.99991,71.08199
276.30003,230.24991,71.24271
276.60000,230.49990,71.47163
276.90003,230.74985,71.59943
277.20000,230.99991,71.65808
277.50000,231.24991,71.81370
277.80003,231.49990,71.63495
278.10000,231.74984,71.85765
278.40003,231.99990,72.07056
278.70000,232.24991,72.05326
279.00000,232.49984,72.03925
279.30003,232.74990,72.23295
279.60000,232.99992,72.31184
279.90003,233.24991,72.29125
280.20000,233.49985,72.40307
280.50000,233.74984,72.39876
280.80003,233.99990,72.37259
281.10000,234.24990,72.25156
281.40003,234.49991,72.14695
281.70000,234.74991,72.23148
282.00000,234.99990,72.28836
282.30003,235.24992,72.36054
282.60000,235.49985,72.51377
282.90003,235.74991,72.66704
283.20000,235.99990,72.70295
283.50000,236.24985,72.88714
283.80003,236.49991,72.80174
284.10000,236.74991,72.93556
284.40003,236.99984,72.91061
284.70000,237.24984,73.10661
285.00000,237.49990,73.22519
285.30003,237.74991,73.45877
285.60000,237.99991,73.52973
285.90003,238.24990,73.39380
286.20000,238.49990,73.66776
286.50000,238.74991,73.87620
286.80003,238.99991,73.78643
287.10000,239.24997,73.99733
287.40003,239.49990,73.91222
287.70000,239.74990,74.27649
288.00000,239.99991,74.38267
288.30003,240.24997,74.10459
288.60000,240.49990,74.52648
288.90003,240.74990,74.38154
289.20000,240.99991,74.54853
289.50000,241.24997,74.53104
289.80003,241.49992,74.59538
290.10000,241.74985,74.75879
290.40003,241.99991,74.87364
290.70000,242.24984,74.92020
291.00000,242.49991,75.02971
291.30003,242.74990,75.05754
291.60000,242.99990,75.02398
291.90003,243.24983,74.95200
292.20000,243.49984,74.94553
292.50000,243.74992,74.57798
292.80003,243.99996,74.85502
293.10000,244.24985,74.67339
293.40003,244.49984,74.90682
293.70000,244.74997,75.04593
294.00000,244.99990,74.85982
294.30003,245.24985,75.08263
294.60000,245.49983,75.14682
294.90003,245.74991,75.23002
295.20000,245.99984,75.37893
295.50000,246.24985,75.56700
295.80003,246.49991,75.46615
296.10000,246.74984,75.76309
296.40003,246.99984,75.88642
296.70000,247.24998,76.06258
297.00000,247.49996,76.04322
297.30003,247.74991,76.12000
297.60000,247.99984,76.21325
297.90003,248.24992,76.26740
298.20000,248.49990,76.14735
298.50000,248.74985,76.37495
298.80003,248.99989,76.42096
299.10000,249.24992,75.91014
299.40003,249.49990,-0.13307
299.70000,249.74991,-0.06643
300.00000,249.99991,-0.03972
300.30003,250.24990,-0.10901
300.60000,250.49984,0.07396
300.90003,250.74989,-0.02924
301.20000,250.99991,-0.02522
301.42203,251.18504,-0.14737