File: EPR/EPR/RDSO EPR Tensile 50.is_tens_RawData/Specimen_RawData_13.csv
Time,Extension,Load
(sec),(mm),(N)
0.00000,0.00000,-0.42354
0.30000,0.24937,0.06754
0.60000,0.49987,0.61893
0.90000,0.74994,1.05146
1.20000,0.99994,1.47305
1.50000,1.24994,1.96114
1.80000,1.49994,2.26655
2.10000,1.74994,2.63763
2.40000,2.00000,2.89586
2.70000,2.24987,3.32030
3.00000,2.49994,3.43275
3.30000,2.75000,3.83048
3.60000,2.99994,3.91099
3.90000,3.24987,4.27854
4.20000,3.49994,4.54637
4.50000,3.74994,4.51285
4.80000,3.99994,4.94278
5.10000,4.24987,4.98492
5.40000,4.49994,5.31885
5.70000,4.74994,5.38882
6.00000,4.99994,5.60491
6.30000,5.24994,5.97452
6.60000,5.49994,6.19585
6.90000,5.74981,6.33952
7.20000,5.99994,6.61990
7.50000,6.24987,6.49897
7.80000,6.49994,6.94055
8.10000,6.74994,7.02243
8.40000,6.99987,7.28233
8.70000,7.25000,7.32794
9.00000,7.49994,7.36793
9.30000,7.74994,7.74871
9.60000,7.99987,7.85082
9.90000,8.25000,8.04094
10.20000,8.49994,8.11596
10.50000,8.74994,8.29471
10.80000,8.99994,8.51315
11.10000,9.24987,8.53863
11.40000,9.49994,8.72758
11.70000,9.74994,8.96905
12.00000,9.99994,9.06920
12.30000,10.24994,9.07616
12.60000,10.49987,9.05994
12.90000,10.75000,9.41769
13.20000,10.99994,9.54720
13.50000,11.24987,9.55641
13.80000,11.49994,9.96350
14.10000,11.74994,9.81253
14.40000,11.99994,10.08762
14.70000,12.24994,9.99653
15.00000,12.49994,10.28896
15.30000,12.74994,10.31498
15.60000,12.99994,10.50441
15.90000,13.24994,10.72760
16.20000,13.49994,10.68625
16.50000,13.74987,10.92654
16.80000,13.99994,10.76847
17.10000,14.24987,10.86833
17.40000,14.49994,10.92007
17.70000,14.74994,11.50121
18.00000,14.99987,11.18703
18.30000,15.24994,11.29762
18.60000,15.49987,11.40924
18.90000,15.74987,11.65208
19.20000,15.99994,11.66727
19.50000,16.24993,11.66154
19.80000,16.49993,11.87165
20.10000,16.74994,11.79884
20.40000,16.99987,11.69760
20.70000,17.24993,12.14590
21.00000,17.49994,12.03957
21.30000,17.74994,12.16492
21.60000,17.99993,12.26291
21.90000,18.24994,12.30961
22.20000,18.49987,12.39267
22.50000,18.74994,12.48390
22.80000,19.00000,12.48003
23.10000,19.24987,12.73900
23.40000,19.49994,12.48875
23.70000,19.74993,12.63448
24.00000,19.99993,12.81402
24.30000,20.24994,12.76428
24.60000,20.49993,12.89727
24.90000,20.74993,12.88752
25.20000,20.99987,13.19798
25.50000,21.24993,12.99497
25.80000,21.50000,13.14491
26.10000,21.74993,13.14359
26.40000,21.99987,13.31318
26.70000,22.25000,13.15751
27.00000,22.49993,13.19519
27.30000,22.74987,13.20121
27.60000,22.99994,13.58253
27.90000,23.24993,13.62163
28.20000,23.49993,13.49114
28.50000,23.74987,13.68274
28.80000,23.99993,13.77696
29.10000,24.24994,13.59924
29.40000,24.49993,13.85815
29.70000,24.74993,13.89804
30.00000,24.99993,13.98986
30.30000,25.25000,14.07346
30.60000,25.49981,14.08429
30.90000,25.74987,14.40926
31.20000,26.00000,14.13525
31.50000,26.24987,14.08855
31.80000,26.49993,14.30273
32.10000,26.74993,14.34394
32.40000,27.00000,14.33590
32.70000,27.24993,14.37496
33.00000,27.49987,14.43875
33.30000,27.74993,14.41670
33.60000,27.99987,14.69091
33.90000,28.24993,14.62147
34.20000,28.49993,14.59046
34.50000,28.74993,14.70659
34.80000,28.99993,14.89141
35.10000,29.24987,14.72134
35.40000,29.49993,14.78881
35.70000,29.74994,14.86809
36.00000,29.99993,14.92013
36.30000,30.24993,15.20438
36.60000,30.49993,14.75862
36.90000,30.74993,15.01984
37.20000,30.99987,15.06502
37.50000,31.24987,14.99206
37.80000,31.49993,15.34104
38.10000,31.74987,15.20923
38.40000,31.99993,15.61245
38.70000,32.24993,15.34902
39.00000,32.49993,15.46016
39.30000,32.74987,15.56467
39.60000,33.00000,15.59809
39.90000,33.24987,15.56663
40.20000,33.49987,15.73054
40.50000,33.74993,15.95912
40.80000,33.99987,15.93325
41.10000,34.24993,15.88866
41.40000,34.49993,15.92041
41.70000,34.74993,16.11808
42.00000,34.99993,16.14321
42.30000,35.24993,16.24136
42.60000,35.49993,16.45755
42.90000,35.74993,16.32495
43.20000,35.99987,16.28252
43.50000,36.24987,16.41354
43.80000,36.50000,16.45172
44.10000,36.74993,16.48435
44.40000,36.99993,16.47646
44.70000,37.24987,16.60876
45.00000,37.49987,16.60861
45.30000,37.74999,16.82559
45.60000,37.99987,16.91540
45.90000,38.24987,16.77859
46.20000,38.49993,16.84200
46.50000,38.74993,16.98611
46.80000,38.99993,16.90026
47.10000,39.24993,17.15285
47.40000,39.49993,17.19352
47.70000,39.74993,17.11596
48.00000,39.99993,17.05990
48.30000,40.25000,17.50874
48.60000,40.49993,17.48086
48.90000,40.74987,17.41045
49.20000,40.99993,17.45749
49.50000,41.24993,17.58621
49.80000,41.49993,17.21548
50.10000,41.74993,17.64280
50.40000,41.99993,17.62071
50.70000,42.24999,17.66520
51.00000,42.49987,17.77118
51.30000,42.74993,17.78162
51.60000,42.99987,17.85017
51.90000,43.24987,18.04142
52.20000,43.49993,18.10482
52.50000,43.74993,18.12878
52.80000,43.99993,17.93112
53.10000,44.24993,18.26275
53.40000,44.49993,18.54749
53.70000,44.74999,18.39824
54.00000,44.99987,18.48060
54.30000,45.24993,18.33850
54.60000,45.49987,18.45140
54.90000,45.74993,18.62148
55.20000,45.99987,18.60712
55.50000,46.24987,18.74893
55.80000,46.49993,18.96526
56.10000,46.74986,18.96115
56.40000,46.99993,18.99167
56.70000,47.24993,19.06243
57.00000,47.49993,19.02107
57.30000,47.74993,19.22981
57.60000,47.99987,19.24926
57.90000,48.24993,19.33055
58.20000,48.49993,19.44144
58.50000,48.74987,19.55782
58.80000,48.99993,19.52680
59.10000,49.24993,19.43311
59.40000,49.49987,19.60094
59.70000,49.74993,19.73284
60.00000,49.99993,19.69854
60.30000,50.24993,19.71236
60.60000,50.49993,20.01121
60.90000,50.74993,20.13352
61.20000,50.99993,19.78963
61.50000,51.24987,19.96167
61.80000,51.49987,20.01685
62.10000,51.74993,20.18815
62.40000,51.99999,20.18070
62.70000,52.24993,20.41517
63.00000,52.49986,20.41884
63.30000,52.74993,20.37234
63.60000,52.99993,20.56050
63.90000,53.24987,20.61092
64.20000,53.49993,20.66252
64.50000,53.74993,20.73019
64.80000,53.99993,20.59852
65.10001,54.24987,20.82495
65.40000,54.49993,21.01973
65.70001,54.74993,21.17481
66.00000,54.99987,21.03536
66.30000,55.24993,21.15874
66.60001,55.49993,21.16070
66.90000,55.74987,21.24567
67.20001,55.99987,21.38287
67.50000,56.24993,21.58950
67.80000,56.49999,21.41344
68.10001,56.74981,21.57328
68.40000,56.99987,21.83464
68.70001,57.24993,21.69235
69.00000,57.49993,21.93691
69.30000,57.74993,21.98532
69.60001,57.99986,21.91143
69.90000,58.24987,22.04784
70.20001,58.49993,22.22699
70.50000,58.74987,22.16583
70.80000,58.99999,22.27138
71.10001,59.24993,22.30847
71.40000,59.49987,22.46439
71.70001,59.74993,22.49526
72.00000,59.99993,22.55122
72.30000,60.24987,22.65593
72.60001,60.49987,22.60575
72.90000,60.74993,22.76941
73.20001,60.99993,22.83561
73.50000,61.24987,22.78465
73.80000,61.49993,22.79406
74.10001,61.74993,22.96884
74.40000,61.99987,23.29425
74.70001,62.24987,23.24378
75.00000,62.49993,23.22732
75.30000,62.74993,23.32248
75.60001,62.99987,23.34972
75.90000,63.24993,23.37329
76.20001,63.49993,23.68748
76.50000,63.74986,23.51818
76.80000,63.99993,23.67341
77.10001,64.24993,23.78043
77.40000,64.49993,24.01499
77.70001,64.74993,23.91351
78.00000,64.99992,24.09883
78.30000,65.24986,24.05007
78.60001,65.49993,23.96026
78.90000,65.74993,24.21270
79.20001,65.99993,24.30840
79.50000,66.24993,24.36946
79.80000,66.49987,24.54649
80.10001,66.74992,24.56090
80.40000,66.99993,24.67673
80.70001,67.24987,24.86965
81.00001,67.49993,24.89076
81.30000,67.74993,24.93589
81.60001,67.99993,24.80036
81.90000,68.24993,25.03355
82.20001,68.49987,24.91703
82.50001,68.74993,25.25831
82.80000,68.99992,25.26267
83.10001,69.24993,25.41780
83.40000,69.49992,25.45059
83.70001,69.74999,25.45608
84.00001,69.99987,25.52904
84.30000,70.24986,25.59661
84.60001,70.49993,25.62066
84.90000,70.74993,25.74106
85.20001,70.99986,25.85444
85.50001,71.24986,25.94514
85.80000,71.49993,26.09248
86.10001,71.74992,26.00894
86.40000,71.99986,26.25732
86.70001,72.24993,26.42328
87.00001,72.49986,26.30857
87.30000,72.74986,26.42211
87.60001,72.99987,26.42372
87.90000,73.24999,26.48389
88.20001,73.49993,26.74556
88.50001,73.74987,26.78539
88.80000,73.99999,26.81847
89.10001,74.24999,26.86247
89.40000,74.49993,27.03862
89.70001,74.74986,27.32120
90.00001,74.99986,27.20885
90.30000,75.24999,27.19214
90.60001,75.49986,27.28440
90.90000,75.74974,27.59688
91.20001,75.99992,27.56429
91.50001,76.24993,27.34129
91.80000,76.49987,27.67185
92.10001,76.74993,27.40230
92.40000,76.99993,27.73334
92.70001,77.24993,27.72923
93.00001,77.49993,27.91013
93.30000,77.74992,28.07139
93.60001,77.99986,28.12892
93.90000,78.24986,28.25480
94.20001,78.49992,28.36382
94.50001,78.74999,28.53081
94.80000,78.99993,28.59221
95.10001,79.24993,28.50583
95.40000,79.49992,28.65772
95.70001,79.74993,28.56467
96.00001,79.99986,28.73911
96.30000,80.24992,28.74049
96.60001,80.49986,28.82413
96.90000,80.74986,28.97255
97.20001,80.99986,29.06457
97.50001,81.24986,29.24935
97.80000,81.49993,29.42364
98.10001,81.74992,29.28311
98.40000,81.99993,29.30119
98.70001,82.24992,29.53178
99.00001,82.49993,29.47401
99.30000,82.74986,29.65022
99.60001,82.99992,29.80153
99.90000,83.24993,29.81442
100.20001,83.49992,29.95382
100.50001,83.74986,29.64507
100.80000,83.99992,30.05192
101.10001,84.24980,30.06711
101.40000,84.49992,30.26928
101.70001,84.74999,30.35866
102.00001,84.99992,30.27874
102.30000,85.24986,30.41481
102.60001,85.49985,30.48263
102.90000,85.74992,30.69695
103.20001,85.99993,30.87291
103.50001,86.24987,30.97027
103.80000,86.49993,30.76717
104.10001,86.74992,31.00854
104.40000,86.99986,31.19249
104.70001,87.24992,31.15005
105.00001,87.49993,31.02966
105.30000,87.74993,31.37697
105.60001,87.99986,31.37800
105.90000,88.24993,31.63197
106.20001,88.49992,31.42808
106.50001,88.74986,31.54725
106.80000,88.99986,31.80641
107.10001,89.24992,31.86031
107.40000,89.49992,31.92846
107.70001,89.74986,31.93121
108.00001,89.99986,31.93821
108.30000,90.24998,32.15680
108.60001,90.49992,32.18939
108.90000,90.74987,32.35280
109.20001,90.99992,32.37613
109.50001,91.24986,32.43111
109.80000,91.49992,32.37035
110.10001,91.74992,32.70252
110.40000,91.99993,32.80115
110.70001,92.24992,32.83472
111.00001,92.49986,32.78116
111.30000,92.74987,32.89308
111.60001,92.99998,33.00289
111.90000,93.24992,33.31026
112.20001,93.49986,33.06928
112.50001,93.74999,33.24034
112.80000,93.99992,33.54242
113.10001,94.24986,33.36935
113.40001,94.49992,33.49906
113.70001,94.74985,33.50229
114.00001,94.99992,33.87097
114.30000,95.24986,33.65287
114.60001,95.49992,33.81751
114.90001,95.74993,34.02257
115.20001,95.99986,33.98386
115.50001,96.24992,34.12807
115.80000,96.49992,33.93815
116.10001,96.74992,34.13802
116.40001,96.99985,34.34083
116.70001,97.24992,34.69181
117.00001,97.49993,34.44088
117.30000,97.74992,34.60827
117.60001,97.99986,34.65540
117.90001,98.24986,34.73361
118.20001,98.49992,34.96033
118.50001,98.74992,35.01202
118.80000,98.99992,35.11458
119.10001,99.24993,35.04241
119.40001,99.49986,35.18269
119.70001,99.74992,35.39819
120.00001,99.99986,35.40613
120.30000,100.24992,35.37286
120.60001,100.49986,35.48375
120.90001,100.74992,35.65735
121.20001,100.99999,35.68455
121.50001,101.24986,35.70101
121.80000,101.49992,35.88138
122.10001,101.74992,35.95713
122.40001,101.99992,35.98982
122.70001,102.24992,36.09316
123.00001,102.49986,36.21414
123.30000,102.74986,36.49697
123.60001,102.99992,36.44253
123.90001,103.24986,36.66744
124.20001,103.49993,36.46183
124.50001,103.74992,36.53886
124.80000,103.99993,36.49206
125.10001,104.24986,36.84589
125.40001,104.49992,37.00147
125.70001,104.74992,36.91131
126.00001,104.99986,36.91263
126.30000,105.24992,37.07756
126.60001,105.49992,37.15876
126.90001,105.74993,37.24681
127.20001,105.99992,37.30879
127.50001,106.24993,37.32737
127.80000,106.49992,37.43649
128.10001,106.74986,37.52430
128.40001,106.99992,37.51783
128.70002,107.24992,37.87229
129.00000,107.49985,37.81290
129.30000,107.74992,37.94692
129.60001,107.99993,37.97715
129.90001,108.24992,37.99518
130.20002,108.49986,38.05771
130.50000,108.74987,38.28144
130.80000,108.99998,38.17531
131.10000,109.24992,38.52644
131.40002,109.49992,38.29859
131.70002,109.74992,38.42457
132.00000,109.99992,38.64595
132.30000,110.24993,38.72136
132.60000,110.49992,38.89605
132.90002,110.74992,39.13918
133.20002,110.99992,38.87654
133.50000,111.24986,39.09063
133.80000,111.49992,39.15516
134.10000,111.74992,39.15344
134.40002,111.99992,39.30172
134.70002,112.24986,39.44406
135.00000,112.49992,39.37296
135.30000,112.74992,39.56534
135.60000,112.99986,39.55941
135.90002,113.24992,39.73546
136.20002,113.49992,39.83278
136.50000,113.74992,39.97831
136.80000,113.99992,40.05867
137.10000,114.24999,40.12545
137.40002,114.49993,40.03696
137.70002,114.74986,40.03814
138.00000,114.99993,40.31435
138.30000,115.24992,40.45880
138.60000,115.49986,40.35477
138.90002,115.74992,40.40902
139.20002,115.99986,40.57121
139.50000,116.24992,40.74271
139.80000,116.49986,40.65465
140.10000,116.74993,40.71017
140.40002,116.99992,40.79680
140.70002,117.24993,40.88162
141.00000,117.49992,40.89392
141.30000,117.74993,41.17498
141.60000,117.99992,41.11917
141.90002,118.24986,41.29209
142.20002,118.49992,41.30586
142.50000,118.74992,41.29616
142.80000,118.99993,41.60736
143.10000,119.24992,41.74362
143.40002,119.49986,41.85961
143.70002,119.74992,41.84613
144.00000,119.99992,41.74073
144.30000,120.24986,41.86848
144.60000,120.49992,41.97123
144.90002,120.74992,42.02611
145.20002,120.99992,42.23676
145.50000,121.24985,42.31129
145.80000,121.49992,42.27851
146.10000,121.74986,42.43805
146.40002,121.99992,42.38346
146.70002,122.24992,42.57270
147.00000,122.49992,42.79065
147.30000,122.74992,42.63581
147.60000,122.99986,42.70672
147.90002,123.24998,42.78678
148.20002,123.49992,42.96264
148.50000,123.74992,43.01924
148.80000,123.99998,42.96534
149.10000,124.24992,43.06084
149.40002,124.49986,43.15801
149.70002,124.74986,43.38522
150.00000,124.99986,43.31490
150.30000,125.24999,43.50664
150.60000,125.49992,43.40349
150.90002,125.74986,43.65065
151.20002,125.99992,43.71504
151.50000,126.24991,43.86929
151.80000,126.49992,43.76144
152.10000,126.74992,43.90074
152.40002,126.99998,44.01996
152.70002,127.24985,44.00119
153.00000,127.49985,44.17808
153.30000,127.74998,44.38153
153.60000,127.99992,44.26986
153.90002,128.24992,44.30837
154.20002,128.49991,44.51025
154.50000,128.74998,44.43886
154.80000,128.99992,44.56734
155.10000,129.24992,44.51849
155.40002,129.49991,44.81596
155.70002,129.74985,45.01294
156.00000,129.99992,45.12192
156.30000,130.24992,45.06650
156.60000,130.49997,45.04661
156.90002,130.74986,45.20733
157.20002,130.99991,45.26657
157.50000,131.24998,45.36026
157.80000,131.49992,45.44155
158.10000,131.74991,45.56703
158.40002,131.99992,45.52597
158.70002,132.24992,45.70085
159.00000,132.49992,45.76436
159.30000,132.74992,45.65749
159.60000,132.99986,45.79033
159.90002,133.24991,46.16228
160.20002,133.49992,46.08335
160.50000,133.74992,46.08129
160.80000,133.99991,46.30811
161.10000,134.24992,46.19217
161.40002,134.49985,46.38215
161.70002,134.74998,46.45677
162.00002,134.99992,46.40787
162.30000,135.24991,46.40518
162.60000,135.49991,46.43712
162.90002,135.74985,46.58084
163.20002,135.99992,46.64327
163.50002,136.24986,46.92928
163.80000,136.49992,46.89086
164.10000,136.74991,47.07892
164.40002,136.99985,47.12885
164.70002,137.24992,47.30163
165.00002,137.49992,47.09397
165.30000,137.74991,47.19603
165.60000,137.99985,47.19991
165.90002,138.24992,47.31148
166.20002,138.49998,47.57608
166.50002,138.74992,47.45490
166.80000,138.99991,47.52134
167.10000,139.24985,47.67466
167.40002,139.49992,47.91711
167.70002,139.74986,47.65786
168.00002,139.99986,48.04231
168.30000,140.24991,48.09734
168.60000,140.49992,48.04785
168.90002,140.74991,48.29784
169.20002,140.99997,48.43186
169.50002,141.24991,48.44627
169.80000,141.49985,48.42823
170.10000,141.74986,48.66079
170.40002,141.99997,48.64780
170.70002,142.24991,48.59439
171.00002,142.49985,48.89637
171.30000,142.74985,49.01882
171.60000,142.99992,48.85610
171.90002,143.24998,48.89319
172.20002,143.49985,49.16940
172.50002,143.74991,49.15358
172.80000,143.99998,49.39162
173.10000,144.24986,49.15284
173.40002,144.49986,49.37633
173.70002,144.74991,49.24589
174.00002,144.99985,49.44860
174.30000,145.24992,49.67670
174.60000,145.49992,49.79459
174.90002,145.74997,49.52205
175.20002,145.99991,49.86834
175.50002,146.24985,50.00510
175.80000,146.49997,49.95595
176.10000,146.74991,49.80297
176.40002,146.99991,49.88485
176.70002,147.24992,50.05473
177.00002,147.49992,50.16042
177.30000,147.74992,50.25931
177.60000,147.99992,50.11373
177.90002,148.24991,50.36926
178.20002,148.49992,50.50705
178.50002,148.74992,50.52052
178.80000,148.99998,50.72833
179.10000,149.24991,50.53669
179.40002,149.49985,50.73774
179.70002,149.74984,50.69976
180.00002,149.99992,50.91081
180.30000,150.24992,51.01699
180.60000,150.49986,50.95633
180.90002,150.74993,51.02468
181.20002,150.99998,51.27674
181.50002,151.24986,51.30143
181.80000,151.49985,51.41502
182.10000,151.74999,51.42398
182.40002,151.99984,51.57025
182.70002,152.24992,51.53061
183.00002,152.49992,51.61758
183.30000,152.74991,51.49827
183.60000,152.99985,51.58226
183.90002,153.24985,51.93265
184.20002,153.49992,51.84734
184.50002,153.74991,51.98268
184.80000,153.99992,51.91839
185.10000,154.24985,52.16731
185.40002,154.49992,51.95641
185.70002,154.74992,52.40079
186.00002,154.99986,52.41054
186.30000,155.24991,52.24659
186.60000,155.49992,52.42740
186.90002,155.74992,52.67470
187.20002,155.99991,52.46621
187.50002,156.24992,52.75154
187.80000,156.49999,52.90412
188.10000,156.74986,52.68950
188.40002,156.99992,52.89364
188.70002,157.24991,52.95425
189.00002,157.49991,52.98674
189.30000,157.74991,52.97993
189.60000,157.99992,53.05460
189.90002,158.24990,53.04279
190.20002,158.49985,53.20429
190.50002,158.74991,53.44841
190.80000,158.99992,53.56312
191.10000,159.24985,53.29759
191.40002,159.49991,53.47434
191.70002,159.74991,53.55406
192.00002,159.99991,53.62869
192.30000,160.24992,53.71929
192.60000,160.49985,53.64569
192.90002,160.74991,53.88309
193.20002,160.99999,53.75422
193.50002,161.24984,53.95238
193.80000,161.49985,53.94821
194.10000,161.74991,54.13593
194.40002,161.99986,54.29214
194.70002,162.24984,54.21257
195.00002,162.49992,54.13975
195.30000,162.74991,54.26412
195.60000,162.99985,54.32203
195.90002,163.24991,54.35417
196.20002,163.49997,54.56771
196.50002,163.74992,54.46339
196.80000,163.99991,54.66297
197.10000,164.24991,54.58776
197.40002,164.49990,54.90381
197.70002,164.74985,54.77499
198.00002,164.99985,54.87622
198.30000,165.24991,55.03473
198.60000,165.49984,55.26435
198.90002,165.74990,55.13303
199.20002,165.99992,55.27650
199.50002,166.24985,55.19937
199.80000,166.49991,55.63709
200.10000,166.74984,55.47691
200.40002,166.99992,55.45765
200.70002,167.24991,55.49435
201.00002,167.49986,55.54669
201.30000,167.74997,55.66237
201.60000,167.99990,55.82035
201.90002,168.24992,55.88689
202.20002,168.49991,55.97999
202.50002,168.74997,56.00145
202.80000,168.99997,55.85622
203.10000,169.24992,55.85920
203.40002,169.49985,55.93300
203.70002,169.74991,56.11959
204.00002,169.99984,56.14262
204.30000,170.24990,56.27340
204.60000,170.49985,56.30672
204.90002,170.74991,56.39027
205.20002,170.99991,56.63737
205.50002,171.24984,56.36978
205.80000,171.49990,56.64384
206.10000,171.74991,56.49817
206.40002,171.99986,56.55990
206.70002,172.24992,56.71420
207.00002,172.49990,56.64938
207.30000,172.74993,56.89232
207.60000,172.99986,56.80813
207.90002,173.24992,56.79398
208.20002,173.49990,57.09704
208.50002,173.74985,56.98884
208.80000,173.99991,57.15956
209.10000,174.24991,57.08748
209.40002,174.49992,57.54445
209.70002,174.74990,57.54210
210.00002,174.99991,57.42485
210.30000,175.24991,57.44749
210.60000,175.49979,57.76300
210.90002,175.74990,57.58302
211.20002,175.99998,57.76422
211.50002,176.24991,57.52726
211.80000,176.49986,57.56283
212.10000,176.74984,57.84640
212.40002,176.99996,57.84164
212.70002,177.24991,57.95601
213.00002,177.49984,58.05003
213.30000,177.74992,58.06155
213.60000,177.99990,58.05322
213.90002,178.24985,58.08532
214.20002,178.49991,58.21012
214.50002,178.74992,58.27842
214.80000,178.99984,58.28955
215.10000,179.24991,58.26799
215.40002,179.49991,58.52313
215.70002,179.74991,58.55376
216.00002,179.99986,58.70526
216.30000,180.24990,58.77308
216.60000,180.49991,58.63956
216.90002,180.74991,58.74495
217.20002,180.99992,58.92175
217.50002,181.24985,58.78812
217.80000,181.49985,59.04674
218.10000,181.74985,59.12338
218.40002,181.99991,58.74123
218.70002,182.24992,58.95203
219.00002,182.49985,59.19227
219.30000,182.74991,59.15744
219.60000,182.99991,59.13523
219.90002,183.24992,59.38808
220.20002,183.49992,59.23358
220.50002,183.74985,59.35730
220.80000,183.99991,59.60397
221.10000,184.24990,59.65512
221.40002,184.49992,59.50847
221.70002,184.74991,59.66448
222.00002,184.99985,59.77013
222.30000,185.24991,59.85573
222.60000,185.49992,59.95804
222.90002,185.74998,59.96294
223.20002,185.99991,59.80316
223.50002,186.24986,59.75254
223.80000,186.49997,59.88773
224.10000,186.74992,59.93453
224.40002,186.99985,59.99999
224.70002,187.24985,60.14434
225.00002,187.49991,60.33676
225.30002,187.74997,60.12435
225.60000,187.99985,60.51890
225.90002,188.24991,60.44201
226.20002,188.49991,60.41369
226.50002,188.74984,60.56064
226.80002,188.99985,60.71700
227.10000,189.24991,60.86317
227.40002,189.49991,60.59833
227.70002,189.74984,60.60656
228.00002,189.99984,60.77855
228.30002,190.24990,60.67422
228.60000,190.49991,60.93270
228.90002,190.74984,60.85018
229.20002,190.99990,61.11826
229.50002,191.24992,61.22185
229.80002,191.49985,61.05020
230.10000,191.74986,61.14502
230.40002,191.99997,61.05216
230.70002,192.24998,61.16373
231.00002,192.49983,61.24468
231.30002,192.74991,61.27790
231.60000,192.99991,61.36581
231.90002,193.24990,61.42980
232.20002,193.49985,61.53956
232.50002,193.74991,61.34812
232.80002,193.99991,61.67309
233.10000,194.24984,61.74389
233.40002,194.49979,61.49850
233.70002,194.74998,61.88084
234.00002,194.99991,61.78667
234.30002,195.24984,61.95459
234.60000,195.49990,62.00384
234.90002,195.74990,61.74947
235.20002,195.99991,61.91421
235.50002,196.24986,61.89780
235.80002,196.49984,62.12065
236.10000,196.74990,61.98169
236.40002,196.99983,62.41749
236.70002,197.24991,62.38300
237.00002,197.49992,62.39784
237.30002,197.74985,62.33914
237.60000,197.99985,62.34380
237.90002,198.24991,62.97090
238.20002,198.49991,62.72379
238.50002,198.74984,62.51872
238.80002,198.99990,62.63902
239.10000,199.24991,62.97398
239.40002,199.49984,62.76612
239.70002,199.74992,62.82331
240.00002,199.99985,62.76079
240.30002,200.24991,62.90259
240.60000,200.49991,63.05522
240.90002,200.74992,62.73202
241.20002,200.99990,62.78161
241.50002,201.24985,63.05106
241.80002,201.49991,63.08256
242.10000,201.74991,63.16444
242.40002,201.99992,63.11657
242.70002,202.24985,63.28660
243.00002,202.49985,63.22187
243.30002,202.74997,63.56987
243.60000,202.99979,63.26455
243.90002,203.24990,63.48289
244.20002,203.49991,63.30659
244.50002,203.74984,63.63734
244.80002,203.99991,63.72760
245.10000,204.24984,63.54802
245.40002,204.49990,63.59883
245.70002,204.74985,63.72378
246.00002,204.99984,63.89298
246.30002,205.24992,64.00460
246.60000,205.49990,64.04669
246.90002,205.74985,63.93678
247.20002,205.99984,64.04924
247.50002,206.24990,64.11132
247.80002,206.49992,64.23034
248.10000,206.74985,64.07212
248.40002,206.99985,64.23367
248.70002,207.24989,64.31790
249.00002,207.49992,64.36278
249.30002,207.74990,64.37665
249.60000,207.99991,64.36523
249.90002,208.24984,64.57941
250.20002,208.49984,64.50576
250.50002,208.74992,64.79188
250.80002,208.99996,64.66987
251.10000,209.24985,64.77478
251.40002,209.49984,64.61572
251.70002,209.74990,64.81922
252.00002,209.99990,64.92021
252.30002,210.24985,65.00856
252.60000,210.49984,64.86851
252.90002,210.74984,64.89194
253.20002,210.99992,65.09313
253.50002,211.24985,65.14287
253.80002,211.49978,64.90021
254.10000,211.74990,65.20622
254.40002,211.99990,65.32494
254.70002,212.24990,65.38482
255.00002,212.49996,65.43710
255.30002,212.74991,65.47469
255.60000,212.99990,65.59121
255.90002,213.24985,65.58695
256.20002,213.49991,65.77795
256.50000,213.74986,65.96670
256.80002,213.99984,65.66697
257.10000,214.24985,65.84650
257.40003,214.49991,65.94264
257.70002,214.74991,65.66182
258.00000,214.99984,65.78241
258.30002,215.24990,65.95611
258.60000,215.49990,65.94631
258.90003,215.74991,66.21620
259.20002,215.99991,66.17970
259.50000,216.24984,66.12169
259.80002,216.49985,66.16598
260.10000,216.74991,66.38496
260.40003,216.99991,66.27652
260.70002,217.24992,66.45077
261.00000,217.49990,66.61497
261.30002,217.74998,66.87114
261.60000,217.99991,66.60497
261.90003,218.24991,66.74795
262.20000,218.49990,66.96370
262.50000,218.74985,66.97624
262.80003,218.99998,66.99815
263.10000,219.24991,67.13299
263.40003,219.49992,67.13020
263.70000,219.74990,66.86923
264.00000,219.99985,67.17097
264.30003,220.24991,67.39377
264.60000,220.49991,67.21639
264.90003,220.74990,67.57727
265.20000,220.99990,67.35330
265.50000,221.24983,67.64421
265.80003,221.49997,67.42189
266.10000,221.74992,67.84687
266.40003,221.99985,67.71986
266.70000,222.24991,67.70659
267.00000,222.49991,67.95644
267.30003,222.74986,67.97613
267.60000,222.99984,68.19119
267.90003,223.24996,67.93782
268.20000,223.49991,68.11774
268.50000,223.74984,68.32957
268.80003,223.99992,68.02978
269.10000,224.24990,68.25783
269.40003,224.49985,68.19531
269.70000,224.74984,68.56399
270.00000,224.99992,68.29596
270.30003,225.24990,68.68354
270.60000,225.49985,68.53919
270.90003,225.74984,68.72877
271.20000,225.99991,68.85313
271.50000,226.24992,68.76924
271.80003,226.49985,69.08534
272.10000,226.74991,68.86190
272.40003,226.99989,69.04438
272.70000,227.24992,69.36238
273.00000,227.49990,69.28213
273.30003,227.74991,69.11994
273.60000,227.99991,69.30530
273.90003,228.24984,69.39840
274.20000,228.49992,69.45304
274.50000,228.74990,69.30942
274.80003,228.99991,69.39169
275.10000,229.24984,69.63664
275.40003,229.49997,69.69128
275.70000,229.74990,69.74258
276.00000,229.99985,69.77658
276.30003,230.24991,69.74870
276.60000,230.49990,69.67256
276.90003,230.74985,70.00885
277.20000,230.99991,70.17672
277.50000,231.24985,69.94005
277.80003,231.49984,70.06901
278.10000,231.74984,70.18995
278.40003,231.99990,70.29279
278.70000,232.24991,70.21827
279.00000,232.49991,70.22513
279.30003,232.74990,70.36095
279.60000,232.99992,70.36041
279.90003,233.24991,70.48748
280.20000,233.49985,70.58434
280.50000,233.74984,70.74570
280.80003,233.99990,70.67510
281.10000,234.24990,70.74526
281.40003,234.49991,70.93004
281.70000,234.74991,70.98110
282.00000,234.99990,70.84983
282.30003,235.24992,71.03524
282.60000,235.49991,71.34771
282.90003,235.74991,71.04112
283.20000,235.99990,71.11756
283.50000,236.24985,71.23222
283.80003,236.49991,71.17337
284.10000,236.74991,71.15466
284.40003,236.99984,71.59369
284.70000,237.24984,71.38549
285.00000,237.49985,71.41553
285.30003,237.74991,71.65284
285.60000,237.99991,71.65901
285.90003,238.24984,71.68949
286.20000,238.49990,71.84727
286.50000,238.74983,71.74123
286.80003,238.99991,71.79273
287.10000,239.24997,71.94767
287.40003,239.49990,71.89901
287.70000,239.74990,72.14210
288.00000,239.99991,72.21050
288.30003,240.24997,72.09050
288.60000,240.49990,72.10354
288.90003,240.74990,72.22388
289.20000,240.99983,72.28949
289.50000,241.24991,72.48907
289.80003,241.49992,72.25220
290.10000,241.74985,72.55110
290.40003,241.99991,72.48240
290.70000,242.24991,72.57286
291.00000,242.49991,72.45888
291.30003,242.74990,72.57928
291.60000,242.99990,72.46491
291.90003,243.24983,72.66777
292.20000,243.49984,72.60358
292.50000,243.74992,72.66409
292.80003,243.99990,72.64229
293.10000,244.24991,72.81982
293.40003,244.49984,72.89410
293.70000,244.74997,72.85412
294.00000,244.99990,73.00567
294.30003,245.24990,72.98387
294.60000,245.49983,72.95912
294.90003,245.74991,73.09510
295.20000,245.99984,73.17805
295.50000,246.24985,72.88881
295.80003,246.49991,72.96167
296.10000,246.74984,73.07706
296.40003,246.99984,73.04713
296.70000,247.24998,73.31579
297.00000,247.49991,73.06614
297.30003,247.74991,73.00018
297.60000,247.99984,72.96765
297.90003,248.24992,72.98646
298.20000,248.49990,72.88739
298.50000,248.74985,72.95731
298.80003,248.99989,72.82721
299.10000,249.24992,72.97554
299.40003,249.49985,72.92801
299.70000,249.74991,72.75229
300.00000,249.99991,72.88734
300.30003,250.24990,72.62338
300.60000,250.49984,72.61205
300.90003,250.74989,72.60931
301.20000,250.99991,72.49014
301.50000,251.24988,72.45492
301.80003,251.49990,72.31036
302.10000,251.74985,71.98873
302.40003,251.99989,72.12701
302.70000,252.24989,71.74138
303.00000,252.49988,71.59301
303.30003,252.74996,71.33189
303.60000,252.99985,70.80656
303.90003,253.24989,70.52711
304.20000,253.49995,70.24566
304.50000,253.74983,70.16446
304.80003,253.99989,69.34695
305.10000,254.24991,68.00700
305.40003,254.49989,67.43660
305.70000,254.74990,66.09419
306.00000,254.99990,63.78782
306.30003,255.24989,58.63049
306.60000,255.49991,0.15280
306.90003,255.74988,0.13849
307.20000,255.99990,0.16554
307.50000,256.24990,-0.00165
307.80003,256.49989,0.16211
308.10000,256.74989,0.32440
308.40003,256.99988,-0.04261
308.70000,257.24996,-0.06011
308.95400,257.46165,0.17847