File: V_8/FR/RDSO FR Tensile Multi.is_tens_RawData/Specimen_RawData_2.csv
Time,Extension,Load,Tensile strain,Tensile stress,Corrected Position
(sec),(mm),(N),(mm/mm),(MPa),(mm)
0.00000,0.00000,-0.24623,0.00000,-0.02736,0.00000
0.21000,0.17319,0.80400,0.00151,0.08933,0.17319
0.42000,0.34981,1.41200,0.00304,0.15689,0.34981
0.63000,0.52500,1.71515,0.00457,0.19057,0.52500
0.84000,0.70000,2.11847,0.00609,0.23539,0.70000
1.05000,0.87506,2.60006,0.00761,0.28890,0.87506
1.26000,1.04987,2.95087,0.00913,0.32787,1.04987
1.47000,1.22500,3.34770,0.01065,0.37197,1.22500
1.68000,1.40006,3.54454,0.01217,0.39384,1.40006
1.89000,1.57500,3.79317,0.01370,0.42146,1.57500
2.10000,1.75000,4.31547,0.01522,0.47950,1.75000
2.31000,1.92494,4.30604,0.01674,0.47845,1.92494
2.52000,2.10000,4.76691,0.01826,0.52966,2.10000
2.73000,2.27506,4.79645,0.01978,0.53294,2.27506
2.94000,2.45006,5.03783,0.02130,0.55976,2.45006
3.15000,2.62500,5.49575,0.02283,0.61064,2.62500
3.36000,2.79987,5.52251,0.02435,0.61361,2.79987
3.57000,2.97500,5.89750,0.02587,0.65528,2.97500
3.78000,3.15006,6.12294,0.02739,0.68033,3.15006
3.99000,3.32500,6.14427,0.02891,0.68270,3.32500
4.20000,3.49994,6.34277,0.03043,0.70475,3.49994
4.41000,3.67500,6.50272,0.03196,0.72252,3.67500
4.62000,3.85000,6.64705,0.03348,0.73856,3.85000
4.83000,4.02500,6.74418,0.03500,0.74935,4.02500
5.04000,4.20000,7.07885,0.03652,0.78654,4.20000
5.25000,4.37500,7.22191,0.03804,0.80243,4.37500
5.46000,4.54994,7.31081,0.03956,0.81231,4.54994
5.67000,4.72500,7.60524,0.04109,0.84503,4.72500
5.88000,4.90006,7.60801,0.04261,0.84533,4.90006
6.09000,5.07506,7.54232,0.04413,0.83804,5.07506
6.30000,5.25000,7.90293,0.04565,0.87810,5.25000
6.51000,5.42500,8.24507,0.04717,0.91612,5.42500
6.72000,5.59994,8.10413,0.04870,0.90046,5.59994
6.93000,5.77500,8.32616,0.05022,0.92513,5.77500
7.14000,5.95006,8.22969,0.05174,0.91441,5.95006
7.35000,6.12500,8.49726,0.05326,0.94414,6.12500
7.56000,6.30000,8.67545,0.05478,0.96394,6.30000
7.77000,6.47494,8.79857,0.05630,0.97762,6.47494
7.98000,6.65006,8.70247,0.05783,0.96694,6.65006
8.19000,6.82506,8.92108,0.05935,0.99123,6.82506
8.40000,7.00006,9.01534,0.06087,1.00170,7.00006
8.61000,7.17494,8.85826,0.06239,0.98425,7.17494
8.82000,7.35000,9.05747,0.06391,1.00639,7.35000
9.03000,7.52506,9.39586,0.06544,1.04398,7.52506
9.24000,7.70006,9.32432,0.06696,1.03604,7.70006
9.45000,7.87506,9.44582,0.06848,1.04954,7.87506
9.66000,8.04994,9.48763,0.07000,1.05418,8.04994
9.87000,8.22500,9.42194,0.07152,1.04688,8.22500
10.08000,8.40006,9.54381,0.07304,1.06042,8.40006
10.29000,8.57500,9.76578,0.07457,1.08509,8.57500
10.50000,8.74994,9.71334,0.07609,1.07926,8.74994
10.71000,8.92494,9.93325,0.07761,1.10369,8.92494
10.92000,9.10000,9.99173,0.07913,1.11019,9.10000
11.13000,9.27494,9.99278,0.08065,1.11031,9.27494
11.34000,9.45012,10.10515,0.08217,1.12279,9.45012
11.55000,9.62500,10.06415,0.08370,1.11824,9.62500
11.76000,9.79994,10.13679,0.08522,1.12631,9.79994
11.97000,9.97500,10.38258,0.08674,1.15362,9.97500
12.18000,10.15006,10.41717,0.08826,1.15746,10.15006
12.39000,10.32500,10.31883,0.08978,1.14654,10.32500
12.60000,10.50006,10.48552,0.09130,1.16506,10.50006
12.81000,10.67494,10.48557,0.09283,1.16506,10.67494
13.02000,10.84994,10.56580,0.09435,1.17398,10.84994
13.23000,11.02500,10.58549,0.09587,1.17617,11.02500
13.44000,11.20006,10.63102,0.09739,1.18122,11.20006
13.65000,11.37500,10.69945,0.09891,1.18883,11.37500
13.86000,11.54987,10.80653,0.10043,1.20073,11.54987
14.07000,11.72494,10.78524,0.10196,1.19836,11.72494
14.28000,11.90000,10.95364,0.10348,1.21707,11.90000
14.49000,12.07512,10.81831,0.10500,1.20203,12.07512
14.70000,12.25000,10.77672,0.10652,1.19741,12.25000
14.91000,12.42494,10.76408,0.10804,1.19601,12.42494
15.12000,12.60006,10.97958,0.10957,1.21995,12.60006
15.33000,12.77494,10.93089,0.11109,1.21454,12.77494
15.54000,12.95006,11.09383,0.11261,1.23265,12.95006
15.75000,13.12500,10.89425,0.11413,1.21047,13.12500
15.96000,13.29987,11.21095,0.11565,1.24566,13.29987
16.17000,13.47487,11.17955,0.11717,1.24217,13.47487
16.38000,13.65012,11.22819,0.11870,1.24758,13.65012
16.59000,13.82506,11.28572,0.12022,1.25397,13.82506
16.80000,13.99994,11.33135,0.12174,1.25904,13.99994
17.01000,14.17500,11.34401,0.12326,1.26045,14.17500
17.22000,14.34994,11.28418,0.12478,1.25380,14.34994
17.43000,14.52500,11.36507,0.12630,1.26279,14.52500
17.64000,14.70006,11.41976,0.12783,1.26886,14.70006
17.85000,14.87506,11.67293,0.12935,1.29699,14.87506
18.06000,15.04987,11.44249,0.13087,1.27139,15.04987
18.27000,15.22500,11.39138,0.13239,1.26571,15.22500
18.48000,15.40000,11.35145,0.13391,1.26127,15.40000
18.69000,15.57506,11.56561,0.13544,1.28507,15.57506
18.90000,15.75006,11.56394,0.13696,1.28488,15.75006
19.11000,15.92493,11.66036,0.13848,1.29560,15.92493
19.32000,16.09994,11.55583,0.14000,1.28398,16.09994
19.53000,16.27500,11.82582,0.14152,1.31398,16.27500
19.74000,16.45006,11.53560,0.14304,1.28173,16.45006
19.95000,16.62506,11.65206,0.14457,1.29467,16.62506
20.16000,16.80000,11.62029,0.14609,1.29114,16.80000
20.37000,16.97487,11.64202,0.14761,1.29356,16.97487
20.58000,17.15000,11.60631,0.14913,1.28959,17.15000
20.79000,17.32506,11.74351,0.15065,1.30483,17.32506
21.00000,17.50000,11.78821,0.15217,1.30980,17.50000
21.21000,17.67493,12.01044,0.15370,1.33449,17.67493
21.42000,17.84994,11.74841,0.15522,1.30538,17.84994
21.63000,18.02500,11.82457,0.15674,1.31384,18.02500
21.84000,18.20006,11.87483,0.15826,1.31943,18.20006
22.05000,18.37506,11.94894,0.15978,1.32766,18.37506
22.26000,18.54993,11.95181,0.16130,1.32798,18.54993
22.47000,18.72494,12.06731,0.16283,1.34081,18.72494
22.68000,18.90006,12.25231,0.16435,1.36137,18.90006
22.89000,19.07506,11.97066,0.16587,1.33007,19.07506
23.10000,19.25000,12.08222,0.16739,1.34247,19.25000
23.31000,19.42493,12.04196,0.16891,1.33800,19.42493
23.52000,19.59994,12.24599,0.17043,1.36067,19.59994
23.73000,19.77493,12.28743,0.17196,1.36527,19.77493
23.94000,19.95006,12.18861,0.17348,1.35429,19.95006
24.15000,20.12500,12.07478,0.17500,1.34164,20.12500
24.36000,20.29993,12.32515,0.17652,1.36946,20.29993
24.57000,20.47493,12.26848,0.17804,1.36316,20.47493
24.78000,20.65000,12.11592,0.17957,1.34621,20.65000
24.99000,20.82506,12.18447,0.18109,1.35383,20.82506
25.20000,21.00006,12.16363,0.18261,1.35151,21.00006
25.41000,21.17500,12.37631,0.18413,1.37515,21.17500
25.62000,21.34993,12.40252,0.18565,1.37806,21.34993
25.83000,21.52493,12.34178,0.18717,1.37131,21.52493
26.04000,21.70000,12.39010,0.18870,1.37668,21.70000
26.25000,21.87506,12.29652,0.19022,1.36628,21.87506
26.46000,22.04994,12.31988,0.19174,1.36888,22.04994
26.67000,22.22494,12.26654,0.19326,1.36295,22.22494
26.88000,22.40000,12.24920,0.19478,1.36102,22.40000
27.09000,22.57500,12.47192,0.19630,1.38577,22.57500
27.30000,22.75006,12.43066,0.19783,1.38118,22.75006
27.51000,22.92500,12.40472,0.19935,1.37830,22.92500
27.72000,23.10000,12.41506,0.20087,1.37945,23.10000
27.93000,23.27493,12.46644,0.20239,1.38516,23.27493
28.14000,23.45006,12.42520,0.20391,1.38058,23.45006
28.35000,23.62506,12.53597,0.20544,1.39289,23.62506
28.56000,23.79999,12.60479,0.20696,1.40053,23.79999
28.77000,23.97493,12.58321,0.20848,1.39813,23.97493
28.98000,24.15000,12.57209,0.21000,1.39690,24.15000
29.19000,24.32500,12.67498,0.21152,1.40833,24.32500
29.40000,24.50006,12.69692,0.21304,1.41077,24.50006
29.61000,24.67500,12.61784,0.21457,1.40198,24.67500
29.82000,24.84993,12.70672,0.21609,1.41186,24.84993
30.03000,25.02493,12.63846,0.21761,1.40427,25.02493
30.24000,25.20012,12.45997,0.21913,1.38444,25.20012
30.45000,25.37519,12.82225,0.22065,1.42469,25.37519
30.66000,25.54993,12.58576,0.22217,1.39842,25.54993
30.87000,25.72493,12.80113,0.22370,1.42235,25.72493
31.08000,25.90000,12.93096,0.22522,1.43677,25.90000
31.29000,26.07506,12.90209,0.22674,1.43357,26.07506
31.50000,26.24993,12.92533,0.22826,1.43615,26.24993
31.71000,26.42500,12.99133,0.22978,1.44348,26.42500
31.92000,26.59993,12.78041,0.23130,1.42005,26.59993
32.13000,26.77493,12.97683,0.23283,1.44187,26.77493
32.34000,26.95012,12.77549,0.23435,1.41950,26.95012
32.55000,27.12506,12.74419,0.23587,1.41602,27.12506
32.76000,27.30000,13.05178,0.23739,1.45020,27.30000
32.97000,27.47493,12.94548,0.23891,1.43839,27.47493
33.18000,27.65006,12.98163,0.24044,1.44240,27.65006
33.39000,27.82500,13.07034,0.24196,1.45226,27.82500
33.60000,28.00000,13.07575,0.24348,1.45286,28.00000
33.81000,28.17506,12.97441,0.24500,1.44160,28.17506
34.02000,28.34993,13.09669,0.24652,1.45519,28.34993
34.23000,28.52499,12.92278,0.24804,1.43586,28.52499
34.44000,28.70006,12.93559,0.24957,1.43729,28.70006
34.65000,28.87506,13.20389,0.25109,1.46710,28.87506
34.86000,29.04993,13.06885,0.25261,1.45209,29.04993
35.07000,29.22500,13.18168,0.25413,1.46463,29.22500
35.28000,29.39994,13.11959,0.25565,1.45773,29.39994
35.49000,29.57506,13.21403,0.25717,1.46823,29.57506
35.70000,29.75000,13.26793,0.25870,1.47421,29.75000
35.91000,29.92500,13.29228,0.26022,1.47692,29.92500
36.12000,30.10000,13.33489,0.26174,1.48165,30.10000
36.33000,30.27493,13.22943,0.26326,1.46994,30.27493
36.54000,30.45000,13.34329,0.26478,1.48259,30.45000
36.75000,30.62500,13.37048,0.26630,1.48561,30.62500
36.96000,30.80000,13.35030,0.26783,1.48337,30.80000
37.17000,30.97493,13.32294,0.26935,1.48033,30.97493
37.38000,31.15000,13.56033,0.27087,1.50670,31.15000
37.59000,31.32500,13.54373,0.27239,1.50486,31.32500
37.80000,31.49999,13.46002,0.27391,1.49556,31.49999
38.01000,31.67506,13.63116,0.27544,1.51457,31.67506
38.22000,31.85000,13.54224,0.27696,1.50469,31.85000
38.43000,32.02493,13.67914,0.27848,1.51990,32.02493
38.64000,32.19999,13.42296,0.28000,1.49144,32.19999
38.85000,32.37506,13.61478,0.28152,1.51275,32.37506
39.06000,32.54987,13.61181,0.28304,1.51242,32.54987
39.27000,32.72500,13.48605,0.28457,1.49845,32.72500
39.48000,32.89999,13.38402,0.28609,1.48711,32.89999
39.69000,33.07493,13.35779,0.28761,1.48420,33.07493
39.90000,33.24999,13.66785,0.28913,1.51865,33.24999
40.11000,33.42500,13.43749,0.29065,1.49305,33.42500
40.32000,33.60000,13.66339,0.29217,1.51815,33.60000
40.53000,33.77500,13.68997,0.29370,1.52111,33.77500
40.74000,33.94993,13.87931,0.29522,1.54215,33.94993
40.95000,34.12499,13.70476,0.29674,1.52275,34.12499
41.16000,34.30006,13.75217,0.29826,1.52802,34.30006
41.37000,34.47500,13.92444,0.29978,1.54716,34.47500
41.58000,34.64999,13.90221,0.30130,1.54469,34.64999
41.79000,34.82499,13.76611,0.30283,1.52957,34.82499
42.00000,34.99993,13.91511,0.30435,1.54612,34.99993
42.21000,35.17500,13.82873,0.30587,1.53653,35.17500
42.42000,35.34999,13.79734,0.30739,1.53304,35.34999
42.63000,35.52499,13.75181,0.30891,1.52798,35.52499
42.84000,35.69999,13.76368,0.31043,1.52930,35.69999
43.05000,35.87506,13.96130,0.31196,1.55126,35.87506
43.26000,36.04993,13.89413,0.31348,1.54379,36.04993
43.47000,36.22500,13.83113,0.31500,1.53679,36.22500
43.68000,36.40006,14.04097,0.31652,1.56011,36.40006
43.89000,36.57499,13.85168,0.31804,1.53908,36.57499
44.10000,36.74999,14.10676,0.31957,1.56742,36.74999
44.31000,36.92500,14.08574,0.32109,1.56508,36.92500
44.52000,37.10000,14.05275,0.32261,1.56142,37.10000
44.73000,37.27499,14.11930,0.32413,1.56881,37.27499
44.94000,37.44999,14.03879,0.32565,1.55987,37.44999
45.15000,37.62500,14.03010,0.32717,1.55890,37.62500
45.36000,37.79993,14.19032,0.32870,1.57670,37.79993
45.57000,37.97499,13.95459,0.33022,1.55051,37.97499
45.78000,38.14999,14.01325,0.33174,1.55703,38.14999
45.99000,38.32493,14.12395,0.33326,1.56933,38.32493
46.20000,38.50000,14.21777,0.33478,1.57975,38.50000
46.41000,38.67500,14.19191,0.33630,1.57688,38.67500
46.62000,38.85000,14.43509,0.33783,1.60390,38.85000
46.83000,39.02499,14.30303,0.33935,1.58923,39.02499
47.04000,39.19993,14.18177,0.34087,1.57575,39.19993
47.25000,39.37500,14.39607,0.34239,1.59956,39.37500
47.46000,39.54993,14.24516,0.34391,1.58280,39.54993
47.67000,39.72499,14.31030,0.34543,1.59003,39.72499
47.88000,39.90006,14.41929,0.34696,1.60214,39.90006
48.09000,40.07499,14.29343,0.34848,1.58816,40.07499
48.30000,40.25000,14.39071,0.35000,1.59897,40.25000
48.51000,40.42499,14.44184,0.35152,1.60465,40.42499
48.72000,40.60006,14.35385,0.35304,1.59487,40.60006
48.93000,40.77493,14.40893,0.35456,1.60099,40.77493
49.14000,40.94999,14.35140,0.35609,1.59460,40.94999
49.35000,41.12505,14.52700,0.35761,1.61411,41.12505
49.56000,41.29987,14.52151,0.35913,1.61350,41.29987
49.77000,41.47499,14.67081,0.36065,1.63009,41.47499
49.98000,41.64999,14.35314,0.36217,1.59479,41.64999
50.19000,41.82499,14.45612,0.36370,1.60624,41.82499
50.40000,41.99999,14.73706,0.36522,1.63745,41.99999
50.61000,42.17499,14.89684,0.36674,1.65520,42.17499
50.82000,42.34999,14.73135,0.36826,1.63682,42.34999
51.03000,42.52493,14.59433,0.36978,1.62159,42.52493
51.24000,42.70006,14.72503,0.37130,1.63611,42.70006
51.45000,42.87499,14.79488,0.37283,1.64388,42.87499
51.66000,43.04993,14.99848,0.37435,1.66650,43.04993
51.87000,43.22500,14.92790,0.37587,1.65866,43.22500
52.08000,43.40006,14.78095,0.37739,1.64233,43.40006
52.29000,43.57499,14.86493,0.37891,1.65166,43.57499
52.50000,43.75000,14.92334,0.38043,1.65815,43.75000
52.71000,43.92500,14.96485,0.38196,1.66276,43.92500
52.92000,44.09993,14.84757,0.38348,1.64973,44.09993
53.13000,44.27499,14.94340,0.38500,1.66038,44.27499
53.34000,44.45006,14.80106,0.38652,1.64456,44.45006
53.55000,44.62505,15.00698,0.38804,1.66744,44.62505
53.76000,44.79993,15.03046,0.38956,1.67005,44.79993
53.97000,44.97499,14.87943,0.39109,1.65327,44.97499
54.18000,45.15006,14.99162,0.39261,1.66574,45.15006
54.39000,45.32500,15.19940,0.39413,1.68882,45.32500
54.60000,45.49999,15.01947,0.39565,1.66883,45.49999
54.81000,45.67499,15.03059,0.39717,1.67007,45.67499
55.02000,45.84999,15.17548,0.39870,1.68616,45.84999
55.23000,46.02499,15.22914,0.40022,1.69213,46.02499
55.44000,46.20005,15.07293,0.40174,1.67477,46.20005
55.65000,46.37499,15.17690,0.40326,1.68632,46.37499
55.86000,46.54987,15.18530,0.40478,1.68726,46.54987
56.07000,46.72499,15.31520,0.40630,1.70169,46.72499
56.28000,46.89999,15.50471,0.40783,1.72275,46.89999
56.49000,47.07505,15.38360,0.40935,1.70929,47.07505
56.70000,47.24999,15.47797,0.41087,1.71977,47.24999
56.91000,47.42499,15.29289,0.41239,1.69921,47.42499
57.12000,47.59999,15.26276,0.41391,1.69586,47.59999
57.33000,47.77506,15.42196,0.41544,1.71355,47.77506
57.54000,47.94999,15.42056,0.41696,1.71340,47.94999
57.75000,48.12493,15.54906,0.41848,1.72767,48.12493
57.96000,48.29993,15.52014,0.42000,1.72446,48.29993
58.17000,48.47493,15.48157,0.42152,1.72017,48.47493
58.38000,48.65006,15.42289,0.42304,1.71365,48.65006
58.59000,48.82505,15.50785,0.42457,1.72309,48.82505
58.80000,48.99999,15.45695,0.42609,1.71744,48.99999
59.01000,49.17499,15.50067,0.42761,1.72230,49.17499
59.22000,49.34999,15.62121,0.42913,1.73569,49.34999
59.43000,49.52499,15.76223,0.43065,1.75136,49.52499
59.64000,49.69999,15.59018,0.43217,1.73224,49.69999
59.85000,49.87499,15.65244,0.43370,1.73916,49.87499
60.06000,50.04987,15.69461,0.43522,1.74385,50.04987
60.27000,50.22499,15.61188,0.43674,1.73465,50.22499
60.48000,50.39999,15.56876,0.43826,1.72986,50.39999
60.69000,50.57505,15.79973,0.43978,1.75553,50.57505
60.90000,50.75006,15.72618,0.44130,1.74735,50.75006
61.11000,50.92487,15.95336,0.44282,1.77260,50.92487
61.32000,51.09993,15.63135,0.44435,1.73682,51.09993
61.53000,51.27499,15.91450,0.44587,1.76828,51.27499
61.74000,51.45005,15.94900,0.44739,1.77211,51.45005
61.95000,51.62499,15.72861,0.44891,1.74762,51.62499
62.16000,51.79993,16.01729,0.45043,1.77970,51.79993
62.37000,51.97493,15.78660,0.45196,1.75407,51.97493
62.58000,52.14999,15.95322,0.45348,1.77258,52.14999
62.79000,52.32512,15.92784,0.45500,1.76976,52.32512
63.00000,52.49993,15.82278,0.45652,1.75809,52.49993
63.21000,52.67493,16.03563,0.45804,1.78174,52.67493
63.42000,52.84993,16.17689,0.45956,1.79743,52.84993
63.63000,53.02500,15.95907,0.46109,1.77323,53.02500
63.84000,53.20006,16.10504,0.46261,1.78945,53.20006
64.05000,53.37506,16.08248,0.46413,1.78694,53.37506
64.26000,53.54993,16.19318,0.46565,1.79924,53.54993
64.47000,53.72493,16.17187,0.46717,1.79687,53.72493
64.68000,53.90005,16.25576,0.46870,1.80620,53.90005
64.89000,54.07499,16.26124,0.47022,1.80680,54.07499
65.10001,54.24999,16.21809,0.47174,1.80201,54.24999
65.31000,54.42487,16.36261,0.47326,1.81807,54.42487
65.52000,54.59993,16.39700,0.47478,1.82189,54.59993
65.73000,54.77499,16.39259,0.47630,1.82140,54.77499
65.94000,54.95006,16.21285,0.47783,1.80143,54.95006
66.15000,55.12499,16.48695,0.47935,1.83188,55.12499
66.36000,55.29987,16.45484,0.48087,1.82832,55.29987
66.57000,55.47499,16.33908,0.48239,1.81545,55.47499
66.78001,55.65005,16.34427,0.48391,1.81603,55.65005
66.99001,55.82506,16.28035,0.48544,1.80893,55.82506
67.20001,55.99999,16.47750,0.48696,1.83083,55.99999
67.41000,56.17499,16.47157,0.48848,1.83017,56.17499
67.62000,56.34993,16.42989,0.49000,1.82554,56.34993
67.83000,56.52505,16.69060,0.49152,1.85451,56.52505
68.04000,56.70005,16.58051,0.49304,1.84228,56.70005
68.25000,56.87499,16.72741,0.49457,1.85860,56.87499
68.46001,57.04993,16.56684,0.49609,1.84076,57.04993
68.67001,57.22493,16.76951,0.49761,1.86328,57.22493
68.88001,57.39999,16.59672,0.49913,1.84408,57.39999
69.09001,57.57506,16.69882,0.50065,1.85543,57.57506
69.30000,57.74999,16.88383,0.50217,1.87598,57.74999
69.51000,57.92499,16.87239,0.50370,1.87471,57.92499
69.72000,58.09999,16.92792,0.50522,1.88088,58.09999
69.93000,58.27500,16.82375,0.50674,1.86931,58.27500
70.14001,58.45012,17.04006,0.50826,1.89334,58.45012
70.35001,58.62506,17.00203,0.50978,1.88911,58.62506
70.56001,58.79987,17.00178,0.51130,1.88909,58.79987
70.77001,58.97499,16.93389,0.51283,1.88154,58.97499
70.98000,59.14999,16.92889,0.51435,1.88099,59.14999
71.19000,59.32506,16.90161,0.51587,1.87796,59.32506
71.40000,59.49999,16.84315,0.51739,1.87146,59.49999
71.61000,59.67493,16.96661,0.51891,1.88518,59.67493
71.82000,59.84987,17.13675,0.52043,1.90408,59.84987
72.03001,60.02499,17.03115,0.52196,1.89235,60.02499
72.24001,60.20011,17.27008,0.52348,1.91890,60.20011
72.45001,60.37505,17.15936,0.52500,1.90660,60.37505
72.66000,60.54993,17.14554,0.52652,1.90506,60.54993
72.87000,60.72499,17.34515,0.52804,1.92724,60.72499
73.08000,60.90006,17.08064,0.52957,1.89785,60.90006
73.29000,61.07505,17.40437,0.53109,1.93382,61.07505
73.50000,61.24999,17.45114,0.53261,1.93902,61.24999
73.71001,61.42493,17.41428,0.53413,1.93492,61.42493
73.92001,61.59993,17.32112,0.53565,1.92457,61.59993
74.13001,61.77499,17.50196,0.53717,1.94466,61.77499
74.34001,61.95005,17.55567,0.53870,1.95063,61.95005
74.55000,62.12506,17.41448,0.54022,1.93494,62.12506
74.76000,62.29999,17.37069,0.54174,1.93008,62.29999
74.97000,62.47499,17.65969,0.54326,1.96219,62.47499
75.18000,62.65006,17.57764,0.54478,1.95307,62.65006
75.39001,62.82506,17.45590,0.54630,1.93954,62.82506
75.60001,62.99999,17.49030,0.54783,1.94337,62.99999
75.81001,63.17499,17.58834,0.54935,1.95426,63.17499
76.02001,63.34993,17.65464,0.55087,1.96163,63.34993
76.23000,63.52499,17.52525,0.55239,1.94725,63.52499
76.44000,63.70005,17.69126,0.55391,1.96570,63.70005
76.65000,63.87505,17.77891,0.55544,1.97543,63.87505
76.86000,64.04999,17.99862,0.55696,1.99985,64.04999
77.07001,64.22493,17.89767,0.55848,1.98863,64.22493
77.28001,64.39999,17.78826,0.56000,1.97647,64.39999
77.49001,64.57511,17.83159,0.56152,1.98129,64.57511
77.70001,64.75005,17.97785,0.56304,1.99754,64.75005
77.91000,64.92493,17.84303,0.56456,1.98256,64.92493
78.12000,65.09999,18.00905,0.56609,2.00101,65.09999
78.33000,65.27499,17.93597,0.56761,1.99289,65.27499
78.54000,65.45005,17.88873,0.56913,1.98764,65.45005
78.75000,65.62505,17.89544,0.57065,1.98838,65.62505
78.96001,65.79993,18.25374,0.57217,2.02819,65.79993
79.17001,65.97486,17.86987,0.57369,1.98554,65.97486
79.38001,66.14999,18.21279,0.57522,2.02364,66.14999
79.59001,66.32505,18.09325,0.57674,2.01036,66.32505
79.80000,66.49998,17.88736,0.57826,1.98748,66.49998
80.01000,66.67505,18.12397,0.57978,2.01377,66.67505
80.22000,66.84999,18.30704,0.58130,2.03412,66.84999
80.43000,67.02492,18.40740,0.58283,2.04527,67.02492
80.64001,67.20005,18.16802,0.58435,2.01867,67.20005
80.85001,67.37505,18.28629,0.58587,2.03181,67.37505
81.06001,67.54993,18.43978,0.58739,2.04886,67.54993
81.27001,67.72499,18.43324,0.58891,2.04814,67.72499
81.48000,67.89993,18.49121,0.59043,2.05458,67.89993
81.69000,68.07499,18.46273,0.59196,2.05141,68.07499
81.90000,68.25005,18.60945,0.59348,2.06772,68.25005
82.11000,68.42505,18.36004,0.59500,2.04000,68.42505
82.32001,68.59993,18.39910,0.59652,2.04434,68.59993
82.53001,68.77493,18.52028,0.59804,2.05781,68.77493
82.74001,68.95012,18.54622,0.59957,2.06069,68.95012
82.95001,69.12505,18.54524,0.60109,2.06058,69.12505
83.16000,69.29999,18.60262,0.60261,2.06696,69.29999
83.37000,69.47499,18.63051,0.60413,2.07006,69.47499
83.58000,69.64999,18.72331,0.60565,2.08037,69.64999
83.79000,69.82499,18.70952,0.60717,2.07884,69.82499
84.00001,69.99999,18.64869,0.60870,2.07208,69.99999
84.21001,70.17499,18.78513,0.61022,2.08724,70.17499
84.42001,70.34992,18.76384,0.61174,2.08487,70.34992
84.63001,70.52492,18.73480,0.61326,2.08164,70.52492
84.84001,70.69999,18.88023,0.61478,2.09780,70.69999
85.05000,70.87505,18.94168,0.61630,2.10463,70.87505
85.26000,71.04993,18.89472,0.61783,2.09941,71.04993
85.47000,71.22499,18.91478,0.61935,2.10164,71.22499
85.68000,71.40005,18.80744,0.62087,2.08972,71.40005
85.89001,71.57499,19.17380,0.62239,2.13042,71.57499
86.10001,71.74999,18.92206,0.62391,2.10245,71.74999
86.31001,71.92499,19.09756,0.62543,2.12195,71.92499
86.52001,72.09993,19.13310,0.62696,2.12590,72.09993
86.73000,72.27493,19.26513,0.62848,2.14057,72.27493
86.94000,72.45012,19.16986,0.63000,2.12998,72.45012
87.15000,72.62505,19.17909,0.63152,2.13101,72.62505
87.36000,72.79993,19.21294,0.63304,2.13477,72.79993
87.57001,72.97499,19.25893,0.63457,2.13988,72.97499
87.78001,73.14999,19.25134,0.63609,2.13904,73.14999
87.99001,73.32499,19.15965,0.63761,2.12885,73.32499
88.20001,73.50005,19.43576,0.63913,2.15953,73.50005
88.41000,73.67505,19.42177,0.64065,2.15797,73.67505
88.62000,73.84993,19.45584,0.64217,2.16176,73.84993
88.83000,74.02499,19.51582,0.64370,2.16842,74.02499
89.04000,74.19999,19.39241,0.64522,2.15471,74.19999
89.25001,74.37499,19.37811,0.64674,2.15312,74.37499
89.46001,74.54999,19.52684,0.64826,2.16965,74.54999
89.67001,74.72493,19.43164,0.64978,2.15907,74.72493
89.88001,74.89999,19.63367,0.65130,2.18152,74.89999
90.09001,75.07499,19.66791,0.65283,2.18532,75.07499
90.30000,75.24999,19.65118,0.65435,2.18346,75.24999
90.51000,75.42499,19.57156,0.65587,2.17462,75.42499
90.72000,75.59999,19.60972,0.65739,2.17886,75.59999
90.93001,75.77499,19.80577,0.65891,2.20064,75.77499
91.14001,75.95005,19.76183,0.66044,2.19576,75.95005
91.35001,76.12505,19.81645,0.66196,2.20183,76.12505
91.56001,76.29993,19.76857,0.66348,2.19651,76.29993
91.77001,76.47493,20.09513,0.66500,2.23279,76.47493
91.98000,76.64993,19.72461,0.66652,2.19162,76.64993
92.19000,76.82499,20.04672,0.66804,2.22741,76.82499
92.40000,76.99999,19.97682,0.66957,2.21965,76.99999
92.61000,77.17505,19.80778,0.67109,2.20086,77.17505
92.82001,77.34999,19.95828,0.67261,2.21759,77.34999
93.03001,77.52493,20.00868,0.67413,2.22319,77.52493
93.24001,77.70005,20.24642,0.67565,2.24960,77.70005
93.45001,77.87499,20.15683,0.67717,2.23965,77.87499
93.66000,78.04993,20.00770,0.67870,2.22308,78.04993
93.87000,78.22492,19.98492,0.68022,2.22055,78.22492
94.08000,78.39998,20.22518,0.68174,2.24724,78.39998
94.29000,78.57499,20.33507,0.68326,2.25945,78.57499
94.50001,78.74999,20.24776,0.68478,2.24975,78.74999
94.71001,78.92499,20.22785,0.68630,2.24754,78.92499
94.92001,79.09999,20.37918,0.68783,2.26435,79.09999
95.13001,79.27499,20.40772,0.68935,2.26752,79.27499
95.34001,79.44998,20.31230,0.69087,2.25692,79.44998
95.55000,79.62504,20.33503,0.69239,2.25945,79.62504
95.76000,79.79993,20.49610,0.69391,2.27734,79.79993
95.97000,79.97499,20.49552,0.69543,2.27728,79.97499
96.18001,80.15005,20.70352,0.69696,2.30039,80.15005
96.39001,80.32498,20.46448,0.69848,2.27383,80.32498
96.60001,80.49992,20.64136,0.70000,2.29348,80.49992
96.81001,80.67499,20.45564,0.70152,2.27285,80.67499
97.02001,80.84998,20.69233,0.70304,2.29915,80.84998
97.23000,81.02492,20.59103,0.70456,2.28789,81.02492
97.44000,81.19998,20.76857,0.70609,2.30762,81.19998
97.65000,81.37499,20.67175,0.70761,2.29686,81.37499
97.86001,81.54999,20.74731,0.70913,2.30526,81.54999
98.07001,81.72498,20.88941,0.71065,2.32105,81.72498
98.28001,81.90005,20.75096,0.71217,2.30566,81.90005
98.49001,82.07498,20.87939,0.71370,2.31993,82.07498
98.70001,82.24999,20.81973,0.71522,2.31330,82.24999
98.91000,82.42499,20.87814,0.71674,2.31979,82.42499
99.12000,82.59999,20.94757,0.71826,2.32751,82.59999
99.33000,82.77499,21.12685,0.71978,2.34743,82.77499
99.54000,82.94999,20.96859,0.72130,2.32984,82.94999
99.75001,83.12498,20.97851,0.72283,2.33095,83.12498
99.96001,83.29999,20.95081,0.72435,2.32787,83.29999
100.17001,83.47498,21.30370,0.72587,2.36708,83.47498
100.38001,83.64999,21.19844,0.72739,2.35538,83.64999
100.59001,83.82499,21.20644,0.72891,2.35627,83.82499
100.80000,83.99999,21.25224,0.73043,2.36136,83.99999
101.01000,84.17505,21.29170,0.73196,2.36574,84.17505
101.22000,84.34999,21.38180,0.73348,2.37576,84.34999
101.43001,84.52505,21.16838,0.73500,2.35204,84.52505
101.64001,84.70004,21.08651,0.73652,2.34295,84.70004
101.85001,84.87498,21.50781,0.73804,2.38976,84.87498
102.06001,85.04986,21.27828,0.73956,2.36425,85.04986
102.27001,85.22498,21.48131,0.74109,2.38681,85.22498
102.48000,85.40005,21.32285,0.74261,2.36921,85.40005
102.69000,85.57499,21.48633,0.74413,2.38737,85.57499
102.90000,85.75005,21.53712,0.74565,2.39301,85.75005
103.11001,85.92498,21.69289,0.74717,2.41032,85.92498
103.32001,86.09999,21.50996,0.74870,2.39000,86.09999
103.53001,86.27499,21.40881,0.75022,2.37876,86.27499
103.74001,86.45005,21.68642,0.75174,2.40960,86.45005
103.95001,86.62499,21.67898,0.75326,2.40878,86.62499
104.16000,86.79993,21.70043,0.75478,2.41116,86.79993
104.37000,86.97499,21.75745,0.75630,2.41749,86.97499
104.58000,87.15005,21.97838,0.75783,2.44204,87.15005
104.79001,87.32505,21.81120,0.75935,2.42347,87.32505
105.00001,87.49999,21.95244,0.76087,2.43916,87.49999
105.21001,87.67499,21.97637,0.76239,2.44182,87.67499
105.42001,87.84992,21.96040,0.76391,2.44004,87.84992
105.63001,88.02504,21.94216,0.76544,2.43802,88.02504
105.84001,88.19998,22.01384,0.76696,2.44598,88.19998
106.05000,88.37499,21.97581,0.76848,2.44176,88.37499
106.26000,88.54993,22.14237,0.77000,2.46026,88.54993
106.47001,88.72499,21.96001,0.77152,2.44000,88.72499
106.68001,88.90011,22.35888,0.77304,2.48432,88.90011
106.89001,89.07499,22.14886,0.77457,2.46098,89.07499
107.10001,89.24992,22.14308,0.77609,2.46034,89.24992
107.31001,89.42492,22.12374,0.77761,2.45819,89.42492
107.52001,89.59993,22.46262,0.77913,2.49585,89.59993
107.73000,89.77499,22.21159,0.78065,2.46795,89.77499
107.94000,89.95005,22.16010,0.78217,2.46223,89.95005
108.15000,90.12499,22.18913,0.78370,2.46546,90.12499
108.36001,90.29986,22.48865,0.78522,2.49874,90.29986
108.57001,90.47498,22.19167,0.78674,2.46574,90.47498
108.78001,90.65005,22.41236,0.78826,2.49026,90.65005
108.99001,90.82499,22.39838,0.78978,2.48871,90.82499
109.20001,90.99999,22.55466,0.79130,2.50607,90.99999
109.41000,91.17492,22.62531,0.79283,2.51392,91.17492
109.62000,91.34993,22.46779,0.79435,2.49642,91.34993
109.83000,91.52499,22.43147,0.79587,2.49239,91.52499
110.04001,91.69999,22.51290,0.79739,2.50143,91.69999
110.25001,91.87498,22.62859,0.79891,2.51429,91.87498
110.46001,92.04992,22.76215,0.80043,2.52913,92.04992
110.67001,92.22493,22.75517,0.80196,2.52835,92.22493
110.88001,92.40005,22.82805,0.80348,2.53645,92.40005
111.09001,92.57499,22.77121,0.80500,2.53013,92.57499
111.30000,92.75005,22.95509,0.80652,2.55057,92.75005
111.51000,92.92499,22.91455,0.80804,2.54606,92.92499
111.72001,93.09999,22.80932,0.80957,2.53437,93.09999
111.93001,93.27493,23.00321,0.81109,2.55591,93.27493
112.14001,93.45005,23.03052,0.81261,2.55895,93.45005
112.35001,93.62505,22.78737,0.81413,2.53193,93.62505
112.56001,93.79987,23.07047,0.81565,2.56339,93.79987
112.77001,93.97492,23.06268,0.81717,2.56252,93.97492
112.98000,94.15004,22.97740,0.81870,2.55304,94.15004
113.19000,94.32505,23.05685,0.82022,2.56187,94.32505
113.40001,94.49992,23.18476,0.82174,2.57608,94.49992
113.61001,94.67498,23.08925,0.82326,2.56547,94.67498
113.82001,94.84999,23.13684,0.82478,2.57076,94.84999
114.03001,95.02498,23.22951,0.82630,2.58106,95.02498
114.24001,95.20005,23.43658,0.82783,2.60406,95.20005
114.45001,95.37498,23.35559,0.82935,2.59507,95.37498
114.66000,95.54992,23.20663,0.83087,2.57852,95.54992
114.87000,95.72499,23.33928,0.83239,2.59325,95.72499
115.08000,95.90005,23.31087,0.83391,2.59010,95.90005
115.29001,96.07505,23.46859,0.83544,2.60762,96.07505
115.50001,96.24999,23.54530,0.83696,2.61614,96.24999
115.71001,96.42493,23.47146,0.83848,2.60794,96.42493
115.92001,96.59993,23.49889,0.84000,2.61099,96.59993
116.13001,96.77499,23.59259,0.84152,2.62140,96.77499
116.34001,96.95005,23.59472,0.84304,2.62164,96.95005
116.55000,97.12499,23.61294,0.84457,2.62366,97.12499
116.76000,97.29993,23.78208,0.84609,2.64245,97.29993
116.97001,97.47499,23.69149,0.84761,2.63239,97.47499
117.18001,97.65005,23.71955,0.84913,2.63551,97.65005
117.39001,97.82499,23.78044,0.85065,2.64227,97.82499
117.60001,97.99992,23.81759,0.85217,2.64640,97.99992
117.81001,98.17492,23.58130,0.85369,2.62014,98.17492
118.02001,98.34993,23.80101,0.85522,2.64456,98.34993
118.23000,98.52492,23.87196,0.85674,2.65244,98.52492
118.44000,98.70011,23.77870,0.85826,2.64208,98.70011
118.65001,98.87498,23.90625,0.85978,2.65625,98.87498
118.86001,99.04992,23.96415,0.86130,2.66268,99.04992
119.07001,99.22499,23.79229,0.86283,2.64359,99.22499
119.28001,99.40005,24.24425,0.86435,2.69381,99.40005
119.49001,99.57504,24.16698,0.86587,2.68522,99.57504
119.70001,99.74998,24.06081,0.86739,2.67342,99.74998
119.91000,99.92499,24.19125,0.86891,2.68792,99.92499
120.12000,100.09993,24.16728,0.87043,2.68525,100.09993
120.33001,100.27498,24.14514,0.87196,2.68279,100.27498
120.54001,100.45005,24.18777,0.87348,2.68753,100.45005
120.75001,100.62505,24.26948,0.87500,2.69661,100.62505
120.96001,100.79992,24.36249,0.87652,2.70694,100.79992
121.17001,100.97499,24.34410,0.87804,2.70490,100.97499
121.38001,101.14999,24.43616,0.87957,2.71513,101.14999
121.59001,101.32499,24.46989,0.88109,2.71888,101.32499
121.80000,101.50004,24.36837,0.88261,2.70760,101.50004
122.01000,101.67498,24.52960,0.88413,2.72551,101.67498
122.22001,101.84992,24.46550,0.88565,2.71839,101.84992
122.43001,102.02498,24.61541,0.88717,2.73505,102.02498
122.64001,102.20011,24.63653,0.88870,2.73739,102.20011
122.85001,102.37505,24.79728,0.89022,2.75525,102.37505
123.06001,102.54992,24.53153,0.89174,2.72573,102.54992
123.27001,102.72492,24.74674,0.89326,2.74964,102.72492
123.48000,102.89999,24.67076,0.89478,2.74120,102.89999
123.69000,103.07498,24.73116,0.89630,2.74791,103.07498
123.90001,103.25004,24.73179,0.89783,2.74798,103.25004
124.11001,103.42498,24.67522,0.89935,2.74169,103.42498
124.32001,103.59992,24.80725,0.90087,2.75636,103.59992
124.53001,103.77498,24.92226,0.90239,2.76914,103.77498
124.74001,103.95005,24.89581,0.90391,2.76620,103.95005
124.95001,104.12505,25.00159,0.90544,2.77795,104.12505
125.16000,104.29992,25.03536,0.90696,2.78171,104.29992
125.37000,104.47492,25.12407,0.90848,2.79156,104.47492
125.58001,104.65004,25.10266,0.91000,2.78919,104.65004
125.79001,104.82505,24.96121,0.91152,2.77347,104.82505
126.00001,104.99999,25.03377,0.91304,2.78153,104.99999
126.21001,105.17498,25.26688,0.91457,2.80743,105.17498
126.42001,105.34992,25.31691,0.91609,2.81299,105.34992
126.63001,105.52499,25.06551,0.91761,2.78506,105.52499
126.84001,105.69998,25.19747,0.91913,2.79972,105.69998
127.05000,105.87505,25.32864,0.92065,2.81429,105.87505
127.26001,106.04993,25.45678,0.92217,2.82853,106.04993
127.47001,106.22492,25.43802,0.92369,2.82645,106.22492
127.68001,106.40005,25.48838,0.92522,2.83204,106.40005
127.89001,106.57504,25.42947,0.92674,2.82550,106.57504
128.10001,106.75005,25.51473,0.92826,2.83497,106.75005
128.31002,106.92492,25.46888,0.92978,2.82988,106.92492
128.52001,107.09993,25.65844,0.93130,2.85094,107.09993
128.73001,107.27492,25.39891,0.93283,2.82210,107.27492
128.94000,107.45005,25.49893,0.93435,2.83321,107.45005
129.15001,107.62505,25.97668,0.93587,2.88630,107.62505
129.36000,107.79992,25.61370,0.93739,2.84597,107.79992
129.57001,107.97499,25.77096,0.93891,2.86344,107.97499
129.78000,108.14998,25.79209,0.94043,2.86579,108.14998
129.99001,108.32504,25.91496,0.94196,2.87944,108.32504
130.20002,108.50005,25.71183,0.94348,2.85687,108.50005
130.41000,108.67499,25.72469,0.94500,2.85830,108.67499
130.62001,108.84985,25.96297,0.94652,2.88477,108.84985
130.83000,109.02498,26.04944,0.94804,2.89438,109.02498
131.04001,109.20005,26.13056,0.94957,2.90340,109.20005
131.25000,109.37504,26.05172,0.95109,2.89464,109.37504
131.46000,109.54992,25.96519,0.95261,2.88502,109.54992
131.67002,109.72492,26.08665,0.95413,2.89852,109.72492
131.88000,109.90005,26.19169,0.95565,2.91019,109.90005
132.09002,110.07499,26.17496,0.95717,2.90833,110.07499
132.30000,110.24999,26.17072,0.95870,2.90786,110.24999
132.51002,110.42498,26.10073,0.96022,2.90008,110.42498
132.72000,110.59999,26.41480,0.96174,2.93498,110.59999
132.93002,110.77492,26.02299,0.96326,2.89144,110.77492
133.14000,110.95005,26.23286,0.96478,2.91476,110.95005
133.35000,111.12511,26.17469,0.96631,2.90830,111.12511
133.56002,111.29992,26.42521,0.96783,2.93613,111.29992
133.77000,111.47492,26.33004,0.96935,2.92556,111.47492
133.98002,111.64992,26.27491,0.97087,2.91943,111.64992
134.19000,111.82498,26.42734,0.97239,2.93637,111.82498
134.40002,111.99999,26.66371,0.97391,2.96263,111.99999
134.61000,112.17505,26.52494,0.97544,2.94722,112.17505
134.82000,112.34992,26.49996,0.97696,2.94444,112.34992
135.03002,112.52498,26.70154,0.97848,2.96684,112.52498
135.24000,112.70011,26.63057,0.98000,2.95895,112.70011
135.45002,112.87505,26.43442,0.98152,2.93716,112.87505
135.66000,113.04999,26.74428,0.98304,2.97159,113.04999
135.87002,113.22498,26.74739,0.98457,2.97193,113.22498
136.08000,113.39999,26.63236,0.98609,2.95915,113.39999
136.29002,113.57498,26.69596,0.98761,2.96622,113.57498
136.50000,113.75004,26.88422,0.98913,2.98714,113.75004
136.71000,113.92498,26.92346,0.99065,2.99150,113.92498
136.92002,114.09992,26.97519,0.99217,2.99724,114.09992
137.13000,114.27498,26.87198,0.99370,2.98578,114.27498
137.34002,114.45004,26.95843,0.99522,2.99538,114.45004
137.55000,114.62505,27.16639,0.99674,3.01849,114.62505
137.76002,114.79999,26.85858,0.99826,2.98429,114.79999
137.97000,114.97498,27.09683,0.99978,3.01076,114.97498
138.18002,115.14999,27.04540,1.00130,3.00504,115.14999
138.39000,115.32499,27.27809,1.00283,3.03090,115.32499
138.60000,115.49998,27.05789,1.00435,3.00643,115.49998
138.81002,115.67499,27.17146,1.00587,3.01905,115.67499
139.02000,115.84993,27.21620,1.00739,3.02402,115.84993
139.23002,116.02492,27.35531,1.00891,3.03948,116.02492
139.44000,116.19998,27.23168,1.01043,3.02574,116.19998
139.65002,116.37505,27.47652,1.01196,3.05295,116.37505
139.86000,116.54999,27.47853,1.01348,3.05317,116.54999
140.07000,116.72492,27.30961,1.01500,3.03440,116.72492
140.28002,116.90005,27.27537,1.01652,3.03060,116.90005
140.49000,117.07499,27.27699,1.01804,3.03078,117.07499
140.70002,117.24998,27.60774,1.01957,3.06753,117.24998
140.91000,117.42499,27.44267,1.02109,3.04919,117.42499
141.12002,117.59993,27.66336,1.02261,3.07371,117.59993
141.33000,117.77492,27.79769,1.02413,3.08863,117.77492
141.54002,117.94998,27.57309,1.02565,3.06368,117.94998
141.75000,118.12504,27.58665,1.02717,3.06518,118.12504
141.96000,118.29992,27.67201,1.02869,3.07467,118.29992
142.17002,118.47499,27.66157,1.03022,3.07351,118.47499
142.38000,118.64998,27.75846,1.03174,3.08427,118.64998
142.59002,118.82499,27.77636,1.03326,3.08626,118.82499
142.80000,119.00004,27.90935,1.03478,3.10104,119.00004
143.01002,119.17498,27.72562,1.03630,3.08062,119.17498
143.22000,119.34998,27.83754,1.03783,3.09306,119.34998
143.43002,119.52498,27.91822,1.03935,3.10202,119.52498
143.64000,119.70005,27.95385,1.04087,3.10598,119.70005
143.85000,119.87505,27.86617,1.04239,3.09624,119.87505
144.06002,120.04992,28.13829,1.04391,3.12648,120.04992
144.27000,120.22492,28.04309,1.04543,3.11590,120.22492
144.48002,120.39999,28.17153,1.04696,3.13017,120.39999
144.69000,120.57498,28.14674,1.04848,3.12742,120.57498
144.90002,120.74999,28.05696,1.05000,3.11744,120.74999
145.11000,120.92505,28.18314,1.05152,3.13146,120.92505
145.32000,121.09999,28.22409,1.05304,3.13601,121.09999
145.53002,121.27498,28.37253,1.05457,3.15250,121.27498
145.74000,121.44999,28.31296,1.05609,3.14588,121.44999
145.95002,121.62505,28.34676,1.05761,3.14964,121.62505
146.16000,121.79992,28.32477,1.05913,3.14720,121.79992
146.37002,121.97498,28.25299,1.06065,3.13922,121.97498
146.58000,122.14999,28.38293,1.06217,3.15366,122.14999
146.79002,122.32498,28.45993,1.06370,3.16221,122.32498
147.00000,122.49999,28.61535,1.06522,3.17948,122.49999
147.21000,122.67498,28.54291,1.06674,3.17143,122.67498
147.42002,122.84998,28.57460,1.06826,3.17496,122.84998
147.63000,123.02498,28.40593,1.06978,3.15621,123.02498
147.84002,123.20004,28.67742,1.07130,3.18638,123.20004
148.05000,123.37505,28.48266,1.07283,3.16474,123.37505
148.26002,123.54992,28.67122,1.07435,3.18569,123.54992
148.47000,123.72498,28.74136,1.07587,3.19348,123.72498
148.68002,123.90004,28.67054,1.07739,3.18562,123.90004
148.89002,124.07498,28.83881,1.07891,3.20431,124.07498
149.10000,124.24998,28.80754,1.08043,3.20084,124.24998
149.31002,124.42498,28.77555,1.08196,3.19728,124.42498
149.52000,124.59998,29.04329,1.08348,3.22703,124.59998
149.73002,124.77492,28.90871,1.08500,3.21208,124.77492
149.94000,124.94999,28.74215,1.08652,3.19357,124.94999
150.15002,125.12498,28.94875,1.08804,3.21653,125.12498
150.36000,125.29992,28.90325,1.08956,3.21147,125.29992
150.57000,125.47503,28.88552,1.09109,3.20950,125.47503
150.78002,125.65004,29.11093,1.09261,3.23455,125.65004
150.99000,125.82498,28.88625,1.09413,3.20958,125.82498
151.20002,125.99992,29.12602,1.09565,3.23622,125.99992
151.41000,126.17498,29.24272,1.09717,3.24919,126.17498
151.62002,126.34992,29.12673,1.09869,3.23630,126.34992
151.83000,126.52497,29.26258,1.10022,3.25140,126.52497
152.04002,126.69998,29.38181,1.10174,3.26465,126.69998
152.25000,126.87504,29.21387,1.10326,3.24599,126.87504
152.46000,127.04998,29.37262,1.10478,3.26362,127.04998
152.67002,127.22492,29.36721,1.10630,3.26302,127.22492
152.88000,127.39998,29.62571,1.10783,3.29175,127.39998
153.09002,127.57498,29.37272,1.10935,3.26364,127.57498
153.30000,127.74998,29.52887,1.11087,3.28099,127.74998
153.51002,127.92492,29.48624,1.11239,3.27625,127.92492
153.72000,128.10004,29.57105,1.11391,3.28567,128.10004
153.93002,128.27498,29.70156,1.11543,3.30017,128.27498
154.14002,128.44997,29.81633,1.11696,3.31293,128.44997
154.35000,128.62504,29.54903,1.11848,3.28323,128.62504
154.56002,128.79992,29.71937,1.12000,3.30215,128.79992
154.77000,128.97498,29.82487,1.12152,3.31387,128.97498
154.98002,129.14998,29.75877,1.12304,3.30653,129.14998
155.19000,129.32497,29.75179,1.12457,3.30575,129.32497
155.40002,129.49991,29.68393,1.12609,3.29821,129.49991
155.61000,129.67497,29.87836,1.12761,3.31982,129.67497
155.82000,129.84998,29.85664,1.12913,3.31740,129.84998
156.03002,130.02499,29.85995,1.13065,3.31777,130.02499
156.24000,130.20011,29.90981,1.13217,3.32331,130.20011
156.45002,130.37498,29.96918,1.13370,3.32991,130.37498
156.66000,130.54991,29.98465,1.13522,3.33163,130.54991
156.87002,130.72498,30.14000,1.13674,3.34889,130.72498
157.08000,130.90004,30.30782,1.13826,3.36754,130.90004
157.29002,131.07498,29.87121,1.13978,3.31902,131.07498
157.50000,131.25004,30.16525,1.14130,3.35169,131.25004
157.71000,131.42492,29.88799,1.14283,3.32089,131.42492
157.92002,131.59998,30.38210,1.14435,3.37579,131.59998
158.13000,131.77504,30.29420,1.14587,3.36602,131.77504
158.34002,131.94998,30.33848,1.14739,3.37094,131.94998
158.55000,132.12504,30.41479,1.14891,3.37942,132.12504
158.76002,132.29991,30.41837,1.15043,3.37982,132.29991
158.97000,132.47497,30.40647,1.15196,3.37850,132.47497
159.18002,132.65003,30.30387,1.15348,3.36710,132.65003
159.39002,132.82505,30.24497,1.15500,3.36055,132.82505
159.60000,132.99997,30.41565,1.15652,3.37952,132.99997
159.81002,133.17505,30.30512,1.15804,3.36724,133.17505
160.02000,133.34997,30.57058,1.15956,3.39673,133.34997
160.23002,133.52498,30.55966,1.16109,3.39552,133.52498
160.44000,133.69999,30.62424,1.16261,3.40269,133.69999
160.65002,133.87498,30.61599,1.16413,3.40178,133.87498
160.86000,134.04992,30.85659,1.16565,3.42851,134.04992
161.07000,134.22498,30.75840,1.16717,3.41760,134.22498
161.28002,134.40010,30.79154,1.16870,3.42128,134.40010
161.49000,134.57504,30.84858,1.17022,3.42762,134.57504
161.70002,134.74998,30.72436,1.17174,3.41382,134.74998
161.91000,134.92498,30.75321,1.17326,3.41702,134.92498
162.12002,135.09998,30.91493,1.17478,3.43499,135.09998
162.33000,135.27498,30.76773,1.17630,3.41864,135.27498
162.54002,135.45004,30.85767,1.17783,3.42863,135.45004
162.75002,135.62503,30.76161,1.17935,3.41796,135.62503
162.96000,135.79986,31.11989,1.18087,3.45777,135.79986
163.17002,135.97491,31.08379,1.18239,3.45375,135.97491
163.38000,136.15005,31.19689,1.18391,3.46632,136.15005
163.59002,136.32505,30.99269,1.18544,3.44363,136.32505
163.80000,136.49997,31.09805,1.18696,3.45534,136.49997
164.01002,136.67497,31.09746,1.18848,3.45527,136.67497
164.22000,136.84998,31.21801,1.19000,3.46867,136.84998
164.43002,137.02499,31.08913,1.19152,3.45435,137.02499
164.64002,137.20010,31.09746,1.19304,3.45527,137.20010
164.85000,137.37499,31.27992,1.19457,3.47555,137.37499
165.06002,137.54993,31.26904,1.19609,3.47434,137.54993
165.27000,137.72492,31.25077,1.19761,3.47231,137.72492
165.48002,137.89998,31.38116,1.19913,3.48680,137.89998
165.69000,138.07498,31.09016,1.20065,3.45446,138.07498
165.90002,138.24992,31.31964,1.20217,3.47996,138.24992
166.11000,138.42492,31.33840,1.20369,3.48204,138.42492
166.32000,138.59998,31.44401,1.20522,3.49378,138.59998
166.53002,138.77504,31.42353,1.20674,3.49150,138.77504
166.74000,138.95012,31.31382,1.20826,3.47931,138.95012
166.95002,139.12504,31.76940,1.20978,3.52993,139.12504
167.16000,139.29985,31.54452,1.21130,3.50495,139.29985
167.37002,139.47497,31.66913,1.21283,3.51879,139.47497
167.58000,139.65005,31.76230,1.21435,3.52914,139.65005
167.79002,139.82505,31.64797,1.21587,3.51644,139.82505
168.00002,139.99998,31.79120,1.21739,3.53236,139.99998
168.21000,140.17492,31.75318,1.21891,3.52813,140.17492
168.42002,140.34999,31.76734,1.22043,3.52970,140.34999
168.63000,140.52498,31.79683,1.22196,3.53298,140.52498
168.84002,140.70011,31.70665,1.22348,3.52296,140.70011
169.05000,140.87498,31.83312,1.22500,3.53701,140.87498
169.26002,141.04992,32.13613,1.22652,3.57068,141.04992
169.47000,141.22493,31.93844,1.22804,3.54872,141.22493
169.68002,141.40004,31.93672,1.22957,3.54852,141.40004
169.89002,141.57504,32.11869,1.23109,3.56874,141.57504
170.10000,141.74998,32.00922,1.23261,3.55658,141.74998
170.31002,141.92492,32.13221,1.23413,3.57025,141.92492
170.52000,142.09992,32.01191,1.23565,3.55688,142.09992
170.73002,142.27492,32.11742,1.23717,3.56860,142.27492
170.94000,142.45003,32.16077,1.23870,3.57342,142.45003
171.15002,142.62504,32.20921,1.24022,3.57880,142.62504
171.36000,142.79986,32.22322,1.24174,3.58036,142.79986
171.57000,142.97497,32.34019,1.24326,3.59335,142.97497
171.78002,143.14997,32.32476,1.24478,3.59164,143.14997
171.99000,143.32511,32.35552,1.24631,3.59506,143.32511
172.20002,143.49997,32.53426,1.24783,3.61492,143.49997
172.41000,143.67498,32.32407,1.24935,3.59156,143.67498
172.62002,143.84999,32.11061,1.25087,3.56785,143.84999
172.83000,144.02498,32.53631,1.25239,3.61515,144.02498
173.04002,144.19998,32.40803,1.25391,3.60089,144.19998
173.25002,144.37499,32.38045,1.25543,3.59783,144.37499
173.46000,144.54992,32.87463,1.25696,3.65274,144.54992
173.67002,144.72499,32.62424,1.25848,3.62492,144.72499
173.88000,144.90004,32.42312,1.26000,3.60257,144.90004
174.09002,145.07504,32.71206,1.26152,3.63467,145.07504
174.30000,145.25004,32.57952,1.26304,3.61995,145.25004
174.51002,145.42492,32.80684,1.26456,3.64520,145.42492
174.72000,145.59998,32.77422,1.26609,3.64158,145.59998
174.93002,145.77498,32.82423,1.26761,3.64714,145.77498
175.14002,145.95004,32.73170,1.26913,3.63686,145.95004
175.35000,146.12503,32.59343,1.27065,3.62149,146.12503
175.56002,146.29985,32.90545,1.27217,3.65616,146.29985
175.77000,146.47491,32.68752,1.27369,3.63195,146.47491
175.98002,146.64997,32.84808,1.27522,3.64979,146.64997
176.19000,146.82504,32.78529,1.27674,3.64281,146.82504
176.40002,146.99997,32.87316,1.27826,3.65257,146.99997
176.61002,147.17499,32.84353,1.27978,3.64928,147.17499
176.82000,147.34991,33.09716,1.28130,3.67746,147.34991
177.03002,147.52491,32.89247,1.28283,3.65472,147.52491
177.24000,147.70010,33.02256,1.28435,3.66917,147.70010
177.45002,147.87504,33.12243,1.28587,3.68027,147.87504
177.66000,148.04992,33.25689,1.28739,3.69521,148.04992
177.87002,148.22492,33.06723,1.28891,3.67414,148.22492
178.08000,148.40004,33.20316,1.29044,3.68924,148.40004
178.29002,148.57498,33.14698,1.29196,3.68300,148.57498
178.50002,148.75004,33.13615,1.29348,3.68179,148.75004
178.71000,148.92492,33.39130,1.29500,3.71014,148.92492
178.92002,149.09992,33.23250,1.29652,3.69250,149.09992
179.13000,149.27498,33.30676,1.29804,3.70075,149.27498
179.34002,149.44998,33.20213,1.29956,3.68913,149.44998
179.55000,149.62504,33.15452,1.30109,3.68384,149.62504
179.76002,149.79991,33.35368,1.30261,3.70596,149.79991
179.97000,149.97492,33.15677,1.30413,3.68409,149.97492
180.18002,150.14998,33.39615,1.30565,3.71068,150.14998
180.39002,150.32510,33.30705,1.30717,3.70078,150.32510
180.60000,150.50004,33.37876,1.30870,3.70875,150.50004
180.81002,150.67498,33.37910,1.31022,3.70879,150.67498
181.02000,150.84999,33.51449,1.31174,3.72383,150.84999
181.23002,151.02491,33.47785,1.31326,3.71976,151.02491
181.44000,151.20004,33.35637,1.31478,3.70626,151.20004
181.65002,151.37504,33.44876,1.31630,3.71653,151.37504
181.86002,151.54992,33.41187,1.31783,3.71243,151.54992
182.07000,151.72492,33.48035,1.31935,3.72004,151.72492
182.28002,151.90004,33.47276,1.32087,3.71920,151.90004
182.49000,152.07504,33.35878,1.32239,3.70653,152.07504
182.70002,152.25003,33.52086,1.32391,3.72454,152.25003
182.91000,152.42497,33.59673,1.32543,3.73297,152.42497
183.12002,152.59991,33.45606,1.32696,3.71734,152.59991
183.33000,152.77492,33.43406,1.32848,3.71490,152.77492
183.54002,152.94998,33.65443,1.33000,3.73938,152.94998
183.75002,153.12503,33.48309,1.33152,3.72034,153.12503
183.96000,153.29991,33.62186,1.33304,3.73576,153.29991
184.17002,153.47498,33.31567,1.33457,3.70174,153.47498
184.38000,153.64997,33.27413,1.33609,3.69713,153.64997
184.59002,153.82505,33.13855,1.33761,3.68206,153.82505
184.80000,154.00005,33.20629,1.33913,3.68959,154.00005
185.01002,154.17499,32.73151,1.34065,3.63683,154.17499
185.22000,154.34991,-0.15703,1.34217,-0.01745,154.34991
185.43002,154.52499,-0.00683,1.34370,-0.00076,154.52499
185.64002,154.70005,-0.19516,1.34522,-0.02168,154.70005
185.85000,154.87504,-0.30388,1.34674,-0.03376,154.87504
186.06002,155.04998,-0.27711,1.34826,-0.03079,155.04998
186.27000,155.22492,-0.30831,1.34978,-0.03426,155.22492
186.48002,155.39998,-0.22734,1.35130,-0.02526,155.39998
186.69000,155.57498,-0.14753,1.35283,-0.01639,155.57498
186.90002,155.74998,-0.21576,1.35435,-0.02397,155.74998
187.11002,155.92498,-0.30887,1.35587,-0.03432,155.92498
187.32000,156.09997,-0.29450,1.35739,-0.03272,156.09997
187.53002,156.27490,-0.11953,1.35891,-0.01328,156.27490
187.74000,156.45003,-0.29322,1.36044,-0.03258,156.45003
187.95002,156.62510,-0.27760,1.36196,-0.03084,156.62510
188.16000,156.79991,-0.19213,1.36348,-0.02135,156.79991
188.37002,156.97496,-0.33753,1.36500,-0.03750,156.97496
188.58000,157.14997,-0.11179,1.36652,-0.01242,157.14997
188.79002,157.32499,-0.36834,1.36804,-0.04093,157.32499
189.00002,157.49991,-0.32357,1.36956,-0.03595,157.49991
189.21000,157.67498,-0.31179,1.37109,-0.03464,157.67498
189.42002,157.84997,0.02092,1.37261,0.00232,157.84997
189.62202,158.01828,-0.24361,1.37407,-0.02707,158.01828