File: V_8/FR/RDSO FR Tensile Multi.is_tens_RawData/Specimen_RawData_1.csv
Time,Extension,Load,Tensile strain,Tensile stress,Corrected Position
(sec),(mm),(N),(mm/mm),(MPa),(mm)
0.00000,0.00000,0.04423,0.00000,0.00491,0.00000
0.02000,0.01975,0.27871,0.00017,0.03097,0.01975
0.04000,0.09712,0.92912,0.00084,0.10324,0.09712
0.06000,0.23287,1.38808,0.00202,0.15423,0.23287
0.08000,0.41681,2.07961,0.00362,0.23107,0.41681
0.10000,0.62131,2.52834,0.00540,0.28093,0.62131
0.12000,0.83587,3.13619,0.00727,0.34847,0.83587
0.14000,1.05712,3.64879,0.00919,0.40542,1.05712
0.16000,1.27581,4.24309,0.01109,0.47145,1.27581
0.18000,1.47337,4.77131,0.01281,0.53015,1.47337
0.20000,1.65075,5.08184,0.01435,0.56465,1.65075
0.22000,1.81800,5.62755,0.01581,0.62528,1.81800
0.24000,1.98387,6.13993,0.01725,0.68221,1.98387
0.26000,2.15169,6.72125,0.01871,0.74681,2.15169
0.28000,2.32137,7.10973,0.02019,0.78997,2.32137
0.30000,2.49144,7.41327,0.02166,0.82370,2.49144
0.32000,2.66069,7.81703,0.02314,0.86856,2.66069
0.34000,2.82900,8.07100,0.02460,0.89678,2.82900
0.36000,2.99669,8.13823,0.02606,0.90425,2.99669
0.38000,3.16400,8.58713,0.02751,0.95413,3.16400
0.40000,3.33125,8.96030,0.02897,0.99559,3.33125
0.42000,3.49831,9.15662,0.03042,1.01740,3.49831
0.44000,3.66531,9.51454,0.03187,1.05717,3.66531
0.46000,3.83231,9.77387,0.03332,1.08599,3.83231
0.48000,3.99925,9.85185,0.03478,1.09465,3.99925
0.50000,4.16619,10.29539,0.03623,1.14393,4.16619
0.52000,4.33300,10.65719,0.03768,1.18413,4.33300
0.54000,4.49975,10.73248,0.03913,1.19250,4.49975
0.56000,4.66644,10.91215,0.04058,1.21246,4.66644
0.58000,4.83312,11.17354,0.04203,1.24150,4.83312
0.60000,4.99987,11.20550,0.04348,1.24506,4.99987
0.62000,5.16656,11.62655,0.04493,1.29184,5.16656
0.64000,5.33325,11.76155,0.04638,1.30684,5.33325
0.66000,5.49994,11.77091,0.04783,1.30788,5.49994
0.68000,5.66656,12.12666,0.04927,1.34741,5.66656
0.70000,5.83325,12.26504,0.05072,1.36278,5.83325
0.72000,6.00000,12.30819,0.05217,1.36758,6.00000
0.74000,6.16669,12.40400,0.05362,1.37822,6.16669
0.76000,6.33337,12.63956,0.05507,1.40440,6.33337
0.78000,6.50000,12.88334,0.05652,1.43148,6.50000
0.80000,6.66662,13.29011,0.05797,1.47668,6.66662
0.82000,6.83331,13.20961,0.05942,1.46773,6.83331
0.84000,7.00000,13.29854,0.06087,1.47762,7.00000
0.86000,7.16669,13.41717,0.06232,1.49080,7.16669
0.88000,7.33325,13.45127,0.06377,1.49459,7.33325
0.90000,7.49994,13.47627,0.06522,1.49736,7.49994
0.92000,7.66662,13.73642,0.06667,1.52627,7.66662
0.94000,7.83331,14.07572,0.06812,1.56397,7.83331
0.96000,8.00006,13.96436,0.06957,1.55160,8.00006
0.98000,8.16662,14.08035,0.07101,1.56448,8.16662
1.00000,8.33331,14.16467,0.07246,1.57385,8.33331
1.02000,8.50000,14.28147,0.07391,1.58683,8.50000
1.04000,8.66669,14.42484,0.07536,1.60276,8.66669
1.06000,8.83331,14.68185,0.07681,1.63132,8.83331
1.08000,8.99994,14.99036,0.07826,1.66560,8.99994
1.10000,9.16662,15.17620,0.07971,1.68624,9.16662
1.12000,9.33331,15.10515,0.08116,1.67835,9.33331
1.14000,9.50006,14.92994,0.08261,1.65888,9.50006
1.16000,9.66675,15.13092,0.08406,1.68121,9.66675
1.18000,9.83337,15.34495,0.08551,1.70499,9.83337
1.20000,10.00000,15.18879,0.08696,1.68764,10.00000
1.22000,10.16669,15.32440,0.08841,1.70271,10.16669
1.24000,10.33331,15.50179,0.08985,1.72242,10.33331
1.26000,10.50000,15.48447,0.09130,1.72050,10.50000
1.28000,10.66669,15.73369,0.09275,1.74819,10.66669
1.30000,10.83331,16.02788,0.09420,1.78088,10.83331
1.32000,11.00000,15.90582,0.09565,1.76731,11.00000
1.34000,11.16669,16.00768,0.09710,1.77863,11.16669
1.36000,11.33337,15.99506,0.09855,1.77723,11.33337
1.38000,11.50006,15.80038,0.10000,1.75560,11.50006
1.40000,11.66669,15.99435,0.10145,1.77715,11.66669
1.42000,11.83331,16.23155,0.10290,1.80351,11.83331
1.44000,12.00000,16.27916,0.10435,1.80880,12.00000
1.46000,12.16669,16.35961,0.10580,1.81773,12.16669
1.48000,12.33337,16.35219,0.10725,1.81691,12.33337
1.50000,12.50006,16.40433,0.10870,1.82270,12.50006
1.52000,12.66662,16.62833,0.11014,1.84759,12.66662
1.54000,12.83325,16.63715,0.11159,1.84857,12.83325
1.56000,13.00000,16.73203,0.11304,1.85911,13.00000
1.58000,13.16669,16.84211,0.11449,1.87135,13.16669
1.60000,13.33331,16.72470,0.11594,1.85830,13.33331
1.62000,13.50000,16.66661,0.11739,1.85185,13.50000
1.64000,13.66656,16.88417,0.11884,1.87602,13.66656
1.66000,13.83325,17.23466,0.12029,1.91496,13.83325
1.68000,14.00000,17.05029,0.12174,1.89448,14.00000
1.70000,14.16669,17.20010,0.12319,1.91112,14.16669
1.72000,14.33337,17.14524,0.12464,1.90503,14.33337
1.74000,14.50006,16.94625,0.12609,1.88292,14.50006
1.76000,14.66669,17.15575,0.12754,1.90619,14.66669
1.78000,14.83337,17.30206,0.12899,1.92245,14.83337
1.80000,15.00012,17.32366,0.13044,1.92485,15.00012
1.82000,15.16675,17.28540,0.13188,1.92060,15.16675
1.84000,15.33337,17.34994,0.13333,1.92777,15.33337
1.86000,15.50000,17.41271,0.13478,1.93475,15.50000
1.88000,15.66662,17.57381,0.13623,1.95265,15.66662
1.90000,15.83337,17.46715,0.13768,1.94079,15.83337
1.92000,16.00006,17.50472,0.13913,1.94497,16.00006
1.94000,16.16669,17.76161,0.14058,1.97351,16.16669
1.96000,16.33331,17.78928,0.14203,1.97659,16.33331
1.98000,16.50000,17.82619,0.14348,1.98069,16.50000
2.00000,16.66668,17.91407,0.14493,1.99045,16.66668
2.02000,16.83343,17.82095,0.14638,1.98011,16.83343
2.04000,17.00012,17.72605,0.14783,1.96956,17.00012
2.06000,17.16662,17.89979,0.14927,1.98887,17.16662
2.08000,17.33319,17.91431,0.15072,1.99048,17.33319
2.10000,17.49987,17.90704,0.15217,1.98967,17.49987
2.12000,17.66669,18.04201,0.15362,2.00467,17.66669
2.14000,17.83337,18.17619,0.15507,2.01958,17.83337
2.16000,18.00000,18.21100,0.15652,2.02344,18.00000
2.18000,18.16662,18.37051,0.15797,2.04117,18.16662
2.20000,18.33331,18.37964,0.15942,2.04218,18.33331
2.22000,18.50000,18.38535,0.16087,2.04282,18.50000
2.24000,18.66668,18.54765,0.16232,2.06085,18.66668
2.26000,18.83331,18.42752,0.16377,2.04750,18.83331
2.28000,19.00000,18.34856,0.16522,2.03873,19.00000
2.30000,19.16662,18.44751,0.16667,2.04972,19.16662
2.32000,19.33337,18.46835,0.16812,2.05204,19.33337
2.34000,19.50006,18.34276,0.16957,2.03808,19.50006
2.36000,19.66675,18.51126,0.17102,2.05681,19.66675
2.38000,19.83337,18.65987,0.17246,2.07332,19.83337
2.40000,20.00006,18.69597,0.17391,2.07733,20.00006
2.42000,20.16675,18.77897,0.17536,2.08655,20.16675
2.44000,20.33337,18.85120,0.17681,2.09458,20.33337
2.46000,20.50000,18.70133,0.17826,2.07793,20.50000
2.48000,20.66668,18.81380,0.17971,2.09042,20.66668
2.50000,20.83331,18.76359,0.18116,2.08484,20.83331
2.52000,21.00000,18.73944,0.18261,2.08216,21.00000
2.54000,21.16668,18.92506,0.18406,2.10278,21.16668
2.56000,21.33337,18.95719,0.18551,2.10635,21.33337
2.58000,21.50000,18.91181,0.18696,2.10131,21.50000
2.60000,21.66662,19.01019,0.18841,2.11224,21.66662
2.62000,21.83325,19.08908,0.18985,2.12101,21.83325
2.64000,22.00000,18.86746,0.19130,2.09638,22.00000
2.66000,22.16668,18.89900,0.19275,2.09989,22.16668
2.68000,22.33337,18.98519,0.19420,2.10947,22.33337
2.70000,22.50000,18.86667,0.19565,2.09630,22.50000
2.72000,22.66662,19.09787,0.19710,2.12199,22.66662
2.74000,22.83325,19.13272,0.19855,2.12586,22.83325
2.76000,23.00000,19.11482,0.20000,2.12387,23.00000
2.78000,23.16668,19.19846,0.20145,2.13316,23.16668
2.80000,23.33331,19.03909,0.20290,2.11545,23.33331
2.82000,23.50000,18.86947,0.20435,2.09661,23.50000
2.84000,23.66662,18.98866,0.20580,2.10985,23.66662
2.86000,23.83331,19.16262,0.20725,2.12918,23.83331
2.88000,24.00006,19.18391,0.20870,2.13155,24.00006
2.90000,24.16675,19.28873,0.21015,2.14319,24.16675
2.92000,24.33331,19.34599,0.21159,2.14955,24.33331
2.94000,24.50000,19.26468,0.21304,2.14052,24.50000
2.96000,24.66675,19.35427,0.21449,2.15047,24.66675
2.98000,24.83343,19.35204,0.21594,2.15023,24.83343
3.00000,25.00006,19.43901,0.21739,2.15989,25.00006
3.02000,25.16668,19.56004,0.21884,2.17334,25.16668
3.04000,25.33331,19.49896,0.22029,2.16655,25.33331
3.06000,25.50006,19.45444,0.22174,2.16160,25.50006
3.08000,25.66668,19.54748,0.22319,2.17194,25.66668
3.10000,25.83331,19.54275,0.22464,2.17142,25.83331
3.12000,25.99993,19.45174,0.22609,2.16130,25.99993
3.14000,26.16662,19.71963,0.22754,2.19107,26.16662
3.16000,26.33331,19.81465,0.22899,2.20163,26.33331
3.18000,26.50000,19.68176,0.23043,2.18686,26.50000
3.20000,26.66668,19.56901,0.23188,2.17433,26.66668
3.22000,26.83331,19.72795,0.23333,2.19199,26.83331
3.24000,27.00000,19.69494,0.23478,2.18833,27.00000
3.26000,27.16662,19.80304,0.23623,2.20034,27.16662
3.28000,27.33331,19.80273,0.23768,2.20030,27.33331
3.30000,27.50000,19.68948,0.23913,2.18772,27.50000
3.32000,27.66668,19.78548,0.24058,2.19839,27.66668
3.34000,27.83331,20.00191,0.24203,2.22243,27.83331
3.36000,27.99993,19.98249,0.24348,2.22028,27.99993
3.38000,28.16662,20.06005,0.24493,2.22889,28.16662
3.40000,28.33331,20.08215,0.24638,2.23135,28.33331
3.42000,28.50000,20.14749,0.24783,2.23861,28.50000
3.44000,28.66668,20.11849,0.24928,2.23539,28.66668
3.46000,28.83331,20.00701,0.25072,2.22300,28.83331
3.48000,29.00000,19.79555,0.25217,2.19951,29.00000
3.50000,29.16669,20.15133,0.25362,2.23904,29.16669
3.52000,29.33337,20.13223,0.25507,2.23691,29.33337
3.54000,29.50006,20.04274,0.25652,2.22697,29.50006
3.56000,29.66668,20.22919,0.25797,2.24769,29.66668
3.58000,29.83331,20.24687,0.25942,2.24965,29.83331
3.60000,30.00000,20.09863,0.26087,2.23318,30.00000
3.62000,30.16675,20.21780,0.26232,2.24642,30.16675
3.64000,30.33337,20.12674,0.26377,2.23630,30.33337
3.66000,30.49999,19.96753,0.26522,2.21861,30.49999
3.68000,30.66662,20.23338,0.26667,2.24815,30.66662
3.70000,30.83331,20.39671,0.26812,2.26630,30.83331
3.72000,31.00006,20.40641,0.26957,2.26738,31.00006
3.74000,31.16668,20.39399,0.27101,2.26600,31.16668
3.76000,31.33331,20.46310,0.27246,2.27368,31.33331
3.78000,31.49993,20.35424,0.27391,2.26158,31.49993
3.80000,31.66662,20.55139,0.27536,2.28349,31.66662
3.82000,31.83331,20.67099,0.27681,2.29678,31.83331
3.84000,32.00006,20.74953,0.27826,2.30550,32.00006
3.86000,32.16668,20.67236,0.27971,2.29693,32.16668
3.88000,32.33331,20.48875,0.28116,2.27653,32.33331
3.90000,32.50000,20.47349,0.28261,2.27483,32.50000
3.92000,32.66668,20.78198,0.28406,2.30911,32.66668
3.94000,32.83337,20.78778,0.28551,2.30975,32.83337
3.96000,33.00000,20.62986,0.28696,2.29221,33.00000
3.98000,33.16656,20.68005,0.28840,2.29778,33.16656
4.00000,33.33325,20.67015,0.28985,2.29668,33.33325
4.02000,33.49999,20.65247,0.29130,2.29472,33.49999
4.04000,33.66668,20.69031,0.29275,2.29892,33.66668
4.06000,33.83343,20.81032,0.29420,2.31226,33.83343
4.08000,34.00012,20.76079,0.29565,2.30675,34.00012
4.10000,34.16662,20.98695,0.29710,2.33188,34.16662
4.12000,34.33324,20.94536,0.29855,2.32726,34.33324
4.14000,34.49999,20.73241,0.30000,2.30360,34.49999
4.16000,34.66668,20.94044,0.30145,2.32671,34.66668
4.18000,34.83337,21.09431,0.30290,2.34381,34.83337
4.20000,35.00006,20.93953,0.30435,2.32661,35.00006
4.22000,35.16668,21.08263,0.30580,2.34251,35.16668
4.24000,35.33331,21.05873,0.30725,2.33986,35.33331
4.26000,35.50006,20.99821,0.30870,2.33313,35.50006
4.28000,35.66675,21.19999,0.31015,2.35555,35.66675
4.30000,35.83337,21.19203,0.31159,2.35467,35.83337
4.32000,35.99999,21.17423,0.31304,2.35269,35.99999
4.34000,36.16668,21.26521,0.31449,2.36280,36.16668
4.36000,36.33331,21.20489,0.31594,2.35610,36.33331
4.38000,36.50006,21.02214,0.31739,2.33579,36.50006
4.40000,36.66668,21.22039,0.31884,2.35782,36.66668
4.42000,36.83331,21.45316,0.32029,2.38368,36.83331
4.44000,36.99999,21.38997,0.32174,2.37666,36.99999
4.46000,37.16668,21.45602,0.32319,2.38400,37.16668
4.48000,37.33337,21.46016,0.32464,2.38446,37.33337
4.50000,37.50006,21.40124,0.32609,2.37792,37.50006
4.52000,37.66668,21.33852,0.32754,2.37095,37.66668
4.54000,37.83325,21.32443,0.32898,2.36938,37.83325
4.56000,37.99993,21.38573,0.33043,2.37619,37.99993
4.58000,38.16668,21.53778,0.33188,2.39309,38.16668
4.60000,38.33337,21.72021,0.33333,2.41336,38.33337
4.62000,38.50000,21.56932,0.33478,2.39659,38.50000
4.64000,38.66662,21.66332,0.33623,2.40704,38.66662
4.66000,38.83325,21.68240,0.33768,2.40916,38.83325
4.68000,38.99999,21.63341,0.33913,2.40371,38.99999
4.70000,39.16674,21.69976,0.34058,2.41108,39.16674
4.72000,39.33337,21.73963,0.34203,2.41551,39.33337
4.74000,39.49999,21.79929,0.34348,2.42214,39.49999
4.76000,39.66662,21.94903,0.34493,2.43878,39.66662
4.78000,39.83337,21.99811,0.34638,2.44423,39.83337
4.80000,40.00005,21.92121,0.34783,2.43569,40.00005
4.82000,40.16674,22.04910,0.34928,2.44990,40.16674
4.84000,40.33337,22.00585,0.35072,2.44509,40.33337
4.86000,40.49999,21.81450,0.35217,2.42383,40.49999
4.88000,40.66668,22.02615,0.35362,2.44735,40.66668
4.90000,40.83337,22.01173,0.35507,2.44575,40.83337
4.92000,41.00006,21.79721,0.35652,2.42191,41.00006
4.94000,41.16668,21.92792,0.35797,2.43644,41.16668
4.96000,41.33331,21.94198,0.35942,2.43800,41.33331
4.98000,41.49999,21.86407,0.36087,2.42934,41.49999
5.00000,41.66662,22.01249,0.36232,2.44583,41.66662
5.02000,41.83331,22.35933,0.36377,2.48437,41.83331
5.04000,41.99999,22.15723,0.36522,2.46191,41.99999
5.06000,42.16668,22.29869,0.36667,2.47763,42.16668
5.08000,42.33331,22.30183,0.36812,2.47798,42.33331
5.10000,42.49999,22.26551,0.36957,2.47395,42.49999
5.12000,42.66662,22.43675,0.37101,2.49297,42.66662
5.14000,42.83324,22.58494,0.37246,2.50944,42.83324
5.16000,42.99993,22.50995,0.37391,2.50111,42.99993
5.18000,43.16655,22.48524,0.37536,2.49836,43.16655
5.20000,43.33324,22.42041,0.37681,2.49116,43.33324
5.22000,43.50006,22.42509,0.37826,2.49168,43.50006
5.24000,43.66674,22.47162,0.37971,2.49685,43.66674
5.26000,43.83337,22.52710,0.38116,2.50301,43.83337
5.28000,44.00000,22.58247,0.38261,2.50916,44.00000
5.30000,44.16662,22.61962,0.38406,2.51329,44.16662
5.32000,44.33331,22.54353,0.38551,2.50484,44.33331
5.34000,44.50012,22.59273,0.38696,2.51030,44.50012
5.36000,44.66674,22.81724,0.38841,2.53525,44.66674
5.38000,44.83331,22.73777,0.38985,2.52642,44.83331
5.40000,44.99999,22.64997,0.39130,2.51666,44.99999
5.42000,45.16668,22.84188,0.39275,2.53799,45.16668
5.44000,45.33337,22.89052,0.39420,2.54339,45.33337
5.46000,45.50005,22.76966,0.39565,2.52996,45.50005
5.48000,45.66668,22.83737,0.39710,2.53749,45.66668
5.50000,45.83324,22.92187,0.39855,2.54687,45.83324
5.52000,45.99999,22.97727,0.40000,2.55303,45.99999
5.54000,46.16668,23.05221,0.40145,2.56136,46.16668
5.56000,46.33337,23.17398,0.40290,2.57489,46.33337
5.58000,46.49999,23.18990,0.40435,2.57666,46.49999
5.60000,46.66662,23.18397,0.40580,2.57600,46.66662
5.62000,46.83331,23.15086,0.40725,2.57232,46.83331
5.64000,46.99999,23.11638,0.40870,2.56849,46.99999
5.66000,47.16674,23.28034,0.41015,2.58670,47.16674
5.68000,47.33337,23.25061,0.41159,2.58340,47.33337
5.70000,47.49999,23.16710,0.41304,2.57412,47.49999
5.72000,47.66662,23.38722,0.41449,2.59858,47.66662
5.74000,47.83330,23.35311,0.41594,2.59479,47.83330
5.76000,47.99999,23.33832,0.41739,2.59315,47.99999
5.78000,48.16668,23.39741,0.41884,2.59971,48.16668
5.80000,48.33330,23.29986,0.42029,2.58887,48.33330
5.82000,48.49993,23.34914,0.42174,2.59435,48.49993
5.84000,48.66662,23.52984,0.42319,2.61443,48.66662
5.86000,48.83337,23.61876,0.42464,2.62431,48.83337
5.88000,49.00006,23.64465,0.42609,2.62718,49.00006
5.90000,49.16668,23.79458,0.42754,2.64384,49.16668
5.92000,49.33337,23.78092,0.42899,2.64232,49.33337
5.94000,49.50006,23.74575,0.43044,2.63842,49.50006
5.96000,49.66674,23.77369,0.43188,2.64152,49.66674
5.98000,49.83343,23.66552,0.43333,2.62950,49.83343
6.00000,50.00005,23.65021,0.43478,2.62780,50.00005
6.02000,50.16668,23.82917,0.43623,2.64769,50.16668
6.04000,50.33324,23.72123,0.43768,2.63569,50.33324
6.06000,50.49999,23.68335,0.43913,2.63148,50.49999
6.08000,50.66668,23.84952,0.44058,2.64995,50.66668
6.10000,50.83343,23.96639,0.44203,2.66293,50.83343
6.12000,51.00005,23.94783,0.44348,2.66087,51.00005
6.14000,51.16655,24.13411,0.44493,2.68157,51.16655
6.16000,51.33324,24.07582,0.44638,2.67509,51.33324
6.18000,51.49993,23.83659,0.44783,2.64851,51.49993
6.20000,51.66668,24.00663,0.44928,2.66740,51.66668
6.22000,51.83337,24.00658,0.45072,2.66740,51.83337
6.24000,51.99999,24.01814,0.45217,2.66868,51.99999
6.26000,52.16662,24.34044,0.45362,2.70449,52.16662
6.28000,52.33331,24.49983,0.45507,2.72220,52.33331
6.30000,52.50006,24.28299,0.45652,2.69811,52.50006
6.32000,52.66668,24.39236,0.45797,2.71026,52.66668
6.34000,52.83331,24.54075,0.45942,2.72675,52.83331
6.36000,52.99993,24.40209,0.46087,2.71134,52.99993
6.38000,53.16656,24.54222,0.46232,2.72691,53.16656
6.40000,53.33330,24.48104,0.46377,2.72012,53.33330
6.42000,53.50005,24.43415,0.46522,2.71491,53.50005
6.44000,53.66668,24.59508,0.46667,2.73279,53.66668
6.46000,53.83330,24.66934,0.46812,2.74104,53.83330
6.48000,53.99999,24.59922,0.46957,2.73325,53.99999
6.50000,54.16675,24.85373,0.47102,2.76153,54.16675
6.52000,54.33343,25.00545,0.47246,2.77838,54.33343
6.54000,54.50006,24.70384,0.47391,2.74487,54.50006
6.56000,54.66668,24.77577,0.47536,2.75286,54.66668
6.58000,54.83331,24.83639,0.47681,2.75960,54.83331
6.60000,55.00006,24.88620,0.47826,2.76513,55.00006
6.62000,55.16674,25.04772,0.47971,2.78308,55.16674
6.64000,55.33337,24.91760,0.48116,2.76862,55.33337
6.66000,55.49999,24.82204,0.48261,2.75800,55.49999
6.68000,55.66662,25.03511,0.48406,2.78168,55.66662
6.70000,55.83331,25.12553,0.48551,2.79173,55.83331
6.72000,56.00005,25.01831,0.48696,2.77981,56.00005
6.74000,56.16674,25.05759,0.48841,2.78418,56.16674
6.76000,56.33337,25.11941,0.48986,2.79105,56.33337
6.78000,56.49999,25.18970,0.49130,2.79886,56.49999
6.80000,56.66662,25.54029,0.49275,2.83781,56.66662
6.82000,56.83324,25.58983,0.49420,2.84331,56.83324
6.84000,56.99999,25.34588,0.49565,2.81621,56.99999
6.86000,57.16674,25.35959,0.49710,2.81773,57.16674
6.88000,57.33337,25.43649,0.49855,2.82628,57.33337
6.90000,57.49999,25.25230,0.50000,2.80581,57.49999
6.92000,57.66662,25.46415,0.50145,2.82935,57.66662
6.94000,57.83337,25.41869,0.50290,2.82430,57.83337
6.96000,58.00006,25.43735,0.50435,2.82637,58.00006
6.98000,58.16668,25.53877,0.50580,2.83764,58.16668
7.00000,58.33324,25.63203,0.50725,2.84800,58.33324
7.02000,58.49999,25.74344,0.50870,2.86038,58.49999
7.04000,58.66662,25.92607,0.51014,2.88067,58.66662
7.06000,58.83337,25.82395,0.51159,2.86933,58.83337
7.08000,59.00005,25.69635,0.51304,2.85515,59.00005
7.10000,59.16668,25.94302,0.51449,2.88256,59.16668
7.12000,59.33337,26.07466,0.51594,2.89718,59.33337
7.14000,59.50006,26.06464,0.51739,2.89607,59.50006
7.16000,59.66675,26.11735,0.51884,2.90193,59.66675
7.18000,59.83330,26.20559,0.52029,2.91173,59.83330
7.20000,59.99999,25.99778,0.52174,2.88864,59.99999
7.22000,60.16655,26.03662,0.52319,2.89296,60.16655
7.24000,60.33331,26.19430,0.52464,2.91048,60.33331
7.26000,60.50006,26.30801,0.52609,2.92311,60.50006
7.28000,60.66674,26.41369,0.52754,2.93485,60.66674
7.30000,60.83337,26.36118,0.52899,2.92902,60.83337
7.32000,60.99999,26.36983,0.53043,2.92998,60.99999
7.34000,61.16662,26.50651,0.53188,2.94517,61.16662
7.36000,61.33331,26.47820,0.53333,2.94202,61.33331
7.38000,61.49999,26.43671,0.53478,2.93741,61.49999
7.40000,61.66662,26.53287,0.53623,2.94810,61.66662
7.42000,61.83324,26.52807,0.53768,2.94756,61.83324
7.44000,61.99993,26.56600,0.53913,2.95178,61.99993
7.46000,62.16668,26.68290,0.54058,2.96477,62.16668
7.48000,62.33336,26.71410,0.54203,2.96823,62.33336
7.50000,62.50005,26.64915,0.54348,2.96102,62.50005
7.52000,62.66668,26.73619,0.54493,2.97069,62.66668
7.54000,62.83330,26.81642,0.54638,2.97960,62.83330
7.56000,62.99999,26.66291,0.54783,2.96255,62.99999
7.58000,63.16661,26.93031,0.54927,2.99226,63.16661
7.60000,63.33330,27.00170,0.55072,3.00019,63.33330
7.62000,63.49999,26.98292,0.55217,2.99810,63.49999
7.64000,63.66661,27.06170,0.55362,3.00686,63.66661
7.66000,63.83331,27.16601,0.55507,3.01845,63.83331
7.68000,63.99999,26.95734,0.55652,2.99526,63.99999
7.70000,64.16674,27.01965,0.55797,3.00218,64.16674
7.72000,64.33337,27.08286,0.55942,3.00921,64.33337
7.74000,64.49999,27.12800,0.56087,3.01422,64.49999
7.76000,64.66668,27.34994,0.56232,3.03888,64.66668
7.78000,64.83336,27.26234,0.56377,3.02915,64.83336
7.80000,65.00005,27.18105,0.56522,3.02012,65.00005
7.82000,65.16674,27.48077,0.56667,3.05342,65.16674
7.84000,65.33330,27.56083,0.56812,3.06231,65.33330
7.86000,65.49999,27.47847,0.56957,3.05316,65.49999
7.88000,65.66667,27.69066,0.57101,3.07674,65.66667
7.90000,65.83336,27.72690,0.57246,3.08077,65.83336
7.92000,66.00005,27.70291,0.57391,3.07810,66.00005
7.94000,66.16668,27.75336,0.57536,3.08371,66.16668
7.96000,66.33330,27.65167,0.57681,3.07241,66.33330
7.98000,66.49993,27.64476,0.57826,3.07164,66.49993
8.00000,66.66661,27.92369,0.57971,3.10263,66.66661
8.02000,66.83331,28.07260,0.58116,3.11918,66.83331
8.04000,66.99999,28.02283,0.58261,3.11365,66.99999
8.06000,67.16661,27.95191,0.58406,3.10577,67.16661
8.08000,67.33324,28.10919,0.58551,3.12324,67.33324
8.10000,67.49999,28.16033,0.58696,3.12893,67.49999
8.12000,67.66674,28.28276,0.58841,3.14253,67.66674
8.14000,67.83342,28.36958,0.58986,3.15218,67.83342
8.16000,67.99999,28.20027,0.59130,3.13336,67.99999
8.18000,68.16655,28.26556,0.59275,3.14062,68.16655
8.20000,68.33324,28.17132,0.59420,3.13015,68.33324
8.22000,68.49999,28.15859,0.59565,3.12873,68.49999
8.24000,68.66667,28.40916,0.59710,3.15657,68.66667
8.26000,68.83337,28.57276,0.59855,3.17475,68.83337
8.28000,69.00005,28.44680,0.60000,3.16076,69.00005
8.30000,69.16668,28.70261,0.60145,3.18918,69.16668
8.32000,69.33337,28.66026,0.60290,3.18447,69.33337
8.34000,69.50011,28.57898,0.60435,3.17544,69.50011
8.36000,69.66674,28.81507,0.60580,3.20167,69.66674
8.38000,69.83330,28.94243,0.60725,3.21583,69.83330
8.40000,69.99999,28.76102,0.60870,3.19567,69.99999
8.42000,70.16668,28.74331,0.61015,3.19370,70.16668
8.44000,70.33330,28.73545,0.61159,3.19283,70.33330
8.46000,70.49999,28.77603,0.61304,3.19734,70.49999
8.48000,70.66668,28.89530,0.61449,3.21059,70.66668
8.50000,70.83330,28.85825,0.61594,3.20647,70.83330
8.52000,70.99999,28.82646,0.61739,3.20294,70.99999
8.54000,71.16668,28.96599,0.61884,3.21844,71.16668
8.56000,71.33336,29.05214,0.62029,3.22802,71.33336
8.58000,71.49999,28.99388,0.62174,3.22154,71.49999
8.60000,71.66661,29.08626,0.62319,3.23181,71.66661
8.62000,71.83324,29.08011,0.62464,3.23112,71.83324
8.64000,71.99999,29.01568,0.62609,3.22396,71.99999
8.66000,72.16667,29.27068,0.62754,3.25230,72.16667
8.68000,72.33337,29.41508,0.62899,3.26834,72.33337
8.70000,72.49999,29.42963,0.63043,3.26996,72.49999
8.72000,72.66662,29.37800,0.63188,3.26422,72.66662
8.74000,72.83324,29.37496,0.63333,3.26389,72.83324
8.76000,72.99999,29.44084,0.63478,3.27120,72.99999
8.78000,73.16668,29.54447,0.63623,3.28272,73.16668
8.80000,73.33330,29.69820,0.63768,3.29980,73.33330
8.82000,73.49993,29.76594,0.63913,3.30733,73.49993
8.84000,73.66655,29.85999,0.64058,3.31778,73.66655
8.86000,73.83330,29.93728,0.64203,3.32636,73.83330
8.88000,74.00006,29.93008,0.64348,3.32556,74.00006
8.90000,74.16674,30.03882,0.64493,3.33765,74.16674
8.92000,74.33336,30.03272,0.64638,3.33697,74.33336
8.94000,74.49999,29.95063,0.64783,3.32785,74.49999
8.96000,74.66674,29.99640,0.64928,3.33293,74.66674
8.98000,74.83342,30.01154,0.65073,3.33462,74.83342
9.00000,75.00011,30.11337,0.65217,3.34593,75.00011
9.02000,75.16667,30.16368,0.65362,3.35152,75.16667
9.04000,75.33324,30.11134,0.65507,3.34570,75.33324
9.06000,75.49999,30.16022,0.65652,3.35114,75.49999
9.08000,75.66668,30.36264,0.65797,3.37363,75.66668
9.10000,75.83336,30.45948,0.65942,3.38439,75.83336
9.12000,76.00005,30.29666,0.66087,3.36630,76.00005
9.14000,76.16668,30.39157,0.66232,3.37684,76.16668
9.16000,76.33337,30.52744,0.66377,3.39194,76.33337
9.18000,76.50005,30.44682,0.66522,3.38298,76.50005
9.20000,76.66662,30.41909,0.66667,3.37990,76.66662
9.22000,76.83324,30.52962,0.66812,3.39218,76.83324
9.24000,76.99993,30.56129,0.66956,3.39570,76.99993
9.26000,77.16662,30.83885,0.67101,3.42654,77.16662
9.28000,77.33336,30.93368,0.67246,3.43708,77.33336
9.30000,77.50005,30.87079,0.67391,3.43009,77.50005
9.32000,77.66668,30.95751,0.67536,3.43972,77.66668
9.34000,77.83331,30.98849,0.67681,3.44317,77.83331
9.36000,77.99999,30.89971,0.67826,3.43330,77.99999
9.38000,78.16661,31.11604,0.67971,3.45734,78.16661
9.40000,78.33330,31.21072,0.68116,3.46786,78.33330
9.42000,78.49999,31.19328,0.68261,3.46592,78.49999
9.44000,78.66668,31.20210,0.68406,3.46690,78.66668
9.46000,78.83330,31.19343,0.68551,3.46594,78.83330
9.48000,78.99993,31.26323,0.68696,3.47369,78.99993
9.50000,79.16661,31.49242,0.68841,3.49916,79.16661
9.52000,79.33336,31.51260,0.68986,3.50140,79.33336
9.54000,79.50012,31.48154,0.69131,3.49795,79.50012
9.56000,79.66667,31.52631,0.69275,3.50292,79.66667
9.58000,79.83330,31.47973,0.69420,3.49775,79.83330
9.60000,79.99999,31.51686,0.69565,3.50187,79.99999
9.62000,80.16667,31.75864,0.69710,3.52874,80.16667
9.64000,80.33336,31.74938,0.69855,3.52771,80.33336
9.66000,80.49999,31.64818,0.70000,3.51646,80.49999
9.68000,80.66662,31.84612,0.70145,3.53846,80.66662
9.70000,80.83330,31.84685,0.70290,3.53854,80.83330
9.72000,81.00005,31.83084,0.70435,3.53676,81.00005
9.74000,81.16667,32.10553,0.70580,3.56728,81.16667
9.76000,81.33330,32.00840,0.70725,3.55649,81.33330
9.78000,81.49993,31.91974,0.70869,3.54664,81.49993
9.80000,81.66661,31.94408,0.71014,3.54934,81.66661
9.82000,81.83330,32.04166,0.71159,3.56018,81.83330
9.84000,81.99998,32.16847,0.71304,3.57427,81.99998
9.86000,82.16668,32.27898,0.71449,3.58655,82.16668
9.88000,82.33324,32.17739,0.71594,3.57527,82.33324
9.90000,82.49993,32.26100,0.71739,3.58456,82.49993
9.92000,82.66667,32.57213,0.71884,3.61913,82.66667
9.94000,82.83337,32.50601,0.72029,3.61178,82.83337
9.96000,83.00005,32.38341,0.72174,3.59816,83.00005
9.98000,83.16667,32.61529,0.72319,3.62392,83.16667
10.00000,83.33330,32.79339,0.72464,3.64371,83.33330
10.02000,83.49992,32.70889,0.72609,3.63432,83.49992
10.04000,83.66668,32.64850,0.72754,3.62761,83.66668
10.06000,83.83336,32.63483,0.72899,3.62609,83.83336
10.08000,83.99999,32.74676,0.73043,3.63853,83.99999
10.10000,84.16661,32.81293,0.73188,3.64588,84.16661
10.12000,84.33330,33.07367,0.73333,3.67485,84.33330
10.14000,84.50005,33.17026,0.73478,3.68558,84.50005
10.16000,84.66673,33.17090,0.73623,3.68566,84.66673
10.18000,84.83343,33.11907,0.73768,3.67990,84.83343
10.20000,85.00005,32.92545,0.73913,3.65838,85.00005
10.22000,85.16655,33.11442,0.74058,3.67938,85.16655
10.24000,85.33323,33.01758,0.74203,3.66862,85.33323
10.26000,85.49999,33.13685,0.74348,3.68187,85.49999
10.28000,85.66667,33.30849,0.74493,3.70094,85.66667
10.30000,85.83336,33.31157,0.74638,3.70129,85.83336
10.32000,85.99998,33.28120,0.74783,3.69791,85.99998
10.34000,86.16667,33.40880,0.74928,3.71209,86.16667
10.36000,86.33336,33.45685,0.75072,3.71743,86.33336
10.38000,86.50005,33.47429,0.75217,3.71937,86.50005
10.40000,86.66667,33.54816,0.75362,3.72757,86.66667
10.42000,86.83324,33.62712,0.75507,3.73635,86.83324
10.44000,86.99992,33.62393,0.75652,3.73599,86.99992
10.46000,87.16661,33.70637,0.75797,3.74515,87.16661
10.48000,87.33337,33.73248,0.75942,3.74805,87.33337
10.50000,87.50005,33.65171,0.76087,3.73908,87.50005
10.52000,87.66667,33.87364,0.76232,3.76374,87.66667
10.54000,87.83330,34.03719,0.76377,3.78191,87.83330
10.56000,87.99999,34.09534,0.76522,3.78837,87.99999
10.58000,88.16668,34.03837,0.76667,3.78204,88.16668
10.60000,88.33330,33.93864,0.76812,3.77096,88.33330
10.62000,88.49998,34.02715,0.76957,3.78079,88.49998
10.64000,88.66655,34.30591,0.77101,3.81177,88.66655
10.66000,88.83324,34.37752,0.77246,3.81972,88.83324
10.68000,88.99999,34.36371,0.77391,3.81819,88.99999
10.70000,89.16673,34.57752,0.77536,3.84195,89.16673
10.72000,89.33342,34.57443,0.77681,3.84160,89.33342
10.74000,89.50005,34.49322,0.77826,3.83258,89.50005
10.76000,89.66668,34.52604,0.77971,3.83623,89.66668
10.78000,89.83336,34.65129,0.78116,3.85014,89.83336
10.80000,90.00004,34.65574,0.78261,3.85064,90.00004
10.82000,90.16667,34.90168,0.78406,3.87796,90.16667
10.84000,90.33330,34.72197,0.78551,3.85800,90.33330
10.86000,90.49992,34.58305,0.78696,3.84256,90.49992
10.88000,90.66661,34.89801,0.78841,3.87756,90.66661
10.90000,90.83336,34.98789,0.78986,3.88754,90.83336
10.92000,91.00011,34.87881,0.79131,3.87542,91.00011
10.94000,91.16674,35.11579,0.79275,3.90175,91.16674
10.96000,91.33330,35.13308,0.79420,3.90368,91.33330
10.98000,91.49999,35.22022,0.79565,3.91336,91.49999
11.00000,91.66667,35.38940,0.79710,3.93216,91.66667
11.02000,91.83336,35.30064,0.79855,3.92229,91.83336
11.04000,91.99998,35.22017,0.80000,3.91335,91.99998
11.06000,92.16661,35.35986,0.80145,3.92887,92.16661
11.08000,92.33324,35.50911,0.80290,3.94546,92.33324
11.10000,92.49998,35.56094,0.80435,3.95122,92.49998
11.12000,92.66668,35.77347,0.80580,3.97483,92.66668
11.14000,92.83336,35.66840,0.80725,3.96316,92.83336
11.16000,92.99998,35.61555,0.80870,3.95728,92.99998
11.18000,93.16668,35.67781,0.81015,3.96420,93.16668
11.20000,93.33336,35.71768,0.81159,3.96863,93.33336
11.22000,93.49999,35.83798,0.81304,3.98200,93.49999
11.24000,93.66661,35.92027,0.81449,3.99114,93.66661
11.26000,93.83324,35.91390,0.81594,3.99043,93.83324
11.28000,93.99999,35.87805,0.81739,3.98645,93.99999
11.30000,94.16661,36.13163,0.81884,4.01463,94.16661
11.32000,94.33337,36.01681,0.82029,4.00187,94.33337
11.34000,94.50011,36.03126,0.82174,4.00347,94.50011
11.36000,94.66674,36.19643,0.82319,4.02183,94.66674
11.38000,94.83336,36.14995,0.82464,4.01666,94.83336
11.40000,94.99999,36.06408,0.82609,4.00712,94.99999
11.42000,95.16661,36.26045,0.82754,4.02894,95.16661
11.44000,95.33330,36.33750,0.82899,4.03750,95.33330
11.46000,95.50005,36.43208,0.83044,4.04801,95.50005
11.48000,95.66667,36.50634,0.83188,4.05626,95.66667
11.50000,95.83330,36.63414,0.83333,4.07046,95.83330
11.52000,95.99999,36.63433,0.83478,4.07048,95.99999
11.54000,96.16667,36.57947,0.83623,4.06439,96.16667
11.56000,96.33343,36.64864,0.83768,4.07207,96.33343
11.58000,96.50005,36.75101,0.83913,4.08345,96.50005
11.60000,96.66661,36.84858,0.84058,4.09429,96.66661
11.62000,96.83323,36.94606,0.84203,4.10512,96.83323
11.64000,96.99998,36.82296,0.84348,4.09144,96.99998
11.66000,97.16667,36.95982,0.84493,4.10665,97.16667
11.68000,97.33336,36.93729,0.84638,4.10414,97.33336
11.70000,97.49998,37.10731,0.84783,4.12303,97.49998
11.72000,97.66667,37.32606,0.84928,4.14734,97.66667
11.74000,97.83336,37.34183,0.85072,4.14909,97.83336
11.76000,98.00005,37.11230,0.85217,4.12359,98.00005
11.78000,98.16667,37.20562,0.85362,4.13396,98.16667
11.80000,98.33324,37.33062,0.85507,4.14785,98.33324
11.82000,98.49992,37.31930,0.85652,4.14659,98.49992
11.84000,98.66661,37.55535,0.85797,4.17282,98.66661
11.86000,98.83337,37.65649,0.85942,4.18405,98.83337
11.88000,99.00005,37.51430,0.86087,4.16826,99.00005
11.90000,99.16667,37.60624,0.86232,4.17847,99.16667
11.92000,99.33336,37.70019,0.86377,4.18891,99.33336
11.94000,99.50005,37.71376,0.86522,4.19042,99.50005
11.96000,99.66673,37.94770,0.86667,4.21641,99.66673
11.98000,99.83342,38.01451,0.86812,4.22383,99.83342
12.00000,100.00011,37.96944,0.86957,4.21883,100.00011
12.02000,100.16668,38.03101,0.87101,4.22567,100.16668
12.04000,100.33330,38.09474,0.87246,4.23275,100.33330
12.06000,100.49999,38.07128,0.87391,4.23014,100.49999
12.08000,100.66668,38.13212,0.87536,4.23690,100.66668
12.10000,100.83336,38.12570,0.87681,4.23619,100.83336
12.12000,101.00004,38.19300,0.87826,4.24367,101.00004
12.14000,101.16667,38.44193,0.87971,4.27133,101.16667
12.16000,101.33330,38.25393,0.88116,4.25044,101.33330
12.18000,101.49999,38.26824,0.88261,4.25203,101.49999
12.20000,101.66674,38.47039,0.88406,4.27449,101.66674
12.22000,101.83336,38.53220,0.88551,4.28136,101.83336
12.24000,101.99999,38.60558,0.88696,4.28951,101.99999
12.26000,102.16654,38.71113,0.88840,4.30124,102.16654
12.28000,102.33324,38.58549,0.88985,4.28728,102.33324
12.30000,102.50005,38.64192,0.89130,4.29355,102.50005
12.32000,102.66673,38.82565,0.89275,4.31396,102.66673
12.34000,102.83330,38.94821,0.89420,4.32758,102.83330
12.36000,102.99992,38.91167,0.89565,4.32352,102.99992
12.38000,103.16661,38.90452,0.89710,4.32272,103.16661
12.40000,103.33329,38.96467,0.89855,4.32941,103.33329
12.42000,103.50005,38.93959,0.90000,4.32662,103.50005
12.44000,103.66667,39.06567,0.90145,4.34063,103.66667
12.46000,103.83323,39.25577,0.90290,4.36175,103.83323
12.48000,103.99998,39.29540,0.90435,4.36616,103.99998
12.50000,104.16668,39.42632,0.90580,4.38070,104.16668
12.52000,104.33336,39.47869,0.90725,4.38652,104.33336
12.54000,104.50005,39.38660,0.90870,4.37629,104.50005
12.56000,104.66667,39.49852,0.91014,4.38872,104.66667
12.58000,104.83329,39.59374,0.91159,4.39930,104.83329
12.60000,104.99999,39.53457,0.91304,4.39273,104.99999
12.62000,105.16673,39.65248,0.91449,4.40583,105.16673
12.64000,105.33337,39.74133,0.91594,4.41570,105.33337
12.66000,105.49999,39.77160,0.91739,4.41907,105.49999
12.68000,105.66667,39.76112,0.91884,4.41790,105.66667
12.70000,105.83336,39.71650,0.92029,4.41294,105.83336
12.72000,106.00004,39.76714,0.92174,4.41857,106.00004
12.74000,106.16673,39.93084,0.92319,4.43676,106.16673
12.76000,106.33335,40.03713,0.92464,4.44857,106.33335
12.78000,106.49998,39.88891,0.92609,4.43210,106.49998
12.80000,106.66661,39.97003,0.92754,4.44111,106.66661
12.82000,106.83330,40.05932,0.92899,4.45104,106.83330
12.84000,107.00005,40.09993,0.93044,4.45555,107.00005
12.86000,107.16667,40.36193,0.93188,4.48466,107.16667
12.88000,107.33330,40.41621,0.93333,4.49069,107.33330
12.90000,107.49999,40.37971,0.93478,4.48663,107.49999
12.92000,107.66661,40.62713,0.93623,4.51412,107.66661
12.94000,107.83330,40.46553,0.93768,4.49617,107.83330
12.96000,108.00004,40.29698,0.93913,4.47744,108.00004
12.98000,108.16667,40.80395,0.94058,4.53377,108.16667
13.00000,108.33323,40.88531,0.94203,4.54281,108.33323
13.02000,108.49998,40.83040,0.94348,4.53671,108.49998
13.04000,108.66667,40.71372,0.94493,4.52375,108.66667
13.06000,108.83336,40.63472,0.94638,4.51497,108.83336
13.08000,108.99998,40.65583,0.94783,4.51731,108.99998
13.10000,109.16661,40.88031,0.94927,4.54226,109.16661
13.12000,109.33324,40.92660,0.95072,4.54740,109.33324
13.14000,109.49999,40.81767,0.95217,4.53530,109.49999
13.16000,109.66673,41.03284,0.95362,4.55921,109.66673
13.18000,109.83342,41.08908,0.95507,4.56545,109.83342
13.20000,110.00005,41.06385,0.95652,4.56265,110.00005
13.22000,110.16667,41.45899,0.95797,4.60655,110.16667
13.24000,110.33336,41.61387,0.95942,4.62376,110.33336
13.26000,110.49998,41.38385,0.96087,4.59821,110.49998
13.28000,110.66668,41.38934,0.96232,4.59882,110.66668
13.30000,110.83330,41.45223,0.96377,4.60580,110.83330
13.32000,110.99998,41.39335,0.96522,4.59926,110.99998
13.34000,111.16661,41.61897,0.96667,4.62433,111.16661
13.36000,111.33336,41.72389,0.96812,4.63599,111.33336
13.38000,111.50005,41.79520,0.96957,4.64391,111.50005
13.40000,111.66668,41.96067,0.97101,4.66230,111.66668
13.42000,111.83323,42.04810,0.97246,4.67201,111.83323
13.44000,111.99999,41.90933,0.97391,4.65659,111.99999
13.46000,112.16667,42.05462,0.97536,4.67274,112.16667
13.48000,112.33336,42.11491,0.97681,4.67943,112.33336
13.50000,112.49999,42.05177,0.97826,4.67242,112.49999
13.52000,112.66661,42.00304,0.97971,4.66700,112.66661
13.54000,112.83323,41.85535,0.98116,4.65059,112.83323
13.56000,112.99998,42.03189,0.98261,4.67021,112.99998
13.58000,113.16667,42.40881,0.98406,4.71209,113.16667
13.60000,113.33336,42.37217,0.98551,4.70802,113.33336
13.62000,113.49998,42.32632,0.98696,4.70292,113.49998
13.64000,113.66662,42.59734,0.98841,4.73304,113.66662
13.66000,113.83330,42.55864,0.98985,4.72874,113.83330
13.68000,113.99998,42.43604,0.99130,4.71512,113.99998
13.70000,114.16667,42.50932,0.99275,4.72326,114.16667
13.72000,114.33336,42.62913,0.99420,4.73657,114.33336
13.74000,114.50005,42.51544,0.99565,4.72394,114.50005
13.76000,114.66667,42.68898,0.99710,4.74322,114.66667
13.78000,114.83336,43.03524,0.99855,4.78169,114.83336
13.80000,115.00005,42.91435,1.00000,4.76826,115.00005
13.82000,115.16673,42.95848,1.00145,4.77316,115.16673
13.84000,115.33330,43.01114,1.00290,4.77902,115.33330
13.86000,115.49998,42.89775,1.00435,4.76642,115.49998
13.88000,115.66667,42.91484,1.00580,4.76832,115.66667
13.90000,115.83336,42.96901,1.00725,4.77433,115.83336
13.92000,116.00011,43.14677,1.00870,4.79409,116.00011
13.94000,116.16667,43.29372,1.01014,4.81041,116.16667
13.96000,116.33329,43.27741,1.01159,4.80860,116.33329
13.98000,116.49999,43.17513,1.01304,4.79724,116.49999
14.00000,116.66667,43.35387,1.01449,4.81710,116.66667
14.02000,116.83342,43.45560,1.01594,4.82840,116.83342
14.04000,117.00004,43.53853,1.01739,4.83761,117.00004
14.06000,117.16668,43.73319,1.01884,4.85924,117.16668
14.08000,117.33330,43.69376,1.02029,4.85486,117.33330
14.10000,117.49999,43.64139,1.02174,4.84904,117.49999
14.12000,117.66667,43.96017,1.02319,4.88446,117.66667
14.14000,117.83335,44.08934,1.02464,4.89882,117.83335
14.16000,117.99999,43.89885,1.02609,4.87765,117.99999
14.18000,118.16661,44.05216,1.02754,4.89468,118.16661
14.20000,118.33323,44.03002,1.02898,4.89222,118.33323
14.22000,118.49998,43.90159,1.03043,4.87795,118.49998
14.24000,118.66674,44.07695,1.03188,4.89744,118.66674
14.26000,118.83336,44.19152,1.03333,4.91017,118.83336
14.28000,118.99993,44.13803,1.03478,4.90423,118.99993
14.30000,119.16655,44.24476,1.03623,4.91608,119.16655
14.32000,119.33330,44.26548,1.03768,4.91839,119.33330
14.34000,119.50005,44.31769,1.03913,4.92419,119.50005
14.36000,119.66674,44.45710,1.04058,4.93968,119.66674
14.38000,119.83336,44.49241,1.04203,4.94360,119.83336
14.40000,119.99998,44.23829,1.04348,4.91537,119.99998
14.42000,120.16667,44.51372,1.04493,4.94597,120.16667
14.44000,120.33336,44.54894,1.04638,4.94988,120.33336
14.46000,120.50005,44.50696,1.04783,4.94522,120.50005
14.48000,120.66667,44.59973,1.04928,4.95553,120.66667
14.50000,120.83329,44.78415,1.05072,4.97602,120.83329
14.52000,120.99999,44.76862,1.05217,4.97429,120.99999
14.54000,121.16673,44.98895,1.05362,4.99877,121.16673
14.56000,121.33336,45.05419,1.05507,5.00602,121.33336
14.58000,121.50005,45.05615,1.05652,5.00624,121.50005
14.60000,121.66660,45.30278,1.05797,5.03364,121.66660
14.62000,121.83330,45.28250,1.05942,5.03139,121.83330
14.64000,121.99998,45.27001,1.06087,5.03000,121.99998
14.66000,122.16668,45.42636,1.06232,5.04737,122.16668
14.68000,122.33336,45.42719,1.06377,5.04747,122.33336
14.70000,122.49999,45.31909,1.06522,5.03545,122.49999
14.72000,122.66668,45.43811,1.06667,5.04868,122.66668
14.74000,122.83330,45.60461,1.06812,5.06718,122.83330
14.76000,122.99999,45.54969,1.06957,5.06108,122.99999
14.78000,123.16667,45.58810,1.07101,5.06534,123.16667
14.80000,123.33330,45.58815,1.07246,5.06535,123.33330
14.82000,123.49992,45.70600,1.07391,5.07844,123.49992
14.84000,123.66655,45.85921,1.07536,5.09547,123.66655
14.86000,123.83330,45.93857,1.07681,5.10429,123.83330
14.88000,124.00005,45.84795,1.07826,5.09422,124.00005
14.90000,124.16674,45.92382,1.07971,5.10265,124.16674
14.92000,124.33330,45.96952,1.08116,5.10772,124.33330
14.94000,124.49998,45.98608,1.08261,5.10956,124.49998
14.96000,124.66673,46.06381,1.08406,5.11820,124.66673
14.98000,124.83343,46.17108,1.08551,5.13012,124.83343
15.00000,125.00010,46.10138,1.08696,5.12238,125.00010
15.02000,125.16667,46.32366,1.08841,5.14707,125.16667
15.04000,125.33329,46.45597,1.08985,5.16177,125.33329
15.06000,125.49998,46.53395,1.09130,5.17044,125.49998
15.08000,125.66673,46.54840,1.09275,5.17204,125.66673
15.10000,125.83342,46.51225,1.09420,5.16803,125.83342
15.12000,126.00005,46.53400,1.09565,5.17044,126.00005
15.14000,126.16660,46.59346,1.09710,5.17705,126.16660
15.16000,126.33330,46.49422,1.09855,5.16602,126.33330
15.18000,126.49998,46.54448,1.10000,5.17161,126.49998
15.20000,126.66667,46.67790,1.10145,5.18643,126.66667
15.22000,126.83329,46.88334,1.10290,5.20926,126.83329
15.24000,126.99998,46.85938,1.10435,5.20660,126.99998
15.26000,127.16666,47.03846,1.10580,5.22650,127.16666
15.28000,127.33336,47.02245,1.10725,5.22472,127.33336
15.30000,127.50004,47.00775,1.10870,5.22308,127.50004
15.32000,127.66661,47.23655,1.11014,5.24851,127.66661
15.34000,127.83323,47.19041,1.11159,5.24338,127.83323
15.36000,127.99992,47.13227,1.11304,5.23692,127.99992
15.38000,128.16660,47.38002,1.11449,5.26445,128.16660
15.40000,128.33329,47.40127,1.11594,5.26681,128.33329
15.42000,128.50004,47.38849,1.11739,5.26539,128.50004
15.44000,128.66661,47.55057,1.11884,5.28340,128.66661
15.46000,128.83330,47.47744,1.12029,5.27527,128.83330
15.48000,128.99998,47.51697,1.12174,5.27966,128.99998
15.50000,129.16666,47.95713,1.12319,5.32857,129.16666
15.52000,129.33335,47.89614,1.12464,5.32179,129.33335
15.54000,129.50005,47.54323,1.12609,5.28258,129.50005
15.56000,129.66667,47.54479,1.12754,5.28275,129.66667
15.58000,129.83330,47.60641,1.12899,5.28960,129.83330
15.60000,129.99998,47.60137,1.13043,5.28904,129.99998
15.62000,130.16666,47.61616,1.13188,5.29068,130.16666
15.64000,130.33335,47.68537,1.13333,5.29837,130.33335
15.66000,130.49997,47.71305,1.13478,5.30145,130.49997
15.68000,130.66666,48.00900,1.13623,5.33433,130.66666
15.70000,130.83328,47.97794,1.13768,5.33088,130.83328
15.72000,131.00005,47.93464,1.13913,5.32607,131.00005
15.74000,131.16673,48.12665,1.14058,5.34741,131.16673
15.76000,131.33335,48.16045,1.14203,5.35116,131.33335
15.78000,131.49998,48.14948,1.14348,5.34994,131.49998
15.80000,131.66660,48.39753,1.14493,5.37750,131.66660
15.82000,131.83328,48.44254,1.14638,5.38250,131.83328
15.84000,132.00005,48.32552,1.14783,5.36950,132.00005
15.86000,132.16667,48.49500,1.14928,5.38833,132.16667
15.88000,132.33329,48.48373,1.15072,5.38708,132.33329
15.90000,132.49998,48.55868,1.15217,5.39541,132.49998
15.92000,132.66667,48.72874,1.15362,5.41430,132.66667
15.94000,132.83335,48.70126,1.15507,5.41125,132.83335
15.96000,132.99997,48.59184,1.15652,5.39909,132.99997
15.98000,133.16660,48.80668,1.15797,5.42296,133.16660
16.00000,133.33322,48.93927,1.15942,5.43770,133.33322
16.02000,133.49992,48.73031,1.16087,5.41448,133.49992
16.04000,133.66667,48.83126,1.16232,5.42570,133.66667
16.06000,133.83335,48.83930,1.16377,5.42659,133.83335
16.08000,134.00003,48.82284,1.16522,5.42476,134.00003
16.10000,134.16666,48.99830,1.16667,5.44425,134.16666
16.12000,134.33336,48.99236,1.16812,5.44360,134.33336
16.14000,134.50011,49.00187,1.16957,5.44465,134.50011
16.16000,134.66673,49.16615,1.17102,5.46291,134.66673
16.18000,134.83335,49.10821,1.17246,5.45647,134.83335
16.20000,134.99998,48.95847,1.17391,5.43983,134.99998
16.22000,135.16660,49.17003,1.17536,5.46334,135.16660
16.24000,135.33329,49.24438,1.17681,5.47160,135.33329
16.26000,135.50005,49.11477,1.17826,5.45720,135.50005
16.28000,135.66679,48.78674,1.17971,5.42075,135.66679
16.30000,135.83342,26.75377,1.18116,2.97264,135.83342
16.32000,135.99998,5.77942,1.18261,0.64216,135.99998
16.34000,136.16661,-1.84950,1.18406,-0.20550,136.16661
16.36000,136.33328,-1.99233,1.18551,-0.22137,136.33328
16.38000,136.49997,-0.87137,1.18696,-0.09682,136.49997
16.40000,136.66667,-0.35429,1.18841,-0.03937,136.66667
16.42000,136.83322,-0.09032,1.18985,-0.01004,136.83322
16.44000,136.99998,-0.17580,1.19130,-0.01953,136.99998
16.46000,137.16667,0.04594,1.19275,0.00510,137.16667
16.48000,137.33335,-0.06725,1.19420,-0.00747,137.33335
16.50000,137.50004,-0.25025,1.19565,-0.02781,137.50004
16.52000,137.66666,-0.18356,1.19710,-0.02040,137.66666
16.54000,137.83323,0.03576,1.19855,0.00397,137.83323
16.56000,137.99992,-0.17369,1.20000,-0.01930,137.99992
16.58000,138.16661,-0.11273,1.20145,-0.01253,138.16661
16.60000,138.33329,-0.05325,1.20290,-0.00592,138.33329
16.62000,138.49998,0.09821,1.20435,0.01091,138.49998
16.64000,138.66660,-0.03684,1.20580,-0.00409,138.66660
16.66000,138.83322,-0.02302,1.20725,-0.00256,138.83322
16.68000,139.00004,-0.12231,1.20870,-0.01359,139.00004
16.70000,139.16673,-0.26820,1.21015,-0.02980,139.16673
16.72000,139.33335,-0.29252,1.21159,-0.03250,139.33335
16.74000,139.49998,-0.13874,1.21304,-0.01542,139.49998
16.76000,139.66660,0.08391,1.21449,0.00932,139.66660
16.78000,139.83334,-0.13911,1.21594,-0.01546,139.83334
16.80000,140.00005,-0.26255,1.21739,-0.02917,140.00005
16.82000,140.16673,-0.17898,1.21884,-0.01989,140.16673
16.84000,140.33330,-0.09140,1.22029,-0.01016,140.33330
16.86000,140.49998,-0.24557,1.22174,-0.02729,140.49998
16.88000,140.66666,-0.09023,1.22319,-0.01003,140.66666
16.90000,140.83335,-0.22363,1.22464,-0.02485,140.83335
16.92000,141.00011,-0.29583,1.22609,-0.03287,141.00011
16.94000,141.16667,-0.16186,1.22754,-0.01798,141.16667
16.96000,141.33330,-0.14266,1.22899,-0.01585,141.33330
16.98000,141.49998,-0.38145,1.23043,-0.04238,141.49998
17.00000,141.66667,-0.24868,1.23188,-0.02763,141.66667
17.02000,141.83335,-0.16475,1.23333,-0.01831,141.83335
17.04000,142.00004,-0.13301,1.23478,-0.01478,142.00004
17.06000,142.16666,-0.00968,1.23623,-0.00108,142.16666
17.08000,142.33328,-0.04631,1.23768,-0.00515,142.33328
17.10000,142.50005,-0.16877,1.23913,-0.01875,142.50005
17.12000,142.66673,0.03784,1.24058,0.00420,142.66673
17.14000,142.83336,0.00744,1.24203,0.00083,142.83336
17.16000,142.99998,-0.02469,1.24348,-0.00274,142.99998
17.18000,143.16655,0.17905,1.24493,0.01989,143.16655
17.20000,143.33323,0.12123,1.24638,0.01347,143.33323
17.22000,143.49997,-0.12150,1.24783,-0.01350,143.49997
17.24000,143.66667,-0.18124,1.24928,-0.02014,143.66667
17.26000,143.83336,-0.20710,1.25072,-0.02301,143.83336
17.28000,144.00004,-0.22566,1.25217,-0.02507,144.00004
17.30000,144.16672,-0.06466,1.25362,-0.00718,144.16672
17.32000,144.33342,-0.15750,1.25507,-0.01750,144.33342
17.34000,144.50005,-0.38187,1.25652,-0.04243,144.50005
17.36000,144.66673,-0.09057,1.25797,-0.01006,144.66673
17.38000,144.83330,-0.02219,1.25942,-0.00247,144.83330
17.40000,145.00004,-0.11572,1.26087,-0.01286,145.00004
17.42000,145.16673,-0.08290,1.26232,-0.00921,145.16673
17.44000,145.33341,-0.22106,1.26377,-0.02456,145.33341
17.46000,145.50011,-0.31295,1.26522,-0.03477,145.50011
17.48000,145.66666,-0.06277,1.26667,-0.00697,145.66666
17.50000,145.83329,-0.17913,1.26812,-0.01990,145.83329
17.52000,145.99998,-0.16887,1.26957,-0.01876,145.99998
17.54000,146.16667,-0.13541,1.27101,-0.01505,146.16667
17.56000,146.33335,-0.19152,1.27246,-0.02128,146.33335
17.58000,146.49997,-0.38686,1.27391,-0.04298,146.49997
17.60000,146.66661,-0.15197,1.27536,-0.01689,146.66661
17.62000,146.83323,-0.21560,1.27681,-0.02396,146.83323
17.64000,146.99997,-0.33217,1.27826,-0.03691,146.99997
17.66000,147.16673,-0.17026,1.27971,-0.01892,147.16673
17.68000,147.33336,-0.05285,1.28116,-0.00587,147.33336
17.70000,147.49998,0.00590,1.28261,0.00066,147.49998
17.72000,147.66661,0.06360,1.28406,0.00707,147.66661
17.74000,147.83329,-0.20820,1.28551,-0.02313,147.83329
17.76000,147.99997,-0.31657,1.28696,-0.03517,147.99997
17.78000,148.16667,-0.21805,1.28841,-0.02423,148.16667
17.80000,148.33330,-0.21670,1.28985,-0.02408,148.33330
17.82000,148.49992,-0.21724,1.29130,-0.02414,148.49992
17.84000,148.66660,-0.12838,1.29275,-0.01426,148.66660
17.86000,148.83335,-0.17724,1.29420,-0.01969,148.83335
17.88000,149.00004,-0.29052,1.29565,-0.03228,149.00004
17.90000,149.16666,-0.13563,1.29710,-0.01507,149.16666
17.92000,149.33328,-0.13421,1.29855,-0.01491,149.33328
17.94000,149.49999,-0.23272,1.30000,-0.02586,149.49999
17.96000,149.66667,-0.11308,1.30145,-0.01256,149.66667
17.98000,149.83336,-0.11646,1.30290,-0.01294,149.83336
18.00000,150.00003,-0.21961,1.30435,-0.02440,150.00003
18.02000,150.16660,-0.19120,1.30580,-0.02124,150.16660
18.04000,150.33329,-0.24376,1.30725,-0.02708,150.33329
18.06000,150.49999,-0.35275,1.30870,-0.03919,150.49999
18.08000,150.66673,-0.30695,1.31015,-0.03411,150.66673
18.10000,150.83335,-0.17587,1.31159,-0.01954,150.83335
18.12000,151.00004,-0.21785,1.31304,-0.02421,151.00004
18.14000,151.16666,-0.14869,1.31449,-0.01652,151.16666
18.16000,151.33329,-0.22579,1.31594,-0.02509,151.33329
18.18000,151.50005,-0.18667,1.31739,-0.02074,151.50005
18.20000,151.66673,0.06923,1.31884,0.00769,151.66673
18.22000,151.83330,0.03274,1.32029,0.00364,151.83330
18.24000,151.99998,0.13607,1.32174,0.01512,151.99998
18.26000,152.16661,0.10384,1.32319,0.01154,152.16661
18.28000,152.33329,-0.16279,1.32464,-0.01809,152.33329
18.30000,152.50011,-0.34075,1.32609,-0.03786,152.50011
18.32000,152.66674,-0.23039,1.32754,-0.02560,152.66674
18.34000,152.83328,-0.19238,1.32899,-0.02138,152.83328
18.36000,152.99991,-0.23720,1.33043,-0.02636,152.99991
18.38000,153.16653,-0.04098,1.33188,-0.00455,153.16653
18.40000,153.33324,-0.03040,1.33333,-0.00338,153.33324
18.42000,153.49998,-0.11482,1.33478,-0.01276,153.49998
18.44000,153.66666,-0.11357,1.33623,-0.01262,153.66666
18.46000,153.83328,-0.30986,1.33768,-0.03443,153.83328
18.48000,153.99999,-0.35960,1.33913,-0.03996,153.99999
18.50000,154.16673,-0.25760,1.34058,-0.02862,154.16673
18.52000,154.33341,-0.13994,1.34203,-0.01555,154.33341
18.54000,154.50010,-0.21449,1.34348,-0.02383,154.50010
18.56000,154.66667,-0.17477,1.34493,-0.01942,154.66667
18.58000,154.83329,-0.24979,1.34638,-0.02775,154.83329
18.60000,154.99997,-0.37116,1.34783,-0.04124,154.99997
18.62000,155.16673,-0.07230,1.34928,-0.00803,155.16673
18.64000,155.33336,-0.05829,1.35072,-0.00648,155.33336
18.66000,155.49998,-0.18329,1.35217,-0.02037,155.49998
18.68000,155.66661,-0.11592,1.35362,-0.01288,155.66661
18.70000,155.83329,-0.06765,1.35507,-0.00752,155.83329
18.71200,155.93335,-0.10580,1.35594,-0.01176,155.93335