File: V_8/EPR/RDSO EPR Tensile Multi.is_tens_RawData/Specimen_RawData_1.csv
Time,Extension,Load,Tensile strain,Tensile stress,Corrected Position
(sec),(mm),(N),(mm/mm),(MPa),(mm)
0.00000,0.00000,-0.09021,0.00000,-0.01002,0.00000
0.04000,0.09837,0.55403,0.00086,0.06156,0.09837
0.08000,0.41775,1.29504,0.00363,0.14389,0.41775
0.12000,0.82981,1.59616,0.00722,0.17735,0.82981
0.16000,1.26737,2.20366,0.01102,0.24485,1.26737
0.20000,1.65612,2.62662,0.01440,0.29185,1.65612
0.24000,1.98887,3.05362,0.01729,0.33929,1.98887
0.28000,2.32287,3.50857,0.02020,0.38984,2.32287
0.32000,2.66144,3.95203,0.02314,0.43911,2.66144
0.36000,2.99737,4.31516,0.02606,0.47946,2.99737
0.40000,3.33162,4.73883,0.02897,0.52654,3.33162
0.44000,3.66569,5.05193,0.03188,0.56133,3.66569
0.48000,3.99931,5.16628,0.03478,0.57403,3.99931
0.52000,4.33294,5.58579,0.03768,0.62064,4.33294
0.56000,4.66650,5.78037,0.04058,0.64226,4.66650
0.60000,4.99987,6.06077,0.04348,0.67342,4.99987
0.64000,5.33331,6.52284,0.04638,0.72476,5.33331
0.68000,5.66662,6.65284,0.04927,0.73920,5.66662
0.72000,5.99994,6.86026,0.05217,0.76225,5.99994
0.76000,6.33337,7.03086,0.05507,0.78121,6.33337
0.80000,6.66669,7.33786,0.05797,0.81532,6.66669
0.84000,7.00006,7.47151,0.06087,0.83017,7.00006
0.88000,7.33337,7.95839,0.06377,0.88427,7.33337
0.92000,7.66669,8.04798,0.06667,0.89422,7.66669
0.96000,8.00012,8.14357,0.06957,0.90484,8.00012
1.00000,8.33337,8.45605,0.07246,0.93956,8.33337
1.04000,8.66669,8.61421,0.07536,0.95713,8.66669
1.08000,9.00006,8.46345,0.07826,0.94038,9.00006
1.12000,9.33331,8.79278,0.08116,0.97698,9.33331
1.16000,9.66669,9.00992,0.08406,1.00110,9.66669
1.20000,10.00006,9.01670,0.08696,1.00186,10.00006
1.24000,10.33331,9.21187,0.08985,1.02354,10.33331
1.28000,10.66675,9.42864,0.09275,1.04763,10.66675
1.32000,11.00006,9.38441,0.09565,1.04271,11.00006
1.36000,11.33337,9.72712,0.09855,1.08079,11.33337
1.40000,11.66681,9.85224,0.10145,1.09469,11.66681
1.44000,12.00006,9.79640,0.10435,1.08849,12.00006
1.48000,12.33337,10.10565,0.10725,1.12285,12.33337
1.52000,12.66675,10.35191,0.11015,1.15021,12.66675
1.56000,13.00000,10.37782,0.11304,1.15309,13.00000
1.60000,13.33337,10.65357,0.11594,1.18373,13.33337
1.64000,13.66668,10.60221,0.11884,1.17802,13.66668
1.68000,14.00000,10.77801,0.12174,1.19756,14.00000
1.72000,14.33337,11.04761,0.12464,1.22751,14.33337
1.76000,14.66662,11.38774,0.12754,1.26530,14.66662
1.80000,15.00000,11.27831,0.13043,1.25315,15.00000
1.84000,15.33337,11.47280,0.13333,1.27476,15.33337
1.88000,15.66668,11.59075,0.13623,1.28786,15.66668
1.92000,16.00012,11.59420,0.13913,1.28824,16.00012
1.96000,16.33344,11.94241,0.14203,1.32693,16.33344
2.00000,16.66668,12.08625,0.14493,1.34292,16.66668
2.04000,17.00012,12.08480,0.14783,1.34276,17.00012
2.08000,17.33331,12.37265,0.15072,1.37474,17.33331
2.12000,17.66675,12.53358,0.15362,1.39262,17.66675
2.16000,18.00012,12.58697,0.15652,1.39855,18.00012
2.20000,18.33331,12.92216,0.15942,1.43580,18.33331
2.24000,18.66675,13.02455,0.16232,1.44717,18.66675
2.28000,19.00006,12.73886,0.16522,1.41543,19.00006
2.32000,19.33337,13.04086,0.16812,1.44898,19.33337
2.36000,19.66675,13.25053,0.17102,1.47228,19.66675
2.40000,20.00000,13.02255,0.17391,1.44695,20.00000
2.44000,20.33331,13.17243,0.17681,1.46360,20.33331
2.48000,20.66681,13.39268,0.17971,1.48808,20.66681
2.52000,21.00000,13.48303,0.18261,1.49811,21.00000
2.56000,21.33337,13.55724,0.18551,1.50636,21.33337
2.60000,21.66675,13.73947,0.18841,1.52661,21.66675
2.64000,22.00000,13.58217,0.19130,1.50913,22.00000
2.68000,22.33343,13.78829,0.19420,1.53203,22.33343
2.72000,22.66668,13.93538,0.19710,1.54838,22.66668
2.76000,23.00006,13.97809,0.20000,1.55312,23.00006
2.80000,23.33337,14.00491,0.20290,1.55610,23.33337
2.84000,23.66669,13.92700,0.20580,1.54744,23.66669
2.88000,24.00012,13.99795,0.20870,1.55533,24.00012
2.92000,24.33337,14.35156,0.21159,1.59462,24.33337
2.96000,24.66668,14.42349,0.21449,1.60261,24.66668
3.00000,25.00006,14.25996,0.21739,1.58444,25.00006
3.04000,25.33331,14.38655,0.22029,1.59851,25.33331
3.08000,25.66668,14.51822,0.22319,1.61314,25.66668
3.12000,26.00006,14.48672,0.22609,1.60964,26.00006
3.16000,26.33337,14.80513,0.22899,1.64501,26.33337
3.20000,26.66675,14.78730,0.23188,1.64303,26.66675
3.24000,27.00012,14.80063,0.23478,1.64451,27.00012
3.28000,27.33337,15.11622,0.23768,1.67958,27.33337
3.32000,27.66675,14.89453,0.24058,1.65495,27.66675
3.36000,28.00006,15.03866,0.24348,1.67096,28.00006
3.40000,28.33331,15.07929,0.24638,1.67548,28.33331
3.44000,28.66675,15.22954,0.24928,1.69217,28.66675
3.48000,29.00006,15.17679,0.25217,1.68631,29.00006
3.52000,29.33337,15.41597,0.25507,1.71289,29.33337
3.56000,29.66668,15.44734,0.25797,1.71637,29.66668
3.60000,30.00000,15.56296,0.26087,1.72922,30.00000
3.64000,30.33343,15.51614,0.26377,1.72401,30.33343
3.68000,30.66668,15.83961,0.26667,1.75996,30.66668
3.72000,31.00006,15.58082,0.26957,1.73120,31.00006
3.76000,31.33343,15.84488,0.27246,1.76054,31.33343
3.80000,31.66668,15.68748,0.27536,1.74305,31.66668
3.84000,32.00006,15.90601,0.27826,1.76733,32.00006
3.88000,32.33337,16.16917,0.28116,1.79657,32.33337
3.92000,32.66668,16.01375,0.28406,1.77931,32.66668
3.96000,33.00012,16.02031,0.28696,1.78003,33.00012
4.00000,33.33337,16.16650,0.28986,1.79628,33.33337
4.04000,33.66668,16.26221,0.29275,1.80691,33.66668
4.08000,34.00012,16.27068,0.29565,1.80785,34.00012
4.12000,34.33331,16.43862,0.29855,1.82651,34.33331
4.16000,34.66668,16.48155,0.30145,1.83128,34.66668
4.20000,35.00006,16.38795,0.30435,1.82088,35.00006
4.24000,35.33331,16.53009,0.30725,1.83668,35.33331
4.28000,35.66675,16.66249,0.31015,1.85139,35.66675
4.32000,36.00006,16.72044,0.31304,1.85783,36.00006
4.36000,36.33343,16.90630,0.31594,1.87848,36.33343
4.40000,36.66681,16.90429,0.31884,1.87825,36.66681
4.44000,36.99999,16.90841,0.32174,1.87871,36.99999
4.48000,37.33337,17.10630,0.32464,1.90070,37.33337
4.52000,37.66681,17.16245,0.32754,1.90694,37.66681
4.56000,37.99993,17.01095,0.33043,1.89011,37.99993
4.60000,38.33337,17.29490,0.33333,1.92166,38.33337
4.64000,38.66668,17.34783,0.33623,1.92754,38.66668
4.68000,38.99999,17.38520,0.33913,1.93169,38.99999
4.72000,39.33337,17.37852,0.34203,1.93095,39.33337
4.76000,39.66668,17.53418,0.34493,1.94824,39.66668
4.80000,39.99999,17.34474,0.34783,1.92719,39.99999
4.84000,40.33337,17.79846,0.35072,1.97761,40.33337
4.88000,40.66668,17.74561,0.35362,1.97173,40.66668
4.92000,41.00012,17.78242,0.35652,1.97582,41.00012
4.96000,41.33337,18.01509,0.35942,2.00168,41.33337
5.00000,41.66668,17.99182,0.36232,1.99909,41.66668
5.04000,42.00005,17.87517,0.36522,1.98613,42.00005
5.08000,42.33337,18.02942,0.36812,2.00327,42.33337
5.12000,42.66674,18.32003,0.37102,2.03556,42.66674
5.16000,43.00012,18.35390,0.37391,2.03932,43.00012
5.20000,43.33331,18.34050,0.37681,2.03783,43.33331
5.24000,43.66668,18.46822,0.37971,2.05202,43.66668
5.28000,44.00006,18.46808,0.38261,2.05201,44.00006
5.32000,44.33331,18.54243,0.38551,2.06027,44.33331
5.36000,44.66674,18.70270,0.38841,2.07808,44.66674
5.40000,44.99999,18.61625,0.39130,2.06847,44.99999
5.44000,45.33330,18.74620,0.39420,2.08291,45.33330
5.48000,45.66674,18.60204,0.39710,2.06689,45.66674
5.52000,46.00006,18.98819,0.40000,2.10980,46.00006
5.56000,46.33343,19.05946,0.40290,2.11772,46.33343
5.60000,46.66668,19.08092,0.40580,2.12010,46.66668
5.64000,46.99999,19.23313,0.40870,2.13701,46.99999
5.68000,47.33343,19.27614,0.41160,2.14179,47.33343
5.72000,47.66668,19.15148,0.41449,2.12794,47.66668
5.76000,48.00005,19.52132,0.41739,2.16904,48.00005
5.80000,48.33337,19.54373,0.42029,2.17153,48.33337
5.84000,48.66668,19.57677,0.42319,2.17520,48.66668
5.88000,49.00006,19.56099,0.42609,2.17344,49.00006
5.92000,49.33337,19.65063,0.42899,2.18340,49.33337
5.96000,49.66668,19.75776,0.43188,2.19531,49.66668
6.00000,50.00005,19.87272,0.43478,2.20808,50.00005
6.04000,50.33331,20.10416,0.43768,2.23380,50.33331
6.08000,50.66668,19.98893,0.44058,2.22099,50.66668
6.12000,51.00012,19.99160,0.44348,2.22129,51.00012
6.16000,51.33336,20.27738,0.44638,2.25304,51.33336
6.20000,51.66674,20.48477,0.44928,2.27609,51.66674
6.24000,52.00006,20.24822,0.45217,2.24980,52.00006
6.28000,52.33331,20.58899,0.45507,2.28767,52.33331
6.32000,52.66680,20.57995,0.45797,2.28666,52.66680
6.36000,53.00005,20.51821,0.46087,2.27980,53.00005
6.40000,53.33330,20.77980,0.46377,2.30887,53.33330
6.44000,53.66668,20.83120,0.46667,2.31458,53.66668
6.48000,53.99999,20.74987,0.46957,2.30554,53.99999
6.52000,54.33337,21.04075,0.47246,2.33786,54.33337
6.56000,54.66674,21.10864,0.47536,2.34540,54.66674
6.60000,54.99993,21.10785,0.47826,2.34532,54.99993
6.64000,55.33337,21.18838,0.48116,2.35426,55.33337
6.68000,55.66668,21.54485,0.48406,2.39387,55.66668
6.72000,56.00005,21.48032,0.48696,2.38670,56.00005
6.76000,56.33349,21.74333,0.48986,2.41593,56.33349
6.80000,56.66668,21.63593,0.49275,2.40399,56.66668
6.84000,57.00005,21.77693,0.49565,2.41966,57.00005
6.88000,57.33337,21.76676,0.49855,2.41853,57.33337
6.92000,57.66668,21.79410,0.50145,2.42157,57.66668
6.96000,58.00006,21.88542,0.50435,2.43171,58.00006
7.00000,58.33331,22.21503,0.50725,2.46834,58.33331
7.04000,58.66668,22.13085,0.51015,2.45898,58.66668
7.08000,59.00012,21.98395,0.51304,2.44266,59.00012
7.12000,59.33337,22.27677,0.51594,2.47520,59.33337
7.16000,59.66668,22.57140,0.51884,2.50793,59.66668
7.20000,60.00006,22.50762,0.52174,2.50085,60.00006
7.24000,60.33324,22.72278,0.52464,2.52475,60.33324
7.28000,60.66674,22.66664,0.52754,2.51852,60.66674
7.32000,61.00012,22.78217,0.53044,2.53135,61.00012
7.36000,61.33337,23.18649,0.53333,2.57628,61.33337
7.40000,61.66680,22.91601,0.53623,2.54622,61.66680
7.44000,62.00006,22.91158,0.53913,2.54573,62.00006
7.48000,62.33336,23.18818,0.54203,2.57646,62.33336
7.52000,62.66674,23.16582,0.54493,2.57398,62.66674
7.56000,63.00006,23.23312,0.54783,2.58146,63.00006
7.60000,63.33336,23.58935,0.55072,2.62104,63.33336
7.64000,63.66661,23.49878,0.55362,2.61098,63.66661
7.68000,63.99999,23.63551,0.55652,2.62617,63.99999
7.72000,64.33337,23.79747,0.55942,2.64416,64.33337
7.76000,64.66668,23.96619,0.56232,2.66291,64.66668
7.80000,64.99999,23.90893,0.56522,2.65655,64.99999
7.84000,65.33337,24.15264,0.56812,2.68363,65.33337
7.88000,65.66667,24.10312,0.57101,2.67812,65.66667
7.92000,66.00011,24.20809,0.57391,2.68979,66.00011
7.96000,66.33343,24.34372,0.57681,2.70486,66.33343
8.00000,66.66674,24.34362,0.57971,2.70485,66.66674
8.04000,67.00011,24.60526,0.58261,2.73392,67.00011
8.08000,67.33330,24.62424,0.58551,2.73603,67.33330
8.12000,67.66674,24.51609,0.58841,2.72401,67.66674
8.16000,68.00012,24.71763,0.59131,2.74640,68.00012
8.20000,68.33330,24.90476,0.59420,2.76720,68.33330
8.24000,68.66674,24.77119,0.59710,2.75235,68.66674
8.28000,69.00005,24.87060,0.60000,2.76340,69.00005
8.32000,69.33337,25.27419,0.60290,2.80824,69.33337
8.36000,69.66674,25.22516,0.60580,2.80280,69.66674
8.40000,70.00005,25.23045,0.60870,2.80338,70.00005
8.44000,70.33336,25.51981,0.61159,2.83553,70.33336
8.48000,70.66674,25.64714,0.61449,2.84968,70.66674
8.52000,71.00006,25.70288,0.61739,2.85588,71.00006
8.56000,71.33342,25.78255,0.62029,2.86473,71.33342
8.60000,71.66674,25.89335,0.62319,2.87704,71.66674
8.64000,71.99993,25.76386,0.62609,2.86265,71.99993
8.68000,72.33337,26.15117,0.62899,2.90569,72.33337
8.72000,72.66668,26.03716,0.63188,2.89302,72.66668
8.76000,73.00011,26.02330,0.63478,2.89148,73.00011
8.80000,73.33343,26.40563,0.63768,2.93396,73.33343
8.84000,73.66662,26.64342,0.64058,2.96038,73.66662
8.88000,74.00006,26.46417,0.64348,2.94046,74.00006
8.92000,74.33336,26.58400,0.64638,2.95378,74.33336
8.96000,74.66668,26.65544,0.64928,2.96172,74.66668
9.00000,75.00005,26.68622,0.65217,2.96514,75.00005
9.04000,75.33330,26.94365,0.65507,2.99374,75.33330
9.08000,75.66668,27.01867,0.65797,3.00207,75.66668
9.12000,76.00005,26.81069,0.66087,2.97897,76.00005
9.16000,76.33343,27.12628,0.66377,3.01403,76.33343
9.20000,76.66674,27.11561,0.66667,3.01285,76.66674
9.24000,77.00005,27.25839,0.66957,3.02871,77.00005
9.28000,77.33330,27.48089,0.67246,3.05343,77.33330
9.32000,77.66680,27.61138,0.67536,3.06793,77.66680
9.36000,78.00011,27.78228,0.67826,3.08692,78.00011
9.40000,78.33336,27.93199,0.68116,3.10355,78.33336
9.44000,78.66674,27.80180,0.68406,3.08909,78.66674
9.48000,78.99999,27.96444,0.68696,3.10716,78.99999
9.52000,79.33336,28.13336,0.68986,3.12593,79.33336
9.56000,79.66674,28.14913,0.69275,3.12768,79.66674
9.60000,80.00005,28.15790,0.69565,3.12866,80.00005
9.64000,80.33330,28.30323,0.69855,3.14480,80.33330
9.68000,80.66662,28.36541,0.70145,3.15171,80.66662
9.72000,81.00005,28.62445,0.70435,3.18049,81.00005
9.76000,81.33342,28.94842,0.70725,3.21649,81.33342
9.80000,81.66668,28.63418,0.71015,3.18158,81.66668
9.84000,81.99998,28.76915,0.71304,3.19657,81.99998
9.88000,82.33336,29.23059,0.71594,3.24784,82.33336
9.92000,82.66667,29.00529,0.71884,3.22281,82.66667
9.96000,83.00011,29.09072,0.72174,3.23230,83.00011
10.00000,83.33337,29.51667,0.72464,3.27963,83.33337
10.04000,83.66668,29.33107,0.72754,3.25901,83.66668
10.08000,84.00011,29.50675,0.73044,3.27853,84.00011
10.12000,84.33335,29.53565,0.73333,3.28174,84.33335
10.16000,84.66667,29.51329,0.73623,3.27925,84.66667
10.20000,84.99999,29.74274,0.73913,3.30475,84.99999
10.24000,85.33323,30.02400,0.74203,3.33600,85.33323
10.28000,85.66674,29.99699,0.74493,3.33300,85.66674
10.32000,86.00011,30.10313,0.74783,3.34479,86.00011
10.36000,86.33343,30.27254,0.75073,3.36362,86.33343
10.40000,86.66680,30.10507,0.75362,3.34501,86.66680
10.44000,87.00005,30.22311,0.75652,3.35812,87.00005
10.48000,87.33337,30.61676,0.75942,3.40186,87.33337
10.52000,87.66674,30.80191,0.76232,3.42243,87.66674
10.56000,88.00005,30.63662,0.76522,3.40407,88.00005
10.60000,88.33342,30.94327,0.76812,3.43814,88.33342
10.64000,88.66668,30.88665,0.77101,3.43185,88.66668
10.68000,88.99999,30.94705,0.77391,3.43856,88.99999
10.72000,89.33336,31.27200,0.77681,3.47467,89.33336
10.76000,89.66668,31.14719,0.77971,3.46080,89.66668
10.80000,89.99999,31.23565,0.78261,3.47063,89.99999
10.84000,90.33336,31.51740,0.78551,3.50193,90.33336
10.88000,90.66661,31.82001,0.78841,3.53556,90.66661
10.92000,91.00005,31.58401,0.79130,3.50933,91.00005
10.96000,91.33343,31.85028,0.79420,3.53892,91.33343
11.00000,91.66667,31.85214,0.79710,3.53913,91.66667
11.04000,92.00011,31.76873,0.80000,3.52986,92.00011
11.08000,92.33336,32.09774,0.80290,3.56642,92.33336
11.12000,92.66674,32.18424,0.80580,3.57603,92.66674
11.16000,93.00011,32.22857,0.80870,3.58095,93.00011
11.20000,93.33336,32.42097,0.81159,3.60233,93.33336
11.24000,93.66673,32.60667,0.81449,3.62296,93.66673
11.28000,94.00005,32.57678,0.81739,3.61964,94.00005
11.32000,94.33337,32.66456,0.82029,3.62940,94.33337
11.36000,94.66674,33.02267,0.82319,3.66919,94.66674
11.40000,94.99999,32.97599,0.82609,3.66400,94.99999
11.44000,95.33335,33.14787,0.82899,3.68310,95.33335
11.48000,95.66673,33.19563,0.83188,3.68840,95.66673
11.52000,95.99999,33.05142,0.83478,3.67238,95.99999
11.56000,96.33336,33.36349,0.83768,3.70705,96.33336
11.60000,96.66674,33.62422,0.84058,3.73602,96.66674
11.64000,97.00011,33.47943,0.84348,3.71994,97.00011
11.68000,97.33336,33.57127,0.84638,3.73014,97.33336
11.72000,97.66667,33.43211,0.84928,3.71468,97.66667
11.76000,98.00011,33.74006,0.85217,3.74890,98.00011
11.80000,98.33336,34.10552,0.85507,3.78950,98.33336
11.84000,98.66667,34.09357,0.85797,3.78817,98.66667
11.88000,99.00005,34.27157,0.86087,3.80795,99.00005
11.92000,99.33330,34.23900,0.86377,3.80433,99.33330
11.96000,99.66660,34.14270,0.86667,3.79363,99.66660
12.00000,100.00005,34.32726,0.86957,3.81414,100.00005
12.04000,100.33330,34.64457,0.87246,3.84940,100.33330
12.08000,100.66668,34.63830,0.87536,3.84870,100.66668
12.12000,101.00011,34.74988,0.87826,3.86110,101.00011
12.16000,101.33336,35.00102,0.88116,3.88900,101.33336
12.20000,101.66674,34.88047,0.88406,3.87561,101.66674
12.24000,102.00005,34.85525,0.88696,3.87281,102.00005
12.28000,102.33330,35.10883,0.88985,3.90098,102.33330
12.32000,102.66673,35.09732,0.89275,3.89970,102.66673
12.36000,103.00005,35.15747,0.89565,3.90638,103.00005
12.40000,103.33342,35.39175,0.89855,3.93242,103.33342
12.44000,103.66674,35.48085,0.90145,3.94232,103.66674
12.48000,104.00005,35.63901,0.90435,3.95989,104.00005
12.52000,104.33336,35.74374,0.90725,3.97153,104.33336
12.56000,104.66667,35.77464,0.91014,3.97496,104.66667
12.60000,104.99999,35.84998,0.91304,3.98333,104.99999
12.64000,105.33337,36.12849,0.91594,4.01428,105.33337
12.68000,105.66667,36.22954,0.91884,4.02550,105.66667
12.72000,105.99999,36.33250,0.92174,4.03694,105.99999
12.76000,106.33342,36.54303,0.92464,4.06034,106.33342
12.80000,106.66673,36.43409,0.92754,4.04823,106.66673
12.84000,107.00011,36.34504,0.93044,4.03834,107.00011
12.88000,107.33343,36.53592,0.93333,4.05955,107.33343
12.92000,107.66667,36.95546,0.93623,4.10616,107.66667
12.96000,108.00011,36.98039,0.93913,4.10893,108.00011
13.00000,108.33336,37.11475,0.94203,4.12386,108.33336
13.04000,108.66667,37.10740,0.94493,4.12304,108.66667
13.08000,109.00011,37.20037,0.94783,4.13337,109.00011
13.12000,109.33329,37.26204,0.95072,4.14023,109.33329
13.16000,109.66667,37.34070,0.95362,4.14897,109.66667
13.20000,109.99999,37.45498,0.95652,4.16166,109.99999
13.24000,110.33330,37.56465,0.95942,4.17385,110.33330
13.28000,110.66673,37.74094,0.96232,4.19344,110.66673
13.32000,111.00005,37.76396,0.96522,4.19600,111.00005
13.36000,111.33336,38.12300,0.96812,4.23589,111.33336
13.40000,111.66680,37.97644,0.97102,4.21960,111.66680
13.44000,112.00004,38.22895,0.97391,4.24766,112.00004
13.48000,112.33336,38.41273,0.97681,4.26808,112.33336
13.52000,112.66680,38.66107,0.97971,4.29567,112.66680
13.56000,113.00005,38.38143,0.98261,4.26460,113.00005
13.60000,113.33336,38.74885,0.98551,4.30543,113.33336
13.64000,113.66667,38.98626,0.98841,4.33181,113.66667
13.68000,114.00005,38.87287,0.99130,4.31921,114.00005
13.72000,114.33336,38.74341,0.99420,4.30482,114.33336
13.76000,114.66667,39.17626,0.99710,4.35292,114.66667
13.80000,114.99998,38.98935,1.00000,4.33215,114.99998
13.84000,115.33330,39.25831,1.00290,4.36203,115.33330
13.88000,115.66667,39.32733,1.00580,4.36970,115.66667
13.92000,116.00011,39.46531,1.00870,4.38503,116.00011
13.96000,116.33337,39.59026,1.01159,4.39892,116.33337
14.00000,116.66667,39.58404,1.01449,4.39823,116.66667
14.04000,117.00011,39.64307,1.01739,4.40479,117.00011
14.08000,117.33335,39.97762,1.02029,4.44196,117.33335
14.12000,117.66673,39.93877,1.02319,4.43764,117.66673
14.16000,118.00011,39.94661,1.02609,4.43851,118.00011
14.20000,118.33330,40.10183,1.02899,4.45576,118.33330
14.24000,118.66674,40.31368,1.03188,4.47930,118.66674
14.28000,119.00004,40.38681,1.03478,4.48742,119.00004
14.32000,119.33330,40.68708,1.03768,4.52079,119.33330
14.36000,119.66674,40.54752,1.04058,4.50528,119.66674
14.40000,119.99992,40.42992,1.04348,4.49221,119.99992
14.44000,120.33336,40.67718,1.04638,4.51969,120.33336
14.48000,120.66673,40.84039,1.04928,4.53782,120.66673
14.52000,121.00005,40.80419,1.05217,4.53380,121.00005
14.56000,121.33342,41.19698,1.05507,4.57744,121.33342
14.60000,121.66673,41.07007,1.05797,4.56334,121.66673
14.64000,122.00005,41.17895,1.06087,4.57544,122.00005
14.68000,122.33342,41.28593,1.06377,4.58733,122.33342
14.72000,122.66668,41.59712,1.06667,4.62190,122.66668
14.76000,122.99999,41.54177,1.06957,4.61575,122.99999
14.80000,123.33336,41.68700,1.07246,4.63189,123.33336
14.84000,123.66661,41.65002,1.07536,4.62778,123.66661
14.88000,124.00005,41.81656,1.07826,4.64628,124.00005
14.92000,124.33336,41.86436,1.08116,4.65160,124.33336
14.96000,124.66662,42.05549,1.08406,4.67283,124.66662
15.00000,125.00005,42.09777,1.08696,4.67753,125.00005
15.04000,125.33336,42.27920,1.08986,4.69769,125.33336
15.08000,125.66666,42.26842,1.09275,4.69649,125.66666
15.12000,126.00011,42.43751,1.09565,4.71528,126.00011
15.16000,126.33336,42.61271,1.09855,4.73475,126.33336
15.20000,126.66672,42.76911,1.10145,4.75212,126.66672
15.24000,127.00004,42.82750,1.10435,4.75861,127.00004
15.28000,127.33336,42.77783,1.10725,4.75309,127.33336
15.32000,127.66673,42.98454,1.11015,4.77606,127.66673
15.36000,128.00003,42.94663,1.11304,4.77185,128.00003
15.40000,128.33335,43.27456,1.11594,4.80828,128.33335
15.44000,128.66673,43.35475,1.11884,4.81719,128.66673
15.48000,129.00004,43.17234,1.12174,4.79693,129.00004
15.52000,129.33335,43.55219,1.12464,4.83913,129.33335
15.56000,129.66667,43.56199,1.12754,4.84022,129.66667
15.60000,129.99992,43.63233,1.13043,4.84804,129.99992
15.64000,130.33335,43.74935,1.13333,4.86104,130.33335
15.68000,130.66674,43.92539,1.13623,4.88060,130.66674
15.72000,131.00010,43.61308,1.13913,4.84590,131.00010
15.76000,131.33341,44.13371,1.14203,4.90375,131.33341
15.80000,131.66673,44.09027,1.14493,4.89892,131.66673
15.84000,132.00010,44.18916,1.14783,4.90991,132.00010
15.88000,132.33336,44.29384,1.15072,4.92154,132.33336
15.92000,132.66667,44.59037,1.15362,4.95449,132.66667
15.96000,133.00011,44.52053,1.15652,4.94672,133.00011
16.00000,133.33330,44.66272,1.15942,4.96252,133.33330
16.04000,133.66667,44.56535,1.16232,4.95170,133.66667
16.08000,134.00011,44.54575,1.16522,4.94953,134.00011
16.12000,134.33329,44.95647,1.16812,4.99516,134.33329
16.16000,134.66666,45.10518,1.17101,5.01169,134.66666
16.20000,135.00004,45.08314,1.17391,5.00924,135.00004
16.24000,135.33329,45.34524,1.17681,5.03836,135.33329
16.28000,135.66673,45.30449,1.17971,5.03383,135.66673
16.32000,136.00004,45.43101,1.18261,5.04789,136.00004
16.36000,136.33335,45.50590,1.18551,5.05621,136.33335
16.40000,136.66679,45.71560,1.18841,5.07951,136.66679
16.44000,136.99998,45.55772,1.19130,5.06197,136.99998
16.48000,137.33335,45.81488,1.19420,5.09054,137.33335
16.52000,137.66673,45.95933,1.19710,5.10659,137.66673
16.56000,138.00004,45.76551,1.20000,5.08506,138.00004
16.60000,138.33336,46.13268,1.20290,5.12585,138.33336
16.64000,138.66666,46.04486,1.20580,5.11610,138.66666
16.68000,139.00004,46.30329,1.20870,5.14481,139.00004
16.72000,139.33341,46.28036,1.21159,5.14226,139.33341
16.76000,139.66660,46.42437,1.21449,5.15826,139.66660
16.80000,139.99998,46.44171,1.21739,5.16019,139.99998
16.84000,140.33335,46.60281,1.22029,5.17809,140.33335
16.88000,140.66666,46.84772,1.22319,5.20530,140.66666
16.92000,141.00011,46.56965,1.22609,5.17441,141.00011
16.96000,141.33342,46.73007,1.22899,5.19223,141.33342
17.00000,141.66673,46.93912,1.23188,5.21546,141.66673
17.04000,142.00011,47.15494,1.23478,5.23944,142.00011
17.08000,142.33336,47.42635,1.23768,5.26959,142.33336
17.12000,142.66673,47.38114,1.24058,5.26457,142.66673
17.16000,143.00010,47.45589,1.24348,5.27288,143.00010
17.20000,143.33329,47.59617,1.24638,5.28846,143.33329
17.24000,143.66673,47.62625,1.24928,5.29181,143.66673
17.28000,144.00004,47.81855,1.25217,5.31317,144.00004
17.32000,144.33329,47.79426,1.25507,5.31047,144.33329
17.36000,144.66668,47.95551,1.25797,5.32839,144.66668
17.40000,144.99999,47.90471,1.26087,5.32275,144.99999
17.44000,145.33329,48.07037,1.26377,5.34115,145.33329
17.48000,145.66679,48.38998,1.26667,5.37666,145.66679
17.52000,146.00004,48.16001,1.26957,5.35111,146.00004
17.56000,146.33342,48.47134,1.27246,5.38570,146.33342
17.60000,146.66672,48.75348,1.27536,5.41705,146.66672
17.64000,146.99997,48.64772,1.27826,5.40530,146.99997
17.68000,147.33336,48.68745,1.28116,5.40972,147.33336
17.72000,147.66673,48.71018,1.28406,5.41224,147.66673
17.76000,148.00011,48.94083,1.28696,5.43787,148.00011
17.80000,148.33336,48.91561,1.28986,5.43507,148.33336
17.84000,148.66660,48.78561,1.29275,5.42062,148.66660
17.88000,149.00011,49.07921,1.29565,5.45325,149.00011
17.92000,149.33336,49.09954,1.29855,5.45550,149.33336
17.96000,149.66667,49.34239,1.30145,5.48249,149.66667
18.00000,150.00003,49.26294,1.30435,5.47366,150.00003
18.04000,150.33329,49.51466,1.30725,5.50163,150.33329
18.08000,150.66667,49.48919,1.31015,5.49880,150.66667
18.12000,151.00010,49.62482,1.31304,5.51387,151.00010
18.16000,151.33335,49.92180,1.31594,5.54687,151.33335
18.20000,151.66673,49.90990,1.31884,5.54554,151.66673
18.24000,152.00011,49.99322,1.32174,5.55480,152.00011
18.28000,152.33335,50.26218,1.32464,5.58469,152.33335
18.32000,152.66679,50.29735,1.32754,5.58859,152.66679
18.36000,153.00005,50.07526,1.33044,5.56392,153.00005
18.40000,153.33329,50.34374,1.33333,5.59375,153.33329
18.44000,153.66673,50.32894,1.33623,5.59210,153.66673
18.48000,153.99999,50.48093,1.33913,5.60899,153.99999
18.52000,154.33341,50.86079,1.34203,5.65120,154.33341
18.56000,154.66672,50.69523,1.34493,5.63280,154.66672
18.60000,154.99997,50.83997,1.34783,5.64889,154.99997
18.64000,155.33336,51.02758,1.35072,5.66973,155.33336
18.68000,155.66672,50.93250,1.35362,5.65917,155.66672
18.72000,156.00011,50.95905,1.35652,5.66212,156.00011
18.76000,156.33347,50.90591,1.35942,5.65621,156.33347
18.80000,156.66666,51.01910,1.36232,5.66879,156.66666
18.84000,156.99998,51.07210,1.36522,5.67468,156.99998
18.88000,157.33335,51.47023,1.36812,5.71891,157.33335
18.92000,157.66667,51.53366,1.37101,5.72596,157.66667
18.96000,158.00009,51.40513,1.37391,5.71168,158.00009
19.00000,158.33328,51.47733,1.37681,5.71970,158.33328
19.04000,158.66660,51.80390,1.37971,5.75599,158.66660
19.08000,159.00010,51.77843,1.38261,5.75316,159.00010
19.12000,159.33335,51.91709,1.38551,5.76857,159.33335
19.16000,159.66672,52.10269,1.38841,5.78919,159.66672
19.20000,160.00004,52.10553,1.39130,5.78950,160.00004
19.24000,160.33329,52.17592,1.39420,5.79732,160.33329
19.28000,160.66672,52.18184,1.39710,5.79798,160.66672
19.32000,161.00010,52.12547,1.40000,5.79172,161.00010
19.36000,161.33334,52.48720,1.40290,5.83191,161.33334
19.40000,161.66672,52.45947,1.40580,5.82883,161.66672
19.44000,162.00004,52.49513,1.40870,5.83279,162.00004
19.48000,162.33334,52.61558,1.41159,5.84618,162.33334
19.52000,162.66678,52.37664,1.41449,5.81963,162.66678
19.56000,163.00002,52.42132,1.41739,5.82459,163.00002
19.60000,163.33336,52.62190,1.42029,5.84688,163.33336
19.64000,163.66666,52.95376,1.42319,5.88375,163.66666
19.68000,163.99996,53.00181,1.42609,5.88909,163.99996
19.72000,164.33336,52.92583,1.42899,5.88065,164.33336
19.76000,164.66666,52.94846,1.43188,5.88316,164.66666
19.80000,164.99998,53.23055,1.43478,5.91451,164.99998
19.84000,165.33328,53.46537,1.43768,5.94060,165.33328
19.88000,165.66666,53.46714,1.44058,5.94079,165.66666
19.92000,166.00009,53.49339,1.44348,5.94371,166.00009
19.96000,166.33341,53.67330,1.44638,5.96370,166.33341
20.00000,166.66673,53.97034,1.44928,5.99670,166.66673
20.04000,167.00009,53.76079,1.45217,5.97342,167.00009
20.08000,167.33328,53.96142,1.45507,5.99571,167.33328
20.12000,167.66673,53.90548,1.45797,5.98950,167.66673
20.16000,168.00011,54.06070,1.46087,6.00674,168.00011
20.20000,168.33330,54.26913,1.46377,6.02990,168.33330
20.24000,168.66671,54.27211,1.46667,6.03023,168.66671
20.28000,169.00005,54.28632,1.46957,6.03181,169.00005
20.32000,169.33329,54.46702,1.47246,6.05189,169.33329
20.36000,169.66673,54.62719,1.47536,6.06969,169.66673
20.40000,169.99997,54.51624,1.47826,6.05736,169.99997
20.44000,170.33335,54.80592,1.48116,6.08955,170.33335
20.48000,170.66672,54.75459,1.48406,6.08384,170.66672
20.52000,171.00003,54.93421,1.48696,6.10380,171.00003
20.56000,171.33342,55.04368,1.48986,6.11596,171.33342
20.60000,171.66672,55.09080,1.49275,6.12120,171.66672
20.64000,171.99997,54.92294,1.49565,6.10255,171.99997
20.68000,172.33334,55.12293,1.49855,6.12477,172.33334
20.72000,172.66667,55.04363,1.50145,6.11596,172.66667
20.76000,173.00004,55.24030,1.50435,6.13781,173.00004
20.80000,173.33342,55.31916,1.50725,6.14657,173.33342
20.84000,173.66659,55.28644,1.51014,6.14294,173.66659
20.88000,174.00004,55.48628,1.51304,6.16514,174.00004
20.92000,174.33334,55.82578,1.51594,6.20286,174.33334
20.96000,174.66666,55.71391,1.51884,6.19043,174.66666
21.00000,175.00004,55.67829,1.52174,6.18648,175.00004
21.04000,175.33328,55.86105,1.52464,6.20678,175.33328
21.08000,175.66666,55.99467,1.52754,6.22163,175.66666
21.12000,176.00009,56.06325,1.53044,6.22925,176.00009
21.16000,176.33336,56.19961,1.53333,6.24440,176.33336
21.20000,176.66679,56.20956,1.53623,6.24551,176.66679
21.24000,177.00011,56.28191,1.53913,6.25355,177.00011
21.28000,177.33330,56.24581,1.54203,6.24953,177.33330
21.32000,177.66671,56.49591,1.54493,6.27732,177.66671
21.36000,178.00003,56.26662,1.54783,6.25185,178.00003
21.40000,178.33328,56.64080,1.55072,6.29342,178.33328
21.44000,178.66665,56.80210,1.55362,6.31134,178.66665
21.48000,178.99998,56.63384,1.55652,6.29265,178.99998
21.52000,179.33335,56.90505,1.55942,6.32278,179.33335
21.56000,179.66673,57.01894,1.56232,6.33544,179.66673
21.60000,179.99997,57.02702,1.56522,6.33634,179.99997
21.64000,180.33342,57.19092,1.56812,6.35455,180.33342
21.68000,180.66673,57.21883,1.57102,6.35765,180.66673
21.72000,181.00003,57.18244,1.57391,6.35360,181.00003
21.76000,181.33348,57.50230,1.57681,6.38914,181.33348
21.80000,181.66672,57.39282,1.57971,6.37698,181.66672
21.84000,182.00004,57.51449,1.58261,6.39050,182.00004
21.88000,182.33335,57.38925,1.58551,6.37658,182.33335
21.92000,182.66665,57.75588,1.58841,6.41732,182.66665
21.96000,183.00010,57.63739,1.59131,6.40415,183.00010
22.00000,183.33329,57.82044,1.59420,6.42449,183.33329
22.04000,183.66667,57.91380,1.59710,6.43487,183.66667
22.08000,184.00010,58.02254,1.60000,6.44695,184.00010
22.12000,184.33329,58.05869,1.60290,6.45097,184.33329
22.16000,184.66666,58.10978,1.60580,6.45664,184.66666
22.20000,185.00004,57.88098,1.60870,6.43122,185.00004
22.24000,185.33329,58.24693,1.61159,6.47188,185.33329
22.28000,185.66672,58.19221,1.61449,6.46580,185.66672
22.32000,186.00011,58.09194,1.61739,6.45466,186.00011
22.36000,186.33336,58.52132,1.62029,6.50237,186.33336
22.40000,186.66679,58.54826,1.62319,6.50536,186.66679
22.44000,186.99998,58.63060,1.62609,6.51451,186.99998
22.48000,187.33334,58.76487,1.62899,6.52943,187.33334
22.52000,187.66671,58.80817,1.63188,6.53424,187.66671
22.56000,188.00003,58.65652,1.63478,6.51739,188.00003
22.60000,188.33334,59.09177,1.63768,6.56575,188.33334
22.64000,188.66666,58.95766,1.64058,6.55085,188.66666
22.68000,189.00003,58.83991,1.64348,6.53777,189.00003
22.72000,189.33333,59.02168,1.64638,6.55796,189.33333
22.76000,189.66660,59.16980,1.64927,6.57442,189.66660
22.80000,190.00003,59.08012,1.65217,6.56446,190.00003
22.84000,190.33341,59.54030,1.65507,6.61559,190.33341
22.88000,190.66660,59.42921,1.65797,6.60325,190.66660
22.92000,191.00010,59.55946,1.66087,6.61772,191.00010
22.96000,191.33341,59.66854,1.66377,6.62984,191.33341
23.00000,191.66665,59.68877,1.66667,6.63209,191.66665
23.04000,192.00010,59.56254,1.66957,6.61806,192.00010
23.08000,192.33329,59.81406,1.67246,6.64601,192.33329
23.12000,192.66665,59.85154,1.67536,6.65017,192.66665
23.16000,193.00003,59.81583,1.67826,6.64620,193.00003
23.20000,193.33327,60.18310,1.68116,6.68701,193.33327
23.24000,193.66672,59.98996,1.68406,6.66555,193.66672
23.28000,194.00008,59.92800,1.68696,6.65867,194.00008
23.32000,194.33334,60.30575,1.68986,6.70064,194.33334
23.36000,194.66672,60.27176,1.69275,6.69686,194.66672
23.40000,195.00002,60.36321,1.69565,6.70702,195.00002
23.44000,195.33329,60.39681,1.69855,6.71076,195.33329
23.48000,195.66672,60.56663,1.70145,6.72963,195.66672
23.52000,196.00004,60.49321,1.70435,6.72147,196.00004
23.56000,196.33340,60.76579,1.70725,6.75175,196.33340
23.60000,196.66672,60.82080,1.71015,6.75787,196.66672
23.64000,196.99998,60.71181,1.71304,6.74576,196.99998
23.68000,197.33340,60.86816,1.71594,6.76313,197.33340
23.72000,197.66666,61.03456,1.71884,6.78162,197.66666
23.76000,198.00004,60.95075,1.72174,6.77231,198.00004
23.80000,198.33334,61.05180,1.72464,6.78353,198.33334
23.84000,198.66666,61.01344,1.72754,6.77927,198.66666
23.88000,199.00009,61.08016,1.73044,6.78668,199.00009
23.92000,199.33335,61.07590,1.73333,6.78621,199.33335
23.96000,199.66666,61.45835,1.73623,6.82871,199.66666
24.00000,200.00003,61.49548,1.73913,6.83283,200.00003
24.04000,200.33335,61.57699,1.74203,6.84189,200.33335
24.08000,200.66671,61.71683,1.74493,6.85743,200.66671
24.12000,201.00003,61.53712,1.74783,6.83746,201.00003
24.16000,201.33335,61.56572,1.75072,6.84064,201.33335
24.20000,201.66678,61.67407,1.75362,6.85267,201.66678
24.24000,202.00009,61.82258,1.75652,6.86918,202.00009
24.28000,202.33333,61.83037,1.75942,6.87004,202.33333
24.32000,202.66673,61.90576,1.76232,6.87842,202.66673
24.36000,203.00003,61.98305,1.76522,6.88701,203.00003
24.40000,203.33327,62.19108,1.76812,6.91012,203.33327
24.44000,203.66672,61.99691,1.77102,6.88855,203.66672
24.48000,203.99997,62.06191,1.77391,6.89577,203.99997
24.52000,204.33335,62.22899,1.77681,6.91433,204.33335
24.56000,204.66665,62.38304,1.77971,6.93145,204.66665
24.60000,205.00004,62.23247,1.78261,6.91472,205.00004
24.64000,205.33340,62.52563,1.78551,6.94729,205.33340
24.68000,205.66672,62.38941,1.78841,6.93216,205.66672
24.72000,206.00004,62.58073,1.79130,6.95341,206.00004
24.76000,206.33340,62.76652,1.79420,6.97406,206.33340
24.80000,206.66672,62.78440,1.79710,6.97604,206.66672
24.84000,207.00010,62.66998,1.80000,6.96333,207.00010
24.88000,207.33342,62.84945,1.80290,6.98327,207.33342
24.92000,207.66661,63.17890,1.80580,7.01988,207.66661
24.96000,208.00009,63.04944,1.80870,7.00549,208.00009
25.00000,208.33341,63.06306,1.81159,7.00701,208.33341
25.04000,208.66666,63.30581,1.81449,7.03398,208.66666
25.08000,209.00009,63.21466,1.81739,7.02385,209.00009
25.12000,209.33334,63.56483,1.82029,7.06276,209.33334
25.16000,209.66666,63.35093,1.82319,7.03899,209.66666
25.20000,210.00003,63.34990,1.82609,7.03888,210.00003
25.24000,210.33328,63.37023,1.82899,7.04114,210.33328
25.28000,210.66673,63.47182,1.83188,7.05242,210.66673
25.32000,211.00003,63.70380,1.83478,7.07820,211.00003
25.36000,211.33333,63.70752,1.83768,7.07861,211.33333
25.40000,211.66679,63.78624,1.84058,7.08736,211.66679
25.44000,212.00003,63.67177,1.84348,7.07464,212.00003
25.48000,212.33335,63.82072,1.84638,7.09119,212.33335
25.52000,212.66671,63.92113,1.84928,7.10235,212.66671
25.56000,212.99995,64.18549,1.85217,7.13172,212.99995
25.60000,213.33335,64.17520,1.85507,7.13058,213.33335
25.64000,213.66665,64.12034,1.85797,7.12448,213.66665
25.68000,214.00005,64.17324,1.86087,7.13036,214.00005
25.72000,214.33340,64.39381,1.86377,7.15487,214.33340
25.76000,214.66665,64.50221,1.86667,7.16691,214.66665
25.80000,215.00003,64.26504,1.86957,7.14056,215.00003
25.84000,215.33335,64.47218,1.87246,7.16358,215.33335
25.88000,215.66672,64.58092,1.87536,7.17566,215.66672
25.92000,216.00008,64.75804,1.87826,7.19534,216.00008
25.96000,216.33334,64.68839,1.88116,7.18760,216.33334
26.00000,216.66672,64.71210,1.88406,7.19023,216.66672
26.04000,217.00010,64.96970,1.88696,7.21886,217.00010
26.08000,217.33334,64.87908,1.88986,7.20879,217.33334
26.12000,217.66672,65.08368,1.89275,7.23152,217.66672
26.16000,218.00004,65.04097,1.89565,7.22677,218.00004
26.20000,218.33329,65.12928,1.89855,7.23659,218.33329
26.24000,218.66672,65.04973,1.90145,7.22775,218.66672
26.28000,219.00009,65.15436,1.90435,7.23937,219.00009
26.32000,219.33334,65.38663,1.90725,7.26518,219.33334
26.36000,219.66673,65.54504,1.91015,7.28278,219.66673
26.40000,219.99998,65.42126,1.91304,7.26903,219.99998
26.44000,220.33334,65.54440,1.91594,7.28271,220.33334
26.48000,220.66671,65.72711,1.91884,7.30301,220.66671
26.52000,221.00003,65.57536,1.92174,7.28615,221.00003
26.56000,221.33341,66.12818,1.92464,7.34758,221.33341
26.60000,221.66671,66.17691,1.92754,7.35299,221.66671
26.64000,222.00003,65.72711,1.93044,7.30301,222.00003
26.68000,222.33341,66.09741,1.93333,7.34416,222.33341
26.72000,222.66671,66.16604,1.93623,7.35178,222.66671
26.76000,223.00003,66.01488,1.93913,7.33499,223.00003
26.80000,223.33335,66.19523,1.94203,7.35503,223.33335
26.84000,223.66660,66.38685,1.94493,7.37632,223.66660
26.88000,224.00016,66.38215,1.94783,7.37579,224.00016
26.92000,224.33341,66.48859,1.95073,7.38762,224.33341
26.96000,224.66652,66.71861,1.95362,7.41318,224.66652
27.00000,225.00003,66.60433,1.95652,7.40048,225.00003
27.04000,225.33335,66.72150,1.95942,7.41350,225.33335
27.08000,225.66672,67.00276,1.96232,7.44475,225.66672
27.12000,226.00010,66.86619,1.96522,7.42958,226.00010
27.16000,226.33335,66.98404,1.96812,7.44267,226.33335
27.20000,226.66672,67.13261,1.97101,7.45918,226.66672
27.24000,227.00004,67.00349,1.97391,7.44483,227.00004
27.28000,227.33334,67.32795,1.97681,7.48088,227.33334
27.32000,227.66672,67.28044,1.97971,7.47560,227.66672
27.36000,227.99997,67.25207,1.98261,7.47245,227.99997
27.40000,228.33334,67.52579,1.98551,7.50287,228.33334
27.44000,228.66672,67.61229,1.98841,7.51248,228.66672
27.48000,229.00004,67.45285,1.99130,7.49476,229.00004
27.52000,229.33334,67.78353,1.99420,7.53150,229.33334
27.56000,229.66672,67.81248,1.99710,7.53472,229.66672
27.60000,229.99996,67.90858,2.00000,7.54540,229.99996
27.64000,230.33336,68.07610,2.00290,7.56401,230.33336
27.68000,230.66672,68.15349,2.00580,7.57261,230.66672
27.72000,231.00004,68.10926,2.00870,7.56770,231.00004
27.76000,231.33347,68.33639,2.01160,7.59293,231.33347
27.80000,231.66666,68.36000,2.01449,7.59556,231.66666
27.84000,232.00003,68.57572,2.01739,7.61952,232.00003
27.88000,232.33334,68.63842,2.02029,7.62649,232.33334
27.92000,232.66673,68.72884,2.02319,7.63654,232.66673
27.96000,233.00003,68.84228,2.02609,7.64914,233.00003
28.00000,233.33328,68.94383,2.02899,7.66043,233.33328
28.04000,233.66665,68.98169,2.03188,7.66463,233.66665
28.08000,234.00009,69.08646,2.03478,7.67627,234.00009
28.12000,234.33335,69.23174,2.03768,7.69242,234.33335
28.16000,234.66665,69.27347,2.04058,7.69705,234.66665
28.20000,234.99997,69.17003,2.04348,7.68556,234.99997
28.24000,235.33329,69.20940,2.04638,7.68993,235.33329
28.28000,235.66671,69.60944,2.04928,7.73438,235.66671
28.32000,236.00005,69.41200,2.05217,7.71244,236.00005
28.36000,236.33335,69.59250,2.05507,7.73250,236.33335
28.40000,236.66678,69.66519,2.05797,7.74058,236.66678
28.44000,237.00003,69.62199,2.06087,7.73578,237.00003
28.48000,237.33335,69.79817,2.06377,7.75535,237.33335
28.52000,237.66672,70.04764,2.06667,7.78307,237.66672
28.56000,237.99997,69.88478,2.06957,7.76498,237.99997
28.60000,238.33334,70.01668,2.07246,7.77963,238.33334
28.64000,238.66672,70.09128,2.07536,7.78792,238.66672
28.68000,239.00010,70.13169,2.07826,7.79241,239.00010
28.72000,239.33342,70.34378,2.08116,7.81598,239.33342
28.76000,239.66666,70.34873,2.08406,7.81653,239.66666
28.80000,240.00004,70.65556,2.08696,7.85062,240.00004
28.84000,240.33334,70.52228,2.08986,7.83581,240.33334
28.88000,240.66664,70.75882,2.09275,7.86209,240.66664
28.92000,241.00009,70.83400,2.09565,7.87044,241.00009
28.96000,241.33340,70.95577,2.09855,7.88398,241.33340
29.00000,241.66666,70.90453,2.10145,7.87828,241.66666
29.04000,242.00009,70.84424,2.10435,7.87158,242.00009
29.08000,242.33328,71.20147,2.10725,7.91127,242.33328
29.12000,242.66671,71.11251,2.11015,7.90139,242.66671
29.16000,243.00009,71.26220,2.11304,7.91802,243.00009
29.20000,243.33328,71.37237,2.11594,7.93026,243.33328
29.24000,243.66671,71.38456,2.11884,7.93162,243.66671
29.28000,244.00003,71.49761,2.12174,7.94418,244.00003
29.32000,244.33335,71.50815,2.12464,7.94535,244.33335
29.36000,244.66671,71.60851,2.12754,7.95650,244.66671
29.40000,244.99997,71.36135,2.13043,7.92904,244.99997
29.44000,245.33328,71.79067,2.13333,7.97674,245.33328
29.48000,245.66673,71.73714,2.13623,7.97079,245.66673
29.52000,246.00003,71.61566,2.13913,7.95730,246.00003
29.56000,246.33341,71.75090,2.14203,7.97232,246.33341
29.60000,246.66678,71.86023,2.14493,7.98447,246.66678
29.64000,247.00003,71.89334,2.14783,7.98815,247.00003
29.68000,247.33340,72.27800,2.15073,8.03089,247.33340
29.72000,247.66672,72.42989,2.15362,8.04777,247.66672
29.76000,248.00003,72.08555,2.15652,8.00951,248.00003
29.80000,248.33340,72.36729,2.15942,8.04081,248.33340
29.84000,248.66665,72.51679,2.16232,8.05742,248.66665
29.88000,249.00010,72.56322,2.16522,8.06258,249.00010
29.92000,249.33334,72.64296,2.16812,8.07144,249.33334
29.96000,249.66672,72.86608,2.17102,8.09623,249.66672
30.00000,250.00004,72.90081,2.17391,8.10009,250.00004
30.04000,250.33329,72.97296,2.17681,8.10811,250.33329
30.08000,250.66672,73.02904,2.17971,8.11434,250.66672
30.12000,251.00008,73.16453,2.18261,8.12939,251.00008
30.16000,251.33340,73.39279,2.18551,8.15475,251.33340
30.20000,251.66675,73.31010,2.18841,8.14557,251.66675
30.24000,252.00000,73.46190,2.19130,8.16243,252.00000
30.28000,252.33334,73.42864,2.19420,8.15874,252.33334
30.32000,252.66677,73.83255,2.19710,8.20362,252.66677
30.36000,253.00009,73.57270,2.20000,8.17474,253.00009
30.40000,253.33334,73.89035,2.20290,8.21004,253.33334
30.44000,253.66670,73.85900,2.20580,8.20656,253.66670
30.48000,254.00002,73.91822,2.20870,8.21313,254.00002
30.52000,254.33332,74.19144,2.21159,8.24349,254.33332
30.56000,254.66671,74.05165,2.21449,8.22796,254.66671
30.60000,254.99998,73.97719,2.21739,8.21969,254.99998
30.64000,255.33339,74.02603,2.22029,8.22511,255.33339
30.68000,255.66671,74.31620,2.22319,8.25736,255.66671
30.72000,256.00007,74.33339,2.22609,8.25927,256.00007
30.76000,256.33339,74.65192,2.22899,8.29466,256.33339
30.80000,256.66669,74.63909,2.23188,8.29323,256.66669
30.84000,257.00008,74.58840,2.23478,8.28760,257.00008
30.88000,257.33335,74.89581,2.23768,8.32176,257.33335
30.92000,257.66671,74.96149,2.24058,8.32905,257.66671
30.96000,258.00014,74.92378,2.24348,8.32486,258.00014
31.00000,258.33333,75.13984,2.24638,8.34887,258.33333
31.04000,258.66663,75.30834,2.24927,8.36759,258.66663
31.08000,259.00010,75.10149,2.25217,8.34461,259.00010
31.12000,259.33335,75.25691,2.25507,8.36188,259.33335
31.16000,259.66665,75.46797,2.25797,8.38533,259.66665
31.20000,260.00002,75.39612,2.26087,8.37735,260.00002
31.24000,260.33327,75.70186,2.26377,8.41132,260.33327
31.28000,260.66676,75.79052,2.26667,8.42117,260.66676
31.32000,261.00008,75.94363,2.26957,8.43818,261.00008
31.36000,261.33332,76.15632,2.27246,8.46181,261.33332
31.40000,261.66677,75.98561,2.27536,8.44285,261.66677
31.44000,262.00002,76.11929,2.27826,8.45770,262.00002
31.48000,262.33340,76.23856,2.28116,8.47095,262.33340
31.52000,262.66677,76.31022,2.28406,8.47891,262.66677
31.56000,263.00002,76.48440,2.28696,8.49827,263.00002
31.60000,263.33332,76.58477,2.28986,8.50942,263.33332
31.64000,263.66672,76.77188,2.29275,8.53021,263.66672
31.68000,264.00004,76.39574,2.29565,8.48842,264.00004
31.72000,264.33339,76.56174,2.29855,8.50686,264.33339
31.76000,264.66671,76.77007,2.30145,8.53001,264.66671
31.80000,265.00002,76.87298,2.30435,8.54144,265.00002
31.84000,265.33334,77.38533,2.30725,8.59837,265.33334
31.88000,265.66664,77.16613,2.31014,8.57401,265.66664
31.92000,266.00009,77.30672,2.31304,8.58963,266.00009
31.96000,266.33341,77.27444,2.31594,8.58605,266.33341
32.00000,266.66671,77.51577,2.31884,8.61286,266.66671
32.04000,267.00009,77.50930,2.32174,8.61214,267.00009
32.08000,267.33333,77.76112,2.32464,8.64012,267.33333
32.12000,267.66671,77.80207,2.32754,8.64467,267.66671
32.16000,268.00007,77.69534,2.33044,8.63282,268.00007
32.20000,268.33331,78.11811,2.33333,8.67979,268.33331
32.24000,268.66673,78.16038,2.33623,8.68449,268.66673
32.28000,269.00008,78.21950,2.33913,8.69106,269.00008
32.32000,269.33333,78.49988,2.34203,8.72221,269.33333
32.36000,269.66671,78.27069,2.34493,8.69674,269.66671
32.40000,269.99995,78.42797,2.34783,8.71422,269.99995
32.44000,270.33333,78.46593,2.35072,8.71844,270.33333
32.48000,270.66672,78.60362,2.35362,8.73374,270.66672
32.52000,271.00002,78.73377,2.35652,8.74820,271.00002
32.56000,271.33340,78.93895,2.35942,8.77100,271.33340
32.60000,271.66670,79.27046,2.36232,8.80783,271.66670
32.64000,272.00002,79.08272,2.36522,8.78697,272.00002
32.68000,272.33338,79.29206,2.36812,8.81023,272.33338
32.72000,272.66670,79.21482,2.37101,8.80165,272.66670
32.76000,273.00010,79.13366,2.37391,8.79263,273.00010
32.80000,273.33340,79.27600,2.37681,8.80844,273.33340
32.84000,273.66666,79.64195,2.37971,8.84910,273.66666
32.88000,274.00007,79.58160,2.38261,8.84240,274.00007
32.92000,274.33334,79.70195,2.38551,8.85577,274.33334
32.96000,274.66664,79.87402,2.38841,8.87489,274.66664
33.00000,275.00007,79.91615,2.39130,8.87957,275.00007
33.04000,275.33332,79.98188,2.39420,8.88688,275.33332
33.08000,275.66666,79.99907,2.39710,8.88879,275.66666
33.12000,276.00009,80.01308,2.40000,8.89034,276.00009
33.16000,276.33334,80.09244,2.40290,8.89916,276.33334
33.20000,276.66677,80.31844,2.40580,8.92427,276.66677
33.24000,277.00007,80.51300,2.40870,8.94589,277.00007
33.28000,277.33326,80.67307,2.41159,8.96367,277.33326
33.32000,277.66678,80.69893,2.41449,8.96655,277.66678
33.36000,278.00003,80.73905,2.41739,8.97101,278.00003
33.40000,278.33333,80.92455,2.42029,8.99162,278.33333
33.44000,278.66671,80.82173,2.42319,8.98019,278.66671
33.48000,279.00001,80.92700,2.42609,8.99189,279.00001
33.52000,279.33339,81.25625,2.42899,9.02847,279.33339
33.56000,279.66669,81.23597,2.43188,9.02622,279.66669
33.60000,279.99995,81.24455,2.43478,9.02717,279.99995
33.64000,280.33340,81.38302,2.43768,9.04256,280.33340
33.68000,280.66671,81.54873,2.44058,9.06097,280.66671
33.72000,281.00003,81.57920,2.44348,9.06435,281.00003
33.76000,281.33338,81.86530,2.44638,9.09614,281.33338
33.80000,281.66670,81.76988,2.44928,9.08554,281.66670
33.84000,282.00006,81.81230,2.45217,9.09026,282.00006
33.88000,282.33340,82.01284,2.45507,9.11254,282.33340
33.92000,282.66666,82.20450,2.45797,9.13383,282.66666
33.96000,283.00008,82.22263,2.46087,9.13585,283.00008
34.00000,283.33334,82.47920,2.46377,9.16436,283.33334
34.04000,283.66670,82.53200,2.46667,9.17022,283.66670
34.08000,284.00002,82.66180,2.46957,9.18464,284.00002
34.12000,284.33332,82.79655,2.47246,9.19962,284.33332
34.16000,284.66672,82.63452,2.47536,9.18161,284.66672
34.20000,285.00004,82.55678,2.47826,9.17298,285.00004
34.24000,285.33328,82.65602,2.48116,9.18400,285.33328
34.28000,285.66672,67.30600,2.48406,7.47844,285.66672
34.32000,286.00007,0.77570,2.48696,0.08619,286.00007
34.36000,286.33339,-1.93794,2.48986,-0.21533,286.33339
34.40000,286.66684,0.32252,2.49276,0.03584,286.66684
34.44000,287.00003,0.03389,2.49565,0.00377,287.00003
34.48000,287.33334,0.00746,2.49855,0.00083,287.33334
34.52000,287.66671,-0.12751,2.50145,-0.01417,287.66671
34.56000,287.99996,-0.22562,2.50435,-0.02507,287.99996
34.56400,288.03334,-0.15450,2.50464,-0.01717,288.03334