File: V_7/NR/RDSO NR Tensile 500.is_tens_RawData/Specimen_RawData_3.csv
Time,Extension,Load,Tensile strain,Tensile stress,Corrected Position
(sec),(mm),(N),(mm/mm),(MPa),(mm)
0.00000,0.00000,-0.06329,0.00000,-0.00703,0.00000
0.03000,0.05131,0.35130,0.00045,0.03903,0.05131
0.06000,0.23375,0.98562,0.00203,0.10951,0.23375
0.09000,0.51712,1.45575,0.00450,0.16175,0.51712
0.12000,0.83325,1.62258,0.00725,0.18029,0.83325
0.15000,1.16412,2.07508,0.01012,0.23056,1.16412
0.18000,1.47400,2.41267,0.01282,0.26807,1.47400
0.21000,1.73775,2.72672,0.01511,0.30297,1.73775
0.24000,1.98569,3.47291,0.01727,0.38588,1.98569
0.27000,2.23706,3.86399,0.01945,0.42933,2.23706
0.30000,2.49162,4.23970,0.02167,0.47108,2.49162
0.33000,2.74519,4.66041,0.02387,0.51782,2.74519
0.36000,2.99700,4.78603,0.02606,0.53178,2.99700
0.39000,3.24787,5.05494,0.02824,0.56166,3.24787
0.42000,3.49837,5.37641,0.03042,0.59738,3.49837
0.45000,3.74894,5.78706,0.03260,0.64301,3.74894
0.48000,3.99937,6.04059,0.03478,0.67118,3.99937
0.51000,4.24956,6.28143,0.03695,0.69794,4.24956
0.54000,4.49962,6.73170,0.03913,0.74797,4.49962
0.57000,4.74981,6.94801,0.04130,0.77200,4.74981
0.60000,4.99987,7.13715,0.04348,0.79302,4.99987
0.63000,5.24987,7.44239,0.04565,0.82693,5.24987
0.66000,5.49994,7.63283,0.04783,0.84809,5.49994
0.69000,5.75000,7.87909,0.05000,0.87545,5.75000
0.72000,6.00000,7.98462,0.05217,0.88718,6.00000
0.75000,6.24994,8.18263,0.05435,0.90918,6.24994
0.78000,6.50000,8.49164,0.05652,0.94352,6.50000
0.81000,6.75006,8.87534,0.05870,0.98615,6.75006
0.84000,6.99994,8.98496,0.06087,0.99833,6.99994
0.87000,7.24994,9.28880,0.06304,1.03209,7.24994
0.90000,7.50000,9.33714,0.06522,1.03746,7.50000
0.93000,7.75000,9.55112,0.06739,1.06124,7.75000
0.96000,7.99994,9.74137,0.06956,1.08237,7.99994
0.99000,8.25000,10.04528,0.07174,1.11614,8.25000
1.02000,8.50006,10.05371,0.07391,1.11708,8.50006
1.05000,8.75000,10.32835,0.07609,1.14759,8.75000
1.08000,9.00000,10.35380,0.07826,1.15042,9.00000
1.11000,9.25006,10.50089,0.08044,1.16677,9.25006
1.14000,9.50006,10.70397,0.08261,1.18933,9.50006
1.17000,9.75000,10.96230,0.08478,1.21803,9.75000
1.20000,10.00000,11.02172,0.08696,1.22464,10.00000
1.23000,10.25006,10.89424,0.08913,1.21047,10.25006
1.26000,10.50000,11.02471,0.09130,1.22497,10.50000
1.29000,10.74994,11.30817,0.09348,1.25646,10.74994
1.32000,11.00000,11.49854,0.09565,1.27762,11.00000
1.35000,11.25006,11.54044,0.09783,1.28227,11.25006
1.38000,11.49994,11.55954,0.10000,1.28439,11.49994
1.41000,11.74994,11.71097,0.10217,1.30122,11.74994
1.44000,12.00000,12.01241,0.10435,1.33471,12.00000
1.47000,12.25000,12.12798,0.10652,1.34755,12.25000
1.50000,12.49994,12.11319,0.10870,1.34591,12.49994
1.53000,12.75000,12.30378,0.11087,1.36709,12.75000
1.56000,13.00006,12.34123,0.11304,1.37125,13.00006
1.59000,13.25000,12.25088,0.11522,1.36121,13.25000
1.62000,13.50000,12.27099,0.11739,1.36344,13.50000
1.65000,13.75006,12.50710,0.11957,1.38968,13.75006
1.68000,14.00006,12.57926,0.12174,1.39770,14.00006
1.71000,14.25000,12.63708,0.12391,1.40412,14.25000
1.74000,14.50006,12.58668,0.12609,1.39852,14.50006
1.77000,14.75006,12.85463,0.12826,1.42829,14.75006
1.80000,15.00000,13.02306,0.13043,1.44701,15.00000
1.83000,15.25000,12.92211,0.13261,1.43579,15.25000
1.86000,15.50006,12.99372,0.13478,1.44375,15.50006
1.89000,15.75006,12.89213,0.13696,1.43246,15.75006
1.92000,16.00000,13.15063,0.13913,1.46118,16.00000
1.95000,16.24993,13.34779,0.14130,1.48309,16.24993
1.98000,16.50006,13.36775,0.14348,1.48531,16.50006
2.01000,16.75006,13.28913,0.14565,1.47657,16.75006
2.04000,17.00000,13.47639,0.14783,1.49738,17.00000
2.07000,17.25000,13.50517,0.15000,1.50057,17.25000
2.10000,17.50000,13.49165,0.15217,1.49907,17.50000
2.13000,17.74994,13.70306,0.15435,1.52256,17.74994
2.16000,17.99993,13.57480,0.15652,1.50831,17.99993
2.19000,18.25006,13.70435,0.15870,1.52271,18.25006
2.22000,18.50006,13.61308,0.16087,1.51256,18.50006
2.25000,18.75000,13.68378,0.16304,1.52042,18.75000
2.28000,19.00006,13.80398,0.16522,1.53378,19.00006
2.31000,19.25006,13.85137,0.16739,1.53904,19.25006
2.34000,19.50000,13.83320,0.16957,1.53702,19.50000
2.37000,19.75000,13.92617,0.17174,1.54735,19.75000
2.40000,20.00006,13.96398,0.17391,1.55155,20.00006
2.43000,20.25000,14.04664,0.17609,1.56074,20.25000
2.46000,20.50000,13.93523,0.17826,1.54836,20.50000
2.49000,20.75000,13.84466,0.18043,1.53830,20.75000
2.52000,21.00006,14.21113,0.18261,1.57901,21.00006
2.55000,21.25000,14.11088,0.18478,1.56788,21.25000
2.58000,21.49994,14.27661,0.18696,1.58629,21.49994
2.61000,21.75000,14.32959,0.18913,1.59218,21.75000
2.64000,22.00000,14.25636,0.19130,1.58404,22.00000
2.67000,22.24993,14.32508,0.19348,1.59168,22.24993
2.70000,22.49993,14.31313,0.19565,1.59035,22.49993
2.73000,22.75000,14.39934,0.19783,1.59993,22.75000
2.76000,23.00000,14.40157,0.20000,1.60017,23.00000
2.79000,23.25000,14.47073,0.20217,1.60786,23.25000
2.82000,23.50006,14.59916,0.20435,1.62213,23.50006
2.85000,23.75006,14.57215,0.20652,1.61913,23.75006
2.88000,24.00006,14.50646,0.20870,1.61183,24.00006
2.91000,24.25000,14.80068,0.21087,1.64452,24.25000
2.94000,24.50006,14.82110,0.21304,1.64679,24.50006
2.97000,24.75006,14.83232,0.21522,1.64804,24.75006
3.00000,24.99993,14.83053,0.21739,1.64784,24.99993
3.03000,25.25006,14.88595,0.21957,1.65399,25.25006
3.06000,25.50012,14.72372,0.22174,1.63597,25.50012
3.09000,25.74993,14.88659,0.22391,1.65407,25.74993
3.12000,25.99987,15.06085,0.22609,1.67343,25.99987
3.15000,26.25000,15.11343,0.22826,1.67927,26.25000
3.18000,26.50006,14.97052,0.23044,1.66339,26.50006
3.21000,26.75000,15.00385,0.23261,1.66709,26.75000
3.24000,27.00000,15.21257,0.23478,1.69029,27.00000
3.27000,27.25000,15.27289,0.23696,1.69699,27.25000
3.30000,27.49993,15.20774,0.23913,1.68975,27.49993
3.33000,27.74993,15.18685,0.24130,1.68743,27.74993
3.36000,28.00006,15.26650,0.24348,1.69628,28.00006
3.39000,28.25006,15.57469,0.24565,1.73052,28.25006
3.42000,28.50000,15.58427,0.24783,1.73159,28.50000
3.45000,28.75000,15.15856,0.25000,1.68428,28.75000
3.48000,29.00006,15.46125,0.25217,1.71792,29.00006
3.51000,29.25006,15.53784,0.25435,1.72643,29.25006
3.54000,29.50000,15.60663,0.25652,1.73407,29.50000
3.57000,29.75006,15.68650,0.25870,1.74294,29.75006
3.60000,30.00006,15.57396,0.26087,1.73044,30.00006
3.63000,30.25006,15.66110,0.26304,1.74012,30.25006
3.66000,30.49999,15.79404,0.26522,1.75489,30.49999
3.69000,30.75000,15.66448,0.26739,1.74050,30.75000
3.72000,31.00000,15.71192,0.26957,1.74577,31.00000
3.75000,31.24993,15.96058,0.27174,1.77340,31.24993
3.78000,31.49999,15.88926,0.27391,1.76547,31.49999
3.81000,31.75006,15.87375,0.27609,1.76375,31.75006
3.84000,31.99999,16.06092,0.27826,1.78455,31.99999
3.87000,32.24999,16.14147,0.28043,1.79350,32.24999
3.90000,32.50000,16.22413,0.28261,1.80268,32.50000
3.93000,32.75000,16.21472,0.28478,1.80164,32.75000
3.96000,32.99993,16.10162,0.28696,1.78907,32.99993
3.99000,33.24999,16.09192,0.28913,1.78799,33.24999
4.02000,33.50006,16.20593,0.29130,1.80066,33.50006
4.05000,33.75006,16.18048,0.29348,1.79783,33.75006
4.08000,34.00000,16.48944,0.29565,1.83216,34.00000
4.11000,34.25006,16.50002,0.29783,1.83334,34.25006
4.14000,34.50006,16.30703,0.30000,1.81189,34.50006
4.17000,34.75000,16.52696,0.30217,1.83633,34.75000
4.20000,34.99999,16.47117,0.30435,1.83013,34.99999
4.23000,35.25006,16.65324,0.30652,1.85036,35.25006
4.26000,35.49999,16.68706,0.30870,1.85412,35.49999
4.29000,35.74993,16.92981,0.31087,1.88109,35.74993
4.32000,35.99999,16.78801,0.31304,1.86533,35.99999
4.35000,36.25000,16.80895,0.31522,1.86766,36.25000
4.38000,36.50000,16.93687,0.31739,1.88187,36.50000
4.41000,36.74999,17.03917,0.31957,1.89324,36.74999
4.44000,36.99999,17.04507,0.32174,1.89390,36.99999
4.47000,37.24993,17.14414,0.32391,1.90490,37.24993
4.50000,37.49993,17.13801,0.32609,1.90422,37.49993
4.53000,37.74999,16.97686,0.32826,1.88632,37.74999
4.56000,38.00006,17.18207,0.33044,1.90912,38.00006
4.59000,38.25000,17.28104,0.33261,1.92012,38.25000
4.62000,38.50000,17.13583,0.33478,1.90398,38.50000
4.65000,38.75006,17.29498,0.33696,1.92166,38.75006
4.68000,39.00006,17.33632,0.33913,1.92626,39.00006
4.71000,39.24999,17.36899,0.34130,1.92989,39.24999
4.74000,39.49999,17.48094,0.34348,1.94233,39.49999
4.77000,39.75006,17.60405,0.34565,1.95601,39.75006
4.80000,39.99999,17.57802,0.34783,1.95311,39.99999
4.83000,40.25000,17.42473,0.35000,1.93608,40.25000
4.86000,40.50006,17.53460,0.35217,1.94829,40.50006
4.89000,40.75006,17.72107,0.35435,1.96901,40.75006
4.92000,40.99999,17.71331,0.35652,1.96815,40.99999
4.95000,41.25000,17.65735,0.35870,1.96193,41.25000
4.98000,41.50006,17.91120,0.36087,1.99013,41.50006
5.01000,41.74999,17.94774,0.36304,1.99419,41.74999
5.04000,41.99993,17.87118,0.36522,1.98569,41.99993
5.07000,42.24999,17.92638,0.36739,1.99182,42.24999
5.10000,42.50005,17.90214,0.36957,1.98913,42.50005
5.13000,42.74993,17.98999,0.37174,1.99889,42.74993
5.16000,42.99993,18.07629,0.37391,2.00848,42.99993
5.19000,43.25006,18.43847,0.37609,2.04872,43.25006
5.22000,43.50006,18.37528,0.37826,2.04170,43.50006
5.25000,43.75006,18.36818,0.38044,2.04091,43.75006
5.28000,44.00006,18.43004,0.38261,2.04778,44.00006
5.31000,44.25006,18.30827,0.38478,2.03425,44.25006
5.34000,44.49999,18.47322,0.38696,2.05258,44.49999
5.37000,44.74999,18.65428,0.38913,2.07270,44.74999
5.40000,45.00006,18.64826,0.39130,2.07203,45.00006
5.43000,45.25006,18.68117,0.39348,2.07569,45.25006
5.46000,45.49999,18.79050,0.39565,2.08783,45.49999
5.49000,45.75000,18.44900,0.39783,2.04989,45.75000
5.52000,45.99999,18.68069,0.40000,2.07563,45.99999
5.55000,46.24999,18.86366,0.40217,2.09596,46.24999
5.58000,46.49993,18.95178,0.40435,2.10575,46.49993
5.61000,46.75000,18.89694,0.40652,2.09966,46.75000
5.64000,47.00006,18.89221,0.40870,2.09913,47.00006
5.67000,47.24999,18.92170,0.41087,2.10241,47.24999
5.70000,47.49993,19.11337,0.41304,2.12371,47.49993
5.73000,47.74999,19.21655,0.41522,2.13517,47.74999
5.76000,47.99999,19.28099,0.41739,2.14233,47.99999
5.79000,48.24993,19.33933,0.41956,2.14881,48.24993
5.82000,48.50006,19.26448,0.42174,2.14050,48.50006
5.85000,48.75012,19.41148,0.42391,2.15683,48.75012
5.88000,49.00006,19.48375,0.42609,2.16486,49.00006
5.91000,49.25000,19.39952,0.42826,2.15550,49.25000
5.94000,49.50006,19.53932,0.43044,2.17104,49.50006
5.97000,49.74999,19.61267,0.43261,2.17919,49.74999
6.00000,49.99993,19.72183,0.43478,2.19131,49.99993
6.03000,50.24999,19.55906,0.43696,2.17323,50.24999
6.06000,50.50005,19.73395,0.43913,2.19266,50.50005
6.09000,50.74999,19.67500,0.44130,2.18611,50.74999
6.12000,50.99999,19.67476,0.44348,2.18608,50.99999
6.15000,51.24993,19.99899,0.44565,2.22211,51.24993
6.18000,51.49999,19.81634,0.44783,2.20182,51.49999
6.21000,51.74999,19.95770,0.45000,2.21752,51.74999
6.24000,51.99999,20.00558,0.45217,2.22284,51.99999
6.27000,52.25006,20.02248,0.45435,2.22472,52.25006
6.30000,52.49999,20.12576,0.45652,2.23620,52.49999
6.33000,52.74987,20.19554,0.45869,2.24395,52.74987
6.36000,52.99999,20.37202,0.46087,2.26356,52.99999
6.39000,53.25005,20.20078,0.46304,2.24453,53.25005
6.42000,53.50005,20.30418,0.46522,2.25602,53.50005
6.45000,53.75005,20.42803,0.46739,2.26978,53.75005
6.48000,54.00012,20.40339,0.46957,2.26704,54.00012
6.51000,54.25006,20.20484,0.47174,2.24498,54.25006
6.54000,54.49993,20.20932,0.47391,2.24548,54.49993
6.57000,54.75000,20.24667,0.47609,2.24963,54.75000
6.60000,55.00006,20.45735,0.47826,2.27304,55.00006
6.63000,55.24999,20.60877,0.48043,2.28986,55.24999
6.66000,55.49999,20.78102,0.48261,2.30900,55.49999
6.69000,55.75005,20.60199,0.48478,2.28911,55.75005
6.72000,55.99999,20.89255,0.48696,2.32139,55.99999
6.75000,56.24993,20.92549,0.48913,2.32505,56.24993
6.78000,56.49999,20.84658,0.49130,2.31629,56.49999
6.81000,56.75005,21.02975,0.49348,2.33664,56.75005
6.84000,57.00005,20.93982,0.49565,2.32665,57.00005
6.87000,57.24999,21.05260,0.49783,2.33918,57.24999
6.90000,57.49999,21.14062,0.50000,2.34896,57.49999
6.93000,57.74999,21.17400,0.50217,2.35267,57.74999
6.96000,57.99993,21.11145,0.50435,2.34572,57.99993
6.99000,58.24999,21.34983,0.50652,2.37220,58.24999
7.02000,58.50011,21.58359,0.50870,2.39818,58.50011
7.05000,58.75005,21.53055,0.51087,2.39228,58.75005
7.08000,59.00005,21.51605,0.51304,2.39067,59.00005
7.11000,59.25005,21.68758,0.51522,2.40973,59.25005
7.14000,59.50006,21.54345,0.51739,2.39372,59.50006
7.17000,59.74993,21.64659,0.51956,2.40518,59.74993
7.20000,59.99999,21.75339,0.52174,2.41704,59.99999
7.23000,60.25005,21.77034,0.52391,2.41893,60.25005
7.26000,60.50006,21.70571,0.52609,2.41175,60.50006
7.29000,60.74999,21.71320,0.52826,2.41258,60.74999
7.32000,60.99999,21.90369,0.53043,2.43374,60.99999
7.35000,61.24999,21.84411,0.53261,2.42712,61.24999
7.38000,61.49993,21.80938,0.53478,2.42326,61.49993
7.41000,61.74999,21.87893,0.53696,2.43099,61.74999
7.44000,62.00006,21.90335,0.53913,2.43371,62.00006
7.47000,62.25005,22.09247,0.54130,2.45472,62.25005
7.50000,62.49993,22.18997,0.54348,2.46555,62.49993
7.53000,62.74999,22.07041,0.54565,2.45227,62.74999
7.56000,63.00006,22.20427,0.54783,2.46714,63.00006
7.59000,63.24999,22.39947,0.55000,2.48883,63.24999
7.62000,63.50006,22.54544,0.55217,2.50505,63.50006
7.65000,63.75011,22.37880,0.55435,2.48653,63.75011
7.68000,64.00005,22.25495,0.55652,2.47277,64.00005
7.71000,64.24999,22.46459,0.55870,2.49607,64.24999
7.74000,64.49999,22.52741,0.56087,2.50305,64.49999
7.77000,64.75005,22.52574,0.56304,2.50286,64.75005
7.80000,64.99999,22.57576,0.56522,2.50842,64.99999
7.83000,65.24999,22.61372,0.56739,2.51264,65.24999
7.86000,65.49999,22.83739,0.56957,2.53749,65.49999
7.89000,65.74999,22.78251,0.57174,2.53139,65.74999
7.92000,65.99993,22.73556,0.57391,2.52617,65.99993
7.95000,66.24999,22.84971,0.57609,2.53886,66.24999
7.98000,66.50005,23.02921,0.57826,2.55880,66.50005
8.01000,66.75005,22.90399,0.58044,2.54489,66.75005
8.04000,66.99999,23.00109,0.58261,2.55568,66.99999
8.07000,67.24999,23.11765,0.58478,2.56863,67.24999
8.10000,67.49999,23.17976,0.58696,2.57553,67.49999
8.13000,67.74993,23.27706,0.58913,2.58634,67.74993
8.16000,67.99993,23.36853,0.59130,2.59650,67.99993
8.19000,68.24999,23.16408,0.59348,2.57379,68.24999
8.22000,68.50005,23.12401,0.59565,2.56933,68.50005
8.25000,68.74999,23.42807,0.59783,2.60312,68.74999
8.28000,69.00005,23.78194,0.60000,2.64244,69.00005
8.31000,69.25012,23.65907,0.60217,2.62879,69.25012
8.34000,69.50005,23.67026,0.60435,2.63003,69.50005
8.37000,69.74993,23.63387,0.60652,2.62599,69.74993
8.40000,69.99999,23.63402,0.60870,2.62600,69.99999
8.43000,70.25005,23.58567,0.61087,2.62063,70.25005
8.46000,70.49999,23.70475,0.61304,2.63386,70.49999
8.49000,70.74999,23.86276,0.61522,2.65142,70.74999
8.52000,70.99999,23.87893,0.61739,2.65321,70.99999
8.55000,71.24993,24.04221,0.61956,2.67136,71.24993
8.58000,71.49999,24.17468,0.62174,2.68608,71.49999
8.61000,71.75006,24.27569,0.62391,2.69730,71.75006
8.64000,71.99999,24.16001,0.62609,2.68445,71.99999
8.67000,72.24999,24.03063,0.62826,2.67007,72.24999
8.70000,72.49999,24.25825,0.63043,2.69536,72.49999
8.73000,72.74999,24.24985,0.63261,2.69443,72.74999
8.76000,72.99999,24.44357,0.63478,2.71595,72.99999
8.79000,73.24993,24.43916,0.63696,2.71546,73.24993
8.82000,73.50005,24.37661,0.63913,2.70851,73.50005
8.85000,73.75005,24.42354,0.64130,2.71373,73.75005
8.88000,74.00006,24.58836,0.64348,2.73204,74.00006
8.91000,74.24999,24.43914,0.64565,2.71546,74.24999
8.94000,74.50006,24.60749,0.64783,2.73417,74.50006
8.97000,74.75005,24.53265,0.65000,2.72585,74.75005
9.00000,74.99999,24.66098,0.65217,2.74011,74.99999
9.03000,75.24999,24.63014,0.65435,2.73668,75.24999
9.06000,75.50005,24.64567,0.65652,2.73841,75.50005
9.09000,75.74999,24.87726,0.65870,2.76414,75.74999
9.12000,75.99999,24.89556,0.66087,2.76617,75.99999
9.15000,76.25006,24.99553,0.66304,2.77728,76.25006
9.18000,76.50005,25.20128,0.66522,2.80014,76.50005
9.21000,76.74993,25.17527,0.66739,2.79725,76.74993
9.24000,76.99999,25.23201,0.66957,2.80356,76.99999
9.27000,77.25005,25.14203,0.67174,2.79356,77.25005
9.30000,77.49998,25.34737,0.67391,2.81637,77.49998
9.33000,77.74992,25.40002,0.67609,2.82222,77.74992
9.36000,77.99999,25.29317,0.67826,2.81035,77.99999
9.39000,78.24999,25.31396,0.68043,2.81266,78.24999
9.42000,78.49999,25.39116,0.68261,2.82124,78.49999
9.45000,78.74999,25.53957,0.68478,2.83773,78.74999
9.48000,79.00012,25.59713,0.68696,2.84413,79.00012
9.51000,79.25005,25.73465,0.68913,2.85941,79.25005
9.54000,79.49999,25.80168,0.69130,2.86685,79.49999
9.57000,79.74998,25.73082,0.69348,2.85898,79.74998
9.60000,79.99999,25.71946,0.69565,2.85772,79.99999
9.63000,80.24999,25.76548,0.69783,2.86283,80.24999
9.66000,80.49999,25.88713,0.70000,2.87635,80.49999
9.69000,80.75004,25.82068,0.70217,2.86896,80.75004
9.72000,80.99998,26.04030,0.70435,2.89337,80.99998
9.75000,81.24992,26.18156,0.70652,2.90906,81.24992
9.78000,81.49993,26.20346,0.70869,2.91150,81.49993
9.81000,81.74999,26.20711,0.71087,2.91190,81.74999
9.84000,81.99993,26.25915,0.71304,2.91768,81.99993
9.87000,82.24992,26.29890,0.71522,2.92210,82.24992
9.90000,82.49999,26.23686,0.71739,2.91521,82.49999
9.93000,82.74999,26.25356,0.71957,2.91706,82.74999
9.96000,82.99992,26.34328,0.72174,2.92703,82.99992
9.99000,83.24993,26.45197,0.72391,2.93911,83.24993
10.02000,83.50004,26.55466,0.72609,2.95052,83.50004
10.05000,83.75005,26.50702,0.72826,2.94522,83.75005
10.08000,83.99999,26.46284,0.73043,2.94032,83.99999
10.11000,84.25005,26.44940,0.73261,2.93882,84.25005
10.14000,84.50005,26.54814,0.73478,2.94979,84.50005
10.17000,84.74999,26.68868,0.73696,2.96541,84.74999
10.20000,84.99999,26.96224,0.73913,2.99580,84.99999
10.23000,85.25005,26.78262,0.74130,2.97585,85.25005
10.26000,85.50005,26.82957,0.74348,2.98106,85.50005
10.29000,85.74999,26.81975,0.74565,2.97997,85.74999
10.32000,86.00005,26.97000,0.74783,2.99667,86.00005
10.35000,86.25005,27.17218,0.75000,3.01913,86.25005
10.38000,86.49998,27.07610,0.75217,3.00846,86.49998
10.41000,86.74999,27.20813,0.75435,3.02313,86.74999
10.44000,87.00005,27.32204,0.75652,3.03578,87.00005
10.47000,87.25005,27.18190,0.75870,3.02021,87.25005
10.50000,87.49999,27.32838,0.76087,3.03649,87.49999
10.53000,87.74999,27.47731,0.76304,3.05303,87.74999
10.56000,87.99999,27.46957,0.76522,3.05218,87.99999
10.59000,88.24993,27.60175,0.76739,3.06686,88.24993
10.62000,88.49998,27.70273,0.76957,3.07808,88.49998
10.65000,88.75005,27.58174,0.77174,3.06464,88.75005
10.68000,89.00005,27.47886,0.77391,3.05321,89.00005
10.71000,89.24999,27.70628,0.77609,3.07848,89.24999
10.74000,89.49999,27.88879,0.77826,3.09875,89.49999
10.77000,89.75005,27.81414,0.78044,3.09046,89.75005
10.80000,89.99999,27.74988,0.78261,3.08332,89.99999
10.83000,90.24998,28.00000,0.78478,3.11111,90.24998
10.86000,90.50005,28.01847,0.78696,3.11316,90.50005
10.89000,90.75006,28.06728,0.78913,3.11859,90.75006
10.92000,90.99999,28.12542,0.79130,3.12505,90.99999
10.95000,91.24992,28.08871,0.79348,3.12097,91.24992
10.98000,91.50005,27.90762,0.79565,3.10085,91.50005
11.01000,91.75004,28.14533,0.79783,3.12726,91.75004
11.04000,91.99998,28.36277,0.80000,3.15142,91.99998
11.07000,92.24999,28.41572,0.80217,3.15730,92.24999
11.10000,92.49998,28.34626,0.80435,3.14958,92.49998
11.13000,92.74987,28.45392,0.80652,3.16155,92.74987
11.16000,92.99998,28.40614,0.80870,3.15624,92.99998
11.19000,93.25005,28.44545,0.81087,3.16061,93.25005
11.22000,93.50005,28.37655,0.81304,3.15295,93.50005
11.25000,93.74992,28.51924,0.81522,3.16880,93.74992
11.28000,94.00005,28.92099,0.81739,3.21344,94.00005
11.31000,94.25005,28.69107,0.81957,3.18790,94.25005
11.34000,94.50004,28.66352,0.82174,3.18484,94.50004
11.37000,94.74998,28.86053,0.82391,3.20673,94.74998
11.40000,95.00004,28.86858,0.82609,3.20762,95.00004
11.43000,95.25005,28.72540,0.82826,3.19171,95.25005
11.46000,95.49998,28.90199,0.83043,3.21133,95.49998
11.49000,95.74998,29.14962,0.83261,3.23885,95.74998
11.52000,96.00005,29.04364,0.83478,3.22707,96.00005
11.55000,96.24999,29.12307,0.83696,3.23590,96.24999
11.58000,96.49992,29.25020,0.83913,3.25002,96.49992
11.61000,96.75005,29.23668,0.84130,3.24852,96.75005
11.64000,97.00004,29.32735,0.84348,3.25859,97.00004
11.67000,97.24999,29.39384,0.84565,3.26598,97.24999
11.70000,97.49993,29.36560,0.84783,3.26285,97.49993
11.73000,97.75005,29.39749,0.85000,3.26639,97.75005
11.76000,97.99998,29.38899,0.85217,3.26544,97.99998
11.79000,98.24992,29.59063,0.85435,3.28785,98.24992
11.82000,98.49999,29.66601,0.85652,3.29622,98.49999
11.85000,98.75004,29.81448,0.85870,3.31272,98.75004
11.88000,98.99999,29.81220,0.86087,3.31247,98.99999
11.91000,99.24999,29.77164,0.86304,3.30796,99.24999
11.94000,99.50005,29.76158,0.86522,3.30684,99.50005
11.97000,99.75005,29.82040,0.86739,3.31338,99.75005
12.00000,99.99998,29.78330,0.86957,3.30926,99.99998
12.03000,100.25005,29.84938,0.87174,3.31660,100.25005
12.06000,100.50005,30.16098,0.87391,3.35122,100.50005
12.09000,100.74999,30.07523,0.87609,3.34169,100.74999
12.12000,100.99999,30.00766,0.87826,3.33418,100.99999
12.15000,101.25005,30.21212,0.88044,3.35690,101.25005
12.18000,101.50004,30.27396,0.88261,3.36377,101.50004
12.21000,101.75005,30.25983,0.88478,3.36220,101.75005
12.24000,101.99999,30.43508,0.88696,3.38168,101.99999
12.27000,102.25005,30.49856,0.88913,3.38873,102.25005
12.30000,102.49998,30.61235,0.89130,3.40137,102.49998
12.33000,102.74992,30.70255,0.89348,3.41139,102.74992
12.36000,102.99998,30.42695,0.89565,3.38077,102.99998
12.39000,103.24999,30.41561,0.89783,3.37951,103.24999
12.42000,103.49993,30.68678,0.90000,3.40964,103.49993
12.45000,103.74992,30.67480,0.90217,3.40831,103.74992
12.48000,104.00005,30.64005,0.90435,3.40445,104.00005
12.51000,104.25005,30.86615,0.90652,3.42957,104.25005
12.54000,104.49998,30.96111,0.90870,3.44012,104.49998
12.57000,104.75005,31.03360,0.91087,3.44818,104.75005
12.60000,105.00005,30.97891,0.91304,3.44210,105.00005
12.63000,105.24998,31.03100,0.91522,3.44789,105.24998
12.66000,105.50004,31.05892,0.91739,3.45099,105.50004
12.69000,105.75005,31.24878,0.91957,3.47209,105.75005
12.72000,106.00004,31.24878,0.92174,3.47209,106.00004
12.75000,106.24998,31.25225,0.92391,3.47247,106.24998
12.78000,106.49998,31.26646,0.92609,3.47405,106.49998
12.81000,106.75005,31.25774,0.92826,3.47308,106.75005
12.84000,106.99992,31.34836,0.93043,3.48315,106.99992
12.87000,107.24992,31.39680,0.93261,3.48853,107.24992
12.90000,107.49999,31.51686,0.93478,3.50187,107.49999
12.93000,107.74999,31.60282,0.93696,3.51142,107.74999
12.96000,107.99993,31.70862,0.93913,3.52318,107.99993
12.99000,108.24999,31.65636,0.94130,3.51737,108.24999
13.02000,108.50005,31.89010,0.94348,3.54334,108.50005
13.05000,108.74998,31.73610,0.94565,3.52623,108.74998
13.08000,108.99998,31.71171,0.94783,3.52352,108.99998
13.11000,109.25005,31.83740,0.95000,3.53749,109.25005
13.14000,109.50005,32.10592,0.95217,3.56732,109.50005
13.17000,109.74999,32.11106,0.95435,3.56790,109.74999
13.20000,109.99999,32.06399,0.95652,3.56267,109.99999
13.23000,110.25004,32.06056,0.95870,3.56228,110.25004
13.26000,110.50005,32.16411,0.96087,3.57379,110.50005
13.29000,110.74998,32.14481,0.96304,3.57165,110.74998
13.32000,111.00005,32.31649,0.96522,3.59072,111.00005
13.35000,111.25005,32.27697,0.96739,3.58633,111.25005
13.38000,111.49999,32.21451,0.96957,3.57939,111.49999
13.41000,111.74999,32.36028,0.97174,3.59559,111.74999
13.44000,112.00004,32.65692,0.97391,3.62855,112.00004
13.47000,112.25005,32.53642,0.97609,3.61516,112.25005
13.50000,112.49992,32.43043,0.97826,3.60338,112.49992
13.53000,112.74998,32.50224,0.98043,3.61136,112.74998
13.56000,113.00005,32.62969,0.98261,3.62552,113.00005
13.59000,113.24998,32.61783,0.98478,3.62420,113.24998
13.62000,113.49992,32.66608,0.98696,3.62956,113.49992
13.65000,113.75004,33.00607,0.98913,3.66734,113.75004
13.68000,114.00005,32.84673,0.99130,3.64964,114.00005
13.71000,114.25004,32.85290,0.99348,3.65032,114.25004
13.74000,114.50005,32.93352,0.99565,3.65928,114.50005
13.77000,114.75004,33.05897,0.99783,3.67322,114.75004
13.80000,114.99998,33.08317,1.00000,3.67591,114.99998
13.83000,115.24999,33.11578,1.00217,3.67953,115.24999
13.86000,115.50005,33.16065,1.00435,3.68452,115.50005
13.89000,115.75005,33.29036,1.00652,3.69893,115.75005
13.92000,115.99992,33.36114,1.00870,3.70679,115.99992
13.95000,116.24998,33.29741,1.01087,3.69971,116.24998
13.98000,116.50004,33.38651,1.01304,3.70961,116.50004
14.01000,116.75005,33.44465,1.01522,3.71607,116.75005
14.04000,116.99999,33.56946,1.01739,3.72994,116.99999
14.07000,117.24998,33.49917,1.01957,3.72213,117.24998
14.10000,117.49999,33.50417,1.02174,3.72269,117.49999
14.13000,117.74998,33.75804,1.02391,3.75089,117.74998
14.16000,117.99992,33.71459,1.02609,3.74607,117.99992
14.19000,118.24999,33.78395,1.02826,3.75377,118.24999
14.22000,118.50005,33.73561,1.03044,3.74840,118.50005
14.25000,118.75005,33.90014,1.03261,3.76668,118.75005
14.28000,119.00004,33.77269,1.03478,3.75252,119.00004
14.31000,119.25004,34.02891,1.03696,3.78099,119.25004
14.34000,119.49998,34.16268,1.03913,3.79585,119.49998
14.37000,119.74998,34.07324,1.04130,3.78592,119.74998
14.40000,120.00005,34.01456,1.04348,3.77940,120.00005
14.43000,120.25005,34.09827,1.04565,3.78870,120.25005
14.46000,120.49999,34.27108,1.04783,3.80790,120.49999
14.49000,120.74999,34.56689,1.05000,3.84077,120.74999
14.52000,121.00005,34.51614,1.05217,3.83513,121.00005
14.55000,121.24998,34.49390,1.05435,3.83266,121.24998
14.58000,121.49998,34.57644,1.05652,3.84183,121.49998
14.61000,121.75005,34.62380,1.05870,3.84709,121.75005
14.64000,121.99998,34.53725,1.06087,3.83747,121.99998
14.67000,122.24992,34.50678,1.06304,3.83409,122.24992
14.70000,122.49999,34.56586,1.06522,3.84065,122.49999
14.73000,122.74999,34.83222,1.06739,3.87025,122.74999
14.76000,122.99999,34.92460,1.06957,3.88051,122.99999
14.79000,123.24998,35.08022,1.07174,3.89780,123.24998
14.82000,123.49999,35.02041,1.07391,3.89116,123.49999
14.85000,123.75005,34.88042,1.07609,3.87560,123.75005
14.88000,123.99998,35.01140,1.07826,3.89016,123.99998
14.91000,124.24998,34.98020,1.08043,3.88669,124.24998
14.94000,124.49998,35.02321,1.08261,3.89147,124.49998
14.97000,124.75004,35.19386,1.08478,3.91043,124.75004
15.00000,124.99998,35.14272,1.08696,3.90475,124.99998
15.03000,125.25004,35.14091,1.08913,3.90455,125.25004
15.06000,125.50004,35.43985,1.09130,3.93776,125.50004
15.09000,125.74998,35.50779,1.09348,3.94531,125.74998
15.12000,125.99997,35.42055,1.09565,3.93562,125.99997
15.15000,126.24999,35.53644,1.09783,3.94849,126.24999
15.18000,126.50005,35.60027,1.10000,3.95559,126.50005
15.21000,126.74998,35.69083,1.10217,3.96565,126.74998
15.24000,127.00004,35.65351,1.10435,3.96150,127.00004
15.27000,127.25005,35.67957,1.10652,3.96440,127.25005
15.30000,127.49991,35.61780,1.10869,3.95753,127.49991
15.33000,127.74984,35.85923,1.11087,3.98436,127.74984
15.36000,128.00003,35.87848,1.11304,3.98650,128.00003
15.39000,128.25004,36.07853,1.11522,4.00873,128.25004
15.42000,128.50004,36.06937,1.11739,4.00771,128.50004
15.45000,128.75005,36.12433,1.11957,4.01381,128.75005
15.48000,129.00010,36.29601,1.12174,4.03289,129.00010
15.51000,129.25004,36.17752,1.12391,4.01972,129.25004
15.54000,129.49998,36.13118,1.12609,4.01458,129.49998
15.57000,129.75005,36.10082,1.12826,4.01120,129.75005
15.60000,130.00004,36.35650,1.13044,4.03961,130.00004
15.63000,130.25003,36.61792,1.13261,4.06866,130.25003
15.66000,130.49997,36.59309,1.13478,4.06590,130.49997
15.69000,130.74997,36.42855,1.13696,4.04762,130.74997
15.72000,130.99998,36.52549,1.13913,4.05839,130.99998
15.75000,131.24992,36.56237,1.14130,4.06249,131.24992
15.78000,131.49998,36.72377,1.14348,4.08042,131.49998
15.81000,131.75005,36.80288,1.14565,4.08921,131.75005
15.84000,131.99999,36.70599,1.14783,4.07844,131.99999
15.87000,132.24992,36.88184,1.15000,4.09798,132.24992
15.90000,132.49998,36.79911,1.15217,4.08879,132.49998
15.93000,132.74997,36.96834,1.15435,4.10759,132.74997
15.96000,132.99991,36.91554,1.15652,4.10173,132.99991
15.99000,133.24998,36.96359,1.15870,4.10707,133.24998
16.02000,133.50010,37.15584,1.16087,4.12843,133.50010
16.05000,133.75004,37.22927,1.16304,4.13659,133.75004
16.08000,133.99998,37.31553,1.16522,4.14617,133.99998
16.11000,134.25005,37.28692,1.16739,4.14299,134.25005
16.14000,134.50004,37.36250,1.16957,4.15139,134.50004
16.17000,134.74998,37.49833,1.17174,4.16648,134.74998
16.20000,134.99998,37.48016,1.17391,4.16446,134.99998
16.23000,135.25004,37.52331,1.17609,4.16926,135.25004
16.26000,135.50005,37.63783,1.17826,4.18198,135.50005
16.29000,135.74998,37.56538,1.18043,4.17393,135.74998
16.32000,135.99998,37.42804,1.18261,4.15867,135.99998
16.35000,136.25003,37.68196,1.18478,4.18688,136.25003
16.38000,136.49997,37.72017,1.18696,4.19113,136.49997
16.41000,136.74999,37.62485,1.18913,4.18054,136.74999
16.44000,137.00004,37.79443,1.19130,4.19938,137.00004
16.47000,137.24998,37.90400,1.19348,4.21156,137.24998
16.50000,137.49992,38.06883,1.19565,4.22987,137.49992
16.53000,137.74998,37.97571,1.19783,4.21952,137.74998
16.56000,138.00004,38.08881,1.20000,4.23209,138.00004
16.59000,138.24998,38.10933,1.20217,4.23437,138.24998
16.62000,138.50003,38.25217,1.20435,4.25024,138.50003
16.65000,138.75005,38.44668,1.20652,4.27185,138.75005
16.68000,139.00004,38.30820,1.20870,4.25647,139.00004
16.71000,139.25004,38.29968,1.21087,4.25552,139.25004
16.74000,139.50004,38.60214,1.21304,4.28913,139.50004
16.77000,139.75011,38.49982,1.21522,4.27776,139.75011
16.80000,140.00005,38.47494,1.21739,4.27499,140.00005
16.83000,140.24998,38.66509,1.21957,4.29612,140.24998
16.86000,140.50004,38.77344,1.22174,4.30816,140.50004
16.89000,140.75004,38.76310,1.22391,4.30701,140.75004
16.92000,140.99992,38.77280,1.22609,4.30809,140.99992
16.95000,141.24991,38.93194,1.22826,4.32577,141.24991
16.98000,141.50004,38.91857,1.23044,4.32429,141.50004
17.01000,141.75004,38.86390,1.23261,4.31821,141.75004
17.04000,141.99992,39.07355,1.23478,4.34151,141.99992
17.07000,142.24998,38.99802,1.23696,4.33311,142.24998
17.10000,142.50005,39.02834,1.23913,4.33648,142.50005
17.13000,142.74999,39.15648,1.24130,4.35072,142.74999
17.16000,142.99998,39.16603,1.24348,4.35178,142.99998
17.19000,143.25003,39.16774,1.24565,4.35197,143.25003
17.22000,143.50004,39.21653,1.24783,4.35739,143.50004
17.25000,143.74998,39.39654,1.25000,4.37739,143.74998
17.28000,144.00004,39.49558,1.25217,4.38840,144.00004
17.31000,144.25009,39.49876,1.25435,4.38875,144.25009
17.34000,144.49998,39.46335,1.25652,4.38482,144.49998
17.37000,144.74998,39.52732,1.25870,4.39192,144.74998
17.40000,145.00004,39.76616,1.26087,4.41846,145.00004
17.43000,145.25004,39.91164,1.26304,4.43463,145.25004
17.46000,145.49998,39.75450,1.26522,4.41717,145.49998
17.49000,145.74997,39.87622,1.26739,4.43069,145.74997
17.52000,146.00004,40.10673,1.26957,4.45630,146.00004
17.55000,146.24998,40.18853,1.27174,4.46539,146.24998
17.58000,146.49997,40.12162,1.27391,4.45796,146.49997
17.61000,146.74998,40.06583,1.27609,4.45176,146.74998
17.64000,147.00005,40.27327,1.27826,4.47481,147.00005
17.67000,147.24999,40.25001,1.28043,4.47222,147.24999
17.70000,147.49992,40.28846,1.28261,4.47650,147.49992
17.73000,147.74998,40.25539,1.28478,4.47282,147.74998
17.76000,147.99997,40.51466,1.28696,4.50163,147.99997
17.79000,148.24991,40.34092,1.28913,4.48232,148.24991
17.82000,148.50005,40.59440,1.29130,4.51049,148.50005
17.85000,148.75010,40.57104,1.29348,4.50789,148.75010
17.88000,148.99998,40.57128,1.29565,4.50792,148.99998
17.91000,149.24997,40.68154,1.29783,4.52017,149.24997
17.94000,149.50004,40.78141,1.30000,4.53127,149.50004
17.97000,149.74998,40.76961,1.30217,4.52996,149.74998
18.00000,149.99998,40.91768,1.30435,4.54641,149.99998
18.03000,150.25004,40.98121,1.30652,4.55347,150.25004
18.06000,150.50004,41.02255,1.30870,4.55806,150.50004
18.09000,150.74998,40.93860,1.31087,4.54873,150.74998
18.12000,150.99992,41.25057,1.31304,4.58340,150.99992
18.15000,151.24998,41.38233,1.31522,4.59804,151.24998
18.18000,151.49998,41.28613,1.31739,4.58735,151.49998
18.21000,151.74999,41.27868,1.31957,4.58652,151.74999
18.24000,151.99998,41.30263,1.32174,4.58918,151.99998
18.27000,152.24998,41.52619,1.32391,4.61402,152.24998
18.30000,152.49997,41.35074,1.32609,4.59453,152.49997
18.33000,152.74997,41.49484,1.32826,4.61054,152.74997
18.36000,152.99998,41.61353,1.33043,4.62373,152.99998
18.39000,153.25004,41.38341,1.33261,4.59816,153.25004
18.42000,153.50004,41.40197,1.33478,4.60022,153.50004
18.45000,153.75005,41.66133,1.33696,4.62904,153.75005
18.48000,154.00010,41.79858,1.33913,4.64429,154.00010
18.51000,154.25004,41.74882,1.34130,4.63876,154.25004
18.54000,154.49992,41.78981,1.34348,4.64331,154.49992
18.57000,154.74997,41.86740,1.34565,4.65193,154.74997
18.60000,155.00004,41.90575,1.34783,4.65619,155.00004
18.63000,155.25005,41.85991,1.35000,4.65110,155.25005
18.66000,155.49998,41.92486,1.35217,4.65832,155.49998
18.69000,155.75004,42.02747,1.35435,4.66972,155.75004
18.72000,155.99998,42.19367,1.35652,4.68819,155.99998
18.75000,156.24992,42.01356,1.35869,4.66817,156.24992
18.78000,156.49999,41.95239,1.36087,4.66138,156.49999
18.81000,156.75010,42.28091,1.36304,4.69788,156.75010
18.84000,156.99998,42.24412,1.36522,4.69379,156.99998
18.87000,157.24996,42.13019,1.36739,4.68113,157.24996
18.90000,157.50004,42.11388,1.36957,4.67932,157.50004
18.93000,157.74997,41.93965,1.37174,4.65996,157.74997
18.96000,157.99992,20.07847,1.37391,2.23094,157.99992
18.99000,158.24998,-0.12802,1.37609,-0.01422,158.24998
19.02000,158.50009,-1.45267,1.37826,-0.16141,158.50009
19.05000,158.75004,-0.34033,1.38044,-0.03781,158.75004
19.08000,158.99997,-0.05425,1.38261,-0.00603,158.99997
19.11000,159.25003,0.02250,1.38478,0.00250,159.25003
19.14000,159.50004,-0.02979,1.38696,-0.00331,159.50004
19.17000,159.74997,-0.04759,1.38913,-0.00529,159.74997
19.20000,159.99997,0.03651,1.39130,0.00406,159.99997
19.23000,160.25003,0.05052,1.39348,0.00561,160.25003
19.26000,160.49998,-0.18227,1.39565,-0.02025,160.49998
19.29000,160.74996,0.11782,1.39783,0.01309,160.74996
19.32000,160.99999,0.06813,1.40000,0.00757,160.99999
19.35000,161.25003,-0.03963,1.40217,-0.00440,161.25003
19.38000,161.49998,-0.09332,1.40435,-0.01037,161.49998
19.41000,161.74996,-0.02523,1.40652,-0.00280,161.74996
19.44000,162.00004,0.14346,1.40870,0.01594,162.00004
19.47000,162.24997,0.17479,1.41087,0.01942,162.24997
19.50000,162.49992,0.11510,1.41304,0.01279,162.49992
19.53000,162.74998,-0.00770,1.41522,-0.00086,162.74998
19.56000,163.00002,0.10058,1.41739,0.01118,163.00002
19.59000,163.24999,0.02441,1.41957,0.00271,163.24999
19.62000,163.49992,0.03884,1.42174,0.00432,163.49992
19.65000,163.75003,0.12157,1.42391,0.01351,163.75003
19.68000,164.00011,-0.00657,1.42609,-0.00073,164.00011
19.71000,164.24991,0.09382,1.42826,0.01042,164.24991
19.74000,164.49990,0.07959,1.43043,0.00884,164.49990
19.77000,164.75003,-0.12491,1.43261,-0.01388,164.75003
19.80000,164.99998,-0.12998,1.43478,-0.01444,164.99998
19.83000,165.24997,0.05478,1.43696,0.00609,165.24997
19.86000,165.50004,0.05990,1.43913,0.00666,165.50004
19.89000,165.74997,0.03634,1.44130,0.00404,165.74997
19.92000,165.99992,-0.10696,1.44348,-0.01188,165.99992
19.95000,166.24996,-0.16904,1.44565,-0.01878,166.24996
19.98000,166.50004,0.05576,1.44783,0.00620,166.50004
20.01000,166.74997,0.08593,1.45000,0.00955,166.74997
20.04000,166.99998,0.10068,1.45217,0.01119,166.99998
20.07000,167.24998,-0.07759,1.45435,-0.00862,167.24998
20.10000,167.50002,-0.03694,1.45652,-0.00410,167.50002
20.13000,167.74997,0.01366,1.45870,0.00152,167.74997
20.16000,167.99998,0.00624,1.46087,0.00069,167.99998
20.19000,168.25004,-0.12185,1.46304,-0.01354,168.25004
20.22000,168.50004,0.01528,1.46522,0.00170,168.50004
20.25000,168.74997,0.05179,1.46739,0.00575,168.74997
20.28000,168.99997,-0.08793,1.46957,-0.00977,168.99997
20.31000,169.25003,-0.02437,1.47174,-0.00271,169.25003
20.34000,169.49998,-0.15207,1.47391,-0.01690,169.49998
20.37000,169.74997,-0.16233,1.47609,-0.01804,169.74997
20.40000,169.99997,-0.06385,1.47826,-0.00709,169.99997
20.43000,170.25003,-0.11776,1.48044,-0.01308,170.25003
20.46000,170.49998,-0.11884,1.48261,-0.01320,170.49998
20.49000,170.74997,0.02042,1.48478,0.00227,170.74997
20.52000,171.00003,0.07959,1.48696,0.00884,171.00003
20.55000,171.24997,0.11072,1.48913,0.01230,171.24997
20.58000,171.49990,0.00555,1.49130,0.00062,171.49990
20.61000,171.75004,-0.09699,1.49348,-0.01078,171.75004
20.64000,171.99997,-0.01634,1.49565,-0.00182,171.99997
20.67000,172.24997,-0.14142,1.49783,-0.01571,172.24997
20.70000,172.49998,0.01817,1.50000,0.00202,172.49998
20.73000,172.74998,0.04827,1.50217,0.00536,172.74998
20.76000,172.99997,-0.00250,1.50435,-0.00028,172.99997
20.79000,173.24997,-0.08886,1.50652,-0.00987,173.24997
20.82000,173.50005,0.07692,1.50870,0.00855,173.50005
20.85000,173.75009,-0.01191,1.51087,-0.00132,173.75009
20.88000,174.00004,0.14741,1.51304,0.01638,174.00004
20.91000,174.24997,0.13080,1.51522,0.01453,174.24997
20.91600,174.30004,0.08160,1.51565,0.00907,174.30004