File: V_7/NatR/RDSO NatR Tensile 250.is_tens_RawData/Specimen_RawData_2.csv
Time,Extension,Load,
(sec),(mm),(N),(kgf)
0,0,-0.197800131,-0.02017
0.02,0.0115,-0.169360846,-0.01727
0.04,0.06806,0.250461841,0.02554
0.06,0.16525,0.759721176,0.07747
0.08,0.27769,0.991256182,0.10108
0.1,0.38562,0.99831697,0.1018
0.12,0.48231,1.376461394,0.14036
0.14,0.5705,1.830411223,0.18665
0.16,0.65512,2.137359368,0.21795
0.18,0.73925,2.396647194,0.24439
0.2,0.82412,2.744979402,0.27991
0.22,0.90956,2.848929892,0.29051
0.24,0.99475,2.970434285,0.3029
0.26,1.0795,3.271204241,0.33357
0.28,1.16394,3.406536011,0.34737
0.3,1.24787,3.789976026,0.38647
0.32,1.33169,3.954531613,0.40325
0.34,1.41537,4.074466942,0.41548
0.36,1.49894,4.32502685,0.44103
0.38,1.58256,4.459966354,0.45479
0.4,1.66619,4.702582875,0.47953
0.42,1.74956,4.962066834,0.50599
0.44,1.833,5.139076866,0.52404
0.46,1.91644,5.217235867,0.53201
0.48,1.99981,5.504080379,0.56126
0.5,2.08319,5.622348578,0.57332
0.52,2.16656,5.765329535,0.5879
0.54,2.24981,6.103462827,0.62238
0.56,2.33312,6.249778045,0.6373
0.58,2.41656,6.328133179,0.64529
0.6,2.49987,6.522304849,0.66509
0.62,2.58331,6.691763761,0.68237
0.64,2.66675,7.004792029,0.71429
0.66,2.75006,7.287027416,0.74307
0.68,2.83344,7.361852155,0.7507
0.7,2.91675,7.458251525,0.76053
0.72,2.99994,7.656345855,0.78073
0.74,3.08325,7.824627969,0.79789
0.76,3.16662,7.779811578,0.79332
0.78,3.24994,7.849144594,0.80039
0.8,3.33325,8.070676817,0.82298
0.82,3.41669,8.260239362,0.84231
0.84,3.5,8.567187507,0.87361
0.86,3.58337,8.6494653,0.882
0.88,3.66675,8.724780372,0.88968
0.9,3.75006,8.724486173,0.88965
0.92,3.83337,8.821768141,0.89957
0.94,3.91669,8.996130378,0.91735
0.96,3.99994,9.210307614,0.93919
0.98,4.08331,9.286407218,0.94695
1,4.16669,9.459004258,0.96455
1.02,4.24994,9.758303216,0.99507
1.04,4.33325,9.893144653,1.00882
1.06,4.41669,10.10104563,1.03002
1.08,4.5,10.10898902,1.03083
1.1,4.58337,10.14654849,1.03466
1.12,4.66675,10.26972001,1.04722
1.14,4.75006,10.52459485,1.07321
1.16,4.83337,10.58333668,1.0792
1.18,4.91669,10.69827062,1.09092
1.2,4.99994,11.02542046,1.12428
1.22,5.08331,11.11368031,1.13328
1.24,5.16669,11.16977435,1.139
1.26,5.25,11.43651523,1.1662
1.28,5.33331,11.59999209,1.18287
1.3,5.41675,11.8467274,1.20803
1.32,5.5,11.89595678,1.21305
1.34,5.58331,12.00520286,1.22419
1.36,5.66669,12.16720872,1.24071
1.38,5.74994,12.3004811,1.2543
1.4,5.83325,12.3554964,1.25991
1.42,5.91662,12.33078364,1.25739
1.44,5.99994,12.5305451,1.27776
1.46,6.08331,12.69480649,1.29451
1.48,6.16669,12.93085256,1.31858
1.5,6.25,13.10972585,1.33682
1.52,6.33344,13.19229785,1.34524
1.54,6.41681,13.21514734,1.34757
1.56,6.50006,13.24662669,1.35078
1.58,6.58337,13.36146256,1.36249
1.6,6.66669,13.59986222,1.3868
1.62,6.75,13.885628,1.41594
1.64,6.83331,13.99026496,1.42661
1.66,6.91669,14.09058699,1.43684
1.68,6.99994,14.24670885,1.45276
1.7,7.08331,14.2995667,1.45815
1.72,7.16669,14.40881278,1.46929
1.74,7.25,14.48667758,1.47723
1.76,7.33337,14.71762419,1.50078
1.78,7.41675,14.83569625,1.51282
1.8,7.5,15.01604055,1.53121
1.82,7.58331,15.21560587,1.55156
1.84,7.66669,15.31788923,1.56199
1.86,7.74994,15.4924476,1.57979
1.88,7.83325,15.67269383,1.59817
1.9,7.91669,15.67122283,1.59802
1.92,8.00006,15.75399096,1.60646
1.94,8.08337,15.87461275,1.61876
1.96,8.16675,15.82665824,1.61387
1.98,8.25012,15.83499389,1.61472
2,8.33344,16.12880112,1.64468
2.02,8.41675,16.32140373,1.66432
2.04,8.5,16.33778083,1.66599
2.06,8.58325,16.44741918,1.67717
2.08,8.66656,16.60030485,1.69276
2.1,8.74981,16.71396393,1.70435
2.12,8.83325,16.85616035,1.71885
2.14,8.91669,17.03611238,1.7372
2.16,9.00006,17.183016,1.75218
2.18,9.08344,17.33531327,1.76771
2.2,9.16687,17.36914621,1.77116
2.22,9.25012,17.33384227,1.76756
2.24,9.33331,17.35149424,1.76936
2.26,9.41656,17.3978797,1.77409
2.28,9.49987,17.71806682,1.80674
2.3,9.58325,17.79475482,1.81456
2.32,9.66662,17.86516657,1.82174
2.34,9.74994,17.94950376,1.83034
2.36,9.83337,18.13514365,1.84927
2.38,9.91675,18.34373109,1.87054
2.4,10.00006,18.53927569,1.89048
2.42,10.08337,18.5322149,1.88976
2.44,10.16675,18.39884446,1.87616
2.46,10.25,18.63008527,1.89974
2.48,10.33325,18.76070985,1.91306
2.5,10.41662,18.88446977,1.92568
2.52,10.49987,19.05893008,1.94347
2.54,10.58325,19.05422288,1.94299
2.56,10.66662,19.01960541,1.93946
2.58,10.75,19.1425808,1.952
2.6,10.83337,19.27997197,1.96601
2.62,10.91675,19.35254118,1.97341
2.64,11,19.49875833,1.98832
2.66,11.08337,19.54602638,1.99314
2.68,11.16675,19.71548529,2.01042
2.7,11.25,19.93446779,2.03275
2.72,11.33331,19.97938224,2.03733
2.74,11.41662,20.00174141,2.03961
2.76,11.49994,20.03312269,2.04281
2.78,11.58325,20.20915205,2.06076
2.8,11.66669,20.37949356,2.07813
2.82,11.75006,20.33340231,2.07343
2.84,11.83344,20.38988861,2.07919
2.86,11.91681,20.38527949,2.07872
2.88,12.00006,20.29172405,2.06918
2.9,12.08331,20.4584371,2.08618
2.92,12.16662,20.66280768,2.10702
2.94,12.24994,20.58562935,2.09915
2.96,12.33325,20.65653143,2.10638
2.98,12.41669,20.71929399,2.11278
3,12.5,20.96436217,2.13777
3.02,12.58337,21.023104,2.14376
3.04,12.66675,21.06144801,2.14767
3.06,12.75006,21.09361382,2.15095
3.08,12.83337,21.23375085,2.16524
3.1,12.91669,21.40173876,2.18237
3.12,12.99994,21.50470859,2.19287
3.14,13.08325,21.54403325,2.19688
3.16,13.16669,21.46911045,2.18924
3.18,13.25,21.54109126,2.19658
3.2,13.33331,21.78351165,2.2213
3.22,13.41675,21.90325084,2.23351
3.24,13.5,21.86961403,2.23008
3.26,13.58337,21.84490127,2.22756
3.28,13.66675,22.13880657,2.25753
3.3,13.75,22.30287183,2.27426
3.32,13.83331,22.32248513,2.27626
3.34,13.91669,22.19362575,2.26312
3.36,14,22.14449443,2.25811
3.38,14.08325,22.22853742,2.26668
3.4,14.16662,22.46556415,2.29085
3.42,14.24994,22.5927564,2.30382
3.44,14.33331,22.60432825,2.305
3.46,14.41675,22.63747473,2.30838
3.48,14.5,22.88126805,2.33324
3.5,14.58331,22.93647949,2.33887
3.52,14.66669,22.88764237,2.33389
3.54,14.74994,22.85773209,2.33084
3.56,14.83325,22.92579024,2.33778
3.58,14.91662,22.93314522,2.33853
3.6,14.99994,23.02876006,2.34828
3.62,15.08331,23.19410018,2.36514
3.64,15.16669,23.29893327,2.37583
3.66,15.25,23.38905638,2.38502
3.68,15.33337,23.41641694,2.38781
3.7,15.41669,23.47005931,2.39328
3.72,15.5,23.454859,2.39173
3.74,15.58331,23.60235102,2.40677
3.76,15.66662,23.60529302,2.40707
3.78,15.74987,23.58656231,2.40516
3.8,15.83325,23.62490632,2.40907
3.82,15.91668,23.76004195,2.42285
3.84,16,23.91430056,2.43858
3.86,16.08337,24.09513518,2.45702
3.88,16.16675,24.01069993,2.44841
3.9,16.25006,23.95637109,2.44287
3.92,16.33337,23.94254371,2.44146
3.94,16.41675,24.26410376,2.47425
3.96,16.5,24.31823647,2.47977
3.98,16.58331,24.24154847,2.47195
4,16.66668,24.29509278,2.47741
4.02,16.75,24.43150328,2.49132
4.04,16.83337,24.53780736,2.50216
4.06,16.91675,24.52496065,2.50085
4.08,17.00006,24.50250342,2.49856
4.1,17.08331,24.54339715,2.50273
4.12,17.16669,24.6559775,2.51421
4.14,17.24993,24.7335481,2.52212
4.16,17.33325,24.80896124,2.52981
4.18,17.41668,24.97910661,2.54716
4.2,17.50006,24.99911218,2.5492
4.22,17.58337,24.8494627,2.53394
4.24,17.66675,24.99195333,2.54847
4.26,17.75,25.11590938,2.56111
4.28,17.83337,25.17788741,2.56743
4.3,17.91668,25.19455871,2.56913
4.32,18,25.10051294,2.55954
4.34,18.08331,25.05255842,2.55465
4.36,18.16675,25.17759321,2.5674
4.38,18.25,25.31292498,2.5812
4.4,18.33331,25.57897939,2.60833
4.42,18.41668,25.62507065,2.61303
4.44,18.5,25.51131351,2.60143
4.46,18.58331,25.68263569,2.6189
4.48,18.66675,25.79629476,2.63049
4.5,18.75006,25.8283625,2.63376
4.52,18.83337,25.72333328,2.62305
4.54,18.91675,25.82002685,2.63291
4.56,19,25.81943845,2.63285
4.58,19.08337,25.76775741,2.62758
4.6,19.16668,26.0660757,2.658
4.62,19.24993,25.98830897,2.65007
4.64,19.33325,25.93162653,2.64429
4.66,19.41662,26.07323455,2.65873
4.68,19.5,26.12324847,2.66383
4.7,19.58337,26.13354545,2.66488
4.72,19.66681,26.25220592,2.67698
4.74,19.75006,26.15100129,2.66666
4.76,19.83337,26.14207724,2.66575
4.78,19.91668,26.1278576,2.6643
4.8,19.99993,26.22994482,2.67471
4.82,20.08325,26.35654867,2.68762
4.84,20.16662,26.36586499,2.68857
4.86,20.24994,26.44726019,2.69687
4.88,20.33331,26.52365399,2.70466
4.9,20.41675,26.5581734,2.70818
4.92,20.5,26.52296752,2.70459
4.94,20.58331,26.54562089,2.7069
4.96,20.66675,26.52100619,2.70439
4.98,20.75006,26.70841128,2.7235
5,20.83331,26.67036147,2.71962
5.02,20.91669,26.60563758,2.71302
5.04,21,26.64162799,2.71669
5.06,21.08331,26.68458112,2.72107
5.08,21.16668,26.97073916,2.75025
5.1,21.24993,27.12705716,2.76619
5.12,21.33331,26.98574334,2.75178
5.14,21.41668,26.83923199,2.73684
5.16,21.5,26.85511876,2.73846
5.18,21.58337,26.89767962,2.7428
5.2,21.66675,26.99741325,2.75297
5.22,21.75,26.92072525,2.74515
5.24,21.83337,27.01006383,2.75426
5.26,21.91675,27.145984,2.76812
5.28,22,27.17667881,2.77125
5.3,22.08331,27.1439246,2.76791
5.32,22.16668,27.21198275,2.77485
5.34,22.25,27.34878552,2.7888
5.36,22.33337,27.47068218,2.80123
5.38,22.41675,27.65543947,2.82007
5.4,22.50006,27.64582895,2.81909
5.42,22.58337,27.5560981,2.80994
5.44,22.66668,27.48019463,2.8022
5.46,22.74993,27.63857203,2.81835
5.48,22.83331,27.75478083,2.8302
5.5,22.91668,27.93041793,2.84811
5.52,22.99994,28.00916533,2.85614
5.54,23.08331,28.0689859,2.86224
5.56,23.16675,28.12154954,2.8676
5.58,23.25006,28.17538805,2.87309
5.6,23.33337,27.95483649,2.8506
5.62,23.41675,27.89334879,2.84433
5.64,23.50006,27.91737509,2.84678
5.66,23.58337,27.95307129,2.85042
5.68,23.66669,28.03142643,2.85841
5.7,23.75,28.02211011,2.85746
5.72,23.83331,28.166464,2.87218
5.74,23.91668,28.29346011,2.88513
5.76,23.99993,28.38868269,2.89484
5.78,24.08331,28.4386966,2.89994
5.8,24.16675,28.36269506,2.89219
5.82,24.25006,28.36750032,2.89268
5.84,24.33337,28.4565447,2.90176
5.86,24.41674,28.60884198,2.91729
5.88,24.5,28.82105788,2.93893
5.9,24.58331,28.65140284,2.92163
5.92,24.66662,28.58118723,2.91447
5.94,24.74987,28.56314299,2.91263
5.96,24.83325,28.64679371,2.92116
5.98,24.91668,28.67905759,2.92445
6,24.99999,28.61894283,2.91832
6.02,25.08337,28.79899292,2.93668
6.04,25.16675,28.82321535,2.93915
6.06,25.25006,28.89588262,2.94656
6.08,25.33337,28.86087288,2.94299
6.1,25.41675,28.92481224,2.94951
6.12,25.49993,29.04572824,2.96184
6.14,25.58318,29.0862297,2.96597
6.16,25.66656,29.11025599,2.96842
6.18,25.74987,29.27726324,2.98545
6.2,25.83331,29.19302412,2.97686
6.22,25.91675,29.11702258,2.96911
6.24,26.00012,29.29452295,2.98721
6.26,26.0835,29.36385596,2.99428
6.28,26.16681,29.43446384,3.00148
6.3,26.25006,29.50379686,3.00855
6.32,26.33331,29.42857985,3.00088
6.34,26.41662,29.40514196,2.99849
6.36,26.49981,29.48006476,3.00613
6.38,26.58318,29.61323907,3.01971
6.4,26.66668,29.6579574,3.02427
6.42,26.75006,29.7317034,3.03179
6.44,26.83337,29.65942839,3.02442
6.46,26.91675,29.7551413,3.03418
6.48,27.00006,29.81064694,3.03984
6.5,27.08343,29.80662621,3.03943
6.52,27.16674,30.0074664,3.05991
6.54,27.24993,30.09621658,3.06896
6.56,27.33331,30.13691418,3.07311
6.58,27.41662,30.31215902,3.09098
6.6,27.49993,30.30745183,3.0905
6.62,27.58331,30.1845745,3.07797
6.64,27.66668,30.20310907,3.07986
6.66,27.74999,30.3054905,3.0903
6.68,27.83337,30.45425738,3.10547
6.7,27.91675,30.40542026,3.10049
6.72,28.00006,30.59969,3.1203
6.74,28.08337,30.70236562,3.13077
6.76,28.16675,30.42297416,3.10228
6.78,28.25,30.41228491,3.10119
6.8,28.33331,30.41767857,3.10174
6.82,28.41668,30.57929216,3.11822
6.84,28.49993,30.78287822,3.13898
6.86,28.58331,30.73570823,3.13417
6.88,28.66675,30.57840956,3.11813
6.9,28.75006,30.49093425,3.10921
6.92,28.83337,30.80739484,3.14148
6.94,28.91675,31.06060255,3.1673
6.96,29,30.99156373,3.16026
6.98,29.08331,31.13405435,3.17479
7,29.16662,31.00539111,3.16167
7.02,29.24993,31.04246024,3.16545
7.04,29.33325,31.05010943,3.16623
7.06,29.41668,31.07570479,3.16884
7.08,29.5,31.11395072,3.17274
7.1,29.58337,31.11718692,3.17307
7.12,29.66675,31.12954329,3.17433
7.14,29.75,31.22908079,3.18448
7.16,29.83331,31.35744984,3.19757
7.18,29.91668,31.3417592,3.19597
7.2,29.99987,31.50278439,3.21239
7.22,30.08325,31.54701239,3.2169
7.24,30.16668,31.54848338,3.21705
7.26,30.25,31.54642399,3.21684
7.28,30.33331,31.62046419,3.22439
7.3,30.41668,31.39736291,3.20164
7.32,30.50006,31.4415909,3.20615
7.34,30.58337,31.60957881,3.22328
7.36,30.66675,31.70607625,3.23312
7.38,30.75,31.79002117,3.24168
7.4,30.83331,31.65135514,3.22754
7.42,30.91668,31.71921716,3.23446
7.44,30.99993,31.91495789,3.25442
7.46,31.08331,32.05058386,3.26825
7.48,31.16668,32.14335477,3.27771
7.5,31.25,32.16120287,3.27953
7.52,31.33331,31.9477121,3.25776
7.54,31.41674,32.01018046,3.26413
7.56,31.50006,32.11540582,3.27486
7.58,31.58337,32.05342779,3.26854
7.6,31.66668,32.23181075,3.28673
7.62,31.74993,32.25024726,3.28861
7.64,31.83331,32.32595459,3.29633
7.66,31.91668,32.39391468,3.30326
7.68,31.99999,32.43637747,3.30759
7.7,32.08331,32.43686781,3.30764
7.72,32.16675,32.50590662,3.31468
7.74,32.25006,32.41803904,3.30572
7.76,32.33337,32.45010678,3.30899
7.78,32.41675,32.56464846,3.32067
7.8,32.5,32.68831031,3.33328
7.82,32.58331,32.76342925,3.34094
7.84,32.66668,32.89925135,3.35479
7.86,32.74993,32.7738243,3.342
7.88,32.83331,32.81854262,3.34656
7.9,32.91668,32.72841951,3.33737
7.92,33.00006,32.71694573,3.3362
7.94,33.08343,32.93985088,3.35893
7.96,33.16674,33.04517431,3.36967
7.98,33.24999,32.97672389,3.36269
8,33.33337,32.88777757,3.35362
8.02,33.41675,32.95877772,3.36086
8.04,33.49999,32.95995452,3.36098
8.06,33.58331,33.12764823,3.37808
8.08,33.66668,33.30740413,3.39641
8.1,33.74999,33.30259887,3.39592
8.12,33.83337,33.25209462,3.39077
8.14,33.91674,33.45136575,3.41109
8.16,34.00006,33.42782979,3.40869
8.18,34.08331,33.40419576,3.40628
8.2,34.16662,33.35859484,3.40163
8.22,34.24993,33.48892522,3.41492
8.24,34.33324,33.47039065,3.41303
8.26,34.41668,33.3241735,3.39812
8.28,34.49999,33.44950249,3.4109
8.3,34.58337,33.47882437,3.41389
8.32,34.66674,33.64700842,3.43104
8.34,34.75,33.71938149,3.43842
8.36,34.83331,33.76135396,3.4427
8.38,34.91662,33.96464581,3.46343
8.4,34.99993,34.01593459,3.46866
8.42,35.08331,33.891194,3.45594
8.44,35.16668,33.96945107,3.46392
8.46,35.24993,33.8929592,3.45612
8.48,35.33331,33.93630459,3.46054
8.5,35.41662,34.01819012,3.46889
8.52,35.49993,34.07879522,3.47507
8.54,35.58331,34.27326109,3.4949
8.56,35.66668,34.35230268,3.50296
8.58,35.75,34.1672512,3.48409
8.6,35.83331,34.18049018,3.48544
8.62,35.91675,34.19176782,3.48659
8.64,35.99999,34.36230547,3.50398
8.66,36.08331,34.30581916,3.49822
8.68,36.16668,34.34867422,3.50259
8.7,36.24993,34.34965489,3.50269
8.72,36.33325,34.32935512,3.50062
8.74,36.41662,34.50960135,3.519
8.76,36.5,34.58236669,3.52642
8.78,36.58343,34.73436977,3.54192
8.8,36.66681,34.80546798,3.54917
8.82,36.75006,34.87695846,3.55646
8.84,36.83337,34.71063768,3.5395
8.86,36.91668,34.72632832,3.5411
8.88,36.99987,34.82498321,3.55116
8.9,37.08325,34.85126504,3.55384
8.92,37.16662,34.94227075,3.56312
8.94,37.24993,35.06397127,3.57553
8.96,37.33331,35.11761365,3.581
8.98,37.41675,35.1842008,3.58779
9,37.50006,35.08025031,3.57719
9.02,37.58337,34.95943239,3.56487
9.04,37.66675,35.06642294,3.57578
9.06,37.75006,35.12526284,3.58178
9.08,37.83337,35.07083593,3.57623
9.1,37.91675,35.09319509,3.57851
9.12,37.99993,35.27255872,3.5968
9.14,38.08331,35.30698006,3.60031
9.16,38.16668,35.24529623,3.59402
9.18,38.25,35.27226452,3.59677
9.2,38.33331,35.1654701,3.58588
9.22,38.41668,35.48693209,3.61866
9.24,38.5,35.64285782,3.63456
9.26,38.58337,35.58607732,3.62877
9.28,38.66674,35.29854634,3.59945
9.3,38.75006,35.31306018,3.60093
9.32,38.83331,35.5761726,3.62776
9.34,38.91662,35.55165598,3.62526
9.36,38.99993,35.41583388,3.61141
9.38,39.08325,35.43417231,3.61328
9.4,39.16668,35.65050701,3.63534
9.42,39.24999,35.81672973,3.65229
9.44,39.33337,35.89488873,3.66026
9.46,39.41674,35.8744909,3.65818
9.48,39.49999,35.88684728,3.65944
9.5,39.5833,35.9107755,3.66188
9.52,39.66662,35.93382113,3.66423
9.54,39.74993,35.96637921,3.66755
9.56,39.83324,36.09161013,3.68032
9.58,39.91656,36.13024833,3.68426
9.6,39.99993,36.14338924,3.6856
9.62,40.08331,36.21693912,3.6931
9.64,40.16668,36.3039241,3.70197
9.66,40.25,36.2231173,3.69373
9.68,40.33337,36.22919743,3.69435
9.7,40.41674,36.28617406,3.70016
9.72,40.49999,36.26822789,3.69833
9.74,40.5833,36.26244197,3.69774
9.76,40.66668,36.25606765,3.69709
9.78,40.74993,36.23929828,3.69538
9.8,40.83325,36.32883299,3.70451
9.82,40.91668,36.34736756,3.7064
9.84,40.99999,36.56958625,3.72906
9.86,41.08331,36.76591538,3.74908
9.88,41.16668,36.54644256,3.7267
9.9,41.25,36.5015281,3.72212
9.92,41.33337,36.47505014,3.71942
9.94,41.41674,36.54683482,3.72674
9.96,41.49999,36.64048833,3.73629
9.98,41.58331,36.59292608,3.73144
10,41.66668,36.53045772,3.72507
10.02,41.74993,36.56703652,3.7288
10.04,41.83331,36.5802755,3.73015
10.06,41.91674,36.63352561,3.73558
10.08,41.99999,36.51810134,3.72381
10.1,42.08337,36.56497712,3.72859
10.12,42.16674,36.36933446,3.70864
10.14,42.25005,35.94048965,3.66491
10.16,42.33337,31.20436803,3.18196
10.18,42.41668,12.01579405,1.22527
10.2,42.49993,0.591733261,0.06034
10.22,42.58324,-2.092837177,-0.21341
10.24,42.66662,-1.601327879,-0.16329
10.26,42.74993,-0.870340188,-0.08875
10.28,42.8333,-0.72990896,-0.07443
10.3,42.91681,-0.796790313,-0.08125
10.32,43.00018,-0.660281745,-0.06733
10.34,43.08349,-0.643022041,-0.06557
10.36,43.16681,-0.482977513,-0.04925
10.38,43.24999,-0.4121735,-0.04203
10.4,43.33324,-0.383341949,-0.03909
10.42,43.41662,-0.601147645,-0.0613
10.44,43.49987,-0.664400538,-0.06775
10.46,43.58324,-0.633901856,-0.06464
10.48,43.66662,-0.45895122,-0.0468
10.5,43.75,-0.38638201,-0.0394
10.52,43.83337,-0.614975022,-0.06271
10.54,43.91674,-0.733733553,-0.07482
10.56,44.00006,-0.748639661,-0.07634
10.58,44.08337,-0.672245858,-0.06855
10.6,44.16674,-0.661948875,-0.0675
10.62,44.24999,-0.794730916,-0.08104
10.64,44.33325,-0.584672473,-0.05962
10.66,44.41662,-0.482389114,-0.04919
10.68,44.49993,-0.671853592,-0.06851
10.7,44.58331,-0.450223302,-0.04591
10.72,44.66668,-0.429433204,-0.04379
10.74,44.74999,-0.616053753,-0.06282
10.76,44.83331,-0.637138051,-0.06497
10.78,44.91674,-0.677933715,-0.06913
10.8,44.99999,-0.659497213,-0.06725
10.82,45.08337,-0.625370071,-0.06377
10.84,45.16668,-0.471895998,-0.04812
10.86,45.24993,-0.480133584,-0.04896
10.88,45.33324,-0.556331255,-0.05673
10.9,45.41662,-0.509357401,-0.05194
10.92,45.49987,-0.585457005,-0.0597
10.94,45.58331,-0.543680676,-0.05544
10.96,45.66674,-0.614288556,-0.06264
10.98,45.75005,-0.586928003,-0.05985
11,45.83343,-0.58055368,-0.0592
11.02,45.91674,-0.555252523,-0.05662
11.04,45.99999,-0.624389406,-0.06367
11.06,46.0833,-0.419822687,-0.04281
11.08,46.16668,-0.421097551,-0.04294
11.1,46.24993,-0.47856452,-0.0488
11.12,46.3333,-0.442672181,-0.04514
11.14,46.41674,-0.520242783,-0.05305
11.16,46.50006,-0.397169325,-0.0405
11.18,46.58343,-0.4118793,-0.042
11.2,46.66674,-0.463070013,-0.04722
11.22,46.75,-0.461697082,-0.04708
11.24,46.83331,-0.45532276,-0.04643
11.26,46.91662,-0.490430567,-0.05001
11.28,46.99993,-0.502198547,-0.05121
11.3,47.08324,-0.459441553,-0.04685
11.32,47.16668,-0.600068914,-0.06119
11.34,47.24999,-0.605266438,-0.06172
11.36,47.33337,-0.507592204,-0.05176
11.38,47.41674,-0.587712535,-0.05993
11.4,47.49999,-0.771979488,-0.07872
11.42,47.58337,-0.6279198,-0.06403
11.44,47.66674,-0.717062248,-0.07312
11.46,47.75005,-0.73187029,-0.07463
11.48,47.8333,-0.629096598,-0.06415
11.5,47.91668,-0.569177966,-0.05804
11.52,47.99993,-0.499550751,-0.05094
11.532,48.04993,-0.568393434,-0.05796