File: V_7/FR/RDSO FR Tensile 250.is_tens_RawData/Specimen_RawData_1.csv
Time,Extension,Load,
(sec),(mm),(N),(kgf)
0,0,0.051190713,0.00522
0.04,0.068,0.605854837,0.06178
0.08,0.27781,1.456189459,0.14849
0.12,0.48269,2.127356585,0.21693
0.16,0.65531,2.686727901,0.27397
0.2,0.82412,3.321708488,0.33872
0.24,0.99494,3.78732823,0.3862
0.28,1.16406,4.382395752,0.44688
0.32,1.33162,4.792313722,0.48868
0.36,1.49887,5.190954045,0.52933
0.4,1.666,5.538305588,0.56475
0.44,1.83294,5.804261936,0.59187
0.48,1.99994,5.988921155,0.6107
0.52,2.16669,6.464935946,0.65924
0.56,2.33312,6.633119994,0.67639
0.6,2.49987,6.972626217,0.71101
0.64,2.66669,7.337727796,0.74824
0.68,2.83337,7.640949414,0.77916
0.72,3.00006,7.871307623,0.80265
0.76,3.16675,8.240233796,0.84027
0.8,3.33325,8.50854374,0.86763
0.84,3.49994,8.862956071,0.90377
0.88,3.66662,8.87923511,0.90543
0.92,3.83337,9.178534068,0.93595
0.96,4.00006,9.42644618,0.96123
1,4.16675,9.585608109,0.97746
1.04,4.33325,9.767227267,0.99598
1.08,4.5,9.838717746,1.00327
1.12,4.66669,9.960320206,1.01567
1.16,4.83331,10.22509976,1.04267
1.2,5,10.60981464,1.0819
1.24,5.16662,10.58353281,1.07922
1.28,5.33331,10.78172521,1.09943
1.32,5.5,11.09622448,1.1315
1.36,5.66675,11.18271913,1.14032
1.4,5.83331,11.36188662,1.15859
1.44,6.00006,11.56615914,1.17942
1.48,6.16669,11.68021048,1.19105
1.52,6.33331,11.79171209,1.20242
1.56,6.5,11.91645268,1.21514
1.6,6.66669,11.95842514,1.21942
1.64,6.83331,12.10670169,1.23454
1.68,7,12.38491635,1.26291
1.72,7.16662,12.44777698,1.26932
1.76,7.33337,12.69451229,1.29448
1.8,7.50006,12.63410333,1.28832
1.84,7.66675,12.80052218,1.30529
1.88,7.83325,12.78708707,1.30392
1.92,7.99994,13.14679499,1.3406
1.96,8.16669,13.25103968,1.35123
2,8.3335,13.31076218,1.35732
2.04,8.50019,13.26702452,1.35286
2.08,8.66656,13.59858736,1.38667
2.12,8.83306,13.3742112,1.36379
2.16,9,13.38352752,1.36474
2.2,9.16681,13.75137496,1.40225
2.24,9.33337,13.93750518,1.42123
2.28,9.50006,13.84267487,1.41156
2.32,9.66662,13.72411248,1.39947
2.36,9.83319,13.9845771,1.42603
2.4,10,14.27397134,1.45554
2.44,10.16675,14.41283351,1.4697
2.48,10.33331,14.27171581,1.45531
2.52,10.50006,14.36056406,1.46437
2.56,10.66669,14.35340521,1.46364
2.6,10.83325,14.51658786,1.48028
2.64,11.00006,14.50756574,1.47936
2.68,11.16681,14.63103147,1.49195
2.72,11.33331,14.61867509,1.49069
2.76,11.49994,14.56728824,1.48545
2.8,11.66669,14.89443809,1.51881
2.84,11.83331,14.94033321,1.52349
2.88,12.00006,14.904637,1.51985
2.92,12.16669,14.96112331,1.52561
2.96,12.33325,14.9283691,1.52227
3,12.5,15.12901315,1.54273
3.04,12.66675,15.17530054,1.54745
3.08,12.83337,15.44086462,1.57453
3.12,13.00006,15.3595675,1.56624
3.16,13.16669,15.36456889,1.56675
3.2,13.33325,15.41213114,1.5716
3.24,13.49994,15.2778781,1.55791
3.28,13.66675,15.49352634,1.5799
3.32,13.83331,15.52186755,1.58279
3.36,14,15.44027623,1.57447
3.4,14.16662,15.56423228,1.58711
3.44,14.33325,15.73388733,1.60441
3.48,14.5,15.74477271,1.60552
3.52,14.66675,15.62473931,1.59328
3.56,14.83331,15.69760272,1.60071
3.6,14.99994,15.76389568,1.60747
3.64,15.16662,15.78233218,1.60935
3.68,15.33337,15.82391237,1.61359
3.72,15.50012,16.05554545,1.63721
3.76,15.66675,16.08329827,1.64004
3.8,15.83331,15.888244,1.62015
3.84,16,15.85303812,1.61656
3.88,16.16669,16.01416138,1.63299
3.92,16.33331,15.83254223,1.61447
3.96,16.50006,15.97483672,1.62898
4,16.66668,16.03495148,1.63511
4.04,16.83337,16.24196986,1.65622
4.08,17.00006,16.28737465,1.66085
4.12,17.16662,16.34709715,1.66694
4.16,17.33325,16.20754852,1.65271
4.2,17.50006,16.34611649,1.66684
4.24,17.66669,16.3756345,1.66985
4.28,17.83331,16.45075344,1.67751
4.32,18.00006,16.4142727,1.67379
4.36,18.16675,16.30581115,1.66273
4.4,18.33325,16.54891801,1.68752
4.44,18.49993,16.40122986,1.67246
4.48,18.66662,16.49203944,1.68172
4.52,18.83331,16.55176194,1.68781
4.56,19.00012,16.48360572,1.68086
4.6,19.16668,16.51822319,1.68439
4.64,19.33318,16.75171953,1.7082
4.68,19.49994,16.77858975,1.71094
4.72,19.66675,16.58814461,1.69152
4.76,19.83331,16.56794291,1.68946
4.8,20.00006,16.88548224,1.72184
4.84,20.16668,16.75338666,1.70837
4.88,20.33331,16.57941669,1.69063
4.92,20.5,16.62923447,1.69571
4.96,20.66668,16.79820305,1.71294
5,20.83331,16.6923893,1.70215
5.04,21.00006,16.86469214,1.71972
5.08,21.16675,16.89675988,1.72299
5.12,21.33331,16.93343675,1.72673
5.16,21.5,16.97589955,1.73106
5.2,21.66675,16.99835678,1.73335
5.24,21.83337,16.89597535,1.72291
5.28,22,17.12662776,1.74643
5.32,22.16668,17.08779343,1.74247
5.36,22.33325,17.0216966,1.73573
5.4,22.5,17.15585158,1.74941
5.44,22.66675,17.25627167,1.75965
5.48,22.83337,17.08328237,1.74201
5.52,23,17.11319265,1.74506
5.56,23.16668,17.09622714,1.74333
5.6,23.33331,17.03228779,1.73681
5.64,23.50006,17.35110198,1.76932
5.68,23.66675,17.2225368,1.75621
5.72,23.83331,16.95344232,1.72877
5.76,23.99993,17.20802295,1.75473
5.8,24.16662,17.06788593,1.74044
5.84,24.33337,17.5556687,1.79018
5.88,24.50006,17.40699988,1.77502
5.92,24.66668,17.31442511,1.76558
5.96,24.83325,17.48947381,1.78343
6,24.99993,17.28686842,1.76277
6.04,25.16675,17.56733861,1.79137
6.08,25.3335,17.21851607,1.7558
6.12,25.50012,17.35178844,1.76939
6.16,25.6665,17.56694634,1.79133
6.2,25.83312,17.3188381,1.76603
6.24,26.00006,17.59558176,1.79425
6.28,26.16681,17.35443624,1.76966
6.32,26.33337,17.37483407,1.77174
6.36,26.50006,17.39601644,1.7739
6.4,26.66668,17.59175717,1.79386
6.44,26.83325,17.56665215,1.7913
6.48,27,17.75964702,1.81098
6.52,27.16668,17.54654851,1.78925
6.56,27.33337,17.66628771,1.80146
6.6,27.50006,17.8088764,1.816
6.64,27.66668,17.63598516,1.79837
6.68,27.83325,17.67530983,1.80238
6.72,28.00006,17.67795762,1.80265
6.76,28.16675,17.87977848,1.82323
6.8,28.33331,17.78730177,1.8138
6.84,28.5,17.79318576,1.8144
6.88,28.66668,17.86634337,1.82186
6.92,28.83331,17.8100532,1.81612
6.96,29.00006,17.85898838,1.82111
7,29.16669,17.61941192,1.79668
7.04,29.33325,18.00961853,1.83647
7.08,29.5,17.72738314,1.80769
7.12,29.66675,17.62451138,1.7972
7.16,29.83337,17.97196099,1.83263
7.2,30.00006,17.90704097,1.82601
7.24,30.16668,17.9057661,1.82588
7.28,30.33325,17.70031678,1.80493
7.32,30.49999,18.05100259,1.84069
7.36,30.66675,17.98882843,1.83435
7.4,30.83337,18.02942796,1.83849
7.44,31,17.99412402,1.83489
7.48,31.16662,18.01815031,1.83734
7.52,31.33331,17.93724545,1.82909
7.56,31.50006,17.8106416,1.81618
7.6,31.66674,17.93802998,1.82917
7.64,31.83331,18.05414072,1.84101
7.68,31.99999,18.20614379,1.85651
7.72,32.16668,18.21369491,1.85728
7.76,32.33337,18.1039585,1.84609
7.8,32.50006,18.30725035,1.86682
7.84,32.66668,18.3794273,1.87418
7.88,32.83331,18.28930418,1.86499
7.92,33,18.29499204,1.86557
7.96,33.16668,18.32696172,1.86883
8,33.33331,18.33137471,1.86928
8.04,33.49999,18.39031268,1.87529
8.08,33.66668,17.99353562,1.83483
8.12,33.83337,18.40002126,1.87628
8.16,34.00006,18.23683861,1.85964
8.2,34.16662,18.27851687,1.86389
8.24,34.33324,18.36148113,1.87235
8.28,34.49999,18.41012211,1.87731
8.32,34.66668,18.19486614,1.85536
8.36,34.83331,18.1402431,1.84979
8.4,35.00006,18.24438973,1.86041
8.44,35.16675,18.24056513,1.86002
8.48,35.33325,18.47984739,1.88442
8.52,35.49999,18.45925343,1.88232
8.56,35.66662,18.54869008,1.89144
8.6,35.83337,18.61714049,1.89842
8.64,36.00012,18.52191792,1.88871
8.68,36.16668,18.50004909,1.88648
8.72,36.33318,18.41071051,1.87737
8.76,36.5,18.63518473,1.90026
8.8,36.66668,18.59203547,1.89586
8.84,36.83337,18.66617374,1.90342
8.88,37.00006,18.72354265,1.90927
8.92,37.16674,18.63802866,1.90055
8.96,37.33324,18.67862819,1.90469
9,37.49999,18.61517916,1.89822
9.04,37.66668,18.66784087,1.90359
9.08,37.83337,18.70795007,1.90768
9.12,38.00006,18.73619322,1.91056
9.16,38.16668,18.79415053,1.91647
9.2,38.33324,18.74041008,1.91099
9.24,38.5,18.79885772,1.91695
9.28,38.66674,18.89260929,1.92651
9.32,38.83331,18.95056659,1.93242
9.36,38.99993,18.86083575,1.92327
9.4,39.16662,18.87858578,1.92508
9.44,39.33324,18.9883222,1.93627
9.48,39.50006,19.04372977,1.94192
9.52,39.66675,19.0433375,1.94188
9.56,39.8333,19.07491492,1.9451
9.6,39.99999,19.0240184,1.93991
9.64,40.16662,19.03068692,1.94059
9.68,40.33331,18.97194509,1.9346
9.72,40.50006,18.89663002,1.92692
9.76,40.66675,18.98224207,1.93565
9.8,40.8333,19.20622596,1.95849
9.84,40.99999,19.04294524,1.94184
9.88,41.16668,19.1024716,1.94791
9.92,41.33337,19.03372699,1.9409
9.96,41.50006,19.3612691,1.9743
10,41.66668,19.32959362,1.97107
10.04,41.83325,19.25418048,1.96338
10.08,41.99999,19.15591784,1.95336
10.12,42.16681,19.03323665,1.94085
10.16,42.3335,19.20308783,1.95817
10.2,42.50005,19.20014584,1.95787
10.24,42.66656,19.23035032,1.96095
10.28,42.83318,19.27702997,1.96571
10.32,43.00006,19.42560072,1.98086
10.36,43.16675,19.31115711,1.96919
10.4,43.33337,19.33430081,1.97155
10.44,43.50006,19.51631223,1.99011
10.48,43.66662,19.39412137,1.97765
10.52,43.83324,19.36293623,1.97447
10.56,44,19.49954286,1.9884
10.6,44.16674,19.58593945,1.99721
10.64,44.33337,19.55906923,1.99447
10.68,44.49999,19.55053744,1.9936
10.72,44.66662,19.44080103,1.98241
10.76,44.83324,19.47796823,1.9862
10.8,45.00006,19.51072244,1.98954
10.84,45.1668,19.64801554,2.00354
10.88,45.33324,19.65144787,2.00389
10.92,45.49999,19.91573709,2.03084
10.96,45.66668,19.7497105,2.01391
11,45.83337,19.84483501,2.02361
11.04,46.00006,20.02763096,2.04225
11.08,46.16662,19.67135537,2.00592
11.12,46.33325,19.67802389,2.0066
11.16,46.49999,19.8316941,2.02227
11.2,46.66681,19.90112518,2.02935
11.24,46.83337,20.05234372,2.04477
11.28,47.00006,19.81923965,2.021
11.32,47.16668,19.79815535,2.01885
11.36,47.33331,19.89122046,2.02834
11.4,47.49999,19.91073569,2.03033
11.44,47.66674,20.03371109,2.04287
11.48,47.8333,20.06077744,2.04563
11.52,47.99999,19.99213089,2.03863
11.56,48.16662,20.05057852,2.04459
11.6,48.3333,19.98487397,2.03789
11.64,48.50006,19.95143329,2.03448
11.68,48.66675,20.15443095,2.05518
11.72,48.83324,20.39528227,2.07974
11.76,48.99999,20.13834804,2.05354
11.8,49.16668,20.15266575,2.055
11.84,49.33331,20.23719907,2.06362
11.88,49.5,20.02880776,2.04237
11.92,49.66668,20.0843134,2.04803
11.96,49.83325,20.2011106,2.05994
12,49.99993,20.3366385,2.07376
12.04,50.16668,20.21003465,2.06085
12.08,50.33331,20.39155574,2.07936
12.12,50.50005,20.40214693,2.08044
12.16,50.66674,20.25445878,2.06538
12.2,50.83337,20.33683464,2.07378
12.24,50.99999,20.31594647,2.07165
12.28,51.16662,20.54728535,2.09524
12.32,51.33331,20.60475232,2.1011
12.36,51.49999,20.55973979,2.09651
12.4,51.66662,20.43382241,2.08367
12.44,51.83337,20.58170669,2.09875
12.48,52.00012,20.60641945,2.10127
12.52,52.16674,20.45255311,2.08558
12.56,52.33331,20.47412774,2.08778
12.6,52.49993,20.55277707,2.0958
12.64,52.66662,20.68977597,2.10977
12.68,52.83337,20.49295651,2.0897
12.72,53.00011,20.67084914,2.10784
12.76,53.16662,20.79961045,2.12097
12.8,53.33318,20.68604944,2.10939
12.84,53.49999,20.71488099,2.11233
12.88,53.66674,20.69242377,2.11004
12.92,53.83337,20.89914795,2.13112
12.96,54.00006,20.53414444,2.0939
13,54.16668,20.85276249,2.12639
13.04,54.33324,20.74979267,2.11589
13.08,54.49993,20.86560921,2.1277
13.12,54.66668,21.00123517,2.14153
13.16,54.83331,21.04693416,2.14619
13.2,55.00006,20.99201692,2.14059
13.24,55.16668,21.10253787,2.15186
13.28,55.33325,20.94151268,2.13544
13.32,55.49999,21.05958474,2.14748
13.36,55.66674,21.15814157,2.15753
13.4,55.83331,21.13715534,2.15539
13.44,55.99999,21.10028234,2.15163
13.48,56.16668,21.26454373,2.16838
13.52,56.3333,21.14715813,2.15641
13.56,56.50006,21.42311726,2.18455
13.6,56.66674,21.3217165,2.17421
13.64,56.83331,21.02506533,2.14396
13.68,56.99999,21.23012239,2.16487
13.72,57.16668,21.15549378,2.15726
13.76,57.3333,21.21139168,2.16296
13.8,57.50006,21.18834606,2.16061
13.84,57.66674,21.33878007,2.17595
13.88,57.83331,21.60346155,2.20294
13.92,57.99993,21.61699473,2.20432
13.96,58.16668,21.51883016,2.19431
14,58.33337,21.64984701,2.20767
14.04,58.50005,21.60895328,2.2035
14.08,58.66668,21.60238282,2.20283
14.12,58.83324,21.66965644,2.20969
14.16,58.99993,21.64700308,2.20738
14.2,59.16681,21.50627765,2.19303
14.24,59.33343,21.64857214,2.20754
14.28,59.49999,21.76213315,2.21912
14.32,59.66649,21.61875993,2.2045
14.36,59.83318,21.72418141,2.21525
14.4,60.00006,21.82205178,2.22523
14.44,60.16681,21.94826337,2.2381
14.48,60.33337,21.92031441,2.23525
14.52,60.5,21.69986092,2.21277
14.56,60.66662,21.69878219,2.21266
14.6,60.83325,21.99200102,2.24256
14.64,61.00005,21.77713732,2.22065
14.68,61.16674,21.75016904,2.2179
14.72,61.33337,21.90011271,2.23319
14.76,61.49999,22.06682576,2.25019
14.8,61.66662,22.03985748,2.24744
14.84,61.8333,22.19548901,2.26331
14.88,62.00006,22.29022125,2.27297
14.92,62.16674,22.20058847,2.26383
14.96,62.33331,22.06662963,2.25017
15,62.49999,22.11899714,2.25551
15.04,62.66674,22.25393665,2.26927
15.08,62.83336,22.10467943,2.25405
15.12,63.00006,22.27276541,2.27119
15.16,63.16661,22.21882884,2.26569
15.2,63.33324,22.12870573,2.2565
15.24,63.49999,22.46046469,2.29033
15.28,63.66674,22.58863761,2.3034
15.32,63.83337,22.43016215,2.28724
15.36,63.99999,22.52263886,2.29667
15.4,64.16667,22.7713355,2.32203
15.44,64.33324,22.31503208,2.2755
15.48,64.49999,22.57971356,2.30249
15.52,64.66674,22.70543481,2.31531
15.56,64.8333,22.69866822,2.31462
15.6,64.99999,22.48272579,2.2926
15.64,65.16661,22.42192456,2.2864
15.68,65.3333,22.82389914,2.32739
15.72,65.50005,22.71180913,2.31596
15.76,65.66674,22.74779954,2.31963
15.8,65.83324,22.78810487,2.32374
15.84,65.99999,22.86165475,2.33124
15.88,66.16674,22.80448198,2.32541
15.92,66.33336,22.79389079,2.32433
15.96,66.50005,22.85939922,2.33101
16,66.66668,22.9267709,2.33788
16.04,66.83331,23.07936238,2.35344
16.08,67.00005,23.03817445,2.34924
16.12,67.16674,22.91755265,2.33694
16.16,67.33336,23.19772864,2.36551
16.2,67.49999,23.03091753,2.3485
16.24,67.66674,23.06651566,2.35213
16.28,67.83336,23.13888874,2.35951
16.32,67.99999,23.12035417,2.35762
16.36,68.16661,23.19262918,2.36499
16.4,68.3333,23.16722996,2.3624
16.44,68.49999,23.32550929,2.37854
16.48,68.66661,23.32090017,2.37807
16.52,68.8333,23.44466009,2.39069
16.56,69.00005,23.419457,2.38812
16.6,69.16668,23.55724043,2.40217
16.64,69.33324,23.45181894,2.39142
16.68,69.49992,23.20214163,2.36596
16.72,69.66668,23.34924138,2.38096
16.76,69.83336,23.42426226,2.38861
16.8,70.00005,23.61156927,2.40771
16.84,70.16661,23.59725156,2.40625
16.88,70.33318,23.67756803,2.41444
16.92,70.50005,23.51644477,2.39801
16.96,70.66674,23.78701024,2.4256
17,70.83336,23.65491466,2.41213
17.04,71.00006,23.82358904,2.42933
17.08,71.16674,23.85987365,2.43303
17.12,71.33331,23.73885959,2.42069
17.16,71.49999,23.88242894,2.43533
17.2,71.66667,23.84467334,2.43148
17.24,71.83337,23.79632656,2.42655
17.28,72.00005,24.04570967,2.45198
17.32,72.16667,23.87164163,2.43423
17.36,72.3333,24.06218484,2.45366
17.4,72.50005,23.74415518,2.42123
17.44,72.66674,23.80632934,2.42757
17.48,72.8333,24.11906341,2.45946
17.52,72.99999,24.24939379,2.47275
17.56,73.16662,24.29244498,2.47714
17.6,73.33324,24.38756949,2.48684
17.64,73.50005,24.03492235,2.45088
17.68,73.66674,24.22664236,2.47043
17.72,73.8333,24.22929016,2.4707
17.76,73.99999,24.50917195,2.49924
17.8,74.16661,24.3591302,2.48394
17.84,74.3333,24.22566169,2.47033
17.88,74.50006,24.26518249,2.47436
17.92,74.66668,24.44327126,2.49252
17.96,74.83324,24.28685519,2.47657
18,74.99993,24.21310918,2.46905
18.04,75.16674,24.27655821,2.47552
18.08,75.33337,24.51358494,2.49969
18.12,75.50005,24.40306399,2.48842
18.16,75.66668,24.66529381,2.51516
18.2,75.83324,24.76993077,2.52583
18.24,76.00005,24.68049412,2.51671
18.28,76.16686,24.66813774,2.51545
18.32,76.33343,24.66911841,2.51555
18.36,76.49993,24.77757996,2.52661
18.4,76.66655,24.98146021,2.5474
18.44,76.8333,24.87005667,2.53604
18.48,77.00011,24.85279696,2.53428
18.52,77.1668,24.79562419,2.52845
18.56,77.33336,24.98979586,2.54825
18.6,77.50005,24.96302371,2.54552
18.64,77.66661,25.06913166,2.55634
18.68,77.83324,25.12630443,2.56217
18.72,77.99999,25.19142059,2.56881
18.76,78.16673,24.9668483,2.54591
18.8,78.3333,25.12483343,2.56202
18.84,78.49999,25.28026884,2.57787
18.88,78.66655,25.25418315,2.57521
18.92,78.8333,25.46532032,2.59674
18.96,79.00004,25.26144007,2.57595
19,79.16674,25.34881732,2.58486
19.04,79.33323,25.3023338,2.58012
19.08,79.49999,25.38549419,2.5886
19.12,79.66667,25.44462829,2.59463
19.16,79.8333,25.40059643,2.59014
19.2,79.99999,25.4571808,2.59591
19.24,80.16662,25.61114521,2.61161
19.28,80.33324,25.60496702,2.61098
19.32,80.50005,25.50180106,2.60046
19.36,80.6668,25.6916578,2.61982
19.4,80.83336,25.68812741,2.61946
19.44,80.99998,25.8125738,2.63215
19.48,81.16661,25.56299456,2.6067
19.52,81.3333,25.68106662,2.61874
19.56,81.50005,25.7739356,2.62821
19.6,81.66674,25.70371998,2.62105
19.64,81.8333,25.93849118,2.64499
19.68,81.99998,25.8324813,2.63418
19.72,82.16668,25.84611254,2.63557
19.76,82.33336,25.88651594,2.63969
19.8,82.50005,25.89828392,2.64089
19.84,82.66667,26.14286177,2.66583
19.88,82.83324,25.99331036,2.65058
19.92,82.99999,26.19925001,2.67158
19.96,83.16674,26.19797514,2.67145
20,83.3333,26.21405805,2.67309
20.04,83.49999,26.29800297,2.68165
20.08,83.66668,25.94457131,2.64561
20.12,83.83323,26.3430155,2.68624
20.16,83.99999,26.38126143,2.69014
20.2,84.16668,26.37145478,2.68914
20.24,84.3333,26.35321441,2.68728
20.28,84.49999,26.53689297,2.70601
20.32,84.66667,26.33105138,2.68502
20.36,84.8333,26.62672188,2.71517
20.4,84.99992,26.49109591,2.70134
20.44,85.16661,26.44647565,2.69679
20.48,85.3333,26.58023836,2.71043
20.52,85.50005,26.59396767,2.71183
20.56,85.66667,26.74950114,2.72769
20.6,85.83336,26.62172049,2.71466
20.64,86.00011,26.74244035,2.72697
20.68,86.16674,26.72586711,2.72528
20.72,86.3333,26.66408522,2.71898
20.76,86.49993,26.77950949,2.73075
20.8,86.66667,26.80422225,2.73327
20.84,86.83342,26.93465069,2.74657
20.88,87.00011,26.91337026,2.7444
20.92,87.16661,26.98623367,2.75183
20.96,87.33324,26.91366446,2.74443
21,87.49999,26.96210931,2.74937
21.04,87.66667,26.95583305,2.74873
21.08,87.83337,26.9314145,2.74624
21.12,88.00005,27.0259506,2.75588
21.16,88.16661,27.21943581,2.77561
21.2,88.33324,27.17628655,2.77121
21.24,88.49998,27.2844539,2.78224
21.28,88.66673,27.29033789,2.78284
21.32,88.83336,27.25572041,2.77931
21.36,88.99999,27.26640966,2.7804
21.4,89.16661,27.31612938,2.78547
21.44,89.33323,27.37899,2.79188
21.48,89.50005,27.42998458,2.79708
21.52,89.66674,27.57355394,2.81172
21.56,89.83323,27.45077468,2.7992
21.6,89.99999,27.70535531,2.82516
21.64,90.16661,27.63013831,2.81749
21.68,90.3333,27.62366592,2.81683
21.72,90.50005,27.55148898,2.80947
21.76,90.66674,27.74016892,2.82871
21.8,90.8333,27.57325974,2.81169
21.84,90.99999,27.90776457,2.8458
21.88,91.16674,27.81499366,2.83634
21.92,91.3333,27.88962227,2.84395
21.96,91.50005,27.89658499,2.84466
22,91.66674,27.78106265,2.83288
22.04,91.8333,27.99945675,2.85515
22.08,91.99998,27.83176303,2.83805
22.12,92.16674,27.80214695,2.83503
22.16,92.33336,28.14528163,2.87002
22.2,92.50005,28.31248502,2.88707
22.24,92.66668,28.10929123,2.86635
22.28,92.83324,28.15116562,2.87062
22.32,92.99998,28.19588395,2.87518
22.36,93.1668,28.18009524,2.87357
22.4,93.33336,28.18735216,2.87431
22.44,93.49992,28.29728471,2.88552
22.48,93.66655,28.23844481,2.87952
22.52,93.83329,28.14263384,2.86975
22.56,94.00005,28.49567324,2.90575
22.6,94.16673,28.49792877,2.90598
22.64,94.33337,28.56235846,2.91255
22.68,94.49999,28.58609055,2.91497
22.72,94.66661,28.4021178,2.89621
22.76,94.83323,28.6351238,2.91997
22.8,95.00004,28.56010293,2.91232
22.84,95.16673,28.71946099,2.92857
22.88,95.3333,28.63247601,2.9197
22.92,95.49998,28.56343719,2.91266
22.96,95.66661,28.6166873,2.91809
23,95.83335,28.6761156,2.92415
23.04,96.00011,28.87724999,2.94466
23.08,96.16667,28.90117822,2.9471
23.12,96.3333,28.89647102,2.94662
23.16,96.49999,28.84096538,2.94096
23.2,96.66674,29.01895608,2.95911
23.24,96.83336,28.95472252,2.95256
23.28,96.99998,28.89696136,2.94667
23.32,97.16667,28.93873768,2.95093
23.36,97.3333,29.10035128,2.96741
23.4,97.50005,29.35414738,2.99329
23.44,97.66674,29.28049944,2.98578
23.48,97.83329,29.37072062,2.99498
23.52,97.99998,29.31090005,2.98888
23.56,98.16661,29.26657399,2.98436
23.6,98.33329,29.19881004,2.97745
23.64,98.50005,29.26176874,2.98387
23.68,98.66673,29.39239331,2.99719
23.72,98.83324,29.37023028,2.99493
23.76,98.99999,29.42249973,3.00026
23.8,99.16667,29.49889353,3.00805
23.84,99.3333,29.45025255,3.00309
23.88,99.50005,29.71424757,3.03001
23.92,99.66668,29.61157194,3.01954
23.96,99.83324,29.58009259,3.01633
24,99.99998,29.53861047,3.0121
24.04,100.16668,29.63196977,3.02162
24.08,100.3333,29.67482483,3.02599
24.12,100.50005,29.88017608,3.04693
24.16,100.66673,29.85918985,3.04479
24.2,100.8333,29.95676602,3.05474
24.24,101.00004,29.86546611,3.04543
24.28,101.16674,30.00177854,3.05933
24.32,101.33336,29.93999665,3.05303
24.36,101.50004,30.00982,3.06015
24.4,101.66674,30.05355766,3.06461
24.44,101.83336,30.08454667,3.06777
24.48,101.99999,30.11533955,3.07091
24.52,102.16667,30.03659215,3.06288
24.56,102.3333,30.22252624,3.08184
24.6,102.49998,30.22801796,3.0824
24.64,102.66667,30.25008292,3.08465
24.68,102.83336,30.2229185,3.08188
24.72,103.0001,30.4184631,3.10182
24.76,103.16667,30.32078887,3.09186
24.8,103.33324,30.45308058,3.10535
24.84,103.49993,30.55379487,3.11562
24.88,103.66674,30.49672017,3.1098
24.92,103.83342,30.58841235,3.11915
24.96,104.00005,30.63411134,3.12381
25,104.1666,30.51309728,3.11147
25.04,104.33324,30.48563866,3.10867
25.08,104.49998,30.68383105,3.12888
25.12,104.66673,30.70442502,3.13098
25.16,104.83329,30.75747899,3.13639
25.2,105.00005,30.83995292,3.1448
25.24,105.16661,30.6951087,3.13003
25.28,105.33324,30.71580073,3.13214
25.32,105.50004,30.88427898,3.14932
25.36,105.66674,31.02804447,3.16398
25.4,105.83336,31.12885683,3.17426
25.44,106.00004,31.03167293,3.16435
25.48,106.16673,30.98156095,3.15924
25.52,106.3333,31.11434299,3.17278
25.56,106.50005,31.23800484,3.18539
25.6,106.66673,31.22123547,3.18368
25.64,106.8333,31.14111514,3.17551
25.68,106.99999,31.07276279,3.16854
25.72,107.16667,31.1248361,3.17385
25.76,107.3333,31.31077019,3.19281
25.8,107.50005,31.35078132,3.19689
25.84,107.66674,31.38706592,3.20059
25.88,107.8333,31.2050545,3.18203
25.92,107.99998,31.36009764,3.19784
25.96,108.16667,31.49601781,3.2117
26,108.3333,31.46787272,3.20883
26.04,108.50005,31.7343194,3.236
26.08,108.66674,31.41020962,3.20295
26.12,108.83324,31.62889791,3.22525
26.16,108.99998,31.70019226,3.23252
26.2,109.16674,31.63340897,3.22571
26.24,109.33336,31.75991476,3.23861
26.28,109.49999,31.75697276,3.23831
26.32,109.66661,31.64968801,3.22737
26.36,109.83324,31.69430827,3.23192
26.4,110.00005,31.73471167,3.23604
26.44,110.16686,31.79992589,3.24269
26.48,110.33336,32.08333807,3.27159
26.52,110.49986,32.06794163,3.27002
26.56,110.6666,32.06647064,3.26987
26.6,110.83336,32.18287557,3.28174
26.64,111.00011,32.22396543,3.28593
26.68,111.1668,32.13178292,3.27653
26.72,111.3333,32.24377487,3.28795
26.76,111.49999,32.28623766,3.29228
26.8,111.66661,32.07225656,3.27046
26.84,111.83336,32.14149151,3.27752
26.88,112.00004,32.28123627,3.29177
26.92,112.16674,32.26103457,3.28971
26.96,112.3333,32.29241585,3.29291
27,112.49999,32.20954966,3.28446
27.04,112.66661,32.37145745,3.30097
27.08,112.83336,32.43559294,3.30751
27.12,113.00005,32.57553384,3.32178
27.16,113.16667,32.62937235,3.32727
27.2,113.33324,32.56376586,3.32058
27.24,113.49998,32.65222184,3.3296
27.28,113.66673,32.54434869,3.3186
27.32,113.8333,32.47452534,3.31148
27.36,113.99998,32.5803391,3.32227
27.4,114.16661,32.57955456,3.32219
27.44,114.33329,32.8511007,3.34988
27.48,114.49998,32.75126901,3.3397
27.52,114.66667,32.90062428,3.35493
27.56,114.8333,32.96171971,3.36116
27.6,114.99998,32.91013674,3.3559
27.64,115.1666,33.00153471,3.36522
27.68,115.3333,33.08577384,3.37381
27.72,115.50005,33.04968536,3.37013
27.76,115.66673,33.031445,3.36827
27.8,115.83329,32.91386326,3.35628
27.84,115.99999,33.20884729,3.38636
27.88,116.16673,33.25915541,3.39149
27.92,116.33337,33.19855031,3.38531
27.96,116.50004,32.98241175,3.36327
28,116.66667,33.24199377,3.38974
28.04,116.83323,33.35114179,3.40087
28.08,117.00004,33.3833076,3.40415
28.12,117.1668,33.4415591,3.41009
28.16,117.33335,33.6344559,3.42976
28.2,117.50005,33.61464647,3.42774
28.24,117.66667,33.4611724,3.41209
28.28,117.83324,33.75380283,3.44193
28.32,117.99999,33.56698615,3.42288
28.36,118.16673,33.65210787,3.43156
28.4,118.33323,33.59856357,3.4261
28.44,118.50005,33.82107645,3.44879
28.48,118.66674,33.68858861,3.43528
28.52,118.8333,33.66799465,3.43318
28.56,118.99998,33.77900593,3.4445
28.6,119.16667,33.75841196,3.4424
28.64,119.33323,33.92208495,3.45909
28.68,119.49998,33.80558195,3.44721
28.72,119.66667,33.96150768,3.46311
28.76,119.83336,33.98710304,3.46572
28.8,120.00005,34.04574681,3.4717
28.84,120.16667,33.91796616,3.45867
28.88,120.33324,33.94346345,3.46127
28.92,120.49999,34.23148476,3.49064
28.96,120.6668,34.17637138,3.48502
29,120.83342,34.16617247,3.48398
29.04,120.99999,34.43585534,3.51148
29.08,121.16661,34.31866587,3.49953
29.12,121.3333,34.35446015,3.50318
29.16,121.50005,34.48361373,3.51635
29.2,121.66673,34.23736875,3.49124
29.24,121.83336,34.18068631,3.48546
29.28,122.00005,34.58442609,3.52663
29.32,122.16668,34.54274783,3.52238
29.36,122.33323,34.61992616,3.53025
29.4,122.49999,34.64287372,3.53259
29.44,122.66673,34.64493312,3.5328
29.48,122.8333,34.61306151,3.52955
29.52,122.99999,34.67768733,3.53614
29.56,123.16661,34.78663921,3.54725
29.6,123.3333,34.64336406,3.53264
29.64,123.50004,34.72534765,3.541
29.68,123.66674,34.95786332,3.56471
29.72,123.8333,34.93677902,3.56256
29.76,123.99992,34.82517935,3.55118
29.8,124.16661,34.90873201,3.5597
29.84,124.3333,34.95835365,3.56476
29.88,124.50005,35.04828063,3.57393
29.92,124.66667,34.79624973,3.54823
29.96,124.83324,35.06818813,3.57596
30,124.99998,34.98973493,3.56796
30.04,125.16673,35.05681242,3.5748
30.08,125.33336,35.24323684,3.59381
30.12,125.5001,35.33659614,3.60333
30.16,125.66666,35.15713445,3.58503
30.2,125.83323,35.24755176,3.59425
30.24,126.00005,35.20940389,3.59036
30.28,126.16679,35.41073442,3.61089
30.32,126.33336,35.55332311,3.62543
30.36,126.50005,35.50762412,3.62077
30.4,126.6666,35.3616031,3.60588
30.44,126.83329,35.62618652,3.63286
30.48,127.00011,35.5603839,3.62615
30.52,127.16685,35.62716718,3.63296
30.56,127.33328,35.5799972,3.62815
30.6,127.49985,35.69581373,3.63996
30.64,127.66661,35.78946724,3.64951
30.68,127.83329,35.71964389,3.64239
30.72,128.00003,35.82212339,3.65284
30.76,128.1668,35.68051536,3.6384
30.8,128.33329,35.72140909,3.64257
30.84,128.49991,35.8730199,3.65803
30.88,128.66661,35.89312353,3.66008
30.92,128.8333,35.92254348,3.66308
30.96,129.00004,36.09729799,3.6809
31,129.16672,36.10582977,3.68177
31.04,129.33329,36.11004663,3.6822
31.08,129.49985,36.06601477,3.67771
31.12,129.6666,35.80466755,3.65106
31.16,129.83336,36.04885313,3.67596
31.2,130.00011,36.19722775,3.69109
31.24,130.16666,36.08052861,3.67919
31.28,130.3333,36.21370292,3.69277
31.32,130.50004,36.10014191,3.68119
31.36,130.66679,36.15378429,3.68666
31.4,130.83336,36.2635207,3.69785
31.44,130.99998,36.43631388,3.71547
31.48,131.16667,36.23851375,3.6953
31.52,131.33335,36.5606622,3.72815
31.56,131.50009,36.61881563,3.73408
31.6,131.66673,36.57164565,3.72927
31.64,131.83328,36.31176942,3.70277
31.68,131.99999,36.41405278,3.7132
31.72,132.16667,36.61175484,3.73336
31.76,132.33329,36.51231541,3.72322
31.8,132.50004,36.55958347,3.72804
31.84,132.66667,36.78611708,3.75114
31.88,132.83323,36.60743992,3.73292
31.92,132.99991,36.60175206,3.73234
31.96,133.16668,36.99539099,3.77248
32,133.33336,36.75503,3.74797
32.04,133.50004,36.62793582,3.73501
32.08,133.66667,36.70854648,3.74323
32.12,133.83323,36.25744058,3.69723
32.16,134.00003,35.83801016,3.65446
32.2,134.16673,34.8317498,3.55185
32.24,134.33336,3.474986428,0.35435
32.28,134.50004,-1.515421625,-0.15453
32.32,134.66666,-0.0591341,-0.00603
32.36,134.83323,-0.136802768,-0.01395
32.4,135.00004,-0.140235095,-0.0143
32.44,135.16674,-0.093359308,-0.00952
32.48,135.33329,-0.117875933,-0.01202
32.52,135.50005,0.09610517,0.0098
32.56,135.66679,-0.16700725,-0.01703
32.6,135.8333,-0.110030613,-0.01122
32.64,135.99998,-0.104146623,-0.01062
32.68,136.16666,-0.017161638,-0.00175
32.72,136.33328,-0.005982057,-0.00061
32.76,136.50005,0.070705947,0.00721
32.8,136.66674,0.040305332,0.00411
32.84,136.83336,-0.169655045,-0.0173
32.88,137.00004,-0.011375714,-0.00116
32.92,137.16667,-0.050013915,-0.0051
32.96,137.33323,0.002647796,0.00027
33,137.49997,0.005785924,0.00059
33.04,137.66679,-0.055897905,-0.0057
33.08,137.83336,-0.040795664,-0.00416
33.12,137.99998,-0.006080123,-0.00062
33.16,138.16661,-0.093555441,-0.00954
33.2,138.33323,-0.064920023,-0.00662
33.24,138.50003,0.148864947,0.01518
33.28,138.66673,-0.295082099,-0.03009
33.32,138.83336,-0.054819174,-0.00559
33.36,138.99999,0.19024901,0.0194
33.4,139.16667,0.099831697,0.01018
33.44,139.33323,-0.124544455,-0.0127
33.48,139.50004,-0.046483521,-0.00474
33.52,139.66672,-0.073844075,-0.00753
33.554,139.80836,-0.02549729,-0.0026