File: V_7/FR/RDSO FR Tensile 250.is_tens_RawData/Specimen_RawData_8.csv
Time,Extension,Load,
(sec),(mm),(N),(kgf)
0,0,0.421587884,0.04299
0.04,0.06794,0.942615198,0.09612
0.08,0.27775,1.590834763,0.16222
0.12,0.48262,2.186392618,0.22295
0.16,0.65525,2.850597022,0.29068
0.2,0.82412,3.447822007,0.35158
0.24,0.99487,3.739569845,0.38133
0.28,1.164,4.203522456,0.42864
0.32,1.33162,4.504096279,0.45929
0.36,1.49894,5.011002017,0.51098
0.4,1.666,5.204094956,0.53067
0.44,1.83294,5.590378899,0.57006
0.48,1.99994,5.741205176,0.58544
0.52,2.16669,6.34519675,0.64703
0.56,2.33312,6.686075904,0.68179
0.6,2.49987,6.762469707,0.68958
0.64,2.66669,7.251233143,0.73942
0.68,2.83337,7.477276426,0.76247
0.72,3.00012,7.838063079,0.79926
0.76,3.16675,7.788245297,0.79418
0.8,3.33325,8.176882837,0.83381
0.84,3.49994,8.34771468,0.85123
0.88,3.66662,8.425285281,0.85914
0.92,3.83337,8.585918208,0.87552
0.96,4.00006,8.793524989,0.89669
1,4.16669,9.091156816,0.92704
1.04,4.33325,9.424386783,0.96102
1.08,4.5,9.653470127,0.98438
1.12,4.66675,9.536869059,0.97249
1.16,4.83337,9.546283443,0.97345
1.2,5,9.982090969,1.01789
1.24,5.16662,10.36023539,1.05645
1.28,5.33331,10.58431735,1.0793
1.32,5.5,10.50478541,1.07119
1.36,5.66675,10.56705764,1.07754
1.4,5.83337,10.76064091,1.09728
1.44,6,10.96020624,1.11763
1.48,6.16669,10.92264677,1.1138
1.52,6.33331,11.12466376,1.1344
1.56,6.5,11.61705566,1.18461
1.6,6.66669,11.73179346,1.19631
1.64,6.83331,11.76984326,1.20019
1.68,7,11.73561806,1.1967
1.72,7.16669,11.85751471,1.20913
1.76,7.33337,12.18613556,1.24264
1.8,7.50006,12.1775057,1.24176
1.84,7.66675,12.09660084,1.23351
1.88,7.83331,12.35981133,1.26035
1.92,7.99994,12.65185336,1.29013
1.96,8.16669,12.6142939,1.2863
2,8.33344,12.7887542,1.30409
2.04,8.50019,12.78022241,1.30322
2.08,8.66656,12.84033718,1.30935
2.12,8.83306,13.14316653,1.34023
2.16,9,13.0993308,1.33576
2.2,9.16681,13.07844264,1.33363
2.24,9.33337,13.49179294,1.37578
2.28,9.50006,13.54769084,1.38148
2.32,9.66662,13.56710801,1.38346
2.36,9.83319,13.60251002,1.38707
2.4,10,13.73970505,1.40106
2.44,10.16675,13.87366389,1.41472
2.48,10.33331,14.00772079,1.42839
2.52,10.50006,14.0044846,1.42806
2.56,10.66669,14.2594575,1.45406
2.6,10.83325,14.34006816,1.46228
2.64,11.00006,14.50305469,1.4789
2.68,11.16681,14.38459035,1.46682
2.72,11.33331,14.48501045,1.47706
2.76,11.49994,14.66466828,1.49538
2.8,11.66669,14.69585342,1.49856
2.84,11.83331,14.87394219,1.51672
2.88,12.00006,14.8273606,1.51197
2.92,12.16669,14.80431497,1.50962
2.96,12.33325,15.0038803,1.52997
3,12.5,15.18079227,1.54801
3.04,12.66675,15.26101066,1.55619
3.08,12.83337,15.18510719,1.54845
3.12,13.00006,15.17932127,1.54786
3.16,13.16669,15.11812777,1.54162
3.2,13.33325,15.41919193,1.57232
3.24,13.49994,15.47763956,1.57828
3.28,13.66675,15.59884976,1.59064
3.32,13.83331,15.49342827,1.57989
3.36,14,15.51755263,1.58235
3.4,14.16662,15.69838725,1.60079
3.44,14.33325,15.76468021,1.60755
3.48,14.5,15.88598847,1.61992
3.52,14.66669,16.05868357,1.63753
3.56,14.83331,15.9675798,1.62824
3.6,14.99994,16.01141552,1.63271
3.64,15.16662,15.97395412,1.62889
3.68,15.33337,16.15704427,1.64756
3.72,15.50006,15.97032566,1.62852
3.76,15.66675,16.02426223,1.63402
3.8,15.83331,16.18567969,1.65048
3.84,16,16.26334836,1.6584
3.88,16.16669,16.32571865,1.66476
3.92,16.33331,16.27119368,1.6592
3.96,16.50006,16.40485832,1.67283
4,16.66668,16.46203109,1.67866
4.04,16.83337,16.4166263,1.67403
4.08,17.00006,16.49458917,1.68198
4.12,17.16662,16.5170464,1.68427
4.16,17.33325,16.54646635,1.68727
4.2,17.50006,16.50076736,1.68261
4.24,17.66669,16.60726758,1.69347
4.28,17.83325,16.87871565,1.72115
4.32,18.00006,16.69101637,1.70201
4.36,18.16675,16.7324985,1.70624
4.4,18.33331,17.00816343,1.73435
4.44,18.5,16.95540365,1.72897
4.48,18.66662,17.10760286,1.74449
4.52,18.83331,16.97844928,1.73132
4.56,19.00012,16.89273916,1.72258
4.6,19.16668,16.91686352,1.72504
4.64,19.33318,17.38503299,1.77278
4.68,19.49994,17.12751036,1.74652
4.72,19.66675,16.94755833,1.72817
4.76,19.83331,17.12113604,1.74587
4.8,20.00006,17.24813215,1.75882
4.84,20.16668,17.30324553,1.76444
4.88,20.33331,17.34129533,1.76832
4.92,20.5,17.32295689,1.76645
4.96,20.66668,17.25715427,1.75974
5,20.83331,17.56165075,1.79079
5.04,21.00006,17.29343888,1.76344
5.08,21.16675,17.36090863,1.77032
5.12,21.33331,17.58528478,1.7932
5.16,21.5,17.56204302,1.79083
5.2,21.66675,17.46358425,1.78079
5.24,21.83331,17.38542525,1.77282
5.28,22,17.54517558,1.78911
5.32,22.16668,17.61441053,1.79617
5.36,22.33325,17.62843404,1.7976
5.4,22.5,17.72905027,1.80786
5.44,22.66675,17.64539954,1.79933
5.48,22.83337,17.77318019,1.81236
5.52,23,17.67521176,1.80237
5.56,23.16668,17.74346604,1.80933
5.6,23.33331,18.03962687,1.83953
5.64,23.50006,17.83780602,1.81895
5.68,23.66675,17.84800493,1.81999
5.72,23.83331,17.84476874,1.81966
5.76,23.99993,18.03766554,1.83933
5.8,24.16662,17.96195821,1.83161
5.84,24.33337,17.80318854,1.81542
5.88,24.50006,17.91096363,1.82641
5.92,24.66668,18.03717521,1.83928
5.96,24.83325,17.90380477,1.82568
6,24.99993,17.99873314,1.83536
6.04,25.16675,18.17368378,1.8532
6.08,25.3335,18.24664526,1.86064
6.12,25.50006,17.96107561,1.83152
6.16,25.6665,18.06394737,1.84201
6.2,25.83312,18.23497534,1.85945
6.24,26.00006,18.28596992,1.86465
6.28,26.16681,18.18986475,1.85485
6.32,26.33337,18.17721417,1.85356
6.36,26.50006,18.34275043,1.87044
6.4,26.66668,18.29234425,1.8653
6.44,26.83325,18.45768436,1.88216
6.48,27,18.39541214,1.87581
6.52,27.16668,18.44817191,1.88119
6.56,27.33337,18.60792224,1.89748
6.6,27.50006,18.47180594,1.8836
6.64,27.66668,18.5541818,1.892
6.68,27.83325,18.49308637,1.88577
6.72,28.00006,18.60419572,1.8971
6.76,28.16675,18.60890291,1.89758
6.8,28.33331,18.41306411,1.87761
6.84,28.5,18.64165712,1.90092
6.88,28.66668,18.59409487,1.89607
6.92,28.83331,18.40364972,1.87665
6.96,29.00006,18.54535582,1.8911
7,29.16669,18.72452331,1.90937
7.04,29.33325,18.62420128,1.89914
7.08,29.5,18.67146933,1.90396
7.12,29.66675,18.5939968,1.89606
7.16,29.83337,18.68186438,1.90502
7.2,30.00006,18.84073211,1.92122
7.24,30.16668,18.70422355,1.9073
7.28,30.33325,18.80758564,1.91784
7.32,30.49999,18.81739229,1.91884
7.36,30.66675,18.8267086,1.91979
7.4,30.83337,18.70795007,1.90768
7.44,31,18.92173504,1.92948
7.48,31.16662,18.99812885,1.93727
7.52,31.33331,18.98694926,1.93613
7.56,31.50006,19.04804469,1.94236
7.6,31.66674,19.14895512,1.95265
7.64,31.83331,19.08736936,1.94637
7.68,31.99999,19.05657648,1.94323
7.72,32.16668,19.18582813,1.95641
7.76,32.33337,18.95439119,1.93281
7.8,32.50006,19.01215236,1.9387
7.84,32.66668,19.02656813,1.94017
7.88,32.83331,19.17268722,1.95507
7.92,33,19.28693469,1.96672
7.96,33.16668,19.30272339,1.96833
8,33.33331,19.1616057,1.95394
8.04,33.49999,19.1835726,1.95618
8.08,33.66675,19.32243476,1.97034
8.12,33.83337,19.17680601,1.95549
8.16,34.00006,19.28291396,1.96631
8.2,34.16662,19.45913946,1.98428
8.24,34.33324,19.47669337,1.98607
8.28,34.49999,19.39774983,1.97802
8.32,34.66668,19.32763229,1.97087
8.36,34.83331,19.59476543,1.99811
8.4,35.00006,19.63693403,2.00241
8.44,35.16668,19.50022933,1.98847
8.48,35.33325,19.52043102,1.99053
8.52,35.49999,19.49454147,1.98789
8.56,35.66662,19.52768795,1.99127
8.6,35.83337,19.62673511,2.00137
8.64,36.00012,19.57799606,1.9964
8.68,36.16668,19.72695907,2.01159
8.72,36.33318,19.56495322,1.99507
8.76,36.5,19.59986489,1.99863
8.8,36.66668,19.7333334,2.01224
8.84,36.83337,19.71813309,2.01069
8.88,37.00006,19.85473972,2.02462
8.92,37.16674,19.55053744,1.9936
8.96,37.33331,19.57083721,1.99567
9,37.49999,19.59260797,1.99789
9.04,37.66668,19.95967088,2.03532
9.08,37.83337,19.80119541,2.01916
9.12,38.00006,19.65742993,2.0045
9.16,38.16668,19.85572039,2.02472
9.2,38.33324,19.87533369,2.02672
9.24,38.5,19.87837375,2.02703
9.28,38.66674,20.12069607,2.05174
9.32,38.83331,20.07382028,2.04696
9.36,38.99999,20.09608138,2.04923
9.4,39.16662,19.91367769,2.03063
9.44,39.33324,19.89416246,2.02864
9.48,39.50006,19.99468062,2.03889
9.52,39.66675,20.07323189,2.0469
9.56,39.8333,19.94064598,2.03338
9.6,39.99999,20.23876814,2.06378
9.64,40.16662,20.00909639,2.04036
9.68,40.33331,19.92848573,2.03214
9.72,40.50006,20.23033442,2.06292
9.76,40.66675,20.23337448,2.06323
9.8,40.8333,20.12962012,2.05265
9.84,40.99993,20.07764488,2.04735
9.88,41.16668,20.28240773,2.06823
9.92,41.33337,20.27877927,2.06786
9.96,41.50006,20.19130395,2.05894
10,41.66668,20.35409434,2.07554
10.04,41.83325,20.43382241,2.08367
10.08,41.99999,20.60749818,2.10138
10.12,42.16681,20.44980725,2.0853
10.16,42.3335,20.42381962,2.08265
10.2,42.50005,20.53443863,2.09393
10.24,42.66656,20.45480864,2.08581
10.28,42.83318,20.73253296,2.11413
10.32,43.00006,20.60269292,2.10089
10.36,43.16675,20.57337104,2.0979
10.4,43.33337,20.64388085,2.10509
10.44,43.50006,20.67467373,2.10823
10.48,43.66662,20.89797115,2.131
10.52,43.83324,20.96073371,2.1374
10.56,44,20.91542699,2.13278
10.6,44.16674,21.09586935,2.15118
10.64,44.33337,20.59318047,2.09992
10.68,44.49999,20.82334254,2.12339
10.72,44.66656,20.91434826,2.13267
10.76,44.83324,20.97348236,2.1387
10.8,45.00006,20.97171716,2.13852
10.84,45.1668,21.00290231,2.1417
10.88,45.33324,20.91003333,2.13223
10.92,45.49999,20.9247433,2.13373
10.96,45.66668,20.89296976,2.13049
11,45.83337,21.04830709,2.14633
11.04,46.00006,21.10695086,2.15231
11.08,46.16662,21.08978922,2.15056
11.12,46.33325,21.13627275,2.1553
11.16,46.49999,21.25130475,2.16703
11.2,46.66674,21.08959309,2.15054
11.24,46.83337,20.99839125,2.14124
11.28,47.00006,21.33475934,2.17554
11.32,47.16668,21.21482401,2.16331
11.36,47.33331,21.25532548,2.16744
11.4,47.50005,21.20089857,2.16189
11.44,47.66674,21.23051465,2.16491
11.48,47.8333,21.43714077,2.18598
11.52,47.99999,21.2824899,2.17021
11.56,48.16662,21.50882738,2.19329
11.6,48.3333,21.29131588,2.17111
11.64,48.50006,21.50255112,2.19265
11.68,48.66675,21.50941578,2.19335
11.72,48.83324,21.47695577,2.19004
11.76,48.99999,21.62827238,2.20547
11.8,49.16668,21.54305259,2.19678
11.84,49.33331,21.66083045,2.20879
11.88,49.5,21.48303589,2.19066
11.92,49.66668,21.70898111,2.2137
11.96,49.83325,21.60042149,2.20263
12,49.99993,21.52167409,2.1946
12.04,50.16668,21.88687374,2.23184
12.08,50.33331,21.56953054,2.19948
12.12,50.50005,21.72329881,2.21516
12.16,50.66674,21.83921342,2.22698
12.2,50.83337,21.85657119,2.22875
12.24,50.99999,21.69750732,2.21253
12.28,51.16662,21.96101201,2.2394
12.32,51.33331,21.86186678,2.22929
12.36,51.50005,21.75997569,2.2189
12.4,51.66668,21.76939007,2.21986
12.44,51.8333,21.90678124,2.23387
12.48,52.00006,22.05005639,2.24848
12.52,52.16674,22.07614208,2.25114
12.56,52.33331,22.13341292,2.25698
12.6,52.49993,22.23196975,2.26703
12.64,52.66662,22.22657609,2.26648
12.68,52.83337,22.02622623,2.24605
12.72,53.00011,22.07820148,2.25135
12.76,53.16662,22.0459376,2.24806
12.8,53.33318,22.29777237,2.27374
12.84,53.49993,22.40613585,2.28479
12.88,53.66674,22.32925172,2.27695
12.92,53.83337,22.3767159,2.28179
12.96,54.00006,22.3401371,2.27806
13,54.16668,22.35935813,2.28002
13.04,54.33324,22.50626175,2.295
13.08,54.49993,22.44369532,2.28862
13.12,54.66668,22.37397004,2.28151
13.16,54.83331,22.64100512,2.30874
13.2,55.00006,22.64737944,2.30939
13.24,55.16662,22.53999663,2.29844
13.28,55.33325,22.54941101,2.2994
13.32,55.50005,22.74279815,2.31912
13.36,55.66674,22.74799567,2.31965
13.4,55.83331,22.81360216,2.32634
13.44,55.99999,22.62090149,2.30669
13.48,56.16668,22.67572066,2.31228
13.52,56.3333,22.71298593,2.31608
13.56,56.50006,22.76643217,2.32153
13.6,56.66674,22.75770426,2.32064
13.64,56.83331,22.81585769,2.32657
13.68,56.99999,22.91343386,2.33652
13.72,57.16668,22.86685227,2.33177
13.76,57.3333,22.78614354,2.32354
13.8,57.50006,23.03180012,2.34859
13.84,57.66674,22.98266881,2.34358
13.88,57.83331,23.13163182,2.35877
13.92,57.99993,22.99100446,2.34443
13.96,58.16668,23.0450391,2.34994
14,58.33337,22.90215621,2.33537
14.04,58.50005,23.19782671,2.36552
14.08,58.66668,23.23823011,2.36964
14.12,58.83324,23.24332956,2.37016
14.16,58.99999,23.11800058,2.35738
14.2,59.16681,23.0646524,2.35194
14.24,59.33343,23.22636406,2.36843
14.28,59.49993,23.3190369,2.37788
14.32,59.66649,23.37346381,2.38343
14.36,59.83318,23.48692675,2.395
14.4,60.00006,23.40955228,2.38711
14.44,60.16681,23.43681477,2.38989
14.48,60.33337,23.49565467,2.39589
14.52,60.5,23.52664368,2.39905
14.56,60.66662,23.76827954,2.42369
14.6,60.8333,23.53546967,2.39995
14.64,61.00005,23.56224182,2.40268
14.68,61.16674,23.86134465,2.43318
14.72,61.33337,23.770437,2.42391
14.76,61.49999,23.66001412,2.41265
14.8,61.66662,23.6337323,2.40997
14.84,61.8333,23.71699076,2.41846
14.88,62.00012,23.85487226,2.43252
14.92,62.16674,23.81917605,2.42888
14.96,62.33331,23.70659571,2.4174
15,62.49999,23.91537929,2.43869
15.04,62.66674,23.95784208,2.44302
15.08,62.83336,23.81790119,2.42875
15.12,63.00006,24.05404532,2.45283
15.16,63.16661,24.01217092,2.44856
15.2,63.33324,24.09042799,2.45654
15.24,63.49999,24.09464485,2.45697
15.28,63.66674,23.82908077,2.42989
15.32,63.83331,24.15201375,2.46282
15.36,63.99999,24.2244849,2.47021
15.4,64.16661,24.19231908,2.46693
15.44,64.33324,24.34118403,2.48211
15.48,64.49999,24.34540089,2.48254
15.52,64.66668,24.39355154,2.48745
15.56,64.8333,24.26743802,2.47459
15.6,64.99992,24.28028474,2.4759
15.64,65.16661,24.357365,2.48376
15.68,65.3333,24.47023955,2.49527
15.72,65.50005,24.47190668,2.49544
15.76,65.66674,24.54280876,2.50267
15.8,65.83324,24.60056992,2.50856
15.84,65.99999,24.53202144,2.50157
15.88,66.16674,24.65617363,2.51423
15.92,66.33336,24.52319546,2.50067
15.96,66.50005,24.86005388,2.53502
16,66.66668,24.84779557,2.53377
16.04,66.83324,24.68431872,2.5171
16.08,66.99999,24.70059775,2.51876
16.12,67.16674,24.82435768,2.53138
16.16,67.33336,24.67863086,2.51652
16.2,67.50006,24.81180517,2.5301
16.24,67.66674,25.06265927,2.55568
16.28,67.83336,24.8678992,2.53582
16.32,67.99999,24.95517839,2.54472
16.36,68.16661,25.0453015,2.55391
16.4,68.3333,25.05010676,2.5544
16.44,68.49999,25.09129469,2.5586
16.48,68.66661,24.9896978,2.54824
16.52,68.8333,25.03137606,2.55249
16.56,69.00005,25.15317465,2.56491
16.6,69.16668,25.11247705,2.56076
16.64,69.33324,25.07099492,2.55653
16.68,69.49992,25.32096643,2.58202
16.72,69.66662,25.30635452,2.58053
16.76,69.83336,25.3207703,2.582
16.8,70.00005,25.34920959,2.5849
16.84,70.16661,25.31890704,2.58181
16.88,70.33318,25.27546358,2.57738
16.92,70.49999,25.22603806,2.57234
16.96,70.66674,25.45502334,2.59569
17,70.83336,25.52543509,2.60287
17.04,71.00006,25.5561299,2.606
17.08,71.16674,25.51101931,2.6014
17.12,71.33331,25.60251535,2.61073
17.16,71.49999,25.85376173,2.63635
17.2,71.66667,25.68047822,2.61868
17.24,71.83337,25.71833189,2.62254
17.28,72.00005,25.75216483,2.62599
17.32,72.16667,25.85248686,2.63622
17.36,72.3333,25.81247573,2.63214
17.4,72.50005,25.82336111,2.63325
17.44,72.66674,25.85435013,2.63641
17.48,72.8333,26.07862821,2.65928
17.52,72.99999,25.9457481,2.64573
17.56,73.16662,25.94584617,2.64574
17.6,73.33324,26.0646047,2.65785
17.64,73.49999,26.19522928,2.67117
17.68,73.66674,26.15629688,2.6672
17.72,73.83324,26.26848496,2.67864
17.76,73.99999,26.40509159,2.69257
17.8,74.16661,26.04969859,2.65633
17.84,74.3333,26.26201257,2.67798
17.88,74.50006,26.07146936,2.65855
17.92,74.66668,26.30221983,2.68208
17.96,74.83324,26.32997265,2.68491
18,74.99993,26.479426,2.70015
18.04,75.16674,26.46942321,2.69913
18.08,75.33337,26.40528772,2.69259
18.12,75.50005,26.43333474,2.69545
18.16,75.66668,26.80010345,2.73285
18.2,75.83324,26.41833057,2.69392
18.24,76.00005,26.37861364,2.68987
18.28,76.16686,26.41480017,2.69356
18.32,76.33343,26.70488088,2.72314
18.36,76.49993,26.72694584,2.72539
18.4,76.66649,26.64094152,2.71662
18.44,76.8333,26.88659811,2.74167
18.48,77.00011,26.76970284,2.72975
18.52,77.1668,26.76234785,2.729
18.56,77.33336,26.88512711,2.74152
18.6,77.49998,26.95318526,2.74846
18.64,77.66668,26.92984543,2.74608
18.68,77.83331,26.89140336,2.74216
18.72,77.99999,27.11440659,2.7649
18.76,78.16673,26.95318526,2.74846
18.8,78.3333,27.22169134,2.77584
18.84,78.49999,27.13794255,2.7673
18.88,78.66655,27.15892878,2.76944
18.92,78.8333,27.50833972,2.80507
18.96,79.00004,27.21904354,2.77557
19,79.16674,27.30887245,2.78473
19.04,79.33323,27.26209473,2.77996
19.08,79.49992,27.26199667,2.77995
19.12,79.66667,27.30632273,2.78447
19.16,79.8333,27.38958118,2.79296
19.2,79.99999,27.44714622,2.79883
19.24,80.16662,27.50529965,2.80476
19.28,80.33324,27.64425988,2.81893
19.32,80.50005,27.55119478,2.80944
19.36,80.6668,27.48803995,2.803
19.4,80.83336,27.61258441,2.8157
19.44,81.00005,27.57492687,2.81186
19.48,81.16661,27.78302398,2.83308
19.52,81.3333,27.74203219,2.8289
19.56,81.50005,27.97288073,2.85244
19.6,81.66674,27.65995052,2.82053
19.64,81.8333,27.76821594,2.83157
19.68,81.99998,27.95895528,2.85102
19.72,82.16668,27.82342738,2.8372
19.76,82.33336,28.20873066,2.87649
19.8,82.50011,28.08124421,2.86349
19.84,82.66667,28.16214907,2.87174
19.88,82.83324,27.9082549,2.84585
19.92,82.99999,28.13939764,2.86942
19.96,83.16674,28.10664343,2.86608
20,83.3333,28.19333422,2.87492
20.04,83.49999,28.3031687,2.88612
20.08,83.66668,28.38985948,2.89496
20.12,83.83323,28.30924882,2.88674
20.16,83.99999,28.21020166,2.87664
20.2,84.16668,28.47429474,2.90357
20.24,84.3333,28.45066071,2.90116
20.28,84.49999,28.50263596,2.90646
20.32,84.66673,28.53087911,2.90934
20.36,84.8333,28.32954859,2.88881
20.4,84.99992,28.68454932,2.92501
20.44,85.16661,28.36671579,2.8926
20.48,85.3333,28.72377592,2.92901
20.52,85.49999,28.82125402,2.93895
20.56,85.66667,28.75329393,2.93202
20.6,85.83336,28.6933753,2.92591
20.64,86.00005,28.7914418,2.93591
20.68,86.16674,28.9861038,2.95576
20.72,86.3333,28.85302756,2.94219
20.76,86.49993,28.86401101,2.94331
20.8,86.66674,29.0698526,2.9643
20.84,86.83342,28.99777372,2.95695
20.88,87.00005,29.09397695,2.96676
20.92,87.16661,28.99149746,2.95631
20.96,87.33324,29.31070392,2.98886
21,87.49999,29.32825782,2.99065
21.04,87.66667,29.40524003,2.9985
21.08,87.8333,29.26745659,2.98445
21.12,88.00005,29.40445549,2.99842
21.16,88.16661,29.23676178,2.98132
21.2,88.33324,29.27412511,2.98513
21.24,88.49998,29.33453408,2.99129
21.28,88.66673,29.46751225,3.00485
21.32,88.83336,29.29903401,2.98767
21.36,88.99999,29.35816811,2.9937
21.4,89.16661,29.61618107,3.02001
21.44,89.33323,29.65521153,3.02399
21.48,89.50005,29.61931919,3.02033
21.52,89.66674,29.65933033,3.02441
21.56,89.83323,29.86056278,3.04493
21.6,89.99993,30.07228836,3.06652
21.64,90.16661,29.70865778,3.02944
21.68,90.3333,29.77916759,3.03663
21.72,90.50005,29.88272581,3.04719
21.76,90.66674,29.68208175,3.02673
21.8,90.8333,29.9506859,3.05412
21.84,90.99999,29.94087925,3.05312
21.88,91.16674,29.97716385,3.05682
21.92,91.3333,30.05493059,3.06475
21.96,91.50005,30.37384285,3.09727
22,91.66674,30.29548771,3.08928
22.04,91.8333,30.27391308,3.08708
22.08,91.99998,30.06150104,3.06542
22.12,92.16674,30.30754989,3.09051
22.16,92.33336,30.26400837,3.08607
22.2,92.50005,30.403557,3.1003
22.24,92.66661,30.22487983,3.08208
22.28,92.83324,30.45690517,3.10574
22.32,92.99998,30.50230996,3.11037
22.36,93.1668,30.44327393,3.10435
22.4,93.33336,30.5794883,3.11824
22.44,93.49986,30.56958358,3.11723
22.48,93.66655,30.4591607,3.10597
22.52,93.83329,30.68334072,3.12883
22.56,94.00005,30.99882065,3.161
22.6,94.16673,30.84622918,3.14544
22.64,94.33337,31.00127231,3.16125
22.68,94.49992,30.90899174,3.15184
22.72,94.66661,30.88908424,3.14981
22.76,94.8333,30.89496823,3.15041
22.8,95.00004,30.78640861,3.13934
22.84,95.16673,31.06452521,3.1677
22.88,95.3333,30.99117146,3.16022
22.92,95.49992,31.28605743,3.19029
22.96,95.66661,31.07070339,3.16833
23,95.83335,31.32263623,3.19402
23.04,96.00011,31.23143439,3.18472
23.08,96.16673,31.30684753,3.19241
23.12,96.3333,31.35107552,3.19692
23.16,96.49999,31.30625913,3.19235
23.2,96.66674,31.34019014,3.19581
23.24,96.83336,31.40138363,3.20205
23.28,96.99998,31.36951202,3.1988
23.32,97.16667,31.3803974,3.19991
23.36,97.3333,31.60055669,3.22236
23.4,97.50005,31.68724748,3.2312
23.44,97.66674,31.58398346,3.22067
23.48,97.83329,31.6573372,3.22815
23.52,97.99998,31.69842706,3.23234
23.56,98.16661,31.53740187,3.21592
23.6,98.33329,31.67655823,3.23011
23.64,98.50005,31.65429714,3.22784
23.68,98.66673,31.54201099,3.21639
23.72,98.83324,31.87828102,3.25068
23.76,98.99999,31.6532184,3.22773
23.8,99.16667,31.77060401,3.2397
23.84,99.3333,31.9670312,3.25973
23.88,99.50005,31.96860027,3.25989
23.92,99.6666,32.11491549,3.27481
23.96,99.83324,32.25426798,3.28902
24,99.99998,31.89848272,3.25274
24.04,100.16673,32.06029245,3.26924
24.08,100.3333,32.19327062,3.2828
24.12,100.50005,32.12766413,3.27611
24.16,100.66668,32.27035089,3.29066
24.2,100.8333,32.37606658,3.30144
24.24,101.00004,32.4772712,3.31176
24.28,101.16674,32.49001985,3.31306
24.32,101.33336,32.39695474,3.30357
24.36,101.50004,32.45010678,3.30899
24.4,101.66674,32.58416369,3.32266
24.44,101.83336,32.54944815,3.31912
24.48,101.99999,32.51139835,3.31524
24.52,102.16667,32.46138443,3.31014
24.56,102.3333,32.46187476,3.31019
24.6,102.49998,32.71272887,3.33577
24.64,102.66667,32.77186297,3.3418
24.68,102.8333,32.6537909,3.32976
24.72,103.0001,33.12196038,3.3775
24.76,103.16667,32.96770177,3.36177
24.8,103.33324,32.79363373,3.34402
24.84,103.49993,32.88130518,3.35296
24.88,103.66674,33.10470067,3.37574
24.92,103.83342,33.08459704,3.37369
24.96,104.00005,33.0305624,3.36818
25,104.16655,33.18227127,3.38365
25.04,104.33324,32.97348769,3.36236
25.08,104.49998,33.32995942,3.39871
25.12,104.66673,33.31191519,3.39687
25.16,104.83336,33.46136853,3.41211
25.2,104.99999,33.35114179,3.40087
25.24,105.16661,33.33260722,3.39898
25.28,105.33324,33.35329925,3.40109
25.32,105.49999,33.37585454,3.40339
25.36,105.66674,33.460584,3.41203
25.4,105.83336,33.45930914,3.4119
25.44,106.00004,33.62445312,3.42874
25.48,106.16668,33.66917145,3.4333
25.52,106.3333,33.5413908,3.42027
25.56,106.50011,33.64288962,3.43062
25.6,106.66673,33.76517855,3.44309
25.64,106.8333,33.8552036,3.45227
25.68,106.99999,33.79773663,3.44641
25.72,107.16667,33.92659601,3.45955
25.76,107.3333,33.81980159,3.44866
25.8,107.50005,33.95336816,3.46228
25.84,107.66667,34.07967781,3.47516
25.88,107.83323,34.06212391,3.47337
25.92,107.99998,34.05761285,3.47291
25.96,108.16667,34.0071086,3.46776
26,108.3333,34.35132202,3.50286
26.04,108.50005,34.27728181,3.49531
26.08,108.66674,34.01985725,3.46906
26.12,108.83324,34.21510765,3.48897
26.16,108.99998,34.30719209,3.49836
26.2,109.16674,34.54627822,3.52274
26.24,109.33336,34.61767063,3.53002
26.28,109.49999,34.42830422,3.51071
26.32,109.66661,34.35504855,3.50324
26.36,109.83324,34.42575449,3.51045
26.4,110.00005,34.54294396,3.5224
26.44,110.16686,34.5764827,3.52582
26.48,110.33336,34.58432802,3.52662
26.52,110.49986,34.80968484,3.5496
26.56,110.66655,34.71122607,3.53956
26.6,110.83336,34.75378694,3.5439
26.64,111.00011,34.81203844,3.54984
26.68,111.1668,34.94746827,3.56365
26.72,111.3333,35.02062588,3.57111
26.76,111.49992,34.90971267,3.5598
26.8,111.66661,34.84645978,3.55335
26.84,111.8333,35.09015503,3.5782
26.88,112.00004,35.08397684,3.57757
26.92,112.16674,35.20489284,3.5899
26.96,112.3333,35.04112178,3.5732
27,112.49992,35.13202943,3.58247
27.04,112.66661,35.09378349,3.57857
27.08,112.83336,35.10094235,3.5793
27.12,113.00005,35.40720402,3.61053
27.16,113.16667,35.37268462,3.60701
27.2,113.33324,35.19694945,3.58909
27.24,113.49998,35.54204546,3.62428
27.28,113.66673,35.54233966,3.62431
27.32,113.8333,35.43270131,3.61313
27.36,113.99998,35.40151617,3.60995
27.4,114.16661,35.58656765,3.62882
27.44,114.33324,35.61147654,3.63136
27.48,114.49998,35.58813672,3.62898
27.52,114.66667,35.72582208,3.64302
27.56,114.8333,35.66129433,3.63644
27.6,114.99998,35.75200584,3.64569
27.64,115.1666,35.78721171,3.64928
27.68,115.3333,35.94470651,3.66534
27.72,115.50005,36.19575675,3.69094
27.76,115.66673,35.95098277,3.66598
27.8,115.83329,35.99119003,3.67008
27.84,115.99999,36.24753586,3.69622
27.88,116.16673,36.09484632,3.68065
27.92,116.33337,36.24086734,3.69554
27.96,116.50004,36.19762001,3.69113
28,116.66667,35.95529769,3.66642
28.04,116.83323,36.24528033,3.69599
28.08,117.00004,36.43837327,3.71568
28.12,117.16673,36.37659138,3.70938
28.16,117.33335,36.37747398,3.70947
28.2,117.50005,36.42660529,3.71448
28.24,117.66667,36.57233211,3.72934
28.28,117.83324,36.58615949,3.73075
28.32,117.99999,36.63185848,3.73541
28.36,118.16667,36.46122277,3.71801
28.4,118.3333,36.51957233,3.72396
28.44,118.50005,36.59920233,3.73208
28.48,118.66674,36.93282457,3.7661
28.52,118.8333,36.88634104,3.76136
28.56,118.99998,36.76817091,3.74931
28.6,119.16667,37.00715897,3.77368
28.64,119.33323,37.02794907,3.7758
28.68,119.49998,37.02490901,3.77549
28.72,119.66667,37.04609137,3.77765
28.76,119.83329,37.16102531,3.78937
28.8,120.00005,36.98999733,3.77193
28.84,120.16667,37.20544944,3.7939
28.88,120.33324,37.03628472,3.77665
28.92,120.49999,37.18201154,3.79151
28.96,120.6668,37.37667354,3.81136
29,120.83342,37.31508778,3.80508
29.04,120.99999,37.3457826,3.80821
29.08,121.16661,37.34813619,3.80845
29.12,121.3333,37.4251184,3.8163
29.16,121.49998,37.41943054,3.81572
29.2,121.66673,37.60389362,3.83453
29.24,121.83336,37.47483811,3.82137
29.28,122.00005,37.44875242,3.81871
29.32,122.16668,37.56564769,3.83063
29.36,122.33323,37.74530552,3.84895
29.4,122.49999,37.71186484,3.84554
29.44,122.66668,37.74255966,3.84867
29.48,122.8333,37.74814945,3.84924
29.52,122.99999,37.81395207,3.85595
29.56,123.16661,37.92712081,3.86749
29.6,123.3333,37.83415377,3.85801
29.64,123.50004,37.81493273,3.85605
29.68,123.66674,38.18905643,3.8942
29.72,123.8333,38.19366556,3.89467
29.76,123.99992,38.10569991,3.8857
29.8,124.16661,38.01587099,3.87654
29.84,124.3333,38.17728845,3.893
29.88,124.50005,38.3466493,3.91027
29.92,124.66667,38.11697755,3.88685
29.96,124.83324,38.15728288,3.89096
30,124.99998,38.25387839,3.90081
30.04,125.16673,38.33684265,3.90927
30.08,125.33336,38.47972554,3.92384
30.12,125.50004,38.32889926,3.90846
30.16,125.66666,38.43343815,3.91912
30.2,125.83323,38.44402933,3.9202
30.24,126.00005,38.49796591,3.9257
30.28,126.16679,38.55925747,3.93195
30.32,126.33336,38.49982917,3.92589
30.36,126.50005,38.56720085,3.93276
30.4,126.6666,38.57249645,3.9333
30.44,126.83329,38.77676896,3.95413
30.48,127.00011,38.68340966,3.94461
30.52,127.1668,38.96633151,3.97346
30.56,127.33328,38.95946685,3.97276
30.6,127.49985,38.86777468,3.96341
30.64,127.66661,38.8135439,3.95788
30.68,127.83329,38.90366702,3.96707
30.72,128.00003,38.69713897,3.94601
30.76,128.16672,39.02007195,3.97894
30.8,128.33329,39.00948077,3.97786
30.84,128.49991,39.13569235,3.99073
30.88,128.66661,38.97407876,3.97425
30.92,128.8333,39.17325182,3.99456
30.96,129.00004,39.15520759,3.99272
31,129.16672,39.266415,4.00406
31.04,129.33329,39.09685802,3.98677
31.08,129.49985,39.20630023,3.99793
31.12,129.66667,39.20090658,3.99738
31.16,129.83336,39.49844034,4.02772
31.2,130.00011,39.48510329,4.02636
31.24,130.16666,39.4414637,4.02191
31.28,130.33323,39.7555707,4.05394
31.32,130.50004,39.52746802,4.03068
31.36,130.66679,39.80323102,4.0588
31.4,130.83336,39.7945031,4.05791
31.44,130.99998,39.6993786,4.04821
31.48,131.16667,39.71202918,4.0495
31.52,131.33335,39.9136539,4.07006
31.56,131.50004,39.7181093,4.05012
31.6,131.6668,39.85706953,4.06429
31.64,131.83328,39.76822128,4.05523
31.68,131.99999,39.88599915,4.06724
31.72,132.16667,39.74046846,4.0524
31.76,132.33329,39.84147696,4.0627
31.8,132.50004,39.99043997,4.07789
31.84,132.66667,39.93140394,4.07187
31.88,132.83323,40.00544414,4.07942
31.92,132.99991,40.02289998,4.0812
31.96,133.16668,40.41477371,4.12116
32,133.33336,40.13449966,4.09258
32.04,133.50004,40.28071681,4.10749
32.08,133.66661,40.27797095,4.10721
32.12,133.83323,40.39506235,4.11915
32.16,134.00003,40.15568202,4.09474
32.2,134.16673,40.08399541,4.08743
32.24,134.33329,40.09694019,4.08875
32.28,134.49999,40.41261625,4.12094
32.32,134.66661,40.32749453,4.11226
32.36,134.83323,40.40271153,4.11993
32.4,134.99998,40.14518891,4.09367
32.44,135.16666,40.01770246,4.08067
32.48,135.33329,39.82961091,4.06149
32.52,135.50005,39.148441,3.99203
32.56,135.66679,14.28152246,1.45631
32.6,135.8333,-1.710966226,-0.17447
32.64,135.99998,-0.53965995,-0.05503
32.68,136.16666,-0.105225355,-0.01073
32.72,136.33328,-0.097183902,-0.00991
32.76,136.50005,-0.162005858,-0.01652
32.8,136.66674,0.218394096,0.02227
32.84,136.83336,0.100714296,0.01027
32.88,137.00004,-0.072471144,-0.00739
32.92,137.16667,-0.020986231,-0.00214
32.96,137.33323,-0.158769664,-0.01619
33,137.49997,-0.019809433,-0.00202
33.04,137.66673,0.02383016,0.00243
33.08,137.83336,-0.133076241,-0.01357
33.12,137.99998,-0.043933792,-0.00448
33.16,138.16661,-0.230064009,-0.02346
33.2,138.33323,0.00588399,0.0006
33.24,138.50003,-0.136410502,-0.01391
33.28,138.66673,-0.121112128,-0.01235
33.32,138.83336,-0.215942433,-0.02202
33.36,138.99999,0.100616229,0.01026
33.4,139.16661,0.024614692,0.00251
33.44,139.33323,-0.125034788,-0.01275
33.48,139.49998,0.055113373,0.00562
33.52,139.66672,-0.141019627,-0.01438
33.56,139.83329,-0.106892485,-0.0109
33.6,139.99998,-0.073549875,-0.0075
33.64,140.16667,-0.122975391,-0.01254
33.68,140.33335,-0.0980665,-0.01
33.72,140.5001,-0.020005566,-0.00204
33.76,140.66666,-0.003530394,-0.00036
33.8,140.83329,-0.164065255,-0.01673
33.84,140.99997,0.07286341,0.00743
33.88,141.16667,-0.061389629,-0.00626
33.92,141.33336,-0.044031859,-0.00449
33.96,141.50004,-0.07286341,-0.00743
34,141.66667,-0.154847004,-0.01579
34.04,141.83329,-0.009316318,-0.00095
34.08,142.00004,-0.108559616,-0.01107
34.12,142.16674,-0.295572431,-0.03014
34.16,142.33336,-0.057270836,-0.00584
34.2,142.50005,-0.098949099,-0.01009
34.24,142.66667,-0.366474511,-0.03737
34.28,142.83324,-0.213098505,-0.02173
34.32,142.99998,-0.134154972,-0.01368
34.36,143.16672,-0.056976637,-0.00581
34.4,143.33329,0.052661711,0.00537
34.44,143.49997,-0.163182656,-0.01664
34.48,143.66659,0.025203091,0.00257
34.52,143.83323,-0.058349568,-0.00595
34.56,144.0001,-0.008727919,-0.00089
34.6,144.16679,-0.040109199,-0.00409
34.64,144.33323,-0.136704701,-0.01394
34.68,144.49986,-0.293905301,-0.02997
34.72,144.6666,-0.032165812,-0.00328
34.76,144.8333,-0.053838509,-0.00549
34.8,145.00004,0.149159147,0.01521
34.84,145.16673,0.010689249,0.00109
34.88,145.33329,-0.044326058,-0.00452
34.92,145.49998,-0.089044382,-0.00908
34.96,145.66666,-0.024124359,-0.00246
35,145.83336,0.061291563,0.00625
35.04,146.00004,0.001569064,0.00016
35.08,146.16673,0.081591328,0.00832
35.12,146.3333,-0.148668814,-0.01516
35.16,146.49992,0.032754211,0.00334
35.2,146.66666,-0.063547092,-0.00648
35.24,146.83335,-0.13954863,-0.01423
35.28,147.00005,-0.097380035,-0.00993
35.32,147.16667,-0.08659272,-0.00883
35.36,147.33324,-0.126407719,-0.01289
35.4,147.50004,-0.018828768,-0.00192
35.42,147.58341,-0.118660465,-0.0121