File: NATR/NatR/RDSO NatR Tensile 50.is_tens_RawData/Specimen_RawData_5.csv
Time,Extension,Load,Tensile strain,Tensile stress,Corrected Position
(sec),(mm),(N),(mm/mm),(MPa),(mm)
0.00000,0.00000,0.11878,0.00000,0.01320,0.00000
0.06000,0.03144,0.23803,0.00027,0.02645,0.03144
0.12000,0.09562,0.55962,0.00083,0.06218,0.09562
0.18000,0.14762,0.59029,0.00128,0.06559,0.14762
0.24000,0.19881,0.91857,0.00173,0.10206,0.19881
0.30000,0.24944,0.90429,0.00217,0.10048,0.24944
0.36000,0.29975,1.23058,0.00261,0.13673,0.29975
0.42000,0.34981,1.36479,0.00304,0.15164,0.34981
0.48000,0.39987,1.43334,0.00348,0.15926,0.39987
0.54000,0.44987,1.57130,0.00391,0.17459,0.44987
0.60000,0.49994,1.64083,0.00435,0.18231,0.49994
0.66000,0.54994,1.88131,0.00478,0.20903,0.54994
0.72000,0.59994,1.89948,0.00522,0.21105,0.59994
0.78000,0.65000,2.17856,0.00565,0.24206,0.65000
0.84000,0.69994,2.31632,0.00609,0.25737,0.69994
0.90000,0.75000,2.28395,0.00652,0.25377,0.75000
0.96000,0.80000,2.40371,0.00696,0.26708,0.80000
1.02000,0.85000,2.59817,0.00739,0.28869,0.85000
1.08000,0.90000,2.56672,0.00783,0.28519,0.90000
1.14000,0.95000,2.79353,0.00826,0.31039,0.95000
1.20000,0.99994,2.71173,0.00870,0.30130,0.99994
1.26000,1.05000,2.87315,0.00913,0.31924,1.05000
1.32000,1.10000,3.08292,0.00957,0.34255,1.10000
1.38000,1.15006,3.13915,0.01000,0.34879,1.15006
1.44000,1.19994,3.09570,0.01043,0.34397,1.19994
1.50000,1.24994,3.47681,0.01087,0.38631,1.24994
1.56000,1.29994,3.41776,0.01130,0.37975,1.29994
1.62000,1.34994,3.69552,0.01174,0.41061,1.34994
1.68000,1.39994,3.51242,0.01217,0.39027,1.39994
1.74000,1.45000,3.61034,0.01261,0.40115,1.45000
1.80000,1.50006,3.73806,0.01304,0.41534,1.50006
1.86000,1.55012,3.87374,0.01348,0.43042,1.55012
1.92000,1.60006,3.80808,0.01391,0.42312,1.60006
1.98000,1.65000,3.99590,0.01435,0.44399,1.65000
2.04000,1.69994,4.18441,0.01478,0.46493,1.69994
2.10000,1.75000,4.22822,0.01522,0.46980,1.75000
2.16000,1.80006,4.26829,0.01565,0.47425,1.80006
2.22000,1.85000,4.29528,0.01609,0.47725,1.85000
2.28000,1.90006,4.44242,0.01652,0.49360,1.90006
2.34000,1.95000,4.41034,0.01696,0.49004,1.95000
2.40000,1.99987,4.49334,0.01739,0.49926,1.99987
2.46000,2.04994,4.68518,0.01783,0.52058,2.04994
2.52000,2.10000,4.79980,0.01826,0.53331,2.10000
2.58000,2.15000,5.01422,0.01870,0.55714,2.15000
2.64000,2.20000,5.07652,0.01913,0.56406,2.20000
2.70000,2.24994,5.06768,0.01956,0.56308,2.24994
2.76000,2.30000,5.03364,0.02000,0.55929,2.30000
2.82000,2.35000,5.20123,0.02043,0.57791,2.35000
2.88000,2.40006,5.33180,0.02087,0.59242,2.40006
2.94000,2.45000,5.43843,0.02130,0.60427,2.45000
3.00000,2.50000,5.51406,0.02174,0.61267,2.50000
3.06000,2.55000,5.32986,0.02217,0.59221,2.55000
3.12000,2.60006,5.68995,0.02261,0.63222,2.60006
3.18000,2.65012,5.81351,0.02304,0.64595,2.65012
3.24000,2.70000,5.86377,0.02348,0.65153,2.70000
3.30000,2.75000,5.80210,0.02391,0.64468,2.75000
3.36000,2.80000,6.02565,0.02435,0.66952,2.80000
3.42000,2.85006,6.14436,0.02478,0.68271,2.85006
3.48000,2.90006,6.00400,0.02522,0.66711,2.90006
3.54000,2.94994,6.28580,0.02565,0.69842,2.94994
3.60000,2.99994,6.33978,0.02609,0.70442,2.99994
3.66000,3.04994,6.53825,0.02652,0.72647,3.04994
3.72000,3.10000,6.62669,0.02696,0.73630,3.10000
3.78000,3.15006,6.38584,0.02739,0.70954,3.15006
3.84000,3.20000,6.69536,0.02783,0.74393,3.20000
3.90000,3.24994,6.75906,0.02826,0.75101,3.24994
3.96000,3.29994,6.78380,0.02870,0.75376,3.29994
4.02000,3.35000,6.79247,0.02913,0.75472,3.35000
4.08000,3.40006,7.05764,0.02957,0.78418,3.40006
4.14000,3.45006,6.91649,0.03000,0.76850,3.45006
4.20000,3.50000,7.07018,0.03043,0.78558,3.50000
4.26000,3.55000,7.21078,0.03087,0.80120,3.55000
4.32000,3.60000,7.20049,0.03130,0.80005,3.60000
4.38000,3.65006,7.20162,0.03174,0.80018,3.65006
4.44000,3.70000,7.52223,0.03217,0.83580,3.70000
4.50000,3.75000,7.36378,0.03261,0.81820,3.75000
4.56000,3.80000,7.51004,0.03304,0.83445,3.80000
4.62000,3.85000,7.50340,0.03348,0.83371,3.85000
4.68000,3.90006,7.79484,0.03391,0.86609,3.90006
4.74000,3.94994,7.91950,0.03435,0.87994,3.94994
4.80000,3.99994,7.71410,0.03478,0.85712,3.99994
4.86000,4.05000,8.05188,0.03522,0.89465,4.05000
4.92000,4.10000,7.94417,0.03565,0.88269,4.10000
4.98000,4.15000,8.06665,0.03609,0.89629,4.15000
5.04000,4.19994,8.31624,0.03652,0.92403,4.19994
5.10000,4.24994,8.32447,0.03696,0.92494,4.24994
5.16000,4.29994,8.20764,0.03739,0.91196,4.29994
5.22000,4.35006,8.26008,0.03783,0.91779,4.35006
5.28000,4.40006,8.45902,0.03826,0.93989,4.40006
5.34000,4.45000,8.64268,0.03870,0.96030,4.45000
5.40000,4.50000,8.50940,0.03913,0.94549,4.50000
5.46000,4.55000,8.54253,0.03957,0.94917,4.55000
5.52000,4.60000,8.70636,0.04000,0.96737,4.60000
5.58000,4.65000,8.59566,0.04043,0.95507,4.65000
5.64000,4.70000,8.89200,0.04087,0.98800,4.70000
5.70000,4.75000,8.86072,0.04130,0.98452,4.75000
5.76000,4.80000,8.81108,0.04174,0.97901,4.80000
5.82000,4.84994,8.97208,0.04217,0.99690,4.84994
5.88000,4.90000,9.26047,0.04261,1.02894,4.90000
5.94000,4.94994,9.27602,0.04304,1.03067,4.94994
6.00000,5.00000,9.33416,0.04348,1.03713,5.00000
6.06000,5.05000,9.31594,0.04391,1.03510,5.05000
6.12000,5.10006,9.24105,0.04435,1.02678,5.10006
6.18000,5.15000,9.20789,0.04478,1.02310,5.15000
6.24000,5.20000,9.58811,0.04522,1.06535,5.20000
6.30000,5.25000,9.41824,0.04565,1.04647,5.25000
6.36000,5.30006,9.75365,0.04609,1.08374,5.30006
6.42000,5.35000,9.82014,0.04652,1.09113,5.35000
6.48000,5.40006,9.59906,0.04696,1.06656,5.40006
6.54000,5.45000,9.77760,0.04739,1.08640,5.45000
6.60000,5.50000,9.77485,0.04783,1.08609,5.50000
6.66000,5.55000,9.91019,0.04826,1.10113,5.55000
6.72000,5.60006,10.03280,0.04870,1.11476,5.60006
6.78000,5.65006,10.12236,0.04913,1.12471,5.65006
6.84000,5.70000,10.01974,0.04957,1.11330,5.70000
6.90000,5.74994,10.27910,0.05000,1.14212,5.74994
6.96000,5.79994,10.33867,0.05043,1.14874,5.79994
7.02000,5.85000,10.33036,0.05087,1.14782,5.85000
7.08000,5.90006,10.29194,0.05130,1.14355,5.90006
7.14000,5.94994,10.26598,0.05174,1.14066,5.94994
7.20000,5.99994,10.66325,0.05217,1.18481,5.99994
7.26000,6.05000,10.54917,0.05261,1.17213,6.05000
7.32000,6.10006,10.67084,0.05304,1.18565,6.10006
7.38000,6.15006,10.54530,0.05348,1.17170,6.15006
7.44000,6.20000,10.69183,0.05391,1.18798,6.20000
7.50000,6.25000,10.75754,0.05435,1.19528,6.25000
7.56000,6.30006,11.01900,0.05478,1.22433,6.30006
7.62000,6.35006,10.73591,0.05522,1.19288,6.35006
7.68000,6.40006,11.30063,0.05565,1.25563,6.40006
7.74000,6.44994,11.11849,0.05609,1.23539,6.44994
7.80000,6.49994,11.08300,0.05652,1.23144,6.49994
7.86000,6.55000,11.20097,0.05696,1.24455,6.55000
7.92000,6.60006,11.29710,0.05739,1.25523,6.60006
7.98000,6.65006,11.27717,0.05783,1.25302,6.65006
8.04000,6.70000,11.38133,0.05826,1.26459,6.70000
8.10000,6.74981,11.42475,0.05869,1.26942,6.74981
8.16000,6.79994,11.26580,0.05913,1.25176,6.79994
8.22000,6.85006,11.71752,0.05957,1.30195,6.85006
8.28000,6.90006,11.55994,0.06000,1.28444,6.90006
8.34000,6.95000,11.71120,0.06043,1.30124,6.95000
8.40000,7.00000,11.58029,0.06087,1.28670,7.00000
8.46000,7.05000,11.79870,0.06130,1.31097,7.05000
8.52000,7.10006,11.68673,0.06174,1.29853,7.10006
8.58000,7.15006,11.86672,0.06217,1.31852,7.15006
8.64000,7.20006,11.83196,0.06261,1.31466,7.20006
8.70000,7.25006,12.01295,0.06304,1.33477,7.25006
8.76000,7.30000,12.14413,0.06348,1.34935,7.30000
8.82000,7.35006,11.85881,0.06391,1.31765,7.35006
8.88000,7.40006,12.17971,0.06435,1.35330,7.40006
8.94000,7.44987,12.26744,0.06478,1.36305,7.44987
9.00000,7.49994,12.30183,0.06522,1.36687,7.49994
9.06000,7.54994,12.37611,0.06565,1.37512,7.54994
9.12000,7.60000,12.35456,0.06609,1.37273,7.60000
9.18000,7.65000,12.50145,0.06652,1.38905,7.65000
9.24000,7.70000,12.52492,0.06696,1.39166,7.70000
9.30000,7.75000,12.49195,0.06739,1.38799,7.75000
9.36000,7.80000,12.55244,0.06783,1.39472,7.80000
9.42000,7.85006,12.62535,0.06826,1.40282,7.85006
9.48000,7.90006,12.93933,0.06870,1.43770,7.90006
9.54000,7.95000,12.72587,0.06913,1.41399,7.95000
9.60000,8.00000,12.75991,0.06957,1.41777,8.00000
9.66000,8.05000,12.81854,0.07000,1.42428,8.05000
9.72000,8.10006,13.02427,0.07044,1.44714,8.10006
9.78000,8.15006,12.84822,0.07087,1.42758,8.15006
9.84000,8.20006,13.07379,0.07130,1.45264,8.20006
9.90000,8.25000,13.01442,0.07174,1.44605,8.25000
9.96000,8.30000,13.23122,0.07217,1.47014,8.30000
10.02000,8.34994,13.24647,0.07261,1.47183,8.34994
10.08000,8.40000,12.99595,0.07304,1.44399,8.40000
10.14000,8.44994,13.17234,0.07348,1.46359,8.44994
10.20000,8.49994,13.09852,0.07391,1.45539,8.49994
10.26000,8.54994,13.34250,0.07435,1.48250,8.54994
10.32000,8.60000,13.41686,0.07478,1.49076,8.60000
10.38000,8.65006,13.46060,0.07522,1.49562,8.65006
10.44000,8.70000,13.58051,0.07565,1.50895,8.70000
10.50000,8.75000,13.77808,0.07609,1.53090,8.75000
10.56000,8.80000,13.62369,0.07652,1.51374,8.80000
10.62000,8.85006,13.75778,0.07696,1.52864,8.85006
10.68000,8.90006,13.77541,0.07739,1.53060,8.90006
10.74000,8.95006,13.84842,0.07783,1.53871,8.95006
10.80000,9.00000,13.80042,0.07826,1.53338,9.00000
10.86000,9.05000,14.04567,0.07870,1.56063,9.05000
10.92000,9.10000,13.72317,0.07913,1.52480,9.10000
10.98000,9.15006,13.73399,0.07957,1.52600,9.15006
11.04000,9.20000,14.03590,0.08000,1.55954,9.20000
11.10000,9.25000,14.22237,0.08043,1.58026,9.25000
11.16000,9.30000,14.08392,0.08087,1.56488,9.30000
11.22000,9.35000,14.12184,0.08130,1.56909,9.35000
11.28000,9.40006,14.15938,0.08174,1.57326,9.40006
11.34000,9.45000,14.20408,0.08217,1.57823,9.45000
11.40000,9.50000,14.27216,0.08261,1.58580,9.50000
11.46000,9.55000,14.35149,0.08304,1.59461,9.55000
11.52000,9.59994,14.38191,0.08348,1.59799,9.59994
11.58000,9.65000,14.44331,0.08391,1.60481,9.65000
11.64000,9.69994,14.43170,0.08435,1.60352,9.69994
11.70000,9.75000,14.40030,0.08478,1.60003,9.75000
11.76000,9.80006,14.53943,0.08522,1.61549,9.80006
11.82000,9.85012,14.56684,0.08565,1.61854,9.85012
11.88000,9.90006,14.69897,0.08609,1.63322,9.90006
11.94000,9.94994,14.74847,0.08652,1.63872,9.94994
12.00000,10.00000,14.76115,0.08696,1.64013,10.00000
12.06000,10.05000,14.74829,0.08739,1.63870,10.05000
12.12000,10.10000,14.80044,0.08783,1.64449,10.10000
12.18000,10.15000,15.09019,0.08826,1.67669,10.15000
12.24000,10.19994,14.92551,0.08870,1.65839,10.19994
12.30000,10.25000,14.86375,0.08913,1.65153,10.25000
12.36000,10.29994,14.88767,0.08956,1.65419,10.29994
12.42000,10.34994,15.08960,0.09000,1.67662,10.34994
12.48000,10.40000,14.93227,0.09043,1.65914,10.40000
12.54000,10.44994,15.29609,0.09087,1.69957,10.44994
12.60000,10.49994,15.27429,0.09130,1.69714,10.49994
12.66000,10.55000,15.15387,0.09174,1.68376,10.55000
12.72000,10.60000,15.30508,0.09217,1.70056,10.60000
12.78000,10.65006,15.35815,0.09261,1.70646,10.65006
12.84000,10.70006,15.35425,0.09304,1.70603,10.70006
12.90000,10.75000,15.44499,0.09348,1.71611,10.75000
12.96000,10.80006,15.47137,0.09391,1.71904,10.80006
13.02000,10.85006,15.44166,0.09435,1.71574,10.85006
13.08000,10.90000,15.49706,0.09478,1.72190,10.90000
13.14000,10.94994,15.53208,0.09522,1.72579,10.94994
13.20000,10.99994,15.63456,0.09565,1.73717,10.99994
13.26000,11.05000,15.59275,0.09609,1.73253,11.05000
13.32000,11.10000,15.58557,0.09652,1.73173,11.10000
13.38000,11.15000,15.88655,0.09696,1.76517,11.15000
13.44000,11.19994,15.93026,0.09739,1.77003,11.19994
13.50000,11.24994,15.83729,0.09783,1.75970,11.24994
13.56000,11.29994,15.87244,0.09826,1.76360,11.29994
13.62000,11.35000,16.09839,0.09870,1.78871,11.35000
13.68000,11.40012,16.13792,0.09913,1.79310,11.40012
13.74000,11.45006,16.04515,0.09957,1.78279,11.45006
13.80000,11.49994,16.03019,0.10000,1.78113,11.49994
13.86000,11.54994,16.13555,0.10043,1.79284,11.54994
13.92000,11.60000,16.13567,0.10087,1.79285,11.60000
13.98000,11.65006,16.21940,0.10130,1.80216,11.65006
14.04000,11.70000,16.16280,0.10174,1.79587,11.70000
14.10000,11.75000,16.29055,0.10217,1.81006,11.75000
14.16000,11.80000,16.35944,0.10261,1.81772,11.80000
14.22000,11.85006,16.30784,0.10304,1.81198,11.85006
14.28000,11.90006,16.40544,0.10348,1.82283,11.90006
14.34000,11.95000,16.48788,0.10391,1.83199,11.95000
14.40000,12.00000,16.52170,0.10435,1.83574,12.00000
14.46000,12.04994,16.47815,0.10478,1.83091,12.04994
14.52000,12.10000,16.50519,0.10522,1.83391,12.10000
14.58000,12.15006,16.33895,0.10565,1.81544,12.15006
14.64000,12.20000,16.60783,0.10609,1.84531,12.20000
14.70000,12.24994,16.68192,0.10652,1.85355,12.24994
14.76000,12.30006,16.72527,0.10696,1.85836,12.30006
14.82000,12.35006,16.56745,0.10739,1.84083,12.35006
14.88000,12.40012,16.72169,0.10783,1.85797,12.40012
14.94000,12.45000,16.66953,0.10826,1.85217,12.45000
15.00000,12.50000,16.81042,0.10870,1.86783,12.50000
15.06000,12.55000,16.93729,0.10913,1.88192,12.55000
15.12000,12.60006,16.88858,0.10957,1.87651,12.60006
15.18000,12.65006,16.97581,0.11000,1.88620,12.65006
15.24000,12.70000,16.80722,0.11043,1.86747,12.70000
15.30000,12.75000,17.00572,0.11087,1.88952,12.75000
15.36000,12.79994,16.99881,0.11130,1.88876,12.79994
15.42000,12.84994,17.05426,0.11174,1.89492,12.84994
15.48000,12.90000,17.09428,0.11217,1.89936,12.90000
15.54000,12.95000,17.32653,0.11261,1.92517,12.95000
15.60000,13.00006,17.20924,0.11304,1.91214,13.00006
15.66000,13.05000,17.26591,0.11348,1.91843,13.05000
15.72000,13.09994,17.32511,0.11391,1.92501,13.09994
15.78000,13.15000,17.21531,0.11435,1.91281,13.15000
15.84000,13.20000,17.40267,0.11478,1.93363,13.20000
15.90000,13.25000,17.42537,0.11522,1.93615,13.25000
15.96000,13.30000,17.44330,0.11565,1.93814,13.30000
16.02000,13.35006,17.58417,0.11609,1.95380,13.35006
16.08000,13.40006,17.62081,0.11652,1.95787,13.40006
16.14000,13.45000,17.59684,0.11696,1.95520,13.45000
16.20000,13.50000,17.53455,0.11739,1.94828,13.50000
16.26000,13.55000,17.55537,0.11783,1.95060,13.55000
16.32000,13.60006,17.61804,0.11826,1.95756,13.60006
16.38000,13.65000,17.71226,0.11870,1.96803,13.65000
16.44000,13.70000,17.65882,0.11913,1.96209,13.70000
16.50000,13.74993,17.93229,0.11956,1.99248,13.74993
16.56000,13.79994,17.73641,0.12000,1.97071,13.79994
16.62000,13.84994,17.94414,0.12043,1.99379,13.84994
16.68000,13.90000,17.85387,0.12087,1.98376,13.90000
16.74000,13.95000,17.95854,0.12130,1.99539,13.95000
16.80000,14.00000,17.82928,0.12174,1.98103,14.00000
16.86000,14.04994,18.19559,0.12217,2.02173,14.04994
16.92000,14.10000,18.10162,0.12261,2.01129,14.10000
16.98000,14.15006,18.02783,0.12304,2.00309,14.15006
17.04000,14.20000,18.09099,0.12348,2.01011,14.20000
17.10000,14.25000,18.26897,0.12391,2.02989,14.25000
17.16000,14.30006,18.03819,0.12435,2.00424,14.30006
17.22000,14.35006,18.19293,0.12478,2.02144,14.35006
17.28000,14.40006,18.43551,0.12522,2.04839,14.40006
17.34000,14.45000,18.37499,0.12565,2.04167,14.45000
17.40000,14.50000,18.47403,0.12609,2.05267,14.50000
17.46000,14.55000,18.33436,0.12652,2.03715,14.55000
17.52000,14.60000,18.39628,0.12696,2.04403,14.60000
17.58000,14.65000,18.41070,0.12739,2.04563,14.65000
17.64000,14.69987,18.50857,0.12782,2.05651,14.69987
17.70000,14.74994,18.46960,0.12826,2.05218,14.74994
17.76000,14.79994,18.08646,0.12870,2.00961,14.79994
17.82000,14.85000,18.76543,0.12913,2.08505,14.85000
17.88000,14.90006,18.54241,0.12957,2.06027,14.90006
17.94000,14.94994,18.62529,0.13000,2.06948,14.94994
18.00000,14.99994,18.49451,0.13043,2.05495,14.99994
18.06000,15.05000,18.62850,0.13087,2.06983,15.05000
18.12000,15.10006,18.69387,0.13130,2.07710,15.10006
18.18000,15.15006,18.78436,0.13174,2.08715,15.15006
18.24000,15.20006,18.80616,0.13217,2.08957,15.20006
18.30000,15.25000,18.92661,0.13261,2.10296,15.25000
18.36000,15.30006,18.75850,0.13304,2.08428,15.30006
18.42000,15.35000,18.91896,0.13348,2.10211,15.35000
18.48000,15.40000,18.74767,0.13391,2.08307,15.40000
18.54000,15.44994,19.05736,0.13435,2.11748,15.44994
18.60000,15.49994,18.97314,0.13478,2.10813,15.49994
18.66000,15.54994,18.90498,0.13522,2.10055,15.54994
18.72000,15.60000,19.16096,0.13565,2.12900,15.60000
18.78000,15.65006,19.01823,0.13609,2.11314,15.65006
18.84000,15.69993,19.08413,0.13652,2.12046,15.69993
18.90000,15.74993,18.90478,0.13696,2.10053,15.74993
18.96000,15.80000,19.26355,0.13739,2.14039,15.80000
19.02000,15.85000,19.22626,0.13783,2.13625,15.85000
19.08000,15.90006,19.23098,0.13826,2.13678,15.90006
19.14000,15.94994,19.27766,0.13870,2.14196,15.94994
19.20000,16.00000,19.28241,0.13913,2.14249,16.00000
19.26000,16.05000,19.21009,0.13957,2.13445,16.05000
19.32000,16.10006,19.32202,0.14000,2.14689,16.10006
19.38000,16.15012,19.43448,0.14044,2.15939,16.15012
19.44000,16.20006,19.40284,0.14087,2.15587,16.20006
19.50000,16.25000,19.40044,0.14130,2.15560,16.25000
19.56000,16.29987,19.65480,0.14174,2.18387,16.29987
19.62000,16.35000,19.55311,0.14217,2.17257,16.35000
19.68000,16.40006,19.39676,0.14261,2.15520,16.40006
19.74000,16.44993,19.60469,0.14304,2.17830,16.44993
19.80000,16.50000,19.57765,0.14348,2.17529,16.50000
19.86000,16.54994,19.38537,0.14391,2.15393,16.54994
19.92000,16.60000,19.59803,0.14435,2.17756,16.60000
19.98000,16.65006,19.87429,0.14478,2.20825,16.65006
20.04000,16.70000,19.70302,0.14522,2.18922,16.70000
20.10000,16.75000,19.64101,0.14565,2.18233,16.75000
20.16000,16.80000,19.70275,0.14609,2.18919,16.80000
20.22000,16.85006,19.67214,0.14652,2.18579,16.85006
20.28000,16.90006,19.72629,0.14696,2.19181,16.90006
20.34000,16.95006,19.95195,0.14739,2.21688,16.95006
20.40000,17.00000,19.87953,0.14783,2.20884,17.00000
20.46000,17.05000,19.96917,0.14826,2.21880,17.05000
20.52000,17.10000,19.87194,0.14870,2.20799,17.10000
20.58000,17.15006,19.98852,0.14913,2.22095,17.15006
20.64000,17.19994,20.24658,0.14956,2.24962,17.19994
20.70000,17.24993,20.08886,0.15000,2.23210,17.24993
20.76000,17.29993,20.20735,0.15043,2.24526,17.29993
20.82000,17.35000,19.96971,0.15087,2.21886,17.35000
20.88000,17.40006,20.00245,0.15130,2.22249,17.40006
20.94000,17.44993,19.97551,0.15174,2.21950,17.44993
21.00000,17.49994,20.16549,0.15217,2.24061,17.49994
21.06000,17.54993,20.25625,0.15261,2.25069,17.54993
21.12000,17.60000,20.22275,0.15304,2.24697,17.60000
21.18000,17.65000,20.14088,0.15348,2.23788,17.65000
21.24000,17.70000,20.25660,0.15391,2.25073,17.70000
21.30000,17.75000,20.20485,0.15435,2.24498,17.75000
21.36000,17.80012,20.22420,0.15478,2.24713,17.80012
21.42000,17.85006,20.37824,0.15522,2.26425,17.85006
21.48000,17.90000,20.50200,0.15565,2.27800,17.90000
21.54000,17.94994,20.48309,0.15609,2.27590,17.94994
21.60000,17.99993,20.51096,0.15652,2.27900,17.99993
21.66000,18.05000,20.35973,0.15696,2.26219,18.05000
21.72000,18.10000,20.50004,0.15739,2.27778,18.10000
21.78000,18.15000,20.44102,0.15783,2.27122,18.15000
21.84000,18.19994,20.39113,0.15826,2.26568,18.19994
21.90000,18.24994,20.36869,0.15870,2.26319,18.24994
21.96000,18.30000,20.72550,0.15913,2.30283,18.30000
22.02000,18.35006,20.73126,0.15957,2.30347,18.35006
22.08000,18.40006,20.65401,0.16000,2.29489,18.40006
22.14000,18.45000,20.56991,0.16043,2.28555,18.45000
22.20000,18.50006,20.66053,0.16087,2.29561,18.50006
22.26000,18.55000,20.61938,0.16130,2.29104,18.55000
22.32000,18.60006,20.66903,0.16174,2.29656,18.60006
22.38000,18.65006,20.87529,0.16217,2.31948,18.65006
22.44000,18.70000,20.73831,0.16261,2.30426,18.70000
22.50000,18.75000,20.86892,0.16304,2.31877,18.75000
22.56000,18.79987,20.90835,0.16348,2.32315,18.79987
22.62000,18.84994,20.81078,0.16391,2.31231,18.84994
22.68000,18.90000,20.86327,0.16435,2.31814,18.90000
22.74000,18.95000,20.88110,0.16478,2.32012,18.95000
22.80000,19.00000,20.87936,0.16522,2.31993,19.00000
22.86000,19.05000,21.13073,0.16565,2.34786,19.05000
22.92000,19.10000,21.01188,0.16609,2.33465,19.10000
22.98000,19.14994,20.98381,0.16652,2.33153,19.14994
23.04000,19.19993,20.96706,0.16696,2.32967,19.19993
23.10000,19.24993,21.02158,0.16739,2.33573,19.24993
23.16000,19.30000,21.15410,0.16783,2.35046,19.30000
23.22000,19.35006,21.01088,0.16826,2.33454,19.35006
23.28000,19.40006,20.97693,0.16870,2.33077,19.40006
23.34000,19.44994,21.07732,0.16913,2.34192,19.44994
23.40000,19.49994,21.23139,0.16956,2.35904,19.49994
23.46000,19.54993,21.04034,0.17000,2.33782,19.54993
23.52000,19.60006,21.13487,0.17044,2.34832,19.60006
23.58000,19.65006,21.16451,0.17087,2.35161,19.65006
23.64000,19.70000,21.26380,0.17130,2.36264,19.70000
23.70000,19.75000,21.30991,0.17174,2.36777,19.75000
23.76000,19.80006,21.33786,0.17217,2.37087,19.80006
23.82000,19.85006,21.23338,0.17261,2.35926,19.85006
23.88000,19.90006,21.14847,0.17304,2.34983,19.90006
23.94000,19.95000,21.37687,0.17348,2.37521,19.95000
24.00000,19.99993,21.36644,0.17391,2.37405,19.99993
24.06000,20.04993,21.17776,0.17435,2.35308,20.04993
24.12000,20.10000,21.48346,0.17478,2.38705,20.10000
24.18000,20.15000,21.41792,0.17522,2.37977,20.15000
24.24000,20.19993,21.45598,0.17565,2.38400,20.19993
24.30000,20.24994,21.51351,0.17609,2.39039,20.24994
24.36000,20.30000,21.49815,0.17652,2.38868,20.30000
24.42000,20.35006,21.56957,0.17696,2.39662,20.35006
24.48000,20.40006,21.34839,0.17739,2.37204,20.40006
24.54000,20.44993,21.46624,0.17783,2.38514,20.44993
24.60000,20.49993,21.50993,0.17826,2.38999,20.49993
24.66000,20.55006,21.58990,0.17870,2.39888,20.55006
24.72000,20.60012,21.46668,0.17913,2.38519,20.60012
24.78000,20.65012,21.71269,0.17957,2.41252,20.65012
24.84000,20.70000,21.55255,0.18000,2.39473,20.70000
24.90000,20.74993,21.67449,0.18043,2.40828,20.74993
24.96000,20.79993,21.62511,0.18087,2.40279,20.79993
25.02000,20.85000,21.64997,0.18130,2.40555,20.85000
25.08000,20.90000,21.94822,0.18174,2.43869,20.90000
25.14000,20.95000,21.68017,0.18217,2.40891,20.95000
25.20000,21.00000,21.73780,0.18261,2.41531,21.00000
25.26000,21.04987,21.62634,0.18304,2.40293,21.04987
25.32000,21.09993,21.80370,0.18348,2.42263,21.09993
25.38000,21.15006,21.91274,0.18391,2.43475,21.15006
25.44000,21.20000,21.67703,0.18435,2.40856,21.20000
25.50000,21.25000,21.86030,0.18478,2.42892,21.25000
25.56000,21.30000,21.96823,0.18522,2.44091,21.30000
25.62000,21.34999,21.91817,0.18565,2.43535,21.34999
25.68000,21.40012,21.90326,0.18609,2.43370,21.40012
25.74000,21.45006,21.91849,0.18652,2.43539,21.45006
25.80000,21.50000,21.63444,0.18696,2.40383,21.50000
25.86000,21.55006,22.20381,0.18739,2.46709,21.55006
25.92000,21.60000,21.86980,0.18783,2.42998,21.60000
25.98000,21.65006,22.00330,0.18826,2.44481,21.65006
26.04000,21.70000,22.23987,0.18870,2.47110,21.70000
26.10000,21.75000,22.12723,0.18913,2.45858,21.75000
26.16000,21.79994,22.09948,0.18956,2.45550,21.79994
26.22000,21.85000,22.14489,0.19000,2.46054,21.85000
26.28000,21.90000,21.88629,0.19043,2.43181,21.90000
26.34000,21.95000,21.99966,0.19087,2.44441,21.95000
26.40000,21.99993,22.23254,0.19130,2.47028,21.99993
26.46000,22.04994,22.34074,0.19174,2.48230,22.04994
26.52000,22.10000,22.20543,0.19217,2.46727,22.10000
26.58000,22.15006,22.18214,0.19261,2.46468,22.15006
26.64000,22.20000,22.20465,0.19304,2.46718,22.20000
26.70000,22.25006,22.29681,0.19348,2.47742,22.25006
26.76000,22.30006,22.28380,0.19391,2.47598,22.30006
26.82000,22.35006,22.24413,0.19435,2.47157,22.35006
26.88000,22.40006,22.41897,0.19478,2.49100,22.40006
26.94000,22.45000,22.34060,0.19522,2.48229,22.45000
27.00000,22.50000,22.32331,0.19565,2.48037,22.50000
27.06000,22.55006,22.48071,0.19609,2.49786,22.55006
27.12000,22.60006,22.42872,0.19652,2.49208,22.60006
27.18000,22.64993,22.49871,0.19696,2.49986,22.64993
27.24000,22.69994,22.46006,0.19739,2.49556,22.69994
27.30000,22.74993,22.44716,0.19783,2.49413,22.74993
27.36000,22.79993,22.62656,0.19826,2.51406,22.79993
27.42000,22.85006,22.52766,0.19870,2.50307,22.85006
27.48000,22.90000,22.51071,0.19913,2.50119,22.90000
27.54000,22.95000,22.51588,0.19957,2.50176,22.95000
27.60000,23.00000,22.65119,0.20000,2.51680,23.00000
27.66000,23.05000,22.65572,0.20043,2.51730,23.05000
27.72000,23.10006,22.67221,0.20087,2.51913,23.10006
27.78000,23.15012,22.66175,0.20131,2.51797,23.15012
27.84000,23.20000,22.83324,0.20174,2.53703,23.20000
27.90000,23.25000,22.76699,0.20217,2.52967,23.25000
27.96000,23.30000,22.76442,0.20261,2.52938,23.30000
28.02000,23.35000,22.58913,0.20304,2.50990,23.35000
28.08000,23.40006,22.79295,0.20348,2.53255,23.40006
28.14000,23.44993,22.96554,0.20391,2.55173,23.44993
28.20000,23.49993,22.79491,0.20435,2.53277,23.49993
28.26000,23.54993,22.79858,0.20478,2.53318,23.54993
28.32000,23.60000,22.92478,0.20522,2.54720,23.60000
28.38000,23.65000,22.97022,0.20565,2.55225,23.65000
28.44000,23.69993,22.83294,0.20609,2.53699,23.69993
28.50000,23.74993,22.86072,0.20652,2.54008,23.74993
28.56000,23.79999,22.71220,0.20696,2.52358,23.79999
28.62000,23.85006,23.18172,0.20739,2.57575,23.85006
28.68000,23.90000,23.17998,0.20783,2.57555,23.90000
28.74000,23.94993,22.85241,0.20826,2.53916,23.94993
28.80000,24.00000,23.04895,0.20870,2.56099,24.00000
28.86000,24.05006,23.12581,0.20913,2.56953,24.05006
28.92000,24.10006,23.08572,0.20957,2.56508,24.10006
28.98000,24.15012,23.10354,0.21000,2.56706,24.15012
29.04000,24.20000,23.37611,0.21043,2.59735,24.20000
29.10000,24.24987,23.27471,0.21087,2.58608,24.24987
29.16000,24.29993,23.05204,0.21130,2.56134,24.29993
29.22000,24.35000,23.13766,0.21174,2.57085,24.35000
29.28000,24.40000,23.23697,0.21217,2.58189,24.40000
29.34000,24.44993,23.41833,0.21261,2.60204,24.44993
29.40000,24.49987,23.30391,0.21304,2.58932,24.49987
29.46000,24.54993,23.27777,0.21348,2.58642,24.54993
29.52000,24.60000,23.19541,0.21391,2.57727,24.60000
29.58000,24.64999,23.29561,0.21435,2.58840,24.64999
29.64000,24.70006,23.34461,0.21478,2.59385,24.70006
29.70000,24.75000,23.29188,0.21522,2.58799,24.75000
29.76000,24.80000,23.28275,0.21565,2.58697,24.80000
29.82000,24.85006,23.39979,0.21609,2.59998,24.85006
29.88000,24.90006,23.40493,0.21652,2.60055,24.90006
29.94000,24.95000,23.36920,0.21696,2.59658,24.95000
30.00000,24.99999,23.52244,0.21739,2.61360,24.99999
30.06000,25.05000,23.50327,0.21783,2.61147,25.05000
30.12000,25.10000,23.40417,0.21826,2.60046,25.10000
30.18000,25.15006,23.61806,0.21870,2.62423,25.15006
30.24000,25.20000,23.52697,0.21913,2.61411,25.20000
30.30000,25.24993,23.61431,0.21956,2.62381,25.24993
30.36000,25.30000,23.55452,0.22000,2.61717,25.30000
30.42000,25.35006,23.68462,0.22044,2.63162,25.35006
30.48000,25.40000,23.71617,0.22087,2.63513,25.40000
30.54000,25.45000,23.65403,0.22130,2.62823,25.45000
30.60000,25.49987,23.68225,0.22174,2.63136,25.49987
30.66000,25.54993,23.76456,0.22217,2.64051,25.54993
30.72000,25.60000,23.73196,0.22261,2.63688,25.60000
30.78000,25.65006,23.82057,0.22304,2.64673,25.65006
30.84000,25.70006,23.72569,0.22348,2.63619,25.70006
30.90000,25.75000,23.83556,0.22391,2.64840,25.75000
30.96000,25.79993,23.94888,0.22435,2.66099,25.79993
31.02000,25.84993,23.81144,0.22478,2.64572,25.84993
31.08000,25.90006,24.03029,0.22522,2.67003,25.90006
31.14000,25.95000,23.88564,0.22565,2.65396,25.95000
31.20000,26.00000,24.09512,0.22609,2.67724,26.00000
31.26000,26.05000,24.07063,0.22652,2.67451,26.05000
31.32000,26.10000,24.08618,0.22696,2.67624,26.10000
31.38000,26.15006,23.94330,0.22739,2.66037,26.15006
31.44000,26.19993,23.88062,0.22783,2.65340,26.19993
31.50000,26.25000,24.22957,0.22826,2.69217,26.25000
31.56000,26.30000,24.09972,0.22870,2.67775,26.30000
31.62000,26.35000,24.02505,0.22913,2.66945,26.35000
31.68000,26.40006,24.13915,0.22957,2.68213,26.40006
31.74000,26.45000,24.13350,0.23000,2.68150,26.45000
31.80000,26.50000,24.02823,0.23043,2.66980,26.50000
31.86000,26.54999,24.25566,0.23087,2.69507,26.54999
31.92000,26.60000,24.16967,0.23130,2.68552,26.60000
31.98000,26.65006,24.32800,0.23174,2.70311,26.65006
32.04000,26.70000,24.17628,0.23217,2.68625,26.70000
32.10000,26.75000,24.41977,0.23261,2.71331,26.75000
32.16000,26.80000,24.28654,0.23304,2.69850,26.80000
32.22000,26.84999,24.33599,0.23348,2.70400,26.84999
32.28000,26.90012,24.30954,0.23391,2.70106,26.90012
32.34000,26.95006,24.27885,0.23435,2.69765,26.95006
32.40000,27.00006,24.39381,0.23478,2.71042,27.00006
32.46000,27.05000,24.31615,0.23522,2.70179,27.05000
32.52000,27.10000,24.39104,0.23565,2.71012,27.10000
32.58000,27.15000,24.45281,0.23609,2.71698,27.15000
32.64000,27.19993,24.45737,0.23652,2.71749,27.19993
32.70000,27.24993,24.48007,0.23696,2.72001,27.24993
32.76000,27.29993,24.53013,0.23739,2.72557,27.29993
32.82000,27.35000,24.67982,0.23783,2.74220,27.35000
32.88000,27.39993,24.59207,0.23826,2.73245,27.39993
32.94000,27.44993,24.62675,0.23870,2.73631,27.44993
33.00000,27.49993,24.66765,0.23913,2.74085,27.49993
33.06000,27.55000,24.62537,0.23957,2.73615,27.55000
33.12000,27.60006,24.74538,0.24000,2.74949,27.60006
33.18000,27.65012,24.64053,0.24044,2.73784,27.65012
33.24000,27.70000,24.71927,0.24087,2.74659,27.70000
33.30000,27.74999,24.75611,0.24130,2.75068,27.74999
33.36000,27.80000,24.73571,0.24174,2.74841,27.80000
33.42000,27.85006,24.72677,0.24217,2.74742,27.85006
33.48000,27.90006,24.82444,0.24261,2.75827,27.90006
33.54000,27.94993,24.78129,0.24304,2.75348,27.94993
33.60000,27.99993,24.81337,0.24348,2.75704,27.99993
33.66000,28.05000,24.67516,0.24391,2.74168,28.05000
33.72000,28.10000,24.85187,0.24435,2.76132,28.10000
33.78000,28.15000,24.96269,0.24478,2.77363,28.15000
33.84000,28.20000,25.00149,0.24522,2.77794,28.20000
33.90000,28.25000,24.98321,0.24565,2.77591,28.25000
33.96000,28.30000,25.20055,0.24609,2.80006,28.30000
34.02000,28.35006,25.07185,0.24652,2.78576,28.35006
34.08000,28.40000,24.93548,0.24696,2.77061,28.40000
34.14000,28.45000,24.93487,0.24739,2.77054,28.45000
34.20000,28.50000,25.23454,0.24783,2.80384,28.50000
34.26000,28.55006,25.26687,0.24826,2.80743,28.55006
34.32000,28.60012,25.10763,0.24870,2.78974,28.60012
34.38000,28.65006,25.29736,0.24913,2.81082,28.65006
34.44000,28.69993,25.10342,0.24956,2.78927,28.69993
34.50000,28.74993,25.11652,0.25000,2.79072,28.74993
34.56000,28.80000,25.48440,0.25043,2.83160,28.80000
34.62000,28.85000,25.27966,0.25087,2.80885,28.85000
34.68000,28.90006,24.87585,0.25130,2.76398,28.90006
34.74000,28.94993,25.31762,0.25174,2.81307,28.94993
34.80000,28.99987,25.42959,0.25217,2.82551,28.99987
34.86000,29.04993,25.22232,0.25261,2.80248,29.04993
34.92000,29.10000,25.24238,0.25304,2.80471,29.10000
34.98000,29.15006,25.55670,0.25348,2.83963,29.15006
35.04000,29.19993,25.29354,0.25391,2.81039,29.19993
35.10000,29.24993,25.46819,0.25435,2.82980,29.24993
35.16000,29.29999,25.38428,0.25478,2.82048,29.29999
35.22000,29.35006,25.54313,0.25522,2.83813,29.35006
35.28000,29.40006,25.44769,0.25565,2.82752,29.40006
35.34000,29.45000,25.69182,0.25609,2.85465,29.45000
35.40000,29.50000,25.40336,0.25652,2.82260,29.50000
35.46000,29.55000,25.39268,0.25696,2.82141,29.55000
35.52000,29.59999,25.67458,0.25739,2.85273,29.59999
35.58000,29.65006,25.75290,0.25783,2.86143,29.65006
35.64000,29.69993,25.64423,0.25826,2.84936,29.69993
35.70000,29.74994,25.65937,0.25870,2.85104,29.74994
35.76000,29.80000,25.67830,0.25913,2.85314,29.80000
35.82000,29.85000,25.55954,0.25957,2.83995,29.85000
35.88000,29.90006,25.57722,0.26000,2.84191,29.90006
35.94000,29.95000,25.69620,0.26043,2.85513,29.95000
36.00000,29.99987,25.75569,0.26087,2.86174,29.99987
36.06000,30.04993,25.79216,0.26130,2.86580,30.04993
36.12000,30.10006,25.86397,0.26174,2.87377,30.10006
36.18000,30.15006,25.66701,0.26217,2.85189,30.15006
36.24000,30.20006,25.89375,0.26261,2.87708,30.20006
36.30000,30.24993,25.99056,0.26304,2.88784,30.24993
36.36000,30.30000,25.93110,0.26348,2.88123,30.30000
36.42000,30.35000,25.76458,0.26391,2.86273,30.35000
36.48000,30.40006,26.06873,0.26435,2.89653,30.40006
36.54000,30.45000,25.74308,0.26478,2.86034,30.45000
36.60000,30.50006,26.12497,0.26522,2.90277,30.50006
36.66000,30.55000,25.95786,0.26565,2.88421,30.55000
36.72000,30.59993,26.01652,0.26609,2.89072,30.59993
36.78000,30.65000,25.95615,0.26652,2.88402,30.65000
36.84000,30.69993,26.06612,0.26696,2.89623,30.69993
36.90000,30.74993,26.18088,0.26739,2.90899,30.74993
36.96000,30.79993,26.29658,0.26783,2.92184,30.79993
37.02000,30.84993,26.06658,0.26826,2.89629,30.84993
37.08000,30.90000,26.15595,0.26870,2.90622,30.90000
37.14000,30.95000,26.26006,0.26913,2.91778,30.95000
37.20000,31.00000,26.15742,0.26957,2.90638,31.00000
37.26000,31.05000,26.34149,0.27000,2.92683,31.05000
37.32000,31.10006,26.29675,0.27044,2.92186,31.10006
37.38000,31.15006,26.17804,0.27087,2.90867,31.15006
37.44000,31.20000,26.32842,0.27130,2.92538,31.20000
37.50000,31.25000,26.28764,0.27174,2.92085,31.25000
37.56000,31.29999,26.43299,0.27217,2.93700,31.29999
37.62000,31.35006,26.46363,0.27261,2.94040,31.35006
37.68000,31.40006,26.39780,0.27304,2.93309,31.40006
37.74000,31.45000,26.21624,0.27348,2.91292,31.45000
37.80000,31.49999,26.51244,0.27391,2.94583,31.49999
37.86000,31.54999,26.53451,0.27435,2.94828,31.54999
37.92000,31.60000,26.36410,0.27478,2.92934,31.60000
37.98000,31.65000,26.57139,0.27522,2.95238,31.65000
38.04000,31.69993,26.57269,0.27565,2.95252,31.69993
38.10000,31.74993,26.62238,0.27609,2.95804,31.74993
38.16000,31.80000,26.60242,0.27652,2.95582,31.80000
38.22000,31.85000,26.57952,0.27696,2.95328,31.85000
38.28000,31.90006,26.61124,0.27739,2.95680,31.90006
38.34000,31.94993,26.70842,0.27783,2.96760,31.94993
38.40000,31.99999,26.65234,0.27826,2.96137,31.99999
38.46000,32.05006,26.71288,0.27870,2.96810,32.05006
38.52000,32.10012,26.73438,0.27913,2.97049,32.10012
38.58000,32.15006,26.58393,0.27957,2.95377,32.15006
38.64000,32.19993,26.70288,0.28000,2.96699,32.19993
38.70000,32.24999,26.89230,0.28043,2.98803,32.24999
38.76000,32.30000,26.58447,0.28087,2.95383,32.30000
38.82000,32.34999,26.78616,0.28130,2.97624,32.34999
38.88000,32.40006,26.84011,0.28174,2.98223,32.40006
38.94000,32.45000,26.74668,0.28217,2.97185,32.45000
39.00000,32.49993,26.80768,0.28261,2.97863,32.49993
39.06000,32.54993,27.03187,0.28304,3.00354,32.54993
39.12000,32.59999,26.86257,0.28348,2.98473,32.59999
39.18000,32.65006,27.02639,0.28391,3.00293,32.65006
39.24000,32.70000,26.91659,0.28435,2.99073,32.70000
39.30000,32.74993,27.00900,0.28478,3.00100,32.74993
39.36000,32.79999,26.95642,0.28522,2.99516,32.79999
39.42000,32.85006,26.92823,0.28565,2.99203,32.85006
39.48000,32.89999,26.94239,0.28609,2.99360,32.89999
39.54000,32.94999,27.02533,0.28652,3.00281,32.94999
39.60000,33.00000,27.18916,0.28696,3.02102,33.00000
39.66000,33.05006,27.19481,0.28739,3.02165,33.05006
39.72000,33.10006,27.22675,0.28783,3.02519,33.10006
39.78000,33.15006,27.08431,0.28826,3.00937,33.15006
39.84000,33.20000,27.20187,0.28870,3.02243,33.20000
39.90000,33.24999,27.06548,0.28913,3.00728,33.24999
39.96000,33.30000,27.25954,0.28957,3.02884,33.30000
40.02000,33.35000,27.04948,0.29000,3.00550,33.35000
40.08000,33.40000,27.29454,0.29043,3.03273,33.40000
40.14000,33.44993,27.19031,0.29087,3.02115,33.44993
40.20000,33.49993,27.27338,0.29130,3.03038,33.49993
40.26000,33.54999,27.23219,0.29174,3.02580,33.54999
40.32000,33.60000,27.33640,0.29217,3.03738,33.60000
40.38000,33.65012,27.42640,0.29261,3.04738,33.65012
40.44000,33.69999,27.23336,0.29304,3.02593,33.69999
40.50000,33.74993,27.41313,0.29348,3.04590,33.74993
40.56000,33.79987,27.52390,0.29391,3.05821,33.79987
40.62000,33.85000,27.54560,0.29435,3.06062,33.85000
40.68000,33.90006,27.53985,0.29478,3.05998,33.90006
40.74000,33.94999,27.49375,0.29522,3.05486,33.94999
40.80000,34.00000,27.49317,0.29565,3.05480,34.00000
40.86000,34.04993,27.51594,0.29609,3.05733,34.04993
40.92000,34.10000,27.66103,0.29652,3.07345,34.10000
40.98000,34.15006,27.59605,0.29696,3.06623,34.15006
41.04000,34.19999,27.56199,0.29739,3.06244,34.19999
41.10000,34.24993,27.43108,0.29783,3.04790,34.24993
41.16000,34.30000,27.73110,0.29826,3.08123,34.30000
41.22000,34.35006,27.65098,0.29870,3.07233,34.35006
41.28000,34.40006,27.55361,0.29913,3.06151,34.40006
41.34000,34.44999,27.86136,0.29957,3.09571,34.44999
41.40000,34.49993,27.77251,0.30000,3.08583,34.49993
41.46000,34.54993,27.55224,0.30043,3.06136,34.54993
41.52000,34.59993,27.81015,0.30087,3.09002,34.59993
41.58000,34.65006,27.84255,0.30130,3.09362,34.65006
41.64000,34.70000,27.75711,0.30174,3.08412,34.70000
41.70000,34.75000,27.64675,0.30217,3.07186,34.75000
41.76000,34.79999,27.98708,0.30261,3.10968,34.79999
41.82000,34.85006,28.00978,0.30304,3.11220,34.85006
41.88000,34.90006,27.80327,0.30348,3.08925,34.90006
41.94000,34.95006,28.13422,0.30391,3.12602,34.95006
42.00000,34.99999,27.83553,0.30435,3.09284,34.99999
42.06000,35.04993,27.94018,0.30478,3.10446,35.04993
42.12000,35.09993,27.93352,0.30522,3.10372,35.09993
42.18000,35.15000,27.99107,0.30565,3.11012,35.15000
42.24000,35.19993,27.77604,0.30609,3.08623,35.19993
42.30000,35.25006,28.12570,0.30652,3.12508,35.25006
42.36000,35.30006,27.84503,0.30696,3.09389,35.30006
42.42000,35.34993,28.11637,0.30739,3.12404,35.34993
42.48000,35.40000,27.98360,0.30783,3.10929,35.40000
42.54000,35.44999,28.06004,0.30826,3.11778,35.44999
42.60000,35.49999,28.33857,0.30870,3.14873,35.49999
42.66000,35.55000,28.14436,0.30913,3.12715,35.55000
42.72000,35.60000,28.14167,0.30957,3.12685,35.60000
42.78000,35.65006,28.16099,0.31000,3.12900,35.65006
42.84000,35.70006,28.22405,0.31044,3.13601,35.70006
42.90000,35.74993,28.30426,0.31087,3.14492,35.74993
42.96000,35.79993,28.29696,0.31130,3.14411,35.79993
43.02000,35.85000,28.19469,0.31174,3.13274,35.85000
43.08000,35.89999,28.37693,0.31217,3.15299,35.89999
43.14000,35.94993,28.43622,0.31261,3.15958,35.94993
43.20000,35.99993,28.26581,0.31304,3.14065,35.99993
43.26000,36.04993,28.21519,0.31348,3.13502,36.04993
43.32000,36.09999,28.36995,0.31391,3.15222,36.09999
43.38000,36.15006,28.37279,0.31435,3.15253,36.15006
43.44000,36.19999,28.37161,0.31478,3.15240,36.19999
43.50000,36.25000,28.65101,0.31522,3.18345,36.25000
43.56000,36.30000,28.39118,0.31565,3.15458,36.30000
43.62000,36.34999,28.63065,0.31609,3.18118,36.34999
43.68000,36.40000,28.69646,0.31652,3.18850,36.40000
43.74000,36.45000,28.54031,0.31696,3.17115,36.45000
43.80000,36.50000,28.42931,0.31739,3.15881,36.50000
43.86000,36.55006,28.41144,0.31783,3.15683,36.55006
43.92000,36.60006,28.76315,0.31826,3.19591,36.60006
43.98000,36.65006,28.61253,0.31870,3.17917,36.65006
44.04000,36.69993,28.54668,0.31913,3.17185,36.69993
44.10000,36.74999,28.73913,0.31957,3.19324,36.74999
44.16000,36.79999,28.66313,0.32000,3.18479,36.79999
44.22000,36.85012,28.79499,0.32044,3.19944,36.85012
44.28000,36.90006,28.83072,0.32087,3.20341,36.90006
44.34000,36.94987,28.75003,0.32130,3.19445,36.94987
44.40000,36.99993,28.64053,0.32174,3.18228,36.99993
44.46000,37.04993,28.79754,0.32217,3.19973,37.04993
44.52000,37.10000,28.80719,0.32261,3.20080,37.10000
44.58000,37.15000,28.77564,0.32304,3.19729,37.15000
44.64000,37.19993,28.91777,0.32348,3.21309,37.19993
44.70000,37.24993,28.78713,0.32391,3.19857,37.24993
44.76000,37.30000,28.72544,0.32435,3.19172,37.30000
44.82000,37.35006,28.88081,0.32478,3.20898,37.35006
44.88000,37.40012,28.83915,0.32522,3.20435,37.40012
44.94000,37.44999,29.06371,0.32565,3.22930,37.44999
45.00000,37.49999,29.14032,0.32609,3.23781,37.49999
45.06000,37.55006,28.91118,0.32652,3.21235,37.55006
45.12000,37.60006,29.14093,0.32696,3.23788,37.60006
45.18000,37.65006,29.02217,0.32739,3.22469,37.65006
45.24000,37.69999,28.99726,0.32783,3.22192,37.69999
45.30000,37.74999,29.14475,0.32826,3.23831,37.74999
45.36000,37.80000,29.10605,0.32870,3.23401,37.80000
45.42000,37.84999,29.24962,0.32913,3.24996,37.84999
45.48000,37.89993,29.08306,0.32956,3.23145,37.89993
45.54000,37.94987,29.12087,0.33000,3.23565,37.94987
45.60000,38.00000,29.24012,0.33043,3.24890,38.00000
45.66000,38.05000,29.32598,0.33087,3.25844,38.05000
45.72000,38.09999,29.18413,0.33130,3.24268,38.09999
45.78000,38.15006,29.42784,0.33174,3.26976,38.15006
45.84000,38.20000,29.43852,0.33217,3.27095,38.20000
45.90000,38.25000,29.46573,0.33261,3.27397,38.25000
45.96000,38.29999,29.53529,0.33304,3.28170,38.29999
46.02000,38.35006,29.25751,0.33348,3.25083,38.35006
46.08000,38.40012,29.34367,0.33391,3.26041,38.40012
46.14000,38.45006,29.49208,0.33435,3.27690,38.45006
46.20000,38.50000,29.25770,0.33478,3.25086,38.50000
46.26000,38.54993,29.43627,0.33522,3.27070,38.54993
46.32000,38.59999,29.53766,0.33565,3.28196,38.59999
46.38000,38.65006,29.50043,0.33609,3.27783,38.65006
46.44000,38.69993,29.55953,0.33652,3.28439,38.69993
46.50000,38.74993,29.40328,0.33696,3.26703,38.74993
46.56000,38.79993,29.55517,0.33739,3.28391,38.79993
46.62000,38.84993,29.40262,0.33783,3.26696,38.84993
46.68000,38.90006,29.58520,0.33826,3.28724,38.90006
46.74000,38.94999,29.63626,0.33870,3.29292,38.94999
46.80000,38.99999,29.80937,0.33913,3.31215,38.99999
46.86000,39.04999,29.65000,0.33957,3.29444,39.04999
46.92000,39.10006,29.85029,0.34000,3.31670,39.10006
46.98000,39.14999,29.77363,0.34043,3.30818,39.14999
47.04000,39.19999,29.78647,0.34087,3.30961,39.19999
47.10000,39.24999,29.76944,0.34130,3.30772,39.24999
47.16000,39.29999,29.87841,0.34174,3.31982,39.29999
47.22000,39.34999,29.70351,0.34217,3.30039,39.34999
47.28000,39.40005,29.48535,0.34261,3.27615,39.40005
47.34000,39.44999,29.74637,0.34304,3.30515,39.44999
47.40000,39.49999,29.81877,0.34348,3.31320,39.49999
47.46000,39.54993,29.89491,0.34391,3.32166,39.54993
47.52000,39.59999,29.99484,0.34435,3.33276,39.59999
47.58000,39.64999,29.86183,0.34478,3.31798,39.64999
47.64000,39.69993,29.91289,0.34522,3.32365,39.69993
47.70000,39.74999,30.00953,0.34565,3.33439,39.74999
47.76000,39.80000,30.08340,0.34609,3.34260,39.80000
47.82000,39.84999,30.06126,0.34652,3.34014,39.84999
47.88000,39.89999,30.07842,0.34696,3.34205,39.89999
47.94000,39.94999,30.23284,0.34739,3.35920,39.94999
48.00000,39.99999,29.83474,0.34783,3.31497,39.99999
48.06000,40.05006,30.14774,0.34826,3.34975,40.05006
48.12000,40.10005,30.15337,0.34870,3.35037,40.10005
48.18000,40.14999,30.01144,0.34913,3.33460,40.14999
48.24000,40.19999,29.86097,0.34957,3.31789,40.19999
48.30000,40.25000,30.14166,0.35000,3.34907,40.25000
48.36000,40.29999,30.14423,0.35043,3.34936,40.29999
48.42000,40.35006,30.19547,0.35087,3.35505,40.35006
48.48000,40.40000,30.11313,0.35130,3.34590,40.40000
48.54000,40.44993,30.42539,0.35174,3.38060,40.44993
48.60000,40.49993,30.24962,0.35217,3.36107,40.49993
48.66000,40.54999,30.35662,0.35261,3.37296,40.54999
48.72000,40.60006,30.15964,0.35304,3.35107,40.60006
48.78000,40.65006,30.41368,0.35348,3.37930,40.65006
48.84000,40.69993,30.21107,0.35391,3.35679,40.69993
48.90000,40.74999,30.48657,0.35435,3.38740,40.74999
48.96000,40.79999,30.11641,0.35478,3.34627,40.79999
49.02000,40.84999,30.46556,0.35522,3.38506,40.84999
49.08000,40.90006,30.29860,0.35565,3.36651,40.90006
49.14000,40.94993,30.41638,0.35609,3.37960,40.94993
49.20000,40.99999,30.61794,0.35652,3.40199,40.99999
49.26000,41.05006,30.35182,0.35696,3.37242,41.05006
49.32000,41.10000,30.44410,0.35739,3.38268,41.10000
49.38000,41.15005,30.64189,0.35783,3.40465,41.15005
49.44000,41.19999,30.50259,0.35826,3.38918,41.19999
49.50000,41.25000,30.62896,0.35870,3.40322,41.25000
49.56000,41.29999,30.61642,0.35913,3.40182,41.29999
49.62000,41.35000,30.40982,0.35957,3.37887,41.35000
49.68000,41.39999,30.63391,0.36000,3.40377,41.39999
49.74000,41.44993,30.75911,0.36043,3.41768,41.44993
49.80000,41.49999,30.76743,0.36087,3.41860,41.49999
49.86000,41.54999,30.59771,0.36130,3.39975,41.54999
49.92000,41.60006,30.56543,0.36174,3.39616,41.60006
49.98000,41.65005,30.88352,0.36217,3.43150,41.65005
50.04000,41.69993,30.82886,0.36261,3.42543,41.69993
50.10000,41.74993,30.78135,0.36304,3.42015,41.74993
50.16000,41.80000,30.63504,0.36348,3.40389,41.80000
50.22000,41.84999,30.78262,0.36391,3.42029,41.84999
50.28000,41.90006,30.91742,0.36435,3.43527,41.90006
50.34000,41.95006,30.94558,0.36478,3.43840,41.95006
50.40000,41.99999,30.80162,0.36522,3.42240,41.99999
50.46000,42.04999,30.73780,0.36565,3.41531,42.04999
50.52000,42.09999,30.81509,0.36609,3.42390,42.09999
50.58000,42.15006,30.97115,0.36652,3.44124,42.15006
50.64000,42.20000,30.91276,0.36696,3.43475,42.20000
50.70000,42.24999,31.05893,0.36739,3.45099,42.24999
50.76000,42.29999,30.94147,0.36783,3.43794,42.29999
50.82000,42.34999,31.05570,0.36826,3.45063,42.34999
50.88000,42.39999,30.84096,0.36870,3.42677,42.39999
50.94000,42.44993,30.99726,0.36913,3.44414,42.44993
51.00000,42.49987,30.89160,0.36956,3.43240,42.49987
51.06000,42.54993,30.94049,0.37000,3.43783,42.54993
51.12000,42.59999,30.98879,0.37043,3.44320,42.59999
51.18000,42.65000,31.17100,0.37087,3.46344,42.65000
51.24000,42.69993,30.96709,0.37130,3.44079,42.69993
51.30000,42.74999,31.25466,0.37174,3.47274,42.74999
51.36000,42.80006,31.13113,0.37217,3.45901,42.80006
51.42000,42.85006,31.24976,0.37261,3.47220,42.85006
51.48000,42.90012,31.11462,0.37304,3.45718,42.90012
51.54000,42.94999,31.12961,0.37348,3.45885,42.94999
51.60000,42.99993,31.21837,0.37391,3.46871,42.99993
51.66000,43.04999,31.36668,0.37435,3.48519,43.04999
51.72000,43.10005,31.49036,0.37478,3.49893,43.10005
51.78000,43.15006,31.32951,0.37522,3.48106,43.15006
51.84000,43.19999,31.23781,0.37565,3.47087,43.19999
51.90000,43.24999,31.48674,0.37609,3.49853,43.24999
51.96000,43.29993,31.35586,0.37652,3.48398,43.29993
52.02000,43.34999,31.26176,0.37696,3.47353,43.34999
52.08000,43.39999,31.42972,0.37739,3.49219,43.39999
52.14000,43.44999,31.49516,0.37783,3.49946,43.44999
52.20000,43.50000,31.30369,0.37826,3.47819,43.50000
52.26000,43.54999,31.53376,0.37870,3.50375,43.54999
52.32000,43.59999,31.46195,0.37913,3.49577,43.59999
52.38000,43.65006,31.48610,0.37957,3.49846,43.65006
52.44000,43.69999,31.51481,0.38000,3.50165,43.69999
52.50000,43.75000,31.47758,0.38043,3.49751,43.75000
52.56000,43.79999,31.58950,0.38087,3.50994,43.79999
52.62000,43.84999,31.55571,0.38130,3.50619,43.84999
52.68000,43.90012,31.62041,0.38174,3.51338,43.90012
52.74000,43.95006,31.57109,0.38217,3.50790,43.95006
52.80000,43.99993,31.48953,0.38261,3.49884,43.99993
52.86000,44.04993,31.65039,0.38304,3.51671,44.04993
52.92000,44.09993,31.66675,0.38348,3.51853,44.09993
52.98000,44.15006,31.47381,0.38391,3.49709,44.15006
53.04000,44.20000,31.65852,0.38435,3.51761,44.20000
53.10000,44.24987,31.50741,0.38478,3.50082,44.24987
53.16000,44.29987,31.80747,0.38522,3.53416,44.29987
53.22000,44.35000,31.67831,0.38565,3.51981,44.35000
53.28000,44.40005,31.74488,0.38609,3.52721,44.40005
53.34000,44.44999,31.94938,0.38652,3.54993,44.44999
53.40000,44.49999,31.73772,0.38696,3.52641,44.49999
53.46000,44.54999,31.73351,0.38739,3.52595,44.54999
53.52000,44.60000,31.74693,0.38783,3.52744,44.60000
53.58000,44.65005,31.89853,0.38826,3.54428,44.65005
53.64000,44.69999,32.10063,0.38870,3.56674,44.69999
53.70000,44.75005,31.94007,0.38913,3.54890,44.75005
53.76000,44.80006,31.97514,0.38957,3.55279,44.80006
53.82000,44.85006,32.06218,0.39000,3.56246,44.85006
53.88000,44.89993,31.91455,0.39043,3.54606,44.89993
53.94000,44.94993,32.22720,0.39087,3.58080,44.94993
54.00000,44.99993,31.99513,0.39130,3.55501,44.99993
54.06000,45.04993,31.96799,0.39174,3.55200,45.04993
54.12000,45.09999,32.07085,0.39217,3.56343,45.09999
54.18000,45.14999,31.99086,0.39261,3.55454,45.14999
54.24000,45.19999,31.99856,0.39304,3.55540,45.19999
54.30000,45.24999,32.11420,0.39348,3.56824,45.24999
54.36000,45.30000,32.04166,0.39391,3.56018,45.30000
54.42000,45.35005,32.11146,0.39435,3.56794,45.35005
54.48000,45.40006,32.22627,0.39478,3.58070,45.40006
54.54000,45.44999,31.84955,0.39522,3.53884,45.44999
54.60000,45.49999,32.15638,0.39565,3.57293,45.49999
54.66000,45.54999,32.15770,0.39609,3.57308,45.54999
54.72000,45.60005,32.29431,0.39652,3.58826,45.60005
54.78000,45.65006,32.20315,0.39696,3.57813,45.65006
54.84000,45.69993,32.29568,0.39739,3.58841,45.69993
54.90000,45.74993,32.18763,0.39783,3.57640,45.74993
54.96000,45.79999,32.20923,0.39826,3.57880,45.79999
55.02000,45.84999,32.34829,0.39870,3.59425,45.84999
55.08000,45.89993,32.33080,0.39913,3.59231,45.89993
55.14000,45.94993,32.23406,0.39956,3.58156,45.94993
55.20000,45.99993,32.28265,0.40000,3.58696,45.99993
55.26000,46.04993,32.34520,0.40043,3.59391,46.04993
55.32000,46.10006,32.21290,0.40087,3.57921,46.10006
55.38000,46.15000,32.17945,0.40130,3.57549,46.15000
55.44000,46.19993,32.17518,0.40174,3.57502,46.19993
55.50000,46.24993,32.11582,0.40217,3.56842,46.24993
55.56000,46.29999,32.04200,0.40261,3.56022,46.29999
55.62000,46.35012,31.98166,0.40304,3.55352,46.35012
55.68000,46.40012,31.74042,0.40348,3.52671,46.40012
55.74000,46.44999,30.63866,0.40391,3.40430,46.44999
55.80000,46.49993,-0.59673,0.40435,-0.06630,46.49993
55.86000,46.54999,-0.24880,0.40478,-0.02764,46.54999
55.92000,46.60005,0.12135,0.40522,0.01348,46.60005
55.98000,46.64999,-0.03446,0.40565,-0.00383,46.64999
56.04000,46.69993,-0.04822,0.40609,-0.00536,46.69993
56.10000,46.74993,-0.14166,0.40652,-0.01574,46.74993
56.16000,46.79999,-0.03157,0.40696,-0.00351,46.79999
56.22000,46.85000,-0.00164,0.40739,-0.00018,46.85000
56.28000,46.90005,-0.14673,0.40783,-0.01630,46.90005
56.34000,46.94999,-0.15762,0.40826,-0.01751,46.94999
56.40000,46.99999,-0.10712,0.40870,-0.01190,46.99999
56.46000,47.04999,0.12295,0.40913,0.01366,47.04999
56.52000,47.09999,-0.07494,0.40957,-0.00833,47.09999
56.58000,47.15005,-0.14264,0.41000,-0.01585,47.15005
56.64000,47.19993,-0.00279,0.41043,-0.00031,47.19993
56.70000,47.24999,-0.07051,0.41087,-0.00783,47.24999
56.76000,47.29999,-0.14073,0.41130,-0.01564,47.29999
56.82000,47.35006,-0.07369,0.41174,-0.00819,47.35006
56.88000,47.40012,0.09471,0.41217,0.01052,47.40012
56.94000,47.44993,-0.24572,0.41261,-0.02730,47.44993
57.00000,47.49987,-0.06326,0.41304,-0.00703,47.49987
57.06000,47.54993,-0.11641,0.41348,-0.01293,47.54993
57.12000,47.60006,-0.05829,0.41391,-0.00648,47.60006
57.18000,47.65006,0.08623,0.41435,0.00958,47.65006
57.24000,47.70000,0.07656,0.41478,0.00851,47.70000
57.30000,47.74987,-0.04798,0.41522,-0.00533,47.74987
57.36000,47.79993,-0.15206,0.41565,-0.01690,47.79993
57.42000,47.84993,0.02256,0.41609,0.00251,47.84993
57.48000,47.89999,-0.18207,0.41652,-0.02023,47.89999
57.53400,47.94499,-0.03044,0.41691,-0.00338,47.94499