File: NATR/NatR/RDSO NatR Tensile 50.is_tens_RawData/Specimen_RawData_8.csv
Time,Extension,Load
(sec),(mm),(N)
0.00000,0.00000,0.12368
0.10000,0.07600,0.41376
0.20000,0.16475,0.65033
0.30000,0.24931,1.08839
0.40000,0.33300,1.41845
0.50000,0.41669,1.65860
0.60000,0.50000,1.63047
0.70000,0.58331,2.19559
0.80000,0.66675,2.26350
0.90000,0.75000,2.78104
1.00000,0.83319,2.66775
1.10000,0.91669,3.12595
1.20000,0.99987,3.03942
1.30000,1.08325,3.46390
1.40000,1.16675,3.62281
1.50000,1.25006,3.77284
1.60000,1.33331,4.09325
1.70000,1.41681,4.25956
1.80000,1.50000,4.17528
1.90000,1.58319,4.52093
2.00000,1.66669,4.85579
2.10000,1.75000,4.96006
2.20000,1.83319,5.05934
2.30000,1.91675,5.05693
2.40000,2.00000,5.27680
2.50000,2.08331,5.70270
2.60000,2.16681,5.72333
2.70000,2.25000,6.07388
2.80000,2.33325,6.14120
2.90000,2.41669,6.09171
3.00000,2.50000,6.28085
3.10000,2.58325,6.66923
3.20000,2.66675,6.74753
3.30000,2.75000,7.02090
3.40000,2.83325,6.97601
3.50000,2.91681,7.12345
3.60000,3.00000,7.24350
3.70000,3.08325,7.56494
3.80000,3.16675,7.48483
3.90000,3.24994,7.92475
4.00000,3.33325,7.99737
4.10000,3.41669,8.00320
4.20000,3.50000,8.23183
4.30000,3.58325,8.23002
4.40000,3.66675,8.64255
4.50000,3.75006,8.58728
4.60000,3.83325,8.64725
4.70000,3.91675,8.87931
4.80000,4.00000,8.94600
4.90000,4.08325,9.07894
5.00000,4.16675,9.15322
5.10000,4.25000,9.39063
5.20000,4.33325,9.67840
5.30000,4.41675,9.69315
5.40000,4.50000,9.86656
5.50000,4.58331,10.01170
5.60000,4.66675,10.02572
5.70000,4.75000,10.17041
5.80000,4.83325,10.48367
5.90000,4.91675,10.53477
6.00000,5.00000,10.60803
6.10000,5.08325,10.81496
6.20000,5.16669,10.91168
6.30000,5.24994,10.97661
6.40000,5.33325,11.27619
6.50000,5.41669,11.31309
6.60000,5.50006,11.18559
6.70000,5.58331,11.55137
6.80000,5.66675,11.69416
6.90000,5.75000,11.80294
7.00000,5.83325,11.95949
7.10000,5.91675,11.98238
7.20000,6.00000,12.10164
7.30000,6.08325,12.30827
7.40000,6.16681,12.54632
7.50000,6.25000,12.73389
7.60000,6.33319,12.64696
7.70000,6.41675,12.88887
7.80000,6.50000,12.86207
7.90000,6.58331,13.11839
8.00000,6.66669,13.45409
8.10000,6.75000,13.41626
8.20000,6.83325,13.55116
8.30000,6.91675,13.52680
8.40000,7.00000,13.79944
8.50000,7.08325,13.88921
8.60000,7.16675,13.90464
8.70000,7.25000,13.90988
8.80000,7.33325,14.38646
8.90000,7.41675,14.30232
9.00000,7.50000,14.35549
9.10000,7.58325,14.70427
9.20000,7.66675,14.48514
9.30000,7.75000,14.78355
9.40000,7.83325,15.02512
9.50000,7.91669,15.11910
9.60000,7.99994,15.29256
9.70000,8.08325,15.34254
9.80000,8.16687,15.51605
9.90000,8.25000,15.49885
10.00000,8.33325,15.64188
10.10000,8.41675,15.67799
10.20000,8.50000,15.83102
10.30000,8.58319,15.84871
10.40000,8.66675,16.37296
10.50000,8.75000,16.12767
10.60000,8.83325,16.07347
10.70000,8.91669,16.23091
10.80000,9.00000,16.48620
10.90000,9.08325,16.67000
11.00000,9.16681,16.71733
11.10000,9.25000,16.74060
11.20000,9.33331,16.67117
11.30000,9.41681,16.97830
11.40000,9.49987,17.11732
11.50000,9.58319,17.19949
11.60000,9.66669,17.35653
11.70000,9.75000,17.44214
11.80000,9.83325,17.37594
11.90000,9.91681,17.48967
12.00000,10.00006,17.70634
12.10000,10.08331,17.65974
12.20000,10.16669,17.99740
12.30000,10.25000,18.05410
12.40000,10.33325,17.88740
12.50000,10.41669,17.99481
12.60000,10.50000,18.25039
12.70000,10.58325,18.38832
12.80000,10.66675,18.33148
12.90000,10.74994,18.34961
13.00000,10.83319,18.35657
13.10000,10.91675,18.54429
13.20000,11.00000,18.79831
13.30000,11.08325,19.03003
13.40000,11.16675,19.04825
13.50000,11.25000,18.91262
13.60000,11.33331,18.87852
13.70000,11.41669,19.00499
13.80000,11.49994,19.08814
13.90000,11.58325,19.14576
14.00000,11.66675,19.30193
14.10000,11.75000,19.62635
14.20000,11.83331,19.37484
14.30000,11.91681,19.47230
14.40000,12.00000,19.53933
14.50000,12.08325,19.56976
14.60000,12.16669,19.86782
14.70000,12.24994,19.73714
14.80000,12.33319,19.87287
14.90000,12.41675,19.83911
15.00000,12.50006,19.94916
15.10000,12.58331,20.13767
15.20000,12.66675,20.19176
15.30000,12.75000,20.30299
15.40000,12.83325,20.50267
15.50000,12.91681,20.41942
15.60000,13.00000,20.52967
15.70000,13.08331,20.65344
15.80000,13.16675,20.51276
15.90000,13.25000,20.76080
16.00000,13.33325,20.78814
16.10000,13.41669,20.77667
16.20000,13.50000,21.10120
16.30000,13.58325,21.02403
16.40000,13.66675,20.91005
16.50000,13.75000,21.28417
16.60000,13.83325,21.21610
16.70000,13.91675,21.04970
16.80000,14.00000,21.24673
16.90000,14.08325,21.30185
17.00000,14.16675,21.21066
17.10000,14.24994,21.49986
17.20000,14.33325,21.81601
17.30000,14.41675,21.70404
17.40000,14.50006,21.77686
17.50000,14.58325,21.68268
17.60000,14.66675,21.70228
17.70000,14.75006,21.78230
17.80000,14.83325,21.94253
17.90000,14.91675,22.00182
18.00000,14.99994,22.13985
18.10000,15.08325,22.04410
18.20000,15.16662,22.12025
18.30000,15.24994,22.28793
18.40000,15.33325,22.44385
18.50000,15.41675,22.35383
18.60000,15.50000,22.25794
18.70000,15.58331,22.41317
18.80000,15.66675,22.52401
18.90000,15.75000,22.54415
19.00000,15.83318,22.49304
19.10000,15.91662,22.55145
19.20000,15.99994,22.77856
19.30000,16.08325,22.93771
19.40000,16.16675,22.83256
19.50000,16.25006,22.84643
19.60000,16.33331,22.76911
19.70000,16.41681,22.92228
19.80000,16.50000,22.90209
19.90000,16.58325,23.10128
20.00000,16.66675,23.15821
20.10000,16.75000,22.97834
20.20000,16.83325,23.26993
20.30000,16.91675,23.31599
20.40000,16.99993,23.55722
20.50000,17.08318,23.37651
20.60000,17.16675,23.30565
20.70000,17.25000,23.57427
20.80000,17.33331,23.61901
20.90000,17.41681,23.67061
21.00000,17.50000,23.85514
21.10000,17.58325,23.77154
21.20000,17.66675,23.84847
21.30000,17.74994,23.77738
21.40000,17.83318,23.89194
21.50000,17.91675,24.01532
21.60000,17.99993,23.92780
21.70000,18.08325,23.87831
21.80000,18.16675,24.09813
21.90000,18.25006,24.11004
22.00000,18.33325,24.25042
22.10000,18.41675,24.41339
22.20000,18.50000,24.01404
22.30000,18.58318,24.35930
22.40000,18.66668,24.41668
22.50000,18.75000,24.32632
22.60000,18.83325,24.51526
22.70000,18.91675,24.44755
22.80000,19.00000,24.29354
22.90000,19.08325,24.31270
23.00000,19.16675,24.66187
23.10000,19.25006,24.61449
23.20000,19.33325,24.62012
23.30000,19.41675,24.74468
23.40000,19.50000,24.72214
23.50000,19.58318,24.86929
23.60000,19.66675,25.09429
23.70000,19.75000,25.00791
23.80000,19.83325,24.79804
23.90000,19.91681,25.05171
24.00000,20.00000,25.04397
24.10000,20.08331,24.85630
24.20000,20.16675,25.03594
24.30000,20.24994,25.11757
24.40000,20.33325,24.93872
24.50000,20.41668,25.25193
24.60000,20.50000,25.19616
24.70000,20.58325,25.46645
24.80000,20.66675,25.43386
24.90000,20.75000,25.42504
25.00000,20.83331,25.50041
25.10000,20.91675,25.38266
25.20000,21.00000,25.40706
25.30000,21.08325,25.44264
25.40000,21.16675,25.61110
25.50000,21.25000,25.49198
25.60000,21.33325,25.76466
25.70000,21.41668,25.58047
25.80000,21.49994,25.77569
25.90000,21.58325,25.70611
26.00000,21.66675,25.82993
26.10000,21.75000,25.74408
26.20000,21.83331,25.84355
26.30000,21.91668,25.86987
26.40000,22.00000,25.93783
26.50000,22.08325,25.95792
26.60000,22.16668,25.88613
26.70000,22.24993,26.08600
26.80000,22.33325,26.23550
26.90000,22.41675,26.26828
27.00000,22.50000,26.16460
27.10000,22.58331,26.22693
27.20000,22.66675,26.33184
27.30000,22.75000,26.55072
27.40000,22.83325,26.43811
27.50000,22.91668,26.23153
27.60000,23.00000,26.45159
27.70000,23.08325,26.56762
27.80000,23.16675,26.57046
27.90000,23.25000,26.64975
28.00000,23.33325,26.69629
28.10000,23.41675,26.56855
28.20000,23.50000,26.77342
28.30000,23.58331,26.74971
28.40000,23.66675,26.67665
28.50000,23.75000,26.77700
28.60000,23.83325,26.98005
28.70000,23.91675,26.98250
28.80000,24.00000,26.88098
28.90000,24.08325,26.87206
29.00000,24.16675,26.92650
29.10000,24.25000,27.00607
29.20000,24.33325,27.21270
29.30000,24.41674,27.07183
29.40000,24.50000,27.30443
29.50000,24.58325,27.06345
29.60000,24.66675,27.28669
29.70000,24.75000,27.36833
29.80000,24.83325,27.38886
29.90000,24.91675,27.43997
30.00000,24.99999,27.43012
30.10000,25.08325,27.36568
30.20000,25.16675,27.49509
30.30000,25.25000,27.46986
30.40000,25.33325,27.75871
30.50000,25.41668,27.60887
30.60000,25.50000,27.71344
30.70000,25.58324,27.67051
30.80000,25.66668,27.64817
30.90000,25.75000,27.73382
31.00000,25.83318,27.73166
31.10000,25.91675,27.82824
31.20000,26.00000,27.89772
31.30000,26.08331,28.02071
31.40000,26.16681,28.01282
31.50000,26.25000,28.05962
31.60000,26.33325,28.02566
31.70000,26.41669,28.07500
31.80000,26.49993,28.22328
31.90000,26.58318,28.14194
32.00000,26.66668,28.02943
32.10000,26.75000,28.13366
32.20000,26.83331,28.15566
32.30000,26.91675,28.27027
32.40000,27.00000,28.36930
32.50000,27.08318,28.46764
32.60000,27.16674,28.21220
32.70000,27.25000,28.55863
32.80000,27.33325,28.59641
32.90000,27.41675,28.66153
33.00000,27.50000,28.69539
33.10000,27.58325,28.63150
33.20000,27.66668,28.57965
33.30000,27.74993,28.74963
33.40000,27.83325,28.91158
33.50000,27.91675,28.99404
33.60000,28.00000,28.74199
33.70000,28.08331,29.06191
33.80000,28.16681,29.02991
33.90000,28.25000,29.09449
34.00000,28.33324,29.14100
34.10000,28.41675,29.12012
34.20000,28.49993,29.19548
34.30000,28.58318,29.17569
34.40000,28.66675,29.21856
34.50000,28.75006,29.29892
34.60000,28.83331,29.20391
34.70000,28.91675,29.57014
34.80000,29.00000,29.62820
34.90000,29.08325,29.25208
35.00000,29.16675,29.45489
35.10000,29.24993,29.67073
35.20000,29.33325,29.46518
35.30000,29.41675,29.62894
35.40000,29.49993,29.63727
35.50000,29.58325,29.78138
35.60000,29.66675,29.77456
35.70000,29.75000,29.82964
35.80000,29.83325,30.07092
35.90000,29.91674,30.01731
36.00000,30.00006,29.63844
36.10000,30.08325,29.79980
36.20000,30.16668,29.88354
36.30000,30.24993,30.12717
36.40000,30.33318,30.02740
36.50000,30.41675,29.98066
36.60000,30.49999,30.11154
36.70000,30.58325,30.19655
36.80000,30.66675,30.29656
36.90000,30.75006,30.25280
37.00000,30.83325,30.37555
37.10000,30.91675,30.43871
37.20000,31.00000,30.41102
37.30000,31.08318,30.43832
37.40000,31.16675,30.45306
37.50000,31.25000,30.32684
37.60000,31.33325,30.54749
37.70000,31.41668,30.57013
37.80000,31.49999,30.58615
37.90000,31.58331,30.62001
38.00000,31.66674,30.81723
38.10000,31.74999,30.64813
38.20000,31.83324,30.82115
38.30000,31.91668,30.79396
38.40000,31.99999,30.91396
38.50000,32.08312,30.82537
38.60000,32.16668,31.02573
38.70000,32.24999,30.94233
38.80000,32.33331,31.13465
38.90000,32.41681,31.02788
39.00000,32.50006,31.28694
39.10000,32.58331,31.13176
39.20000,32.66674,31.08668
39.30000,32.74993,31.30189
39.40000,32.83318,31.11015
39.50000,32.91668,31.41527
39.60000,33.00000,31.19850
39.70000,33.08318,31.45737
39.80000,33.16681,31.50847
39.90000,33.25006,31.27974
40.00000,33.33325,31.40582
40.10000,33.41675,31.39474
40.20000,33.49999,31.56639
40.30000,33.58331,31.52802
40.40000,33.66675,31.81658
40.50000,33.74999,31.80031
40.60000,33.83324,31.73632
40.70000,33.91674,31.69438
40.80000,33.99993,31.65278
40.90000,34.08324,31.81869
41.00000,34.16675,31.79380
41.10000,34.25000,31.86073
41.20000,34.33324,31.84182
41.30000,34.41681,31.60094
41.40000,34.49999,31.60319
41.50000,34.58325,31.85789
41.60000,34.66674,31.68100
41.70000,34.75000,31.84976
41.80000,34.83325,31.78400
41.90000,34.91662,31.84799
42.00000,34.99999,31.69364
42.10000,35.08325,31.32595
42.20000,35.16681,30.26569
42.30000,35.24999,16.96924
42.40000,35.33325,0.07664
42.50000,35.41674,-0.00700
42.60000,35.50006,0.17792
42.70000,35.58318,0.01627
42.80000,35.66675,0.11520
42.90000,35.75000,-0.02273
43.00000,35.83318,0.03004
43.10000,35.91675,-0.03866
43.20000,36.00006,0.23354
43.30000,36.08331,-0.01053
43.40000,36.16675,-0.11936
43.42400,36.18668,0.01446