File: NATR/NatR/RDSO NatR Tensile 50.is_tens_RawData/Specimen_RawData_10.csv
Time,Extension,Load
(sec),(mm),(N)
0.00000,0.00000,0.49578
0.10000,0.07600,0.89940
0.20000,0.16475,1.24053
0.30000,0.24931,1.40272
0.40000,0.33300,2.04310
0.50000,0.41669,2.36748
0.60000,0.50000,2.18794
0.70000,0.58331,2.44789
0.80000,0.66675,2.90373
0.90000,0.75000,2.93750
1.00000,0.83319,3.16539
1.10000,0.91669,3.37188
1.20000,0.99987,3.49306
1.30000,1.08325,3.86011
1.40000,1.16675,4.14818
1.50000,1.25006,4.18694
1.60000,1.33331,4.13579
1.70000,1.41681,4.60736
1.80000,1.50000,4.54062
1.90000,1.58319,4.59624
2.00000,1.66669,4.95796
2.10000,1.75006,5.21785
2.20000,1.83325,5.49186
2.30000,1.91675,5.52253
2.40000,2.00000,5.83799
2.50000,2.08331,6.04791
2.60000,2.16681,6.14052
2.70000,2.25000,6.36092
2.80000,2.33325,6.26321
2.90000,2.41669,6.38037
3.00000,2.50000,6.86469
3.10000,2.58325,6.80510
3.20000,2.66675,7.08234
3.30000,2.75000,7.05098
3.40000,2.83325,7.20239
3.50000,2.91681,7.43495
3.60000,3.00006,7.38031
3.70000,3.08325,7.46180
3.80000,3.16675,7.73811
3.90000,3.24994,7.89045
4.00000,3.33325,7.91495
4.10000,3.41669,7.87614
4.20000,3.50000,8.12369
4.30000,3.58325,8.48898
4.40000,3.66675,8.64240
4.50000,3.75006,8.40103
4.60000,3.83325,8.67033
4.70000,3.91675,8.75172
4.80000,4.00000,9.09800
4.90000,4.08319,9.00583
5.00000,4.16675,9.25750
5.10000,4.25000,9.28694
5.20000,4.33325,9.33624
5.30000,4.41675,9.41483
5.40000,4.50000,9.75166
5.50000,4.58331,9.92340
5.60000,4.66675,10.01636
5.70000,4.74994,10.17080
5.80000,4.83325,10.19408
5.90000,4.91681,10.32408
6.00000,5.00006,10.15963
6.10000,5.08325,10.60323
6.20000,5.16669,10.80966
6.30000,5.24994,10.74381
6.40000,5.33325,10.84994
6.50000,5.41669,11.06015
6.60000,5.50000,11.08068
6.70000,5.58331,11.16589
6.80000,5.66675,11.39781
6.90000,5.75000,11.33078
7.00000,5.83325,11.63409
7.10000,5.91675,11.69641
7.20000,6.00000,11.76114
7.30000,6.08325,11.87683
7.40000,6.16681,12.07371
7.50000,6.25000,12.26310
7.60000,6.33319,12.13320
7.70000,6.41675,12.41906
7.80000,6.50000,12.14878
7.90000,6.58331,12.48659
8.00000,6.66669,12.78446
8.10000,6.75000,12.87858
8.20000,6.83325,12.88672
8.30000,6.91675,12.95434
8.40000,7.00000,13.13735
8.50000,7.08325,13.16396
8.60000,7.16675,13.31890
8.70000,7.25000,13.46766
8.80000,7.33325,13.44919
8.90000,7.41675,13.54214
9.00000,7.50000,13.86049
9.10000,7.58325,13.88151
9.20000,7.66675,14.17791
9.30000,7.75000,14.13406
9.40000,7.83319,14.18384
9.50000,7.91669,14.13930
9.60000,8.00000,14.34784
9.70000,8.08325,14.49989
9.80000,8.16687,14.74793
9.90000,8.25000,14.74283
10.00000,8.33325,14.86705
10.10000,8.41675,15.03835
10.20000,8.50000,15.07378
10.30000,8.58312,15.03958
10.40000,8.66675,15.36591
10.50000,8.75000,15.28585
10.60000,8.83319,15.53198
10.70000,8.91669,15.76164
10.80000,9.00000,15.61625
10.90000,9.08331,15.68240
11.00000,9.16681,15.66947
11.10000,9.25000,16.16334
11.20000,9.33331,16.09582
11.30000,9.41681,16.26143
11.40000,9.49987,16.50545
11.50000,9.58319,16.36772
11.60000,9.66669,16.48973
11.70000,9.75000,16.52153
11.80000,9.83325,16.47865
11.90000,9.91675,16.55563
12.00000,10.00006,16.78206
12.10000,10.08331,16.97855
12.20000,10.16675,16.87805
12.30000,10.25000,17.31052
12.40000,10.33325,17.11727
12.50000,10.41669,17.33434
12.60000,10.50000,17.45537
12.70000,10.58325,17.54695
12.80000,10.66675,17.72942
12.90000,10.75000,17.64078
13.00000,10.83325,17.69292
13.10000,10.91675,17.77597
13.20000,11.00000,17.96712
13.30000,11.08325,18.07566
13.40000,11.16675,17.88073
13.50000,11.25000,18.34824
13.60000,11.33325,18.47667
13.70000,11.41675,18.25852
13.80000,11.49994,18.49122
13.90000,11.58325,18.52582
14.00000,11.66675,18.55674
14.10000,11.75000,18.68178
14.20000,11.83331,18.77924
14.30000,11.91675,18.82991
14.40000,12.00000,18.99004
14.50000,12.08325,18.81933
14.60000,12.16669,19.08378
14.70000,12.25000,19.17903
14.80000,12.33319,19.25048
14.90000,12.41675,19.35989
15.00000,12.50000,19.29752
15.10000,12.58331,19.54011
15.20000,12.66675,19.40037
15.30000,12.75000,19.74591
15.40000,12.83325,19.55535
15.50000,12.91681,19.71735
15.60000,13.00000,19.79653
15.70000,13.08331,19.86964
15.80000,13.16675,19.92858
15.90000,13.25000,19.74327
16.00000,13.33319,20.10101
16.10000,13.41669,20.17569
16.20000,13.50000,20.44690
16.30000,13.58325,20.55867
16.40000,13.66675,20.39305
16.50000,13.75000,20.41540
16.60000,13.83331,20.54201
16.70000,13.91675,20.70023
16.80000,14.00000,20.71827
16.90000,14.08325,20.63849
17.00000,14.16675,20.83454
17.10000,14.25000,21.02559
17.20000,14.33325,20.79309
17.30000,14.41675,21.03887
17.40000,14.50006,21.09855
17.50000,14.58325,21.10046
17.60000,14.66681,21.23419
17.70000,14.75006,21.06136
17.80000,14.83331,21.09713
17.90000,14.91675,21.32885
18.00000,15.00000,21.52426
18.10000,15.08325,21.45449
18.20000,15.16669,21.44047
18.30000,15.24994,21.61585
18.40000,15.33325,21.60707
18.50000,15.41681,21.69611
18.60000,15.50006,21.70061
18.70000,15.58331,21.74736
18.80000,15.66681,21.97428
18.90000,15.75000,21.96379
19.00000,15.83318,21.97144
19.10000,15.91662,22.17993
19.20000,15.99994,22.20865
19.30000,16.08325,22.13255
19.40000,16.16675,22.16920
19.50000,16.25006,22.21124
19.60000,16.33331,22.46883
19.70000,16.41681,22.48456
19.80000,16.50000,22.41734
19.90000,16.58325,22.52759
20.00000,16.66675,22.54934
20.10000,16.75000,22.44982
20.20000,16.83325,22.54929
20.30000,16.91675,22.39083
20.40000,16.99993,22.50279
20.50000,17.08318,22.81237
20.60000,17.16675,22.71947
20.70000,17.25000,22.83202
20.80000,17.33331,22.80336
20.90000,17.41681,22.83364
21.00000,17.50000,22.77606
21.10000,17.58331,23.07486
21.20000,17.66675,22.91596
21.30000,17.74994,23.32065
21.40000,17.83325,23.00166
21.50000,17.91675,22.97231
21.60000,17.99993,23.07031
21.70000,18.08325,23.29316
21.80000,18.16675,23.13156
21.90000,18.25006,23.26459
22.00000,18.33331,23.36083
22.10000,18.41675,23.25229
22.20000,18.50000,23.45079
22.30000,18.58318,23.39140
22.40000,18.66675,23.47088
22.50000,18.75000,23.67399
22.60000,18.83325,23.55305
22.70000,18.91675,23.56619
22.80000,19.00000,23.66301
22.90000,19.08325,23.65840
23.00000,19.16675,23.75145
23.10000,19.25006,23.86783
23.20000,19.33325,23.72901
23.30000,19.41675,23.84803
23.40000,19.50000,23.72034
23.50000,19.58318,24.02615
23.60000,19.66675,23.89649
23.70000,19.75000,23.97612
23.80000,19.83331,24.11155
23.90000,19.91675,24.00915
24.00000,20.00006,24.12204
24.10000,20.08331,24.36106
24.20000,20.16675,24.35773
24.30000,20.24994,24.18089
24.40000,20.33325,24.26203
24.50000,20.41675,24.35205
24.60000,20.50000,24.59641
24.70000,20.58325,24.74517
24.80000,20.66675,24.51913
24.90000,20.75000,24.53178
25.00000,20.83331,24.62439
25.10000,20.91675,24.59141
25.20000,21.00000,24.61375
25.30000,21.08325,24.64776
25.40000,21.16675,24.63100
25.50000,21.25000,25.08690
25.60000,21.33318,24.78481
25.70000,21.41668,24.95112
25.80000,21.49994,24.83136
25.90000,21.58325,25.17411
26.00000,21.66675,24.88561
26.10000,21.75000,25.31827
26.20000,21.83331,25.20469
26.30000,21.91675,25.06641
26.40000,22.00000,25.13908
26.50000,22.08325,25.16196
26.60000,22.16668,25.43690
26.70000,22.24993,25.24134
26.80000,22.33325,25.26501
26.90000,22.41681,25.33248
27.00000,22.50000,25.64373
27.10000,22.58331,25.65177
27.20000,22.66675,25.66529
27.30000,22.75000,25.69121
27.40000,22.83325,25.69861
27.50000,22.91668,25.76839
27.60000,23.00000,25.81729
27.70000,23.08325,25.73031
27.80000,23.16675,25.74604
27.90000,23.25000,25.89333
28.00000,23.33325,25.96933
28.10000,23.41675,26.08928
28.20000,23.50000,26.17156
28.30000,23.58325,25.95895
28.40000,23.66675,25.91705
28.50000,23.75000,26.14617
28.60000,23.83325,26.22310
28.70000,23.91675,26.30586
28.80000,24.00000,26.29229
28.90000,24.08325,26.44297
29.00000,24.16675,26.35070
29.10000,24.25000,26.32071
29.20000,24.33325,26.44086
29.30000,24.41674,26.49819
29.40000,24.50000,26.27715
29.50000,24.58325,26.41964
29.60000,24.66675,26.47580
29.70000,24.75000,26.74064
29.80000,24.83325,26.77401
29.90000,24.91675,26.75759
30.00000,24.99999,26.71065
30.10000,25.08331,26.94443
30.20000,25.16675,26.73359
30.30000,25.25000,26.84104
30.40000,25.33325,27.02082
30.50000,25.41668,26.97491
30.60000,25.50000,26.96682
30.70000,25.58324,27.15322
30.80000,25.66668,26.96472
30.90000,25.75000,27.14675
31.00000,25.83318,27.25632
31.10000,25.91675,27.08619
31.20000,26.00000,27.26327
31.30000,26.08331,27.29948
31.40000,26.16681,27.29449
31.50000,26.25006,27.37833
31.60000,26.33325,27.50754
31.70000,26.41669,27.42629
31.80000,26.49993,27.45070
31.90000,26.58318,27.40204
32.00000,26.66675,27.58839
32.10000,26.75000,27.89395
32.20000,26.83331,27.52459
32.30000,26.91675,27.67860
32.40000,27.00000,27.61744
32.50000,27.08325,27.60015
32.60000,27.16674,27.87072
32.70000,27.25000,27.78787
32.80000,27.33325,27.91747
32.90000,27.41668,27.96691
33.00000,27.50000,27.92634
33.10000,27.58325,28.08735
33.20000,27.66675,28.01900
33.30000,27.74993,27.91899
33.40000,27.83318,28.15335
33.50000,27.91675,28.29874
33.60000,28.00006,28.25473
33.70000,28.08331,28.11950
33.80000,28.16681,28.20294
33.90000,28.25000,28.39228
34.00000,28.33324,28.47504
34.10000,28.41675,28.61101
34.20000,28.49993,28.48518
34.30000,28.58318,28.46602
34.40000,28.66675,28.55118
34.50000,28.75000,28.50268
34.60000,28.83331,28.51120
34.70000,28.91675,28.63272
34.80000,29.00000,28.81128
34.90000,29.08325,28.64022
35.00000,29.16675,28.66776
35.10000,29.25000,28.74728
35.20000,29.33325,28.79707
35.30000,29.41675,28.76865
35.40000,29.50000,28.99238
35.50000,29.58325,29.02712
35.60000,29.66675,28.94955
35.70000,29.75000,28.99429
35.80000,29.83331,29.07387
35.90000,29.91674,29.16177
36.00000,30.00006,29.11503
36.10000,30.08325,29.32592
36.20000,30.16662,29.40045
36.30000,30.24993,29.15212
36.40000,30.33318,29.14599
36.50000,30.41675,29.12772
36.60000,30.49999,29.14090
36.70000,30.58331,29.15937
36.80000,30.66675,29.38222
36.90000,30.75006,29.39398
37.00000,30.83325,29.35052
37.10000,30.91675,29.23135
37.20000,31.00000,29.30309
37.30000,31.08318,28.82269
37.40000,31.16675,-1.02473
37.50000,31.25000,-0.34407
37.60000,31.33325,-0.11441
37.70000,31.41668,0.00794
37.80000,31.49999,-0.11431
37.90000,31.58331,0.10712
38.00000,31.66674,0.01671
38.10000,31.74999,0.03391
38.20000,31.83324,0.00206
38.30000,31.91668,-0.20173
38.40000,31.99999,0.11084
38.50000,32.08312,-0.14641
38.60000,32.16668,-0.08379
38.70000,32.24999,-0.18732
38.80000,32.33331,-0.05532
38.90000,32.41681,-0.24147
39.00000,32.50006,-0.17767
39.10000,32.58331,0.19091
39.20000,32.66674,-0.15479
39.30000,32.75000,-0.03498
39.40000,32.83324,-0.05292
39.50000,32.91668,-0.02572
39.60000,33.00000,-0.28684
39.70000,33.08325,-0.14200
39.80000,33.16681,0.19610
39.90000,33.25006,-0.27435
39.98600,33.32162,0.23118