File: NATR/NatR/RDSO NatR Tensile 50.is_tens_RawData/Specimen_RawData_7.csv
Time,Extension,Load
(sec),(mm),(N)
0.00000,0.00000,0.06400
0.10000,0.07600,0.15695
0.20000,0.16469,0.66434
0.30000,0.24931,0.98304
0.40000,0.33300,1.32805
0.50000,0.41675,1.37700
0.60000,0.50006,1.78468
0.70000,0.58331,1.92624
0.80000,0.66675,2.20186
0.90000,0.75000,2.25723
1.00000,0.83325,2.72425
1.10000,0.91675,2.94431
1.20000,0.99994,2.93260
1.30000,1.08325,3.29544
1.40000,1.16681,3.45194
1.50000,1.25006,3.61531
1.60000,1.33331,3.95488
1.70000,1.41681,4.01201
1.80000,1.50000,4.24471
1.90000,1.58319,4.47134
2.00000,1.66669,4.56282
2.10000,1.75006,4.58781
2.20000,1.83325,4.77269
2.30000,1.91675,5.02768
2.40000,2.00000,5.14298
2.50000,2.08331,5.35623
2.60000,2.16681,5.62244
2.70000,2.25000,5.70069
2.80000,2.33325,5.82163
2.90000,2.41675,5.94128
3.00000,2.50000,6.10127
3.10000,2.58325,6.25733
3.20000,2.66681,6.24352
3.30000,2.75000,6.66717
3.40000,2.83325,6.66663
3.50000,2.91681,6.63184
3.60000,3.00000,6.96347
3.70000,3.08325,7.04368
3.80000,3.16675,7.31215
3.90000,3.25000,7.45773
4.00000,3.33325,7.60963
4.10000,3.41669,7.66823
4.20000,3.50000,7.84762
4.30000,3.58325,8.08130
4.40000,3.66675,8.34012
4.50000,3.75006,8.16063
4.60000,3.83325,8.63564
4.70000,3.91675,8.48256
4.80000,4.00000,8.75378
4.90000,4.08325,8.83566
5.00000,4.16675,8.64804
5.10000,4.25006,9.09050
5.20000,4.33325,9.32997
5.30000,4.41675,9.38009
5.40000,4.50000,9.39078
5.50000,4.58331,9.58320
5.60000,4.66675,9.48103
5.70000,4.75000,9.77356
5.80000,4.83331,9.80066
5.90000,4.91675,10.06109
6.00000,5.00006,10.25695
6.10000,5.08325,10.38738
6.20000,5.16669,10.44917
6.30000,5.24994,10.27263
6.40000,5.33325,10.71818
6.50000,5.41675,10.78007
6.60000,5.50006,10.87498
6.70000,5.58331,10.95083
6.80000,5.66675,11.15815
6.90000,5.75000,11.27521
7.00000,5.83325,11.20490
7.10000,5.91675,11.42486
7.20000,6.00000,11.40335
7.30000,6.08325,11.80176
7.40000,6.16681,11.92715
7.50000,6.25000,11.74963
7.60000,6.33325,11.91216
7.70000,6.41675,12.11296
7.80000,6.50000,12.18215
7.90000,6.58331,12.29705
8.00000,6.66669,12.41328
8.10000,6.75000,12.47977
8.20000,6.83331,12.54151
8.30000,6.91675,12.78578
8.40000,7.00000,12.87981
8.50000,7.08325,13.11236
8.60000,7.16675,13.22526
8.70000,7.25000,13.09418
8.80000,7.33325,13.37392
8.90000,7.41675,13.49285
9.00000,7.50000,13.68757
9.10000,7.58325,13.64284
9.20000,7.66675,13.89964
9.30000,7.75006,13.88734
9.40000,7.83325,14.06761
9.50000,7.91669,14.16733
9.60000,8.00000,14.22828
9.70000,8.08325,14.60318
9.80000,8.16681,14.57883
9.90000,8.25006,14.61744
10.00000,8.33331,14.70329
10.10000,8.41675,14.80732
10.20000,8.50006,15.02331
10.30000,8.58319,14.89944
10.40000,8.66675,15.16781
10.50000,8.75000,15.24415
10.60000,8.83325,15.39301
10.70000,8.91675,15.56456
10.80000,9.00000,15.70989
10.90000,9.08325,15.56147
11.00000,9.16681,15.48493
11.10000,9.25006,15.73567
11.20000,9.33331,16.06475
11.30000,9.41681,16.17765
11.40000,9.49987,16.02913
11.50000,9.58319,16.42069
11.60000,9.66669,16.33106
11.70000,9.75006,16.56950
11.80000,9.83325,16.66603
11.90000,9.91681,16.61845
12.00000,10.00006,16.75736
12.10000,10.08331,16.85409
12.20000,10.16675,17.11266
12.30000,10.25000,17.09806
12.40000,10.33325,17.19719
12.50000,10.41669,16.95772
12.60000,10.50000,17.24501
12.70000,10.58325,17.45674
12.80000,10.66675,17.46894
12.90000,10.74994,17.60545
13.00000,10.83325,17.72016
13.10000,10.91675,17.53867
13.20000,11.00006,17.77891
13.30000,11.08325,18.04033
13.40000,11.16675,17.86064
13.50000,11.25000,18.03543
13.60000,11.33331,18.16562
13.70000,11.41669,18.37313
13.80000,11.49994,18.40533
13.90000,11.58325,18.29287
14.00000,11.66675,18.52072
14.10000,11.75000,18.54684
14.20000,11.83331,18.69732
14.30000,11.91681,18.82001
14.40000,12.00000,18.59260
14.50000,12.08325,18.79164
14.60000,12.16675,18.86720
14.70000,12.25000,19.10230
14.80000,12.33325,19.06315
14.90000,12.41675,19.08084
15.00000,12.50006,19.22436
15.10000,12.58331,19.50483
15.20000,12.66675,19.59279
15.30000,12.75000,19.41556
15.40000,12.83325,19.66717
15.50000,12.91681,19.64497
15.60000,13.00000,19.82559
15.70000,13.08331,19.75287
15.80000,13.16675,19.75032
15.90000,13.25000,19.87468
16.00000,13.33325,19.82735
16.10000,13.41669,20.16520
16.20000,13.50000,20.14467
16.30000,13.58325,20.28427
16.40000,13.66675,20.45087
16.50000,13.75006,20.39256
16.60000,13.83331,20.54245
16.70000,13.91675,20.62036
16.80000,14.00000,20.70376
16.90000,14.08325,20.59278
17.00000,14.16675,20.57930
17.10000,14.25000,20.81680
17.20000,14.33325,20.70984
17.30000,14.41675,20.83268
17.40000,14.50006,21.01682
17.50000,14.58325,21.14550
17.60000,14.66681,21.02084
17.70000,14.75006,20.89114
17.80000,14.83331,21.16804
17.90000,14.91675,21.43195
18.00000,15.00000,21.40480
18.10000,15.08325,21.50177
18.20000,15.16669,21.55700
18.30000,15.24994,21.40676
18.40000,15.33325,21.48991
18.50000,15.41681,21.66680
18.60000,15.50006,21.62148
18.70000,15.58331,21.98932
18.80000,15.66681,21.73090
18.90000,15.75006,21.92626
19.00000,15.83318,21.81263
19.10000,15.91668,22.06694
19.20000,15.99994,22.14416
19.30000,16.08325,21.99863
19.40000,16.16675,22.24917
19.50000,16.25006,22.29836
19.60000,16.33331,22.02842
19.70000,16.41681,22.14504
19.80000,16.50000,22.45820
19.90000,16.58325,22.43287
20.00000,16.66675,22.54905
20.10000,16.75000,22.55017
20.20000,16.83325,22.47212
20.30000,16.91675,22.83771
20.40000,17.00000,22.78287
20.50000,17.08318,22.82761
20.60000,17.16675,22.83511
20.70000,17.25006,22.95942
20.80000,17.33331,22.96898
20.90000,17.41675,23.01391
21.00000,17.50006,22.93904
21.10000,17.58331,23.08849
21.20000,17.66681,23.31619
21.30000,17.75000,23.28772
21.40000,17.83318,23.31536
21.50000,17.91675,23.26278
21.60000,17.99993,23.52963
21.70000,18.08325,23.31629
21.80000,18.16675,23.41879
21.90000,18.25006,23.42232
22.00000,18.33331,23.51606
22.10000,18.41675,23.57442
22.20000,18.50000,23.64890
22.30000,18.58325,23.61244
22.40000,18.66675,23.58745
22.50000,18.75000,23.62366
22.60000,18.83331,23.80271
22.70000,18.91675,23.72965
22.80000,19.00000,23.75150
22.90000,19.08325,23.81368
23.00000,19.16675,23.89566
23.10000,19.25006,23.98357
23.20000,19.33325,23.99420
23.30000,19.41675,24.01228
23.40000,19.50000,24.13444
23.50000,19.58325,23.93907
23.60000,19.66675,24.34886
23.70000,19.75000,24.24498
23.80000,19.83331,24.28575
23.90000,19.91681,24.13458
24.00000,20.00000,24.34146
24.10000,20.08331,24.11361
24.20000,20.16675,24.47562
24.30000,20.24994,24.39360
24.40000,20.33325,24.67456
24.50000,20.41675,24.48763
24.60000,20.50000,24.59606
24.70000,20.58325,24.53648
24.80000,20.66675,24.62448
24.90000,20.75006,24.64604
25.00000,20.83331,24.74556
25.10000,20.91675,25.01070
25.20000,21.00006,24.80662
25.30000,21.08325,24.87350
25.40000,21.16675,24.86738
25.50000,21.25000,25.12757
25.60000,21.33325,25.11610
25.70000,21.41675,25.05803
25.80000,21.49994,25.03476
25.90000,21.58325,24.97312
26.00000,21.66675,25.16549
26.10000,21.75006,24.97410
26.20000,21.83331,25.26187
26.30000,21.91675,25.56229
26.40000,22.00000,25.45322
26.50000,22.08325,25.35708
26.60000,22.16668,25.29701
26.70000,22.24993,25.49805
26.80000,22.33325,25.45038
26.90000,22.41681,25.51300
27.00000,22.50006,25.52397
27.10000,22.58331,25.56563
27.20000,22.66675,25.62996
27.30000,22.75000,25.90887
27.40000,22.83325,25.58170
27.50000,22.91675,25.79244
27.60000,23.00000,25.96605
27.70000,23.08325,25.80019
27.80000,23.16675,25.90118
27.90000,23.25000,26.01334
28.00000,23.33331,25.91230
28.10000,23.41675,26.12653
28.20000,23.50000,26.12040
28.30000,23.58325,25.91607
28.40000,23.66675,26.23511
28.50000,23.75000,26.07973
28.60000,23.83325,26.19199
28.70000,23.91675,26.41778
28.80000,24.00006,26.32375
28.90000,24.08325,26.54547
29.00000,24.16675,26.41469
29.10000,24.25000,26.49309
29.20000,24.33325,26.52480
29.30000,24.41674,26.77666
29.40000,24.50000,26.63818
29.50000,24.58325,26.73858
29.60000,24.66675,26.76867
29.70000,24.75000,26.86510
29.80000,24.83325,26.70595
29.90000,24.91675,26.86309
30.00000,25.00006,27.07428
30.10000,25.08325,26.89543
30.20000,25.16681,26.96746
30.30000,25.25000,26.98265
30.40000,25.33325,27.04356
30.50000,25.41668,26.93693
30.60000,25.50000,27.11613
30.70000,25.58324,27.35466
30.80000,25.66668,27.12534
30.90000,25.75000,27.24181
31.00000,25.83318,27.12333
31.10000,25.91675,27.29115
31.20000,26.00000,27.30595
31.30000,26.08331,27.41326
31.40000,26.16681,27.40640
31.50000,26.25006,27.39577
31.60000,26.33325,27.41458
31.70000,26.41669,27.62112
31.80000,26.49993,27.60960
31.90000,26.58318,27.70579
32.00000,26.66675,27.49338
32.10000,26.75000,27.66889
32.20000,26.83331,27.66233
32.30000,26.91675,27.72539
32.40000,27.00000,27.92987
32.50000,27.08325,27.97421
32.60000,27.16674,28.03414
32.70000,27.25000,27.99376
32.80000,27.33325,27.95300
32.90000,27.41675,28.14777
33.00000,27.50006,28.22107
33.10000,27.58325,28.02047
33.20000,27.66668,28.12621
33.30000,27.74993,28.17349
33.40000,27.83325,28.18511
33.50000,27.91675,28.19280
33.60000,28.00006,28.37611
33.70000,28.08331,28.31540
33.80000,28.16681,28.20348
33.90000,28.25000,28.46784
34.00000,28.33324,28.47739
34.10000,28.41675,28.59514
34.20000,28.50000,28.70186
34.30000,28.58318,28.55236
34.40000,28.66675,28.51777
34.50000,28.75006,28.57573
34.60000,28.83331,28.58338
34.70000,28.91675,28.82054
34.80000,29.00000,28.79481
34.90000,29.08325,28.75924
35.00000,29.16675,28.92510
35.10000,29.25000,28.98420
35.20000,29.33325,28.99527
35.30000,29.41675,28.95004
35.40000,29.50000,28.87012
35.50000,29.58325,29.03501
35.60000,29.66675,29.14389
35.70000,29.75000,29.22312
35.80000,29.83331,29.26668
35.90000,29.91674,29.10665
36.00000,30.00006,29.38134
36.10000,30.08331,29.31602
36.20000,30.16668,29.32622
36.30000,30.24993,29.42524
36.40000,30.33318,29.52197
36.50000,30.41675,29.51369
36.60000,30.49999,29.62095
36.70000,30.58331,29.58890
36.80000,30.66675,29.61061
36.90000,30.75006,29.74178
37.00000,30.83325,29.77109
37.10000,30.91668,29.70557
37.20000,31.00000,29.71077
37.30000,31.08318,29.73522
37.40000,31.16675,29.85884
37.50000,31.25000,29.90486
37.60000,31.33325,29.86080
37.70000,31.41674,29.88908
37.80000,31.49999,30.02853
37.90000,31.58331,30.06440
38.00000,31.66674,30.00996
38.10000,31.74999,29.90863
38.20000,31.83331,30.01378
38.30000,31.91668,30.10801
38.40000,31.99999,30.20414
38.50000,32.08312,30.14280
38.60000,32.16668,30.26961
38.70000,32.24999,30.29529
38.80000,32.33331,30.31052
38.90000,32.41681,30.30876
39.00000,32.50006,30.56974
39.10000,32.58331,30.53739
39.20000,32.66674,30.57179
39.30000,32.75000,30.38844
39.40000,32.83318,30.69993
39.50000,32.91668,30.79891
39.60000,33.00000,30.50569
39.70000,33.08325,30.65181
39.80000,33.16681,30.69498
39.90000,33.25006,30.83678
40.00000,33.33325,30.80199
40.10000,33.41675,30.72212
40.20000,33.49999,30.81067
40.30000,33.58331,30.79244
40.40000,33.66675,31.01338
40.50000,33.74999,30.94488
40.60000,33.83324,30.98814
40.70000,33.91674,31.20443
40.80000,33.99993,30.93900
40.90000,34.08324,30.91092
41.00000,34.16680,31.08820
41.10000,34.25006,31.26646
41.20000,34.33324,31.23510
41.30000,34.41681,31.43786
41.40000,34.49999,31.25132
41.50000,34.58325,31.33834
41.60000,34.66674,31.24226
41.70000,34.75000,31.46800
41.80000,34.83325,31.55002
41.90000,34.91662,31.57477
42.00000,34.99999,31.37612
42.10000,35.08325,31.46800
42.20000,35.16681,31.45237
42.30000,35.24999,31.58736
42.40000,35.33331,31.62617
42.50000,35.41674,31.60882
42.60000,35.50006,31.79243
42.70000,35.58324,31.52655
42.80000,35.66675,31.91978
42.90000,35.75000,31.84471
43.00000,35.83318,31.82291
43.10000,35.91675,31.93355
43.20000,36.00006,31.87705
43.30000,36.08331,31.83256
43.40000,36.16675,32.07094
43.50000,36.25000,32.05698
43.60000,36.33325,32.03302
43.70000,36.41674,32.12009
43.80000,36.49993,32.13165
43.90000,36.58324,32.25484
44.00000,36.66674,32.24783
44.10000,36.75006,32.21770
44.20000,36.83331,32.26238
44.30000,36.91674,32.15253
44.40000,37.00006,32.27699
44.50000,37.08331,32.19364
44.60000,37.16674,32.43771
44.70000,37.24999,32.32310
44.80000,37.33324,32.22706
44.90000,37.41668,32.38273
45.00000,37.49999,32.46715
45.10000,37.58324,32.62464
45.20000,37.66675,32.58657
45.30000,37.74999,32.53188
45.40000,37.83325,32.41815
45.50000,37.91681,31.99734
45.60000,38.00006,-1.42153
45.70000,38.08324,-0.02724
45.80000,38.16674,0.10379
45.90000,38.25000,-0.29404
46.00000,38.33324,-0.13004
46.10000,38.41668,0.06316
46.20000,38.50006,-0.11907
46.30000,38.58331,-0.12642
46.40000,38.66674,-0.04645
46.50000,38.74999,0.10771
46.60000,38.83325,-0.01058
46.66200,38.88499,-0.15949