File: NATR/NatR/RDSO NatR Tensile 50.is_tens_RawData/Specimen_RawData_1.csv
Time,Extension,Load,Tensile strain,Tensile stress,Corrected Position
(sec),(mm),(N),(mm/mm),(MPa),(mm)
0.00000,0.00000,-0.00027,0.00000,-0.00003,0.00000
0.07000,0.04262,0.05604,0.00037,0.00623,0.04262
0.14000,0.11356,0.41148,0.00099,0.04572,0.11356
0.21000,0.17325,0.80978,0.00151,0.08998,0.17325
0.28000,0.23269,0.66109,0.00202,0.07345,0.23269
0.35000,0.29144,1.02221,0.00253,0.11358,0.29144
0.42000,0.34981,1.18868,0.00304,0.13208,0.34981
0.49000,0.40819,1.30682,0.00355,0.14520,0.40819
0.56000,0.46662,1.51098,0.00406,0.16789,0.46662
0.63000,0.52500,1.77225,0.00457,0.19692,0.52500
0.70000,0.58325,1.85760,0.00507,0.20640,0.58325
0.77000,0.64156,1.91839,0.00558,0.21315,0.64156
0.84000,0.69994,2.19864,0.00609,0.24429,0.69994
0.91000,0.75831,2.13908,0.00659,0.23768,0.75831
0.98000,0.81656,2.44360,0.00710,0.27151,0.81656
1.05000,0.87494,2.40782,0.00761,0.26754,0.87494
1.12000,0.93337,2.39913,0.00812,0.26657,0.93337
1.19000,0.99162,2.69985,0.00862,0.29998,0.99162
1.26000,1.05000,2.80387,0.00913,0.31154,1.05000
1.33000,1.10837,3.12642,0.00964,0.34738,1.10837
1.40000,1.16669,2.94773,0.01015,0.32753,1.16669
1.47000,1.22506,3.05206,0.01065,0.33912,1.22506
1.54000,1.28337,3.24309,0.01116,0.36034,1.28337
1.61000,1.34162,3.15897,0.01167,0.35100,1.34162
1.68000,1.39994,3.28211,0.01217,0.36468,1.39994
1.75000,1.45837,3.48773,0.01268,0.38753,1.45837
1.82000,1.51675,3.41632,0.01319,0.37959,1.51675
1.89000,1.57500,3.89468,0.01370,0.43274,1.57500
1.96000,1.63325,3.73189,0.01420,0.41465,1.63325
2.03000,1.69162,4.01231,0.01471,0.44581,1.69162
2.10000,1.75000,3.79196,0.01522,0.42133,1.75000
2.17000,1.80837,4.12311,0.01572,0.45812,1.80837
2.24000,1.86662,4.05642,0.01623,0.45071,1.86662
2.31000,1.92506,4.29340,0.01674,0.47704,1.92506
2.38000,1.98325,4.30917,0.01725,0.47880,1.98325
2.45000,2.04162,4.48751,0.01775,0.49861,2.04162
2.52000,2.10000,4.37221,0.01826,0.48580,2.10000
2.59000,2.15837,4.69956,0.01877,0.52217,2.15837
2.66000,2.21675,4.45594,0.01928,0.49510,2.21675
2.73000,2.27500,4.66600,0.01978,0.51844,2.27500
2.80000,2.33331,4.83455,0.02029,0.53717,2.33331
2.87000,2.39169,4.96139,0.02080,0.55127,2.39169
2.94000,2.45000,5.15659,0.02130,0.57295,2.45000
3.01000,2.50831,4.83100,0.02181,0.53678,2.50831
3.08000,2.56656,5.31979,0.02232,0.59109,2.56656
3.15000,2.62500,5.39079,0.02283,0.59898,2.62500
3.22000,2.68337,5.36572,0.02333,0.59619,2.68337
3.29000,2.74169,5.60046,0.02384,0.62227,2.74169
3.36000,2.80006,5.45788,0.02435,0.60643,2.80006
3.43000,2.85837,5.80386,0.02486,0.64487,2.85837
3.50000,2.91675,5.81537,0.02536,0.64615,2.91675
3.57000,2.97500,5.76076,0.02587,0.64008,2.97500
3.64000,3.03331,6.06597,0.02638,0.67400,3.03331
3.71000,3.09169,5.95225,0.02688,0.66136,3.09169
3.78000,3.15006,6.04407,0.02739,0.67156,3.15006
3.85000,3.20831,6.21242,0.02790,0.69027,3.20831
3.92000,3.26656,6.13939,0.02840,0.68215,3.26656
3.99000,3.32494,6.51009,0.02891,0.72334,3.32494
4.06000,3.38337,6.50992,0.02942,0.72332,3.38337
4.13000,3.44175,6.34098,0.02993,0.70455,3.44175
4.20000,3.50000,6.67920,0.03043,0.74213,3.50000
4.27000,3.55825,6.70178,0.03094,0.74464,3.55825
4.34000,3.61662,6.76575,0.03145,0.75175,3.61662
4.41000,3.67506,6.85723,0.03196,0.76191,3.67506
4.48000,3.73337,6.97581,0.03246,0.77509,3.73337
4.55000,3.79175,6.93053,0.03297,0.77006,3.79175
4.62000,3.84994,7.21110,0.03348,0.80123,3.84994
4.69000,3.90837,7.16033,0.03399,0.79559,3.90837
4.76000,3.96669,7.27169,0.03449,0.80797,3.96669
4.83000,4.02494,7.52946,0.03500,0.83661,4.02494
4.90000,4.08331,7.34453,0.03551,0.81606,4.08331
4.97000,4.14162,7.56179,0.03601,0.84020,4.14162
5.04000,4.20000,7.56137,0.03652,0.84015,4.20000
5.11000,4.25825,7.60986,0.03703,0.84554,4.25825
5.18000,4.31662,7.70572,0.03754,0.85619,4.31662
5.25000,4.37494,7.76212,0.03804,0.86246,4.37494
5.32000,4.43337,7.76399,0.03855,0.86266,4.43337
5.39000,4.49175,7.97826,0.03906,0.88647,4.49175
5.46000,4.55000,7.85575,0.03957,0.87286,4.55000
5.53000,4.60831,8.17438,0.04007,0.90826,4.60831
5.60000,4.66675,8.01987,0.04058,0.89110,4.66675
5.67000,4.72506,8.24244,0.04109,0.91583,4.72506
5.74000,4.78337,8.41021,0.04159,0.93447,4.78337
5.81000,4.84162,8.41222,0.04210,0.93469,4.84162
5.88000,4.90000,8.45473,0.04261,0.93941,4.90000
5.95000,4.95831,8.51807,0.04312,0.94645,4.95831
6.02000,5.01669,8.66629,0.04362,0.96292,5.01669
6.09000,5.07500,8.70077,0.04413,0.96675,5.07500
6.16000,5.13331,8.81669,0.04464,0.97963,5.13331
6.23000,5.19156,8.99640,0.04514,0.99960,5.19156
6.30000,5.25000,8.98695,0.04565,0.99855,5.25000
6.37000,5.30831,9.13995,0.04616,1.01555,5.30831
6.44000,5.36669,9.06099,0.04667,1.00678,5.36669
6.51000,5.42500,9.20607,0.04717,1.02290,5.42500
6.58000,5.48337,9.27041,0.04768,1.03005,5.48337
6.65000,5.54169,9.24185,0.04819,1.02687,5.54169
6.72000,5.60000,9.25648,0.04870,1.02850,5.60000
6.79000,5.65844,9.41302,0.04920,1.04589,5.65844
6.86000,5.71669,9.53646,0.04971,1.05961,5.71669
6.93000,5.77494,9.31937,0.05022,1.03549,5.77494
7.00000,5.83331,9.65686,0.05072,1.07298,5.83331
7.07000,5.89169,9.62421,0.05123,1.06936,5.89169
7.14000,5.94994,9.72663,0.05174,1.08074,5.94994
7.21000,6.00831,9.98565,0.05225,1.10952,6.00831
7.28000,6.06662,9.71316,0.05275,1.07924,6.06662
7.35000,6.12494,9.94330,0.05326,1.10481,6.12494
7.42000,6.18337,9.98964,0.05377,1.10996,6.18337
7.49000,6.24169,10.28270,0.05428,1.14252,6.24169
7.56000,6.30000,10.30624,0.05478,1.14514,6.30000
7.63000,6.35844,10.23519,0.05529,1.13724,6.35844
7.70000,6.41669,10.24543,0.05580,1.13838,6.41669
7.77000,6.47500,10.27509,0.05630,1.14168,6.47500
7.84000,6.53331,10.51966,0.05681,1.16885,6.53331
7.91000,6.59169,10.50623,0.05732,1.16736,6.59169
7.98000,6.65012,10.57567,0.05783,1.17507,6.65012
8.05000,6.70831,10.55299,0.05833,1.17255,6.70831
8.12000,6.76650,10.90733,0.05884,1.21193,6.76650
8.19000,6.82494,10.87409,0.05935,1.20823,6.82494
8.26000,6.88337,10.77333,0.05986,1.19704,6.88337
8.33000,6.94169,10.89204,0.06036,1.21023,6.94169
8.40000,7.00000,11.09027,0.06087,1.23225,7.00000
8.47000,7.05831,11.10828,0.06138,1.23425,7.05831
8.54000,7.11669,11.16287,0.06188,1.24032,7.11669
8.61000,7.17512,11.29517,0.06239,1.25502,7.17512
8.68000,7.23344,11.36041,0.06290,1.26227,7.23344
8.75000,7.29169,11.45637,0.06341,1.27293,7.29169
8.82000,7.35000,11.53976,0.06391,1.28220,7.35000
8.89000,7.40837,11.51958,0.06442,1.27995,7.40837
8.96000,7.46656,11.65227,0.06493,1.29470,7.46656
9.03000,7.52500,11.74715,0.06543,1.30524,7.52500
9.10000,7.58325,11.76202,0.06594,1.30689,7.58325
9.17000,7.64162,11.79596,0.06645,1.31066,7.64162
9.24000,7.70000,11.94350,0.06696,1.32706,7.70000
9.31000,7.75831,11.87634,0.06746,1.31959,7.75831
9.38000,7.81662,11.92809,0.06797,1.32534,7.81662
9.45000,7.87500,12.10906,0.06848,1.34545,7.87500
9.52000,7.93337,11.95787,0.06899,1.32865,7.93337
9.59000,7.99162,12.15427,0.06949,1.35047,7.99162
9.66000,8.04994,12.35421,0.07000,1.37269,8.04994
9.73000,8.10837,12.26641,0.07051,1.36293,8.10837
9.80000,8.16675,12.29232,0.07102,1.36581,8.16675
9.87000,8.22512,12.37625,0.07152,1.37514,8.22512
9.94000,8.28337,12.55521,0.07203,1.39502,8.28337
10.01000,8.34162,12.55457,0.07254,1.39495,8.34162
10.08000,8.40000,12.50001,0.07304,1.38889,8.40000
10.15000,8.45837,12.84381,0.07355,1.42709,8.45837
10.22000,8.51662,12.70571,0.07406,1.41175,8.51662
10.29000,8.57487,12.83909,0.07456,1.42657,8.57487
10.36000,8.63325,12.91479,0.07507,1.43498,8.63325
10.43000,8.69169,12.87644,0.07558,1.43072,8.69169
10.50000,8.75000,13.00852,0.07609,1.44539,8.75000
10.57000,8.80831,12.79346,0.07659,1.42150,8.80831
10.64000,8.86669,13.18848,0.07710,1.46539,8.86669
10.71000,8.92506,13.09485,0.07761,1.45498,8.92506
10.78000,8.98337,13.29063,0.07812,1.47674,8.98337
10.85000,9.04169,13.20944,0.07862,1.46772,9.04169
10.92000,9.10000,13.38617,0.07913,1.48735,9.10000
10.99000,9.15837,13.39156,0.07964,1.48795,9.15837
11.06000,9.21669,13.32335,0.08015,1.48037,9.21669
11.13000,9.27500,13.49920,0.08065,1.49991,9.27500
11.20000,9.33325,13.63699,0.08116,1.51522,9.33325
11.27000,9.39162,13.63909,0.08167,1.51545,9.39162
11.34000,9.45006,13.63537,0.08217,1.51504,9.45006
11.41000,9.50831,13.81433,0.08268,1.53492,9.50831
11.48000,9.56656,13.65332,0.08319,1.51704,9.56656
11.55000,9.62494,13.77009,0.08370,1.53001,9.62494
11.62000,9.68331,14.03168,0.08420,1.55908,9.68331
11.69000,9.74169,13.96355,0.08471,1.55151,9.74169
11.76000,9.80006,14.05821,0.08522,1.56202,9.80006
11.83000,9.85844,14.25142,0.08573,1.58349,9.85844
11.90000,9.91662,14.10058,0.08623,1.56673,9.91662
11.97000,9.97506,14.14699,0.08674,1.57189,9.97506
12.04000,10.03344,14.36621,0.08725,1.59625,10.03344
12.11000,10.09162,14.34747,0.08775,1.59416,10.09162
12.18000,10.15000,14.30892,0.08826,1.58988,10.15000
12.25000,10.20831,14.25061,0.08877,1.58340,10.20831
12.32000,10.26669,14.36334,0.08928,1.59593,10.26669
12.39000,10.32481,14.68638,0.08978,1.63182,10.32481
12.46000,10.38331,14.55560,0.09029,1.61729,10.38331
12.53000,10.44169,14.64440,0.09080,1.62716,10.44169
12.60000,10.49994,14.81594,0.09130,1.64622,10.49994
12.67000,10.55825,14.65266,0.09181,1.62807,10.55825
12.74000,10.61669,14.75239,0.09232,1.63915,10.61669
12.81000,10.67506,14.98079,0.09283,1.66453,10.67506
12.88000,10.73337,14.85197,0.09333,1.65022,10.73337
12.95000,10.79175,15.07618,0.09384,1.67513,10.79175
13.02000,10.85000,14.99774,0.09435,1.66642,10.85000
13.09000,10.90837,15.03107,0.09486,1.67012,10.90837
13.16000,10.96669,15.04596,0.09536,1.67177,10.96669
13.23000,11.02500,14.95816,0.09587,1.66202,11.02500
13.30000,11.08325,15.09262,0.09638,1.67696,11.08325
13.37000,11.14169,15.28957,0.09688,1.69884,11.14169
13.44000,11.19994,15.37184,0.09739,1.70798,11.19994
13.51000,11.25825,15.33434,0.09790,1.70382,11.25825
13.58000,11.31656,15.29611,0.09840,1.69957,11.31656
13.65000,11.37500,15.46109,0.09891,1.71790,11.37500
13.72000,11.43344,15.41426,0.09942,1.71270,11.43344
13.79000,11.49169,15.63470,0.09993,1.73719,11.49169
13.86000,11.54994,15.61234,0.10043,1.73470,11.54994
13.93000,11.60837,15.63963,0.10094,1.73774,11.60837
14.00000,11.66675,16.00134,0.10145,1.77793,11.66675
14.07000,11.72512,15.74770,0.10196,1.74974,11.72512
14.14000,11.78337,15.87315,0.10246,1.76368,11.78337
14.21000,11.84162,15.90207,0.10297,1.76690,11.84162
14.28000,11.90006,15.93195,0.10348,1.77022,11.90006
14.35000,11.95837,16.01730,0.10399,1.77970,11.95837
14.42000,12.01669,15.93871,0.10449,1.77097,12.01669
14.49000,12.07487,16.14441,0.10500,1.79382,12.07487
14.56000,12.13331,16.01228,0.10551,1.77914,12.13331
14.63000,12.19162,16.22521,0.10601,1.80280,12.19162
14.70000,12.25000,16.11598,0.10652,1.79066,12.25000
14.77000,12.30831,16.53074,0.10703,1.83675,12.30831
14.84000,12.36669,16.25984,0.10754,1.80665,12.36669
14.91000,12.42506,16.48489,0.10804,1.83165,12.42506
14.98000,12.48337,16.38185,0.10855,1.82021,12.48337
15.05000,12.54169,16.44683,0.10906,1.82743,12.54169
15.12000,12.60006,16.53989,0.10957,1.83777,12.60006
15.19000,12.65844,16.53093,0.11007,1.83677,12.65844
15.26000,12.71675,16.83908,0.11058,1.87101,12.71675
15.33000,12.77494,16.49170,0.11109,1.83241,12.77494
15.40000,12.83325,16.65963,0.11159,1.85107,12.83325
15.47000,12.89162,16.63624,0.11210,1.84847,12.89162
15.54000,12.95000,16.82355,0.11261,1.86928,12.95000
15.61000,13.00837,17.02568,0.11312,1.89174,13.00837
15.68000,13.06662,16.85270,0.11362,1.87252,13.06662
15.75000,13.12487,16.97525,0.11413,1.88614,13.12487
15.82000,13.18331,16.96222,0.11464,1.88469,13.18331
15.89000,13.24169,17.08766,0.11515,1.89863,13.24169
15.96000,13.30000,17.06430,0.11565,1.89603,13.30000
16.03000,13.35837,17.08321,0.11616,1.89813,13.35837
16.10000,13.41675,17.02678,0.11667,1.89186,13.41675
16.17000,13.47506,17.15839,0.11717,1.90649,13.47506
16.24000,13.53337,17.39833,0.11768,1.93315,13.53337
16.31000,13.59169,17.18088,0.11819,1.90899,13.59169
16.38000,13.65006,17.36292,0.11870,1.92921,13.65006
16.45000,13.70837,17.20870,0.11920,1.91208,13.70837
16.52000,13.76662,17.35518,0.11971,1.92835,13.76662
16.59000,13.82494,17.30279,0.12022,1.92253,13.82494
16.66000,13.88325,17.47631,0.12072,1.94181,13.88325
16.73000,13.94162,17.72999,0.12123,1.97000,13.94162
16.80000,14.00000,17.62235,0.12174,1.95804,14.00000
16.87000,14.05825,17.74844,0.12225,1.97205,14.05825
16.94000,14.11662,17.61905,0.12275,1.95767,14.11662
17.01000,14.17506,17.92793,0.12326,1.99199,14.17506
17.08000,14.23344,17.71523,0.12377,1.96836,14.23344
17.15000,14.29169,17.80729,0.12428,1.97859,14.29169
17.22000,14.35006,17.77643,0.12478,1.97516,14.35006
17.29000,14.40837,17.88250,0.12529,1.98694,14.40837
17.36000,14.46669,17.93684,0.12580,1.99298,14.46669
17.43000,14.52500,18.03349,0.12630,2.00372,14.52500
17.50000,14.58337,18.26321,0.12681,2.02925,14.58337
17.57000,14.64169,18.08602,0.12732,2.00956,14.64169
17.64000,14.69987,17.90964,0.12782,1.98996,14.69987
17.71000,14.75825,18.20311,0.12833,2.02257,14.75825
17.78000,14.81656,18.20848,0.12884,2.02316,14.81656
17.85000,14.87494,18.13427,0.12935,2.01492,14.87494
17.92000,14.93337,18.19657,0.12986,2.02184,14.93337
17.99000,14.99169,18.20049,0.13036,2.02228,14.99169
18.06000,15.05000,18.22795,0.13087,2.02533,15.05000
18.13000,15.10844,18.39160,0.13138,2.04351,15.10844
18.20000,15.16675,18.34401,0.13188,2.03822,15.16675
18.27000,15.22506,18.39767,0.13239,2.04419,15.22506
18.34000,15.28337,18.42931,0.13290,2.04770,15.28337
18.41000,15.34169,18.51241,0.13341,2.05693,15.34169
18.48000,15.40000,18.50384,0.13391,2.05598,15.40000
18.55000,15.45831,18.52779,0.13442,2.05864,15.45831
18.62000,15.51662,18.68586,0.13493,2.07621,15.51662
18.69000,15.57494,18.71819,0.13543,2.07980,15.57494
18.76000,15.63331,18.78563,0.13594,2.08729,15.63331
18.83000,15.69162,18.72213,0.13645,2.08024,15.69162
18.90000,15.74993,18.82592,0.13696,2.09177,15.74993
18.97000,15.80825,19.00752,0.13746,2.11195,15.80825
19.04000,15.86668,18.86048,0.13797,2.09561,15.86668
19.11000,15.92500,18.94098,0.13848,2.10455,15.92500
19.18000,15.98337,18.73202,0.13899,2.08134,15.98337
19.25000,16.04169,19.02785,0.13949,2.11421,16.04169
19.32000,16.10006,18.90667,0.14000,2.10074,16.10006
19.39000,16.15850,19.23889,0.14051,2.13765,16.15850
19.46000,16.21675,19.11401,0.14102,2.12378,16.21675
19.53000,16.27494,19.20260,0.14152,2.13362,16.27494
19.60000,16.33331,19.43982,0.14203,2.15998,16.33331
19.67000,16.39162,19.13662,0.14254,2.12629,16.39162
19.74000,16.44993,19.35202,0.14304,2.15022,16.44993
19.81000,16.50831,19.16613,0.14355,2.12957,16.50831
19.88000,16.56650,19.50161,0.14406,2.16685,16.56650
19.95000,16.62494,19.27565,0.14456,2.14174,16.62494
20.02000,16.68337,19.31717,0.14507,2.14635,16.68337
20.09000,16.74175,19.49656,0.14558,2.16628,16.74175
20.16000,16.80006,19.48841,0.14609,2.16538,16.80006
20.23000,16.85837,19.54182,0.14659,2.17131,16.85837
20.30000,16.91675,19.52953,0.14710,2.16995,16.91675
20.37000,16.97506,19.67045,0.14761,2.18561,16.97506
20.44000,17.03337,19.46556,0.14812,2.16284,17.03337
20.51000,17.09162,19.75110,0.14862,2.19457,17.09162
20.58000,17.15006,19.51324,0.14913,2.16814,17.15006
20.65000,17.20831,19.65331,0.14964,2.18370,17.20831
20.72000,17.26662,19.85590,0.15014,2.20621,17.26662
20.79000,17.32487,19.76807,0.15065,2.19645,17.32487
20.86000,17.38331,19.89408,0.15116,2.21045,17.38331
20.93000,17.44156,19.66575,0.15167,2.18508,17.44156
21.00000,17.50000,19.63009,0.15217,2.18112,17.50000
21.07000,17.55825,19.87368,0.15268,2.20819,17.55825
21.14000,17.61662,20.06268,0.15319,2.22919,17.61662
21.21000,17.67506,19.83917,0.15370,2.20435,17.67506
21.28000,17.73337,19.91010,0.15420,2.21223,17.73337
21.35000,17.79181,20.10463,0.15471,2.23385,17.79181
21.42000,17.85006,19.91162,0.15522,2.21240,17.85006
21.49000,17.90837,20.00855,0.15572,2.22317,17.90837
21.56000,17.96668,20.08242,0.15623,2.23138,17.96668
21.63000,18.02500,20.21479,0.15674,2.24609,18.02500
21.70000,18.08331,19.88095,0.15725,2.20899,18.08331
21.77000,18.14162,20.12204,0.15775,2.23578,18.14162
21.84000,18.20000,20.13226,0.15826,2.23692,18.20000
21.91000,18.25831,20.24954,0.15877,2.24995,18.25831
21.98000,18.31662,20.18349,0.15927,2.24261,18.31662
22.05000,18.37500,20.34724,0.15978,2.26080,18.37500
22.12000,18.43337,20.20923,0.16029,2.24547,18.43337
22.19000,18.49169,20.25437,0.16080,2.25049,18.49169
22.26000,18.55000,20.17227,0.16130,2.24136,18.55000
22.33000,18.60837,20.41640,0.16181,2.26849,18.60837
22.40000,18.66675,20.28875,0.16232,2.25431,18.66675
22.47000,18.72512,20.37472,0.16283,2.26386,18.72512
22.54000,18.78331,20.48157,0.16333,2.27573,18.78331
22.61000,18.84162,20.42120,0.16384,2.26902,18.84162
22.68000,18.90000,20.43979,0.16435,2.27109,18.90000
22.75000,18.95837,20.53416,0.16486,2.28157,18.95837
22.82000,19.01662,20.56587,0.16536,2.28510,19.01662
22.89000,19.07494,20.66957,0.16587,2.29662,19.07494
22.96000,19.13325,20.51679,0.16638,2.27964,19.13325
23.03000,19.19162,20.58081,0.16688,2.28676,19.19162
23.10000,19.24993,20.83292,0.16739,2.31477,19.24993
23.17000,19.30831,20.55676,0.16790,2.28408,19.30831
23.24000,19.36675,20.63410,0.16841,2.29268,19.36675
23.31000,19.42500,20.72381,0.16891,2.30265,19.42500
23.38000,19.48331,20.61118,0.16942,2.29013,19.48331
23.45000,19.54168,20.75886,0.16993,2.30654,19.54168
23.52000,19.60006,20.68941,0.17044,2.29882,19.60006
23.59000,19.65843,20.80037,0.17094,2.31115,19.65843
23.66000,19.71668,20.94220,0.17145,2.32691,19.71668
23.73000,19.77506,20.72426,0.17196,2.30270,19.77506
23.80000,19.83331,20.83084,0.17246,2.31454,19.83331
23.87000,19.89168,20.85536,0.17297,2.31726,19.89168
23.94000,19.95000,20.88127,0.17348,2.32014,19.95000
24.01000,20.00825,21.06833,0.17398,2.34093,20.00825
24.08000,20.06662,20.94076,0.17449,2.32675,20.06662
24.15000,20.12493,20.86368,0.17500,2.31819,20.12493
24.22000,20.18331,21.13394,0.17551,2.34822,20.18331
24.29000,20.24168,21.14918,0.17601,2.34991,20.24168
24.36000,20.30000,21.30403,0.17652,2.36712,20.30000
24.43000,20.35837,21.04962,0.17703,2.33885,20.35837
24.50000,20.41675,21.15748,0.17754,2.35083,20.41675
24.57000,20.47500,21.42727,0.17804,2.38081,20.47500
24.64000,20.53337,21.30012,0.17855,2.36668,20.53337
24.71000,20.59175,21.20969,0.17906,2.35663,20.59175
24.78000,20.65012,21.28518,0.17957,2.36502,20.65012
24.85000,20.70831,21.44603,0.18007,2.38289,20.70831
24.92000,20.76662,21.40293,0.18058,2.37810,20.76662
24.99000,20.82487,21.28114,0.18109,2.36457,20.82487
25.06000,20.88331,21.45434,0.18159,2.38382,20.88331
25.13000,20.94168,21.57682,0.18210,2.39742,20.94168
25.20000,21.00000,21.43367,0.18261,2.38152,21.00000
25.27000,21.05812,21.51101,0.18311,2.39011,21.05812
25.34000,21.11662,21.48593,0.18362,2.38733,21.11662
25.41000,21.17506,21.51779,0.18413,2.39087,21.17506
25.48000,21.23337,21.42505,0.18464,2.38056,21.23337
25.55000,21.29168,21.38454,0.18515,2.37606,21.29168
25.62000,21.35006,21.69974,0.18565,2.41108,21.35006
25.69000,21.40850,21.60146,0.18616,2.40016,21.40850
25.76000,21.46675,21.53063,0.18667,2.39229,21.46675
25.83000,21.52506,21.69347,0.18717,2.41039,21.52506
25.90000,21.58331,21.56976,0.18768,2.39664,21.58331
25.97000,21.64169,21.79403,0.18819,2.42156,21.64169
26.04000,21.70000,21.76053,0.18870,2.41784,21.70000
26.11000,21.75831,21.66107,0.18920,2.40679,21.75831
26.18000,21.81656,21.87083,0.18971,2.43009,21.81656
26.25000,21.87487,22.00676,0.19022,2.44520,21.87487
26.32000,21.93337,21.81972,0.19072,2.42441,21.93337
26.39000,21.99169,21.88504,0.19123,2.43167,21.99169
26.46000,22.04994,21.84164,0.19174,2.42685,22.04994
26.53000,22.10831,22.17149,0.19225,2.46350,22.10831
26.60000,22.16681,22.02466,0.19275,2.44718,22.16681
26.67000,22.22506,21.89968,0.19326,2.43330,22.22506
26.74000,22.28337,22.08119,0.19377,2.45347,22.28337
26.81000,22.34169,21.95442,0.19428,2.43938,22.34169
26.88000,22.40006,22.13154,0.19478,2.45906,22.40006
26.95000,22.45837,22.01531,0.19529,2.44615,22.45837
27.02000,22.51668,22.26428,0.19580,2.47381,22.51668
27.09000,22.57500,22.03154,0.19630,2.44795,22.57500
27.16000,22.63318,22.43707,0.19681,2.49301,22.63318
27.23000,22.69162,22.15253,0.19732,2.46139,22.69162
27.30000,22.74993,22.37160,0.19783,2.48573,22.74993
27.37000,22.80825,22.47016,0.19833,2.49668,22.80825
27.44000,22.86668,22.35270,0.19884,2.48363,22.86668
27.51000,22.92506,22.42019,0.19935,2.49113,22.92506
27.58000,22.98337,22.37439,0.19986,2.48604,22.98337
27.65000,23.04168,22.41123,0.20036,2.49014,23.04168
27.72000,23.10006,22.50912,0.20087,2.50101,23.10006
27.79000,23.15843,22.39864,0.20138,2.48874,23.15843
27.86000,23.21668,22.59104,0.20188,2.51012,23.21668
27.93000,23.27500,22.55590,0.20239,2.50621,23.27500
28.00000,23.33337,22.70637,0.20290,2.52293,23.33337
28.07000,23.39168,22.48309,0.20341,2.49812,23.39168
28.14000,23.44993,22.76375,0.20391,2.52931,23.44993
28.21000,23.50831,22.67147,0.20442,2.51905,23.50831
28.28000,23.56656,22.62043,0.20493,2.51338,23.56656
28.35000,23.62493,22.59322,0.20543,2.51036,23.62493
28.42000,23.68324,22.64909,0.20594,2.51657,23.68324
28.49000,23.74168,22.55690,0.20645,2.50632,23.74168
28.56000,23.79999,22.84137,0.20696,2.53793,23.79999
28.63000,23.85837,22.77404,0.20746,2.53045,23.85837
28.70000,23.91668,22.67860,0.20797,2.51984,23.91668
28.77000,23.97500,22.89588,0.20848,2.54399,23.97500
28.84000,24.03337,23.01222,0.20899,2.55691,24.03337
28.91000,24.09175,23.03284,0.20949,2.55920,24.09175
28.98000,24.15012,22.71171,0.21000,2.52352,24.15012
29.05000,24.20831,23.05667,0.21051,2.56185,24.20831
29.12000,24.26656,23.00110,0.21101,2.55568,24.26656
29.19000,24.32487,22.86681,0.21152,2.54076,24.32487
29.26000,24.38325,22.96627,0.21203,2.55181,24.38325
29.33000,24.44162,23.22669,0.21254,2.58074,24.44162
29.40000,24.49987,23.05976,0.21304,2.56220,24.49987
29.47000,24.55825,22.98885,0.21355,2.55432,24.55825
29.54000,24.61662,23.21084,0.21406,2.57898,24.61662
29.61000,24.67506,23.31823,0.21457,2.59091,24.67506
29.68000,24.73337,23.25603,0.21507,2.58400,24.73337
29.75000,24.79168,23.35869,0.21558,2.59541,24.79168
29.82000,24.85000,23.47500,0.21609,2.60833,24.85000
29.89000,24.90843,23.30476,0.21660,2.58942,24.90843
29.96000,24.96668,23.30139,0.21710,2.58904,24.96668
30.03000,25.02506,23.12380,0.21761,2.56931,25.02506
30.10000,25.08331,23.55825,0.21812,2.61758,25.08331
30.17000,25.14168,23.55475,0.21862,2.61719,25.14168
30.24000,25.20000,23.21973,0.21913,2.57997,25.20000
30.31000,25.25831,23.42737,0.21964,2.60304,25.25831
30.38000,25.31656,23.48068,0.22014,2.60896,25.31656
30.45000,25.37493,23.40772,0.22065,2.60086,25.37493
30.52000,25.43337,23.59851,0.22116,2.62206,25.43337
30.59000,25.49156,23.68881,0.22167,2.63209,25.49156
30.66000,25.54993,23.64500,0.22217,2.62722,25.54993
30.73000,25.60831,23.46971,0.22268,2.60775,25.60831
30.80000,25.66675,23.69226,0.22319,2.63247,25.66675
30.87000,25.72512,23.69662,0.22370,2.63296,25.72512
30.94000,25.78337,23.75702,0.22420,2.63967,25.78337
31.01000,25.84162,23.70649,0.22471,2.63405,25.84162
31.08000,25.90006,23.78227,0.22522,2.64247,25.90006
31.15000,25.95837,23.78580,0.22572,2.64287,25.95837
31.22000,26.01668,23.73522,0.22623,2.63725,26.01668
31.29000,26.07487,23.90759,0.22674,2.65640,26.07487
31.36000,26.13331,23.86987,0.22725,2.65221,26.13331
31.43000,26.19162,23.87002,0.22775,2.65222,26.19162
31.50000,26.25000,24.04224,0.22826,2.67136,26.25000
31.57000,26.30831,23.88687,0.22877,2.65410,26.30831
31.64000,26.36662,24.14665,0.22927,2.68296,26.36662
31.71000,26.42500,23.74252,0.22978,2.63806,26.42500
31.78000,26.48337,24.19859,0.23029,2.68873,26.48337
31.85000,26.54168,24.01248,0.23080,2.66805,26.54168
31.92000,26.60000,24.10898,0.23130,2.67878,26.60000
31.99000,26.65843,24.13653,0.23181,2.68184,26.65843
32.06000,26.71675,24.09044,0.23232,2.67672,26.71675
32.13000,26.77506,24.28439,0.23283,2.69827,26.77506
32.20000,26.83331,24.21045,0.23333,2.69005,26.83331
32.27000,26.89168,24.31355,0.23384,2.70151,26.89168
32.34000,26.95006,24.33768,0.23435,2.70419,26.95006
32.41000,27.00831,24.20175,0.23485,2.68908,27.00831
32.48000,27.06656,24.28742,0.23536,2.69860,27.06656
32.55000,27.12493,24.51306,0.23587,2.72367,27.12493
32.62000,27.18325,24.57441,0.23638,2.73049,27.18325
32.69000,27.24168,24.45849,0.23688,2.71761,27.24168
32.76000,27.29993,24.26771,0.23739,2.69641,27.29993
32.83000,27.35831,24.26881,0.23790,2.69653,27.35831
32.90000,27.41656,24.22791,0.23840,2.69199,27.41656
32.97000,27.47506,24.76982,0.23891,2.75220,27.47506
33.04000,27.53337,24.30741,0.23942,2.70082,27.53337
33.11000,27.59168,24.66637,0.23993,2.74071,27.59168
33.18000,27.65012,24.53414,0.24044,2.72602,27.65012
33.25000,27.70837,24.38357,0.24094,2.70929,27.70837
33.32000,27.76668,24.71925,0.24145,2.74658,27.76668
33.39000,27.82500,24.69197,0.24196,2.74355,27.82500
33.46000,27.88337,24.77494,0.24246,2.75277,27.88337
33.53000,27.94162,24.72804,0.24297,2.74756,27.94162
33.60000,27.99993,24.70034,0.24348,2.74448,27.99993
33.67000,28.05825,24.70375,0.24398,2.74486,28.05825
33.74000,28.11662,24.81807,0.24449,2.75756,28.11662
33.81000,28.17499,24.70495,0.24500,2.74499,28.17499
33.88000,28.23337,24.74156,0.24551,2.74906,28.23337
33.95000,28.29168,24.78285,0.24601,2.75365,28.29168
34.02000,28.35000,24.80228,0.24652,2.75581,28.35000
34.09000,28.40843,24.85990,0.24703,2.76221,28.40843
34.16000,28.46675,24.89451,0.24754,2.76606,28.46675
34.23000,28.52506,24.83698,0.24804,2.75966,28.52506
34.30000,28.58337,24.91662,0.24855,2.76851,28.58337
34.37000,28.64168,25.04133,0.24906,2.78237,28.64168
34.44000,28.70000,25.14326,0.24957,2.79370,28.70000
34.51000,28.75824,24.94885,0.25007,2.77209,28.75824
34.58000,28.81662,25.30243,0.25058,2.81138,28.81662
34.65000,28.87500,25.20038,0.25109,2.80004,28.87500
34.72000,28.93331,25.12982,0.25159,2.79220,28.93331
34.79000,28.99156,25.06896,0.25210,2.78544,28.99156
34.86000,29.04993,25.25543,0.25261,2.80616,29.04993
34.93000,29.10831,25.21674,0.25312,2.80186,29.10831
35.00000,29.16662,25.38325,0.25362,2.82036,29.16662
35.07000,29.22506,25.22477,0.25413,2.80275,29.22506
35.14000,29.28331,25.28708,0.25464,2.80967,29.28331
35.21000,29.34168,25.24047,0.25515,2.80450,29.34168
35.28000,29.40006,25.39121,0.25565,2.82125,29.40006
35.35000,29.45837,25.27699,0.25616,2.80855,29.45837
35.42000,29.51668,25.53480,0.25667,2.83720,29.51668
35.49000,29.57493,25.35950,0.25717,2.81772,29.57493
35.56000,29.63331,25.46033,0.25768,2.82893,29.63331
35.63000,29.69162,25.60443,0.25819,2.84494,29.69162
35.70000,29.75000,25.49371,0.25870,2.83263,29.75000
35.77000,29.80831,25.35026,0.25920,2.81670,29.80831
35.84000,29.86662,25.58582,0.25971,2.84287,29.86662
35.91000,29.92500,25.33447,0.26022,2.81494,29.92500
35.98000,29.98331,25.65993,0.26072,2.85110,29.98331
36.05000,30.04162,25.56872,0.26123,2.84097,30.04162
36.12000,30.10006,25.50309,0.26174,2.83368,30.10006
36.19000,30.15843,25.69574,0.26225,2.85508,30.15843
36.26000,30.21675,25.64382,0.26275,2.84931,30.21675
36.33000,30.27500,25.75444,0.26326,2.86160,30.27500
36.40000,30.33331,25.88299,0.26377,2.87589,30.33331
36.47000,30.39168,25.74913,0.26428,2.86101,30.39168
36.54000,30.45000,25.59042,0.26478,2.84338,30.45000
36.61000,30.50837,25.66035,0.26529,2.85115,30.50837
36.68000,30.56656,25.69525,0.26580,2.85503,30.56656
36.75000,30.62487,25.93151,0.26630,2.88128,30.62487
36.82000,30.68331,25.82985,0.26681,2.86998,30.68331
36.89000,30.74162,25.98084,0.26732,2.88676,30.74162
36.96000,30.79993,25.84143,0.26783,2.87127,30.79993
37.03000,30.85831,25.84112,0.26833,2.87124,30.85831
37.10000,30.91675,26.00677,0.26884,2.88964,30.91675
37.17000,30.97506,25.91709,0.26935,2.87968,30.97506
37.24000,31.03331,26.10976,0.26985,2.90108,31.03331
37.31000,31.09168,26.05487,0.27036,2.89499,31.09168
37.38000,31.15006,26.18762,0.27087,2.90973,31.15006
37.45000,31.20837,26.00533,0.27138,2.88948,31.20837
37.52000,31.26668,26.05713,0.27188,2.89524,31.26668
37.59000,31.32500,26.02722,0.27239,2.89191,31.32500
37.66000,31.38331,26.11853,0.27290,2.90206,31.38331
37.73000,31.44168,26.04753,0.27341,2.89417,31.44168
37.80000,31.49999,26.14596,0.27391,2.90511,31.49999
37.87000,31.55831,26.35568,0.27442,2.92841,31.55831
37.94000,31.61662,26.19680,0.27493,2.91076,31.61662
38.01000,31.67500,26.38986,0.27543,2.93221,31.67500
38.08000,31.73331,26.22472,0.27594,2.91386,31.73331
38.15000,31.79168,26.20305,0.27645,2.91145,31.79168
38.22000,31.85000,26.42422,0.27696,2.93602,31.85000
38.29000,31.90837,26.41203,0.27746,2.93467,31.90837
38.36000,31.96668,26.34544,0.27797,2.92727,31.96668
38.43000,32.02506,26.44570,0.27848,2.93841,32.02506
38.50000,32.08343,26.37794,0.27899,2.93088,32.08343
38.57000,32.14168,26.48670,0.27949,2.94297,32.14168
38.64000,32.19993,26.33730,0.28000,2.92637,32.19993
38.71000,32.25831,26.57602,0.28051,2.95289,32.25831
38.78000,32.31662,26.73144,0.28101,2.97016,32.31662
38.85000,32.37493,26.49417,0.28152,2.94380,32.37493
38.92000,32.43331,26.54822,0.28203,2.94980,32.43331
38.99000,32.49162,26.73570,0.28254,2.97063,32.49162
39.06000,32.55000,26.59321,0.28304,2.95480,32.55000
39.13000,32.60831,26.51707,0.28355,2.94634,32.60831
39.20000,32.66674,26.60482,0.28406,2.95609,32.66674
39.27000,32.72500,26.70573,0.28457,2.96730,32.72500
39.34000,32.78337,26.77967,0.28507,2.97552,32.78337
39.41000,32.84168,26.50674,0.28558,2.94519,32.84168
39.48000,32.89999,26.75740,0.28609,2.97304,32.89999
39.55000,32.95837,26.89661,0.28659,2.98851,32.95837
39.62000,33.01668,26.68601,0.28710,2.96511,33.01668
39.69000,33.07499,26.87885,0.28761,2.98654,33.07499
39.76000,33.13337,26.84587,0.28812,2.98287,33.13337
39.83000,33.19168,26.61129,0.28862,2.95681,33.19168
39.90000,33.24999,26.80158,0.28913,2.97795,33.24999
39.97000,33.30831,26.93604,0.28964,2.99289,33.30831
40.04000,33.36668,26.88454,0.29015,2.98717,33.36668
40.11000,33.42500,26.99685,0.29065,2.99965,33.42500
40.18000,33.48331,26.98292,0.29116,2.99810,33.48331
40.25000,33.54162,27.00234,0.29167,3.00026,33.54162
40.32000,33.60000,26.87839,0.29217,2.98649,33.60000
40.39000,33.65849,26.97444,0.29268,2.99716,33.65849
40.46000,33.71675,27.15695,0.29319,3.01744,33.71675
40.53000,33.77493,27.28102,0.29370,3.03122,33.77493
40.60000,33.83331,27.10726,0.29420,3.01192,33.83331
40.67000,33.89168,26.73695,0.29471,2.97077,33.89168
40.74000,33.94999,27.06641,0.29522,3.00738,33.94999
40.81000,34.00831,27.19592,0.29572,3.02177,34.00831
40.88000,34.06656,27.09019,0.29623,3.01002,34.06656
40.95000,34.12499,27.07035,0.29674,3.00782,34.12499
41.02000,34.18337,27.28651,0.29725,3.03183,34.18337
41.09000,34.24162,27.17174,0.29775,3.01908,34.24162
41.16000,34.30000,27.01346,0.29826,3.00150,34.30000
41.23000,34.35831,27.20527,0.29877,3.02281,34.35831
41.30000,34.41668,27.42809,0.29928,3.04757,34.41668
41.37000,34.47506,27.46899,0.29978,3.05211,34.47506
41.44000,34.53337,27.27120,0.30029,3.03013,34.53337
41.51000,34.59168,27.41435,0.30080,3.04604,34.59168
41.58000,34.65006,27.54484,0.30130,3.06054,34.65006
41.65000,34.70837,27.39620,0.30181,3.04402,34.70837
41.72000,34.76668,27.28345,0.30232,3.03149,34.76668
41.79000,34.82493,27.41281,0.30283,3.04587,34.82493
41.86000,34.88337,27.46005,0.30333,3.05112,34.88337
41.93000,34.94168,27.53242,0.30384,3.05916,34.94168
42.00000,34.99993,27.60301,0.30435,3.06700,34.99993
42.07000,35.05825,27.54163,0.30485,3.06018,35.05825
42.14000,35.11662,27.77741,0.30536,3.08638,35.11662
42.21000,35.17500,27.60612,0.30587,3.06735,35.17500
42.28000,35.23337,27.73683,0.30638,3.08187,35.23337
42.35000,35.29174,27.60871,0.30688,3.06763,35.29174
42.42000,35.34993,27.98514,0.30739,3.10946,35.34993
42.49000,35.40837,27.80437,0.30790,3.08937,35.40837
42.56000,35.46681,27.59091,0.30841,3.06566,35.46681
42.63000,35.52499,27.77440,0.30891,3.08604,35.52499
42.70000,35.58331,27.72921,0.30942,3.08102,35.58331
42.77000,35.64168,27.82105,0.30993,3.09123,35.64168
42.84000,35.70006,27.89210,0.31044,3.09912,35.70006
42.91000,35.75825,27.84738,0.31094,3.09415,35.75825
42.98000,35.81656,27.99014,0.31145,3.11002,35.81656
43.05000,35.87499,27.98306,0.31196,3.10923,35.87499
43.12000,35.93331,27.83790,0.31246,3.09310,35.93331
43.19000,35.99156,27.86509,0.31297,3.09612,35.99156
43.26000,36.05000,28.08105,0.31348,3.12012,36.05000
43.33000,36.10831,27.90827,0.31399,3.10092,36.10831
43.40000,36.16675,28.01186,0.31449,3.11243,36.16675
43.47000,36.22506,28.20461,0.31500,3.13385,36.22506
43.54000,36.28337,27.92436,0.31551,3.10271,36.28337
43.61000,36.34162,27.99210,0.31601,3.11023,36.34162
43.68000,36.40000,28.13726,0.31652,3.12636,36.40000
43.75000,36.45837,28.02910,0.31703,3.11434,36.45837
43.82000,36.51662,28.31793,0.31754,3.14644,36.51662
43.89000,36.57499,28.14585,0.31804,3.12732,36.57499
43.96000,36.63337,28.16995,0.31855,3.12999,36.63337
44.03000,36.69162,28.12516,0.31906,3.12502,36.69162
44.10000,36.74999,28.29079,0.31957,3.14342,36.74999
44.17000,36.80837,28.28974,0.32007,3.14330,36.80837
44.24000,36.86668,28.27914,0.32058,3.14213,36.86668
44.31000,36.92500,28.33446,0.32109,3.14827,36.92500
44.38000,36.98331,28.45270,0.32159,3.16141,36.98331
44.45000,37.04168,28.38302,0.32210,3.15367,37.04168
44.52000,37.10000,28.52214,0.32261,3.16913,37.10000
44.59000,37.15837,28.53595,0.32312,3.17066,37.15837
44.66000,37.21668,28.40188,0.32362,3.15576,37.21668
44.73000,37.27493,28.47097,0.32413,3.16344,37.27493
44.80000,37.33331,28.28729,0.32464,3.14303,37.33331
44.87000,37.39174,28.47543,0.32515,3.16394,37.39174
44.94000,37.45006,28.35795,0.32565,3.15088,37.45006
45.01000,37.50831,28.29449,0.32616,3.14383,37.50831
45.08000,37.56668,28.53996,0.32667,3.17111,37.56668
45.15000,37.62500,28.53149,0.32717,3.17017,37.62500
45.22000,37.68331,28.59862,0.32768,3.17762,37.68331
45.29000,37.74168,28.89100,0.32819,3.21011,37.74168
45.36000,37.80000,28.75039,0.32870,3.19449,37.80000
45.43000,37.85831,28.57095,0.32920,3.17455,37.85831
45.50000,37.91668,28.90780,0.32971,3.21198,37.91668
45.57000,37.97499,28.79232,0.33022,3.19915,37.97499
45.64000,38.03331,28.77373,0.33072,3.19708,38.03331
45.71000,38.09162,28.71219,0.33123,3.19024,38.09162
45.78000,38.15006,28.81241,0.33174,3.20138,38.15006
45.85000,38.20831,28.88113,0.33225,3.20901,38.20831
45.92000,38.26662,28.71018,0.33275,3.19002,38.26662
45.99000,38.32499,28.87939,0.33326,3.20882,38.32499
46.06000,38.38337,29.08411,0.33377,3.23157,38.38337
46.13000,38.44174,28.91497,0.33428,3.21277,38.44174
46.20000,38.50000,28.85837,0.33478,3.20649,38.50000
46.27000,38.55818,29.22601,0.33529,3.24733,38.55818
46.34000,38.61662,29.10917,0.33580,3.23435,38.61662
46.41000,38.67506,29.07157,0.33630,3.23017,38.67506
46.48000,38.73331,28.84899,0.33681,3.20544,38.73331
46.55000,38.79162,29.15447,0.33732,3.23939,38.79162
46.62000,38.84993,28.98617,0.33783,3.22069,38.84993
46.69000,38.90843,29.08007,0.33833,3.23112,38.90843
46.76000,38.96668,28.97659,0.33884,3.21962,38.96668
46.83000,39.02499,29.39711,0.33935,3.26635,39.02499
46.90000,39.08331,29.21967,0.33985,3.24663,39.08331
46.97000,39.14168,29.18313,0.34036,3.24257,39.14168
47.04000,39.19999,29.06395,0.34087,3.22933,39.19999
47.11000,39.25825,29.31325,0.34138,3.25703,39.25825
47.18000,39.31662,29.25530,0.34188,3.25059,39.31662
47.25000,39.37493,29.23666,0.34239,3.24852,39.37493
47.32000,39.43331,29.35787,0.34290,3.26199,39.43331
47.39000,39.49168,29.47212,0.34341,3.27468,39.49168
47.46000,39.54993,29.47842,0.34391,3.27538,39.54993
47.53000,39.60831,29.53259,0.34442,3.28140,39.60831
47.60000,39.66675,29.47141,0.34493,3.27460,39.66675
47.67000,39.72499,29.40247,0.34543,3.26694,39.72499
47.74000,39.78331,29.46688,0.34594,3.27410,39.78331
47.81000,39.84162,29.71963,0.34645,3.30218,39.84162
47.88000,39.89999,29.58846,0.34696,3.28761,39.89999
47.95000,39.95837,29.60795,0.34746,3.28977,39.95837
48.02000,40.01674,29.61285,0.34797,3.29032,40.01674
48.09000,40.07499,29.62522,0.34848,3.29169,40.07499
48.16000,40.13325,29.83974,0.34898,3.31553,40.13325
48.23000,40.19162,29.55725,0.34949,3.28414,40.19162
48.30000,40.25000,29.66070,0.35000,3.29563,40.25000
48.37000,40.30831,29.74897,0.35051,3.30544,40.30831
48.44000,40.36662,29.83841,0.35101,3.31538,40.36662
48.51000,40.42499,29.86795,0.35152,3.31866,40.42499
48.58000,40.48337,29.89256,0.35203,3.32140,40.48337
48.65000,40.54168,29.87339,0.35254,3.31927,40.54168
48.72000,40.60006,29.93116,0.35304,3.32568,40.60006
48.79000,40.65837,29.89726,0.35355,3.32192,40.65837
48.86000,40.71668,29.96706,0.35406,3.32967,40.71668
48.93000,40.77499,30.01328,0.35457,3.33481,40.77499
49.00000,40.83330,30.02883,0.35507,3.33654,40.83330
49.07000,40.89168,29.87167,0.35558,3.31907,40.89168
49.14000,40.94999,30.06442,0.35609,3.34049,40.94999
49.21000,41.00837,30.24457,0.35659,3.36051,41.00837
49.28000,41.06668,30.23353,0.35710,3.35928,41.06668
49.35000,41.12493,30.30034,0.35761,3.36670,41.12493
49.42000,41.18337,30.13157,0.35812,3.34795,41.18337
49.49000,41.24168,30.03586,0.35862,3.33732,41.24168
49.56000,41.29999,30.15565,0.35913,3.35063,41.29999
49.63000,41.35831,30.12413,0.35964,3.34713,41.35831
49.70000,41.41668,30.12381,0.36015,3.34709,41.41668
49.77000,41.47499,30.15428,0.36065,3.35048,41.47499
49.84000,41.53330,30.37357,0.36116,3.37484,41.53330
49.91000,41.59174,30.39894,0.36167,3.37766,41.59174
49.98000,41.65012,30.29529,0.36217,3.36614,41.65012
50.05000,41.70830,30.41202,0.36268,3.37911,41.70830
50.12000,41.76662,30.65409,0.36319,3.40601,41.76662
50.19000,41.82493,30.38978,0.36370,3.37664,41.82493
50.26000,41.88324,30.49549,0.36420,3.38839,41.88324
50.33000,41.94168,30.18134,0.36471,3.35348,41.94168
50.40000,41.99999,30.56773,0.36522,3.39641,41.99999
50.47000,42.05831,30.40565,0.36572,3.37841,42.05831
50.54000,42.11668,30.44018,0.36623,3.38224,42.11668
50.61000,42.17506,30.45468,0.36674,3.38385,42.17506
50.68000,42.23337,30.56832,0.36725,3.39648,42.23337
50.75000,42.29168,30.62676,0.36775,3.40297,42.29168
50.82000,42.34999,30.60300,0.36826,3.40033,42.34999
50.89000,42.40837,30.58517,0.36877,3.39835,42.40837
50.96000,42.46662,30.79898,0.36927,3.42211,42.46662
51.03000,42.52493,30.69621,0.36978,3.41069,42.52493
51.10000,42.58330,30.60898,0.37029,3.40100,42.58330
51.17000,42.64162,30.61921,0.37080,3.40213,42.64162
51.24000,42.69999,30.56979,0.37130,3.39664,42.69999
51.31000,42.75837,30.72227,0.37181,3.41359,42.75837
51.38000,42.81668,30.67187,0.37232,3.40799,42.81668
51.45000,42.87506,30.66614,0.37283,3.40735,42.87506
51.52000,42.93337,30.80569,0.37333,3.42285,42.93337
51.59000,42.99162,30.79080,0.37384,3.42120,42.99162
51.66000,43.04993,30.81500,0.37435,3.42389,43.04993
51.73000,43.10837,30.84919,0.37486,3.42769,43.10837
51.80000,43.16675,31.04183,0.37536,3.44909,43.16675
51.87000,43.22506,30.74436,0.37587,3.41604,43.22506
51.94000,43.28331,30.95308,0.37638,3.43923,43.28331
52.01000,43.34162,30.87000,0.37688,3.43000,43.34162
52.08000,43.39999,31.14318,0.37739,3.46035,43.39999
52.15000,43.45837,30.94593,0.37790,3.43844,43.45837
52.22000,43.51668,31.14215,0.37841,3.46024,43.51668
52.29000,43.57493,31.11820,0.37891,3.45758,43.57493
52.36000,43.63331,31.23277,0.37942,3.47031,43.63331
52.43000,43.69168,31.32054,0.37993,3.48006,43.69168
52.50000,43.75000,31.22762,0.38043,3.46974,43.75000
52.57000,43.80831,30.96444,0.38094,3.44049,43.80831
52.64000,43.86668,31.19672,0.38145,3.46630,43.86668
52.71000,43.92506,31.15562,0.38196,3.46174,43.92506
52.78000,43.98337,31.16517,0.38246,3.46280,43.98337
52.85000,44.04168,31.24129,0.38297,3.47125,44.04168
52.92000,44.09999,31.37070,0.38348,3.48563,44.09999
52.99000,44.15837,31.39348,0.38399,3.48816,44.15837
53.06000,44.21668,31.55041,0.38449,3.50560,44.21668
53.13000,44.27487,31.23531,0.38500,3.47059,44.27487
53.20000,44.33325,31.32113,0.38551,3.48013,44.33325
53.27000,44.39168,31.51995,0.38601,3.50222,44.39168
53.34000,44.44999,31.45000,0.38652,3.49444,44.44999
53.41000,44.50831,31.22091,0.38703,3.46899,44.50831
53.48000,44.56656,31.54307,0.38754,3.50479,44.56656
53.55000,44.62500,31.18932,0.38804,3.46548,44.62500
53.62000,44.68337,31.50868,0.38855,3.50096,44.68337
53.69000,44.74168,31.55816,0.38906,3.50646,44.74168
53.76000,44.80006,31.42865,0.38957,3.49207,44.80006
53.83000,44.85837,31.61689,0.39007,3.51299,44.85837
53.90000,44.91662,31.65166,0.39058,3.51685,44.91662
53.97000,44.97499,31.59092,0.39109,3.51010,44.97499
54.04000,45.03337,31.60464,0.39159,3.51163,45.03337
54.11000,45.09162,31.65999,0.39210,3.51778,45.09162
54.18000,45.14999,31.80076,0.39261,3.53342,45.14999
54.25000,45.20837,31.68365,0.39312,3.52041,45.20837
54.32000,45.26662,31.51770,0.39362,3.50197,45.26662
54.39000,45.32500,31.72685,0.39413,3.52521,45.32500
54.46000,45.38337,31.84059,0.39464,3.53784,45.38337
54.53000,45.44168,31.81487,0.39515,3.53499,45.44168
54.60000,45.49993,31.99963,0.39565,3.55551,45.49993
54.67000,45.55831,31.89569,0.39616,3.54397,45.55831
54.74000,45.61668,32.01325,0.39667,3.55703,45.61668
54.81000,45.67499,32.05356,0.39717,3.56151,45.67499
54.88000,45.73331,31.92822,0.39768,3.54758,45.73331
54.95000,45.79168,31.89045,0.39819,3.54338,45.79168
55.02000,45.84999,31.88232,0.39870,3.54248,45.84999
55.09000,45.90830,31.95207,0.39920,3.55023,45.90830
55.16000,45.96668,31.97313,0.39971,3.55257,45.96668
55.23000,46.02499,32.17087,0.40022,3.57454,46.02499
55.30000,46.08330,32.07374,0.40072,3.56375,46.08330
55.37000,46.14162,32.07306,0.40123,3.56367,46.14162
55.44000,46.19993,32.10249,0.40174,3.56694,46.19993
55.51000,46.25831,32.23724,0.40225,3.58192,46.25831
55.58000,46.31662,32.12855,0.40275,3.56984,46.31662
55.65000,46.37506,32.09632,0.40326,3.56626,46.37506
55.72000,46.43331,32.25747,0.40377,3.58416,46.43331
55.79000,46.49162,32.35936,0.40427,3.59548,46.49162
55.86000,46.54999,32.41701,0.40478,3.60189,46.54999
55.93000,46.60837,32.28388,0.40529,3.58710,46.60837
56.00000,46.66668,32.26805,0.40580,3.58534,46.66668
56.07000,46.72505,32.38659,0.40630,3.59851,46.72505
56.14000,46.78337,32.50680,0.40681,3.61187,46.78337
56.21000,46.84168,32.39389,0.40732,3.59932,46.84168
56.28000,46.90005,32.25116,0.40783,3.58346,46.90005
56.35000,46.95836,32.35005,0.40833,3.59445,46.95836
56.42000,47.01662,32.45086,0.40884,3.60565,47.01662
56.49000,47.07493,32.29401,0.40935,3.58822,47.07493
56.56000,47.13336,32.68156,0.40986,3.63128,47.13336
56.63000,47.19162,32.45933,0.41036,3.60659,47.19162
56.70000,47.24999,32.38008,0.41087,3.59779,47.24999
56.77000,47.30830,32.69386,0.41138,3.63265,47.30830
56.84000,47.36668,32.63714,0.41188,3.62635,47.36668
56.91000,47.42505,32.52438,0.41239,3.61382,47.42505
56.98000,47.48337,32.53770,0.41290,3.61530,47.48337
57.05000,47.54168,32.63826,0.41341,3.62647,47.54168
57.12000,47.59999,32.73956,0.41391,3.63773,47.59999
57.19000,47.65843,32.71967,0.41442,3.63552,47.65843
57.26000,47.71668,32.67044,0.41493,3.63005,47.71668
57.33000,47.77493,32.42299,0.41543,3.60255,47.77493
57.40000,47.83324,32.68715,0.41594,3.63191,47.83324
57.47000,47.89168,32.44924,0.41645,3.60547,47.89168
57.54000,47.94999,32.50626,0.41696,3.61181,47.94999
57.61000,48.00831,32.76513,0.41746,3.64057,48.00831
57.68000,48.06655,31.66934,0.41797,3.51882,48.06655
57.75000,48.12500,-1.56672,0.41848,-0.17408,48.12500
57.82000,48.18337,-0.31113,0.41899,-0.03457,48.18337
57.89000,48.24175,0.10024,0.41949,0.01114,48.24175
57.96000,48.30006,-0.12255,0.42000,-0.01362,48.30006
58.03000,48.35831,-0.08349,0.42051,-0.00928,48.35831
58.10000,48.41674,-0.10470,0.42102,-0.01163,48.41674
58.17000,48.47506,-0.19914,0.42152,-0.02213,48.47506
58.24000,48.53337,-0.27418,0.42203,-0.03046,48.53337
58.31000,48.59168,-0.16321,0.42254,-0.01813,48.59168
58.38000,48.64999,0.11024,0.42304,0.01225,48.64999
58.45000,48.70825,-0.24452,0.42355,-0.02717,48.70825
58.52000,48.76662,-0.17954,0.42406,-0.01995,48.76662
58.59000,48.82493,-0.02958,0.42456,-0.00329,48.82493
58.66000,48.88324,-0.04374,0.42507,-0.00486,48.88324
58.73000,48.94168,-0.03870,0.42558,-0.00430,48.94168
58.80000,48.99999,-0.02481,0.42609,-0.00276,48.99999
58.87000,49.05831,-0.32899,0.42659,-0.03655,49.05831
58.94000,49.11668,-0.06561,0.42710,-0.00729,49.11668
59.01000,49.17506,0.15006,0.42761,0.01667,49.17506
59.08000,49.23337,-0.06164,0.42812,-0.00685,49.23337
59.15000,49.29168,-0.04972,0.42862,-0.00552,49.29168
59.22000,49.34999,-0.07685,0.42913,-0.00854,49.34999
59.29000,49.40837,-0.12221,0.42964,-0.01358,49.40837
59.36000,49.46662,-0.23137,0.43014,-0.02571,49.46662
59.43000,49.52499,-0.18613,0.43065,-0.02068,49.52499
59.50000,49.58337,-0.18128,0.43116,-0.02014,49.58337
59.57000,49.64162,0.03191,0.43167,0.00355,49.64162
59.64000,49.69993,-0.11582,0.43217,-0.01287,49.69993
59.71000,49.75831,-0.21016,0.43268,-0.02335,49.75831
59.78000,49.81656,-0.09696,0.43319,-0.01077,49.81656
59.85000,49.87493,-0.11266,0.43370,-0.01252,49.87493
59.92000,49.93331,-0.02878,0.43420,-0.00320,49.93331
59.99000,49.99174,-0.13181,0.43471,-0.01465,49.99174
60.06000,50.05006,-0.22093,0.43522,-0.02455,50.05006
60.13000,50.10843,-0.11658,0.43573,-0.01295,50.10843
60.20000,50.16681,0.06483,0.43623,0.00720,50.16681
60.27000,50.22505,-0.09245,0.43674,-0.01027,50.22505
60.34000,50.28337,-0.07308,0.43725,-0.00812,50.28337
60.41000,50.34168,-0.13578,0.43775,-0.01509,50.34168
60.48000,50.39999,-0.11158,0.43826,-0.01240,50.39999
60.55000,50.45831,-0.06008,0.43877,-0.00668,50.45831
60.62000,50.51662,-0.19152,0.43927,-0.02128,50.51662
60.69000,50.57487,-0.11023,0.43978,-0.01225,50.57487
60.69400,50.57824,-0.18998,0.43981,-0.02111,50.57824