File: NATR/NatR/RDSO NatR Tensile 50.is_tens_RawData/Specimen_RawData_9.csv
Time,Extension,Load
(sec),(mm),(N)
0.00000,0.00000,-0.03341
0.10000,0.07594,0.08374
0.20000,0.16475,0.70541
0.30000,0.24931,0.87901
0.40000,0.33300,1.49220
0.50000,0.41669,1.52664
0.60000,0.50006,1.85401
0.70000,0.58331,1.90708
0.80000,0.66675,2.30172
0.90000,0.75000,2.58724
1.00000,0.83319,2.62483
1.10000,0.91675,3.07528
1.20000,0.99987,3.10762
1.30000,1.08325,3.35105
1.40000,1.16681,3.67303
1.50000,1.25006,3.88741
1.60000,1.33331,3.97958
1.70000,1.41681,4.30694
1.80000,1.50000,4.37329
1.90000,1.58319,4.74196
2.00000,1.66669,4.71227
2.10000,1.75000,4.91743
2.20000,1.83325,4.97643
2.30000,1.91675,5.33202
2.40000,2.00000,5.55340
2.50000,2.08331,5.58986
2.60000,2.16681,5.75783
2.70000,2.25000,5.88430
2.80000,2.33325,6.13454
2.90000,2.41675,6.29056
3.00000,2.50000,6.28957
3.10000,2.58325,6.60920
3.20000,2.66675,6.76492
3.30000,2.75000,6.97871
3.40000,2.83325,7.04211
3.50000,2.91681,7.18539
3.60000,3.00000,7.41932
3.70000,3.08331,7.47650
3.80000,3.16675,7.63604
3.90000,3.24994,8.10198
4.00000,3.33325,8.10213
4.10000,3.41669,8.33507
4.20000,3.50000,8.28235
4.30000,3.58319,8.38236
4.40000,3.66675,8.76911
4.50000,3.75006,8.77495
4.60000,3.83325,9.06468
4.70000,3.91675,9.19884
4.80000,4.00000,9.26886
4.90000,4.08319,9.35099
5.00000,4.16675,9.42855
5.10000,4.25000,9.68767
5.20000,4.33325,9.68610
5.30000,4.41675,9.85255
5.40000,4.50000,10.02709
5.50000,4.58331,10.27508
5.60000,4.66675,10.38758
5.70000,4.75000,10.27704
5.80000,4.83325,10.60867
5.90000,4.91675,10.87086
6.00000,5.00000,10.86160
6.10000,5.08325,11.04222
6.20000,5.16669,11.13865
6.30000,5.24994,11.31250
6.40000,5.33325,11.41961
6.50000,5.41669,11.41163
6.60000,5.50000,11.64751
6.70000,5.58331,11.76070
6.80000,5.66675,11.75404
6.90000,5.75000,12.07504
7.00000,5.83325,12.18058
7.10000,5.91675,12.35007
7.20000,6.00000,12.26491
7.30000,6.08325,12.57552
7.40000,6.16681,12.81827
7.50000,6.25000,12.79288
7.60000,6.33319,12.64936
7.70000,6.41675,13.06616
7.80000,6.50000,12.81885
7.90000,6.58331,13.37755
8.00000,6.66669,13.56693
8.10000,6.75000,13.44527
8.20000,6.83331,13.79694
8.30000,6.91675,13.85329
8.40000,7.00000,14.03988
8.50000,7.08325,14.08888
8.60000,7.16675,14.14499
8.70000,7.25000,14.17649
8.80000,7.33325,14.54154
8.90000,7.41675,14.53223
9.00000,7.50000,14.71074
9.10000,7.58325,14.74112
9.20000,7.66675,14.87533
9.30000,7.75000,15.00170
9.40000,7.83319,15.05477
9.50000,7.91669,15.46906
9.60000,7.99994,15.46279
9.70000,8.08325,15.45196
9.80000,8.16687,15.46289
9.90000,8.25000,15.79128
10.00000,8.33325,15.78668
10.10000,8.41675,16.22307
10.20000,8.50000,16.05500
10.30000,8.58319,16.24654
10.40000,8.66675,16.12335
10.50000,8.75000,16.37320
10.60000,8.83319,16.49428
10.70000,8.91669,16.55886
10.80000,9.00000,16.67171
10.90000,9.08325,16.82797
11.00000,9.16681,16.89887
11.10000,9.25006,17.03730
11.20000,9.33331,17.10722
11.30000,9.41681,17.12888
11.40000,9.49987,17.20238
11.50000,9.58319,17.40720
11.60000,9.66669,17.47207
11.70000,9.75006,17.61991
11.80000,9.83325,17.55420
11.90000,9.91681,17.77818
12.00000,10.00006,17.85917
12.10000,10.08331,18.00294
12.20000,10.16675,17.95835
12.30000,10.25000,18.16390
12.40000,10.33325,18.24446
12.50000,10.41669,18.34050
12.60000,10.50000,18.41640
12.70000,10.58319,18.37598
12.80000,10.66675,18.60956
12.90000,10.74994,18.57394
13.00000,10.83319,18.60632
13.10000,10.91675,18.58677
13.20000,11.00000,18.71834
13.30000,11.08325,18.84040
13.40000,11.16675,19.13523
13.50000,11.25000,19.06369
13.60000,11.33331,19.11058
13.70000,11.41669,19.10843
13.80000,11.49994,19.55065
13.90000,11.58325,19.28522
14.00000,11.66675,19.28228
14.10000,11.75000,19.65365
14.20000,11.83331,19.78477
14.30000,11.91681,19.70529
14.40000,12.00000,19.74611
14.50000,12.08325,20.00973
14.60000,12.16669,20.07798
14.70000,12.25000,20.05574
14.80000,12.33319,20.08970
14.90000,12.41675,20.16810
15.00000,12.50006,20.12850
15.10000,12.58331,20.39291
15.20000,12.66675,20.47670
15.30000,12.75000,20.46175
15.40000,12.83325,20.39271
15.50000,12.91681,20.57783
15.60000,13.00000,20.76080
15.70000,13.08325,20.60395
15.80000,13.16675,20.65045
15.90000,13.25000,20.89658
16.00000,13.33319,20.65599
16.10000,13.41669,21.10973
16.20000,13.50000,21.05186
16.30000,13.58325,21.05734
16.40000,13.66675,21.24237
16.50000,13.75006,21.36844
16.60000,13.83331,21.40328
16.70000,13.91675,21.33022
16.80000,14.00000,21.53514
16.90000,14.08325,21.53044
17.00000,14.16675,21.48012
17.10000,14.25000,21.63638
17.20000,14.33325,21.61678
17.30000,14.41675,21.71061
17.40000,14.50006,21.78078
17.50000,14.58325,22.01500
17.60000,14.66675,22.04200
17.70000,14.75000,22.11829
17.80000,14.83331,22.21742
17.90000,14.91675,22.08551
18.00000,15.00000,22.04895
18.10000,15.08325,22.27871
18.20000,15.16669,22.30263
18.30000,15.24994,22.55370
18.40000,15.33325,22.54180
18.50000,15.41681,22.45825
18.60000,15.50006,22.53209
18.70000,15.58331,22.56453
18.80000,15.66675,22.78312
18.90000,15.75000,22.86279
19.00000,15.83318,22.99392
19.10000,15.91662,22.99725
19.20000,15.99994,22.89067
19.30000,16.08325,23.02263
19.40000,16.16675,23.12872
19.50000,16.25006,23.16042
19.60000,16.33331,23.16395
19.70000,16.41681,23.13126
19.80000,16.50000,23.16777
19.90000,16.58325,23.38386
20.00000,16.66681,23.41987
20.10000,16.75000,23.38263
20.20000,16.83325,23.39155
20.30000,16.91675,23.51400
20.40000,16.99993,23.43947
20.50000,17.08318,23.54531
20.60000,17.16675,23.61269
20.70000,17.25000,23.91918
20.80000,17.33331,23.60994
20.90000,17.41681,23.78399
21.00000,17.50000,23.95177
21.10000,17.58325,23.88959
21.20000,17.66675,23.99533
21.30000,17.75000,24.06667
21.40000,17.83318,24.03320
21.50000,17.91675,23.95402
21.60000,17.99993,24.02845
21.70000,18.08325,24.25375
21.80000,18.16681,24.17751
21.90000,18.25006,24.27394
22.00000,18.33325,24.38169
22.10000,18.41675,24.33137
22.20000,18.50000,24.38600
22.30000,18.58325,24.54261
22.40000,18.66675,24.61003
22.50000,18.75000,24.42241
22.60000,18.83325,24.66560
22.70000,18.91675,24.54256
22.80000,19.00000,24.65295
22.90000,19.08325,24.79427
23.00000,19.16675,24.81049
23.10000,19.25006,24.80681
23.20000,19.33325,24.81975
23.30000,19.41675,25.06416
23.40000,19.50000,24.92069
23.50000,19.58318,25.00712
23.60000,19.66675,25.15746
23.70000,19.75000,25.18382
23.80000,19.83325,24.94465
23.90000,19.91675,25.05681
24.00000,20.00006,25.15515
24.10000,20.08325,25.41167
24.20000,20.16675,25.28382
24.30000,20.25000,25.30725
24.40000,20.33325,25.32626
24.50000,20.41668,25.20111
24.60000,20.50000,25.43832
24.70000,20.58325,25.25536
24.80000,20.66675,25.52314
24.90000,20.75000,25.26790
25.00000,20.83331,25.59968
25.10000,20.91669,25.57057
25.20000,21.00000,25.64275
25.30000,21.08325,25.77431
25.40000,21.16675,25.85418
25.50000,21.25000,25.69650
25.60000,21.33325,25.79847
25.70000,21.41668,25.87898
25.80000,21.49994,25.91416
25.90000,21.58325,26.13598
26.00000,21.66675,26.15695
26.10000,21.75000,25.98790
26.20000,21.83331,26.11310
26.30000,21.91675,26.06729
26.40000,22.00000,26.22095
26.50000,22.08325,26.32600
26.60000,22.16668,26.35036
26.70000,22.24993,26.10271
26.80000,22.33325,26.35285
26.90000,22.41675,26.35594
27.00000,22.50000,26.35158
27.10000,22.58331,26.53930
27.20000,22.66675,26.60030
27.30000,22.75000,26.45889
27.40000,22.83325,26.59536
27.50000,22.91668,26.45997
27.60000,23.00000,26.74730
27.70000,23.08325,26.92983
27.80000,23.16675,26.90067
27.90000,23.25000,26.89440
28.00000,23.33325,26.89827
28.10000,23.41675,26.89891
28.20000,23.50000,27.07737
28.30000,23.58325,26.87951
28.40000,23.66675,27.13132
28.50000,23.75000,27.09589
28.60000,23.83325,27.15097
28.70000,23.91675,27.35877
28.80000,24.00000,27.32099
28.90000,24.08325,27.34574
29.00000,24.16675,27.21775
29.10000,24.25000,27.20878
29.20000,24.33325,27.50038
29.30000,24.41674,27.36852
29.40000,24.50000,27.30041
29.50000,24.58325,27.29208
29.60000,24.66675,27.42997
29.70000,24.75000,27.56212
29.80000,24.83325,27.56355
29.90000,24.91675,27.53468
30.00000,24.99999,27.74499
30.10000,25.08325,27.83353
30.20000,25.16675,27.74215
30.30000,25.25006,27.72554
30.40000,25.33325,27.92869
30.50000,25.41668,27.89228
30.60000,25.50000,27.92257
30.70000,25.58324,28.02115
30.80000,25.66668,28.18364
30.90000,25.75000,28.23616
31.00000,25.83318,27.91370
31.10000,25.91675,28.34980
31.20000,26.00000,28.19216
31.30000,26.08331,28.33328
31.40000,26.16681,28.34940
31.50000,26.25006,28.20451
31.60000,26.33325,28.52404
31.70000,26.41669,28.25719
31.80000,26.49993,28.29340
31.90000,26.58318,28.55246
32.00000,26.66675,28.69813
32.10000,26.75000,28.47259
32.20000,26.83331,28.48704
32.30000,26.91675,28.83215
32.40000,27.00000,28.79300
32.50000,27.08325,28.69583
32.60000,27.16674,28.92162
32.70000,27.25000,28.74150
32.80000,27.33325,28.90609
32.90000,27.41675,28.94005
33.00000,27.50000,29.15281
33.10000,27.58325,29.03168
33.20000,27.66668,29.12164
33.30000,27.74999,29.20303
33.40000,27.83325,29.13281
33.50000,27.91675,29.15472
33.60000,28.00006,29.09851
33.70000,28.08331,29.36091
33.80000,28.16681,29.31842
33.90000,28.25000,29.30706
34.00000,28.33324,29.44352
34.10000,28.41675,29.29559
34.20000,28.49993,29.35179
34.30000,28.58318,29.39663
34.40000,28.66675,29.62213
34.50000,28.75006,29.59498
34.60000,28.83331,29.57087
34.70000,28.91675,29.62982
34.80000,29.00000,29.74825
34.90000,29.08325,29.70106
35.00000,29.16675,29.84160
35.10000,29.25000,29.73904
35.20000,29.33325,29.80583
35.30000,29.41675,29.84752
35.40000,29.49993,30.02902
35.50000,29.58325,29.89466
35.60000,29.66675,30.10512
35.70000,29.75000,30.30092
35.80000,29.83331,30.13231
35.90000,29.91674,30.17955
36.00000,30.00006,30.17837
36.10000,30.08325,30.12962
36.20000,30.16662,30.28357
36.30000,30.24993,30.22977
36.40000,30.33318,30.36178
36.50000,30.41675,30.28710
36.60000,30.49999,30.30224
36.70000,30.58325,30.46198
36.80000,30.66675,30.49310
36.90000,30.75006,30.54038
37.00000,30.83325,30.63755
37.10000,30.91668,30.62966
37.20000,31.00000,30.72016
37.30000,31.08318,30.89994
37.40000,31.16668,30.64426
37.50000,31.25000,30.77896
37.60000,31.33325,30.81694
37.70000,31.41674,31.04239
37.80000,31.49999,30.91871
37.90000,31.58331,31.00882
38.00000,31.66674,31.07448
38.10000,31.74999,30.85418
38.20000,31.83324,31.18262
38.30000,31.91668,31.38837
38.40000,31.99999,31.07237
38.50000,32.08312,31.20761
38.60000,32.16668,31.16327
38.70000,32.24999,31.25186
38.80000,32.33331,31.36623
38.90000,32.41681,31.32198
39.00000,32.50006,31.51612
39.10000,32.58331,31.42307
39.20000,32.66674,31.42699
39.30000,32.74993,31.44512
39.40000,32.83324,31.62539
39.50000,32.91668,31.54380
39.60000,32.99993,31.58981
39.70000,33.08325,31.76254
39.80000,33.16681,31.85167
39.90000,33.25006,31.70060
40.00000,33.33325,31.75396
40.10000,33.41675,31.90199
40.20000,33.50006,31.80933
40.30000,33.58331,31.73147
40.40000,33.66675,31.76837
40.50000,33.74999,31.92321
40.60000,33.83324,32.03365
40.70000,33.91668,31.89092
40.80000,33.99993,31.95844
40.90000,34.08324,31.90983
41.00000,34.16675,32.01523
41.10000,34.25006,32.08476
41.20000,34.33324,32.11710
41.30000,34.41674,32.05517
41.40000,34.49999,31.86230
41.50000,34.58325,31.85657
41.60000,34.66674,30.97374
41.70000,34.75000,-0.77263
41.80000,34.83325,-0.01068
41.90000,34.91662,0.13323
42.00000,34.99999,0.10883
42.10000,35.08325,0.06963
42.20000,35.16681,-0.04733
42.30000,35.24999,-0.00397
42.40000,35.33325,-0.04228
42.50000,35.41674,0.07546
42.60000,35.50006,-0.06860
42.70000,35.58324,-0.10559
42.80000,35.66675,0.07541
42.90000,35.75000,0.12716
43.00000,35.83318,-0.08506
43.10000,35.91675,0.10001
43.20000,35.99999,0.04523
43.30000,36.08331,-0.02513
43.40000,36.16675,0.04224
43.50000,36.25000,-0.09790
43.54600,36.28831,0.00387