File: NR/NR/RDSO NR Tensile 50.is_tens_RawData/Specimen_RawData_5.csv
Time,Extension,Load
(sec),(mm),(N)
0.00000,0.00000,0.35909
0.20000,0.16469,0.62168
0.40000,0.33294,1.12295
0.60000,0.50000,1.31747
0.80000,0.66675,1.78474
1.00000,0.83325,1.94884
1.20000,0.99994,2.21275
1.40000,1.16681,2.48279
1.60000,1.33331,2.81956
1.80000,1.49994,3.04521
2.00000,1.66669,3.09333
2.20000,1.83331,3.67986
2.40000,2.00000,3.63899
2.60000,2.16681,3.83837
2.80000,2.33331,4.29936
3.00000,2.49994,4.49247
3.20000,2.66675,4.76677
3.40000,2.83325,4.93102
3.60000,3.00000,4.97673
3.80000,3.16675,5.25334
4.00000,3.33331,5.26794
4.20000,3.49994,5.73785
4.40000,3.66681,5.92772
4.60000,3.83331,6.02602
4.80000,3.99994,6.24132
5.00000,4.16669,6.30605
5.20000,4.33331,6.55482
5.40000,4.49994,6.69320
5.60000,4.66681,6.70765
5.80000,4.83325,7.14988
6.00000,5.00000,7.14150
6.20000,5.16669,7.39894
6.40000,5.33325,7.46147
6.60000,5.50000,7.60097
6.80000,5.66681,7.71783
7.00000,5.83325,7.72734
7.20000,5.99994,7.87312
7.40000,6.16675,8.08107
7.60000,6.33325,8.39114
7.80000,6.50000,8.31990
8.00000,6.66675,8.55137
8.20000,6.83331,8.57955
8.40000,6.99994,8.85448
8.60000,7.16675,8.83900
8.80000,7.33325,8.85850
9.00000,7.50006,9.04127
9.20000,7.66675,9.10512
9.40000,7.83319,9.51040
9.60000,7.99994,9.39123
9.80000,8.16681,9.46786
10.00000,8.33325,9.59419
10.20000,8.49994,9.70708
10.40000,8.66675,10.05160
10.60000,8.83325,10.12637
10.80000,8.99994,9.99108
11.00000,9.16675,10.20394
11.20000,9.33331,10.41508
11.40000,9.49994,10.34844
11.60000,9.66675,10.35079
11.80000,9.83325,10.69609
12.00000,10.00000,10.76087
12.20000,10.16675,10.73603
12.40000,10.33325,10.78640
12.60000,10.49994,10.83746
12.80000,10.66675,10.91831
13.00000,10.83325,10.88572
13.20000,11.00000,11.01812
13.40000,11.16669,11.14905
13.60000,11.33325,11.15939
13.80000,11.49994,11.34495
14.00000,11.66675,11.29948
14.20000,11.83331,11.57937
14.40000,12.00000,11.53041
14.60000,12.16669,11.59906
14.80000,12.33325,11.52370
15.00000,12.49994,11.82142
15.20000,12.66675,11.48421
15.40000,12.83325,11.83936
15.60000,12.99994,11.86273
15.80000,13.16675,11.92040
16.00000,13.33319,11.86038
16.20000,13.49994,11.96642
16.40000,13.66675,12.05422
16.60000,13.83325,11.99954
16.80000,13.99994,12.37669
17.00000,14.16675,12.19422
17.20000,14.33325,12.21107
17.40000,14.50000,12.39840
17.60000,14.66675,12.43505
17.80000,14.83325,12.54603
18.00000,15.00000,12.34073
18.20000,15.16675,12.51237
18.40000,15.33331,12.43882
18.60000,15.50000,12.57529
18.80000,15.66668,12.58509
19.00000,15.83318,12.57984
19.20000,15.99994,12.48900
19.40000,16.16675,12.83783
19.60000,16.33325,12.91706
19.80000,16.49993,12.87100
20.00000,16.66675,12.95827
20.20000,16.83325,13.05402
20.40000,16.99993,12.85723
20.60000,17.16675,12.82729
20.80000,17.33331,13.07332
21.00000,17.50000,12.95577
21.20000,17.66675,13.15549
21.40000,17.83318,13.01109
21.60000,18.00000,13.20131
21.80000,18.16681,13.12972
22.00000,18.33325,13.19259
22.20000,18.49993,13.21968
22.40000,18.66675,13.09601
22.60000,18.83331,13.22096
22.80000,18.99993,13.43357
23.00000,19.16675,13.19342
23.20000,19.33325,13.36732
23.40000,19.49994,13.39569
23.60000,19.66669,13.38227
23.80000,19.83325,13.37070
24.00000,20.00000,13.55156
24.20000,20.16675,13.49658
24.40000,20.33318,13.65539
24.60000,20.50000,13.58106
24.80000,20.66675,13.82454
25.00000,20.83331,13.54034
25.20000,20.99993,13.50589
25.40000,21.16668,13.82900
25.60000,21.33325,13.64040
25.80000,21.50000,13.73031
26.00000,21.66681,13.82101
26.20000,21.83331,13.87270
26.40000,21.99993,13.81567
26.60000,22.16675,13.96478
26.80000,22.33325,13.95150
27.00000,22.50000,14.12893
27.20000,22.66675,14.02627
27.40000,22.83325,14.25809
27.60000,22.99994,13.97311
27.80000,23.16675,13.91151
28.00000,23.33325,14.07145
28.20000,23.50000,14.13838
28.40000,23.66681,14.51602
28.60000,23.83331,14.33335
28.80000,24.00000,14.22105
29.00000,24.16662,14.17004
29.20000,24.33331,14.39323
29.40000,24.50000,14.22545
29.60000,24.66681,14.34658
29.80000,24.83318,14.42871
30.00000,24.99993,14.46957
30.20000,25.16681,14.40945
30.40000,25.33331,14.59580
30.60000,25.49987,14.58551
30.80000,25.66675,14.55527
31.00000,25.83325,14.59119
31.20000,26.00000,14.46462
31.40000,26.16681,14.71918
31.60000,26.33331,14.48721
31.80000,26.49993,14.55086
32.00000,26.66668,14.73633
32.20000,26.83325,14.88298
32.40000,27.00000,14.63166
32.60000,27.16674,14.69527
32.80000,27.33325,14.94428
33.00000,27.50000,14.88147
33.20000,27.66675,14.95678
33.40000,27.83325,14.97564
33.60000,28.00000,14.82673
33.80000,28.16675,15.01269
34.00000,28.33318,14.94717
34.20000,28.50000,15.04586
34.40000,28.66675,14.97363
34.60000,28.83331,14.88450
34.80000,29.00000,15.27513
35.00000,29.16675,15.11456
35.20000,29.33325,15.28302
35.40000,29.49993,15.13141
35.60000,29.66675,15.16958
35.80000,29.83331,15.34745
36.00000,30.00000,15.21310
36.20000,30.16675,15.27787
36.40000,30.33325,15.45261
36.60000,30.49993,15.33114
36.80000,30.66681,15.30585
37.00000,30.83325,15.43722
37.20000,30.99993,15.43546
37.40000,31.16675,15.56933
37.60000,31.33331,15.49107
37.80000,31.49999,15.53885
38.00000,31.66681,15.51180
38.20000,31.83324,15.59804
38.40000,31.99999,15.70334
38.60000,32.16675,15.68247
38.80000,32.33337,15.60255
39.00000,32.50000,15.63547
39.20000,32.66668,15.64616
39.40000,32.83324,15.66218
39.60000,33.00000,15.41527
39.80000,33.16681,15.82251
40.00000,33.33325,15.86911
40.20000,33.49999,15.69854
40.40000,33.66675,15.80815
40.60000,33.83331,16.09191
40.80000,33.99993,16.10514
41.00000,34.16675,15.82947
41.20000,34.33331,16.11935
41.40000,34.49999,15.90448
41.60000,34.66668,16.05859
41.80000,34.83331,16.04198
42.00000,34.99999,16.16139
42.20000,35.16681,16.07113
42.40000,35.33318,16.02600
42.60000,35.49999,16.27777
42.80000,35.66675,16.18809
43.00000,35.83324,16.32980
43.20000,35.99999,16.26919
43.40000,36.16681,16.16987
43.60000,36.33325,16.25469
43.80000,36.50000,16.49400
44.00000,36.66674,16.65203
44.20000,36.83325,16.60332
44.40000,36.99999,16.41496
44.60000,37.16668,16.58818
44.80000,37.33324,16.50659
45.00000,37.49999,16.45211
45.20000,37.66675,16.46215
45.40000,37.83325,16.39321
45.60000,38.00000,16.67506
45.80000,38.16668,16.61562
46.00000,38.33324,16.71416
46.20000,38.49993,16.72881
46.40000,38.66687,16.83171
46.60000,38.83331,16.71318
46.80000,38.99993,16.74429
47.00000,39.16674,16.77982
47.20000,39.33331,16.88855
47.40000,39.49999,16.88419
47.60000,39.66675,16.95127
47.80000,39.83324,16.89394
48.00000,39.99993,17.01423
48.20000,40.16674,17.00037
48.40000,40.33324,16.86650
48.60000,40.49993,17.11699
48.80000,40.66675,16.95901
49.00000,40.83325,17.22885
49.20000,40.99993,17.20298
49.40000,41.16674,17.13546
49.60000,41.33331,17.22116
49.80000,41.50006,17.15555
50.00000,41.66668,17.36468
50.20000,41.83325,17.32401
50.40000,41.99993,17.24105
50.60000,42.16681,17.36737
50.80000,42.33324,17.49051
51.00000,42.49993,17.32210
51.20000,42.66674,17.37703
51.40000,42.83324,17.51143
51.60000,42.99999,17.62364
51.80000,43.16681,17.43382
52.00000,43.33324,17.61360
52.20000,43.50000,17.82988
52.40000,43.66674,17.69842
52.60000,43.83324,17.65427
52.80000,44.00000,17.63369
53.00000,44.16674,17.84419
53.20000,44.33331,17.76050
53.40000,44.49993,17.84870
53.60000,44.66674,17.80489
53.80000,44.83324,17.81646
54.00000,44.99999,17.82768
54.20000,45.16675,17.90500
54.40000,45.33324,17.79475
54.60000,45.49993,18.07390
54.80000,45.66681,18.11433
55.00000,45.83324,18.17695
55.20000,45.99999,18.02681
55.40000,46.16668,18.03598
55.60000,46.33325,18.27828
55.80000,46.49993,18.06302
56.00000,46.66674,18.13089
56.20000,46.83331,18.21747
56.40000,46.99999,18.20356
56.60000,47.16674,18.19925
56.80000,47.33324,18.41788
57.00000,47.49993,18.47805
57.20000,47.66674,18.47467
57.40000,47.83330,18.35443
57.60000,47.99993,18.37275
57.80000,48.16674,18.44802
58.00000,48.33324,18.53377
58.20000,48.49999,18.40147
58.40000,48.66675,18.42842
58.60000,48.83324,18.51608
58.80000,48.99993,18.62162
59.00000,49.16681,18.72095
59.20000,49.33331,18.80400
59.40000,49.50000,18.73761
59.60000,49.66668,18.83144
59.80000,49.83330,18.82032
60.00000,49.99999,18.70478
60.20000,50.16681,18.88735
60.40000,50.33324,18.87368
60.60000,50.49993,18.86182
60.80000,50.66680,19.02009
61.00000,50.83318,18.80885
61.20000,50.99993,19.10932
61.40000,51.16674,19.04400
61.60000,51.33331,18.87755
61.80000,51.49993,19.20854
62.00000,51.66674,19.21604
62.20000,51.83324,18.95894
62.40000,51.99999,19.23731
62.60000,52.16674,19.14230
62.80000,52.33324,19.28851
63.00000,52.49993,19.34711
63.20000,52.66674,19.41831
63.40000,52.83324,19.41444
63.60000,53.00005,19.32208
63.80000,53.16674,19.47863
64.00000,53.33324,19.35275
64.20000,53.49993,19.36696
64.40000,53.66674,19.65180
64.60001,53.83330,19.60490
64.80000,53.99993,19.43703
65.00000,54.16675,19.68659
65.20000,54.33324,19.31051
65.40000,54.49999,19.72020
65.60001,54.66674,19.64175
65.80000,54.83324,19.76974
66.00000,55.00000,19.70060
66.20001,55.16674,19.64597
66.40000,55.33325,19.68208
66.60001,55.49999,19.83212
66.80000,55.66674,19.87553
67.00000,55.83324,19.90816
67.20001,55.99987,19.99627
67.40000,56.16674,19.86602
67.60001,56.33330,19.95623
67.80000,56.49999,19.98558
68.00000,56.66674,20.10965
68.20001,56.83324,20.10166
68.40000,56.99993,20.00719
68.60001,57.16668,20.13538
68.80000,57.33324,20.04948
69.00000,57.49993,20.13631
69.20001,57.66674,20.31143
69.40000,57.83318,20.29913
69.60001,57.99993,20.29923
69.80000,58.16674,20.29869
70.00000,58.33331,20.43104
70.20001,58.49999,20.47147
70.40000,58.66680,20.46617
70.60001,58.83324,20.14998
70.80000,58.99993,20.47411
71.00000,59.16681,20.57750
71.20001,59.33330,20.59588
71.40000,59.49993,20.58980
71.60001,59.66668,20.45843
71.80000,59.83324,20.55947
72.00000,59.99999,20.76115
72.20001,60.16674,20.73802
72.40000,60.33324,20.64757
72.60001,60.50000,20.80163
72.80000,60.66668,20.79937
73.00000,60.83325,20.65997
73.20001,60.99993,20.78335
73.40000,61.16674,20.82995
73.60001,61.33324,20.83691
73.80000,61.49999,21.08362
74.00000,61.66674,20.96318
74.20001,61.83330,21.01776
74.40000,61.99993,21.04339
74.60001,62.16674,20.87292
74.80000,62.33318,21.07803
75.00000,62.49999,21.00924
75.20001,62.66681,21.13492
75.40000,62.83324,21.11621
75.60001,62.99999,21.14879
75.80000,63.16674,21.04736
76.00000,63.33324,21.19171
76.20001,63.49999,21.40006
76.40000,63.66680,21.54050
76.60001,63.83324,21.26242
76.80000,63.99999,21.20318
77.00000,64.16674,21.35145
77.20001,64.33324,21.60630
77.40000,64.49999,21.46783
77.60001,64.66680,21.62159
77.80000,64.83324,21.58974
78.00000,64.99999,21.75144
78.20001,65.16674,21.35390
78.40000,65.33330,21.57612
78.60001,65.49993,21.51521
78.80000,65.66674,21.74247
79.00000,65.83318,21.87198
79.20001,65.99993,21.77060
79.40000,66.16674,21.84655
79.60001,66.33330,21.68588
79.80000,66.49998,22.04191
80.00000,66.66674,21.74625
80.20001,66.83324,21.59606
80.40000,66.99993,21.99404
80.60001,67.16674,21.89021
80.80000,67.33330,21.94068
81.00001,67.49993,21.96758
81.20001,67.66674,21.95244
81.40000,67.83324,22.09655
81.60001,67.99999,22.18279
81.80000,68.16680,22.18411
82.00001,68.33324,22.33258
82.20001,68.49999,22.36962
82.40000,68.66667,22.43950
82.60001,68.83324,22.07557
82.80000,68.99999,22.27344
83.00001,69.16680,22.35536
83.20001,69.33324,22.32591
83.40000,69.49992,22.42092
83.60001,69.66668,22.45376
83.80000,69.83330,22.45998
84.00001,69.99999,22.57145
84.20001,70.16674,22.53573
84.40000,70.33318,22.62305
84.60001,70.49993,22.59536
84.80000,70.66680,22.79171
85.00001,70.83324,22.54666
85.20001,70.99999,22.58885
85.40000,71.16674,22.74864
85.60001,71.33324,22.70723
85.80000,71.49993,22.81096
86.00001,71.66680,22.74937
86.20001,71.83324,22.71987
86.40000,71.99999,22.84144
86.60001,72.16674,23.04185
86.80000,72.33324,22.97413
87.00001,72.49999,22.90710
87.20001,72.66680,23.15293
87.40000,72.83324,23.00544
87.60001,72.99993,23.12662
87.80000,73.16674,23.08551
88.00001,73.33330,23.15774
88.20001,73.49999,23.05165
88.40000,73.66681,23.34472
88.60001,73.83330,23.34433
88.80000,73.99993,23.26661
89.00001,74.16674,23.36594
89.20001,74.33324,23.44100
89.40000,74.49999,23.20732
89.60001,74.66668,23.37226
89.80000,74.83324,23.47251
90.00001,74.99993,23.61324
90.20001,75.16680,23.44586
90.40000,75.33330,23.69776
90.60001,75.49999,23.70168
90.80000,75.66668,23.65602
91.00001,75.83318,23.56213
91.20001,75.99992,23.41121
91.40000,76.16680,23.72746
91.60001,76.33324,23.73878
91.80000,76.49993,23.69967
92.00001,76.66674,23.76509
92.20001,76.83330,23.85588
92.40000,76.99999,23.98020
92.60001,77.16680,24.01945
92.80000,77.33324,23.82869
93.00001,77.49993,23.87960
93.20001,77.66674,23.88974
93.40000,77.83324,24.04375
93.60001,77.99999,23.90846
93.80000,78.16673,23.90052
94.00001,78.33323,24.02699
94.20001,78.49992,24.12685
94.40000,78.66674,24.24147
94.60001,78.83323,24.29497
94.80000,78.99993,24.07746
95.00001,79.16674,24.35980
95.20001,79.33323,24.16272
95.40000,79.49992,24.25700
95.60001,79.66680,24.42884
95.80000,79.83324,24.29953
96.00001,79.99999,24.38685
96.20001,80.16674,24.34103
96.40000,80.33324,24.18933
96.60001,80.49999,24.29581
96.80000,80.66680,24.41115
97.00001,80.83324,24.59867
97.20001,80.99993,24.64174
97.40000,81.16674,24.79511
97.60001,81.33323,24.64591
97.80000,81.49998,24.84357
98.00001,81.66674,24.70393
98.20001,81.83330,24.64287
98.40000,81.99993,24.96357
98.60001,82.16674,24.88900
98.80000,82.33324,24.86219
99.00001,82.49999,24.77963
99.20001,82.66667,24.81065
99.40000,82.83324,24.83466
99.60001,82.99992,25.08313
99.80000,83.16680,25.02233
100.00001,83.33330,24.99910
100.20001,83.49999,25.18344
100.40000,83.66674,25.30030
100.60001,83.83323,25.08696
100.80000,83.99999,25.01400
101.00001,84.16673,25.02365
101.20001,84.33324,25.23170
101.40000,84.49992,25.17736
101.60001,84.66673,25.19392
101.80000,84.83318,25.38728
102.00001,84.99992,25.20460
102.20001,85.16680,25.37566
102.40000,85.33323,25.41511
102.60001,85.49993,25.50835
102.80000,85.66674,25.53575
103.00001,85.83323,25.47268
103.20001,85.99998,25.55196
103.40000,86.16674,25.55246
103.60001,86.33324,25.56368
103.80000,86.49993,25.43255
104.00001,86.66674,25.80054
104.20001,86.83329,25.71430
104.40000,86.99992,25.72596
104.60001,87.16674,25.59322
104.80000,87.33324,25.85557
105.00001,87.49993,25.87786
105.20001,87.66674,25.93338
105.40000,87.83324,25.77982
105.60001,87.99993,25.74174
105.80000,88.16673,26.03599
106.00001,88.33324,26.02334
106.20001,88.49998,26.04481
106.40000,88.66673,26.01913
106.60001,88.83330,26.03912
106.80000,88.99992,25.94715
107.00001,89.16680,26.08170
107.20001,89.33323,26.10816
107.40000,89.49999,26.05882
107.60001,89.66674,26.17759
107.80000,89.83323,26.23174
108.00001,89.99986,26.39045
108.20001,90.16674,26.26565
108.40000,90.33323,26.50477
108.60001,90.49999,26.20146
108.80000,90.66674,26.48100
109.00001,90.83324,26.39697
109.20001,90.99992,26.56288
109.40000,91.16674,26.42676
109.60001,91.33330,26.28824
109.80000,91.49999,26.72419
110.00001,91.66680,26.56244
110.20001,91.83324,26.64608
110.40000,91.99993,26.50276
110.60001,92.16674,26.63736
110.80000,92.33336,26.81131
111.00001,92.49998,26.83086
111.20001,92.66668,27.00339
111.40000,92.83324,26.93837
111.60001,93.00006,26.93391
111.80000,93.16674,27.06160
112.00001,93.33324,26.95223
112.20001,93.49992,27.01206
112.40000,93.66673,26.98452
112.60001,93.83324,27.06547
112.80000,93.99992,27.14402
113.00001,94.16673,27.02294
113.20001,94.33329,27.30004
113.40001,94.49992,26.98727
113.60001,94.66674,27.42640
113.80000,94.83330,27.17141
114.00001,94.99999,27.32194
114.20001,95.16673,27.42190
114.40001,95.33317,27.34614
114.60001,95.49998,27.46507
114.80000,95.66673,27.40210
115.00001,95.83324,27.46830
115.20001,95.99992,27.46237
115.40001,96.16673,27.70286
115.60001,96.33318,27.54827
115.80000,96.49992,27.65318
116.00001,96.66674,27.61050
116.20001,96.83330,27.81561
116.40001,96.99993,27.78411
116.60001,97.16674,27.70369
116.80000,97.33323,27.66371
117.00001,97.49998,27.88411
117.20001,97.66679,27.76544
117.40001,97.83324,27.87000
117.60001,97.99998,27.62569
117.80000,98.16674,27.94894
118.00001,98.33324,27.83903
118.20001,98.49992,27.90303
118.40001,98.66673,27.93042
118.60001,98.83317,28.06546
118.80000,98.99992,28.15278
119.00001,99.16673,28.23848
119.20001,99.33330,28.19163
119.40001,99.49992,28.26097
119.60001,99.66673,28.20732
119.80000,99.83324,28.20261
120.00001,99.99998,28.51891
120.20001,100.16680,28.40787
120.40001,100.33330,28.32599
120.60001,100.49986,28.49455
120.80000,100.66673,28.54037
121.00001,100.83323,28.41076
121.20001,100.99992,28.41042
121.40001,101.16674,28.62146
121.60001,101.33323,28.51866
121.80000,101.49992,28.44222
122.00001,101.66674,28.67105
122.20001,101.83323,28.56217
122.40001,101.99992,28.55267
122.60001,102.16679,28.90037
122.80000,102.33324,28.68423
123.00001,102.49992,28.66488
123.20001,102.66673,28.82217
123.40001,102.83330,28.73402
123.60001,102.99998,28.85401
123.80000,103.16680,28.76410
124.00001,103.33324,28.81099
124.20001,103.49993,29.03047
124.40001,103.66674,28.94290
124.60001,103.83330,29.07084
124.80000,103.99998,29.05717
125.00001,104.16673,29.20187
125.20001,104.33324,29.15189
125.40001,104.49998,29.15086
125.60001,104.66673,29.39345
125.80000,104.83329,29.20515
126.00001,104.99999,29.20314
126.20001,105.16667,29.33583
126.40001,105.33324,29.41556
126.60001,105.49992,29.31461
126.80000,105.66674,29.37356
127.00001,105.83323,29.53374
127.20001,105.99992,29.44804
127.40001,106.16673,29.30771
127.60001,106.33330,29.53100
127.80000,106.49998,29.66281
128.00000,106.66680,29.66251
128.20002,106.83317,29.70730
128.40001,106.99992,29.73753
128.60001,107.16673,29.60376
128.80000,107.33323,29.77168
129.00000,107.49999,29.71852
129.20002,107.66674,29.84876
129.40001,107.83323,29.71597
129.60001,107.99998,29.87179
129.80000,108.16674,29.82686
130.00000,108.33330,29.79516
130.20002,108.49998,29.91727
130.40001,108.66679,30.01688
130.60001,108.83324,30.04050
130.80000,108.99986,30.09205
131.00000,109.16680,30.24267
131.20002,109.33329,30.15040
131.40002,109.49999,30.11155
131.60000,109.66667,30.35885
131.80000,109.83324,30.02697
132.00000,109.99999,30.23116
132.20002,110.16673,30.45739
132.40002,110.33317,30.39727
132.60000,110.49998,30.28457
132.80000,110.66673,30.54206
133.00000,110.83324,30.26477
133.20002,110.99992,30.36140
133.40002,111.16680,30.46494
133.60000,111.33323,30.48356
133.80000,111.49986,30.59185
134.00000,111.66673,30.57464
134.20002,111.83336,30.53549
134.40002,111.99992,30.67946
134.60000,112.16674,30.78191
134.80000,112.33323,30.74786
135.00000,112.49999,30.83170
135.20002,112.66680,30.65667
135.40002,112.83323,31.05681
135.60000,112.99998,30.82954
135.80000,113.16667,30.90138
136.00000,113.33324,30.82126
136.20002,113.49998,31.01060
136.40002,113.66680,30.84978
136.60000,113.83324,30.80842
136.80000,113.99992,31.00413
137.00000,114.16674,31.00776
137.20002,114.33329,31.14344
137.40002,114.49993,31.21115
137.60000,114.66674,31.10267
137.80000,114.83323,31.21169
138.00000,114.99998,31.32728
138.20002,115.16673,31.28103
138.40002,115.33324,31.39089
138.60000,115.49998,31.17578
138.80000,115.66673,31.41921
139.00000,115.83324,31.49055
139.20002,115.99992,31.32919
139.40002,116.16673,31.53103
139.60000,116.33324,31.61545
139.80000,116.49992,31.62569
140.00000,116.66667,31.66332
140.20002,116.83323,31.64921
140.40002,116.99992,31.69366
140.60000,117.16680,31.79298
140.80000,117.33330,31.63525
141.00000,117.49987,31.87010
141.20002,117.66673,31.74467
141.40002,117.83330,31.96222
141.60000,118.00005,31.75045
141.80000,118.16673,31.91288
142.00000,118.33330,31.99873
142.20002,118.49998,32.01686
142.40002,118.66674,31.88784
142.60000,118.83317,32.18978
142.80000,118.99998,32.00819
143.00000,119.16674,32.06659
143.20002,119.33330,32.12201
143.40002,119.49993,32.13632
143.60000,119.66674,32.24902
143.80000,119.83329,32.28964
144.00000,119.99998,32.48868
144.20002,120.16667,32.28592
144.40002,120.33324,32.32316
144.60000,120.49992,32.34491
144.80000,120.66680,32.35991
145.00000,120.83324,32.48040
145.20002,120.99992,32.41763
145.40002,121.16673,32.83462
145.60000,121.33324,32.49995
145.80000,121.49992,32.69291
146.00000,121.66680,32.72157
146.20002,121.83330,32.66047
146.40002,121.99992,32.70153
146.60000,122.16673,32.86323
146.80000,122.33323,32.71682
147.00000,122.50005,32.87509
147.20002,122.66673,32.91302
147.40002,122.83330,32.82795
147.60000,122.99992,32.76915
147.80000,123.16667,33.10593
148.00000,123.33323,32.95815
148.20002,123.49999,32.87720
148.40002,123.66674,33.09804
148.60000,123.83323,33.20074
148.80000,123.99992,33.12568
149.00000,124.16679,33.26738
149.20002,124.33324,33.23583
149.40002,124.49998,33.34691
149.60000,124.66673,33.26871
149.80000,124.83324,33.25582
150.00000,124.99992,33.49842
150.20002,125.16673,33.43065
150.40002,125.33324,33.35000
150.60000,125.49992,33.24891
150.80000,125.66673,33.49719
151.00000,125.83317,33.53434
151.20002,125.99992,33.65370
151.40002,126.16679,33.70515
151.60000,126.33330,33.85484
151.80000,126.49992,33.56006
152.00000,126.66672,33.68016
152.20002,126.83329,33.62841
152.40002,127.00004,33.92579
152.60000,127.16673,33.97543
152.80000,127.33323,33.72455
153.00000,127.49991,33.79168
153.20002,127.66673,33.96367
153.40002,127.83329,33.83162
153.60000,127.99998,33.98641
153.80000,128.16672,33.90771
154.00000,128.33322,33.99807
154.20002,128.49991,33.97519
154.40002,128.66679,34.13272
154.60000,128.83330,34.15614
154.80000,128.99992,34.17060
155.00000,129.16672,34.14164
155.20002,129.33323,34.27296
155.40002,129.49991,34.07627
155.60000,129.66673,34.30873
155.80000,129.83330,34.27374
156.00000,129.99998,34.55059
156.20002,130.16673,34.52105
156.40002,130.33323,34.43157
156.60000,130.49997,34.34582
156.80000,130.66674,34.42079
157.00000,130.83328,34.60023
157.20002,130.99991,34.66505
157.40002,131.16673,34.69999
157.60000,131.33324,34.72150
157.80000,131.49992,34.60973
158.00000,131.66673,34.74757
158.20002,131.83328,34.77119
158.40002,131.99992,34.65883
158.60000,132.16673,34.73762
158.80000,132.33329,34.79520
159.00000,132.49998,34.90491
159.20002,132.66672,34.84116
159.40002,132.83323,34.97297
159.60000,132.99997,34.86424
159.80000,133.16679,34.85449
160.00000,133.33330,35.14462
160.20002,133.49992,35.09165
160.40002,133.66672,35.16368
160.60000,133.83317,35.14560
160.80000,133.99998,35.22184
161.00002,134.16680,35.10747
161.20002,134.33329,35.11130
161.40002,134.49991,35.36953
161.60000,134.66673,35.17671
161.80000,134.83330,35.30999
162.00002,134.99998,35.42544
162.20002,135.16674,35.23801
162.40002,135.33323,35.26212
162.60000,135.49998,35.42088
162.80000,135.66673,35.46199
163.00002,135.83324,35.45890
163.20002,135.99998,35.32748
163.40002,136.16680,35.34914
163.60000,136.33323,35.29436
163.80000,136.49992,35.48281
164.00002,136.66674,35.28505
164.20002,136.83336,35.46027
164.40002,136.99993,35.26986
164.60000,137.16673,35.26330
164.80000,137.33323,35.15892
165.00002,137.49997,34.80392
165.20002,137.66673,0.01663
165.40002,137.83328,-0.05878
165.60000,137.99998,-0.11763
165.80000,138.16672,-0.00866
166.00002,138.33317,-0.08451
166.20002,138.49998,0.05857
166.40002,138.66673,0.10546
166.60000,138.83329,-0.17437
166.80000,138.99991,0.22282
167.00002,139.16673,0.02300
167.20002,139.33323,0.15775
167.40002,139.49998,0.03907
167.60000,139.66672,0.12742
167.80000,139.83329,0.10326
167.99600,139.99660,-0.09088