File: NR/NR/RDSO NR Tensile 50.is_tens_RawData/Specimen_RawData_4.csv
Time,Extension,Load
(sec),(mm),(N)
0.00000,0.00000,0.10630
0.10000,0.07569,0.42720
0.20000,0.16469,0.53519
0.30000,0.24931,0.79327
0.40000,0.33294,0.97972
0.50000,0.41675,1.27970
0.60000,0.50000,1.33825
0.70000,0.58331,1.47697
0.80000,0.66675,1.68110
0.90000,0.74994,1.84942
1.00000,0.83325,1.85123
1.10000,0.91675,1.98745
1.20000,0.99994,2.20359
1.30000,1.08331,2.21765
1.40000,1.16681,2.37607
1.50000,1.24994,2.68075
1.60000,1.33325,2.64003
1.70000,1.41675,2.71387
1.80000,1.49994,2.90169
1.90000,1.58325,2.99596
2.00000,1.66669,3.07476
2.10000,1.75006,3.33000
2.20000,1.83331,3.26791
2.30000,1.91675,3.59435
2.40000,2.00000,3.59420
2.50000,2.08331,3.90834
2.60000,2.16681,3.84449
2.70000,2.25000,4.02496
2.80000,2.33331,3.98434
2.90000,2.41675,4.23194
3.00000,2.49994,4.12345
3.10000,2.58325,4.31837
3.20000,2.66669,4.36174
3.30000,2.75000,4.58660
3.40000,2.83325,4.83042
3.50000,2.91675,4.76300
3.60000,3.00000,4.92563
3.70000,3.08331,5.03034
3.80000,3.16675,4.88177
3.90000,3.24987,5.22178
4.00000,3.33331,5.08723
4.10000,3.41675,5.39078
4.20000,3.49994,5.40725
4.30000,3.58325,5.78063
4.40000,3.66681,5.58610
4.50000,3.75000,5.69277
4.60000,3.83331,5.94282
4.70000,3.91681,5.85212
4.80000,3.99994,6.08090
4.90000,4.08331,6.04542
5.00000,4.16669,6.24436
5.10000,4.24994,6.19663
5.20000,4.33331,6.42639
5.30000,4.41675,6.43757
5.40000,4.49994,6.55056
5.50000,4.58325,6.69545
5.60000,4.66681,6.63905
5.70000,4.74994,6.71358
5.80000,4.83325,6.64170
5.90000,4.91681,6.86391
6.00000,5.00000,7.25395
6.10000,5.08319,7.12793
6.20000,5.16669,7.23671
6.30000,5.24994,7.07907
6.40000,5.33325,7.24788
6.50000,5.41675,7.38018
6.60000,5.50000,7.52218
6.70000,5.58331,7.53428
6.80000,5.66681,7.66114
6.90000,5.74994,7.59259
7.00000,5.83325,7.92358
7.10000,5.91675,7.69108
7.20000,5.99994,7.75850
7.30000,6.08325,7.98905
7.40000,6.16675,8.08122
7.50000,6.25000,8.11606
7.60000,6.33325,7.97753
7.70000,6.41669,8.12571
7.80000,6.50000,8.25468
7.90000,6.58331,8.34361
8.00000,6.66675,8.29040
8.10000,6.75000,8.35674
8.20000,6.83331,8.47753
8.30000,6.91681,8.53290
8.40000,6.99994,8.68396
8.50000,7.08325,8.71180
8.60000,7.16675,8.72238
8.70000,7.24994,8.76922
8.80000,7.33325,9.09801
8.90000,7.41681,8.96390
9.00000,7.50006,9.16799
9.10000,7.58331,8.95910
9.20000,7.66675,9.26025
9.30000,7.74994,9.18396
9.40000,7.83319,9.34718
9.50000,7.91669,9.10855
9.60000,7.99994,9.36619
9.70000,8.08331,9.40990
9.80000,8.16687,9.48560
9.90000,8.25000,9.46115
10.00000,8.33325,9.64294
10.10000,8.41681,9.50741
10.20000,8.49994,9.55788
10.30000,8.58325,9.58684
10.40000,8.66675,9.53460
10.50000,8.74994,9.88363
10.60000,8.83325,9.81885
10.70000,8.91675,9.97276
10.80000,8.99994,9.92410
10.90000,9.08331,9.84159
11.00000,9.16675,10.10109
11.10000,9.25000,10.20218
11.20000,9.33331,10.28704
11.30000,9.41681,10.07056
11.40000,9.49994,10.22952
11.50000,9.58319,10.26127
11.60000,9.66669,10.24035
11.70000,9.74994,10.48035
11.80000,9.83325,10.31463
11.90000,9.91681,10.64935
12.00000,10.00000,10.62529
12.10000,10.08331,10.44340
12.20000,10.16675,10.66214
12.30000,10.24994,10.53797
12.40000,10.33325,10.67414
12.50000,10.41675,10.84804
12.60000,10.49987,10.62784
12.70000,10.58325,10.81462
12.80000,10.66675,10.83016
12.90000,10.74994,10.87852
13.00000,10.83325,10.78233
13.10000,10.91675,11.01601
13.20000,10.99994,11.17223
13.30000,11.08331,11.10270
13.40000,11.16675,11.17350
13.50000,11.25000,11.18693
13.60000,11.33325,11.11343
13.70000,11.41669,11.44344
13.80000,11.49994,11.33123
13.90000,11.58325,11.24837
14.00000,11.66675,11.39635
14.10000,11.75000,11.20261
14.20000,11.83337,11.33510
14.30000,11.91675,11.40370
14.40000,12.00000,11.41845
14.50000,12.08325,11.44050
14.60000,12.16669,11.55506
14.70000,12.25000,11.37376
14.80000,12.33325,11.58206
14.90000,12.41675,11.56893
15.00000,12.50000,11.61842
15.10000,12.58331,11.62817
15.20000,12.66675,11.77747
15.30000,12.74994,11.73469
15.40000,12.83325,11.70040
15.50000,12.91675,11.79937
15.60000,12.99994,11.97607
15.70000,13.08325,11.87944
15.80000,13.16675,11.84529
15.90000,13.25000,11.87488
16.00000,13.33319,12.07098
16.10000,13.41675,12.06025
16.20000,13.49994,11.95936
16.30000,13.58325,11.83206
16.40000,13.66675,12.07127
16.50000,13.75000,12.04011
16.60000,13.83331,12.10166
16.70000,13.91675,12.06966
16.80000,13.99994,12.02507
16.90000,14.08325,12.18201
17.00000,14.16675,12.16423
17.10000,14.25000,12.09965
17.20000,14.33331,12.24684
17.30000,14.41675,12.15683
17.40000,14.50000,12.23273
17.50000,14.58325,12.22607
17.60000,14.66675,12.50816
17.70000,14.75000,12.55162
17.80000,14.83325,12.48371
17.90000,14.91669,12.11013
18.00000,15.00000,12.43809
18.10000,15.08319,12.35837
18.20000,15.16675,12.42814
18.30000,15.24994,12.65780
18.40000,15.33331,12.64550
18.50000,15.41681,12.46244
18.60000,15.50000,12.55676
18.70000,15.58325,12.57916
18.80000,15.66668,12.44328
18.90000,15.75000,12.56691
19.00000,15.83318,12.53432
19.10000,15.91668,12.82470
19.20000,15.99994,12.68666
19.30000,16.08331,12.76727
19.40000,16.16675,12.68637
19.50000,16.25000,12.74664
19.60000,16.33325,12.65011
19.70000,16.41675,12.85517
19.80000,16.49993,12.73307
19.90000,16.58325,12.77462
20.00000,16.66675,12.63908
20.10000,16.75000,12.91677
20.20000,16.83325,13.00732
20.30000,16.91675,12.96807
20.40000,16.99993,12.82798
20.50000,17.08325,13.01898
20.60000,17.16675,13.22145
20.70000,17.25000,12.88163
20.80000,17.33337,12.95724
20.90000,17.41687,12.91113
21.00000,17.50000,13.08199
21.10000,17.58325,13.14663
21.20000,17.66675,12.91285
21.30000,17.74994,13.05568
21.40000,17.83318,12.95347
21.50000,17.91681,12.95994
21.60000,18.00000,13.12712
21.70000,18.08331,12.88884
21.80000,18.16675,13.18514
21.90000,18.25000,13.27064
22.00000,18.33325,13.14658
22.10000,18.41675,13.29764
22.20000,18.49993,13.13565
22.30000,18.58325,13.09346
22.40000,18.66675,13.44489
22.50000,18.74994,13.33331
22.60000,18.83331,13.23698
22.70000,18.91675,13.27050
22.80000,19.00000,13.24374
22.90000,19.08325,13.43126
23.00000,19.16675,13.44205
23.10000,19.25006,13.22429
23.20000,19.33325,13.30622
23.30000,19.41668,13.25207
23.40000,19.49994,13.29735
23.50000,19.58325,13.28985
23.60000,19.66675,13.29647
23.70000,19.75000,13.44077
23.80000,19.83325,13.60556
23.90000,19.91681,13.46067
24.00000,20.00000,13.38658
24.10000,20.08325,13.57390
24.20000,20.16675,13.48894
24.30000,20.24994,13.45292
24.40000,20.33318,13.37011
24.50000,20.41668,13.45998
24.60000,20.50000,13.66901
24.70000,20.58331,13.63594
24.80000,20.66675,13.55710
24.90000,20.74993,13.64824
25.00000,20.83331,13.63868
25.10000,20.91675,13.85247
25.20000,20.99993,13.52716
25.30000,21.08331,13.76290
25.40000,21.16668,13.64133
25.50000,21.25000,13.88417
25.60000,21.33325,13.78936
25.70000,21.41668,13.68357
25.80000,21.50000,13.61766
25.90000,21.58331,13.86315
26.00000,21.66681,13.84424
26.10000,21.75000,13.59953
26.20000,21.83331,13.76069
26.30000,21.91675,13.82591
26.40000,21.99993,13.78304
26.50000,22.08325,13.81866
26.60000,22.16675,13.80798
26.70000,22.24993,13.85085
26.80000,22.33325,14.08982
26.90000,22.41687,13.98981
27.00000,22.50000,14.01887
27.10000,22.58325,13.85369
27.20000,22.66681,13.92205
27.30000,22.75000,13.92803
27.40000,22.83325,14.05146
27.50000,22.91675,14.09477
27.60000,23.00000,14.15450
27.70000,23.08331,14.01681
27.80000,23.16675,13.98697
27.90000,23.24993,14.18910
28.00000,23.33325,13.87520
28.10000,23.41675,14.17244
28.20000,23.50000,14.18307
28.30000,23.58325,14.28607
28.40000,23.66681,14.14887
28.50000,23.75000,14.24050
28.60000,23.83331,14.25133
28.70000,23.91668,14.23197
28.80000,24.00000,14.03783
28.90000,24.08325,14.19757
29.00000,24.16662,14.42949
29.10000,24.24994,14.44963
29.20000,24.33331,14.13162
29.30000,24.41681,14.37515
29.40000,24.50000,14.19949
29.50000,24.58331,14.46237
29.60000,24.66675,14.24285
29.70000,24.75000,14.41616
29.80000,24.83318,14.48496
29.90000,24.91681,14.39308
30.00000,24.99999,14.33923
30.10000,25.08325,14.45477
30.20000,25.16681,14.27455
30.30000,25.25000,14.46095
30.40000,25.33331,14.33178
30.50000,25.41675,14.51818
30.60000,25.49987,14.39186
30.70000,25.58324,14.39117
30.80000,25.66675,14.49540
30.90000,25.74993,14.48883
31.00000,25.83325,14.47153
31.10000,25.91675,14.27127
31.20000,26.00000,14.50446
31.30000,26.08331,14.67689
31.40000,26.16681,14.63666
31.50000,26.25006,14.52058
31.60000,26.33331,14.54342
31.70000,26.41669,14.44154
31.80000,26.49993,14.72707
31.90000,26.58325,14.76029
32.00000,26.66668,14.77523
32.10000,26.74993,14.50323
32.20000,26.83325,14.63955
32.30000,26.91681,14.65347
32.40000,27.00000,14.61064
32.50000,27.08325,14.64911
32.60000,27.16674,14.71741
32.70000,27.25000,14.66459
32.80000,27.33325,14.74000
32.90000,27.41675,14.76382
33.00000,27.50000,14.85094
33.10000,27.58325,14.67542
33.20000,27.66675,14.83869
33.30000,27.74999,14.76690
33.40000,27.83325,14.77749
33.50000,27.91681,14.82036
33.60000,28.00000,14.92669
33.70000,28.08325,14.95149
33.80000,28.16675,14.73496
33.90000,28.24993,14.88377
34.00000,28.33318,14.78812
34.10000,28.41668,14.95090
34.20000,28.50000,14.88578
34.30000,28.58325,14.99162
34.40000,28.66675,14.86236
34.50000,28.75006,14.97579
34.60000,28.83331,15.05958
34.70000,28.91675,14.84868
34.80000,28.99993,15.08202
34.90000,29.08325,14.99916
35.00000,29.16675,15.03283
35.10000,29.25000,14.89479
35.20000,29.33331,15.12494
35.30000,29.41675,15.18002
35.40000,29.50000,15.01357
35.50000,29.58325,15.02807
35.60000,29.66675,14.93100
35.70000,29.75000,15.09133
35.80000,29.83325,15.28841
35.90000,29.91674,15.16978
36.00000,30.00000,15.45692
36.10000,30.08325,15.06619
36.20000,30.16675,15.27008
36.30000,30.24993,14.95090
36.40000,30.33325,15.09995
36.50000,30.41681,15.21167
36.60000,30.49993,15.29321
36.70000,30.58331,15.14910
36.80000,30.66681,15.21893
36.90000,30.75000,15.33927
37.00000,30.83325,15.38631
37.10000,30.91675,15.28498
37.20000,30.99993,15.38430
37.30000,31.08324,15.56898
37.40000,31.16675,15.37827
37.50000,31.25000,15.22010
37.60000,31.33325,15.20065
37.70000,31.41674,15.43286
37.80000,31.49999,15.33011
37.90000,31.58325,15.45388
38.00000,31.66674,15.29806
38.10000,31.74993,15.50112
38.20000,31.83324,15.36862
38.30000,31.91675,15.56560
38.40000,31.99999,15.69192
38.50000,32.08318,15.56467
38.60000,32.16675,15.54282
38.70000,32.24999,15.52082
38.80000,32.33337,15.45045
38.90000,32.41681,15.59603
39.00000,32.50006,15.46912
39.10000,32.58331,15.61612
39.20000,32.66662,15.66438
39.30000,32.74987,15.62612
39.40000,32.83324,15.60142
39.50000,32.91674,15.69966
39.60000,32.99993,15.87851
39.70000,33.08331,15.82133
39.80000,33.16681,15.65012
39.90000,33.24999,15.71157
40.00000,33.33325,15.67835
40.10000,33.41675,15.71427
40.20000,33.49999,15.75087
40.30000,33.58331,15.65767
40.40000,33.66675,15.76013
40.50000,33.74999,15.58422
40.60000,33.83324,15.81511
40.70000,33.91674,15.87268
40.80000,33.99993,15.71020
40.90000,34.08324,15.84706
41.00000,34.16675,16.04173
41.10000,34.25000,15.80541
41.20000,34.33331,15.86852
41.30000,34.41674,15.88385
41.40000,34.49999,15.91948
41.50000,34.58325,15.74058
41.60000,34.66668,15.90934
41.70000,34.75000,15.86915
41.80000,34.83331,16.28325
41.90000,34.91674,16.05001
42.00000,34.99999,15.91277
42.10000,35.08325,16.10181
42.20000,35.16675,16.08588
42.30000,35.24993,15.95348
42.40000,35.33318,16.17584
42.50000,35.41674,16.08387
42.60000,35.49999,16.22210
42.70000,35.58318,16.13875
42.80000,35.66675,16.26013
42.90000,35.74993,16.13008
43.00000,35.83324,15.94976
43.10000,35.91675,16.24106
43.20000,35.99999,16.36939
43.30000,36.08331,16.26365
43.40000,36.16675,16.19834
43.50000,36.25000,16.51728
43.60000,36.33325,16.37253
43.70000,36.41674,16.36871
43.80000,36.49993,16.45559
43.90000,36.58318,16.18805
44.00000,36.66674,16.21602
44.10000,36.74999,16.37895
44.20000,36.83325,16.42040
44.30000,36.91674,16.24366
44.40000,36.99999,16.41036
44.50000,37.08331,16.41977
44.60000,37.16668,16.44191
44.70000,37.24999,16.42981
44.80000,37.33324,16.37067
44.90000,37.41675,16.41433
45.00000,37.49993,16.42501
45.10000,37.58324,16.38414
45.20000,37.66681,16.69431
45.30000,37.74999,16.63439
45.40000,37.83325,16.40139
45.50000,37.91675,16.50263
45.60000,38.00000,16.38694
45.70000,38.08324,16.39291
45.80000,38.16668,16.48293
45.90000,38.25000,16.60979
46.00000,38.33324,16.85836
46.10000,38.41668,16.44059
46.20000,38.49993,16.77864
46.30000,38.58337,16.86415
46.40000,38.66687,16.78663
46.50000,38.74999,16.64605
46.60000,38.83331,16.63159
46.70000,38.91675,16.74900
46.80000,38.99993,16.74439
46.90000,39.08325,16.80265
47.00000,39.16674,16.87218
47.10000,39.24999,16.63174
47.20000,39.33331,17.04103
47.30000,39.41681,16.67907
47.40000,39.49999,16.85910
47.50000,39.58330,16.89482
47.60000,39.66675,16.60626
47.70000,39.74999,16.89409
47.80000,39.83324,16.90433
47.90000,39.91674,17.18882
48.00000,39.99993,16.81799
48.10000,40.08318,16.93260
48.20000,40.16674,17.16153
48.30000,40.24993,16.90996
48.40000,40.33324,16.75933
48.50000,40.41681,17.06666
48.60000,40.49993,16.88987
48.70000,40.58330,16.98856
48.80000,40.66675,16.77403
48.90000,40.74999,17.07685
49.00000,40.83325,17.03143
49.10000,40.91668,17.21665
49.20000,40.99993,17.18240
49.30000,41.08324,16.95769
49.40000,41.16668,16.98743
49.50000,41.25000,17.10160
49.60000,41.33324,17.19240
49.70000,41.41680,16.95239
49.80000,41.50006,16.99326
49.90000,41.58324,17.25531
50.00000,41.66668,17.27094
50.10000,41.74993,17.24772
50.20000,41.83325,17.31426
50.30000,41.91674,17.27104
50.40000,41.99999,17.12968
50.50000,42.08324,17.43931
50.60000,42.16681,17.25301
50.70000,42.24999,17.17583
50.80000,42.33324,17.38555
50.90000,42.41674,17.38276
51.00000,42.49993,17.29000
51.10000,42.58324,17.35429
51.20000,42.66668,17.39491
51.30000,42.74993,17.52226
51.40000,42.83324,17.32979
51.50000,42.91675,17.22861
51.60000,42.99999,17.30201
51.70000,43.08337,17.72483
51.80000,43.16681,17.22395
51.90000,43.24993,17.46797
52.00000,43.33324,17.69048
52.10000,43.41675,17.51045
52.20000,43.50000,17.67637
52.30000,43.58324,17.63315
52.40000,43.66674,17.43254
52.50000,43.75000,17.53701
52.60000,43.83331,17.49438
52.70000,43.91674,17.60875
52.80000,44.00000,17.57803
52.90000,44.08325,17.53794
53.00000,44.16674,17.80288
53.10000,44.24999,17.72081
53.20000,44.33331,17.78760
53.30000,44.41674,17.59581
53.40000,44.49993,17.57959
53.50000,44.58318,17.75624
53.60000,44.66674,17.61825
53.70000,44.74999,17.67696
53.80000,44.83324,17.81587
53.90000,44.91674,17.82244
54.00000,44.99999,17.75251
54.10000,45.08324,17.76055
54.20000,45.16675,17.94489
54.30000,45.24993,17.87560
54.40000,45.33324,17.90657
54.50000,45.41674,17.87756
54.60000,45.49993,17.90446
54.70000,45.58324,18.05744
54.80000,45.66681,17.82601
54.90000,45.74993,17.86051
55.00000,45.83324,17.94224
55.10000,45.91674,17.95924
55.20000,45.99999,17.99521
55.30000,46.08324,18.21257
55.40000,46.16668,17.93244
55.50000,46.24999,17.94792
55.60000,46.33325,18.16749
55.70000,46.41668,18.05224
55.80000,46.49999,17.96307
55.90000,46.58324,18.24379
56.00000,46.66674,18.18386
56.10000,46.75000,18.22997
56.20000,46.83331,17.94557
56.30000,46.91674,18.08610
56.40000,46.99999,17.97291
56.50000,47.08324,18.14314
56.60000,47.16674,18.10453
56.70000,47.24999,18.06822
56.80000,47.33324,18.33243
56.90000,47.41680,18.27921
57.00000,47.49999,18.31861
57.10000,47.58324,18.34889
57.20000,47.66674,18.20689
57.30000,47.74993,18.32669
57.40000,47.83330,18.34727
57.50000,47.91674,18.35149
57.60000,47.99993,18.10546
57.70000,48.08324,18.11585
57.80000,48.16674,18.29043
57.90000,48.24999,18.31959
58.00000,48.33324,18.56758
58.10000,48.41674,18.36183
58.20000,48.49999,18.38510
58.30000,48.58330,18.61643
58.40000,48.66675,18.64671
58.50000,48.74999,18.45017
58.60000,48.83324,18.59546
58.70000,48.91668,18.41102
58.80000,48.99993,18.46257
58.90000,49.08324,18.48055
59.00000,49.16674,18.67876
59.10000,49.25005,18.61452
59.20000,49.33331,18.67841
59.30000,49.41680,18.65543
59.40000,49.49993,18.55004
59.50000,49.58318,18.79895
59.60000,49.66668,18.69777
59.70000,49.74993,18.49873
59.80000,49.83330,18.67944
59.90000,49.91674,18.84256
60.00000,49.99999,18.69674
60.10000,50.08331,18.73746
60.20000,50.16681,18.67298
60.30000,50.24993,18.92013
60.40000,50.33324,18.84506
60.50000,50.41681,18.57816
60.60000,50.49993,18.89078
60.70000,50.58330,18.80003
60.80000,50.66674,18.71188
60.90000,50.74993,18.95918
61.00000,50.83318,18.81081
61.10000,50.91668,18.75490
61.20000,50.99993,19.03293
61.30000,51.08324,18.94017
61.40000,51.16674,19.12098
61.50000,51.24999,18.90778
61.60000,51.33331,18.85535
61.70000,51.41674,19.02514
61.80000,51.49993,18.97472
61.90000,51.58324,18.86486
62.00000,51.66674,19.22947
62.10000,51.74999,19.06096
62.20000,51.83324,19.17635
62.30000,51.91681,19.04733
62.40000,51.99999,19.24691
62.50000,52.08324,19.12750
62.60000,52.16674,18.97545
62.70000,52.24999,19.21452
62.80000,52.33324,19.30645
62.90000,52.41674,19.25485
63.00000,52.49993,18.98721
63.10000,52.58324,19.26480
63.20000,52.66674,19.38269
63.30000,52.74993,19.30145
63.40000,52.83324,19.34677
63.50000,52.91680,19.21070
63.60000,53.00005,19.29777
63.70000,53.08331,19.40253
63.80000,53.16680,19.21188
63.90000,53.24993,19.41434
64.00000,53.33324,19.51077
64.10001,53.41668,19.50881
64.20000,53.49993,19.31899
64.30000,53.58324,19.03445
64.40000,53.66674,19.45374
64.50000,53.74999,19.36970
64.60001,53.83324,19.34413
64.70000,53.91681,19.65900
64.80000,53.99993,19.45403
64.90000,54.08324,19.39685
65.00000,54.16675,19.32262
65.10001,54.24999,19.52734
65.20000,54.33318,19.66733
65.30000,54.41674,19.52592
65.40000,54.49999,19.53327
65.50000,54.58324,19.63019
65.60001,54.66674,19.65537
65.70001,54.75000,19.59883
65.80000,54.83324,19.60289
65.90000,54.91674,19.64288
66.00000,55.00000,19.54160
66.10001,55.08318,19.57614
66.20001,55.16668,19.87519
66.30000,55.24993,19.73294
66.40000,55.33325,19.86039
66.50000,55.41674,19.93369
66.60001,55.50005,19.72339
66.70001,55.58331,19.69320
66.80000,55.66674,19.70937
66.90000,55.74993,19.81403
67.00000,55.83331,19.78860
67.10001,55.91668,19.64641
67.20001,55.99987,19.85191
67.30000,56.08324,19.85662
67.40000,56.16674,19.95114
67.50000,56.24993,19.70962
67.60001,56.33330,19.88984
67.70001,56.41674,19.73573
67.80000,56.49999,19.77410
67.90000,56.58324,19.86225
68.00000,56.66674,20.00940
68.10001,56.74999,20.02375
68.20001,56.83324,20.11078
68.30000,56.91674,19.80178
68.40000,56.99993,20.07486
68.50000,57.08324,19.68860
68.60001,57.16668,19.92331
68.70001,57.24993,19.99803
68.80000,57.33324,19.99514
68.90000,57.41681,20.06594
69.00000,57.49993,19.98754
69.10001,57.58324,20.09000
69.20001,57.66674,20.09505
69.30000,57.74999,20.20040
69.40000,57.83318,20.00783
69.50000,57.91674,20.19589
69.60001,57.99993,20.22132
69.70001,58.08318,20.26037
69.80000,58.16674,20.06251
69.90000,58.24999,20.47269
70.00000,58.33331,20.17614
70.10001,58.41680,20.24014
70.20001,58.49999,20.50150
70.30000,58.58331,20.32226
70.40000,58.66680,20.26601
70.50000,58.74987,20.31432
70.60001,58.83318,20.16389
70.70001,58.91674,20.42889
70.80000,58.99993,20.42144
70.90000,59.08324,20.44334
71.00000,59.16674,20.38870
71.10001,59.24999,20.55824
71.20001,59.33330,20.26243
71.30000,59.41668,20.52953
71.40000,59.49993,20.53272
71.50000,59.58318,20.61484
71.60001,59.66668,20.53855
71.70001,59.74993,20.51846
71.80000,59.83324,20.53497
71.90000,59.91681,20.53859
72.00000,59.99999,20.64698
72.10001,60.08331,20.53301
72.20001,60.16674,20.54457
72.30000,60.25000,20.55653
72.40000,60.33324,20.74371
72.50000,60.41668,20.53742
72.60001,60.50000,20.58637
72.70001,60.58331,20.63508
72.80000,60.66668,20.80074
72.90000,60.74987,20.47142
73.00000,60.83325,20.71931
73.10001,60.91674,20.60930
73.20001,60.99993,20.61817
73.30000,61.08331,20.84190
73.40000,61.16674,20.74841
73.50000,61.24999,20.66717
73.60001,61.33324,20.94196
73.70001,61.41668,20.81525
73.80000,61.49993,20.80775
73.90000,61.58324,20.95294
74.00000,61.66674,20.75287
74.10001,61.74999,21.05344
74.20001,61.83330,20.86689
74.30000,61.91680,20.89899
74.40000,61.99993,20.91320
74.50000,62.08324,20.88159
74.60001,62.16674,20.92677
74.70001,62.24993,20.94294
74.80000,62.33318,20.95392
74.90000,62.41681,20.95152
75.00000,62.49999,21.10023
75.10001,62.58324,21.03222
75.20001,62.66681,21.00380
75.30000,62.74993,21.14041
75.40000,62.83324,21.11121
75.50000,62.91680,21.03839
75.60001,62.99999,21.01772
75.70001,63.08324,21.02536
75.80000,63.16674,21.13213
75.90000,63.24993,21.17417
76.00000,63.33318,21.15163
76.10001,63.41674,21.42437
76.20001,63.49999,20.98832
76.30000,63.58324,21.13267
76.40000,63.66680,21.19265
76.50000,63.74999,21.31740
76.60001,63.83324,21.44303
76.70001,63.91668,21.21146
76.80000,63.99999,21.40702
76.90000,64.08324,21.33048
77.00000,64.16674,21.36439
77.10001,64.24999,21.38433
77.20001,64.33330,21.59273
77.30000,64.41674,21.27516
77.40000,64.49999,21.45367
77.50000,64.58324,21.31377
77.60001,64.66674,21.37007
77.70001,64.74999,21.48385
77.80000,64.83324,21.42172
77.90000,64.91674,21.46489
78.00000,64.99999,21.54892
78.10001,65.08324,21.68573
78.20001,65.16668,21.65246
78.30000,65.24999,21.59454
78.40000,65.33330,21.59915
78.50000,65.41680,21.68500
78.60001,65.49993,21.81254
78.70001,65.58330,21.62615
78.80000,65.66674,21.47464
78.90000,65.74993,21.50507
79.00000,65.83324,21.63585
79.10001,65.91668,21.39301
79.20001,65.99993,21.79294
79.30000,66.08331,21.64001
79.40000,66.16674,21.79956
79.50000,66.25005,21.67368
79.60001,66.33330,21.85375
79.70001,66.41674,21.89619
79.80000,66.49998,21.94788
79.90000,66.58311,21.75904
80.00000,66.66674,21.74237
80.10001,66.74992,21.98159
80.20001,66.83331,21.85944
80.30000,66.91680,21.64251
80.40000,66.99999,21.77374
80.50001,67.08324,21.93161
80.60001,67.16674,21.96082
80.70001,67.24992,21.91838
80.80000,67.33330,21.93798
80.90000,67.41674,22.01560
81.00001,67.49999,21.94759
81.10001,67.58330,22.03686
81.20001,67.66674,21.95582
81.30000,67.74993,21.87066
81.40000,67.83324,22.04578
81.50001,67.91674,21.91995
81.60001,67.99993,22.04377
81.70001,68.08330,22.10404
81.80000,68.16674,22.30014
81.90000,68.24999,22.00717
82.00001,68.33324,22.17725
82.10001,68.41674,22.19170
82.20001,68.49999,22.36727
82.30000,68.58324,22.39221
82.40000,68.66667,22.21434
82.50001,68.74999,22.22870
82.60001,68.83324,22.29671
82.70001,68.91680,22.15358
82.80000,68.99999,22.37550
82.90000,69.08331,22.35228
83.00001,69.16674,22.16451
83.10001,69.24999,22.29989
83.20001,69.33324,22.44557
83.30000,69.41674,22.29715
83.40000,69.49992,22.34586
83.50001,69.58318,22.39848
83.60001,69.66668,22.39731
83.70001,69.74999,22.37825
83.80000,69.83330,22.29181
83.90000,69.91680,22.49800
84.00001,69.99999,22.45302
84.10001,70.08330,22.43690
84.20001,70.16674,22.68239
84.30000,70.24992,22.50535
84.40000,70.33318,22.46346
84.50001,70.41674,22.46757
84.60001,70.49999,22.37805
84.70001,70.58324,22.60217
84.80000,70.66674,22.51755
84.90000,70.74999,22.65039
85.00001,70.83324,22.71688
85.10001,70.91674,22.53916
85.20001,70.99999,22.66622
85.30000,71.08324,22.42553
85.40000,71.16674,22.79122
85.50001,71.24993,22.66450
85.60001,71.33318,22.67440
85.70001,71.41673,22.72712
85.80000,71.49993,22.72693
85.90000,71.58324,22.70238
86.00001,71.66680,22.58145
86.10001,71.74999,22.53887
86.20001,71.83324,22.74800
86.30000,71.91674,22.78955
86.40000,71.99999,22.73835
86.50001,72.08318,22.61354
86.60001,72.16674,22.74261
86.70001,72.24993,22.85006
86.80000,72.33324,22.89544
86.90000,72.41681,22.86775
87.00001,72.49999,22.85320
87.10001,72.58330,22.87667
87.20001,72.66680,22.81802
87.30000,72.74993,22.92273
87.40000,72.83324,22.92307
87.50001,72.91668,22.87594
87.60001,72.99999,23.07777
87.70001,73.08324,22.91190
87.80000,73.16674,23.17841
87.90000,73.24999,23.01578
88.00001,73.33330,23.10452
88.10001,73.41674,23.03058
88.20001,73.49999,23.16460
88.30000,73.58330,23.03582
88.40000,73.66681,23.15818
88.50001,73.74999,23.24554
88.60001,73.83324,23.16249
88.70001,73.91674,23.11589
88.80000,73.99993,23.39499
88.90000,74.08318,23.15475
89.00001,74.16674,23.33507
89.10001,74.24999,23.04479
89.20001,74.33324,23.00985
89.30000,74.41680,23.55321
89.40000,74.49999,23.11241
89.50001,74.58330,23.34609
89.60001,74.66668,23.43640
89.70001,74.74992,23.37941
89.80000,74.83324,23.47374
89.90000,74.91674,23.48050
90.00001,74.99993,23.47584
90.10001,75.08317,23.33972
90.20001,75.16674,23.54297
90.30000,75.24999,23.28362
90.40000,75.33330,23.33884
90.50001,75.41680,23.42552
90.60001,75.49999,23.35325
90.70001,75.58330,23.54023
90.80000,75.66668,23.46913
90.90000,75.74987,23.51279
91.00001,75.83324,23.60162
91.10001,75.91668,23.48069
91.20001,75.99992,23.75745
91.30000,76.08330,23.52176
91.40000,76.16680,23.55218
91.50001,76.24999,23.47863
91.60001,76.33324,23.47383
91.70001,76.41668,23.47863
91.80000,76.49993,23.66459
91.90000,76.58318,23.48319
92.00001,76.66674,23.76323
92.10001,76.75005,23.76705
92.20001,76.83330,23.65763
92.30000,76.91680,23.47202
92.40000,76.99999,23.90302
92.50001,77.08324,23.74573
92.60001,77.16680,23.81007
92.70001,77.24993,23.92444
92.80000,77.33324,23.77842
92.90000,77.41680,23.82923
93.00001,77.49993,23.73971
93.10001,77.58324,23.99696
93.20001,77.66674,23.95540
93.30000,77.74999,23.98946
93.40000,77.83324,23.98765
93.50001,77.91680,23.97878
93.60001,77.99999,23.89156
93.70001,78.08330,23.97476
93.80000,78.16673,23.80522
93.90000,78.24992,24.11392
94.00001,78.33323,24.04424
94.10001,78.41674,24.13729
94.20001,78.49992,23.93801
94.30000,78.58329,24.06982
94.40000,78.66674,23.99362
94.50001,78.74999,24.29154
94.60001,78.83323,24.05144
94.70001,78.91680,24.00563
94.80000,78.99993,24.09153
94.90000,79.08324,24.20222
95.00001,79.16674,24.17610
95.10001,79.24993,24.32844
95.20001,79.33330,24.26107
95.30000,79.41674,24.22172
95.40000,79.49992,24.03895
95.50001,79.58324,24.25847
95.60001,79.66680,24.35828
95.70001,79.74993,24.35622
95.80000,79.83324,24.36607
95.90000,79.91680,24.44815
96.00001,79.99999,24.11652
96.10001,80.08317,24.42355
96.20001,80.16674,24.33192
96.30000,80.24992,24.22240
96.40000,80.33318,24.42938
96.50001,80.41673,24.28512
96.60001,80.49999,24.52228
96.70001,80.58324,24.48093
96.80000,80.66680,24.37656
96.90000,80.74999,24.56134
97.00001,80.83324,24.60348
97.10001,80.91674,24.56623
97.20001,80.99993,24.53497
97.30000,81.08323,24.55531
97.40000,81.16674,24.47436
97.50001,81.24999,24.84382
97.60001,81.33323,24.75964
97.70001,81.41668,24.63523
97.80000,81.49998,24.48328
97.90000,81.58323,24.60916
98.00001,81.66674,24.74234
98.10001,81.74999,24.75508
98.20001,81.83324,24.82079
98.30000,81.91674,24.50018
98.40000,81.99993,24.74597
98.50001,82.08317,24.75577
98.60001,82.16674,24.68560
98.70001,82.24999,24.75067
98.80000,82.33324,24.69525
98.90000,82.41680,24.94613
99.00001,82.49999,24.85563
99.10001,82.58330,24.74935
99.20001,82.66667,24.94731
99.30000,82.74992,24.88758
99.40000,82.83324,24.89615
99.50001,82.91667,24.92521
99.60001,82.99992,24.95853
99.70001,83.08330,24.89968
99.80000,83.16685,24.79712
99.90000,83.24998,24.77419
100.00001,83.33330,24.95593
100.10001,83.41674,25.02855
100.20001,83.49999,25.17501
100.30000,83.58317,24.86734
100.40000,83.66674,25.13361
100.50001,83.74998,24.83240
100.60001,83.83330,24.98190
100.70001,83.91674,24.96137
100.80000,83.99999,25.04398
100.90000,84.08330,24.96357
101.00001,84.16673,25.34617
101.10001,84.24993,25.19642
101.20001,84.33324,25.29153
101.30000,84.41680,25.22029
101.40000,84.49992,25.29805
101.50001,84.58317,25.18236
101.60001,84.66673,25.23302
101.70001,84.74993,25.25316
101.80000,84.83318,25.27198
101.90000,84.91674,25.29364
102.00001,84.99999,25.30481
102.10001,85.08329,25.38478
102.20001,85.16674,25.34328
102.30000,85.24999,25.39188
102.40000,85.33323,25.27933
102.50001,85.41674,25.49718
102.60001,85.49993,25.43138
102.70001,85.58324,25.36611
102.80000,85.66674,25.39869
102.90000,85.74992,25.45661
103.00001,85.83323,25.54457
103.10001,85.91673,25.33269
103.20001,85.99998,25.54315
103.30000,86.08324,25.53295
103.40000,86.16674,25.53800
103.50001,86.24999,25.46151
103.60001,86.33324,25.40305
103.70001,86.41673,25.31868
103.80000,86.49993,25.39624
103.90000,86.58317,25.49787
104.00001,86.66674,25.48822
104.10001,86.74999,25.79305
104.20001,86.83324,25.59146
104.30000,86.91681,25.52992
104.40000,86.99999,25.55726
104.50001,87.08323,25.48812
104.60001,87.16674,25.74826
104.70001,87.24992,25.58038
104.80000,87.33324,25.64330
104.90000,87.41674,25.84106
105.00001,87.49993,25.73782
105.10001,87.58330,25.77746
105.20001,87.66674,25.64364
105.30000,87.74993,25.94205
105.40000,87.83324,25.82881
105.50001,87.91680,25.98566
105.60001,87.99993,25.85425
105.70001,88.08331,26.03946
105.80000,88.16673,25.92549
105.90000,88.24993,26.02226
106.00001,88.33324,25.80059
106.10001,88.41667,25.94156
106.20001,88.49998,25.89266
106.30000,88.58330,25.79099
106.40000,88.66673,25.99179
106.50001,88.74998,25.92490
106.60001,88.83324,25.93059
106.70001,88.91674,26.01766
106.80000,88.99992,25.98669
106.90000,89.08317,25.96547
107.00001,89.16680,25.92926
107.10001,89.24992,26.22317
107.20001,89.33323,26.09807
107.30000,89.41680,26.13786
107.40000,89.49999,26.31778
107.50001,89.58329,26.32543
107.60001,89.66674,26.05505
107.70001,89.74999,26.18690
107.80000,89.83330,26.05470
107.90000,89.91674,26.29118
108.00001,89.99986,26.23929
108.10001,90.08324,26.11463
108.20001,90.16674,26.30563
108.30000,90.24998,26.44513
108.40000,90.33323,26.38766
108.50001,90.41680,26.41089
108.60001,90.49999,26.24100
108.70001,90.58330,26.30946
108.80000,90.66674,26.41216
108.90000,90.74998,26.44724
109.00001,90.83324,26.46341
109.10001,90.91668,26.46214
109.20001,90.99992,26.19034
109.30000,91.08324,26.27667
109.40000,91.16674,26.49394
109.50001,91.24999,26.41912
109.60001,91.33330,26.43935
109.70001,91.41673,26.61801
109.80000,91.49999,26.52035
109.90000,91.58324,26.39153
110.00001,91.66680,26.43926
110.10001,91.74999,26.68984
110.20001,91.83324,26.69111
110.30000,91.91674,26.68876
110.40000,91.99993,26.69165
110.50001,92.08323,26.72752
110.60001,92.16674,26.60884
110.70001,92.24992,26.66710
110.80000,92.33330,26.65143
110.90000,92.41686,26.51251
111.00001,92.49998,26.88251
111.10001,92.58323,26.92220
111.20001,92.66668,26.75168
111.30000,92.74992,26.75231
111.40000,92.83324,26.86139
111.50001,92.91680,26.71522
111.60001,93.00006,26.93352
111.70001,93.08336,26.76373
111.80000,93.16674,26.85129
111.90000,93.24999,26.66867
112.00001,93.33324,26.97267
112.10001,93.41667,27.02740
112.20001,93.49992,27.05822
112.30000,93.58324,26.77809
112.40000,93.66673,26.91362
112.50001,93.74992,26.96213
112.60001,93.83324,27.02490
112.70001,93.91680,27.11893
112.80000,93.99992,26.92631
112.90001,94.08324,27.03936
113.00001,94.16673,27.22585
113.10001,94.24998,27.02230
113.20001,94.33329,27.05107
113.30000,94.41674,26.98791
113.40001,94.49992,27.20699
113.50001,94.58323,27.24819
113.60001,94.66674,27.10124
113.70001,94.74993,27.29641
113.80000,94.83330,27.46462
113.90001,94.91679,27.30449
114.00001,94.99999,27.18322
114.10001,95.08323,27.29082
114.20001,95.16673,27.25500
114.30000,95.24993,27.41102
114.40001,95.33317,27.45620
114.50001,95.41674,27.40034
114.60001,95.49998,27.32478
114.70001,95.58330,27.15759
114.80000,95.66673,27.18229
114.90001,95.74998,27.44586
115.00001,95.83324,27.28729
115.10001,95.91680,27.31023
115.20001,95.99992,27.48457
115.30000,96.08329,27.49643
115.40001,96.16673,27.46649
115.50001,96.24992,27.43101
115.60001,96.33318,27.53303
115.70001,96.41673,27.54572
115.80000,96.49999,27.58472
115.90001,96.58324,27.66371
116.00001,96.66674,27.55327
116.10001,96.74999,27.55777
116.20001,96.83330,27.82526
116.30000,96.91673,27.72148
116.40001,96.99993,27.61064
116.50001,97.08324,27.53827
116.60001,97.16674,27.71943
116.70001,97.24992,27.66915
116.80000,97.33323,27.71624
116.90001,97.41686,27.55361
117.00001,97.50005,27.66606
117.10001,97.58330,27.74657
117.20001,97.66679,27.55332
117.30000,97.74992,27.81762
117.40001,97.83324,27.66979
117.50001,97.91673,27.95453
117.60001,97.99992,27.79959
117.70001,98.08330,27.78910
117.80000,98.16674,27.95781
117.90001,98.24999,27.87789
118.00001,98.33324,27.84369
118.10001,98.41673,27.96560
118.20001,98.49992,27.84776
118.30000,98.58330,27.87828
118.40001,98.66673,28.00857
118.50001,98.74999,27.94218
118.60001,98.83317,27.90023
118.70001,98.91674,28.03787
118.80000,98.99992,27.82673
118.90001,99.08323,27.98295
119.00001,99.16673,27.98079
119.10001,99.24999,28.20595
119.20001,99.33330,28.11294
119.30000,99.41679,28.16263
119.40001,99.49992,28.10339
119.50001,99.58323,28.15841
119.60001,99.66673,28.00735
119.70001,99.74992,28.21241
119.80000,99.83324,28.31198
119.90001,99.91674,28.23387
120.00001,99.99998,28.31477
120.10001,100.08324,28.30679
120.20001,100.16680,28.06924
120.30000,100.24998,28.32903
120.40001,100.33330,28.13372
120.50001,100.41674,28.35407
120.60001,100.49986,28.36823
120.70001,100.58324,28.32962
120.80000,100.66673,28.35975
120.90001,100.74992,28.27347
121.00001,100.83323,28.40542
121.10001,100.91674,28.48926
121.20001,100.99999,28.36764
121.30000,101.08324,28.51356
121.40001,101.16674,28.60113
121.50001,101.24998,28.52234
121.60001,101.33323,28.32516
121.70001,101.41673,28.57359
121.80000,101.49992,28.49960
121.90001,101.58330,28.60319
122.00001,101.66667,28.48000
122.10001,101.74998,28.71216
122.20001,101.83323,28.65616
122.30000,101.91679,28.68565
122.40001,101.99992,28.83417
122.50001,102.08324,28.56193
122.60001,102.16679,28.61843
122.70001,102.24998,28.67502
122.80000,102.33324,28.74989
122.90001,102.41673,28.57599
123.00001,102.49992,28.53365
123.10001,102.58324,28.74901
123.20001,102.66673,28.49103
123.30000,102.74999,28.61132
123.40001,102.83330,28.82109
123.50001,102.91673,28.86568
123.60001,102.99998,28.67213
123.70001,103.08329,28.93217
123.80000,103.16680,28.84167
123.90001,103.24992,28.99989
124.00001,103.33324,28.74445
124.10001,103.41667,28.75646
124.20001,103.49993,28.73936
124.30000,103.58323,28.86651
124.40001,103.66674,28.84265
124.50001,103.74999,28.87415
124.60001,103.83330,28.99224
124.70001,103.91674,28.93266
124.80000,103.99998,28.73696
124.90001,104.08323,28.93232
125.00001,104.16673,28.99847
125.10001,104.24992,29.11881
125.20001,104.33324,29.18604
125.30000,104.41673,29.05295
125.40001,104.49992,29.09475
125.50001,104.58324,29.05001
125.60001,104.66673,28.93849
125.70001,104.74999,29.14547
125.80000,104.83329,29.13253
125.90001,104.91673,29.23543
126.00001,104.99999,29.26091
126.10001,105.08330,29.19662
126.20001,105.16667,29.22637
126.30000,105.24986,29.26155
126.40001,105.33324,29.35200
126.50001,105.41674,29.28595
126.60001,105.49992,29.30971
126.70001,105.58330,29.39051
126.80000,105.66680,29.14395
126.90001,105.74993,29.22039
127.00001,105.83317,29.44780
127.10001,105.91674,29.41496
127.20001,105.99992,29.33863
127.30000,106.08323,29.30746
127.40001,106.16673,29.44613
127.50001,106.24998,29.46838
127.60001,106.33330,29.73082
127.70001,106.41679,29.45676
127.80000,106.49998,29.30854
127.90001,106.58330,29.44647
128.00000,106.66673,29.52291
128.10001,106.74998,29.41198
128.20002,106.83317,29.57931
128.30000,106.91673,29.49920
128.40001,106.99992,29.58588
128.50000,107.08317,29.74949
128.60001,107.16673,29.69921
128.70002,107.24999,29.46970
128.80000,107.33323,29.60332
128.90001,107.41680,29.77590
129.00000,107.49999,29.71548
129.10001,107.58329,29.68961
129.20002,107.66674,29.51938
129.30000,107.74992,29.64448
129.40001,107.83323,29.94774
129.50000,107.91673,29.72004
129.60001,107.99998,29.73655
129.70002,108.08324,29.77350
129.80000,108.16674,29.90673
129.90001,108.24999,30.02168
130.00000,108.33330,29.83568
130.10001,108.41668,29.76860
130.20002,108.49998,29.86807
130.30000,108.58330,29.94901
130.40001,108.66679,29.93010
130.50000,108.74998,29.85699
130.60001,108.83324,30.06887
130.70002,108.91673,30.00198
130.80000,108.99986,30.18485
130.90001,109.08323,30.04373
131.00000,109.16680,29.97739
131.10000,109.25005,30.18284
131.20002,109.33329,29.80334
131.30000,109.41680,29.99287
131.40002,109.49999,29.97347
131.50000,109.58323,30.17633
131.60000,109.66667,30.16246
131.70002,109.74992,30.14139
131.80000,109.83324,30.14340
131.90002,109.91674,30.15271
132.00000,109.99999,30.38742
132.10000,110.08330,30.07651
132.20002,110.16673,30.18578
132.30000,110.24993,30.21215
132.40002,110.33324,30.24782
132.50000,110.41667,30.31740
132.60000,110.49998,30.06657
132.70002,110.58323,30.27820
132.80000,110.66673,30.29687
132.90002,110.74998,30.25473
133.00000,110.83324,30.31142
133.10000,110.91674,30.35586
133.20002,110.99992,30.42956
133.30000,111.08330,30.33141
133.40002,111.16680,30.30848
133.50000,111.24992,30.37066
133.60000,111.33323,30.46150
133.70002,111.41674,30.49120
133.80000,111.49992,30.44524
133.90002,111.58324,30.37022
134.00000,111.66673,30.57425
134.10000,111.74999,30.80847
134.20002,111.83330,30.49713
134.30000,111.91680,30.61301
134.40002,111.99999,30.56759
134.50000,112.08324,30.79088
134.60000,112.16674,30.48870
134.70002,112.24986,30.57499
134.80000,112.33323,30.70822
134.90002,112.41680,30.71547
135.00000,112.49992,30.70366
135.10000,112.58330,30.71665
135.20002,112.66680,30.56666
135.30000,112.74998,30.69371
135.40002,112.83323,30.76952
135.50000,112.91673,30.71508
135.60000,112.99998,30.81411
135.70002,113.08330,30.67818
135.80000,113.16667,30.82655
135.90002,113.24998,30.74423
136.00000,113.33324,30.82724
136.10000,113.41673,30.89888
136.20002,113.49998,31.10718
136.30000,113.58330,30.90574
136.40002,113.66680,30.87506
136.50000,113.74999,30.90980
136.60000,113.83324,30.89638
136.70002,113.91673,30.82435
136.80000,113.99992,30.85835
136.90002,114.08323,31.10972
137.00000,114.16674,30.84361
137.10000,114.24992,30.95425
137.20002,114.33329,30.93411
137.30000,114.41674,30.91402
137.40002,114.49993,30.90044
137.50000,114.58330,30.97027
137.60000,114.66674,30.97390
137.70002,114.74992,31.10830
137.80000,114.83323,31.11516
137.90002,114.91674,31.15980
138.00000,114.99998,31.18386
138.10000,115.08323,31.06479
138.20002,115.16673,31.17739
138.30000,115.24999,31.08689
138.40002,115.33324,31.08086
138.50000,115.41673,30.94229
138.60000,115.49998,31.28960
138.70002,115.58330,31.32038
138.80000,115.66673,31.25026
138.90002,115.74992,31.05239
139.00000,115.83317,31.17705
139.10000,115.91673,31.27088
139.20002,115.99992,31.26162
139.30000,116.08324,31.28392
139.40002,116.16680,31.52794
139.50000,116.24998,31.17337
139.60000,116.33324,31.25388
139.70002,116.41674,31.31494
139.80000,116.49999,31.37349
139.90002,116.58323,31.44233
140.00000,116.66667,31.49143
140.10000,116.74993,31.39040
140.20002,116.83323,31.29367
140.30000,116.91674,31.48325
140.40002,116.99992,31.28044
140.50000,117.08330,31.33542
140.60000,117.16680,31.38011
140.70002,117.24993,31.46360
140.80000,117.33323,31.60918
140.90002,117.41674,31.51505
141.00000,117.49987,31.34443
141.10000,117.58317,31.55200
141.20002,117.66667,31.47100
141.30000,117.74998,31.49202
141.40002,117.83324,31.61300
141.50000,117.91673,31.48977
141.60000,118.00005,31.56101
141.70002,118.08329,31.53823
141.80000,118.16673,31.58483
141.90002,118.24999,31.47511
142.00000,118.33330,31.56792
142.10000,118.41673,31.78984
142.20002,118.49998,31.96271
142.30000,118.58324,31.75623
142.40002,118.66674,31.75814
142.50000,118.74992,31.70576
142.60000,118.83323,31.65117
142.70002,118.91673,31.81277
142.80000,118.99993,31.59193
142.90002,119.08330,31.77686
143.00000,119.16674,31.73849
143.10000,119.24999,31.81763
143.20002,119.33330,31.73761
143.30000,119.41673,31.81669
143.40002,119.49993,31.91273
143.50000,119.58323,31.56126
143.60000,119.66674,31.63853
143.70002,119.74998,31.65857
143.80000,119.83329,31.79303
143.90002,119.91680,31.71919
144.00000,119.99998,31.69375
144.10000,120.08330,31.81116
144.20002,120.16667,31.74427
144.30000,120.24992,31.71605
144.40002,120.33324,31.62888
144.50000,120.41667,31.85991
144.60000,120.49992,31.65142
144.70002,120.58330,31.54754
144.80000,120.66680,31.64720
144.90002,120.74992,31.52235
145.00000,120.83324,31.60693
145.10000,120.91674,31.45503
145.20002,120.99992,31.57317
145.30000,121.08323,31.27510
145.40002,121.16673,31.05720
145.50000,121.24993,30.69744
145.60000,121.33324,30.46665
145.70002,121.41667,0.00070
145.80000,121.49992,0.09914
145.90002,121.58323,0.11321
146.00000,121.66673,0.28965
146.10000,121.74998,0.18940
146.20002,121.83330,-0.01728
146.30000,121.91679,0.08302
146.40002,121.99992,0.06460
146.50000,122.08324,0.21248
146.60000,122.16673,0.02207
146.70002,122.24992,0.11208
146.80000,122.33323,0.02559
146.90002,122.41674,0.23002
147.00000,122.49999,0.05774
147.10000,122.58329,-0.02497
147.20002,122.66673,0.31925
147.30000,122.74992,0.01070
147.40002,122.83330,0.02172
147.50000,122.91674,0.02809
147.60000,122.99986,0.10556
147.70002,123.08329,0.37883
147.80000,123.16667,0.16328
147.90002,123.24998,0.20101
148.00000,123.33323,0.01374
148.10000,123.41673,0.17397
148.20002,123.49999,0.05494
148.30000,123.58330,0.15907
148.40002,123.66674,0.13099
148.50000,123.74998,0.12345
148.60000,123.83323,0.03926
148.70002,123.91668,0.02001
148.80000,123.99992,0.27206
148.90002,124.08324,0.35252
148.99800,124.16511,-0.00998