File: EPR/EPR/RDSO EPR Tensile 500.is_tens_RawData/Specimen_RawData_5.csv
Time,Extension,Load,Tensile strain,Tensile stress,Corrected Position
(sec),(mm),(N),(mm/mm),(MPa),(mm)
0.00000,0.00000,0.19665,0.00000,0.02185,0.00000
0.04000,0.09794,0.63203,0.00085,0.07023,0.09794
0.08000,0.41850,1.38437,0.00364,0.15382,0.41850
0.12000,0.83744,2.10848,0.00728,0.23428,0.83744
0.16000,1.27606,2.96633,0.01110,0.32959,1.27606
0.20000,1.64925,3.22461,0.01434,0.35829,1.64925
0.24000,1.98306,3.77985,0.01724,0.41998,1.98306
0.28000,2.32119,4.57895,0.02018,0.50877,2.32119
0.32000,2.66056,4.90304,0.02314,0.54478,2.66056
0.36000,2.99656,5.11136,0.02606,0.56793,2.99656
0.40000,3.33119,5.60980,0.02897,0.62331,3.33119
0.44000,3.66531,5.86057,0.03187,0.65117,3.66531
0.48000,3.99925,6.13499,0.03478,0.68167,3.99925
0.52000,4.33300,6.57086,0.03768,0.73010,4.33300
0.56000,4.66644,6.91814,0.04058,0.76868,4.66644
0.60000,4.99981,7.10433,0.04348,0.78937,4.99981
0.64000,5.33325,7.37520,0.04638,0.81947,5.33325
0.68000,5.66656,7.60505,0.04927,0.84501,5.66656
0.72000,6.00000,7.88229,0.05217,0.87581,6.00000
0.76000,6.33337,8.07890,0.05507,0.89766,6.33337
0.80000,6.66662,8.44556,0.05797,0.93840,6.66662
0.84000,7.00000,8.51151,0.06087,0.94572,7.00000
0.88000,7.33325,8.78324,0.06377,0.97592,7.33325
0.92000,7.66656,9.05561,0.06667,1.00618,7.66656
0.96000,8.00006,9.30001,0.06957,1.03333,8.00006
1.00000,8.33331,9.55003,0.07246,1.06112,8.33331
1.04000,8.66669,9.86915,0.07536,1.09657,8.66669
1.08000,8.99994,9.68794,0.07826,1.07644,8.99994
1.12000,9.33325,10.15002,0.08116,1.12778,9.33325
1.16000,9.66675,10.21453,0.08406,1.13495,9.66675
1.20000,10.00006,10.39841,0.08696,1.15538,10.00006
1.24000,10.33331,10.62194,0.08985,1.18022,10.33331
1.28000,10.66669,10.72823,0.09275,1.19203,10.66669
1.32000,10.99994,10.83276,0.09565,1.20364,10.99994
1.36000,11.33337,11.12190,0.09855,1.23577,11.33337
1.40000,11.66669,11.08634,0.10145,1.23182,11.66669
1.44000,12.00000,11.13290,0.10435,1.23699,12.00000
1.48000,12.33337,11.68488,0.10725,1.29832,12.33337
1.52000,12.66669,11.55385,0.11015,1.28376,12.66669
1.56000,13.00000,11.67063,0.11304,1.29674,13.00000
1.60000,13.33331,12.13351,0.11594,1.34817,13.33331
1.64000,13.66656,12.03802,0.11884,1.33756,13.66656
1.68000,14.00000,12.14881,0.12174,1.34987,14.00000
1.72000,14.33337,12.29919,0.12464,1.36658,14.33337
1.76000,14.66669,12.36830,0.12754,1.37426,14.66669
1.80000,15.00012,12.48111,0.13044,1.38679,15.00012
1.84000,15.33337,12.74647,0.13333,1.41627,15.33337
1.88000,15.66662,12.83060,0.13623,1.42562,15.66662
1.92000,16.00006,12.83574,0.13913,1.42619,16.00006
1.96000,16.33331,12.96545,0.14203,1.44061,16.33331
2.00000,16.66668,13.06353,0.14493,1.45150,16.66668
2.04000,17.00012,13.00336,0.14783,1.44482,17.00012
2.08000,17.33312,13.30999,0.15072,1.47889,17.33312
2.12000,17.66669,13.37624,0.15362,1.48625,17.66669
2.16000,18.00000,13.40012,0.15652,1.48890,18.00000
2.20000,18.33325,13.49796,0.15942,1.49977,18.33325
2.24000,18.66668,13.58813,0.16232,1.50979,18.66668
2.28000,19.00000,13.60464,0.16522,1.51163,19.00000
2.32000,19.33331,13.97010,0.16812,1.55223,19.33331
2.36000,19.66669,13.90507,0.17101,1.54501,19.66669
2.40000,20.00000,13.99772,0.17391,1.55530,20.00000
2.44000,20.33337,14.00392,0.17681,1.55599,20.33337
2.48000,20.66668,14.14372,0.17971,1.57152,20.66668
2.52000,21.00000,14.12562,0.18261,1.56951,21.00000
2.56000,21.33337,14.40197,0.18551,1.60022,21.33337
2.60000,21.66662,14.55762,0.18841,1.61751,21.66662
2.64000,22.00000,14.40562,0.19130,1.60062,22.00000
2.68000,22.33337,14.69046,0.19420,1.63227,22.33337
2.72000,22.66662,14.65362,0.19710,1.62818,22.66662
2.76000,23.00000,14.71950,0.20000,1.63550,23.00000
2.80000,23.33331,14.97328,0.20290,1.66370,23.33331
2.84000,23.66656,14.88768,0.20580,1.65419,23.66656
2.88000,24.00006,14.83870,0.20870,1.64874,24.00006
2.92000,24.33331,15.04842,0.21159,1.67205,24.33331
2.96000,24.66668,15.00078,0.21449,1.66675,24.66668
3.00000,25.00006,14.97651,0.21739,1.66406,25.00006
3.04000,25.33331,15.25772,0.22029,1.69530,25.33331
3.08000,25.66668,15.32943,0.22319,1.70327,25.66668
3.12000,26.00000,15.11952,0.22609,1.67995,26.00000
3.16000,26.33331,15.33014,0.22899,1.70335,26.33331
3.20000,26.66668,15.40773,0.23188,1.71197,26.66668
3.24000,27.00000,15.53912,0.23478,1.72657,27.00000
3.28000,27.33331,15.86099,0.23768,1.76233,27.33331
3.32000,27.66668,15.65313,0.24058,1.73924,27.66668
3.36000,27.99993,15.50589,0.24348,1.72288,27.99993
3.40000,28.33331,15.81666,0.24638,1.75741,28.33331
3.44000,28.66668,15.94656,0.24928,1.77184,28.66668
3.48000,29.00000,16.06730,0.25217,1.78526,29.00000
3.52000,29.33343,16.07940,0.25507,1.78660,29.33343
3.56000,29.66668,16.26889,0.25797,1.80765,29.66668
3.60000,30.00000,15.97394,0.26087,1.77488,30.00000
3.64000,30.33337,16.44348,0.26377,1.82705,30.33337
3.68000,30.66662,16.26955,0.26667,1.80773,30.66662
3.72000,31.00006,16.19691,0.26957,1.79966,31.00006
3.76000,31.33331,16.37043,0.27246,1.81894,31.33331
3.80000,31.66662,16.49156,0.27536,1.83240,31.66662
3.84000,32.00006,16.55232,0.27826,1.83915,32.00006
3.88000,32.33331,16.63052,0.28116,1.84784,32.33331
3.92000,32.66668,16.75925,0.28406,1.86214,32.66668
3.96000,33.00000,16.67318,0.28696,1.85258,33.00000
4.00000,33.33325,16.86853,0.28985,1.87428,33.33325
4.04000,33.66668,17.01716,0.29275,1.89080,33.66668
4.08000,34.00006,16.97085,0.29565,1.88565,34.00006
4.12000,34.33324,17.06220,0.29855,1.89580,34.33324
4.16000,34.66668,17.16955,0.30145,1.90773,34.66668
4.20000,35.00006,17.07672,0.30435,1.89741,35.00006
4.24000,35.33331,17.39051,0.30725,1.93228,35.33331
4.28000,35.66675,17.49707,0.31015,1.94412,35.66675
4.32000,35.99999,17.48156,0.31304,1.94240,35.99999
4.36000,36.33331,17.58274,0.31594,1.95364,36.33331
4.40000,36.66668,17.67566,0.31884,1.96396,36.66668
4.44000,36.99999,17.75883,0.32174,1.97320,36.99999
4.48000,37.33337,17.82740,0.32464,1.98082,37.33337
4.52000,37.66662,17.87482,0.32754,1.98609,37.66662
4.56000,37.99993,17.86938,0.33043,1.98549,37.99993
4.60000,38.33337,17.87614,0.33333,1.98624,38.33337
4.64000,38.66662,18.16619,0.33623,2.01847,38.66662
4.68000,38.99999,18.07831,0.33913,2.00870,38.99999
4.72000,39.33337,18.08551,0.34203,2.00950,39.33337
4.76000,39.66662,18.04866,0.34493,2.00541,39.66662
4.80000,40.00005,18.34233,0.34783,2.03804,40.00005
4.84000,40.33331,18.51891,0.35072,2.05766,40.33331
4.88000,40.66668,18.61367,0.35362,2.06819,40.66668
4.92000,41.00006,18.53307,0.35652,2.05923,41.00006
4.96000,41.33331,18.70240,0.35942,2.07804,41.33331
5.00000,41.66662,18.79554,0.36232,2.08839,41.66662
5.04000,41.99999,18.81351,0.36522,2.09039,41.99999
5.08000,42.33331,19.02519,0.36812,2.11391,42.33331
5.12000,42.66662,18.92791,0.37101,2.10310,42.66662
5.16000,42.99993,19.17841,0.37391,2.13093,42.99993
5.20000,43.33324,19.18970,0.37681,2.13219,43.33324
5.24000,43.66674,19.12654,0.37971,2.12517,43.66674
5.28000,44.00000,19.08507,0.38261,2.12056,44.00000
5.32000,44.33331,19.41044,0.38551,2.15672,44.33331
5.36000,44.66674,19.53204,0.38841,2.17023,44.66674
5.40000,44.99999,19.66424,0.39130,2.18492,44.99999
5.44000,45.33337,19.54707,0.39420,2.17190,45.33337
5.48000,45.66668,19.70915,0.39710,2.18991,45.66668
5.52000,45.99999,19.72806,0.40000,2.19201,45.99999
5.56000,46.33337,19.94329,0.40290,2.21592,46.33337
5.60000,46.66662,19.89935,0.40580,2.21104,46.66662
5.64000,46.99999,19.88640,0.40870,2.20960,46.99999
5.68000,47.33337,20.12798,0.41159,2.23644,47.33337
5.72000,47.66662,20.14471,0.41449,2.23830,47.66662
5.76000,47.99999,20.35570,0.41739,2.26174,47.99999
5.80000,48.33330,20.46341,0.42029,2.27371,48.33330
5.84000,48.66662,20.64313,0.42319,2.29368,48.66662
5.88000,49.00006,20.54945,0.42609,2.28327,49.00006
5.92000,49.33331,20.75574,0.42899,2.30619,49.33331
5.96000,49.66674,20.83712,0.43188,2.31524,49.66674
6.00000,50.00005,20.78307,0.43478,2.30923,50.00005
6.04000,50.33324,20.82331,0.43768,2.31370,50.33324
6.08000,50.66668,20.83051,0.44058,2.31450,50.66668
6.12000,51.00005,21.02293,0.44348,2.33588,51.00005
6.16000,51.33324,21.08382,0.44638,2.34265,51.33324
6.20000,51.66668,21.22430,0.44928,2.35826,51.66668
6.24000,51.99999,21.28820,0.45217,2.36536,51.99999
6.28000,52.33331,21.40980,0.45507,2.37887,52.33331
6.32000,52.66674,21.43781,0.45797,2.38198,52.66674
6.36000,52.99993,21.50399,0.46087,2.38933,52.99993
6.40000,53.33330,21.65432,0.46377,2.40603,53.33330
6.44000,53.66668,21.74787,0.46667,2.41643,53.66668
6.48000,53.99999,21.81860,0.46957,2.42429,53.99999
6.52000,54.33343,22.01277,0.47246,2.44586,54.33343
6.56000,54.66668,22.15758,0.47536,2.46195,54.66668
6.60000,55.00006,22.09300,0.47826,2.45478,55.00006
6.64000,55.33337,22.34707,0.48116,2.48301,55.33337
6.68000,55.66662,22.51344,0.48406,2.50149,55.66662
6.72000,56.00005,22.39213,0.48696,2.48801,56.00005
6.76000,56.33337,22.58280,0.48986,2.50920,56.33337
6.80000,56.66655,22.58753,0.49275,2.50973,56.66655
6.84000,56.99999,22.73962,0.49565,2.52662,56.99999
6.88000,57.33330,22.67893,0.49855,2.51988,57.33330
6.92000,57.66662,23.00912,0.50145,2.55657,57.66662
6.96000,58.00006,22.99618,0.50435,2.55513,58.00006
7.00000,58.33324,23.13564,0.50725,2.57063,58.33324
7.04000,58.66662,23.07243,0.51014,2.56360,58.66662
7.08000,59.00005,23.08403,0.51304,2.56489,59.00005
7.12000,59.33337,23.28006,0.51594,2.58667,59.33337
7.16000,59.66675,23.57802,0.51884,2.61978,59.66675
7.20000,59.99999,23.49017,0.52174,2.61002,59.99999
7.24000,60.33331,23.76709,0.52464,2.64079,60.33331
7.28000,60.66674,23.53070,0.52754,2.61452,60.66674
7.32000,60.99999,23.73320,0.53043,2.63702,60.99999
7.36000,61.33337,23.96021,0.53333,2.66225,61.33337
7.40000,61.66668,24.15045,0.53623,2.68338,61.66668
7.44000,61.99999,24.06841,0.53913,2.67427,61.99999
7.48000,62.33336,24.21873,0.54203,2.69097,62.33336
7.52000,62.66668,24.26311,0.54493,2.69590,62.66668
7.56000,62.99999,24.24658,0.54783,2.69406,62.99999
7.60000,63.33330,24.40080,0.55072,2.71120,63.33330
7.64000,63.66661,24.67037,0.55362,2.74115,63.66661
7.68000,63.99999,24.55811,0.55652,2.72868,63.99999
7.72000,64.33337,24.88242,0.55942,2.76471,64.33337
7.76000,64.66668,24.97257,0.56232,2.77473,64.66668
7.80000,65.00005,24.92932,0.56522,2.76992,65.00005
7.84000,65.33330,25.09703,0.56812,2.78856,65.33330
7.88000,65.66667,25.17957,0.57101,2.79773,65.66667
7.92000,66.00005,25.17411,0.57391,2.79712,66.00005
7.96000,66.33330,25.44809,0.57681,2.82757,66.33330
8.00000,66.66661,25.41748,0.57971,2.82416,66.66661
8.04000,66.99999,25.55921,0.58261,2.83991,66.99999
8.08000,67.33324,25.79836,0.58551,2.86648,67.33324
8.12000,67.66668,25.81142,0.58841,2.86794,67.66668
8.16000,67.99999,25.82138,0.59130,2.86904,67.99999
8.20000,68.33318,26.06546,0.59420,2.89616,68.33318
8.24000,68.66674,26.16005,0.59710,2.90667,68.66674
8.28000,68.99999,26.34726,0.60000,2.92747,68.99999
8.32000,69.33337,26.55658,0.60290,2.95073,69.33337
8.36000,69.66674,26.60216,0.60580,2.95580,69.66674
8.40000,69.99999,26.50978,0.60870,2.94553,69.99999
8.44000,70.33330,26.78396,0.61159,2.97600,70.33330
8.48000,70.66668,26.75895,0.61449,2.97322,70.66668
8.52000,70.99999,26.82613,0.61739,2.98068,70.99999
8.56000,71.33336,26.91472,0.62029,2.99052,71.33336
8.60000,71.66661,26.93938,0.62319,2.99326,71.66661
8.64000,71.99999,27.03617,0.62609,3.00402,71.99999
8.68000,72.33337,27.14934,0.62899,3.01659,72.33337
8.72000,72.66662,27.57194,0.63188,3.06355,72.66662
8.76000,72.99999,27.38306,0.63478,3.04256,72.99999
8.80000,73.33330,27.54174,0.63768,3.06019,73.33330
8.84000,73.66655,27.87511,0.64058,3.09723,73.66655
8.88000,74.00006,27.64784,0.64348,3.07198,74.00006
8.92000,74.33336,27.77641,0.64638,3.08627,74.33336
8.96000,74.66674,27.91947,0.64928,3.10216,74.66674
9.00000,75.00005,28.00668,0.65217,3.11185,75.00005
9.04000,75.33324,28.26188,0.65507,3.14021,75.33324
9.08000,75.66668,28.25987,0.65797,3.13999,75.66668
9.12000,76.00005,28.22512,0.66087,3.13612,76.00005
9.16000,76.33337,28.53539,0.66377,3.17060,76.33337
9.20000,76.66667,28.58952,0.66667,3.17661,76.66667
9.24000,76.99993,28.71986,0.66956,3.19110,76.99993
9.28000,77.33336,28.61296,0.67246,3.17922,77.33336
9.32000,77.66668,29.00619,0.67536,3.22291,77.66668
9.36000,77.99999,29.10146,0.67826,3.23350,77.99999
9.40000,78.33330,29.09049,0.68116,3.23228,78.33330
9.44000,78.66661,29.50544,0.68406,3.27838,78.66661
9.48000,78.99999,29.23398,0.68696,3.24822,78.99999
9.52000,79.33336,29.26636,0.68986,3.25182,79.33336
9.56000,79.66667,29.40343,0.69275,3.26705,79.66667
9.60000,79.99999,29.61749,0.69565,3.29083,79.99999
9.64000,80.33336,30.00011,0.69855,3.33335,80.33336
9.68000,80.66662,29.91606,0.70145,3.32401,80.66662
9.72000,81.00005,30.01645,0.70435,3.33516,81.00005
9.76000,81.33330,30.20104,0.70725,3.35567,81.33330
9.80000,81.66661,30.23819,0.71014,3.35980,81.66661
9.84000,81.99998,30.22083,0.71304,3.35787,81.99998
9.88000,82.33324,30.36819,0.71594,3.37424,82.33324
9.92000,82.66667,30.50629,0.71884,3.38959,82.66667
9.96000,83.00005,30.47661,0.72174,3.38629,83.00005
10.00000,83.33330,30.60742,0.72464,3.40082,83.33330
10.04000,83.66668,31.02509,0.72754,3.44723,83.66668
10.08000,83.99999,30.79747,0.73043,3.42194,83.99999
10.12000,84.33330,31.17157,0.73333,3.46351,84.33330
10.16000,84.66673,31.00469,0.73623,3.44497,84.66673
10.20000,84.99999,31.19719,0.73913,3.46635,84.99999
10.24000,85.33323,31.52618,0.74203,3.50291,85.33323
10.28000,85.66667,31.45454,0.74493,3.49495,85.66667
10.32000,85.99998,31.48391,0.74783,3.49821,85.99998
10.36000,86.33336,31.89007,0.75072,3.54334,86.33336
10.40000,86.66667,31.65926,0.75362,3.51770,86.66667
10.44000,86.99992,31.96051,0.75652,3.55117,86.99992
10.48000,87.33337,32.18004,0.75942,3.57556,87.33337
10.52000,87.66667,32.00469,0.76232,3.55608,87.66667
10.56000,87.99999,32.19831,0.76522,3.57759,87.99999
10.60000,88.33330,32.50225,0.76812,3.61136,88.33330
10.64000,88.66655,32.68559,0.77101,3.63173,88.66655
10.68000,88.99999,32.36828,0.77391,3.59648,88.99999
10.72000,89.33342,32.50430,0.77681,3.61159,89.33342
10.76000,89.66668,32.67437,0.77971,3.63049,89.66668
10.80000,90.00004,32.83675,0.78261,3.64853,90.00004
10.84000,90.33330,33.16865,0.78551,3.68541,90.33330
10.88000,90.66661,33.14308,0.78841,3.68256,90.66661
10.92000,91.00011,33.15014,0.79131,3.68335,91.00011
10.96000,91.33330,33.48008,0.79420,3.72001,91.33330
11.00000,91.66667,33.48904,0.79710,3.72100,91.66667
11.04000,91.99998,33.63315,0.80000,3.73702,91.99998
11.08000,92.33324,33.71671,0.80290,3.74630,92.33324
11.12000,92.66668,33.51207,0.80580,3.72356,92.66668
11.16000,92.99998,33.75722,0.80870,3.75080,92.99998
11.20000,93.33330,34.17798,0.81159,3.79755,93.33330
11.24000,93.66655,34.14957,0.81449,3.79440,93.66655
11.28000,93.99999,34.14967,0.81739,3.79441,93.99999
11.32000,94.33337,34.45076,0.82029,3.82786,94.33337
11.36000,94.66674,34.56700,0.82319,3.84078,94.66674
11.40000,94.99999,34.35167,0.82609,3.81685,94.99999
11.44000,95.33330,34.66266,0.82899,3.85141,95.33330
11.48000,95.66667,34.60663,0.83188,3.84518,95.66667
11.52000,95.99999,34.57430,0.83478,3.84159,95.99999
11.56000,96.33343,34.83532,0.83768,3.87059,96.33343
11.60000,96.66661,35.04644,0.84058,3.89405,96.66661
11.64000,96.99998,35.17080,0.84348,3.90787,96.99998
11.68000,97.33336,35.35302,0.84638,3.92811,97.33336
11.72000,97.66667,35.42228,0.84928,3.93581,97.66667
11.76000,98.00005,35.49257,0.85217,3.94362,98.00005
11.80000,98.33324,35.60008,0.85507,3.95556,98.33324
11.84000,98.66661,35.78362,0.85797,3.97596,98.66661
11.88000,99.00005,35.75996,0.86087,3.97333,99.00005
11.92000,99.33330,35.90255,0.86377,3.98917,99.33330
11.96000,99.66673,36.19840,0.86667,4.02204,99.66673
12.00000,100.00011,36.11347,0.86957,4.01261,100.00011
12.04000,100.33330,36.08055,0.87246,4.00895,100.33330
12.08000,100.66668,36.46697,0.87536,4.05189,100.66668
12.12000,100.99999,36.37254,0.87826,4.04139,100.99999
12.16000,101.33330,36.59384,0.88116,4.06598,101.33330
12.20000,101.66674,36.69126,0.88406,4.07681,101.66674
12.24000,101.99999,36.72957,0.88696,4.08106,101.99999
12.28000,102.33324,36.92946,0.88985,4.10327,102.33324
12.32000,102.66667,36.90154,0.89275,4.10017,102.66667
12.36000,102.99992,36.94049,0.89565,4.10450,102.99992
12.40000,103.33329,37.29384,0.89855,4.14376,103.33329
12.44000,103.66661,37.51602,0.90145,4.16845,103.66661
12.48000,103.99993,37.57402,0.90435,4.17489,103.99993
12.52000,104.33336,37.67654,0.90725,4.18628,104.33336
12.56000,104.66667,37.90455,0.91014,4.21162,104.66667
12.60000,104.99999,37.70549,0.91304,4.18950,104.99999
12.64000,105.33337,37.84425,0.91594,4.20492,105.33337
12.68000,105.66667,38.24860,0.91884,4.24985,105.66667
12.72000,106.00004,37.98826,0.92174,4.22092,106.00004
12.76000,106.33335,38.19526,0.92464,4.24392,106.33335
12.80000,106.66661,38.38096,0.92754,4.26455,106.66661
12.84000,107.00005,38.36102,0.93044,4.26234,107.00005
12.88000,107.33330,38.67406,0.93333,4.29712,107.33330
12.92000,107.66661,38.78844,0.93623,4.30983,107.66661
12.96000,108.00004,38.77908,0.93913,4.30879,108.00004
13.00000,108.33323,38.95081,0.94203,4.32787,108.33323
13.04000,108.66667,38.86794,0.94493,4.31866,108.66667
13.08000,108.99998,38.85701,0.94783,4.31745,108.99998
13.12000,109.33324,39.30878,0.95072,4.36764,109.33324
13.16000,109.66673,39.40135,0.95362,4.37793,109.66673
13.20000,110.00005,39.25534,0.95652,4.36170,110.00005
13.24000,110.33336,39.54340,0.95942,4.39371,110.33336
13.28000,110.66668,39.64661,0.96232,4.40518,110.66668
13.32000,110.99998,39.57044,0.96522,4.39672,110.99998
13.36000,111.33336,39.92728,0.96812,4.43636,111.33336
13.40000,111.66668,39.95044,0.97101,4.43894,111.66668
13.44000,111.99999,40.16974,0.97391,4.46330,111.99999
13.48000,112.33336,40.25761,0.97681,4.47307,112.33336
13.52000,112.66661,40.35401,0.97971,4.48378,112.66661
13.56000,112.99998,40.29249,0.98261,4.47694,112.99998
13.60000,113.33336,40.67715,0.98551,4.51968,113.33336
13.64000,113.66662,40.48317,0.98841,4.49813,113.66662
13.68000,113.99998,40.76972,0.99130,4.52997,113.99998
13.72000,114.33329,40.84447,0.99420,4.53827,114.33329
13.76000,114.66667,40.96036,0.99710,4.55115,114.66667
13.80000,115.00005,41.05294,1.00000,4.56144,115.00005
13.84000,115.33330,41.03814,1.00290,4.55979,115.33330
13.88000,115.66667,41.14571,1.00580,4.57175,115.66667
13.92000,116.00011,41.47580,1.00870,4.60842,116.00011
13.96000,116.33329,41.48467,1.01159,4.60941,116.33329
14.00000,116.66667,41.58151,1.01449,4.62017,116.66667
14.04000,117.00004,41.45062,1.01739,4.60562,117.00004
14.08000,117.33330,41.51215,1.02029,4.61246,117.33330
14.12000,117.66667,42.08588,1.02319,4.67621,117.66667
14.16000,117.99999,42.07627,1.02609,4.67514,117.99999
14.20000,118.33323,42.15509,1.02898,4.68390,118.33323
14.24000,118.66674,42.17904,1.03188,4.68656,118.66674
14.28000,118.99993,42.30199,1.03478,4.70022,118.99993
14.32000,119.33330,42.57727,1.03768,4.73081,119.33330
14.36000,119.66674,42.51075,1.04058,4.72342,119.66674
14.40000,119.99998,42.46382,1.04348,4.71820,119.99998
14.44000,120.33336,42.72632,1.04638,4.74737,120.33336
14.48000,120.66667,42.77858,1.04928,4.75318,120.66667
14.52000,120.99999,42.83384,1.05217,4.75932,120.99999
14.56000,121.33336,43.07586,1.05507,4.78621,121.33336
14.60000,121.66660,43.17911,1.05797,4.79768,121.66660
14.64000,121.99998,43.27448,1.06087,4.80828,121.99998
14.68000,122.33336,43.54790,1.06377,4.83866,122.33336
14.72000,122.66668,43.53609,1.06667,4.83734,122.66668
14.76000,122.99999,43.59928,1.06957,4.84436,122.99999
14.80000,123.33330,43.82431,1.07246,4.86937,123.33330
14.84000,123.66655,43.89538,1.07536,4.87726,123.66655
14.88000,124.00005,44.00569,1.07826,4.88952,124.00005
14.92000,124.33330,43.86388,1.08116,4.87376,124.33330
14.96000,124.66673,44.16116,1.08406,4.90680,124.66673
15.00000,125.00010,44.27916,1.08696,4.91991,125.00010
15.04000,125.33329,44.43516,1.08985,4.93724,125.33329
15.08000,125.66673,44.38506,1.09275,4.93167,125.66673
15.12000,126.00005,44.61439,1.09565,4.95715,126.00005
15.16000,126.33323,44.87130,1.09855,4.98570,126.33323
15.20000,126.66667,44.65368,1.10145,4.96152,126.66667
15.24000,126.99998,44.80464,1.10435,4.97829,126.99998
15.28000,127.33336,44.83780,1.10725,4.98198,127.33336
15.32000,127.66667,44.86092,1.11014,4.98455,127.66667
15.36000,127.99992,45.10015,1.11304,5.01113,127.99992
15.40000,128.33335,45.49005,1.11594,5.05445,128.33335
15.44000,128.66667,45.37043,1.11884,5.04116,128.66667
15.48000,128.99998,45.31866,1.12174,5.03541,128.99998
15.52000,129.33335,45.59443,1.12464,5.06605,129.33335
15.56000,129.66667,45.68529,1.12754,5.07614,129.66667
15.60000,129.99998,45.77493,1.13043,5.08610,129.99998
15.64000,130.33335,46.00921,1.13333,5.11213,130.33335
15.68000,130.66666,46.06187,1.13623,5.11799,130.66666
15.72000,131.00005,46.08998,1.13913,5.12111,131.00005
15.76000,131.33335,45.95347,1.14203,5.10594,131.33335
15.80000,131.66660,46.32079,1.14493,5.14675,131.66660
15.84000,132.00005,46.28988,1.14783,5.14332,132.00005
15.88000,132.33329,46.51025,1.15072,5.16781,132.33329
15.92000,132.66660,46.56242,1.15362,5.17360,132.66660
15.96000,132.99997,46.60914,1.15652,5.17879,132.99997
16.00000,133.33316,46.79317,1.15942,5.19924,133.33316
16.04000,133.66667,46.76682,1.16232,5.19631,133.66667
16.08000,134.00003,46.95530,1.16522,5.21726,134.00003
16.12000,134.33336,47.19438,1.16812,5.24382,134.33336
16.16000,134.66673,47.20511,1.17102,5.24501,134.66673
16.20000,134.99998,47.45874,1.17391,5.27319,134.99998
16.24000,135.33329,47.47471,1.17681,5.27497,135.33329
16.28000,135.66673,47.47500,1.17971,5.27500,135.66673
16.32000,135.99998,47.68911,1.18261,5.29879,135.99998
16.36000,136.33328,47.57625,1.18551,5.28625,136.33328
16.40000,136.66667,47.74735,1.18841,5.30526,136.66667
16.44000,136.99998,47.78452,1.19130,5.30939,136.99998
16.48000,137.33335,47.96228,1.19420,5.32914,137.33335
16.52000,137.66666,48.08258,1.19710,5.34251,137.66666
16.56000,137.99992,48.19926,1.20000,5.35547,137.99992
16.60000,138.33329,48.43315,1.20290,5.38146,138.33329
16.64000,138.66660,48.51372,1.20580,5.39041,138.66660
16.68000,139.00004,48.47601,1.20870,5.38622,139.00004
16.72000,139.33341,48.58494,1.21159,5.39833,139.33341
16.76000,139.66660,48.75285,1.21449,5.41698,139.66660
16.80000,140.00005,48.78543,1.21739,5.42060,140.00005
16.84000,140.33330,48.88951,1.22029,5.43217,140.33330
16.88000,140.66661,49.04352,1.22319,5.44928,140.66661
16.92000,141.00003,48.88756,1.22609,5.43195,141.00003
16.96000,141.33330,49.14794,1.22899,5.46088,141.33330
17.00000,141.66661,49.27907,1.23188,5.47545,141.66661
17.04000,142.00004,49.36547,1.23478,5.48505,142.00004
17.08000,142.33328,49.52629,1.23768,5.50292,142.33328
17.12000,142.66667,49.64330,1.24058,5.51592,142.66667
17.16000,142.99998,49.65050,1.24348,5.51672,142.99998
17.20000,143.33323,49.87798,1.24638,5.54200,143.33323
17.24000,143.66667,50.05681,1.24928,5.56187,143.66667
17.28000,144.00004,50.03996,1.25217,5.56000,144.00004
17.32000,144.33342,50.17902,1.25507,5.57545,144.33342
17.36000,144.66673,50.40159,1.25797,5.60018,144.66673
17.40000,144.99999,50.17633,1.26087,5.57515,144.99999
17.44000,145.33341,50.49981,1.26377,5.61109,145.33341
17.48000,145.66666,50.53101,1.26667,5.61456,145.66666
17.52000,145.99998,50.60208,1.26957,5.62245,145.99998
17.56000,146.33335,50.75275,1.27246,5.63919,146.33335
17.60000,146.66661,50.98615,1.27536,5.66513,146.66661
17.64000,146.99997,50.94682,1.27826,5.66076,146.99997
17.68000,147.33336,51.06217,1.28116,5.67357,147.33336
17.72000,147.66661,51.10596,1.28406,5.67844,147.66661
17.76000,147.99997,51.11640,1.28696,5.67960,147.99997
17.80000,148.33330,51.32276,1.28985,5.70253,148.33330
17.84000,148.66660,51.36605,1.29275,5.70734,148.66660
17.88000,149.00004,51.31796,1.29565,5.70200,149.00004
17.92000,149.33328,51.34945,1.29855,5.70549,149.33328
17.96000,149.66667,51.41739,1.30145,5.71304,149.66667
18.00000,150.00003,51.67871,1.30435,5.74208,150.00003
18.04000,150.33322,52.12822,1.30725,5.79202,150.33322
18.08000,150.66673,52.04314,1.31015,5.78257,150.66673
18.12000,151.00004,52.00537,1.31304,5.77837,151.00004
18.16000,151.33329,52.15359,1.31594,5.79484,151.33329
18.20000,151.66667,52.31999,1.31884,5.81333,151.66667
18.24000,151.99998,52.32063,1.32174,5.81340,151.99998
18.28000,152.33329,52.48280,1.32464,5.83142,152.33329
18.32000,152.66674,52.63230,1.32754,5.84803,152.66674
18.36000,152.99991,52.51797,1.33043,5.83533,152.99991
18.40000,153.33329,52.70396,1.33333,5.85600,153.33329
18.44000,153.66666,53.00642,1.33623,5.88960,153.66666
18.48000,153.99999,52.66512,1.33913,5.85168,153.99999
18.52000,154.33341,53.05399,1.34203,5.89489,154.33341
18.56000,154.66667,53.05022,1.34493,5.89447,154.66667
18.60000,155.00004,53.18114,1.34783,5.90902,155.00004
18.64000,155.33336,53.31550,1.35072,5.92394,155.33336
18.68000,155.66661,53.38006,1.35362,5.93112,155.66661
18.72000,156.00003,53.30502,1.35652,5.92278,156.00003
18.76000,156.33328,53.44844,1.35942,5.93872,156.33328
18.80000,156.66660,53.60631,1.36232,5.95626,156.66660
18.84000,156.99998,53.54498,1.36522,5.94944,156.99998
18.88000,157.33328,53.75477,1.36812,5.97275,157.33328
18.92000,157.66660,53.83902,1.37101,5.98211,157.66660
18.96000,157.99997,53.60670,1.37391,5.95630,157.99997
19.00000,158.33322,53.90216,1.37681,5.98913,158.33322
19.04000,158.66667,54.01277,1.37971,6.00142,158.66667
19.08000,159.00003,54.14585,1.38261,6.01621,159.00003
19.12000,159.33335,54.37788,1.38551,6.04199,159.33335
19.16000,159.66678,54.37768,1.38841,6.04197,159.66678
19.20000,160.00004,54.30445,1.39130,6.03383,160.00004
19.24000,160.33323,54.63827,1.39420,6.07092,160.33323
19.28000,160.66672,54.67696,1.39710,6.07522,160.66672
19.32000,161.00004,54.70405,1.40000,6.07823,161.00004
19.36000,161.33334,54.90312,1.40290,6.10035,161.33334
19.40000,161.66659,55.15371,1.40580,6.12819,161.66659
19.44000,161.99991,54.90317,1.40869,6.10035,161.99991
19.48000,162.33342,55.19324,1.41159,6.13258,162.33342
19.52000,162.66666,55.21871,1.41449,6.13541,162.66666
19.56000,162.99997,55.08406,1.41739,6.12045,162.99997
19.60000,163.33321,55.40700,1.42029,6.15633,163.33321
19.64000,163.66655,55.46509,1.42319,6.16279,163.66655
19.68000,164.00004,55.38961,1.42609,6.15440,164.00004
19.72000,164.33341,55.53210,1.42899,6.17023,164.33341
19.76000,164.66666,55.57883,1.43188,6.17543,164.66666
19.80000,165.00004,55.38873,1.43478,6.15430,165.00004
19.84000,165.33334,55.57153,1.43768,6.17461,165.33334
19.88000,165.66666,55.74542,1.44058,6.19394,165.66666
19.92000,166.00003,55.86596,1.44348,6.20733,166.00003
19.96000,166.33328,56.08496,1.44638,6.23166,166.33328
20.00000,166.66660,56.00051,1.44927,6.22228,166.66660
20.04000,166.99998,56.17249,1.45217,6.24139,166.99998
20.08000,167.33328,56.26527,1.45507,6.25170,167.33328
20.12000,167.66673,56.30915,1.45797,6.25657,167.66673
20.16000,167.99998,56.68524,1.46087,6.29836,167.99998
20.20000,168.33322,56.69029,1.46377,6.29892,168.33322
20.24000,168.66671,56.78702,1.46667,6.30967,168.66671
20.28000,168.99997,57.11202,1.46957,6.34578,168.99997
20.32000,169.33341,56.90203,1.47246,6.32245,169.33341
20.36000,169.66673,57.02106,1.47536,6.33567,169.66673
20.40000,169.99992,57.11207,1.47826,6.34579,169.99992
20.44000,170.33335,57.37501,1.48116,6.37500,170.33335
20.48000,170.66667,57.54439,1.48406,6.39382,170.66667
20.52000,170.99997,57.25980,1.48696,6.36220,170.99997
20.56000,171.33335,57.39886,1.48986,6.37765,171.33335
20.60000,171.66661,57.68095,1.49275,6.40899,171.66661
20.64000,171.99997,57.58093,1.49565,6.39788,171.99997
20.68000,172.33334,57.63104,1.49855,6.40345,172.33334
20.72000,172.66667,58.02818,1.50145,6.44758,172.66667
20.76000,173.00004,57.76760,1.50435,6.41862,173.00004
20.80000,173.33329,57.97592,1.50725,6.44177,173.33329
20.84000,173.66659,58.06301,1.51014,6.45145,173.66659
20.88000,174.00010,58.06169,1.51304,6.45130,174.00010
20.92000,174.33329,58.04910,1.51594,6.44990,174.33329
20.96000,174.66659,58.36895,1.51884,6.48544,174.66659
21.00000,175.00004,58.37170,1.52174,6.48574,175.00004
21.04000,175.33328,58.64105,1.52464,6.51567,175.33328
21.08000,175.66666,58.55137,1.52754,6.50571,175.66666
21.12000,176.00004,58.35196,1.53044,6.48355,176.00004
21.16000,176.33328,58.67113,1.53333,6.51901,176.33328
21.20000,176.66671,58.65584,1.53623,6.51732,176.66671
21.24000,176.99996,58.71413,1.53913,6.52379,176.99996
21.28000,177.33330,58.84634,1.54203,6.53848,177.33330
21.32000,177.66666,59.08331,1.54493,6.56481,177.66666
21.36000,177.99998,59.13558,1.54783,6.57062,177.99998
21.40000,178.33328,59.13636,1.55072,6.57071,178.33328
21.44000,178.66660,59.13269,1.55362,6.57030,178.66660
21.48000,178.99998,59.18304,1.55652,6.57589,178.99998
21.52000,179.33335,59.40821,1.55942,6.60091,179.33335
21.56000,179.66667,59.48741,1.56232,6.60971,179.66667
21.60000,180.00003,59.43006,1.56522,6.60334,180.00003
21.64000,180.33335,59.70010,1.56812,6.63334,180.33335
21.68000,180.66660,59.76495,1.57101,6.64055,180.66660
21.72000,180.99997,59.66503,1.57391,6.62945,180.99997
21.76000,181.33335,59.83661,1.57681,6.64851,181.33335
21.80000,181.66659,59.95721,1.57971,6.66191,181.66659
21.84000,181.99997,60.04890,1.58261,6.67210,181.99997
21.88000,182.33329,60.14545,1.58551,6.68283,182.33329
21.92000,182.66659,60.19457,1.58841,6.68829,182.66659
21.96000,183.00004,60.26104,1.59130,6.69567,183.00004
22.00000,183.33329,60.21265,1.59420,6.69029,183.33329
22.04000,183.66667,60.21907,1.59710,6.69101,183.66667
22.08000,184.00004,60.28289,1.60000,6.69810,184.00004
22.12000,184.33329,60.66887,1.60290,6.74099,184.33329
22.16000,184.66672,60.41916,1.60580,6.71324,184.66672
22.20000,185.00004,60.50654,1.60870,6.72295,185.00004
22.24000,185.33329,60.55562,1.61159,6.72840,185.33329
22.28000,185.66666,60.74695,1.61449,6.74966,185.66666
22.32000,185.99996,60.78236,1.61739,6.75360,185.99996
22.36000,186.33336,61.05147,1.62029,6.78350,186.33336
22.40000,186.66672,61.18509,1.62319,6.79834,186.66672
22.44000,186.99991,61.02771,1.62609,6.78086,186.99991
22.48000,187.33334,61.25504,1.62899,6.80612,187.33334
22.52000,187.66666,61.32587,1.63188,6.81399,187.66666
22.56000,187.99998,61.38597,1.63478,6.82066,187.99998
22.60000,188.33334,61.46601,1.63768,6.82956,188.33334
22.64000,188.66658,61.47100,1.64058,6.83011,188.66658
22.68000,188.99998,61.56476,1.64348,6.84053,188.99998
22.72000,189.33333,61.78596,1.64638,6.86511,189.33333
22.76000,189.66665,61.77489,1.64928,6.86388,189.66665
22.80000,190.00009,61.67991,1.65217,6.85332,190.00009
22.84000,190.33335,61.77136,1.65507,6.86348,190.33335
22.88000,190.66660,61.84219,1.65797,6.87136,190.66660
22.92000,191.00003,61.89421,1.66087,6.87713,191.00003
22.96000,191.33329,61.98336,1.66377,6.88704,191.33329
23.00000,191.66665,62.08034,1.66667,6.89782,191.66665
23.04000,191.99997,62.00565,1.66956,6.88952,191.99997
23.08000,192.33322,62.00271,1.67246,6.88919,192.33322
23.12000,192.66665,62.27994,1.67536,6.91999,192.66665
23.16000,192.99997,62.24810,1.67826,6.91646,192.99997
23.20000,193.33327,62.33726,1.68116,6.92636,193.33327
23.24000,193.66667,62.54264,1.68406,6.94918,193.66667
23.28000,194.00002,62.59020,1.68696,6.95447,194.00002
23.32000,194.33334,62.58349,1.68986,6.95372,194.33334
23.36000,194.66678,62.74107,1.69275,6.97123,194.66678
23.40000,195.00002,62.58726,1.69565,6.95414,195.00002
23.44000,195.33329,62.89413,1.69855,6.98824,195.33329
23.48000,195.66659,62.92024,1.70145,6.99114,195.66659
23.52000,195.99997,62.77898,1.70435,6.97544,195.99997
23.56000,196.33340,63.06028,1.70725,7.00670,196.33340
23.60000,196.66659,63.29138,1.71014,7.03238,196.66659
23.64000,196.99998,63.06974,1.71304,7.00775,196.99998
23.68000,197.33334,63.18587,1.71594,7.02065,197.33334
23.72000,197.66659,63.44695,1.71884,7.04966,197.66659
23.76000,197.99998,63.18205,1.72174,7.02023,197.99998
23.80000,198.33328,63.54408,1.72464,7.06045,198.33328
23.84000,198.66660,63.26826,1.72754,7.02981,198.66660
23.88000,199.00003,63.52360,1.73044,7.05818,199.00003
23.92000,199.33335,63.59923,1.73333,7.06658,199.33335
23.96000,199.66671,63.58361,1.73623,7.06485,199.66671
24.00000,200.00003,63.54291,1.73913,7.06032,200.00003
24.04000,200.33328,63.60164,1.74203,7.06685,200.33328
24.08000,200.66671,63.90293,1.74493,7.10033,200.66671
24.12000,201.00003,63.97953,1.74783,7.10884,201.00003
24.16000,201.33335,64.00339,1.75072,7.11149,201.33335
24.20000,201.66665,63.99692,1.75362,7.11077,201.66665
24.24000,201.99997,63.99732,1.75652,7.11081,201.99997
24.28000,202.33328,64.36855,1.75942,7.15206,202.33328
24.32000,202.66667,64.13902,1.76232,7.12656,202.66667
24.36000,202.99992,64.23248,1.76522,7.13694,202.99992
24.40000,203.33327,64.34313,1.76812,7.14924,203.33327
24.44000,203.66665,64.66362,1.77101,7.18485,203.66665
24.48000,203.99997,64.50232,1.77391,7.16692,203.99997
24.52000,204.33340,64.49943,1.77681,7.16660,204.33340
24.56000,204.66672,64.79039,1.77971,7.19893,204.66672
24.60000,205.00004,64.71334,1.78261,7.19037,205.00004
24.64000,205.33340,64.77016,1.78551,7.19668,205.33340
24.68000,205.66659,64.55610,1.78841,7.17290,205.66659
24.72000,205.99997,64.78711,1.79130,7.19857,205.99997
24.76000,206.33329,64.91338,1.79420,7.21260,206.33329
24.80000,206.66659,64.93253,1.79710,7.21473,206.66659
24.84000,207.00004,64.92817,1.80000,7.21424,207.00004
24.88000,207.33329,65.15232,1.80290,7.23915,207.33329
24.92000,207.66666,65.18009,1.80580,7.24223,207.66666
24.96000,208.00002,65.25219,1.80870,7.25024,208.00002
25.00000,208.33328,65.23186,1.81159,7.24798,208.33328
25.04000,208.66666,65.33879,1.81449,7.25987,208.66666
25.08000,209.00004,65.38028,1.81739,7.26448,209.00004
25.12000,209.33328,65.58375,1.82029,7.28708,209.33328
25.16000,209.66671,65.59619,1.82319,7.28847,209.66671
25.20000,210.00003,65.49176,1.82609,7.27686,210.00003
25.24000,210.33328,65.76459,1.82899,7.30718,210.33328
25.28000,210.66673,65.66315,1.83188,7.29591,210.66673
25.32000,210.99998,65.65056,1.83478,7.29451,210.99998
25.36000,211.33328,65.74912,1.83768,7.30546,211.33328
25.40000,211.66665,65.78306,1.84058,7.30923,211.66665
25.44000,211.99998,65.69524,1.84348,7.29947,211.99998
25.48000,212.33335,65.83846,1.84638,7.31538,212.33335
25.52000,212.66660,66.15499,1.84927,7.35055,212.66660
25.56000,212.99995,66.10914,1.85217,7.34546,212.99995
25.60000,213.33335,66.09586,1.85507,7.34399,213.33335
25.64000,213.66665,66.17061,1.85797,7.35229,213.66665
25.68000,214.00005,66.21239,1.86087,7.35693,214.00005
25.72000,214.33335,66.30124,1.86377,7.36681,214.33335
25.76000,214.66665,66.34910,1.86667,7.37212,214.66665
25.80000,215.00010,66.20935,1.86957,7.35659,215.00010
25.84000,215.33327,66.64137,1.87246,7.40460,215.33327
25.88000,215.66667,66.76129,1.87536,7.41792,215.66667
25.92000,216.00002,66.65568,1.87826,7.40619,216.00002
25.96000,216.33327,66.80503,1.88116,7.42278,216.33327
26.00000,216.66661,66.85822,1.88406,7.42869,216.66661
26.04000,216.99997,66.74434,1.88696,7.41604,216.99997
26.08000,217.33321,66.89809,1.88985,7.43312,217.33321
26.12000,217.66672,67.04915,1.89275,7.44991,217.66672
26.16000,217.99996,67.06331,1.89565,7.45148,217.99996
26.20000,218.33329,67.17906,1.89855,7.46434,218.33329
26.24000,218.66672,67.08016,1.90145,7.45335,218.66672
26.28000,218.99998,67.27207,1.90435,7.47467,218.99998
26.32000,219.33334,67.36935,1.90725,7.48548,219.33334
26.36000,219.66673,67.44915,1.91015,7.49435,219.66673
26.40000,219.99998,67.56514,1.91304,7.50724,219.99998
26.44000,220.33334,67.72511,1.91594,7.52501,220.33334
26.48000,220.66666,67.88842,1.91884,7.54316,220.66666
26.52000,220.99990,67.62000,1.92174,7.51333,220.99990
26.56000,221.33335,67.78252,1.92464,7.53139,221.33335
26.60000,221.66666,67.84673,1.92754,7.53853,221.66666
26.64000,222.00003,67.91036,1.93044,7.54560,222.00003
26.68000,222.33335,68.19622,1.93333,7.57736,222.33335
26.72000,222.66660,68.18917,1.93623,7.57657,222.66660
26.76000,222.99998,68.24560,1.93913,7.58284,222.99998
26.80000,223.33328,68.24878,1.94203,7.58320,223.33328
26.84000,223.66660,68.39622,1.94493,7.59958,223.66660
26.88000,224.00009,68.25774,1.94783,7.58419,224.00009
26.92000,224.33328,68.52014,1.95072,7.61335,224.33328
26.96000,224.66667,68.52308,1.95362,7.61368,224.66667
27.00000,225.00003,68.54904,1.95652,7.61656,225.00003
27.04000,225.33327,68.85445,1.95942,7.65049,225.33327
27.08000,225.66667,68.77485,1.96232,7.64165,225.66667
27.12000,226.00003,68.91773,1.96522,7.65753,226.00003
27.16000,226.33329,69.08128,1.96812,7.67570,226.33329
27.20000,226.66665,69.01295,1.97101,7.66811,226.66665
27.24000,226.99997,69.16397,1.97391,7.68489,226.99997
27.28000,227.33334,69.20751,1.97681,7.68972,227.33334
27.32000,227.66672,69.26159,1.97971,7.69573,227.66672
27.36000,227.99997,69.47055,1.98261,7.71895,227.99997
27.40000,228.33334,69.39634,1.98551,7.71070,228.33334
27.44000,228.66666,69.43141,1.98841,7.71460,228.66666
27.48000,229.00004,69.67838,1.99130,7.74204,229.00004
27.52000,229.33334,69.68675,1.99420,7.74297,229.33334
27.56000,229.66666,69.77218,1.99710,7.75246,229.66666
27.60000,230.00002,69.88533,2.00000,7.76504,230.00002
27.64000,230.33336,70.00117,2.00290,7.77791,230.33336
27.68000,230.66666,70.08018,2.00580,7.78669,230.66666
27.72000,231.00004,70.18564,2.00870,7.79840,231.00004
27.76000,231.33328,70.58009,2.01159,7.84223,231.33328
27.80000,231.66658,70.47424,2.01449,7.83047,231.66658
27.84000,232.00003,70.52435,2.01739,7.83604,232.00003
27.88000,232.33328,70.68016,2.02029,7.85335,232.33328
27.92000,232.66666,70.76054,2.02319,7.86228,232.66666
27.96000,233.00003,70.75751,2.02609,7.86195,233.00003
28.00000,233.33322,71.04812,2.02898,7.89424,233.33322
28.04000,233.66665,71.14701,2.03188,7.90522,233.66665
28.08000,234.00003,71.07178,2.03478,7.89686,234.00003
28.12000,234.33328,71.19110,2.03768,7.91012,234.33328
28.16000,234.66678,71.35460,2.04058,7.92829,234.66678
28.20000,234.99997,71.30488,2.04348,7.92276,234.99997
28.24000,235.33335,71.55744,2.04638,7.95083,235.33335
28.28000,235.66671,71.61161,2.04928,7.95685,235.66671
28.32000,235.99997,71.56493,2.05217,7.95166,235.99997
28.36000,236.33335,71.52016,2.05507,7.94668,236.33335
28.40000,236.66659,71.78432,2.05797,7.97604,236.66659
28.44000,236.99997,71.74161,2.06087,7.97129,236.99997
28.48000,237.33340,72.00900,2.06377,8.00100,237.33340
28.52000,237.66667,71.95762,2.06667,7.99529,237.66667
28.56000,237.99991,71.94527,2.06956,7.99392,237.99991
28.60000,238.33334,72.05505,2.07246,8.00612,238.33334
28.64000,238.66666,72.26998,2.07536,8.03000,238.66666
28.68000,239.00002,72.21242,2.07826,8.02360,239.00002
28.72000,239.33334,72.44225,2.08116,8.04914,239.33334
28.76000,239.66666,72.45758,2.08406,8.05084,239.66666
28.80000,240.00004,72.33243,2.08696,8.03694,240.00004
28.84000,240.33329,72.55937,2.08985,8.06215,240.33329
28.88000,240.66664,72.50103,2.09275,8.05567,240.66664
28.92000,241.00004,72.45890,2.09565,8.05099,241.00004
28.96000,241.33323,72.67178,2.09855,8.07464,241.33323
29.00000,241.66666,72.83959,2.10145,8.09329,241.66666
29.04000,242.00009,72.82558,2.10435,8.09173,242.00009
29.08000,242.33328,73.07187,2.10725,8.11910,242.33328
29.12000,242.66671,73.16390,2.11015,8.12932,242.66671
29.16000,242.99996,72.98733,2.11304,8.10970,242.99996
29.20000,243.33321,73.28808,2.11594,8.14312,243.33321
29.24000,243.66671,73.36846,2.11884,8.15205,243.66671
29.28000,243.99996,73.49782,2.12174,8.16642,243.99996
29.32000,244.33335,73.45168,2.12464,8.16130,244.33335
29.36000,244.66671,73.54171,2.12754,8.17130,244.66671
29.40000,244.99997,73.47387,2.13043,8.16376,244.99997
29.44000,245.33335,73.92661,2.13333,8.21407,245.33335
29.48000,245.66665,73.78387,2.13623,8.19821,245.66665
29.52000,246.00003,73.73533,2.13913,8.19281,246.00003
29.56000,246.33333,74.10221,2.14203,8.23358,246.33333
29.60000,246.66660,74.23177,2.14493,8.24797,246.66660
29.64000,246.99997,74.15575,2.14783,8.23953,246.99997
29.68000,247.33335,74.24445,2.15072,8.24938,247.33335
29.72000,247.66659,74.44499,2.15362,8.27167,247.66659
29.76000,247.99997,74.43500,2.15652,8.27056,247.99997
29.80000,248.33329,74.54364,2.15942,8.28263,248.33329
29.84000,248.66659,74.89842,2.16232,8.32205,248.66659
29.88000,249.00010,74.75740,2.16522,8.30638,249.00010
29.92000,249.33329,75.08171,2.16812,8.34241,249.33329
29.96000,249.66665,74.99594,2.17101,8.33288,249.66665
30.00000,250.00010,75.14068,2.17391,8.34896,250.00010
30.04000,250.33329,75.26294,2.17681,8.36255,250.33329
30.08000,250.66664,75.22018,2.17971,8.35780,250.66664
30.12000,250.99996,75.16552,2.18261,8.35172,250.99996
30.16000,251.33327,75.58055,2.18551,8.39784,251.33327
30.20000,251.66664,75.45711,2.18841,8.38412,251.66664
30.24000,251.99994,75.71334,2.19130,8.41259,251.99994
30.28000,252.33334,75.63433,2.19420,8.40381,252.33334
30.32000,252.66672,75.72803,2.19710,8.41423,252.66672
30.36000,252.99996,75.75189,2.20000,8.41688,252.99996
30.40000,253.33334,76.06194,2.20290,8.45133,253.33334
30.44000,253.66664,76.16975,2.20580,8.46331,253.66664
30.48000,253.99996,75.87978,2.20870,8.43109,253.99996
30.52000,254.33341,76.24131,2.21159,8.47126,254.33341
30.56000,254.66666,76.35554,2.21449,8.48395,254.66666
30.60000,254.99998,76.31793,2.21739,8.47977,254.99998
30.64000,255.33333,76.57802,2.22029,8.50867,255.33333
30.68000,255.66658,76.75132,2.22319,8.52792,255.66658
30.72000,256.00001,76.80197,2.22609,8.53355,256.00001
30.76000,256.33333,76.72286,2.22899,8.52476,256.33333
30.80000,256.66658,76.78717,2.23188,8.53191,256.66658
30.84000,257.00003,77.01112,2.23478,8.55679,257.00003
30.88000,257.33327,77.14480,2.23768,8.57164,257.33327
30.92000,257.66665,77.30369,2.24058,8.58930,257.66665
30.96000,257.99995,77.49840,2.24348,8.61093,257.99995
31.00000,258.33322,77.69486,2.24638,8.63276,258.33322
31.04000,258.66663,77.56727,2.24927,8.61859,258.66663
31.08000,259.00001,77.70633,2.25217,8.63404,259.00001
31.12000,259.33325,77.48713,2.25507,8.60968,259.33325
31.16000,259.66672,77.95320,2.25797,8.66147,259.66672
31.20000,260.00002,78.06576,2.26087,8.67397,260.00002
31.24000,260.33327,77.98729,2.26377,8.66525,260.33327
31.28000,260.66670,77.99008,2.26667,8.66556,260.66670
31.32000,260.99995,78.11895,2.26956,8.67988,260.99995
31.36000,261.33332,78.28368,2.27246,8.69819,261.33332
31.40000,261.66666,78.22632,2.27536,8.69181,261.66666
31.44000,261.99991,78.39727,2.27826,8.71081,261.99991
31.48000,262.33340,78.41172,2.28116,8.71241,262.33340
31.52000,262.66670,78.35397,2.28406,8.70600,262.66670
31.56000,262.99996,78.57336,2.28696,8.73037,262.99996
31.60000,263.33332,78.83346,2.28986,8.75927,263.33332
31.64000,263.66657,78.67779,2.29275,8.74198,263.66657
31.68000,264.00004,78.86192,2.29565,8.76243,264.00004
31.72000,264.33339,79.00216,2.29855,8.77802,264.33339
31.76000,264.66671,79.27935,2.30145,8.80882,264.66671
31.80000,265.00015,79.17276,2.30435,8.79697,265.00015
31.84000,265.33326,79.30947,2.30725,8.81216,265.33326
31.88000,265.66658,79.48257,2.31014,8.83140,265.66658
31.92000,266.00009,79.56178,2.31304,8.84020,266.00009
31.96000,266.33335,79.79302,2.31594,8.86589,266.33335
32.00000,266.66665,79.79615,2.31884,8.86624,266.66665
32.04000,267.00003,79.82912,2.32174,8.86990,267.00003
32.08000,267.33333,80.09235,2.32464,8.89915,267.33333
32.12000,267.66671,80.22573,2.32754,8.91397,267.66671
32.16000,267.99995,80.33094,2.33043,8.92566,267.99995
32.20000,268.33320,80.40329,2.33333,8.93370,268.33320
32.24000,268.66673,80.43239,2.33623,8.93693,268.66673
32.28000,269.00003,80.40540,2.33913,8.93393,269.00003
32.32000,269.33333,80.59672,2.34203,8.95519,269.33333
32.36000,269.66676,80.69219,2.34493,8.96580,269.66676
32.40000,270.00001,80.58604,2.34783,8.95401,270.00001
32.44000,270.33338,80.94367,2.35073,8.99374,270.33338
32.48000,270.66663,81.03413,2.35362,9.00379,270.66663
32.52000,271.00002,80.98349,2.35652,8.99817,271.00002
32.56000,271.33340,81.25509,2.35942,9.02834,271.33340
32.60000,271.66659,81.40488,2.36232,9.04499,271.66659
32.64000,271.99997,81.29217,2.36522,9.03246,271.99997
32.68000,272.33338,81.66694,2.36812,9.07410,272.33338
32.72000,272.66664,81.70367,2.37101,9.07819,272.66664
32.76000,272.99995,81.66674,2.37391,9.07408,272.99995
32.80000,273.33329,81.79478,2.37681,9.08831,273.33329
32.84000,273.66659,81.92184,2.37971,9.10243,273.66659
32.88000,274.00002,81.94202,2.38261,9.10467,274.00002
32.92000,274.33334,82.18639,2.38551,9.13182,274.33334
32.96000,274.66670,82.25468,2.38841,9.13941,274.66670
33.00000,275.00002,82.26354,2.39130,9.14039,275.00002
33.04000,275.33326,82.48558,2.39420,9.16506,275.33326
33.08000,275.66671,82.56816,2.39710,9.17424,275.66671
33.12000,276.00003,82.60215,2.40000,9.17802,276.00003
33.16000,276.33328,82.74856,2.40290,9.19428,276.33328
33.20000,276.66671,82.66554,2.40580,9.18506,276.66671
33.24000,276.99996,82.84369,2.40870,9.20485,276.99996
33.28000,277.33326,82.89889,2.41159,9.21099,277.33326
33.32000,277.66673,82.87386,2.41449,9.20821,277.66673
33.36000,277.99997,83.09129,2.41739,9.23237,277.99997
33.40000,278.33328,83.31637,2.42029,9.25737,278.33328
33.44000,278.66665,83.39082,2.42319,9.26565,278.66665
33.48000,278.99995,83.42844,2.42609,9.26983,278.99995
33.52000,279.33333,83.57979,2.42899,9.28664,279.33333
33.56000,279.66663,83.59576,2.43188,9.28842,279.66663
33.60000,280.00010,83.56892,2.43478,9.28544,280.00010
33.64000,280.33329,84.02470,2.43768,9.33608,280.33329
33.68000,280.66659,84.01020,2.44058,9.33447,280.66659
33.72000,281.00003,83.93320,2.44348,9.32591,281.00003
33.76000,281.33333,84.11958,2.44638,9.34662,281.33333
33.80000,281.66665,84.39427,2.44928,9.37714,281.66665
33.84000,282.00001,84.20412,2.45217,9.35601,282.00001
33.88000,282.33325,84.31232,2.45507,9.36804,282.33325
33.92000,282.66659,84.28553,2.45797,9.36506,282.66659
33.96000,283.00002,84.46059,2.46087,9.38451,283.00002
34.00000,283.33327,84.76962,2.46377,9.41885,283.33327
34.04000,283.66664,84.87601,2.46667,9.43067,283.66664
34.08000,284.00002,85.00973,2.46957,9.44553,284.00002
34.12000,284.33327,84.97437,2.47246,9.44160,284.33327
34.16000,284.66672,85.35231,2.47536,9.48359,284.66672
34.20000,284.99996,85.20561,2.47826,9.46729,284.99996
34.24000,285.33328,85.25631,2.48116,9.47292,285.33328
34.28000,285.66672,85.44553,2.48406,9.49395,285.66672
34.32000,285.99996,85.49789,2.48696,9.49977,285.99996
34.36000,286.33332,85.45307,2.48986,9.49479,286.33332
34.40000,286.66664,85.58841,2.49275,9.50982,286.66664
34.44000,287.00003,85.58361,2.49565,9.50929,287.00003
34.48000,287.33334,85.81529,2.49855,9.53503,287.33334
34.52000,287.66666,85.98257,2.50145,9.55362,287.66666
34.56000,287.99996,86.27597,2.50435,9.58622,287.99996
34.60000,288.33333,86.22675,2.50725,9.58075,288.33333
34.64000,288.66658,86.34935,2.51014,9.59437,288.66658
34.68000,288.99996,86.35572,2.51304,9.59508,288.99996
34.72000,289.33341,86.55659,2.51594,9.61740,289.33341
34.76000,289.66671,86.64128,2.51884,9.62681,289.66671
34.80000,290.00008,86.70285,2.52174,9.63365,290.00008
34.84000,290.33333,86.74797,2.52464,9.63866,290.33333
34.88000,290.66665,86.82335,2.52754,9.64704,290.66665
34.92000,291.00006,86.76820,2.53044,9.64091,291.00006
34.96000,291.33325,72.86565,2.53333,8.09618,291.33325
35.00000,291.66672,1.69078,2.53623,0.18786,291.66672
35.04000,292.00008,-1.76110,2.53913,-0.19568,292.00008
35.08000,292.33327,0.41489,2.54203,0.04610,292.33327
35.12000,292.66670,0.36821,2.54493,0.04091,292.66670
35.16000,292.99995,0.11443,2.54783,0.01271,292.99995
35.20000,293.33327,0.05377,2.55072,0.00597,293.33327
35.24000,293.66670,-0.03381,2.55362,-0.00376,293.66670
35.28000,293.99995,-0.11965,2.55652,-0.01329,293.99995
35.32000,294.33334,0.19836,2.55942,0.02204,294.33334
35.36000,294.66677,0.16099,2.56232,0.01789,294.66677
35.40000,294.99996,-0.02336,2.56522,-0.00260,294.99996
35.44000,295.33332,0.03246,2.56812,0.00361,295.33332
35.48000,295.66670,0.31168,2.57101,0.03463,295.66670
35.52000,295.99994,0.11465,2.57391,0.01274,295.99994
35.56000,296.33334,0.27022,2.57681,0.03002,296.33334
35.60000,296.66666,0.20390,2.57971,0.02266,296.66666
35.64000,296.99996,0.11945,2.58261,0.01327,296.99996
35.68000,297.33328,0.36841,2.58551,0.04093,297.33328
35.72000,297.66658,0.25846,2.58841,0.02872,297.66658
35.76000,297.99996,0.00861,2.59130,0.00096,297.99996
35.80000,298.33326,0.13084,2.59420,0.01454,298.33326
35.84000,298.66656,0.33370,2.59710,0.03708,298.66656
35.88000,299.00009,0.29153,2.60000,0.03239,299.00009
35.92000,299.33328,0.20559,2.60290,0.02284,299.33328
35.96000,299.66665,0.28746,2.60580,0.03194,299.66665
36.00000,300.00007,0.01879,2.60870,0.00209,300.00007
36.04000,300.33326,0.12354,2.61159,0.01373,300.33326
36.08000,300.66663,0.32968,2.61449,0.03663,300.66663
36.12000,301.00003,0.12149,2.61739,0.01350,301.00003
36.15400,301.28328,0.20983,2.61985,0.02331,301.28328