File: EPR/EPR/RDSO EPR Tensile 500.is_tens_RawData/Specimen_RawData_1.csv
Time,Extension,Load,Tensile strain,Tensile stress,Corrected Position
(sec),(mm),(N),(mm/mm),(MPa),(mm)
0.00000,0.00000,0.05456,0.00000,0.00606,0.00000
0.04000,0.09831,0.67801,0.00085,0.07533,0.09831
0.08000,0.41912,1.47206,0.00364,0.16356,0.41912
0.12000,0.83556,1.70081,0.00727,0.18898,0.83556
0.16000,1.27375,2.29756,0.01108,0.25528,1.27375
0.20000,1.65106,2.57232,0.01436,0.28581,1.65106
0.24000,1.98456,3.27248,0.01726,0.36361,1.98456
0.28000,2.32169,3.48222,0.02019,0.38691,2.32169
0.32000,2.66087,4.08257,0.02314,0.45362,2.66087
0.36000,2.99681,4.46639,0.02606,0.49627,2.99681
0.40000,3.33131,4.90092,0.02897,0.54455,3.33131
0.44000,3.66544,5.25065,0.03187,0.58341,3.66544
0.48000,3.99925,5.41844,0.03478,0.60205,3.99925
0.52000,4.33294,5.88551,0.03768,0.65395,4.33294
0.56000,4.66644,6.00953,0.04058,0.66773,4.66644
0.60000,4.99987,6.50856,0.04348,0.72317,4.99987
0.64000,5.33331,6.58720,0.04638,0.73191,5.33331
0.68000,5.66656,7.12657,0.04927,0.79184,5.66656
0.72000,5.99994,7.23926,0.05217,0.80436,5.99994
0.76000,6.33337,7.45321,0.05507,0.82813,6.33337
0.80000,6.66662,7.81424,0.05797,0.86825,6.66662
0.84000,7.00000,8.07041,0.06087,0.89671,7.00000
0.88000,7.33337,8.11469,0.06377,0.90163,7.33337
0.92000,7.66662,8.36041,0.06667,0.92893,7.66662
0.96000,8.00012,8.43565,0.06957,0.93729,8.00012
1.00000,8.33337,8.68098,0.07246,0.96455,8.33337
1.04000,8.66669,9.10712,0.07536,1.01190,8.66669
1.08000,9.00000,9.08621,0.07826,1.00958,9.00000
1.12000,9.33331,9.07815,0.08116,1.00868,9.33331
1.16000,9.66675,9.50510,0.08406,1.05612,9.66675
1.20000,10.00006,9.59886,0.08696,1.06654,10.00006
1.24000,10.33331,9.68105,0.08985,1.07567,10.33331
1.28000,10.66669,9.91641,0.09275,1.10182,10.66669
1.32000,11.00000,10.00164,0.09565,1.11129,11.00000
1.36000,11.33331,10.11572,0.09855,1.12397,11.33331
1.40000,11.66669,10.25870,0.10145,1.13986,11.66669
1.44000,11.99994,10.40792,0.10435,1.15644,11.99994
1.48000,12.33337,10.51512,0.10725,1.16835,12.33337
1.52000,12.66669,10.79062,0.11015,1.19896,12.66669
1.56000,13.00006,11.04667,0.11304,1.22741,13.00006
1.60000,13.33344,10.87288,0.11594,1.20810,13.33344
1.64000,13.66668,11.07501,0.11884,1.23056,13.66668
1.68000,14.00000,11.05177,0.12174,1.22797,14.00000
1.72000,14.33344,11.27934,0.12464,1.25326,14.33344
1.76000,14.66662,11.44505,0.12754,1.27167,14.66662
1.80000,15.00006,11.58320,0.13044,1.28702,15.00006
1.84000,15.33344,11.70718,0.13333,1.30080,15.33344
1.88000,15.66656,11.92363,0.13623,1.32485,15.66656
1.92000,16.00006,11.85427,0.13913,1.31714,16.00006
1.96000,16.33337,12.21799,0.14203,1.35755,16.33337
2.00000,16.66662,12.23817,0.14493,1.35980,16.66662
2.04000,17.00012,12.08218,0.14783,1.34246,17.00012
2.08000,17.33331,12.30510,0.15072,1.36723,17.33331
2.12000,17.66669,12.59833,0.15362,1.39981,17.66669
2.16000,18.00006,12.42567,0.15652,1.38063,18.00006
2.20000,18.33337,12.52557,0.15942,1.39173,18.33337
2.24000,18.66675,12.60228,0.16232,1.40025,18.66675
2.28000,19.00006,12.70112,0.16522,1.41124,19.00006
2.32000,19.33337,12.71366,0.16812,1.41263,19.33337
2.36000,19.66675,12.87908,0.17102,1.43101,19.66675
2.40000,20.00000,13.17865,0.17391,1.46429,20.00000
2.44000,20.33331,13.02776,0.17681,1.44753,20.33331
2.48000,20.66675,13.30635,0.17971,1.47848,20.66675
2.52000,21.00000,13.41364,0.18261,1.49040,21.00000
2.56000,21.33337,13.29930,0.18551,1.47770,21.33337
2.60000,21.66668,13.38401,0.18841,1.48711,21.66668
2.64000,22.00000,13.41977,0.19130,1.49109,22.00000
2.68000,22.33343,13.46755,0.19420,1.49639,22.33343
2.72000,22.66668,13.75909,0.19710,1.52879,22.66668
2.76000,23.00006,13.70587,0.20000,1.52287,23.00006
2.80000,23.33343,13.77913,0.20290,1.53101,23.33343
2.84000,23.66669,13.92923,0.20580,1.54769,23.66669
2.88000,24.00006,13.80323,0.20870,1.53369,24.00006
2.92000,24.33337,13.84131,0.21159,1.53792,24.33337
2.96000,24.66662,14.05085,0.21449,1.56121,24.66662
3.00000,25.00006,13.89181,0.21739,1.54353,25.00006
3.04000,25.33331,14.16263,0.22029,1.57363,25.33331
3.08000,25.66662,14.32704,0.22319,1.59189,25.66662
3.12000,26.00000,14.15279,0.22609,1.57253,26.00000
3.16000,26.33331,14.36961,0.22899,1.59662,26.33331
3.20000,26.66662,14.49108,0.23188,1.61012,26.66662
3.24000,27.00000,14.37321,0.23478,1.59702,27.00000
3.28000,27.33337,14.52535,0.23768,1.61393,27.33337
3.32000,27.66675,14.61998,0.24058,1.62444,27.66675
3.36000,28.00006,14.72936,0.24348,1.63660,28.00006
3.40000,28.33337,14.74114,0.24638,1.63790,28.33337
3.44000,28.66668,14.91850,0.24928,1.65761,28.66668
3.48000,29.00000,15.06219,0.25217,1.67358,29.00000
3.52000,29.33343,14.98086,0.25507,1.66454,29.33343
3.56000,29.66668,15.10613,0.25797,1.67846,29.66668
3.60000,30.00000,15.05377,0.26087,1.67264,30.00000
3.64000,30.33343,15.23625,0.26377,1.69292,30.33343
3.68000,30.66668,15.20571,0.26667,1.68952,30.66668
3.72000,31.00000,15.23836,0.26957,1.69315,31.00000
3.76000,31.33337,15.41915,0.27246,1.71324,31.33337
3.80000,31.66656,15.65924,0.27536,1.73992,31.66656
3.84000,32.00012,15.53210,0.27826,1.72579,32.00012
3.88000,32.33343,15.52583,0.28116,1.72509,32.33343
3.92000,32.66662,15.72446,0.28406,1.74716,32.66662
3.96000,33.00012,15.82617,0.28696,1.75846,33.00012
4.00000,33.33337,15.83741,0.28986,1.75971,33.33337
4.04000,33.66668,15.91512,0.29275,1.76835,33.66668
4.08000,34.00012,15.93207,0.29565,1.77023,34.00012
4.12000,34.33337,15.94275,0.29855,1.77142,34.33337
4.16000,34.66668,16.20497,0.30145,1.80055,34.66668
4.20000,35.00006,16.20208,0.30435,1.80023,35.00006
4.24000,35.33331,16.19231,0.30725,1.79915,35.33331
4.28000,35.66675,16.46786,0.31015,1.82976,35.66675
4.32000,35.99999,16.51912,0.31304,1.83546,35.99999
4.36000,36.33331,16.47984,0.31594,1.83109,36.33331
4.40000,36.66668,16.64153,0.31884,1.84906,36.66668
4.44000,36.99993,16.45084,0.32174,1.82787,36.99993
4.48000,37.33337,16.70895,0.32464,1.85655,37.33337
4.52000,37.66675,16.93285,0.32754,1.88143,37.66675
4.56000,38.00000,16.93273,0.33043,1.88141,38.00000
4.60000,38.33343,16.90625,0.33333,1.87847,38.33343
4.64000,38.66668,17.16160,0.33623,1.90684,38.66668
4.68000,39.00006,17.13897,0.33913,1.90433,39.00006
4.72000,39.33343,17.20264,0.34203,1.91140,39.33343
4.76000,39.66668,17.33531,0.34493,1.92615,39.66668
4.80000,39.99999,17.28942,0.34783,1.92105,39.99999
4.84000,40.33337,17.20034,0.35072,1.91115,40.33337
4.88000,40.66668,17.74008,0.35362,1.97112,40.66668
4.92000,41.00006,17.66374,0.35652,1.96264,41.00006
4.96000,41.33331,17.69695,0.35942,1.96633,41.33331
5.00000,41.66662,17.86317,0.36232,1.98480,41.66662
5.04000,42.00005,17.66793,0.36522,1.96310,42.00005
5.08000,42.33337,17.77588,0.36812,1.97510,42.33337
5.12000,42.66668,17.99905,0.37101,1.99989,42.66668
5.16000,43.00006,17.95993,0.37391,1.99555,43.00006
5.20000,43.33337,17.93723,0.37681,1.99303,43.33337
5.24000,43.66674,18.16951,0.37971,2.01883,43.66674
5.28000,44.00006,18.42703,0.38261,2.04745,44.00006
5.32000,44.33337,18.30085,0.38551,2.03343,44.33337
5.36000,44.66674,18.51483,0.38841,2.05720,44.66674
5.40000,44.99999,18.56516,0.39130,2.06280,44.99999
5.44000,45.33337,18.67517,0.39420,2.07502,45.33337
5.48000,45.66668,18.77194,0.39710,2.08577,45.66668
5.52000,45.99999,18.77103,0.40000,2.08567,45.99999
5.56000,46.33337,18.92724,0.40290,2.10303,46.33337
5.60000,46.66662,18.97984,0.40580,2.10887,46.66662
5.64000,46.99999,19.00184,0.40870,2.11132,46.99999
5.68000,47.33343,19.09613,0.41160,2.12179,47.33343
5.72000,47.66668,19.32622,0.41449,2.14736,47.66668
5.76000,48.00012,19.19275,0.41739,2.13253,48.00012
5.80000,48.33337,19.18327,0.42029,2.13147,48.33337
5.84000,48.66662,19.61507,0.42319,2.17945,48.66662
5.88000,49.00006,19.45441,0.42609,2.16160,49.00006
5.92000,49.33337,19.56481,0.42899,2.17387,49.33337
5.96000,49.66662,19.68803,0.43188,2.18756,49.66662
6.00000,50.00005,19.94761,0.43478,2.21640,50.00005
6.04000,50.33337,19.87419,0.43768,2.20824,50.33337
6.08000,50.66668,20.10844,0.44058,2.23427,50.66668
6.12000,51.00005,20.14153,0.44348,2.23795,51.00005
6.16000,51.33324,20.30682,0.44638,2.25631,51.33324
6.20000,51.66668,20.40964,0.44928,2.26774,51.66668
6.24000,52.00006,20.15973,0.45217,2.23997,52.00006
6.28000,52.33337,20.47442,0.45507,2.27494,52.33337
6.32000,52.66680,20.70128,0.45797,2.30014,52.66680
6.36000,53.00005,20.60236,0.46087,2.28915,53.00005
6.40000,53.33343,20.67914,0.46377,2.29768,53.33343
6.44000,53.66668,21.09715,0.46667,2.34413,53.66668
6.48000,53.99993,20.93397,0.46956,2.32600,53.99993
6.52000,54.33343,21.04814,0.47246,2.33868,54.33343
6.56000,54.66668,21.17236,0.47536,2.35248,54.66668
6.60000,55.00000,21.15093,0.47826,2.35010,55.00000
6.64000,55.33337,21.08255,0.48116,2.34251,55.33337
6.68000,55.66668,21.32203,0.48406,2.36911,55.66668
6.72000,55.99999,21.25497,0.48696,2.36166,55.99999
6.76000,56.33343,21.55132,0.48986,2.39459,56.33343
6.80000,56.66662,21.69824,0.49275,2.41092,56.66662
6.84000,56.99999,21.61188,0.49565,2.40132,56.99999
6.88000,57.33343,21.75871,0.49855,2.41763,57.33343
6.92000,57.66668,21.96580,0.50145,2.44064,57.66668
6.96000,58.00012,21.90974,0.50435,2.43442,58.00012
7.00000,58.33337,22.18894,0.50725,2.46544,58.33337
7.04000,58.66668,22.23579,0.51015,2.47064,58.66668
7.08000,59.00012,22.18921,0.51304,2.46547,59.00012
7.12000,59.33337,22.22360,0.51594,2.46929,59.33337
7.16000,59.66668,22.37383,0.51884,2.48598,59.66668
7.20000,59.99999,22.72819,0.52174,2.52535,59.99999
7.24000,60.33331,22.78596,0.52464,2.53177,60.33331
7.28000,60.66674,23.03210,0.52754,2.55912,60.66674
7.32000,60.99999,22.67754,0.53043,2.51973,60.99999
7.36000,61.33337,22.81280,0.53333,2.53476,61.33337
7.40000,61.66668,23.00273,0.53623,2.55586,61.66668
7.44000,61.99999,23.09154,0.53913,2.56573,61.99999
7.48000,62.33336,23.14329,0.54203,2.57148,62.33336
7.52000,62.66668,23.38568,0.54493,2.59841,62.66668
7.56000,63.00006,23.39153,0.54783,2.59906,63.00006
7.60000,63.33343,23.36116,0.55073,2.59568,63.33343
7.64000,63.66668,23.62395,0.55362,2.62488,63.66668
7.68000,64.00005,23.76828,0.55652,2.64092,64.00005
7.72000,64.33343,23.58856,0.55942,2.62095,64.33343
7.76000,64.66668,23.92884,0.56232,2.65876,64.66668
7.80000,64.99999,24.08517,0.56522,2.67613,64.99999
7.84000,65.33330,24.17380,0.56812,2.68598,65.33330
7.88000,65.66662,24.43679,0.57101,2.71520,65.66662
7.92000,66.00011,24.24723,0.57391,2.69414,66.00011
7.96000,66.33330,24.25854,0.57681,2.69539,66.33330
8.00000,66.66661,24.43811,0.57971,2.71535,66.66661
8.04000,67.00005,24.74138,0.58261,2.74904,67.00005
8.08000,67.33336,24.50899,0.58551,2.72322,67.33336
8.12000,67.66674,24.90905,0.58841,2.76767,67.66674
8.16000,68.00012,24.88228,0.59131,2.76470,68.00012
8.20000,68.33330,24.93513,0.59420,2.77057,68.33330
8.24000,68.66667,25.24392,0.59710,2.80488,68.66667
8.28000,69.00005,24.98546,0.60000,2.77616,69.00005
8.32000,69.33337,25.23253,0.60290,2.80361,69.33337
8.36000,69.66668,25.41207,0.60580,2.82356,69.66668
8.40000,69.99999,25.66930,0.60870,2.85214,69.99999
8.44000,70.33336,25.69563,0.61159,2.85507,70.33336
8.48000,70.66668,25.77878,0.61449,2.86431,70.66668
8.52000,70.99999,25.67418,0.61739,2.85269,70.99999
8.56000,71.33336,25.58562,0.62029,2.84285,71.33336
8.60000,71.66661,26.00236,0.62319,2.88915,71.66661
8.64000,71.99999,26.23358,0.62609,2.91484,71.99999
8.68000,72.33343,26.18131,0.62899,2.90903,72.33343
8.72000,72.66668,26.48694,0.63188,2.94299,72.66668
8.76000,73.00005,26.49399,0.63478,2.94378,73.00005
8.80000,73.33343,26.40800,0.63768,2.93422,73.33343
8.84000,73.66662,26.70983,0.64058,2.96776,73.66662
8.88000,74.00006,26.87397,0.64348,2.98600,74.00006
8.92000,74.33336,26.75091,0.64638,2.97232,74.33336
8.96000,74.66668,26.96324,0.64928,2.99592,74.66668
9.00000,74.99999,27.13875,0.65217,3.01542,74.99999
9.04000,75.33330,27.19059,0.65507,3.02118,75.33330
9.08000,75.66668,27.47151,0.65797,3.05239,75.66668
9.12000,76.00005,27.32723,0.66087,3.03636,76.00005
9.16000,76.33330,27.65438,0.66377,3.07271,76.33330
9.20000,76.66662,27.67846,0.66667,3.07538,76.66662
9.24000,76.99999,27.77211,0.66957,3.08579,76.99999
9.28000,77.33330,27.61684,0.67246,3.06854,77.33330
9.32000,77.66668,27.92746,0.67536,3.10305,77.66668
9.36000,78.00005,27.97500,0.67826,3.10833,78.00005
9.40000,78.33336,28.06155,0.68116,3.11795,78.33336
9.44000,78.66668,28.29404,0.68406,3.14378,78.66668
9.48000,78.99999,28.42181,0.68696,3.15798,78.99999
9.52000,79.33336,28.42463,0.68986,3.15829,79.33336
9.56000,79.66667,28.59761,0.69275,3.17751,79.66667
9.60000,79.99999,28.65808,0.69565,3.18423,79.99999
9.64000,80.33343,28.71977,0.69855,3.19109,80.33343
9.68000,80.66662,28.86025,0.70145,3.20670,80.66662
9.72000,81.00005,28.94024,0.70435,3.21558,81.00005
9.76000,81.33342,29.09892,0.70725,3.23321,81.33342
9.80000,81.66661,29.15697,0.71014,3.23966,81.66661
9.84000,81.99998,29.32666,0.71304,3.25852,81.99998
9.88000,82.33330,29.45970,0.71594,3.27330,82.33330
9.92000,82.66667,29.53587,0.71884,3.28176,82.66667
9.96000,83.00011,29.44157,0.72174,3.27129,83.00011
10.00000,83.33337,29.50648,0.72464,3.27850,83.33337
10.04000,83.66661,29.85668,0.72754,3.31741,83.66661
10.08000,84.00005,29.98959,0.73044,3.33218,84.00005
10.12000,84.33335,30.00943,0.73333,3.33438,84.33335
10.16000,84.66667,30.23467,0.73623,3.35941,84.66667
10.20000,85.00005,30.23056,0.73913,3.35895,85.00005
10.24000,85.33330,30.35539,0.74203,3.37282,85.33330
10.28000,85.66667,30.39462,0.74493,3.37718,85.66667
10.32000,85.99998,30.55029,0.74783,3.39448,85.99998
10.36000,86.33336,30.60299,0.75072,3.40033,86.33336
10.40000,86.66667,30.95234,0.75362,3.43915,86.66667
10.44000,86.99999,31.02316,0.75652,3.44702,86.99999
10.48000,87.33337,30.92814,0.75942,3.43646,87.33337
10.52000,87.66674,31.06784,0.76232,3.45198,87.66674
10.56000,87.99999,31.19470,0.76522,3.46608,87.99999
10.60000,88.33342,31.29830,0.76812,3.47759,88.33342
10.64000,88.66661,31.42800,0.77101,3.49200,88.66661
10.68000,88.99999,31.43731,0.77391,3.49303,88.99999
10.72000,89.33342,31.47057,0.77681,3.49673,89.33342
10.76000,89.66668,31.83333,0.77971,3.53704,89.66668
10.80000,90.00004,31.88677,0.78261,3.54297,90.00004
10.84000,90.33336,31.87183,0.78551,3.54131,90.33336
10.88000,90.66661,32.22524,0.78841,3.58058,90.66661
10.92000,91.00005,32.37718,0.79130,3.59746,91.00005
10.96000,91.33336,32.25306,0.79420,3.58367,91.33336
11.00000,91.66667,32.46510,0.79710,3.60723,91.66667
11.04000,91.99998,32.47818,0.80000,3.60869,91.99998
11.08000,92.33330,32.59241,0.80290,3.62138,92.33330
11.12000,92.66674,32.80450,0.80580,3.64494,92.66674
11.16000,93.00006,32.74778,0.80870,3.63864,93.00006
11.20000,93.33336,32.80955,0.81159,3.64551,93.33336
11.24000,93.66667,33.25715,0.81449,3.69524,93.66667
11.28000,93.99999,33.10912,0.81739,3.67879,93.99999
11.32000,94.33337,33.11407,0.82029,3.67934,94.33337
11.36000,94.66674,33.47091,0.82319,3.71899,94.66674
11.40000,94.99999,33.61545,0.82609,3.73505,94.99999
11.44000,95.33335,33.56152,0.82899,3.72906,95.33335
11.48000,95.66673,33.66184,0.83188,3.74020,95.66673
11.52000,95.99999,33.81202,0.83478,3.75689,95.99999
11.56000,96.33336,33.75608,0.83768,3.75068,96.33336
11.60000,96.66655,34.02245,0.84058,3.78027,96.66655
11.64000,96.99998,34.11811,0.84348,3.79090,96.99998
11.68000,97.33342,34.24194,0.84638,3.80466,97.33342
11.72000,97.66667,34.42993,0.84928,3.82555,97.66667
11.76000,98.00011,34.48322,0.85217,3.83147,98.00011
11.80000,98.33342,34.64658,0.85507,3.84962,98.33342
11.84000,98.66667,34.80636,0.85797,3.86737,98.66667
11.88000,99.00005,34.90628,0.86087,3.87848,99.00005
11.92000,99.33336,34.89658,0.86377,3.87740,99.33336
11.96000,99.66660,35.12636,0.86667,3.90293,99.66660
12.00000,100.00005,35.06175,0.86957,3.89575,100.00005
12.04000,100.33330,35.10373,0.87246,3.90041,100.33330
12.08000,100.66668,35.22413,0.87536,3.91379,100.66668
12.12000,101.00004,35.25915,0.87826,3.91768,101.00004
12.16000,101.33330,35.51871,0.88116,3.94652,101.33330
12.20000,101.66667,35.70518,0.88406,3.96724,101.66667
12.24000,102.00005,35.68892,0.88696,3.96544,102.00005
12.28000,102.33330,35.73888,0.88985,3.97099,102.33330
12.32000,102.66673,36.15582,0.89275,4.01731,102.66673
12.36000,102.99998,36.19907,0.89565,4.02212,102.99998
12.40000,103.33336,36.22224,0.89855,4.02469,103.33336
12.44000,103.66674,36.29968,0.90145,4.03330,103.66674
12.48000,103.99998,36.35910,0.90435,4.03990,103.99998
12.52000,104.33342,36.61528,0.90725,4.06836,104.33342
12.56000,104.66667,36.58608,0.91014,4.06512,104.66667
12.60000,104.99999,36.68346,0.91304,4.07594,104.99999
12.64000,105.33337,36.62145,0.91594,4.06905,105.33337
12.68000,105.66667,36.93243,0.91884,4.10360,105.66667
12.72000,105.99999,37.03020,0.92174,4.11447,105.99999
12.76000,106.33335,37.03128,0.92464,4.11459,106.33335
12.80000,106.66661,37.34776,0.92754,4.14975,106.66661
12.84000,106.99999,37.33629,0.93043,4.14848,106.99999
12.88000,107.33336,37.45723,0.93333,4.16191,107.33336
12.92000,107.66661,37.60501,0.93623,4.17833,107.66661
12.96000,108.00011,37.66359,0.93913,4.18484,108.00011
13.00000,108.33342,37.62416,0.94203,4.18046,108.33342
13.04000,108.66674,37.88284,0.94493,4.20920,108.66674
13.08000,109.00005,38.11854,0.94783,4.23539,109.00005
13.12000,109.33336,38.10728,0.95072,4.23414,109.33336
13.16000,109.66673,38.34930,0.95362,4.26103,109.66673
13.20000,110.00005,38.57814,0.95652,4.28646,110.00005
13.24000,110.33336,38.34748,0.95942,4.26083,110.33336
13.28000,110.66673,38.58177,0.96232,4.28686,110.66673
13.32000,110.99998,38.71573,0.96522,4.30175,110.99998
13.36000,111.33336,38.68698,0.96812,4.29855,111.33336
13.40000,111.66668,38.89687,0.97101,4.32187,111.66668
13.44000,111.99999,38.92455,0.97391,4.32495,111.99999
13.48000,112.33336,39.08099,0.97681,4.34233,112.33336
13.52000,112.66674,39.24166,0.97971,4.36018,112.66674
13.56000,113.00005,39.46947,0.98261,4.38550,113.00005
13.60000,113.33343,39.46727,0.98551,4.38525,113.33343
13.64000,113.66667,39.64512,0.98841,4.40501,113.66667
13.68000,113.99998,39.71267,0.99130,4.41252,113.99998
13.72000,114.33342,39.68245,0.99420,4.40916,114.33342
13.76000,114.66667,39.92232,0.99710,4.43581,114.66667
13.80000,115.00005,39.96032,1.00000,4.44004,115.00005
13.84000,115.33342,40.02787,1.00290,4.44754,115.33342
13.88000,115.66667,40.14513,1.00580,4.46057,115.66667
13.92000,116.00005,40.17589,1.00870,4.46399,116.00005
13.96000,116.33337,40.08440,1.01159,4.45382,116.33337
14.00000,116.66661,40.63638,1.01449,4.51515,116.66661
14.04000,117.00011,40.56746,1.01739,4.50750,117.00011
14.08000,117.33330,40.66768,1.02029,4.51863,117.33330
14.12000,117.66667,40.88153,1.02319,4.54239,117.66667
14.16000,118.00011,40.90593,1.02609,4.54510,118.00011
14.20000,118.33336,41.11489,1.02899,4.56832,118.33336
14.24000,118.66674,41.46271,1.03188,4.60697,118.66674
14.28000,119.00004,41.10039,1.03478,4.56671,119.00004
14.32000,119.33336,41.38879,1.03768,4.59875,119.33336
14.36000,119.66674,41.60804,1.04058,4.62312,119.66674
14.40000,119.99998,41.59432,1.04348,4.62159,119.99998
14.44000,120.33336,41.64561,1.04638,4.62729,120.33336
14.48000,120.66667,41.61715,1.04928,4.62413,120.66667
14.52000,120.99999,41.98711,1.05217,4.66523,120.99999
14.56000,121.33336,41.87543,1.05507,4.65283,121.33336
14.60000,121.66660,42.22375,1.05797,4.69153,121.66660
14.64000,121.99992,42.13930,1.06087,4.68214,121.99992
14.68000,122.33342,42.27998,1.06377,4.69778,122.33342
14.72000,122.66673,42.67071,1.06667,4.74119,122.66673
14.76000,123.00004,42.66762,1.06957,4.74085,123.00004
14.80000,123.33342,42.57612,1.07246,4.73068,123.33342
14.84000,123.66667,42.85361,1.07536,4.76151,123.66667
14.88000,124.00005,42.73968,1.07826,4.74885,124.00005
14.92000,124.33343,42.78895,1.08116,4.75433,124.33343
14.96000,124.66662,43.23964,1.08406,4.80440,124.66662
15.00000,125.00005,43.28583,1.08696,4.80954,125.00005
15.04000,125.33336,43.14182,1.08986,4.79354,125.33336
15.08000,125.66666,43.53001,1.09275,4.83667,125.66666
15.12000,126.00005,43.51982,1.09565,4.83554,126.00005
15.16000,126.33330,43.66123,1.09855,4.85125,126.33330
15.20000,126.66667,43.79000,1.10145,4.86556,126.66667
15.24000,126.99998,43.43963,1.10435,4.82663,126.99998
15.28000,127.33336,43.75136,1.10725,4.86126,127.33336
15.32000,127.66673,43.97369,1.11015,4.88597,127.66673
15.36000,128.00003,43.92103,1.11304,4.88011,128.00003
15.40000,128.33335,44.30711,1.11594,4.92301,128.33335
15.44000,128.66673,44.27532,1.11884,4.91948,128.66673
15.48000,129.00004,44.46870,1.12174,4.94097,129.00004
15.52000,129.33343,44.37686,1.12464,4.93076,129.33343
15.56000,129.66673,44.58890,1.12754,4.95432,129.66673
15.60000,129.99998,44.62966,1.13043,4.95885,129.99998
15.64000,130.33335,44.78023,1.13333,4.97558,130.33335
15.68000,130.66666,45.06781,1.13623,5.00753,130.66666
15.72000,131.00005,45.13329,1.13913,5.01481,131.00005
15.76000,131.33341,45.17375,1.14203,5.01931,131.33341
15.80000,131.66654,45.26839,1.14493,5.02982,131.66654
15.84000,132.00005,45.30625,1.14783,5.03403,132.00005
15.88000,132.33341,45.40083,1.15073,5.04454,132.33341
15.92000,132.66672,45.61538,1.15362,5.06838,132.66672
15.96000,133.00017,45.63507,1.15652,5.07056,133.00017
16.00000,133.33336,45.40701,1.15942,5.04522,133.33336
16.04000,133.66667,45.84295,1.16232,5.09366,133.66667
16.08000,134.00011,45.88449,1.16522,5.09828,134.00011
16.12000,134.33329,46.16168,1.16812,5.12908,134.33329
16.16000,134.66666,46.27414,1.17101,5.14157,134.66666
16.20000,135.00004,46.31176,1.17391,5.14575,135.00004
16.24000,135.33329,46.17588,1.17681,5.13065,135.33329
16.28000,135.66673,46.51827,1.17971,5.16870,135.66673
16.32000,135.99998,46.54144,1.18261,5.17127,135.99998
16.36000,136.33328,46.50925,1.18551,5.16770,136.33328
16.40000,136.66667,46.70411,1.18841,5.18935,136.66667
16.44000,136.99998,46.92462,1.19130,5.21385,136.99998
16.48000,137.33341,46.88328,1.19420,5.20925,137.33341
16.52000,137.66673,47.04845,1.19710,5.22761,137.66673
16.56000,137.99998,47.17159,1.20000,5.24129,137.99998
16.60000,138.33341,47.22831,1.20290,5.24759,138.33341
16.64000,138.66666,47.26035,1.20580,5.25115,138.66666
16.68000,138.99999,47.33813,1.20870,5.25979,138.99999
16.72000,139.33341,47.45711,1.21159,5.27301,139.33341
16.76000,139.66667,47.70594,1.21449,5.30066,139.66667
16.80000,140.00005,47.80376,1.21739,5.31153,140.00005
16.84000,140.33342,47.73077,1.22029,5.30342,140.33342
16.88000,140.66666,47.94218,1.22319,5.32691,140.66666
16.92000,141.00003,48.03897,1.22609,5.33766,141.00003
16.96000,141.33330,48.02423,1.22899,5.33603,141.33330
17.00000,141.66661,48.18087,1.23188,5.35343,141.66661
17.04000,142.00004,48.25185,1.23478,5.36132,142.00004
17.08000,142.33336,48.35432,1.23768,5.37270,142.33336
17.12000,142.66673,48.47178,1.24058,5.38575,142.66673
17.16000,143.00010,48.67217,1.24348,5.40802,143.00010
17.20000,143.33335,48.42843,1.24638,5.38094,143.33335
17.24000,143.66673,48.86168,1.24928,5.42908,143.66673
17.28000,144.00004,48.86368,1.25217,5.42930,144.00004
17.32000,144.33335,48.55980,1.25507,5.39553,144.33335
17.36000,144.66668,48.65502,1.25797,5.40611,144.66668
17.40000,144.99999,48.88269,1.26087,5.43141,144.99999
17.44000,145.33335,48.94127,1.26377,5.43792,145.33335
17.48000,145.66674,49.10497,1.26667,5.45611,145.66674
17.52000,145.99998,49.40999,1.26957,5.49000,145.99998
17.56000,146.33335,49.55208,1.27246,5.50579,146.33335
17.60000,146.66666,49.57535,1.27536,5.50837,146.66666
17.64000,146.99997,49.67459,1.27826,5.51940,146.99997
17.68000,147.33342,49.74987,1.28116,5.52776,147.33342
17.72000,147.66666,50.06145,1.28406,5.56238,147.66666
17.76000,148.00005,50.04352,1.28696,5.56039,148.00005
17.80000,148.33341,50.03118,1.28986,5.55902,148.33341
17.84000,148.66660,50.12096,1.29275,5.56900,148.66660
17.88000,149.00004,50.09784,1.29565,5.56643,149.00004
17.92000,149.33336,50.36715,1.29855,5.59635,149.33336
17.96000,149.66667,50.42710,1.30145,5.60301,149.66667
18.00000,150.00003,50.62004,1.30435,5.62445,150.00003
18.04000,150.33329,50.62396,1.30725,5.62488,150.33329
18.08000,150.66667,50.83841,1.31015,5.64871,150.66667
18.12000,151.00010,50.90380,1.31304,5.65598,151.00010
18.16000,151.33329,51.03585,1.31594,5.67065,151.33329
18.20000,151.66667,51.22061,1.31884,5.69118,151.66667
18.24000,152.00004,51.13137,1.32174,5.68126,152.00004
18.28000,152.33335,51.26220,1.32464,5.69580,152.33335
18.32000,152.66674,51.48482,1.32754,5.72054,152.66674
18.36000,153.00005,51.59596,1.33044,5.73288,153.00005
18.40000,153.33335,51.55320,1.33333,5.72813,153.33335
18.44000,153.66666,51.50378,1.33623,5.72264,153.66666
18.48000,153.99999,51.69858,1.33913,5.74429,153.99999
18.52000,154.33341,51.85528,1.34203,5.76170,154.33341
18.56000,154.66667,51.92924,1.34493,5.76992,154.66667
18.60000,154.99997,52.03818,1.34783,5.78202,154.99997
18.64000,155.33342,51.96108,1.35073,5.77345,155.33342
18.68000,155.66667,52.25512,1.35362,5.80612,155.66667
18.72000,155.99998,52.41000,1.35652,5.82333,155.99998
18.76000,156.33335,52.36871,1.35942,5.81875,156.33335
18.80000,156.66660,52.39864,1.36232,5.82207,156.66660
18.84000,156.99998,52.74916,1.36522,5.86102,156.99998
18.88000,157.33341,52.39585,1.36812,5.82176,157.33341
18.92000,157.66667,52.84678,1.37101,5.87186,157.66667
18.96000,158.00016,53.10492,1.37391,5.90055,158.00016
19.00000,158.33335,52.89115,1.37681,5.87679,158.33335
19.04000,158.66660,53.09997,1.37971,5.90000,158.66660
19.08000,159.00010,53.03927,1.38261,5.89325,159.00010
19.12000,159.33335,53.22575,1.38551,5.91397,159.33335
19.16000,159.66665,53.48036,1.38841,5.94226,159.66665
19.20000,159.99997,53.60267,1.39130,5.95585,159.99997
19.24000,160.33329,53.56339,1.39420,5.95149,160.33329
19.28000,160.66672,53.67536,1.39710,5.96393,160.66672
19.32000,161.00004,53.94476,1.40000,5.99386,161.00004
19.36000,161.33334,53.86129,1.40290,5.98459,161.33334
19.40000,161.66667,53.98728,1.40580,5.99859,161.66667
19.44000,161.99997,53.93722,1.40870,5.99302,161.99997
19.48000,162.33342,54.13237,1.41159,6.01471,162.33342
19.52000,162.66672,54.11635,1.41449,6.01293,162.66672
19.56000,163.00002,54.11326,1.41739,6.01258,163.00002
19.60000,163.33336,54.50257,1.42029,6.05584,163.33336
19.64000,163.66666,54.39516,1.42319,6.04391,163.66666
19.68000,163.99996,54.64080,1.42609,6.07120,163.99996
19.72000,164.33341,54.56174,1.42899,6.06242,164.33341
19.76000,164.66660,54.70908,1.43188,6.07879,164.66660
19.80000,164.99998,54.70350,1.43478,6.07817,164.99998
19.84000,165.33334,54.80778,1.43768,6.08975,165.33334
19.88000,165.66658,54.93940,1.44058,6.10438,165.66658
19.92000,166.00003,55.10207,1.44348,6.12245,166.00003
19.96000,166.33334,55.14835,1.44638,6.12759,166.33334
20.00000,166.66660,55.37789,1.44927,6.15310,166.66660
20.04000,167.00003,55.37725,1.45217,6.15303,167.00003
20.08000,167.33335,55.19969,1.45507,6.13330,167.33335
20.12000,167.66673,55.69049,1.45797,6.18783,167.66673
20.16000,168.00016,55.67702,1.46087,6.18634,168.00016
20.20000,168.33330,55.72057,1.46377,6.19117,168.33330
20.24000,168.66671,55.90694,1.46667,6.21188,168.66671
20.28000,169.00005,55.78836,1.46957,6.19871,169.00005
20.32000,169.33335,55.94877,1.47246,6.21653,169.33335
20.36000,169.66665,56.07677,1.47536,6.23075,169.66665
20.40000,169.99997,56.13270,1.47826,6.23697,169.99997
20.44000,170.33335,56.12678,1.48116,6.23631,170.33335
20.48000,170.66672,56.29572,1.48406,6.25508,170.66672
20.52000,171.00003,56.36233,1.48696,6.26248,171.00003
20.56000,171.33335,56.46059,1.48986,6.27340,171.33335
20.60000,171.66667,56.53842,1.49275,6.28205,171.66667
20.64000,171.99997,56.70305,1.49565,6.30034,171.99997
20.68000,172.33342,56.65157,1.49855,6.29462,172.33342
20.72000,172.66667,56.90667,1.50145,6.32296,172.66667
20.76000,173.00004,56.99053,1.50435,6.33228,173.00004
20.80000,173.33342,56.94782,1.50725,6.32754,173.33342
20.84000,173.66659,57.37377,1.51014,6.37486,173.66659
20.88000,174.00004,57.20595,1.51304,6.35622,174.00004
20.92000,174.33340,57.23559,1.51594,6.35951,174.33340
20.96000,174.66666,57.49167,1.51884,6.38796,174.66666
21.00000,175.00009,57.59017,1.52174,6.39891,175.00009
21.04000,175.33334,57.63720,1.52464,6.40413,175.33334
21.08000,175.66666,57.58836,1.52754,6.39871,175.66666
21.12000,176.00004,57.88235,1.53044,6.43137,176.00004
21.16000,176.33328,57.82553,1.53333,6.42506,176.33328
21.20000,176.66666,58.03464,1.53623,6.44829,176.66666
21.24000,176.99996,58.08362,1.53913,6.45374,176.99996
21.28000,177.33335,57.96567,1.54203,6.44063,177.33335
21.32000,177.66671,58.10591,1.54493,6.45621,177.66671
21.36000,178.00003,58.27387,1.54783,6.47487,178.00003
21.40000,178.33341,58.32211,1.55073,6.48024,178.33341
21.44000,178.66665,58.35615,1.55362,6.48402,178.66665
21.48000,178.99998,58.43286,1.55652,6.49254,178.99998
21.52000,179.33335,58.26334,1.55942,6.47370,179.33335
21.56000,179.66667,58.67900,1.56232,6.51989,179.66667
21.60000,179.99997,58.75786,1.56522,6.52865,179.99997
21.64000,180.33335,58.69751,1.56812,6.52195,180.33335
21.68000,180.66667,58.80699,1.57101,6.53411,180.66667
21.72000,180.99997,59.04083,1.57391,6.56009,180.99997
21.76000,181.33335,58.98288,1.57681,6.55365,181.33335
21.80000,181.66659,59.09716,1.57971,6.56635,181.66659
21.84000,182.00004,59.28687,1.58261,6.58743,182.00004
21.88000,182.33340,59.44121,1.58551,6.60458,182.33340
21.92000,182.66665,59.46399,1.58841,6.60711,182.66665
21.96000,183.00015,59.70787,1.59131,6.63421,183.00015
22.00000,183.33334,59.53683,1.59420,6.61520,183.33334
22.04000,183.66667,59.87710,1.59710,6.65301,183.66667
22.08000,184.00004,59.59609,1.60000,6.62179,184.00004
22.12000,184.33329,59.73300,1.60290,6.63700,184.33329
22.16000,184.66672,59.76778,1.60580,6.64086,184.66672
22.20000,185.00004,59.89601,1.60870,6.65511,185.00004
22.24000,185.33329,59.91962,1.61159,6.65774,185.33329
22.28000,185.66672,60.28087,1.61449,6.69787,185.66672
22.32000,185.99996,60.19230,1.61739,6.68803,185.99996
22.36000,186.33328,60.03860,1.62029,6.67096,186.33328
22.40000,186.66666,60.48253,1.62319,6.72028,186.66666
22.44000,186.99998,60.40621,1.62609,6.71180,186.99998
22.48000,187.33334,60.51579,1.62899,6.72398,187.33334
22.52000,187.66671,60.74698,1.63188,6.74966,187.66671
22.56000,188.00003,60.92248,1.63478,6.76917,188.00003
22.60000,188.33341,60.77005,1.63768,6.75223,188.33341
22.64000,188.66666,60.99233,1.64058,6.77693,188.66666
22.68000,189.00003,60.86439,1.64348,6.76271,189.00003
22.72000,189.33341,61.00772,1.64638,6.77864,189.33341
22.76000,189.66660,61.28192,1.64927,6.80910,189.66660
22.80000,189.99998,61.00659,1.65217,6.77851,189.99998
22.84000,190.33335,61.28995,1.65507,6.80999,190.33335
22.88000,190.66660,61.37969,1.65797,6.81997,190.66660
22.92000,191.00003,61.18498,1.66087,6.79833,191.00003
22.96000,191.33335,61.25919,1.66377,6.80658,191.33335
23.00000,191.66665,61.51003,1.66667,6.83445,191.66665
23.04000,192.00005,61.51400,1.66957,6.83489,192.00005
23.08000,192.33340,61.89155,1.67246,6.87684,192.33340
23.12000,192.66672,61.91261,1.67536,6.87918,192.66672
23.16000,193.00010,61.94930,1.67826,6.88326,193.00010
23.20000,193.33340,61.84443,1.68116,6.87160,193.33340
23.24000,193.66667,61.93260,1.68406,6.88140,193.66667
23.28000,194.00002,61.87250,1.68696,6.87472,194.00002
23.32000,194.33334,62.01126,1.68986,6.89014,194.33334
23.36000,194.66672,62.18735,1.69275,6.90971,194.66672
23.40000,194.99997,62.13984,1.69565,6.90443,194.99997
23.44000,195.33329,62.10683,1.69855,6.90076,195.33329
23.48000,195.66666,62.43516,1.70145,6.93724,195.66666
23.52000,195.99997,62.46925,1.70435,6.94103,195.99997
23.56000,196.33334,62.45485,1.70725,6.93943,196.33334
23.60000,196.66659,62.47959,1.71014,6.94218,196.66659
23.64000,196.99998,62.43658,1.71304,6.93740,196.99998
23.68000,197.33340,62.77333,1.71594,6.97481,197.33340
23.72000,197.66673,62.87644,1.71884,6.98627,197.66673
23.76000,198.00004,62.86796,1.72174,6.98533,198.00004
23.80000,198.33334,62.70760,1.72464,6.96751,198.33334
23.84000,198.66666,62.77078,1.72754,6.97453,198.66666
23.88000,199.00009,63.12027,1.73044,7.01336,199.00009
23.92000,199.33335,62.85028,1.73333,6.98336,199.33335
23.96000,199.66666,63.02152,1.73623,7.00239,199.66666
24.00000,200.00003,63.08765,1.73913,7.00974,200.00003
24.04000,200.33335,62.91165,1.74203,6.99018,200.33335
24.08000,200.66665,63.49146,1.74493,7.05461,200.66665
24.12000,201.00003,63.54657,1.74783,7.06073,201.00003
24.16000,201.33328,63.60534,1.75072,7.06726,201.33328
24.20000,201.66665,63.47094,1.75362,7.05233,201.66665
24.24000,202.00003,63.54676,1.75652,7.06075,202.00003
24.28000,202.33333,63.67313,1.75942,7.07479,202.33333
24.32000,202.66673,63.83115,1.76232,7.09235,202.66673
24.36000,203.00003,63.72021,1.76522,7.08002,203.00003
24.40000,203.33335,63.78491,1.76812,7.08721,203.33335
24.44000,203.66672,63.99784,1.77102,7.11087,203.66672
24.48000,203.99997,64.08733,1.77391,7.12081,203.99997
24.52000,204.33335,64.05049,1.77681,7.11672,204.33335
24.56000,204.66665,64.15576,1.77971,7.12842,204.66665
24.60000,204.99997,64.35203,1.78261,7.15023,204.99997
24.64000,205.33340,64.10202,1.78551,7.12245,205.33340
24.68000,205.66665,64.30153,1.78841,7.14461,205.66665
24.72000,206.00004,64.29712,1.79130,7.14412,206.00004
24.76000,206.33334,64.35423,1.79420,7.15047,206.33334
24.80000,206.66659,64.63333,1.79710,7.18148,206.66659
24.84000,207.00004,64.69319,1.80000,7.18813,207.00004
24.88000,207.33342,64.81290,1.80290,7.20143,207.33342
24.92000,207.66666,64.79694,1.80580,7.19966,207.66666
24.96000,208.00009,64.93962,1.80870,7.21551,208.00009
25.00000,208.33341,64.91880,1.81159,7.21320,208.33341
25.04000,208.66666,64.87903,1.81449,7.20878,208.66666
25.08000,209.00009,65.07070,1.81739,7.23008,209.00009
25.12000,209.33334,65.20765,1.82029,7.24529,209.33334
25.16000,209.66666,65.26369,1.82319,7.25152,209.66666
25.20000,210.00003,65.26207,1.82609,7.25134,210.00003
25.24000,210.33334,65.36498,1.82899,7.26278,210.33334
25.28000,210.66666,65.36753,1.83188,7.26306,210.66666
25.32000,210.99998,65.69919,1.83478,7.29991,210.99998
25.36000,211.33333,65.23077,1.83768,7.24786,211.33333
25.40000,211.66665,65.35107,1.84058,7.26123,211.66665
25.44000,211.99998,65.49812,1.84348,7.27757,211.99998
25.48000,212.33341,65.63478,1.84638,7.29275,212.33341
25.52000,212.66665,65.61083,1.84928,7.29009,212.66665
25.56000,213.00003,65.52074,1.85217,7.28008,213.00003
25.60000,213.33341,65.82556,1.85507,7.31395,213.33341
25.64000,213.66665,66.01566,1.85797,7.33507,213.66665
25.68000,213.99997,66.00302,1.86087,7.33367,213.99997
25.72000,214.33340,65.80391,1.86377,7.31155,214.33340
25.76000,214.66659,66.08429,1.86667,7.34270,214.66659
25.80000,214.99997,65.87425,1.86957,7.31936,214.99997
25.84000,215.33335,66.01341,1.87246,7.33482,215.33335
25.88000,215.66659,66.20204,1.87536,7.35578,215.66659
25.92000,216.00002,66.32430,1.87826,7.36937,216.00002
25.96000,216.33334,66.18519,1.88116,7.35391,216.33334
26.00000,216.66666,66.37843,1.88406,7.37538,216.66666
26.04000,217.00002,66.34619,1.88696,7.37180,217.00002
26.08000,217.33334,66.34448,1.88986,7.37161,217.33334
26.12000,217.66672,66.48751,1.89275,7.38750,217.66672
26.16000,218.00004,66.43201,1.89565,7.38133,218.00004
26.20000,218.33334,66.43358,1.89855,7.38151,218.33334
26.24000,218.66672,66.73756,1.90145,7.41528,218.66672
26.28000,218.99998,66.73904,1.90435,7.41545,218.99998
26.32000,219.33334,66.84625,1.90725,7.42736,219.33334
26.36000,219.66673,66.98301,1.91015,7.44256,219.66673
26.40000,220.00004,67.01564,1.91304,7.44618,220.00004
26.44000,220.33334,66.95549,1.91594,7.43950,220.33334
26.48000,220.66671,66.97042,1.91884,7.44116,220.66671
26.52000,220.99996,67.14794,1.92174,7.46088,220.99996
26.56000,221.33335,67.16709,1.92464,7.46301,221.33335
26.60000,221.66660,67.20872,1.92754,7.46764,221.66660
26.64000,221.99996,67.28548,1.93043,7.47616,221.99996
26.68000,222.33341,67.46289,1.93333,7.49588,222.33341
26.72000,222.66665,67.50174,1.93623,7.50019,222.66665
26.76000,223.00011,67.53441,1.93913,7.50382,223.00011
26.80000,223.33341,67.59681,1.94203,7.51076,223.33341
26.84000,223.66660,67.58182,1.94493,7.50909,223.66660
26.88000,224.00003,67.79822,1.94783,7.53314,224.00003
26.92000,224.33333,67.69585,1.95072,7.52176,224.33333
26.96000,224.66660,67.71726,1.95362,7.52414,224.66660
27.00000,225.00008,68.05955,1.95652,7.56217,225.00008
27.04000,225.33327,67.99445,1.95942,7.55494,225.33327
27.08000,225.66667,67.97833,1.96232,7.55315,225.66667
27.12000,226.00010,67.94586,1.96522,7.54954,226.00010
27.16000,226.33329,68.03324,1.96812,7.55925,226.33329
27.20000,226.66665,68.26944,1.97101,7.58549,226.66665
27.24000,226.99997,68.22805,1.97391,7.58089,226.99997
27.28000,227.33340,68.33948,1.97681,7.59328,227.33340
27.32000,227.66665,68.62720,1.97971,7.62524,227.66665
27.36000,228.00004,68.69005,1.98261,7.63223,228.00004
27.40000,228.33340,68.53492,1.98551,7.61499,228.33340
27.44000,228.66672,68.66859,1.98841,7.62984,228.66672
27.48000,228.99996,68.63920,1.99130,7.62658,228.99996
27.52000,229.33342,68.74662,1.99420,7.63851,229.33342
27.56000,229.66666,68.84135,1.99710,7.64904,229.66666
27.60000,229.99996,69.18344,2.00000,7.68705,229.99996
27.64000,230.33341,69.28587,2.00290,7.69843,230.33341
27.68000,230.66666,69.33314,2.00580,7.70368,230.66666
27.72000,230.99996,69.32657,2.00870,7.70295,230.99996
27.76000,231.33341,69.16125,2.01159,7.68458,231.33341
27.80000,231.66658,69.37996,2.01449,7.70888,231.66658
27.84000,232.00003,69.47303,2.01739,7.71922,232.00003
27.88000,232.33341,69.42017,2.02029,7.71335,232.33341
27.92000,232.66666,69.57736,2.02319,7.73082,232.66666
27.96000,233.00009,69.80327,2.02609,7.75592,233.00009
28.00000,233.33333,69.71123,2.02899,7.74569,233.33333
28.04000,233.66665,69.77314,2.03188,7.75257,233.66665
28.08000,234.00009,69.95531,2.03478,7.77281,234.00009
28.12000,234.33335,69.92910,2.03768,7.76990,234.33335
28.16000,234.66671,70.05278,2.04058,7.78364,234.66671
28.20000,234.99997,70.24391,2.04348,7.80488,234.99997
28.24000,235.33329,70.13027,2.04638,7.79225,235.33329
28.28000,235.66678,70.35461,2.04928,7.81718,235.66678
28.32000,235.99997,70.55015,2.05217,7.83891,235.99997
28.36000,236.33329,70.33874,2.05507,7.81542,236.33329
28.40000,236.66665,70.39586,2.05797,7.82176,236.66665
28.44000,237.00003,70.36431,2.06087,7.81826,237.00003
28.48000,237.33340,70.35804,2.06377,7.81756,237.33340
28.52000,237.66672,70.42627,2.06667,7.82514,237.66672
28.56000,237.99997,70.62808,2.06957,7.84756,237.99997
28.60000,238.33342,70.71228,2.07246,7.85692,238.33342
28.64000,238.66666,70.75406,2.07536,7.86156,238.66666
28.68000,238.99997,71.00034,2.07826,7.88893,238.99997
28.72000,239.33342,71.00642,2.08116,7.88960,239.33342
28.76000,239.66659,71.26720,2.08406,7.91858,239.66659
28.80000,240.00004,71.02944,2.08696,7.89216,240.00004
28.84000,240.33334,71.14151,2.08986,7.90461,240.33334
28.88000,240.66659,71.36134,2.09275,7.92904,240.66659
28.92000,241.00009,71.42600,2.09565,7.93622,241.00009
28.96000,241.33334,71.66704,2.09855,7.96300,241.33334
29.00000,241.66659,71.77147,2.10145,7.97461,241.66659
29.04000,242.00009,71.81291,2.10435,7.97921,242.00009
29.08000,242.33334,71.76437,2.10725,7.97382,242.33334
29.12000,242.66671,71.89814,2.11015,7.98868,242.66671
29.16000,243.00009,72.06600,2.11304,8.00733,243.00009
29.20000,243.33335,72.01104,2.11594,8.00123,243.33335
29.24000,243.66666,71.99787,2.11884,7.99976,243.66666
29.28000,244.00003,72.13056,2.12174,8.01451,244.00003
29.32000,244.33341,72.17366,2.12464,8.01930,244.33341
29.36000,244.66665,72.29397,2.12754,8.03266,244.66665
29.40000,244.99997,72.31454,2.13043,8.03495,244.99997
29.44000,245.33335,72.49435,2.13333,8.05493,245.33335
29.48000,245.66673,72.63057,2.13623,8.07006,245.66673
29.52000,245.99997,72.75068,2.13913,8.08341,245.99997
29.56000,246.33333,72.48059,2.14203,8.05340,246.33333
29.60000,246.66660,72.42666,2.14493,8.04741,246.66660
29.64000,246.99997,72.39590,2.14783,8.04399,246.99997
29.68000,247.33340,72.60177,2.15073,8.06686,247.33340
29.72000,247.66667,72.87230,2.15362,8.09692,247.66667
29.76000,248.00010,72.79402,2.15652,8.08822,248.00010
29.80000,248.33340,72.70924,2.15942,8.07880,248.33340
29.84000,248.66665,72.90781,2.16232,8.10087,248.66665
29.88000,249.00004,73.03159,2.16522,8.11462,249.00004
29.92000,249.33334,73.10379,2.16812,8.12264,249.33334
29.96000,249.66665,73.24707,2.17101,8.13856,249.66665
30.00000,250.00004,73.51984,2.17391,8.16887,250.00004
30.04000,250.33334,73.30702,2.17681,8.14522,250.33334
30.08000,250.66672,73.59675,2.17971,8.17742,250.66672
30.12000,251.00008,73.82246,2.18261,8.20250,251.00008
30.16000,251.33332,73.87399,2.18551,8.20822,251.33332
30.20000,251.66664,73.91087,2.18841,8.21232,251.66664
30.24000,252.00000,73.73939,2.19130,8.19326,252.00000
30.28000,252.33334,73.77431,2.19420,8.19715,252.33334
30.32000,252.66677,74.00188,2.19710,8.22243,252.66677
30.36000,253.00002,74.21412,2.20000,8.24601,253.00002
30.40000,253.33334,74.19536,2.20290,8.24393,253.33334
30.44000,253.66670,74.34236,2.20580,8.26026,253.66670
30.48000,253.99996,74.32252,2.20870,8.25806,253.99996
30.52000,254.33341,74.25938,2.21159,8.25104,254.33341
30.56000,254.66666,74.29940,2.21449,8.25549,254.66666
30.60000,254.99998,74.60573,2.21739,8.28953,254.99998
30.64000,255.33339,74.74994,2.22029,8.30555,255.33339
30.68000,255.66665,74.77330,2.22319,8.30814,255.66665
30.72000,256.00001,74.87014,2.22609,8.31890,256.00001
30.76000,256.33333,74.84565,2.22899,8.31618,256.33333
30.80000,256.66658,74.82929,2.23188,8.31437,256.66658
30.84000,257.00008,75.00455,2.23478,8.33384,257.00008
30.88000,257.33335,75.08267,2.23768,8.34252,257.33335
30.92000,257.66665,75.26484,2.24058,8.36276,257.66665
30.96000,258.00008,75.28811,2.24348,8.36535,258.00008
31.00000,258.33338,75.40150,2.24638,8.37794,258.33338
31.04000,258.66663,75.74874,2.24927,8.41653,258.66663
31.08000,259.00010,75.73948,2.25217,8.41550,259.00010
31.12000,259.33340,75.84881,2.25507,8.42765,259.33340
31.16000,259.66672,76.03445,2.25797,8.44827,259.66672
31.20000,260.00002,75.82750,2.26087,8.42528,260.00002
31.24000,260.33327,75.81511,2.26377,8.42390,260.33327
31.28000,260.66676,76.05404,2.26667,8.45045,260.66676
31.32000,261.00000,76.20432,2.26957,8.46715,261.00000
31.36000,261.33332,76.23155,2.27246,8.47017,261.33332
31.40000,261.66666,76.49498,2.27536,8.49944,261.66666
31.44000,261.99996,76.49498,2.27826,8.49944,261.99996
31.48000,262.33340,76.64227,2.28116,8.51581,262.33340
31.52000,262.66664,76.76933,2.28406,8.52993,262.66664
31.56000,263.00002,76.92074,2.28696,8.54675,263.00002
31.60000,263.33338,76.74940,2.28986,8.52771,263.33338
31.64000,263.66664,77.05681,2.29275,8.56187,263.66664
31.68000,264.00004,77.08776,2.29565,8.56531,264.00004
31.72000,264.33339,77.10833,2.29855,8.56759,264.33339
31.76000,264.66671,77.11989,2.30145,8.56888,264.66671
31.80000,265.00002,77.17236,2.30435,8.57471,265.00002
31.84000,265.33339,77.41697,2.30725,8.60189,265.33339
31.88000,265.66664,77.48883,2.31014,8.60987,265.66664
31.92000,266.00009,77.47928,2.31304,8.60881,266.00009
31.96000,266.33335,77.69970,2.31594,8.63330,266.33335
32.00000,266.66660,77.97288,2.31884,8.66365,266.66660
32.04000,267.00009,77.86727,2.32174,8.65192,267.00009
32.08000,267.33333,77.98389,2.32464,8.66488,267.33333
32.12000,267.66671,78.32579,2.32754,8.70287,267.66671
32.16000,268.00007,78.38643,2.33044,8.70960,268.00007
32.20000,268.33331,78.32628,2.33333,8.70292,268.33331
32.24000,268.66673,78.64609,2.33623,8.73845,268.66673
32.28000,269.00003,78.63482,2.33913,8.73720,269.00003
32.32000,269.33340,78.65382,2.34203,8.73931,269.33340
32.36000,269.66676,78.88057,2.34493,8.76451,269.66676
32.40000,269.99995,78.75419,2.34783,8.75047,269.99995
32.44000,270.33333,78.87880,2.35072,8.76431,270.33333
32.48000,270.66678,79.08217,2.35362,8.78691,270.66678
32.52000,271.00002,79.17201,2.35652,8.79689,271.00002
32.56000,271.33334,79.19503,2.35942,8.79945,271.33334
32.60000,271.66659,79.44749,2.36232,8.82750,271.66659
32.64000,271.99997,79.55358,2.36522,8.83929,271.99997
32.68000,272.33338,79.50798,2.36812,8.83422,272.33338
32.72000,272.66664,79.65973,2.37101,8.85108,272.66664
32.76000,273.00010,79.66271,2.37391,8.85141,273.00010
32.80000,273.33340,79.96503,2.37681,8.88500,273.33340
32.84000,273.66666,79.94911,2.37971,8.88323,273.66666
32.88000,274.00007,80.01142,2.38261,8.89016,274.00007
32.92000,274.33334,80.13451,2.38551,8.90383,274.33334
32.96000,274.66659,80.60337,2.38841,8.95593,274.66659
33.00000,275.00007,80.42263,2.39130,8.93585,275.00007
33.04000,275.33332,80.46852,2.39420,8.94095,275.33332
33.08000,275.66671,80.84049,2.39710,8.98228,275.66671
33.12000,276.00009,80.68013,2.40000,8.96446,276.00009
33.16000,276.33328,80.78627,2.40290,8.97625,276.33328
33.20000,276.66664,80.92704,2.40580,8.99189,276.66664
33.24000,277.00001,81.14506,2.40870,9.01612,277.00001
33.28000,277.33332,80.98832,2.41159,8.99870,277.33332
33.32000,277.66673,81.37523,2.41449,9.04169,277.66673
33.36000,278.00009,81.50660,2.41739,9.05629,278.00009
33.40000,278.33341,81.52340,2.42029,9.05816,278.33341
33.44000,278.66665,81.52947,2.42319,9.05883,278.66665
33.48000,278.99995,81.57312,2.42609,9.06368,278.99995
33.52000,279.33344,81.57871,2.42899,9.06430,279.33344
33.56000,279.66669,81.73800,2.43188,9.08200,279.66669
33.60000,279.99995,81.91482,2.43478,9.10165,279.99995
33.64000,280.33340,81.79643,2.43768,9.08849,280.33340
33.68000,280.66665,82.10585,2.44058,9.12287,280.66665
33.72000,280.99997,82.15670,2.44348,9.12852,280.99997
33.76000,281.33333,82.17256,2.44638,9.13029,281.33333
33.80000,281.66657,82.13642,2.44927,9.12627,281.66657
33.84000,281.99995,82.33602,2.45217,9.14845,281.99995
33.88000,282.33340,82.51226,2.45507,9.16803,282.33340
33.92000,282.66659,82.51275,2.45797,9.16808,282.66659
33.96000,283.00008,82.65279,2.46087,9.18364,283.00008
34.00000,283.33334,82.61414,2.46377,9.17935,283.33334
34.04000,283.66664,82.87321,2.46667,9.20813,283.66664
34.08000,284.00008,82.82682,2.46957,9.20298,284.00008
34.12000,284.33332,82.96652,2.47246,9.21850,284.33332
34.16000,284.66672,83.07771,2.47536,9.23086,284.66672
34.20000,285.00004,83.28745,2.47826,9.25416,285.00004
34.24000,285.33334,83.29646,2.48116,9.25516,285.33334
34.28000,285.66672,83.40682,2.48406,9.26742,285.66672
34.32000,285.99996,83.70630,2.48696,9.30070,285.99996
34.36000,286.33332,83.70336,2.48986,9.30037,286.33332
34.40000,286.66670,83.91168,2.49275,9.32352,286.66670
34.44000,286.99994,83.85163,2.49565,9.31685,286.99994
34.48000,287.33334,84.05412,2.49855,9.33935,287.33334
34.52000,287.66671,83.97482,2.50145,9.33053,287.66671
34.56000,288.00001,84.11863,2.50435,9.34651,288.00001
34.60000,288.33345,84.24897,2.50725,9.36100,288.33345
34.64000,288.66664,84.31407,2.51014,9.36823,288.66664
34.68000,288.99996,84.76510,2.51304,9.41834,288.99996
34.72000,289.33346,84.64044,2.51594,9.40449,289.33346
34.76000,289.66665,84.65018,2.51884,9.40558,289.66665
34.80000,290.00003,84.78694,2.52174,9.42077,290.00003
34.84000,290.33333,84.97901,2.52464,9.44211,290.33333
34.88000,290.66665,85.15358,2.52754,9.46151,290.66665
34.92000,291.00006,85.19482,2.53044,9.46609,291.00006
34.96000,291.33325,85.16136,2.53333,9.46237,291.33325
35.00000,291.66657,85.45830,2.53623,9.49537,291.66657
35.04000,292.00008,85.57409,2.53913,9.50823,292.00008
35.08000,292.33335,85.49396,2.54203,9.49933,292.33335
35.12000,292.66670,85.56042,2.54493,9.50671,292.66670
35.16000,293.00008,85.82664,2.54783,9.53629,293.00008
35.20000,293.33338,85.89409,2.55072,9.54379,293.33338
35.24000,293.66670,85.89536,2.55362,9.54393,293.66670
35.28000,294.00004,86.03482,2.55652,9.55942,294.00004
35.32000,294.33334,86.06685,2.55942,9.56298,294.33334
35.36000,294.66672,86.15046,2.56232,9.57227,294.66672
35.40000,295.00002,86.13361,2.56522,9.57040,295.00002
35.44000,295.33332,86.23849,2.56812,9.58205,295.33332
35.48000,295.66664,85.94219,2.57101,9.54913,295.66664
35.52000,296.00000,26.77260,2.57391,2.97473,296.00000
35.56000,296.33341,-5.27736,2.57681,-0.58637,296.33341
35.60000,296.66666,-1.65382,2.57971,-0.18376,296.66666
35.64000,296.99996,-1.07372,2.58261,-0.11930,296.99996
35.68000,297.33339,-1.20801,2.58551,-0.13422,297.33339
35.72000,297.66664,-1.01017,2.58841,-0.11224,297.66664
35.76000,298.00002,-1.00111,2.59130,-0.11123,298.00002
35.80000,298.33341,-1.18410,2.59420,-0.13157,298.33341
35.84000,298.66666,-0.96576,2.59710,-0.10731,298.66666
35.88000,299.00009,-0.73503,2.60000,-0.08167,299.00009
35.92000,299.33339,-0.75232,2.60290,-0.08359,299.33339
35.95600,299.63333,-0.91661,2.60551,-0.10185,299.63333