File: V_8/EPR/RDSO EPR Tensile 50.is_tens_RawData/Specimen_RawData_3.csv
Time,Extension,Load
(sec),(mm),(N)
0.00000,0.00000,3.47897
0.30000,0.24925,4.25635
0.60000,0.49987,4.44314
0.90000,0.74994,4.89526
1.20000,0.99994,5.13742
1.50000,1.24987,5.56043
1.80000,1.49987,5.74399
2.10000,1.74994,5.94155
2.40000,1.99994,6.13451
2.70000,2.24987,6.09174
3.00000,2.49994,6.47340
3.30000,2.74994,6.77680
3.60000,2.99994,7.02999
3.90000,3.24987,7.15636
4.20000,3.49994,7.26239
4.50000,3.74994,7.47089
4.80000,3.99994,7.66350
5.10000,4.24994,7.75308
5.40000,4.49994,7.89557
5.70000,4.74994,8.15135
6.00000,4.99987,8.05634
6.30000,5.24994,8.21216
6.60000,5.50000,8.14003
6.90000,5.74994,8.42320
7.20000,5.99994,8.78349
7.50000,6.24994,8.94784
7.80000,6.49994,8.96514
8.10000,6.74994,9.05456
8.40000,6.99987,9.15511
8.70000,7.24994,9.36654
9.00000,7.49994,9.47817
9.30000,7.74994,9.37791
9.60000,7.99987,9.56392
9.90000,8.25000,9.77295
10.20000,8.49981,9.92294
10.50000,8.74987,9.92852
10.80000,8.99987,10.05445
11.10000,9.24994,10.20836
11.40000,9.49987,10.28696
11.70000,9.74987,10.34806
12.00000,10.00000,10.37668
12.30000,10.24994,10.54185
12.60000,10.49994,10.41744
12.90000,10.74994,10.82772
13.20000,10.99994,10.50471
13.50000,11.24987,10.84330
13.80000,11.49987,10.82581
14.10000,11.74994,10.87726
14.40000,11.99987,11.15602
14.70000,12.24987,11.13823
15.00000,12.49994,11.44816
15.30000,12.74987,11.45114
15.60000,12.99994,11.52827
15.90000,13.24987,11.59217
16.20000,13.49994,11.68615
16.50000,13.74987,11.70937
16.80000,13.99987,12.22172
17.10000,14.24994,11.93904
17.40000,14.50000,12.05717
17.70000,14.74994,12.16688
18.00000,14.99994,12.23303
18.30000,15.25000,12.14572
18.60000,15.50000,12.27562
18.90000,15.74987,12.46789
19.20000,15.99994,12.44511
19.50000,16.24993,12.77189
19.80000,16.49987,13.04820
20.10000,16.74994,12.92359
20.40000,16.99987,13.03830
20.70000,17.24993,13.27619
21.00000,17.49987,13.42780
21.30000,17.74994,13.38938
21.60000,17.99993,13.47655
21.90000,18.24987,13.55417
22.20000,18.49987,13.72851
22.50000,18.74994,13.65736
22.80000,18.99993,13.68201
23.10000,19.24987,13.86399
23.40000,19.49994,13.74796
23.70000,19.74993,14.02638
24.00000,19.99993,14.39300
24.30000,20.24994,14.36262
24.60000,20.49993,14.17779
24.90000,20.74993,14.49717
25.20000,20.99993,14.35189
25.50000,21.24987,14.54921
25.80000,21.49994,14.71841
26.10000,21.74993,14.82444
26.40000,21.99993,14.81057
26.70000,22.24993,15.03279
27.00000,22.49993,14.80915
27.30000,22.74993,14.89647
27.60000,22.99994,15.06111
27.90000,23.24993,15.13956
28.20000,23.49993,15.13784
28.50000,23.74993,15.11457
28.80000,23.99993,15.05273
29.10000,24.25000,15.39044
29.40000,24.49993,15.37657
29.70000,24.74987,15.28117
30.00000,24.99999,15.63980
30.30000,25.24993,15.53567
30.60000,25.49981,15.53464
30.90000,25.74987,15.69291
31.20000,25.99993,16.00049
31.50000,26.25000,15.70928
31.80000,26.49987,15.80924
32.10000,26.74993,15.84844
32.40000,26.99994,16.03322
32.70000,27.24993,16.17272
33.00000,27.49993,16.09839
33.30000,27.74993,16.11995
33.60000,28.00000,16.19996
33.90000,28.24987,16.36583
34.20000,28.49987,16.37426
34.50000,28.74993,16.22045
34.80000,28.99987,16.47681
35.10000,29.24993,16.54071
35.40000,29.49993,16.44266
35.70000,29.74994,16.78968
36.00000,29.99993,16.58745
36.30000,30.24987,16.76552
36.60000,30.49999,16.76591
36.90000,30.74993,16.80815
37.20000,30.99987,16.97568
37.50000,31.24993,17.06383
37.80000,31.49993,16.98867
38.10000,31.74993,17.11793
38.40000,31.99993,17.03752
38.70000,32.24999,17.30354
39.00000,32.49993,17.03967
39.30000,32.74993,17.36356
39.60000,32.99993,17.25469
39.90000,33.24993,17.42447
40.20000,33.49993,17.56775
40.50000,33.74993,17.45377
40.80000,33.99987,17.58965
41.10000,34.24993,17.75267
41.40000,34.49987,17.80344
41.70000,34.74993,17.87532
42.00000,34.99993,17.94308
42.30000,35.24987,17.67834
42.60000,35.49987,17.86973
42.90000,35.75000,17.90585
43.20000,35.99993,18.23115
43.50000,36.24993,18.03506
43.80000,36.49993,18.27570
44.10000,36.74993,18.12345
44.40000,36.99993,18.35537
44.70000,37.24993,18.41716
45.00000,37.49993,18.44960
45.30000,37.74993,18.48855
45.60000,37.99993,18.36154
45.90000,38.24993,18.38467
46.20000,38.49993,18.68778
46.50000,38.74987,18.63854
46.80000,38.99987,18.83385
47.10000,39.24993,18.93817
47.40000,39.49993,18.78108
47.70000,39.74987,18.94102
48.00000,39.99987,19.07895
48.30000,40.24987,19.18636
48.60000,40.49999,19.39916
48.90000,40.74987,19.12021
49.20000,40.99987,19.27358
49.50000,41.24993,19.37025
49.80000,41.49993,19.25001
50.10000,41.74993,19.75485
50.40000,41.99993,19.59629
50.70000,42.24993,19.65592
51.00000,42.49987,19.74633
51.30000,42.74987,19.95286
51.60000,42.99993,19.87971
51.90000,43.24993,19.79812
52.20000,43.49981,19.88108
52.50000,43.74993,19.80728
52.80000,43.99987,20.16111
53.10000,44.24993,20.13059
53.40000,44.49987,20.32105
53.70000,44.74993,20.27264
54.00000,44.99999,20.47971
54.30000,45.24987,20.68262
54.60000,45.49993,20.63950
54.90000,45.74993,20.63465
55.20000,45.99987,20.58212
55.50000,46.24993,20.65263
55.80000,46.49993,20.89126
56.10000,46.74993,20.84157
56.40000,46.99986,21.07016
56.70000,47.24993,20.92399
57.00000,47.49993,21.06256
57.30000,47.74987,20.99328
57.60000,47.99993,21.40541
57.90000,48.24993,21.26091
58.20000,48.49993,21.42903
58.50000,48.74987,21.26488
58.80000,48.99987,21.53987
59.10000,49.24993,21.43560
59.40000,49.49987,21.71877
59.70000,49.74993,21.71676
60.00000,49.99999,21.88542
60.30000,50.24993,21.87317
60.60000,50.49993,21.87513
60.90000,50.74981,21.95098
61.20000,50.99993,22.09440
61.50000,51.24993,21.85709
61.80000,51.49987,22.22606
62.10000,51.74993,22.27991
62.40000,51.99993,22.30437
62.70000,52.24986,22.25042
63.00000,52.49986,22.35082
63.30000,52.74993,22.55652
63.60000,52.99993,22.56735
63.90000,53.24993,22.79696
64.20000,53.49987,22.54133
64.50000,53.74993,22.64472
64.80000,53.99987,22.73591
65.10001,54.24987,23.08488
65.40000,54.49993,23.00987
65.70001,54.74993,23.19651
66.00000,54.99993,23.10233
66.30000,55.24987,23.29328
66.60001,55.49993,23.36021
66.90000,55.74993,23.52578
67.20001,55.99987,23.60771
67.50000,56.24993,23.66739
67.80000,56.49993,23.66009
68.10001,56.74987,23.85751
68.40000,56.99987,24.05851
68.70001,57.24993,24.03680
69.00000,57.49993,24.05008
69.30000,57.74986,24.09521
69.60001,57.99993,24.01466
69.90000,58.24993,24.08424
70.20001,58.49987,24.23824
70.50000,58.74987,24.47780
70.80000,58.99993,24.45507
71.10001,59.24993,24.54537
71.40000,59.49981,24.69713
71.70001,59.74993,24.78792
72.00000,59.99999,24.91366
72.30000,60.24993,24.88244
72.60001,60.49987,24.81522
72.90000,60.74987,25.01891
73.20001,60.99987,25.23490
73.50000,61.24993,25.24509
73.80000,61.49987,25.18448
74.10001,61.74999,25.36955
74.40000,61.99993,25.44864
74.70001,62.24993,25.60083
75.00000,62.49993,25.64351
75.30000,62.74993,25.53453
75.60001,62.99987,25.77860
75.90000,63.24986,25.79389
76.20001,63.49993,25.99719
76.50000,63.74992,25.90531
76.80000,63.99986,26.09377
77.10001,64.24993,25.91634
77.40000,64.49993,26.12341
77.70001,64.74993,26.14683
78.00000,64.99992,26.33607
78.30000,65.24993,26.43363
78.60001,65.49993,26.47420
78.90000,65.74986,26.58210
79.20001,65.99993,26.58249
79.50000,66.24999,26.66143
79.80000,66.49987,26.70480
80.10001,66.74986,26.91510
80.40000,66.99986,27.04623
80.70001,67.24992,27.23355
81.00001,67.49993,27.20082
81.30000,67.74987,27.29505
81.60001,67.99986,27.26825
81.90000,68.24993,27.40059
82.20001,68.49993,27.56827
82.50001,68.74999,27.51672
82.80000,68.99992,27.57719
83.10001,69.24986,27.84728
83.40000,69.49987,27.84311
83.70001,69.74999,27.82229
84.00001,69.99987,28.01089
84.30000,70.24986,27.92117
84.60001,70.49993,27.89334
84.90000,70.74993,28.18964
85.20001,70.99993,28.54989
85.50001,71.24993,28.48275
85.80000,71.49993,28.45267
86.10001,71.74992,28.40749
86.40000,71.99986,28.49069
86.70001,72.24993,28.74843
87.00001,72.49992,28.85319
87.30000,72.74986,28.71766
87.60001,72.99987,28.95796
87.90000,73.24993,29.08521
88.20001,73.49993,29.04753
88.50001,73.74993,29.15312
88.80000,73.99987,29.22652
89.10001,74.24993,29.25171
89.40000,74.49986,29.59647
89.70001,74.74986,29.58628
90.00001,74.99993,29.57143
90.30000,75.24993,29.74857
90.60001,75.49993,29.71633
90.90000,75.74987,29.90463
91.20001,75.99992,30.12714
91.50001,76.24993,29.83295
91.80000,76.49980,29.92957
92.10001,76.74999,30.12699
92.40000,76.99999,30.30648
92.70001,77.24993,30.43824
93.00001,77.49987,30.28801
93.30000,77.74986,30.34401
93.60001,77.99999,30.71225
93.90000,78.24986,30.62576
94.20001,78.49980,30.80883
94.50001,78.74993,30.71710
94.80000,78.99986,30.82024
95.10001,79.24986,31.09107
95.40000,79.49986,31.16829
95.70001,79.74993,31.06137
96.00001,79.99986,31.30348
96.30000,80.24986,31.29319
96.60001,80.49992,31.32769
96.90000,80.74986,31.45680
97.20001,80.99986,31.55269
97.50001,81.24992,31.66730
97.80000,81.49993,31.68989
98.10001,81.74992,31.65182
98.40000,81.99993,31.97164
98.70001,82.24992,32.29690
99.00001,82.49986,32.26657
99.30000,82.74986,32.18166
99.60001,82.99986,32.38300
99.90000,83.24986,32.28485
100.20001,83.49986,32.45302
100.50001,83.74986,32.55827
100.80000,83.99987,32.69395
101.10001,84.24993,32.66685
101.40000,84.49992,32.72805
101.70001,84.74993,32.73335
102.00001,84.99992,32.88926
102.30000,85.24993,33.00917
102.60001,85.49985,33.04337
102.90000,85.74992,33.27122
103.20001,85.99993,33.32095
103.50001,86.24992,33.31257
103.80000,86.49986,33.31159
104.10001,86.74999,33.43130
104.40000,86.99981,33.54988
104.70001,87.24992,33.92105
105.00001,87.49999,33.75230
105.30000,87.74993,33.74421
105.60001,87.99986,34.19702
105.90000,88.24986,34.07329
106.20001,88.49992,33.89744
106.50001,88.74992,34.11686
106.80000,88.99986,34.28375
107.10001,89.24992,34.56447
107.40000,89.49992,34.53223
107.70001,89.74986,34.69584
108.00001,89.99993,34.68863
108.30000,90.24993,34.48651
108.60001,90.49986,34.63665
108.90000,90.74987,35.02277
109.20001,90.99992,34.94500
109.50001,91.24992,34.93726
109.80000,91.49986,35.03457
110.10001,91.74992,35.17692
110.40000,91.99993,35.11890
110.70001,92.24986,35.30236
111.00001,92.49986,35.56020
111.30000,92.74987,35.44529
111.60001,92.99998,35.61444
111.90000,93.24986,35.64364
112.20001,93.49986,35.76168
112.50001,93.74992,35.97616
112.80000,93.99986,35.87276
113.10001,94.24992,35.92769
113.40001,94.49986,36.21052
113.70001,94.74993,36.17764
114.00001,94.99992,36.39452
114.30000,95.24986,36.52755
114.60001,95.49987,36.60771
114.90001,95.74998,36.63373
115.20001,95.99992,36.73355
115.50001,96.24986,36.75060
115.80000,96.49999,36.88192
116.10001,96.74992,36.98825
116.40001,96.99985,36.96708
116.70001,97.24992,36.99526
117.00001,97.49993,37.14573
117.30000,97.74992,37.24667
117.60001,97.99986,37.53229
117.90001,98.24986,37.61662
118.20001,98.49992,37.46629
118.50001,98.74986,37.42577
118.80000,98.99992,37.66611
119.10001,99.24993,37.80125
119.40001,99.49992,37.88303
119.70001,99.74986,37.84226
120.00001,99.99992,37.99078
120.30000,100.24992,37.99030
120.60001,100.49992,38.24975
120.90001,100.74986,37.96545
121.20001,100.99986,38.29444
121.50001,101.24993,38.46358
121.80000,101.49992,38.39258
122.10001,101.74992,38.49107
122.40001,101.99992,38.81967
122.70001,102.24986,38.55923
123.00001,102.49992,38.97054
123.30000,102.74992,39.05065
123.60001,102.99986,38.95172
123.90001,103.24986,39.01219
124.20001,103.49993,39.11783
124.50001,103.74992,39.40090
124.80000,103.99986,39.28712
125.10001,104.24992,39.49880
125.40001,104.49992,39.50292
125.70001,104.74992,39.60680
126.00001,104.99992,39.92221
126.30000,105.24986,39.77938
126.60001,105.49992,39.76727
126.90001,105.74993,40.01791
127.20001,105.99992,40.01129
127.50001,106.24993,40.04883
127.80000,106.49987,40.22714
128.10001,106.74986,40.32328
128.40001,106.99986,40.51021
128.70002,107.24992,40.40388
129.00000,107.49992,40.58400
129.30000,107.74986,40.65991
129.60001,107.99993,40.73629
129.90001,108.24999,40.60831
130.20002,108.49993,40.76045
130.50000,108.74987,41.09140
130.80000,108.99992,41.17303
131.10000,109.24992,40.90951
131.40002,109.49986,41.19665
131.70002,109.74992,41.28494
132.00000,109.99999,41.49516
132.30000,110.24985,41.46551
132.60000,110.49992,41.42185
132.90002,110.74992,41.63045
133.20002,110.99992,41.79503
133.50000,111.24986,41.73560
133.80000,111.49986,41.78460
134.10000,111.74999,41.91268
134.40002,111.99992,42.04880
134.70002,112.24993,42.07762
135.00000,112.49992,42.14847
135.30000,112.74992,42.28812
135.60000,112.99992,42.24368
135.90002,113.24992,42.50818
136.20002,113.49992,42.42439
136.50000,113.74986,42.50480
136.80000,113.99986,42.49279
137.10000,114.24992,42.89591
137.40002,114.49993,42.72094
137.70002,114.74986,42.86010
138.00000,114.99993,42.99896
138.30000,115.24992,43.03287
138.60000,115.49992,42.93320
138.90002,115.74986,43.21059
139.20002,115.99992,43.08790
139.50000,116.24992,43.42036
139.80000,116.49992,43.41497
140.10000,116.74993,43.82368
140.40002,116.99999,43.64100
140.70002,117.24993,43.71867
141.00000,117.49987,43.91104
141.30000,117.74986,43.97656
141.60000,117.99992,43.96950
141.90002,118.24992,44.14311
142.20002,118.49992,44.22356
142.50000,118.74992,44.42378
142.80000,118.99993,44.43485
143.10000,119.24986,44.34773
143.40002,119.49993,44.53334
143.70002,119.74992,44.69847
144.00000,119.99992,44.71322
144.30000,120.24986,44.66427
144.60000,120.49992,44.81617
144.90002,120.74992,44.90755
145.20002,120.99986,45.04784
145.50000,121.24993,45.03020
145.80000,121.49992,45.14706
146.10000,121.74992,45.20988
146.40002,121.99992,45.29598
146.70002,122.24986,45.28833
147.00000,122.49992,45.29705
147.30000,122.74992,45.42538
147.60000,122.99986,45.56895
147.90002,123.24993,45.43832
148.20002,123.49992,45.64637
148.50000,123.74992,45.73202
148.80000,123.99986,45.81538
149.10000,124.24992,46.01667
149.40002,124.49986,45.91352
149.70002,124.74992,46.31576
150.00000,124.99992,46.36069
150.30000,125.24992,46.26808
150.60000,125.49992,46.28925
150.90002,125.74992,46.50745
151.20002,125.99997,46.53450
151.50000,126.24991,46.78645
151.80000,126.49992,46.74931
152.10000,126.74998,46.87269
152.40002,126.99991,46.99118
152.70002,127.24985,47.02391
153.00000,127.49991,46.92870
153.30000,127.74984,47.29125
153.60000,127.99992,47.20961
153.90002,128.24985,47.21647
154.20002,128.49986,47.40150
154.50000,128.74993,47.36044
154.80000,128.99992,47.55732
155.10000,129.24992,47.65140
155.40002,129.49991,47.61960
155.70002,129.74991,47.72137
156.00000,129.99984,47.74058
156.30000,130.24986,47.95079
156.60000,130.49997,47.99278
156.90002,130.74991,48.12822
157.20002,130.99991,48.04247
157.50000,131.24992,47.97637
157.80000,131.49998,48.19839
158.10000,131.74991,48.35102
158.40002,131.99992,48.50301
158.70002,132.24992,48.61238
159.00000,132.49986,48.79050
159.30000,132.74985,48.65100
159.60000,132.99991,48.69446
159.90002,133.24998,48.89878
160.20002,133.49985,48.98782
160.50000,133.74992,49.18607
160.80000,133.99998,49.18255
161.10000,134.24992,49.04867
161.40002,134.49985,49.35542
161.70002,134.74992,49.13310
162.00002,134.99998,49.31886
162.30000,135.24991,49.30019
162.60000,135.49991,49.51403
162.90002,135.74985,49.63222
163.20002,135.99992,49.80239
163.50002,136.24991,49.56293
163.80000,136.49992,50.00285
164.10000,136.74991,50.12138
164.40002,136.99993,49.90936
164.70002,137.24986,50.24481
165.00002,137.49997,50.20836
165.30000,137.74991,50.16195
165.60000,137.99992,50.32630
165.90002,138.24992,50.54190
166.20002,138.49986,50.26809
166.50002,138.74992,50.63951
166.80000,138.99991,50.65450
167.10000,139.24993,50.68772
167.40002,139.49992,50.61927
167.70002,139.74992,50.98829
168.00002,139.99991,51.04817
168.30000,140.24991,50.99363
168.60000,140.49992,51.07154
168.90002,140.74986,51.13308
169.20002,140.99992,51.30140
169.50002,141.24999,51.24279
169.80000,141.49985,51.33030
170.10000,141.74992,51.54159
170.40002,141.99992,51.54635
170.70002,142.24991,51.71329
171.00002,142.49991,51.72588
171.30000,142.74985,51.81869
171.60000,142.99992,51.86244
171.90002,143.24992,51.90782
172.20002,143.49991,51.92384
172.50002,143.74998,52.03458
172.80000,143.99998,51.97049
173.10000,144.24986,52.02336
173.40002,144.49986,52.22357
173.70002,144.74998,52.47342
174.00002,144.99992,52.54986
174.30000,145.24986,52.52884
174.60000,145.49992,52.57191
174.90002,145.74992,52.75400
175.20002,145.99991,52.78639
175.50002,146.24992,52.85694
175.80000,146.49992,52.98562
176.10000,146.74991,53.01840
176.40002,146.99985,53.00301
176.70002,147.24985,53.25213
177.00002,147.49992,53.16751
177.30000,147.74986,53.16094
177.60000,147.99992,53.27692
177.90002,148.24999,53.43960
178.20002,148.49992,53.47630
178.50002,148.74992,53.53535
178.80000,148.99991,53.80255
179.10000,149.24991,53.55843
179.40002,149.49991,53.92338
179.70002,149.74984,53.90142
180.00002,149.99992,53.91676
180.30000,150.24992,54.06817
180.60000,150.49991,53.95601
180.90002,150.74993,54.30126
181.20002,150.99992,54.28769
181.50002,151.24992,54.20802
181.80000,151.49985,54.30856
182.10000,151.74999,54.35752
182.40002,151.99992,54.53700
182.70002,152.24992,54.67655
183.00002,152.49985,54.61638
183.30000,152.74986,54.65240
183.60000,152.99991,54.84080
183.90002,153.24985,54.63520
184.20002,153.49992,54.81258
184.50002,153.74998,55.03768
184.80000,153.99992,54.98089
185.10000,154.24985,55.18581
185.40002,154.49998,55.41773
185.70002,154.74985,55.34589
186.00002,154.99991,55.39323
186.30000,155.24991,55.44320
186.60000,155.49992,55.48623
186.90002,155.74986,55.63273
187.20002,155.99986,55.54233
187.50002,156.24992,55.64827
187.80000,156.49991,55.81850
188.10000,156.74992,55.81933
188.40002,156.99985,55.83707
188.70002,157.24991,55.90895
189.00002,157.49991,56.10025
189.30000,157.74984,56.13989
189.60000,157.99992,56.14043
189.90002,158.24990,56.43947
190.20002,158.49991,56.50640
190.50002,158.74991,56.58877
190.80000,158.99984,56.53899
191.10000,159.24998,56.49156
191.40002,159.49985,56.78948
191.70002,159.74991,56.84289
192.00002,159.99991,56.77468
192.30000,160.24992,56.63317
192.60000,160.49985,57.02154
192.90002,160.74991,57.02585
193.20002,160.99991,57.03996
193.50002,161.24984,57.13914
193.80000,161.49985,57.08436
194.10000,161.74996,57.34073
194.40002,161.99991,57.23929
194.70002,162.24984,57.51840
195.00002,162.49992,57.53888
195.30000,162.74985,57.53962
195.60000,162.99991,57.80446
195.90002,163.24991,57.72797
196.20002,163.49992,57.92471
196.50002,163.74992,57.84611
196.80000,163.99985,57.83557
197.10000,164.24986,57.96366
197.40002,164.49990,58.00482
197.70002,164.74985,58.14045
198.00002,164.99985,58.26241
198.30000,165.24991,58.09292
198.60000,165.49991,58.41716
198.90002,165.74990,58.26790
199.20002,165.99992,58.49232
199.50002,166.24991,58.67048
199.80000,166.49991,58.35605
200.10000,166.74984,58.77985
200.40002,166.99998,58.71478
200.70002,167.24991,58.75486
201.00002,167.49986,58.86653
201.30000,167.74984,58.89711
201.60000,167.99990,58.95140
201.90002,168.24985,59.05185
202.20002,168.49985,59.13853
202.50002,168.74991,59.23550
202.80000,168.99984,59.23016
203.10000,169.24992,59.53920
203.40002,169.49985,59.40141
203.70002,169.74986,59.52087
204.00002,169.99992,59.45140
204.30000,170.24985,59.52818
204.60000,170.49992,59.66293
204.90002,170.74991,59.77303
205.20002,170.99986,59.69090
205.50002,171.24990,59.98574
205.80000,171.49998,60.08604
206.10000,171.74991,59.83937
206.40002,171.99986,60.25347
206.70002,172.24984,60.02754
207.00002,172.49990,60.28165
207.30000,172.74993,60.16277
207.60000,172.99991,60.29360
207.90002,173.24992,60.25960
208.20002,173.49990,60.47005
208.50002,173.74985,60.34422
208.80000,173.99983,60.53895
209.10000,174.24991,60.49543
209.40002,174.49992,60.68967
209.70002,174.74985,60.82006
210.00002,174.99991,60.59402
210.30000,175.24991,60.98230
210.60000,175.49992,61.13067
210.90002,175.74985,61.03492
211.20002,175.99991,61.10450
211.50002,176.24998,61.09509
211.80000,176.49986,61.10896
212.10000,176.74992,61.35964
212.40002,176.99990,61.51331
212.70002,177.24985,61.37860
213.00002,177.49984,61.60817
213.30000,177.74992,61.42418
213.60000,177.99990,61.52663
213.90002,178.24985,61.70627
214.20002,178.49991,61.81000
214.50002,178.74992,61.78942
214.80000,178.99992,61.80388
215.10000,179.24985,62.02893
215.40002,179.49985,61.99944
215.70002,179.74991,62.24042
216.00002,179.99992,62.16211
216.30000,180.24985,62.31588
216.60000,180.49996,62.37997
216.90002,180.74999,62.49188
217.20002,180.99992,62.47718
217.50002,181.24985,62.56970
217.80000,181.49991,62.49860
218.10000,181.74991,62.76947
218.40002,181.99991,62.81210
218.70002,182.24992,62.84654
219.00002,182.49990,62.81846
219.30000,182.74985,63.03319
219.60000,182.99984,62.97208
219.90002,183.24992,63.04514
220.20002,183.49985,63.20640
220.50002,183.74991,63.22933
220.80000,183.99991,63.02221
221.10000,184.24984,63.11487
221.40002,184.49984,63.35036
221.70002,184.74985,63.04710
222.00002,184.99991,63.39285
222.30000,185.24984,63.51573
222.60000,185.49992,63.46154
222.90002,185.74992,63.74780
223.20002,185.99985,63.54778
223.50002,186.24991,63.57845
223.80000,186.49984,63.51079
224.10000,186.74992,63.66136
224.40002,186.99991,63.69444
224.70002,187.24991,63.75990
225.00002,187.49991,64.07012
225.30002,187.74984,63.92939
225.60000,187.99990,64.23716
225.90002,188.24991,64.15509
226.20002,188.49991,64.38509
226.50002,188.74984,64.24255
226.80002,188.99985,64.32991
227.10000,189.24991,64.44340
227.40002,189.49991,64.23667
227.70002,189.74984,64.48191
228.00002,189.99984,64.73294
228.30002,190.24983,64.67149
228.60000,190.49991,64.52626
228.90002,190.74984,64.64209
229.20002,190.99990,64.72280
229.50002,191.24985,64.61549
229.80002,191.49985,65.00945
230.10000,191.74986,65.08192
230.40002,191.99990,65.17193
230.70002,192.24990,65.18697
231.00002,192.49983,65.11558
231.30002,192.74991,65.26125
231.60000,192.99991,65.25543
231.90002,193.24990,65.42849
232.20002,193.49985,65.20525
232.50002,193.74991,65.27904
232.80002,193.99991,65.13528
233.10000,194.24984,65.35127
233.40002,194.49979,65.43085
233.70002,194.74998,65.58490
234.00002,194.99991,65.67212
234.30002,195.24978,65.73459
234.60000,195.49990,65.68741
234.90002,195.74990,65.85205
235.20002,195.99983,65.70397
235.50002,196.24986,65.95455
235.80002,196.49990,66.21862
236.10000,196.74990,66.09729
236.40002,196.99983,66.10621
236.70002,197.24978,66.26703
237.00002,197.49997,66.25640
237.30002,197.74985,66.44877
237.60000,197.99991,66.38973
237.90002,198.24997,66.48665
238.20002,198.49991,66.48821
238.50002,198.74990,66.60483
238.80002,198.99985,66.62678
239.10000,199.24983,66.65280
239.40002,199.49991,66.89486
239.70002,199.74984,66.85993
240.00002,199.99990,67.03539
240.30002,200.24991,67.07886
240.60000,200.49991,66.92024
240.90002,200.74992,67.03520
241.20002,200.99990,66.98801
241.50002,201.24990,67.14197
241.80002,201.49983,67.25487
242.10000,201.74991,67.30215
242.40002,201.99992,67.23115
242.70002,202.24990,67.56450
243.00002,202.49985,67.06518
243.30002,202.74984,67.41088
243.60000,202.99997,67.62217
243.90002,203.24990,67.48286
244.20002,203.49991,67.49217
244.50002,203.74991,67.66078
244.80002,203.99991,67.61153
245.10000,204.24992,67.61550
245.40002,204.49990,67.66979
245.70002,204.74991,67.72527
246.00002,204.99984,67.86722
246.30002,205.24984,67.94943
246.60000,205.49998,67.89936
246.90002,205.74979,67.99751
247.20002,205.99991,67.95620
247.50002,206.24990,67.93224
247.80002,206.49992,68.34433
248.10000,206.74996,68.48305
248.40002,206.99991,68.41292
248.70002,207.24989,68.36447
249.00002,207.49992,68.72775
249.30002,207.74985,68.36824
249.60000,207.99991,68.58056
249.90002,208.24984,68.60055
250.20002,208.49984,68.76416
250.50002,208.74985,68.82188
250.80002,208.99991,68.77136
251.10000,209.24985,68.71780
251.40002,209.49984,68.76950
251.70002,209.74990,68.76499
252.00002,209.99990,68.89210
252.30002,210.24991,68.86563
252.60000,210.49984,69.01087
252.90002,210.74990,68.98083
253.20002,210.99992,69.02695
253.50002,211.24985,69.16439
253.80002,211.49991,69.12014
254.10000,211.74997,69.30046
254.40002,211.99990,69.42473
254.70002,212.24983,69.54257
255.00002,212.49991,69.22897
255.30002,212.74991,69.41640
255.60000,212.99984,69.41380
255.90002,213.24985,69.52184
256.20002,213.49985,69.66090
256.50000,213.74991,69.64302
256.80002,213.99984,69.79644
257.10000,214.24985,69.91570
257.40003,214.49991,70.00155
257.70002,214.74991,69.99405
258.00000,214.99991,70.20005
258.30002,215.24996,70.31951
258.60000,215.49990,70.21127
258.90003,215.74991,70.22573
259.20002,215.99991,70.30104
259.50000,216.24997,70.27712
259.80002,216.49985,70.10660
260.10000,216.74983,70.32221
260.40003,216.99991,70.34739
260.70002,217.24992,70.43011
261.00000,217.49990,70.47856
261.30002,217.74985,70.43108
261.60000,217.99991,70.65114
261.90003,218.24986,70.78437
262.20000,218.49984,70.73243
262.50000,218.74990,70.67809
262.80003,218.99983,70.80926
263.10000,219.24986,70.93750
263.40003,219.49984,71.04182
263.70000,219.74990,70.88845
264.00000,219.99998,70.93304
264.30003,220.24984,71.23483
264.60000,220.49997,71.15795
264.90003,220.74990,71.14261
265.20000,220.99990,71.29931
265.50000,221.24991,71.32567
265.80003,221.49984,71.38183
266.10000,221.74992,71.34125
266.40003,221.99985,71.51143
266.70000,222.24991,71.47272
267.00000,222.49991,71.59341
267.30003,222.74986,71.53696
267.60000,222.99990,71.55656
267.90003,223.24990,71.78946
268.20000,223.49991,71.65936
268.50000,223.74991,71.89025
268.80003,223.99984,71.73933
269.10000,224.24996,71.59410
269.40003,224.49991,71.76530
269.70000,224.74984,71.91656
270.00000,224.99992,71.93190
270.30003,225.24990,71.82317
270.60000,225.49991,72.23942
270.90003,225.74984,72.31552
271.20000,225.99991,72.07836
271.50000,226.24992,72.17773
271.80003,226.49985,72.18503
272.10000,226.74991,72.38887
272.40003,226.99989,72.44473
272.70000,227.24984,72.54753
273.00000,227.49985,72.68831
273.30003,227.74991,72.48927
273.60000,227.99991,72.94193
273.90003,228.24990,72.80689
274.20000,228.49992,73.01921
274.50000,228.74990,72.98231
274.80003,228.99991,73.19222
275.10000,229.24984,73.15758
275.40003,229.49992,73.03606
275.70000,229.74990,73.23138
276.00000,229.99991,73.19977
276.30003,230.24984,73.25867
276.60000,230.49990,73.00352
276.90003,230.74992,73.20996
277.20000,230.99985,73.43208
277.50000,231.24991,73.56247
277.80003,231.49990,73.40375
278.10000,231.74990,73.41047
278.40003,231.99985,73.35711
278.70000,232.24996,73.64788
279.00000,232.49991,73.55032
279.30003,232.74984,73.65640
279.60000,232.99992,73.72882
279.90003,233.24991,73.81692
280.20000,233.49985,73.83231
280.50000,233.74990,73.80546
280.80003,233.99984,74.10627
281.10000,234.24990,74.27042
281.40003,234.49985,74.29688
281.70000,234.74984,74.23337
282.00000,234.99990,74.39438
282.30003,235.24985,74.23337
282.60000,235.49985,74.53428
282.90003,235.74991,74.68942
283.20000,235.99990,74.63503
283.50000,236.24985,74.97793
283.80003,236.49983,75.17996
284.10000,236.74991,75.27609
284.40003,236.99991,75.15751
284.70000,237.24990,75.41074
285.00000,237.49990,75.22949
285.30003,237.74991,75.27972
285.60000,237.99991,75.27011
285.90003,238.24990,75.36081
286.20000,238.49990,75.47376
286.50000,238.74991,75.80784
286.80003,238.99985,75.68891
287.10000,239.24991,75.79519
287.40003,239.49990,75.73292
287.70000,239.74985,75.93323
288.00000,239.99991,75.95699
288.30003,240.24986,75.90623
288.60000,240.49990,75.80436
288.90003,240.74990,76.11801
289.20000,240.99983,76.05960
289.50000,241.24991,76.22085
289.80003,241.49984,76.31660
290.10000,241.74990,76.47463
290.40003,241.99998,76.38701
290.70000,242.24991,76.49378
291.00000,242.49991,76.35943
291.30003,242.74990,76.61467
291.60000,242.99996,76.57062
291.90003,243.24991,76.72281
292.20000,243.49984,76.68831
292.50000,243.74992,77.18674
292.80003,243.99990,77.03759
293.10000,244.24991,77.11422
293.40003,244.49991,77.27823
293.70000,244.74991,77.23010
294.00000,244.99990,77.16704
294.30003,245.24990,77.41743
294.60000,245.49991,77.39803
294.90003,245.74991,77.47741
295.20000,245.99977,77.51592
295.50000,246.24985,77.58579
295.80003,246.49991,77.57815
296.10000,246.74989,77.55096
296.40003,246.99984,77.73064
296.70000,247.24985,77.95570
297.00000,247.49991,77.77141
297.30003,247.74984,77.69394
297.60000,247.99984,77.83207
297.90003,248.24992,77.67410
298.20000,248.49990,77.96878
298.50000,248.74991,78.11887
298.80003,248.99984,77.92713
299.10000,249.24992,77.95771
299.40003,249.49990,78.36225
299.70000,249.74985,78.07859
300.00000,249.99997,78.18359
300.30003,250.24995,78.36254
300.60000,250.49990,78.59132
300.90003,250.74989,78.68477
301.20000,250.99991,78.63841
301.50000,251.24988,78.66301
301.80003,251.49990,78.97920
302.10000,251.74990,78.81030
302.40003,251.99994,79.02958
302.70000,252.24989,79.10381
303.00000,252.49988,79.14943
303.30003,252.74990,79.08401
303.60000,252.99991,79.21436
303.90003,253.24984,79.09426
304.20000,253.49990,79.26375
304.50000,253.74992,79.14820
304.80003,253.99989,79.36239
305.10000,254.24991,79.32960
305.40003,254.49982,79.54320
305.70000,254.74990,79.36434
306.00000,254.99990,79.68627
306.30003,255.24989,79.48136
306.60000,255.49997,79.74448
306.90003,255.74982,79.85184
307.20000,255.99984,79.59694
307.50000,256.24996,79.81603
307.80003,256.49989,79.73160
308.10000,256.74984,79.83401
308.40003,256.99988,80.07705
308.70000,257.24990,79.99061
309.00000,257.49991,80.14874
309.30003,257.74984,80.22782
309.60000,257.99990,80.41892
309.90003,258.24998,80.46224
310.20000,258.49989,80.60796
310.50000,258.74991,80.48717
310.80003,258.99990,80.64363
311.10000,259.24990,80.74153
311.40003,259.49989,80.66882
311.70000,259.74989,80.95453
312.00000,259.99997,80.90774
312.30003,260.24988,80.86531
312.60000,260.49990,80.88010
312.90003,260.74996,80.91931
313.20000,260.99995,80.93106
313.50000,261.24984,81.19189
313.80003,261.49988,81.01515
314.10000,261.74990,81.14073
314.40003,261.99991,81.16176
314.70000,262.24984,80.95184
315.00000,262.49990,81.11423
315.30003,262.74988,80.70121
315.60000,262.99983,80.45498
315.90003,263.24986,0.80034
316.20000,263.49990,0.65383
316.50000,263.74990,0.64163
316.80003,263.99983,0.77545
317.10000,264.24989,0.58332
317.40003,264.49984,0.62350
317.70000,264.74988,0.44176
318.00000,264.99990,0.75443
318.30003,265.24989,0.57764
318.60000,265.49989,0.54642
318.90003,265.74984,0.72895
319.20000,265.99983,0.55034
319.50000,266.24996,0.82915
319.80003,266.49982,0.58690
320.10000,266.74990,0.58303
320.40003,266.99990,0.58675
320.70000,267.24989,0.69837
321.00000,267.49989,0.69298
321.30003,267.74982,0.75355
321.60000,267.99995,0.79794
321.90003,268.24990,0.79353
322.20000,268.49989,0.71890
322.50003,268.74995,0.72503
322.80003,268.99997,0.66618
323.10000,269.24983,0.60125
323.40003,269.49991,0.66069
323.70000,269.74989,0.54226
324.00003,269.99995,0.74919
324.30003,270.24984,0.59988
324.60000,270.49989,0.63389
324.63603,270.52997,0.57406