File: V_8/EPR/RDSO EPR Tensile 50.is_tens_RawData/Specimen_RawData_5.csv
Time,Extension,Load
(sec),(mm),(N)
0.00000,-0.00006,-0.07617
0.20000,0.16469,0.32568
0.40000,0.33306,0.82670
0.60000,0.49994,1.43092
0.80000,0.66669,1.40985
1.00000,0.83337,1.90142
1.20000,0.99994,2.09639
1.40000,1.16675,2.44806
1.60000,1.33331,2.76729
1.80000,1.49994,2.95036
2.00000,1.66669,3.37773
2.20000,1.83344,3.50744
2.40000,1.99994,3.67742
2.60000,2.16662,3.71863
2.80000,2.33337,4.08078
3.00000,2.49994,4.21901
3.20000,2.66675,4.47156
3.40000,2.83331,4.56226
3.60000,2.99994,4.83494
3.80000,3.16675,5.03368
4.00000,3.33331,5.22111
4.20000,3.49994,5.58831
4.40000,3.66681,5.52270
4.60000,3.83337,5.52344
4.80000,3.99994,5.86859
5.00000,4.16669,5.83243
5.20000,4.33337,6.08831
5.40000,4.49994,6.21776
5.60000,4.66675,6.32424
5.80000,4.83325,6.49760
6.00000,4.99987,6.62294
6.20000,5.16675,6.72736
6.40000,5.33331,6.90249
6.60000,5.50000,7.06527
6.80000,5.66675,7.02793
7.00000,5.83331,7.45344
7.20000,5.99994,7.51866
7.40000,6.16675,7.58310
7.60000,6.33337,7.80722
7.80000,6.49994,7.98068
8.00000,6.66675,8.05776
8.20000,6.83337,8.24111
8.40000,6.99987,8.19089
8.60000,7.16675,8.27360
8.80000,7.33337,8.36910
9.00000,7.49994,8.39522
9.20000,7.66669,8.37822
9.40000,7.83325,8.55957
9.60000,7.99987,8.70005
9.80000,8.16681,8.69676
10.00000,8.33331,8.93765
10.20000,8.49981,9.19269
10.40000,8.66675,9.07568
10.60000,8.83331,9.20950
10.80000,8.99987,9.68710
11.00000,9.16675,9.39031
11.20000,9.33337,9.50418
11.40000,9.49987,9.48360
11.60000,9.66669,9.48699
11.80000,9.83337,9.57283
12.00000,10.00000,9.79730
12.20000,10.16675,9.90363
12.40000,10.33331,9.93548
12.60000,10.49994,10.20312
12.80000,10.66669,10.07778
13.00000,10.83337,10.14672
13.20000,10.99994,10.28367
13.40000,11.16675,10.44557
13.60000,11.33331,10.31400
13.80000,11.49987,10.51804
14.00000,11.66675,10.73090
14.20000,11.83337,10.84516
14.40000,11.99987,10.72570
14.60000,12.16669,10.80836
14.80000,12.33337,10.95424
15.00000,12.49994,10.99334
15.20000,12.66675,11.03229
15.40000,12.83337,11.08100
15.60000,12.99994,11.24436
15.80000,13.16675,11.14475
16.00000,13.33331,11.33884
16.20000,13.49994,11.37769
16.40000,13.66681,11.34246
16.60000,13.83331,11.55644
16.80000,13.99987,11.61039
17.00000,14.16675,11.63700
17.20000,14.33337,11.51725
17.40000,14.50000,11.70746
17.60000,14.66675,11.76406
17.80000,14.83331,11.83579
18.00000,14.99994,12.00783
18.20000,15.16675,11.84060
18.40000,15.33331,12.07673
18.60000,15.50000,12.14572
18.80000,15.66675,12.15483
19.00000,15.83331,12.26817
19.20000,15.99994,12.28380
19.40000,16.16675,12.33157
19.60000,16.33337,12.35710
19.80000,16.49987,12.52826
20.00000,16.66675,12.32991
20.20000,16.83337,12.44016
20.40000,16.99987,12.55423
20.60000,17.16669,12.78987
20.80000,17.33337,12.52331
21.00000,17.49987,12.65992
21.20000,17.66669,12.60906
21.40000,17.83337,12.74342
21.60000,17.99993,12.83769
21.80000,18.16675,12.77992
22.00000,18.33331,12.89184
22.20000,18.49987,12.90600
22.40000,18.66681,13.09749
22.60000,18.83337,13.18711
22.80000,18.99993,13.11577
23.00000,19.16662,12.98445
23.20000,19.33331,13.10866
23.40000,19.50000,13.32637
23.60000,19.66675,13.19701
23.80000,19.83337,13.19461
24.00000,19.99993,13.18216
24.20000,20.16675,13.36802
24.40000,20.33331,13.48640
24.60000,20.49993,13.32328
24.80000,20.66675,13.44024
25.00000,20.83337,13.47013
25.20000,20.99987,13.64374
25.40000,21.16675,13.51928
25.60000,21.33331,13.68828
25.80000,21.49994,13.66510
26.00000,21.66675,13.82215
26.20000,21.83337,13.80799
26.40000,21.99987,13.84787
26.60000,22.16668,13.96841
26.80000,22.33337,13.57617
27.00000,22.49993,13.92593
27.20000,22.66675,14.04779
27.40000,22.83331,13.85909
27.60000,22.99994,14.18921
27.80000,23.16675,14.01070
28.00000,23.33337,14.14148
28.20000,23.49993,14.13163
28.40000,23.66675,14.28338
28.60000,23.83331,14.12262
28.80000,23.99993,14.18279
29.00000,24.16675,14.35752
29.20000,24.33337,14.46263
29.40000,24.49993,14.29862
29.60000,24.66668,14.53201
29.80000,24.83331,14.39662
30.00000,24.99999,14.58581
30.20000,25.16681,14.32376
30.40000,25.33331,14.63971
30.60000,25.49981,14.47507
30.80000,25.66668,14.59625
31.00000,25.83337,14.70552
31.20000,25.99993,14.64961
31.40000,26.16675,14.78833
31.60000,26.33331,14.90803
31.80000,26.49987,14.75055
32.00000,26.66668,14.75021
32.20000,26.83337,15.00456
32.40000,26.99994,14.95748
32.60000,27.16674,15.09644
32.80000,27.33337,14.85511
33.00000,27.49993,15.02103
33.20000,27.66668,15.04871
33.40000,27.83337,14.77892
33.60000,28.00000,15.21482
33.80000,28.16675,15.39338
34.00000,28.33331,15.36065
34.20000,28.49987,15.25196
34.40000,28.66675,15.15906
34.60000,28.83331,15.08194
34.80000,28.99987,15.15935
35.00000,29.16669,15.50603
35.20000,29.33337,15.41704
35.40000,29.49993,15.44061
35.60000,29.66675,15.49853
35.80000,29.83331,15.64852
36.00000,29.99993,15.57002
36.20000,30.16675,15.70859
36.40000,30.33337,15.63598
36.60000,30.49993,15.61241
36.80000,30.66675,15.61638
37.00000,30.83331,15.72452
37.20000,30.99993,15.71104
37.40000,31.16681,15.75157
37.60000,31.33337,15.90881
37.80000,31.49993,15.88039
38.00000,31.66674,16.01999
38.20000,31.83331,15.92606
38.40000,31.99993,15.80948
38.60000,32.16675,15.83830
38.80000,32.33337,16.08183
39.00000,32.50000,15.92885
39.20000,32.66668,16.46780
39.40000,32.83331,15.94075
39.60000,33.00000,16.07212
39.80000,33.16674,16.25529
40.00000,33.33337,16.10819
40.20000,33.49993,16.25411
40.40000,33.66681,16.41973
40.60000,33.83337,16.38675
40.80000,33.99981,16.49445
41.00000,34.16675,16.43845
41.20000,34.33337,16.49122
41.40000,34.49987,16.59530
41.60000,34.66674,16.57971
41.80000,34.83337,16.43433
42.00000,34.99993,16.69682
42.20000,35.16668,16.44663
42.40000,35.33325,16.53640
42.60000,35.49987,16.58314
42.80000,35.66681,16.76910
43.00000,35.83337,16.96176
43.20000,35.99993,16.85171
43.40000,36.16675,16.83995
43.60000,36.33337,16.86832
43.80000,36.49993,16.83951
44.00000,36.66681,17.00895
44.20000,36.83337,17.16075
44.40000,36.99993,16.81579
44.60000,37.16668,17.03252
44.80000,37.33331,17.08397
45.00000,37.49993,17.21112
45.20000,37.66675,17.25057
45.40000,37.83331,17.08735
45.60000,37.99987,17.36685
45.80000,38.16674,17.31045
46.00000,38.33331,17.44412
46.20000,38.49993,17.26630
46.40000,38.66674,17.43099
46.60000,38.83331,17.38532
46.80000,38.99987,17.62537
47.00000,39.16668,17.60126
47.20000,39.33343,17.57691
47.40000,39.49993,17.65844
47.60000,39.66675,17.74106
47.80000,39.83330,17.61297
48.00000,39.99987,17.98498
48.20000,40.16674,17.69064
48.40000,40.33324,17.82671
48.60000,40.49999,17.95749
48.80000,40.66675,17.83818
49.00000,40.83325,18.07583
49.20000,40.99993,18.04118
49.40000,41.16681,17.85033
49.60000,41.33331,17.83935
49.80000,41.49993,18.14477
50.00000,41.66674,18.22929
50.20000,41.83331,17.97297
50.40000,41.99993,18.09111
50.60000,42.16681,18.40819
50.80000,42.33337,18.44009
51.00000,42.49987,18.29569
51.20000,42.66674,18.29637
51.40000,42.83337,18.42289
51.60000,42.99993,18.30034
51.80000,43.16675,18.45455
52.00000,43.33331,18.56798
52.20000,43.49981,18.67465
52.40000,43.66674,18.57905
52.60000,43.83331,18.59371
52.80000,43.99993,18.94567
53.00000,44.16674,18.64378
53.20000,44.33331,18.96184
53.40000,44.49993,18.84150
53.60000,44.66674,18.91750
53.80000,44.83337,19.03642
54.00000,44.99999,19.01770
54.20000,45.16668,18.94121
54.40000,45.33330,19.17264
54.60000,45.49993,19.21625
54.80000,45.66681,18.98433
55.00000,45.83337,19.15970
55.20000,45.99987,19.14892
55.40000,46.16675,19.41607
55.60000,46.33330,19.27020
55.80000,46.49993,19.42656
56.00000,46.66674,19.32194
56.20000,46.83337,19.47276
56.40000,46.99986,19.27191
56.60000,47.16674,19.68709
56.80000,47.33337,19.57850
57.00000,47.49993,19.40764
57.20000,47.66674,19.82659
57.40000,47.83330,19.81591
57.60000,47.99993,19.77553
57.80000,48.16674,19.67895
58.00000,48.33330,19.86354
58.20000,48.49993,19.77122
58.40000,48.66675,19.86393
58.60000,48.83330,19.80836
58.80000,48.99987,19.78131
59.00000,49.16674,20.03935
59.20000,49.33331,20.04322
59.40000,49.49987,20.39063
59.60000,49.66668,20.09565
59.80000,49.83330,20.35054
60.00000,49.99993,20.25083
60.20000,50.16674,20.29552
60.40000,50.33331,20.24422
60.60000,50.49993,20.42115
60.80000,50.66680,20.44864
61.00000,50.83337,20.54738
61.20000,50.99993,20.36985
61.40000,51.16674,20.68859
61.60000,51.33336,20.61495
61.80000,51.49987,20.85274
62.00000,51.66674,20.82628
62.20000,51.83343,20.80129
62.40000,51.99993,20.81232
62.60000,52.16668,21.01988
62.80000,52.33331,20.60010
63.00000,52.49986,21.02831
63.20000,52.66674,21.15601
63.40000,52.83337,21.23098
63.60000,52.99993,21.13386
63.80000,53.16674,21.26606
64.00000,53.33330,21.17355
64.20000,53.49993,21.02204
64.40000,53.66674,21.25033
64.60001,53.83337,21.21912
64.80000,53.99987,21.60935
65.00000,54.16675,21.53061
65.20000,54.33330,21.69138
65.40000,54.49993,21.48592
65.60001,54.66674,21.62194
65.80000,54.83331,21.43457
66.00000,54.99993,21.78056
66.20001,55.16674,21.64679
66.40000,55.33330,21.94500
66.60001,55.49993,21.89316
66.80000,55.66674,21.82618
67.00000,55.83324,21.94451
67.20001,55.99987,22.01718
67.40000,56.16674,22.01835
67.60001,56.33337,22.00556
67.80000,56.49993,22.06422
68.00000,56.66674,22.39433
68.20001,56.83331,22.17667
68.40000,56.99987,22.09862
68.60001,57.16674,22.26953
68.80000,57.33337,22.21474
69.00000,57.49987,22.40413
69.20001,57.66674,22.30946
69.40000,57.83324,22.49870
69.60001,57.99993,22.60380
69.80000,58.16680,22.55897
70.00000,58.33331,22.83185
70.20001,58.49987,22.81137
70.40000,58.66674,22.78118
70.60001,58.83330,22.69146
70.80000,58.99993,22.83498
71.00000,59.16681,22.88884
71.20001,59.33337,22.96444
71.40000,59.49981,23.06171
71.60001,59.66668,23.35517
71.80000,59.83337,22.97253
72.00000,59.99999,23.15584
72.20001,60.16674,23.32538
72.40000,60.33331,23.28740
72.60001,60.49987,23.36296
72.80000,60.66674,23.32146
73.00000,60.83337,23.38422
73.20001,60.99987,23.41142
73.40000,61.16681,23.47762
73.60001,61.33331,23.57616
73.80000,61.49987,23.55994
74.00000,61.66674,23.71938
74.20001,61.83343,23.78857
74.40000,61.99993,23.72492
74.60001,62.16668,23.71091
74.80000,62.33331,23.86241
75.00000,62.49993,23.99667
75.20001,62.66674,24.15955
75.40000,62.83330,24.02671
75.60001,62.99987,24.01887
75.80000,63.16674,24.11197
76.00000,63.33330,23.99858
76.20001,63.49993,24.16043
76.40000,63.66680,24.20732
76.60001,63.83331,24.15921
76.80000,63.99993,24.20453
77.00000,64.16667,24.36231
77.20001,64.33337,24.41170
77.40000,64.49993,24.62539
77.60001,64.66674,24.46869
77.80000,64.83330,24.44620
78.00000,64.99987,24.72231
78.20001,65.16674,24.71672
78.40000,65.33337,24.78332
78.60001,65.49993,24.67738
78.80000,65.66674,24.83339
79.00000,65.83330,24.99426
79.20001,65.99993,24.91439
79.40000,66.16680,24.98642
79.60001,66.33336,25.06776
79.80000,66.49987,25.06776
80.00000,66.66668,25.34348
80.20001,66.83331,25.25616
80.40000,66.99986,25.27606
80.60001,67.16674,25.43443
80.80000,67.33330,25.42183
81.00001,67.49993,25.30203
81.20001,67.66674,25.31634
81.40000,67.83330,25.47990
81.60001,67.99986,25.60122
81.80000,68.16674,25.64929
82.00001,68.33330,25.60063
82.20001,68.49993,25.85127
82.40000,68.66674,25.71681
82.60001,68.83337,25.78767
82.80000,68.99992,25.80393
83.00001,69.16674,25.85102
83.20001,69.33324,26.05535
83.40000,69.49992,26.05859
83.60001,69.66680,26.01056
83.80000,69.83336,25.95035
84.00001,69.99987,26.10416
84.20001,70.16668,26.13899
84.40000,70.33330,26.38100
84.60001,70.49993,26.31441
84.80000,70.66674,26.45470
85.00001,70.83336,26.19735
85.20001,70.99993,26.38297
85.40000,71.16674,26.45852
85.60001,71.33331,26.66638
85.80000,71.49993,26.72400
86.00001,71.66674,26.56167
86.20001,71.83337,26.64585
86.40000,71.99986,26.72866
86.60001,72.16674,27.01741
86.80000,72.33337,26.77751
87.00001,72.49992,26.90682
87.20001,72.66674,27.04128
87.40000,72.83330,27.01658
87.60001,72.99987,27.17171
87.80000,73.16674,27.28309
88.00001,73.33330,27.35360
88.20001,73.49993,27.07259
88.40000,73.66674,27.36149
88.60001,73.83336,27.23933
88.80000,73.99987,27.34718
89.00001,74.16674,27.61727
89.20001,74.33336,27.33645
89.40000,74.49993,27.27574
89.60001,74.66668,27.59512
89.80000,74.83337,27.66774
90.00001,74.99993,27.67328
90.20001,75.16674,27.90034
90.40000,75.33330,27.88339
90.60001,75.49986,28.09546
90.80000,75.66674,27.97737
91.00001,75.83336,27.81817
91.20001,75.99999,28.17185
91.40000,76.16674,28.03171
91.60001,76.33330,28.00613
91.80000,76.49980,28.15063
92.00001,76.66674,28.05038
92.20001,76.83337,28.25902
92.40000,76.99999,28.56032
92.60001,77.16674,28.25172
92.80000,77.33330,28.56640
93.00001,77.49987,28.54205
93.20001,77.66674,28.47536
93.40000,77.83336,28.48089
93.60001,77.99999,28.79640
93.80000,78.16680,28.82482
94.00001,78.33330,28.77357
94.20001,78.49980,28.83457
94.40000,78.66680,28.81091
94.60001,78.83336,29.04434
94.80000,78.99993,29.00431
95.00001,79.16667,29.12578
95.20001,79.33330,28.90817
95.40000,79.49986,29.17610
95.60001,79.66674,29.23701
95.80000,79.83336,29.16214
96.00001,79.99986,29.46065
96.20001,80.16674,29.69276
96.40000,80.33330,29.31149
96.60001,80.49992,29.40895
96.80000,80.66674,29.53753
97.00001,80.83330,29.72622
97.20001,80.99993,29.72427
97.40000,81.16674,29.53870
97.60001,81.33336,29.75563
97.80000,81.49993,30.00778
98.00001,81.66668,30.00959
98.20001,81.83336,30.07310
98.40000,81.99986,30.00778
98.60001,82.16674,30.09676
98.80000,82.33336,30.25812
99.00001,82.49993,30.20343
99.20001,82.66667,30.08329
99.40000,82.83329,30.25057
99.60001,82.99992,30.43810
99.80000,83.16674,30.36699
100.00001,83.33337,30.45642
100.20001,83.49986,30.41801
100.40000,83.66674,30.59872
100.60001,83.83336,30.68407
100.80000,83.99987,30.64110
101.00001,84.16673,30.69828
101.20001,84.33335,30.69118
101.40000,84.49992,31.00973
101.60001,84.66673,30.77570
101.80000,84.83324,30.86106
102.00001,84.99992,30.94554
102.20001,85.16674,31.03570
102.40000,85.33330,31.17108
102.60001,85.49985,31.07578
102.80000,85.66674,31.23567
103.00001,85.83336,31.35037
103.20001,85.99993,31.26389
103.40000,86.16674,31.31652
103.60001,86.33330,31.39536
103.80000,86.49986,31.51878
104.00001,86.66680,31.48924
104.20001,86.83336,31.66074
104.40000,86.99981,31.80514
104.60001,87.16667,31.60307
104.80000,87.33337,31.71454
105.00001,87.49993,31.73228
105.20001,87.66674,31.62943
105.40000,87.83337,31.80813
105.60001,87.99986,31.86267
105.80000,88.16673,31.94357
106.00001,88.33330,32.25726
106.20001,88.49992,32.04205
106.40000,88.66673,32.12913
106.60001,88.83336,32.34507
106.80000,88.99986,32.19822
107.00001,89.16673,32.24330
107.20001,89.33336,32.17009
107.40000,89.49992,32.36879
107.60001,89.66668,32.45674
107.80000,89.83336,32.48065
108.00001,89.99986,32.62525
108.20001,90.16674,32.71776
108.40000,90.33336,32.68689
108.60001,90.49992,32.93008
108.80000,90.66674,32.73599
109.00001,90.83330,32.94547
109.20001,90.99992,32.92905
109.40000,91.16674,33.07125
109.60001,91.33336,32.99006
109.80000,91.49986,33.09986
110.00001,91.66667,33.02710
110.20001,91.83336,33.08232
110.40000,91.99993,33.31468
110.60001,92.16674,33.44037
110.80000,92.33336,33.28974
111.00001,92.49986,33.34178
111.20001,92.66668,33.65670
111.40000,92.83336,33.53116
111.60001,92.99998,33.59927
111.80000,93.16674,33.72760
112.00001,93.33330,33.89734
112.20001,93.49986,33.83795
112.40000,93.66673,33.64989
112.60001,93.83336,33.58653
112.80000,93.99986,34.14513
113.00001,94.16673,33.78856
113.20001,94.33329,33.98705
113.40001,94.49986,33.82026
113.60001,94.66674,33.90885
113.80000,94.83336,34.13312
114.00001,94.99992,34.34436
114.20001,95.16673,34.22098
114.40001,95.33330,34.32917
114.60001,95.49987,34.39209
114.80000,95.66673,34.45099
115.00001,95.83335,34.55359
115.20001,95.99992,34.62513
115.40001,96.16673,34.46936
115.60001,96.33336,34.69148
115.80000,96.49992,34.79452
116.00001,96.66674,34.72269
116.20001,96.83330,34.88160
116.40001,96.99993,34.83862
116.60001,97.16667,34.91546
116.80000,97.33336,34.89816
117.00001,97.49993,34.91624
117.20001,97.66674,35.14972
117.40001,97.83329,35.06402
117.60001,97.99986,35.30579
117.80000,98.16674,35.29065
118.00001,98.33336,35.36709
118.20001,98.49992,35.28550
118.40001,98.66673,35.45940
118.60001,98.83329,35.57847
118.80000,98.99992,35.51320
119.00001,99.16673,35.36773
119.20001,99.33342,35.73027
119.40001,99.49992,35.69338
119.60001,99.66668,35.76262
119.80000,99.83336,35.87267
120.00001,99.99992,35.76506
120.20001,100.16668,35.99340
120.40001,100.33330,35.88531
120.60001,100.49992,36.10816
120.80000,100.66673,35.86885
121.00001,100.83342,36.05367
121.20001,100.99986,36.04216
121.40001,101.16667,36.15309
121.60001,101.33336,36.36355
121.80000,101.49992,36.22101
122.00001,101.66674,36.39677
122.20001,101.83330,36.49340
122.40001,101.99992,36.50903
122.60001,102.16674,36.41098
122.80000,102.33330,36.61247
123.00001,102.49992,36.58973
123.20001,102.66673,36.62584
123.40001,102.83330,36.75991
123.60001,102.99992,36.77936
123.80000,103.16667,36.88001
124.00001,103.33324,37.03730
124.20001,103.49993,37.14759
124.40001,103.66674,37.06023
124.60001,103.83330,37.02608
124.80000,103.99986,37.17185
125.00001,104.16668,37.32287
125.20001,104.33336,37.23383
125.40001,104.49992,37.29116
125.60001,104.66673,37.32042
125.80000,104.83329,37.60682
126.00001,104.99992,37.63024
126.20001,105.16667,37.46183
126.40001,105.33337,37.50843
126.60001,105.49986,37.61706
126.80000,105.66680,37.59246
127.00001,105.83330,37.68444
127.20001,105.99992,37.80787
127.40001,106.16673,37.97030
127.60001,106.33335,37.95168
127.80000,106.49992,37.91851
128.00000,106.66673,38.11833
128.20002,106.83335,38.02298
128.40001,106.99986,38.17345
128.60001,107.16667,38.19972
128.80000,107.33336,38.20374
129.00000,107.49992,38.30066
129.20002,107.66674,38.29821
129.40001,107.83330,38.47147
129.60001,107.99993,38.47926
129.80000,108.16674,38.56506
130.00000,108.33336,38.72392
130.20002,108.49993,38.63641
130.40001,108.66667,38.83863
130.60001,108.83329,38.60171
130.80000,108.99992,38.82481
131.00000,109.16674,38.83407
131.20002,109.33336,38.93820
131.40002,109.49986,38.76591
131.60000,109.66667,39.17810
131.80000,109.83337,39.11954
132.00000,109.99999,38.88175
132.20002,110.16673,39.33857
132.40002,110.33324,39.29222
132.60000,110.49992,39.28796
132.80000,110.66680,39.28894
133.00000,110.83342,39.38513
133.20002,110.99992,39.36739
133.40002,111.16673,39.29766
133.60000,111.33330,39.40075
133.80000,111.49986,39.56657
134.00000,111.66673,39.54227
134.20002,111.83330,39.76997
134.40002,111.99992,39.60817
134.60000,112.16667,39.65183
134.80000,112.33330,39.91388
135.00000,112.49992,39.89085
135.20002,112.66674,39.91599
135.40002,112.83336,40.00752
135.60000,112.99992,40.19249
135.80000,113.16674,40.24198
136.00000,113.33330,40.17093
136.20002,113.49992,40.13825
136.40002,113.66680,39.95137
136.60000,113.83330,40.35493
136.80000,113.99986,40.26310
137.00000,114.16667,40.57151
137.20002,114.33336,40.59150
137.40002,114.49993,40.64878
137.60000,114.66667,40.77304
137.80000,114.83330,40.71224
138.00000,114.99986,40.60738
138.20002,115.16673,40.76471
138.40002,115.33336,40.94611
138.60000,115.49992,40.95483
138.80000,115.66667,40.97718
139.00000,115.83336,40.97066
139.20002,115.99992,40.94126
139.40002,116.16673,41.28833
139.60000,116.33337,41.12374
139.80000,116.49992,41.03152
140.00000,116.66667,41.10860
140.20002,116.83336,41.38834
140.40002,116.99992,41.40382
140.60000,117.16673,41.61266
140.80000,117.33335,41.39353
141.00000,117.49987,41.48565
141.20002,117.66667,41.65088
141.40002,117.83330,41.50074
141.60000,117.99992,41.63059
141.80000,118.16673,41.72967
142.00000,118.33330,41.66891
142.20002,118.49985,41.69635
142.40002,118.66674,41.99633
142.60000,118.83330,42.09810
142.80000,118.99993,41.77637
143.00000,119.16674,41.95732
143.20002,119.33336,42.00284
143.40002,119.49993,42.16768
143.60000,119.66674,42.05111
143.80000,119.83336,42.17140
144.00000,119.99992,42.53890
144.20002,120.16667,42.12343
144.40002,120.33329,42.23500
144.60000,120.49992,42.50098
144.80000,120.66673,42.56100
145.00000,120.83329,42.70143
145.20002,120.99986,42.70153
145.40002,121.16673,42.67198
145.60000,121.33330,42.66983
145.80000,121.49992,42.85608
146.00000,121.66673,42.73132
146.20002,121.83330,42.77768
146.40002,121.99992,43.03591
146.60000,122.16668,43.03963
146.80000,122.33336,43.21750
147.00000,122.49999,43.06134
147.20002,122.66673,43.08579
147.40002,122.83330,43.11494
147.60000,122.99986,43.19648
147.80000,123.16674,43.40208
148.00000,123.33336,43.28801
148.20002,123.49992,43.58892
148.40002,123.66667,43.37709
148.60000,123.83330,43.69388
148.80000,123.99986,43.53948
149.00000,124.16674,43.72823
149.20002,124.33336,43.62773
149.40002,124.49986,43.74420
149.60000,124.66667,43.81741
149.80000,124.83330,43.67937
150.00000,124.99992,43.75650
150.20002,125.16673,43.85352
150.40002,125.33336,43.85719
150.60000,125.49992,44.07215
150.80000,125.66673,44.10484
151.00000,125.83329,44.03442
151.20002,125.99997,44.23748
151.40002,126.16673,44.15820
151.60000,126.33336,44.33136
151.80000,126.49992,44.44152
152.00000,126.66672,44.33401
152.20002,126.83335,44.50737
152.40002,126.99991,44.57142
152.60000,127.16673,44.57725
152.80000,127.33328,44.62973
153.00000,127.49991,44.74840
153.20002,127.66673,44.47758
153.40002,127.83336,44.68142
153.60000,127.99992,44.85312
153.80000,128.16672,44.87845
154.00000,128.33329,44.82024
154.20002,128.49986,44.86997
154.40002,128.66679,44.96003
154.60000,128.83335,45.09571
154.80000,128.99992,44.98355
155.00000,129.16672,45.06484
155.20002,129.33329,45.17456
155.40002,129.49985,45.31455
155.60000,129.66679,45.30239
155.80000,129.83336,45.51231
156.00000,129.99984,45.61658
156.20002,130.16673,45.65725
156.40002,130.33330,45.59762
156.60000,130.49997,45.68204
156.80000,130.66674,45.65367
157.00000,130.83323,45.59233
157.20002,130.99985,45.46208
157.40002,131.16673,45.63888
157.60000,131.33335,45.81229
157.80000,131.49998,45.96821
158.00000,131.66673,46.00858
158.20002,131.83328,45.93562
158.40002,131.99992,46.18949
158.60000,132.16673,46.07522
158.80000,132.33336,46.11324
159.00000,132.49986,46.32801
159.20002,132.66667,46.35574
159.40002,132.83329,46.23780
159.60000,132.99991,46.43767
159.80000,133.16673,46.44904
160.00000,133.33330,46.68468
160.20002,133.49985,46.46158
160.40002,133.66672,46.64597
160.60000,133.83335,46.74711
160.80000,133.99998,46.64141
161.00002,134.16673,46.85211
161.20002,134.33336,46.84579
161.40002,134.49991,47.03057
161.60000,134.66666,46.84491
161.80000,134.83335,46.97755
162.00002,134.99992,47.01744
162.20002,135.16674,46.78748
162.40002,135.33329,47.06663
162.60000,135.49991,47.12911
162.80000,135.66673,47.02910
163.00002,135.83330,47.21780
163.20002,135.99992,47.25131
163.40002,136.16673,47.47132
163.60000,136.33328,47.38298
163.80000,136.49992,47.42884
164.00002,136.66674,47.23343
164.20002,136.83336,47.43492
164.40002,136.99993,47.46814
164.60000,137.16667,47.67409
164.80000,137.33335,47.47128
165.00002,137.49997,47.82932
165.20002,137.66673,47.74901
165.40002,137.83336,47.75116
165.60000,137.99985,48.01606
165.80000,138.16672,47.81251
166.00002,138.33329,47.78884
166.20002,138.49986,48.13944
166.40002,138.66680,47.92555
166.60000,138.83329,47.99621
166.80000,138.99985,48.24121
167.00002,139.16667,48.08941
167.20002,139.33335,48.29031
167.40002,139.49992,48.18623
167.60000,139.66672,48.29310
167.80000,139.83329,48.38189
168.00002,139.99991,48.60077
168.20002,140.16673,48.46249
168.40002,140.33335,48.54423
168.60000,140.49992,48.54408
168.80000,140.66673,48.67197
169.00002,140.83329,48.61861
169.20002,140.99992,48.66178
169.40002,141.16679,48.80422
169.60000,141.33330,48.75149
169.80000,141.49993,48.83900
170.00002,141.66667,48.95029
170.20002,141.83329,49.03819
170.40002,141.99986,48.98121
170.60000,142.16674,49.26658
170.80000,142.33328,48.99341
171.00002,142.49991,49.22973
171.20002,142.66667,49.24943
171.40002,142.83336,49.33033
171.60000,142.99992,49.56861
171.80000,143.16672,49.27799
172.00002,143.33329,49.46733
172.20002,143.49991,49.49663
172.40002,143.66673,49.37212
172.60000,143.83336,49.61105
172.80000,143.99998,49.65990
173.00002,144.16672,49.63187
173.20002,144.33329,49.71517
173.40002,144.49986,49.83630
173.60000,144.66673,49.76530
173.80000,144.83335,49.73835
174.00002,144.99992,49.91960
174.20002,145.16667,49.86271
174.40002,145.33329,50.06047
174.60000,145.49986,50.15220
174.80000,145.66674,50.00878
175.00002,145.83336,49.99364
175.20002,145.99991,49.96042
175.40002,146.16673,50.21277
175.60000,146.33330,50.36408
175.80000,146.49992,50.17024
176.00002,146.66679,50.26897
176.20002,146.83335,50.18974
176.40002,146.99985,50.32713
176.60000,147.16673,50.21208
176.80000,147.33336,50.35364
177.00002,147.49992,50.37799
177.20002,147.66666,50.50221
177.40002,147.83329,50.67302
177.60000,147.99992,50.73339
177.80000,148.16673,50.71590
178.00002,148.33330,50.77376
178.20002,148.49992,50.98231
178.40002,148.66672,51.01867
178.60000,148.83329,51.00877
178.80000,148.99991,51.19512
179.00002,149.16673,51.00039
179.20002,149.33336,51.17120
179.40002,149.49991,51.14288
179.60000,149.66667,51.06821
179.80000,149.83336,51.23731
180.00002,149.99992,51.33721
180.20002,150.16672,51.28763
180.40002,150.33334,51.40528
180.60000,150.49991,51.52724
180.80000,150.66673,51.56443
181.00002,150.83330,51.58937
181.20002,150.99992,51.56262
181.40002,151.16672,51.45707
181.60000,151.33329,51.71765
181.80000,151.49985,51.75582
182.00002,151.66673,51.78262
182.20002,151.83336,51.78233
182.40002,151.99992,51.98377
182.60000,152.16673,51.81266
182.80000,152.33335,51.87602
183.00002,152.49985,51.79546
183.20002,152.66674,52.25537
183.40002,152.83328,52.00048
183.60000,152.99991,51.98352
183.80000,153.16667,52.30820
184.00002,153.33329,52.28262
184.20002,153.49992,52.22788
184.40002,153.66673,52.32907
184.60000,153.83328,52.26728
184.80000,153.99992,52.25224
185.00002,154.16673,52.48474
185.20002,154.33336,52.53374
185.40002,154.49998,52.61959
185.60000,154.66672,52.69931
185.80000,154.83323,52.73714
186.00002,154.99991,52.58862
186.20002,155.16668,52.74258
186.40002,155.33342,52.67560
186.60000,155.49992,52.71338
186.80000,155.66672,52.89468
187.00002,155.83329,52.78815
187.20002,155.99986,52.96945
187.40002,156.16673,53.19333
187.60000,156.33328,52.82676
187.80000,156.49991,53.01320
188.00002,156.66673,53.01977
188.20002,156.83329,53.12591
188.40002,156.99985,53.39075
188.60000,157.16674,53.21655
188.80000,157.33335,53.19490
189.00002,157.49991,53.47866
189.20002,157.66667,53.27188
189.40002,157.83329,53.53604
189.60000,157.99992,53.26178
189.80000,158.16672,53.57308
190.00002,158.33328,53.65437
190.20002,158.49991,53.74536
190.40002,158.66673,53.63080
190.60000,158.83328,53.75791
190.80000,158.99984,53.71753
191.00002,159.16672,53.87301
191.20002,159.33335,53.76962
191.40002,159.49979,53.91823
191.60000,159.66672,53.65770
191.80000,159.83336,53.99085
192.00002,159.99997,53.78186
192.20002,160.16671,53.99678
192.40002,160.33323,53.98977
192.60000,160.49985,53.96458
192.80000,160.66680,53.94680
193.00002,160.83341,54.19861
193.20002,160.99999,54.15343
193.40002,161.16673,54.23874
193.60000,161.33329,54.21370
193.80000,161.49985,54.29906
194.00002,161.66680,54.33679
194.20002,161.83341,54.36217
194.40002,161.99991,54.42259
194.60000,162.16667,54.38270
194.80000,162.33329,54.42254
195.00002,162.49992,54.43214
195.20002,162.66672,54.64098
195.40002,162.83335,54.71237
195.60000,162.99991,54.71732
195.80000,163.16673,54.73736
196.00002,163.33321,54.73957
196.20002,163.49992,54.82850
196.40002,163.66672,54.91567
196.60000,163.83335,54.87833
196.80000,163.99985,55.03342
197.00002,164.16673,55.02323
197.20002,164.33336,54.95722
197.40002,164.49990,55.04680
197.60000,164.66672,55.18253
197.80000,164.83329,55.25118
198.00002,164.99991,55.33629
198.20002,165.16672,55.37789
198.40002,165.33328,55.37848
198.60000,165.49991,55.13700
198.80000,165.66673,55.34893
199.00002,165.83322,55.43287
199.20002,165.99992,55.39063
199.40002,166.16672,55.41449
199.60000,166.33328,55.52131
199.80000,166.49991,55.42600
200.00002,166.66673,55.44497
200.20002,166.83334,55.36456
200.40002,166.99998,55.71457
200.60000,167.16672,55.83315
200.80000,167.33335,55.81149
201.00002,167.49986,55.82487
201.20002,167.66673,55.99014
201.40002,167.83336,55.95530
201.60000,167.99990,55.93026
201.80000,168.16672,55.92443
202.00002,168.33330,55.95330
202.20002,168.49985,56.13940
202.40002,168.66671,56.21294
202.60000,168.83329,56.18447
202.80000,168.99984,56.14092
203.00002,169.16672,56.35617
203.20002,169.33329,56.36259
203.40002,169.49985,56.24832
203.60000,169.66673,56.39517
203.80000,169.83334,56.18119
204.00002,169.99992,56.46549
204.20002,170.16673,56.58632
204.40002,170.33329,56.42227
204.60000,170.49998,56.31575
204.80000,170.66672,56.38591
205.00002,170.83334,56.53957
205.20002,170.99986,56.68878
205.40002,171.16673,56.57456
205.60000,171.33327,56.58363
205.80000,171.49990,56.62650
206.00002,171.66672,56.75973
206.20002,171.83322,56.91756
206.40002,171.99986,56.79227
206.60000,172.16666,56.83647
206.80000,172.33342,56.83975
207.00002,172.49990,56.99268
207.20002,172.66672,57.13767
207.40002,172.83330,57.15188
207.60000,172.99986,56.84249
207.80000,173.16671,57.15394
208.00002,173.33334,56.99954
208.20002,173.49990,57.32353
208.40002,173.66679,57.33313
208.60000,173.83330,57.19162
208.80000,173.99983,57.31588
209.00002,174.16678,57.43192
209.20002,174.33334,57.64663
209.40002,174.49984,57.44009
209.60000,174.66666,57.37022
209.80000,174.83328,57.38546
210.00002,174.99998,57.61493
210.20002,175.16673,57.58543
210.40002,175.33334,57.66363
210.60000,175.49992,57.48072
210.80000,175.66679,57.77031
211.00002,175.83335,57.92593
211.20002,175.99998,57.92520
211.40002,176.16678,57.93254
211.60000,176.33328,57.86507
211.80000,176.49986,57.99517
212.00002,176.66671,57.97645
212.20002,176.83342,57.92436
212.40002,176.99985,57.95959
212.60000,177.16672,57.96714
212.80000,177.33330,58.08469
213.00002,177.49984,57.86840
213.20002,177.66671,58.12291
213.40002,177.83334,58.07391
213.60000,177.99990,58.51628
213.80000,178.16665,58.30583
214.00002,178.33328,58.43181
214.20002,178.49991,58.20851
214.40002,178.66679,58.50947
214.60000,178.83334,58.39173
214.80000,178.99992,58.54504
215.00002,179.16674,58.51383
215.20002,179.33335,58.64089
215.40002,179.49985,58.57390
215.60000,179.66673,58.44150
215.80000,179.83334,58.58101
216.00002,179.99992,58.67960
216.20002,180.16666,59.00931
216.40002,180.33328,58.59757
216.60000,180.49991,58.68460
216.80000,180.66678,58.93905
217.00002,180.83328,58.65995
217.20002,180.99984,58.95223
217.40002,181.16672,58.99824
217.60000,181.33335,58.90009
217.80000,181.49991,58.83409
218.00002,181.66672,58.96556
218.20002,181.83336,59.01774
218.40002,181.99991,58.89221
218.60000,182.16671,59.12021
218.80000,182.33335,59.05111
219.00002,182.49990,59.14446
219.20002,182.66665,59.27509
219.40002,182.83322,59.30665
219.60000,182.99984,59.35477
219.80000,183.16673,59.23878
220.00002,183.33329,59.22418
220.20002,183.49985,59.25868
220.40002,183.66672,59.38681
220.60000,183.83328,59.36839
220.80000,183.99991,59.37990
221.00002,184.16673,59.39039
221.20002,184.33329,59.55395
221.40002,184.49984,59.40347
221.60000,184.66672,59.71526
221.80000,184.83335,59.46305
222.00002,184.99991,59.42743
222.20002,185.16673,59.73133
222.40002,185.33329,59.65538
222.60000,185.49984,59.65136
222.80000,185.66672,59.91870
223.00002,185.83329,59.80057
223.20002,185.99991,59.94139
223.40002,186.16673,60.00843
223.60000,186.33328,59.97476
223.80000,186.49984,60.00514
224.00002,186.66672,60.20080
224.20002,186.83335,60.20535
224.40002,186.99991,60.06756
224.60000,187.16672,60.20560
224.80000,187.33328,60.19536
225.00002,187.49991,60.25641
225.20002,187.66671,60.13592
225.40002,187.83329,60.33780
225.60000,187.99990,60.30718
225.80002,188.16665,60.23911
226.00002,188.33328,60.50274
226.20002,188.49997,60.31820
226.40002,188.66673,60.28675
226.60000,188.83329,60.30115
226.80002,188.99985,60.66086
227.00002,189.16672,60.35240
227.20002,189.33333,60.47691
227.40002,189.49991,60.65008
227.60000,189.66665,60.61146
227.80002,189.83334,60.67090
228.00002,189.99984,60.91511
228.20002,190.16666,60.82491
228.40002,190.33335,60.73044
228.60000,190.49991,60.69863
228.80002,190.66671,60.72564
229.00002,190.83334,60.94652
229.20002,190.99990,61.02620
229.40002,191.16677,61.08049
229.60000,191.33329,60.99244
229.80002,191.49985,60.92555
230.00002,191.66671,61.24352
230.20002,191.83334,61.15649
230.40002,191.99984,61.22362
230.60000,192.16672,61.31020
230.80002,192.33329,61.36004
231.00002,192.49983,61.25772
231.20002,192.66665,61.16923
231.40002,192.83328,61.28551
231.60000,192.99991,61.19937
231.80002,193.16673,61.31295
232.00002,193.33327,61.27595
232.20002,193.49985,61.49292
232.40002,193.66672,61.55040
232.60000,193.83341,61.40041
232.80002,193.99991,61.53893
233.00002,194.16671,61.63052
233.20002,194.33334,61.75110
233.40002,194.49985,61.77389
233.60000,194.66672,61.54413
233.80002,194.83341,61.71406
234.00002,194.99991,61.74067
234.20002,195.16665,61.76757
234.40002,195.33329,62.25948
234.60000,195.49990,61.93946
234.80002,195.66672,62.07813
235.00002,195.83330,62.07019
235.20002,195.99991,62.25918
235.40002,196.16671,62.24179
235.60000,196.33334,62.28319
235.80002,196.49984,62.11620
236.00002,196.66679,62.37424
236.20002,196.83335,62.40559
236.40002,196.99983,62.36458
236.60000,197.16665,62.30804
236.80002,197.33334,62.31098
237.00002,197.49997,62.43333
237.20002,197.66673,62.54622
237.40002,197.83327,62.62403
237.60000,197.99991,62.67951
237.80002,198.16672,62.72718
238.00002,198.33334,62.72154
238.20002,198.49991,62.67308
238.40002,198.66666,63.00354
238.60000,198.83335,63.02363
238.80002,198.99985,62.92818
239.00002,199.16672,62.79461
239.20002,199.33335,62.91029
239.40002,199.49984,62.92891
239.60000,199.66666,63.12928
239.80002,199.83334,62.98713
240.00002,199.99990,62.97061
240.20002,200.16672,62.97110
240.40002,200.33328,63.16245
240.60000,200.49984,63.11830
240.80002,200.66671,63.05597
241.00002,200.83334,63.29695
241.20002,200.99990,63.17857
241.40002,201.16672,63.27054
241.60000,201.33328,63.28876
241.80002,201.49983,63.30675
242.00002,201.66673,63.49971
242.20002,201.83334,63.42891
242.40002,201.99992,63.54734
242.60000,202.16666,63.75946
242.80002,202.33333,63.67239
243.00002,202.49985,63.70042
243.20002,202.66673,63.68150
243.40002,202.83334,63.75652
243.60000,202.99992,63.77470
243.80002,203.16672,63.84408
244.00002,203.33327,63.86060
244.20002,203.49991,64.01808
244.40002,203.66672,64.03165
244.60000,203.83336,63.99113
244.80002,203.99984,64.08453
245.00002,204.16671,64.08423
245.20002,204.33335,64.19379
245.40002,204.49990,64.11025
245.60000,204.66672,64.31688
245.80002,204.83335,64.19634
246.00002,204.99984,64.15920
246.20002,205.16671,64.41165
246.40002,205.33334,64.50847
246.60000,205.49998,64.47579
246.80002,205.66672,64.57237
247.00002,205.83328,64.56644
247.20002,205.99991,64.48554
247.40002,206.16679,64.40616
247.60000,206.33334,64.53944
247.80002,206.49984,64.42218
248.00002,206.66666,64.83897
248.20002,206.83328,64.65826
248.40002,206.99985,64.71594
248.60000,207.16667,64.72839
248.80002,207.33334,64.62985
249.00002,207.49992,64.77905
249.20002,207.66666,64.61220
249.40002,207.83328,64.92095
249.60000,207.99991,64.89219
249.80002,208.16673,65.13881
250.00002,208.33336,64.74979
250.20002,208.49984,65.11681
250.40002,208.66672,65.02361
250.60000,208.83329,65.11695
250.80002,208.99991,65.09966
251.00002,209.16671,65.24832
251.20002,209.33334,65.19065
251.40002,209.49984,65.34495
251.60000,209.66666,65.41365
251.80002,209.83335,65.35549
252.00002,209.99990,65.32422
252.20002,210.16672,65.45339
252.40002,210.33322,65.53453
252.60000,210.49984,65.69035
252.80002,210.66673,65.62410
253.00002,210.83334,65.54712
253.20002,210.99992,65.61827
253.40002,211.16672,65.63821
253.60000,211.33333,65.49709
253.80002,211.49985,65.84592
254.00002,211.66673,65.86650
254.20002,211.83342,65.95377
254.40002,211.99984,66.02310
254.60000,212.16661,65.90379
254.80002,212.33335,65.85744
255.00002,212.49991,66.04893
255.20002,212.66671,66.03933
255.40002,212.83334,66.33347
255.60000,212.99990,66.23694
255.80002,213.16672,66.23910
256.00000,213.33329,66.23243
256.20002,213.49985,66.15883
256.40003,213.66678,66.10396
256.60000,213.83328,66.32259
256.80002,213.99984,66.33156
257.00000,214.16672,66.51962
257.20002,214.33335,66.59381
257.40003,214.49991,66.53907
257.60000,214.66672,66.51727
257.80002,214.83328,66.59798
258.00000,214.99991,66.53770
258.20002,215.16666,66.85493
258.40003,215.33335,66.61140
258.60000,215.49990,66.65251
258.80002,215.66667,66.62473
259.00000,215.83328,66.80994
259.20002,215.99986,66.74649
259.40003,216.16671,66.86879
259.60000,216.33334,66.92647
259.80002,216.49990,66.91868
260.00000,216.66666,66.84968
260.20002,216.83335,66.84870
260.40003,216.99985,67.16892
260.60000,217.16665,66.95552
260.80002,217.33334,67.12487
261.00000,217.49990,66.97767
261.20002,217.66672,67.05142
261.40003,217.83335,67.15878
261.60000,217.99991,67.35007
261.80002,218.16671,67.18313
262.00000,218.33323,67.47090
262.20000,218.49984,67.25702
262.40003,218.66672,67.44239
262.60000,218.83335,67.17534
262.80003,218.99983,67.38932
263.00000,219.16673,67.39250
263.20000,219.33334,67.60095
263.40003,219.49984,67.57135
263.60000,219.66666,67.63309
263.80003,219.83335,67.62653
264.00000,219.99991,67.70556
264.20000,220.16672,67.61330
264.40003,220.33334,67.65377
264.60000,220.49997,67.92322
264.80003,220.66671,67.76084
265.00000,220.83327,67.85438
265.20000,220.99990,68.03024
265.40003,221.16672,68.06199
265.60000,221.33335,67.99030
265.80003,221.49984,67.93474
266.00000,221.66671,67.95086
266.20000,221.83334,68.07650
266.40003,221.99985,68.50666
266.60000,222.16665,68.22261
266.80003,222.33341,68.33266
267.00000,222.49991,68.48089
267.20000,222.66665,68.35089
267.40003,222.83329,68.69634
267.60000,222.99990,68.32100
267.80003,223.16672,68.36138
268.00000,223.33335,68.47134
268.20000,223.49991,68.64935
268.40003,223.66673,68.44257
268.60000,223.83329,68.23824
268.80003,223.99984,68.36167
269.00000,224.16672,68.56693
269.20000,224.33333,68.49681
269.40003,224.49991,68.45614
269.60000,224.66660,68.57179
269.80003,224.83334,68.46663
270.00000,224.99992,68.48824
270.20000,225.16672,68.49392
270.40003,225.33327,68.65063
270.60000,225.49991,68.81331
270.80003,225.66672,68.83673
271.00000,225.83328,68.63426
271.20000,225.99991,68.80120
271.40003,226.16677,68.69051
271.60000,226.33329,68.94869
271.80003,226.49985,68.84011
272.00000,226.66672,68.86622
272.20000,226.83335,68.83536
272.40003,226.99989,68.90219
272.60000,227.16666,69.13445
272.80003,227.33329,68.92493
273.00000,227.49985,68.82722
273.20000,227.66672,69.24210
273.40003,227.83328,68.99230
273.60000,227.99991,68.90885
273.80003,228.16665,69.29669
274.00000,228.33321,69.14102
274.20000,228.49984,69.13078
274.40003,228.66677,69.15538
274.60000,228.83333,69.06090
274.80003,228.99991,69.11755
275.00000,229.16667,69.16596
275.20000,229.33334,68.82697
275.40003,229.49992,68.94614
275.60000,229.66672,68.98529
275.80003,229.83335,69.19653
276.00000,229.99991,69.04919
276.20000,230.16665,68.99206
276.40003,230.33328,69.11226
276.60000,230.49990,69.18511
276.80003,230.66672,68.90596
277.00000,230.83335,69.11519
277.20000,230.99985,68.87519
277.40003,231.16665,68.89886
277.60000,231.33334,68.85921
277.80003,231.49990,69.10872
278.00000,231.66671,69.01195
278.20000,231.83329,69.11421
278.40003,231.99985,69.00127
278.60000,232.16672,69.09005
278.80003,232.33334,69.10613
279.00000,232.49991,68.93046
279.20000,232.66666,68.99588
279.40003,232.83329,69.02175
279.60000,232.99992,68.92287
279.80003,233.16672,68.95031
280.00000,233.33333,68.82879
280.20000,233.49985,68.78038
280.40003,233.66665,68.71305
280.60000,233.83327,68.86235
280.80003,233.99990,69.21525
281.00000,234.16666,69.03175
281.20000,234.33335,69.14547
281.40003,234.49985,69.09608
281.60000,234.66665,69.47245
281.80003,234.83342,69.16448
282.00000,234.99997,69.12906
282.20000,235.16672,69.27028
282.40003,235.33329,69.38979
282.60000,235.49985,69.45623
282.80003,235.66671,69.54458
283.00000,235.83328,69.31982
283.20000,235.99990,69.54198
283.40003,236.16672,69.70643
283.60000,236.33329,69.59427
283.80003,236.49983,69.91379
284.00000,236.66672,69.84936
284.20000,236.83334,69.75645
284.40003,236.99991,69.85156
284.60000,237.16673,70.01067
284.80003,237.33327,69.50303
285.00000,237.49990,69.45329
285.20000,237.66667,69.32094
285.40003,237.83322,69.39562
285.60000,237.99991,69.36563
285.80003,238.16671,69.36303
286.00000,238.33334,69.34020
286.20000,238.49990,69.57010
286.40003,238.66672,69.33344
286.60000,238.83335,69.24122
286.80003,238.99985,69.18061
287.00000,239.16671,69.19790
287.20000,239.33342,69.25406
287.40003,239.49990,68.95844
287.60000,239.66659,68.95428
287.80003,239.83330,68.82521
288.00000,239.99991,68.77151
288.20000,240.16671,68.42317
288.40003,240.33334,68.32635
288.60000,240.49990,68.01127
288.80003,240.66672,67.87407
289.00000,240.83328,67.24379
289.20000,240.99983,66.49311
289.40003,241.16678,65.57505
289.60000,241.33334,63.38804
289.80003,241.49984,61.16335
290.00000,241.66666,57.05305
290.20000,241.83335,-0.40946
290.40003,241.99998,0.61404
290.60000,242.16667,0.44578
290.73000,242.27496,0.60567