File: V_8/EPR/RDSO EPR Tensile 50.is_tens_RawData/Specimen_RawData_1.csv
Time,Extension,Load
(sec),(mm),(N)
0.00000,0.00000,-0.10674
0.30000,0.24925,0.71146
0.60000,0.49994,1.49506
0.90000,0.74994,2.04327
1.20000,0.99994,2.39156
1.50000,1.24987,2.67478
1.80000,1.49994,3.20148
2.10000,1.75000,3.70216
2.40000,1.99994,3.82226
2.70000,2.24987,4.03257
3.00000,2.49994,4.54025
3.30000,2.74994,4.77570
3.60000,2.99994,5.05897
3.90000,3.24981,5.17421
4.20000,3.49987,5.43333
4.50000,3.74994,5.91049
4.80000,3.99994,5.93146
5.10000,4.24994,6.23986
5.40000,4.49994,6.52813
5.70000,4.75000,6.49378
6.00000,4.99994,6.85128
6.30000,5.24994,7.06453
6.60000,5.50000,7.15028
6.90000,5.74994,7.49058
7.20000,5.99994,7.49156
7.50000,6.24994,7.77821
7.80000,6.49994,7.71348
8.10000,6.74994,8.11396
8.40000,6.99987,8.26733
8.70000,7.24994,8.41467
9.00000,7.49994,8.60572
9.30000,7.74987,8.88135
9.60000,7.99987,8.83019
9.90000,8.25000,9.12703
10.20000,8.49981,9.04020
10.50000,8.74987,9.18559
10.80000,8.99987,9.43612
11.10000,9.24994,9.59694
11.40000,9.49994,9.62732
11.70000,9.74987,9.58023
12.00000,10.00000,9.51359
12.30000,10.24994,10.01315
12.60000,10.49994,10.01011
12.90000,10.74994,10.09429
13.20000,10.99994,10.42156
13.50000,11.24994,10.53735
13.80000,11.49987,10.45380
14.10000,11.74994,10.62266
14.40000,11.99987,10.82532
14.70000,12.24987,10.86197
15.00000,12.49994,11.04631
15.30000,12.74987,10.91048
15.60000,12.99994,10.95688
15.90000,13.24987,11.38509
16.20000,13.49994,11.31385
16.50000,13.74987,11.56188
16.80000,13.99987,11.62044
17.10000,14.24994,11.73529
17.40000,14.50000,11.64146
17.70000,14.74994,11.71119
18.00000,14.99994,11.95658
18.30000,15.24994,11.95320
18.60000,15.50000,12.14092
18.90000,15.74987,12.19658
19.20000,15.99994,12.13896
19.50000,16.25000,12.05100
19.80000,16.49987,12.34137
20.10000,16.74994,12.42761
20.40000,16.99987,12.56859
20.70000,17.24993,12.53482
21.00000,17.49994,12.50954
21.30000,17.74987,12.65840
21.60000,17.99993,12.79643
21.90000,18.24987,12.85220
22.20000,18.49987,12.66536
22.50000,18.74994,12.88145
22.80000,18.99993,13.00905
23.10000,19.24987,12.89880
23.40000,19.50000,13.01561
23.70000,19.74993,13.27310
24.00000,19.99993,13.16991
24.30000,20.24994,13.35400
24.60000,20.49993,13.31534
24.90000,20.74993,13.38566
25.20000,20.99993,13.47797
25.50000,21.24987,13.61556
25.80000,21.49994,13.66613
26.10000,21.74993,13.64751
26.40000,21.99987,13.71381
26.70000,22.24993,13.64487
27.00000,22.49993,13.74316
27.30000,22.74993,13.87551
27.60000,22.99994,13.85645
27.90000,23.24993,13.98130
28.20000,23.49993,13.97263
28.50000,23.74987,14.24188
28.80000,23.99987,14.02726
29.10000,24.25000,14.15682
29.40000,24.49993,14.25104
29.70000,24.74987,14.26942
30.00000,24.99999,14.29897
30.30000,25.25000,14.24918
30.60000,25.49981,14.47782
30.90000,25.74987,14.46140
31.20000,25.99993,14.65172
31.50000,26.25000,14.44376
31.80000,26.49987,14.76564
32.10000,26.74993,14.54382
32.40000,26.99994,14.79009
32.70000,27.24993,14.81601
33.00000,27.49993,14.84492
33.30000,27.74993,15.01015
33.60000,28.00000,15.09732
33.90000,28.24987,15.00897
34.20000,28.49987,15.01755
34.50000,28.75000,14.89985
34.80000,28.99987,15.10526
35.10000,29.24993,15.41200
35.40000,29.49993,15.34271
35.70000,29.74994,15.41807
36.00000,29.99993,15.22394
36.30000,30.24987,15.42856
36.60000,30.49999,15.43792
36.90000,30.74993,15.67655
37.20000,30.99993,15.55459
37.50000,31.24993,15.72829
37.80000,31.49993,15.72589
38.10000,31.74993,15.70428
38.40000,31.99987,15.78391
38.70000,32.24999,15.98961
39.00000,32.49993,15.79033
39.30000,32.74987,16.03763
39.60000,33.00000,15.90165
39.90000,33.24993,16.07786
40.20000,33.49993,15.94791
40.50000,33.74993,16.16052
40.80000,33.99981,16.33653
41.10000,34.24987,16.25906
41.40000,34.49987,16.24975
41.70000,34.74993,16.14548
42.00000,34.99987,16.29978
42.30000,35.24993,16.35946
42.60000,35.49987,16.43899
42.90000,35.75000,16.61607
43.20000,35.99987,16.57800
43.50000,36.24987,16.81609
43.80000,36.49993,16.55649
44.10000,36.74993,16.83598
44.40000,36.99993,16.87567
44.70000,37.24987,16.94961
45.00000,37.49993,16.92766
45.30000,37.74993,16.99778
45.60000,37.99993,17.07221
45.90000,38.24987,17.14086
46.20000,38.49993,17.10431
46.50000,38.74987,17.35225
46.80000,38.99987,17.30687
47.10000,39.24993,17.22519
47.40000,39.49993,17.25865
47.70000,39.74987,17.40580
48.00000,39.99987,17.52335
48.30000,40.24987,17.48263
48.60000,40.49993,17.52492
48.90000,40.74987,17.69769
49.20000,40.99987,17.73920
49.50000,41.24993,17.83411
49.80000,41.49993,17.66447
50.10000,41.74993,17.79452
50.40000,41.99993,18.00238
50.70000,42.24993,18.19098
51.00000,42.49993,18.02977
51.30000,42.74987,18.23385
51.60000,42.99993,18.04133
51.90000,43.24993,18.31715
52.20000,43.49981,18.47268
52.50000,43.74993,18.34464
52.80000,43.99993,18.28628
53.10000,44.24993,18.64300
53.40000,44.49987,18.71474
53.70000,44.74987,18.55000
54.00000,44.99999,18.61796
54.30000,45.24987,18.73811
54.60000,45.49993,18.82993
54.90000,45.74993,18.93367
55.20000,45.99987,19.05768
55.50000,46.24993,18.99041
55.80000,46.49993,19.17646
56.10000,46.74993,19.13491
56.40000,46.99986,19.28279
56.70000,47.24993,19.22963
57.00000,47.49993,19.21674
57.30000,47.74987,19.30553
57.60000,47.99993,19.37055
57.90000,48.24993,19.76867
58.20000,48.49993,19.49158
58.50000,48.74993,19.52730
58.80000,48.99987,19.74417
59.10000,49.24993,19.75971
59.40000,49.49987,20.09624
59.70000,49.74993,19.93978
60.00000,49.99993,20.10481
60.30000,50.24993,19.91851
60.60000,50.49993,20.24716
60.90000,50.74987,20.21369
61.20000,50.99987,20.20159
61.50000,51.24993,20.35407
61.80000,51.49987,20.48226
62.10000,51.74993,20.28827
62.40000,51.99993,20.30439
62.70000,52.24993,20.67811
63.00000,52.49986,20.63465
63.30000,52.74993,20.66449
63.60000,52.99993,20.73990
63.90000,53.24987,20.77856
64.20000,53.49987,20.97887
64.50000,53.74993,20.95084
64.80000,53.99993,20.95266
65.10001,54.24987,20.91703
65.40000,54.49993,21.04845
65.70001,54.74993,21.32461
66.00000,54.99993,21.27507
66.30000,55.24987,21.19574
66.60001,55.49993,21.49288
66.90000,55.74993,21.52169
67.20001,55.99987,21.52233
67.50000,56.24987,21.71970
67.80000,56.49987,21.80751
68.10001,56.74993,21.68692
68.40000,56.99987,21.87503
68.70001,57.24987,21.81907
69.00000,57.49993,21.93799
69.30000,57.74986,22.03090
69.60001,57.99993,22.21195
69.90000,58.24993,22.27492
70.20001,58.49987,22.37355
70.50000,58.74993,22.21298
70.80000,58.99993,22.26306
71.10001,59.24999,22.67961
71.40000,59.49981,22.43118
71.70001,59.74993,22.48674
72.00000,59.99999,22.71513
72.30000,60.24987,22.56132
72.60001,60.49987,22.86483
72.90000,60.74993,23.02966
73.20001,60.99993,22.93019
73.50000,61.24993,23.06788
73.80000,61.49987,23.20802
74.10001,61.74999,23.26065
74.40000,61.99993,23.17568
74.70001,62.24987,23.16936
75.00000,62.49993,23.26672
75.30000,62.74993,23.46527
75.60001,62.99987,23.55705
75.90000,63.24986,23.51314
76.20001,63.49993,23.68126
76.50000,63.74992,23.75550
76.80000,63.99993,23.94464
77.10001,64.24987,23.86638
77.40000,64.49993,23.83806
77.70001,64.74993,24.11182
78.00000,64.99992,24.09315
78.30000,65.24993,24.16592
78.60001,65.49993,24.28646
78.90000,65.74986,24.42077
79.20001,65.99993,24.47780
79.50000,66.24993,24.51666
79.80000,66.49987,24.56708
80.10001,66.74992,24.66243
80.40000,66.99986,24.85990
80.70001,67.24992,24.82198
81.00001,67.49993,24.81090
81.30000,67.74993,25.08623
81.60001,67.99986,25.13224
81.90000,68.24993,25.03233
82.20001,68.49993,25.01136
82.50001,68.74999,25.29105
82.80000,68.99992,25.41688
83.10001,69.24986,25.15434
83.40000,69.49992,25.39640
83.70001,69.74999,25.58201
84.00001,69.99987,25.68628
84.30000,70.24986,25.63733
84.60001,70.49993,25.80349
84.90000,70.74993,25.77032
85.20001,70.99986,25.97284
85.50001,71.24993,25.84073
85.80000,71.49993,25.81648
86.10001,71.74992,26.11307
86.40000,71.99993,26.18280
86.70001,72.24993,26.24905
87.00001,72.49999,26.19745
87.30000,72.74986,26.37380
87.60001,72.99987,26.50929
87.90000,73.24993,26.67182
88.20001,73.49993,26.59308
88.50001,73.74987,26.88041
88.80000,73.99987,26.79672
89.10001,74.24993,26.88017
89.40000,74.49993,27.00590
89.70001,74.74986,27.04265
90.00001,74.99993,27.12193
90.30000,75.24987,27.21018
90.60001,75.49993,27.34111
90.90000,75.74987,27.17632
91.20001,75.99999,27.36335
91.50001,76.24999,27.50217
91.80000,76.49980,27.49683
92.10001,76.74999,27.59654
92.40000,76.99999,27.75359
92.70001,77.24993,27.99339
93.00001,77.49993,27.70003
93.30000,77.74986,27.92822
93.60001,77.99999,27.98398
93.90000,78.24986,28.17420
94.20001,78.49974,28.12844
94.50001,78.74993,28.30699
94.80000,78.99993,28.38196
95.10001,79.24993,28.23256
95.40000,79.49992,28.60148
95.70001,79.74993,28.31709
96.00001,79.99986,28.47154
96.30000,80.24986,28.61011
96.60001,80.49992,28.81870
96.90000,80.74986,28.88989
97.20001,80.99993,29.02171
97.50001,81.24992,29.06316
97.80000,81.49993,29.15440
98.10001,81.74992,29.00843
98.40000,81.99986,29.07972
98.70001,82.24992,29.36853
99.00001,82.49993,29.44742
99.30000,82.74986,29.47304
99.60001,82.99992,29.64297
99.90000,83.24986,29.62578
100.20001,83.49992,29.90664
100.50001,83.74986,29.60637
100.80000,83.99987,29.89444
101.10001,84.24993,29.99523
101.40000,84.49992,30.07692
101.70001,84.74993,30.11739
102.00001,84.99992,29.98431
102.30000,85.24993,30.35455
102.60001,85.49985,30.46367
102.90000,85.74992,30.30139
103.20001,85.99993,30.43251
103.50001,86.24992,30.80064
103.80000,86.49986,30.63777
104.10001,86.74999,30.96465
104.40000,86.99981,30.92393
104.70001,87.24992,31.06769
105.00001,87.49993,31.01414
105.30000,87.74993,31.14526
105.60001,87.99986,31.20725
105.90000,88.24986,31.17946
106.20001,88.49992,31.23135
106.50001,88.74992,31.50982
106.80000,88.99986,31.43872
107.10001,89.24986,31.71366
107.40000,89.49992,31.52486
107.70001,89.74986,31.72694
108.00001,89.99986,32.11374
108.30000,90.24993,31.75751
108.60001,90.49992,31.83782
108.90000,90.74987,31.92867
109.20001,90.99992,32.00330
109.50001,91.24992,32.25045
109.80000,91.49986,32.10791
110.10001,91.74992,32.21674
110.40000,91.99993,32.31366
110.70001,92.24986,32.50060
111.00001,92.49993,32.49217
111.30000,92.74987,32.69454
111.60001,92.99998,32.76333
111.90000,93.24992,32.75985
112.20001,93.49986,32.68048
112.50001,93.74999,32.78867
112.80000,93.99986,33.00010
113.10001,94.24992,33.21433
113.40001,94.49992,33.23496
113.70001,94.74993,33.37843
114.00001,94.99992,33.30390
114.30000,95.24986,33.33668
114.60001,95.49987,33.31027
114.90001,95.74998,33.63974
115.20001,95.99992,33.61471
115.50001,96.24992,33.79703
115.80000,96.49992,33.77856
116.10001,96.74992,33.86220
116.40001,96.99985,34.00489
116.70001,97.24992,34.11764
117.00001,97.49993,34.24690
117.30000,97.74987,34.26640
117.60001,97.99986,34.20844
117.90001,98.24986,34.20060
118.20001,98.49992,34.33927
118.50001,98.74986,34.46294
118.80000,98.99992,34.62200
119.10001,99.24993,34.77296
119.40001,99.49992,34.92124
119.70001,99.74986,34.87635
120.00001,99.99992,34.96945
120.30000,100.24992,35.06246
120.60001,100.49992,35.20803
120.90001,100.74986,35.23469
121.20001,100.99986,35.06255
121.50001,101.24993,35.34455
121.80000,101.49992,35.10053
122.10001,101.74992,35.49865
122.40001,101.99992,35.42197
122.70001,102.24992,35.64609
123.00001,102.49992,35.78138
123.30000,102.74986,35.93250
123.60001,102.99992,35.83469
123.90001,103.24986,35.92877
124.20001,103.49993,35.84102
124.50001,103.74999,36.24521
124.80000,103.99986,36.14398
125.10001,104.24992,36.37639
125.40001,104.49998,36.54705
125.70001,104.74992,36.36806
126.00001,104.99992,36.49599
126.30000,105.24986,36.45106
126.60001,105.49992,36.60326
126.90001,105.74993,36.71845
127.20001,105.99986,36.86281
127.50001,106.24993,36.97085
127.80000,106.49987,37.03186
128.10001,106.74986,37.01721
128.40001,106.99986,37.16818
128.70002,107.24992,37.24785
129.00000,107.49992,37.33203
129.30000,107.74986,37.27965
129.60001,107.99993,37.53538
129.90001,108.24992,37.54915
130.20002,108.49993,37.58075
130.50000,108.74992,37.55924
130.80000,108.99992,37.72873
131.10000,109.24992,38.05698
131.40002,109.49986,38.07310
131.70002,109.74986,38.03155
132.00000,109.99999,38.19178
132.30000,110.24985,38.12828
132.60000,110.49992,38.14984
132.90002,110.74992,38.30825
133.20002,110.99992,38.49700
133.50000,111.24992,38.45687
133.80000,111.49986,38.47941
134.10000,111.74999,38.63984
134.40002,111.99992,38.65890
134.70002,112.24986,38.82393
135.00000,112.49992,38.90380
135.30000,112.74992,38.95437
135.60000,112.99992,38.95515
135.90002,113.24986,39.20005
136.20002,113.49992,39.38650
136.50000,113.74992,39.13160
136.80000,113.99986,39.61351
137.10000,114.24992,39.45338
137.40002,114.49993,39.48224
137.70002,114.74986,39.46406
138.00000,114.99993,39.66619
138.30000,115.24992,40.00384
138.60000,115.49992,39.68598
138.90002,115.74986,39.65428
139.20002,115.99992,39.92844
139.50000,116.24992,40.06539
139.80000,116.49992,40.25899
140.10000,116.74993,40.30573
140.40002,116.99999,40.35356
140.70002,117.24993,40.43142
141.00000,117.49987,40.47228
141.30000,117.74986,40.70395
141.60000,117.99992,40.68553
141.90002,118.24986,40.67656
142.20002,118.49992,40.56842
142.50000,118.74992,40.81768
142.80000,118.99985,40.90966
143.10000,119.24986,40.86115
143.40002,119.49993,41.05518
143.70002,119.74992,40.93940
144.00000,119.99992,40.99545
144.30000,120.24986,41.00428
144.60000,120.49992,41.31635
144.90002,120.74992,41.27304
145.20002,120.99986,41.55729
145.50000,121.24993,41.74148
145.80000,121.49992,41.63838
146.10000,121.74992,41.90386
146.40002,121.99992,41.80503
146.70002,122.24992,42.07546
147.00000,122.49992,42.07923
147.30000,122.74992,41.77558
147.60000,122.99986,41.98996
147.90002,123.24993,42.14715
148.20002,123.49992,42.33222
148.50000,123.74992,42.25333
148.80000,123.99986,42.31384
149.10000,124.24992,42.68438
149.40002,124.49986,42.69972
149.70002,124.74992,42.68242
150.00000,124.99992,42.84358
150.30000,125.24992,42.67385
150.60000,125.49992,42.83143
150.90002,125.74992,43.02366
151.20002,125.99997,43.05178
151.50000,126.24991,43.06712
151.80000,126.49992,43.11573
152.10000,126.74992,43.26601
152.40002,126.99998,43.12886
152.70002,127.24985,43.44437
153.00000,127.49985,43.36533
153.30000,127.74984,43.37748
153.60000,127.99992,43.58573
153.90002,128.24985,43.83064
154.20002,128.49986,43.85783
154.50000,128.74993,43.78972
154.80000,128.99986,43.87469
155.10000,129.24986,44.18755
155.40002,129.49991,44.25943
155.70002,129.74999,44.08176
156.00000,129.99984,44.25537
156.30000,130.24986,44.26071
156.60000,130.49997,44.23479
156.90002,130.74991,44.27286
157.20002,130.99985,44.35738
157.50000,131.24998,44.66089
157.80000,131.49992,44.60787
158.10000,131.74991,44.62816
158.40002,131.99992,44.80607
158.70002,132.24992,44.87218
159.00000,132.49986,45.10252
159.30000,132.74985,44.91201
159.60000,132.99991,45.15290
159.90002,133.24991,45.00124
160.20002,133.49985,45.04676
160.50000,133.74992,45.54739
160.80000,133.99998,45.36580
161.10000,134.24992,45.62227
161.40002,134.49985,45.54132
161.70002,134.74992,45.54014
162.00002,134.99992,45.87412
162.30000,135.24991,45.91999
162.60000,135.49991,45.93091
162.90002,135.74985,45.85624
163.20002,135.99992,46.19483
163.50002,136.24991,46.28308
163.80000,136.49992,46.12236
164.10000,136.74991,46.11912
164.40002,136.99993,46.27710
164.70002,137.24986,46.48025
165.00002,137.49997,46.45683
165.30000,137.74991,46.43885
165.60000,137.99985,46.59526
165.90002,138.24992,46.75098
166.20002,138.49986,47.01626
166.50002,138.74997,46.88176
166.80000,138.99985,46.78626
167.10000,139.24993,47.03572
167.40002,139.49992,47.24005
167.70002,139.74986,47.24161
168.00002,139.99998,47.21060
168.30000,140.24998,47.29336
168.60000,140.49992,47.19506
168.90002,140.74986,47.26807
169.20002,140.99992,47.51263
169.50002,141.24999,47.53963
169.80000,141.49985,47.66184
170.10000,141.74992,47.70059
170.40002,141.99986,47.54860
170.70002,142.24991,47.91178
171.00002,142.49985,47.78507
171.30000,142.74985,47.89620
171.60000,142.99992,47.98754
171.90002,143.24992,48.04154
172.20002,143.49991,47.99915
172.50002,143.74998,48.22754
172.80000,143.99992,48.30133
173.10000,144.24986,48.42016
173.40002,144.49986,48.40409
173.70002,144.74991,48.70254
174.00002,144.99992,48.53854
174.30000,145.24986,48.80118
174.60000,145.49986,48.73875
174.90002,145.74992,48.88859
175.20002,145.99991,48.81955
175.50002,146.24985,48.92873
175.80000,146.49992,49.11865
176.10000,146.74991,48.96405
176.40002,146.99985,49.09415
176.70002,147.24985,49.27696
177.00002,147.49992,49.33072
177.30000,147.74992,49.20788
177.60000,147.99992,49.37477
177.90002,148.24999,49.43392
178.20002,148.49992,49.48448
178.50002,148.74992,49.60355
178.80000,148.99986,49.57680
179.10000,149.24991,49.90367
179.40002,149.49991,49.74021
179.70002,149.74984,49.78333
180.00002,149.99992,50.02515
180.30000,150.24992,49.83223
180.60000,150.49986,50.23879
180.90002,150.74993,50.05964
181.20002,150.99992,50.27353
181.50002,151.24992,50.49559
181.80000,151.49985,50.33673
182.10000,151.74999,50.32311
182.40002,151.99992,50.62245
182.70002,152.24986,50.58747
183.00002,152.49985,50.88230
183.30000,152.74986,50.86829
183.60000,152.99991,50.75799
183.90002,153.24985,50.97329
184.20002,153.49992,50.92689
184.50002,153.74998,51.00725
184.80000,153.99992,51.18556
185.10000,154.24985,51.23289
185.40002,154.49998,51.43468
185.70002,154.74992,51.08673
186.00002,154.99991,51.20859
186.30000,155.24991,51.38014
186.60000,155.49992,51.31032
186.90002,155.74986,51.49896
187.20002,155.99986,51.59535
187.50002,156.24992,51.67247
187.80000,156.49991,51.68007
188.10000,156.74992,51.69207
188.40002,156.99985,51.89365
188.70002,157.24991,51.74279
189.00002,157.49991,51.90943
189.30000,157.74984,51.99519
189.60000,157.99992,51.99568
189.90002,158.24990,52.04046
190.20002,158.49991,52.25327
190.50002,158.74984,52.28678
190.80000,158.99984,52.41414
191.10000,159.24992,52.30932
191.40002,159.49979,52.56099
191.70002,159.74991,52.60445
192.00002,159.99997,52.55658
192.30000,160.24992,52.84033
192.60000,160.49985,52.81696
192.90002,160.74991,52.71822
193.20002,160.99991,52.86473
193.50002,161.24984,52.92702
193.80000,161.49985,53.02629
194.10000,161.74996,53.03776
194.40002,161.99991,53.15727
194.70002,162.24984,53.12115
195.00002,162.49992,53.26810
195.30000,162.74985,53.43284
195.60000,162.99991,53.39217
195.90002,163.24984,53.48086
196.20002,163.49992,53.72743
196.50002,163.74992,53.69519
196.80000,163.99985,53.83944
197.10000,164.24986,53.74429
197.40002,164.49990,53.76129
197.70002,164.74985,53.92220
198.00002,164.99985,54.13432
198.30000,165.24991,53.90157
198.60000,165.49991,54.28377
198.90002,165.74990,54.15897
199.20002,165.99992,54.10144
199.50002,166.24991,54.24349
199.80000,166.49991,54.38799
200.10000,166.74984,54.25559
200.40002,166.99992,54.44606
200.70002,167.24985,54.49736
201.00002,167.49986,54.56062
201.30000,167.74984,54.59198
201.60000,167.99990,54.67553
201.90002,168.24992,54.78004
202.20002,168.49991,54.89456
202.50002,168.74991,54.86123
202.80000,168.99984,54.98324
203.10000,169.24992,54.92287
203.40002,169.49985,55.03822
203.70002,169.74986,54.98790
204.00002,169.99992,55.01269
204.30000,170.24990,55.08751
204.60000,170.49998,55.07031
204.90002,170.74991,55.22711
205.20002,170.99986,55.29572
205.50002,171.24990,55.43463
205.80000,171.49998,55.36133
206.10000,171.74991,55.56614
206.40002,171.99986,55.48128
206.70002,172.24984,55.72941
207.00002,172.49990,55.65552
207.30000,172.74993,55.76313
207.60000,172.99991,55.96574
207.90002,173.24986,55.95129
208.20002,173.49990,56.08466
208.50002,173.74985,55.96447
208.80000,173.99983,56.07060
209.10000,174.24991,56.27591
209.40002,174.49984,56.26817
209.70002,174.74985,56.40723
210.00002,174.99991,56.40140
210.30000,175.24991,56.27895
210.60000,175.49992,56.64669
210.90002,175.74985,56.57427
211.20002,175.99998,56.63150
211.50002,176.24991,56.68559
211.80000,176.49991,56.58569
212.10000,176.74992,56.56530
212.40002,176.99990,56.73023
212.70002,177.24991,56.63782
213.00002,177.49984,56.89923
213.30000,177.74992,56.77110
213.60000,177.99990,57.02012
213.90002,178.24979,57.15943
214.20002,178.49991,57.12312
214.50002,178.74997,57.25027
214.80000,178.99992,57.22234
215.10000,179.24985,57.36052
215.40002,179.49985,57.17011
215.70002,179.74991,57.36136
216.00002,179.99992,57.43378
216.30000,180.24985,57.38037
216.60000,180.49991,57.65614
216.90002,180.74991,57.46714
217.20002,180.99984,57.54250
217.50002,181.24992,57.85983
217.80000,181.49991,57.81563
218.10000,181.74985,57.81867
218.40002,181.99991,58.05705
218.70002,182.24992,58.11928
219.00002,182.49990,58.01369
219.30000,182.74985,57.93304
219.60000,182.99984,57.94636
219.90002,183.24992,58.16946
220.20002,183.49985,58.11840
220.50002,183.74991,58.28980
220.80000,183.99991,58.36688
221.10000,184.24984,58.20876
221.40002,184.49984,58.49747
221.70002,184.74985,58.56518
222.00002,184.99991,58.67445
222.30000,185.24984,58.59007
222.60000,185.49992,58.82307
222.90002,185.74992,58.42352
223.20002,185.99991,58.62800
223.50002,186.24991,58.96762
223.80000,186.49984,58.84541
224.10000,186.74985,58.88407
224.40002,186.99991,58.89142
224.70002,187.24985,58.94434
225.00002,187.49991,59.13417
225.30002,187.74990,58.90554
225.60000,187.99990,59.09271
225.90002,188.24991,59.16832
226.20002,188.49997,59.36961
226.50002,188.74984,59.26226
226.80002,188.99985,59.32439
227.10000,189.24996,59.33291
227.40002,189.49991,59.27347
227.70002,189.74984,59.46379
228.00002,189.99984,59.46893
228.30002,190.24990,59.61388
228.60000,190.49991,59.74285
228.90002,190.74984,59.52176
229.20002,190.99990,59.61530
229.50002,191.24992,59.92944
229.80002,191.49991,59.86569
230.10000,191.74986,59.99578
230.40002,191.99990,59.87510
230.70002,192.24990,59.89778
231.00002,192.49983,60.05056
231.30002,192.74991,59.88901
231.60000,192.99997,60.13534
231.90002,193.24984,60.27626
232.20002,193.49990,60.04316
232.50002,193.74991,60.32771
232.80002,193.99991,60.40929
233.10000,194.24984,60.50788
233.40002,194.49985,60.34108
233.70002,194.74998,60.67002
234.00002,194.99991,60.59966
234.30002,195.24978,60.74161
234.60000,195.49990,60.61602
234.90002,195.74990,60.81006
235.20002,195.99991,60.89454
235.50002,196.24986,60.72465
235.80002,196.49990,61.07059
236.10000,196.74990,60.92320
236.40002,196.99983,60.99925
236.70002,197.24978,61.02449
237.00002,197.49997,60.96015
237.30002,197.74990,60.99332
237.60000,197.99991,61.22715
237.90002,198.24997,61.28664
238.20002,198.49991,61.30143
238.50002,198.74990,61.20686
238.80002,198.99985,61.38767
239.10000,199.24983,61.24249
239.40002,199.49991,61.46945
239.70002,199.74984,61.48650
240.00002,199.99990,61.45127
240.30002,200.24991,61.53119
240.60000,200.49984,61.35396
240.90002,200.74992,61.76350
241.20002,200.99990,61.60298
241.50002,201.24990,61.61851
241.80002,201.49983,61.79011
242.10000,201.74991,61.80079
242.40002,201.99992,61.77002
242.70002,202.24990,61.93466
243.00002,202.49991,62.16775
243.30002,202.74984,62.03800
243.60000,202.99997,62.08205
243.90002,203.24990,61.96175
244.20002,203.49991,62.21837
244.50002,203.74991,62.08475
244.80002,203.99991,62.21464
245.10000,204.24992,62.33092
245.40002,204.49990,62.43250
245.70002,204.74991,62.44283
246.00002,204.99984,62.35910
246.30002,205.24984,62.34974
246.60000,205.49998,62.55411
246.90002,205.74979,62.52447
247.20002,205.99991,62.45121
247.50002,206.24990,62.43725
247.80002,206.49992,62.70660
248.10000,206.74990,62.74389
248.40002,206.99985,62.80798
248.70002,207.24989,62.73904
249.00002,207.49992,62.89496
249.30002,207.74985,62.96154
249.60000,207.99991,63.01290
249.90002,208.24984,62.76344
250.20002,208.49984,63.03941
250.50002,208.74985,63.08679
250.80002,208.99991,63.34306
251.10000,209.24991,63.14074
251.40002,209.49978,63.39916
251.70002,209.74990,63.31650
252.00002,209.99990,63.40009
252.30002,210.24991,63.34698
252.60000,210.49991,63.53735
252.90002,210.74990,63.55038
253.20002,210.99992,63.65298
253.50002,211.24985,63.43577
253.80002,211.49991,63.70551
254.10000,211.74997,63.59291
254.40002,211.99984,63.84413
254.70002,212.24977,63.75588
255.00002,212.49991,63.89926
255.30002,212.74991,64.00402
255.60000,212.99984,64.04322
255.90002,213.24985,63.88588
256.20002,213.49985,63.98133
256.50000,213.74991,64.10829
256.80002,213.99984,64.15391
257.10000,214.24985,64.18566
257.40003,214.49991,64.19061
257.70002,214.74991,64.18498
258.00000,214.99991,64.56756
258.30002,215.24990,64.77170
258.60000,215.49990,64.65219
258.90003,215.74983,64.65856
259.20002,215.99991,64.77400
259.50000,216.24997,64.94045
259.80002,216.49985,64.86279
260.10000,216.74983,64.84167
260.40003,216.99991,65.09882
260.70002,217.24992,65.16683
261.00000,217.49990,65.35666
261.30002,217.74985,65.03488
261.60000,217.99991,65.21387
261.90003,218.24986,65.22951
262.20000,218.49984,65.42453
262.50000,218.74996,65.27625
262.80003,218.99983,65.50204
263.10000,219.24986,65.49797
263.40003,219.49984,65.60254
263.70000,219.74990,65.59710
264.00000,219.99998,65.63865
264.30003,220.24991,65.89576
264.60000,220.49991,65.72906
264.90003,220.74990,65.83745
265.20000,220.99990,65.93319
265.50000,221.24991,66.15482
265.80003,221.49984,66.08210
266.10000,221.74992,66.10053
266.40003,221.99985,66.34146
266.70000,222.24985,66.23464
267.00000,222.49991,66.21930
267.30003,222.74986,66.39644
267.60000,222.99990,66.66187
267.90003,223.24990,66.52506
268.20000,223.49991,66.70514
268.50000,223.74991,66.69867
268.80003,223.99984,66.91118
269.10000,224.24996,66.75174
269.40003,224.49991,66.96307
269.70000,224.74984,67.07215
270.00000,224.99997,66.99933
270.30003,225.24990,67.03118
270.60000,225.49985,67.19577
270.90003,225.74984,67.12830
271.20000,225.99991,67.00952
271.50000,226.24984,67.20606
271.80003,226.49985,67.08817
272.10000,226.74991,67.32067
272.40003,226.99989,67.28618
272.70000,227.24992,67.48247
273.00000,227.49985,67.45101
273.30003,227.74991,67.52544
273.60000,227.99991,67.63084
273.90003,228.24984,67.71247
274.20000,228.49992,67.82718
274.50000,228.74990,67.68567
274.80003,228.99985,67.92229
275.10000,229.24984,67.97938
275.40003,229.49992,67.95860
275.70000,229.74990,68.03759
276.00000,229.99991,68.20610
276.30003,230.24984,67.79263
276.60000,230.49990,68.10545
276.90003,230.74992,68.07600
277.20000,230.99985,68.16190
277.50000,231.24991,68.47035
277.80003,231.49990,68.37049
278.10000,231.74990,68.35609
278.40003,231.99990,68.26891
278.70000,232.24991,68.59531
279.00000,232.49991,68.70688
279.30003,232.74984,68.47903
279.60000,232.99992,68.43086
279.90003,233.24991,68.67817
280.20000,233.49985,68.62715
280.50000,233.74990,68.67194
280.80003,233.99990,68.85011
281.10000,234.24983,68.80194
281.40003,234.49985,68.81541
281.70000,234.74984,68.66591
282.00000,234.99990,68.69854
282.30003,235.24985,68.89812
282.60000,235.49991,69.19129
282.90003,235.74986,68.96217
283.20000,235.99990,69.10858
283.50000,236.24985,69.24749
283.80003,236.49983,69.13876
284.10000,236.74997,69.20751
284.40003,236.99984,69.24740
284.70000,237.24990,69.19188
285.00000,237.49990,69.18521
285.30003,237.74991,69.30159
285.60000,237.99991,69.15998
285.90003,238.24990,69.01592
286.20000,238.49990,69.04169
286.50000,238.74983,68.85540
286.80003,238.99985,69.09927
287.10000,239.24991,69.09260
287.40003,239.49990,69.29184
287.70000,239.74985,69.23911
288.00000,239.99983,69.19923
288.30003,240.24986,69.30536
288.60000,240.49990,69.14263
288.90003,240.74985,69.13905
289.20000,240.99983,69.05086
289.50000,241.24991,69.29095
289.80003,241.49992,69.28302
290.10000,241.74990,69.43477
290.40003,241.99991,69.45231
290.70000,242.24991,69.54487
291.00000,242.49991,69.49166
291.30003,242.74990,69.73377
291.60000,242.99996,69.81290
291.90003,243.24991,70.10048
292.20000,243.49991,70.18138
292.50000,243.74984,70.20225
292.80003,243.99990,70.24454
293.10000,244.24991,70.45706
293.40003,244.49991,70.38096
293.70000,244.74991,70.39967
294.00000,244.99990,70.49542
294.30003,245.24990,70.51350
294.60000,245.49991,70.59783
294.90003,245.74997,70.45132
295.20000,245.99977,70.59484
295.50000,246.24985,70.75630
295.80003,246.49991,70.69990
296.10000,246.74989,70.93265
296.40003,246.99984,70.86875
296.70000,247.24985,70.99512
297.00000,247.49996,71.30235
297.30003,247.74984,71.25933
297.60000,247.99984,71.19695
297.90003,248.24992,71.30284
298.20000,248.49990,71.26408
298.50000,248.74991,71.24820
298.80003,248.99984,71.12943
299.10000,249.24992,71.41201
299.40003,249.49985,71.17328
299.70000,249.74985,71.49281
300.00000,249.99997,71.50501
300.30003,250.24990,71.64231
300.60000,250.49990,71.26378
300.90003,250.74989,71.30789
301.20000,250.99991,71.36223
301.50000,251.24988,71.29554
301.80003,251.49990,71.18108
302.10000,251.74990,71.32592
302.40003,251.99994,71.33263
302.70000,252.24984,71.12600
303.00000,252.49988,71.13046
303.30003,252.74990,71.06627
303.60000,252.99991,70.99747
303.90003,253.24984,71.24002
304.20000,253.49990,71.24164
304.50000,253.74992,71.09381
304.80003,253.99989,70.89438
305.10000,254.24991,70.97587
305.40003,254.49976,70.94460
305.70000,254.74990,70.39370
306.00000,254.99998,69.50969
306.30003,255.24989,67.38853
306.60000,255.49991,62.67406
306.90003,255.74982,0.73483
307.20000,255.99984,0.49203
307.50000,256.24996,0.55044
307.80003,256.49983,0.68269
308.10000,256.74984,0.72287
308.40003,256.99988,0.62816
308.70000,257.24990,0.57627
309.00000,257.49991,0.80117
309.30003,257.74984,0.62169
309.60000,257.99984,0.60018
309.90003,258.24998,0.66829
310.20000,258.49989,0.65903
310.50000,258.74991,0.60498
310.80003,258.99990,0.67466
311.10000,259.24990,0.70670
311.40003,259.49989,0.59204
311.70000,259.74989,0.81186
312.00000,259.99997,0.59131
312.30003,260.24988,0.70587
312.60000,260.49990,0.63526
312.90003,260.74991,0.62051
313.20000,260.99989,0.67186
313.45400,261.21158,0.66020