File: V_8/EPR/RDSO EPR Tensile 50.is_tens_RawData/Specimen_RawData_2.csv
Time,Extension,Load
(sec),(mm),(N)
0.00000,0.00000,1.82243
0.30000,0.24925,2.47305
0.60000,0.49994,2.79949
0.90000,0.74994,3.14724
1.20000,0.99994,3.31447
1.50000,1.24987,3.72166
1.80000,1.49987,4.11302
2.10000,1.75000,4.32916
2.40000,1.99994,4.57740
2.70000,2.24987,4.70244
3.00000,2.49994,4.89864
3.30000,2.74994,5.09096
3.60000,2.99994,5.31254
3.90000,3.24987,5.67583
4.20000,3.49994,5.71625
4.50000,3.74994,6.11428
4.80000,3.99994,6.05215
5.10000,4.24987,6.25231
5.40000,4.49994,6.46850
5.70000,4.75000,6.51318
6.00000,4.99987,6.72780
6.30000,5.24994,6.82482
6.60000,5.50000,7.16096
6.90000,5.74994,7.00568
7.20000,5.99994,7.29360
7.50000,6.24994,7.68619
7.80000,6.49994,7.54179
8.10000,6.74994,7.54806
8.40000,6.99987,7.66894
8.70000,7.24994,7.71476
9.00000,7.49994,8.00582
9.30000,7.74987,8.08245
9.60000,7.99987,8.16962
9.90000,8.25000,8.46103
10.20000,8.49981,8.37773
10.50000,8.74994,8.38919
10.80000,8.99987,8.70941
11.10000,9.24994,8.78291
11.40000,9.49994,8.84097
11.70000,9.74987,8.94407
12.00000,10.00000,8.96014
12.30000,10.24994,9.03334
12.60000,10.49994,8.99071
12.90000,10.74994,9.03080
13.20000,10.99994,9.38609
13.50000,11.24987,9.60316
13.80000,11.49987,9.41192
14.10000,11.74994,9.71630
14.40000,11.99987,9.74796
14.70000,12.24987,9.68088
15.00000,12.50000,9.92152
15.30000,12.74994,9.99448
15.60000,12.99994,10.09909
15.90000,13.24987,9.91039
16.20000,13.49994,10.19660
16.50000,13.74987,10.28436
16.80000,13.99987,10.36923
17.10000,14.25000,10.58277
17.40000,14.50000,10.60438
17.70000,14.74994,10.66406
18.00000,14.99994,10.68141
18.30000,15.24994,10.85477
18.60000,15.50000,10.98618
18.90000,15.74987,11.14181
19.20000,15.99994,10.91072
19.50000,16.25000,11.26646
19.80000,16.49987,11.50578
20.10000,16.74994,11.24897
20.40000,16.99987,11.52435
20.70000,17.24993,11.59599
21.00000,17.49994,11.80453
21.30000,17.74987,11.77023
21.60000,17.99993,11.81350
21.90000,18.24987,11.98353
22.20000,18.49987,12.26680
22.50000,18.74994,12.10402
22.80000,18.99993,12.26469
23.10000,19.24993,12.31927
23.40000,19.49994,12.42369
23.70000,19.74993,12.65061
24.00000,19.99993,12.87155
24.30000,20.24994,12.87033
24.60000,20.49993,13.06294
24.90000,20.74993,13.02600
25.20000,20.99993,13.18897
25.50000,21.24987,13.37066
25.80000,21.49994,13.43637
26.10000,21.74993,13.44505
26.40000,21.99987,13.71503
26.70000,22.24993,13.95195
27.00000,22.49993,13.94529
27.30000,22.74993,13.86076
27.60000,22.99994,13.87272
27.90000,23.24993,14.29813
28.20000,23.49993,14.18122
28.50000,23.74987,14.34076
28.80000,23.99993,14.48507
29.10000,24.25000,14.70174
29.40000,24.49993,14.69435
29.70000,24.74987,14.62207
30.00000,24.99999,14.76745
30.30000,25.24993,14.87961
30.60000,25.49981,14.84982
30.90000,25.74987,14.93376
31.20000,25.99993,15.02039
31.50000,26.24993,15.03558
31.80000,26.49987,15.09575
32.10000,26.74993,15.14417
32.40000,26.99994,15.20870
32.70000,27.24993,15.16078
33.00000,27.49993,15.23070
33.30000,27.74993,15.40220
33.60000,28.00000,15.47413
33.90000,28.24987,15.62118
34.20000,28.49987,15.72912
34.50000,28.74993,15.72011
34.80000,28.99987,15.85981
35.10000,29.24993,15.86726
35.40000,29.49993,15.94512
35.70000,29.74994,16.00470
36.00000,29.99993,15.92850
36.30000,30.24987,16.07894
36.60000,30.49993,16.10711
36.90000,30.74987,15.97608
37.20000,30.99993,16.06928
37.50000,31.24993,16.36965
37.80000,31.49993,16.36299
38.10000,31.74993,16.49705
38.40000,31.99993,16.46182
38.70000,32.24999,16.61916
39.00000,32.49993,16.54909
39.30000,32.74993,16.39988
39.60000,32.99993,16.67061
39.90000,33.24993,16.74867
40.20000,33.49993,16.86220
40.50000,33.74993,16.71858
40.80000,33.99981,16.87641
41.10000,34.24987,16.89459
41.40000,34.49987,16.86234
41.70000,34.74993,17.02733
42.00000,34.99993,16.87557
42.30000,35.24987,17.15801
42.60000,35.49987,17.09416
42.90000,35.75000,17.12729
43.20000,35.99993,17.26434
43.50000,36.24993,17.35112
43.80000,36.49993,17.33759
44.10000,36.74993,17.61645
44.40000,36.99993,17.55339
44.70000,37.24987,17.42006
45.00000,37.49993,17.87297
45.30000,37.74993,17.62748
45.60000,37.99993,17.93147
45.90000,38.24993,17.76081
46.20000,38.49993,17.92128
46.50000,38.74987,17.97797
46.80000,38.99987,18.05074
47.10000,39.24993,18.10591
47.40000,39.49993,17.97935
47.70000,39.74987,18.16652
48.00000,39.99987,18.32553
48.30000,40.24993,18.42789
48.60000,40.49993,18.31186
48.90000,40.74987,18.52187
49.20000,40.99987,18.39085
49.50000,41.24993,18.44871
49.80000,41.49993,18.57322
50.10000,41.74993,18.67798
50.40000,41.99993,18.78770
50.70000,42.24993,18.83807
51.00000,42.49987,18.78853
51.30000,42.74987,18.87104
51.60000,42.99993,18.90882
51.90000,43.24993,19.05112
52.20000,43.49987,19.26045
52.50000,43.74993,19.34296
52.80000,43.99993,19.14074
53.10000,44.24993,19.26716
53.40000,44.49987,19.29857
53.70000,44.74993,19.40509
54.00000,44.99999,19.47516
54.30000,45.24987,19.47105
54.60000,45.49993,19.72041
54.90000,45.74993,19.58149
55.20000,45.99987,19.73942
55.50000,46.24993,19.86496
55.80000,46.49993,19.91822
56.10000,46.74993,20.12701
56.40000,46.99986,20.02783
56.70000,47.24993,20.05370
57.00000,47.49993,20.26553
57.30000,47.74987,20.05331
57.60000,47.99987,20.51577
57.90000,48.24993,20.53542
58.20000,48.49993,20.46996
58.50000,48.74987,20.43311
58.80000,48.99987,20.46427
59.10000,49.24993,20.62029
59.40000,49.49987,20.49113
59.70000,49.74993,20.68884
60.00000,49.99993,20.76763
60.30000,50.24993,20.89861
60.60000,50.49993,20.95040
60.90000,50.74987,21.08603
61.20000,50.99993,20.98475
61.50000,51.24993,21.42942
61.80000,51.49987,21.35186
62.10000,51.74993,21.45706
62.40000,51.99993,21.33662
62.70000,52.24986,21.31271
63.00000,52.49986,21.53732
63.30000,52.74993,21.59926
63.60000,52.99993,21.55276
63.90000,53.24987,21.63243
64.20000,53.49987,21.80981
64.50000,53.74993,21.60509
64.80000,53.99987,21.93804
65.10001,54.24987,22.08573
65.40000,54.49993,21.97621
65.70001,54.74993,22.27957
66.00000,54.99993,22.27849
66.30000,55.24993,22.49125
66.60001,55.49993,22.52364
66.90000,55.74993,22.51717
67.20001,55.99987,22.42309
67.50000,56.24993,22.55667
67.80000,56.49993,22.79333
68.10001,56.74993,22.51389
68.40000,56.99987,22.72616
68.70001,57.24987,22.59636
69.00000,57.49993,23.08062
69.30000,57.74986,23.00492
69.60001,57.99993,23.10066
69.90000,58.24993,23.28916
70.20001,58.49987,23.37021
70.50000,58.74993,23.34929
70.80000,58.99993,23.49883
71.10001,59.24999,23.42631
71.40000,59.49981,23.52456
71.70001,59.74993,23.67695
72.00000,59.99999,23.69474
72.30000,60.24993,23.71781
72.60001,60.49987,23.76525
72.90000,60.74993,23.73908
73.20001,60.99987,23.94155
73.50000,61.24993,24.07615
73.80000,61.49987,24.28210
74.10001,61.74993,24.06145
74.40000,61.99993,24.34972
74.70001,62.24987,24.22668
75.00000,62.49993,24.37044
75.30000,62.74993,24.44061
75.60001,62.99987,24.61373
75.90000,63.24986,24.74451
76.20001,63.49993,24.72750
76.50000,63.74992,24.73133
76.80000,63.99986,24.81433
77.10001,64.24987,25.10206
77.40000,64.49993,24.95991
77.70001,64.74993,25.03037
78.00000,64.99992,25.20589
78.30000,65.24993,25.16963
78.60001,65.49993,25.23083
78.90000,65.74986,25.51807
79.20001,65.99993,25.57609
79.50000,66.24993,25.72088
79.80000,66.49987,25.52586
80.10001,66.74992,25.67933
80.40000,66.99993,26.07030
80.70001,67.24992,25.80702
81.00001,67.49993,26.03340
81.30000,67.74993,26.04506
81.60001,67.99986,26.24787
81.90000,68.24993,26.11988
82.20001,68.49993,26.30917
82.50001,68.74999,26.38194
82.80000,68.99986,26.59964
83.10001,69.24986,26.49669
83.40000,69.49992,26.47773
83.70001,69.74999,26.57235
84.00001,69.99987,26.80902
84.30000,70.24986,26.88634
84.60001,70.49993,26.75830
84.90000,70.74993,27.09875
85.20001,70.99986,27.11586
85.50001,71.24993,27.24282
85.80000,71.49993,27.39648
86.10001,71.74992,27.40104
86.40000,71.99986,27.50060
86.70001,72.24993,27.51912
87.00001,72.49992,27.67823
87.30000,72.74986,27.80538
87.60001,72.99987,27.80857
87.90000,73.24993,27.92788
88.20001,73.49993,27.70229
88.50001,73.74987,27.87413
88.80000,73.99987,28.06714
89.10001,74.24993,28.03009
89.40000,74.49986,28.21404
89.70001,74.74986,28.28132
90.00001,74.99993,28.18587
90.30000,75.24987,28.22683
90.60001,75.49986,28.68556
90.90000,75.74987,28.59296
91.20001,75.99999,28.74309
91.50001,76.24993,28.74941
91.80000,76.49980,28.70272
92.10001,76.74999,29.02670
92.40000,76.99999,28.88598
92.70001,77.24993,29.08766
93.00001,77.49987,29.01720
93.30000,77.74986,28.96923
93.60001,77.99999,29.26862
93.90000,78.24986,29.40684
94.20001,78.49980,29.45232
94.50001,78.74993,29.50019
94.80000,78.99993,29.55360
95.10001,79.24986,29.63803
95.40000,79.49986,29.76552
95.70001,79.74993,29.75371
96.00001,79.99986,29.92845
96.30000,80.24986,30.06545
96.60001,80.49992,30.17555
96.90000,80.74992,30.26723
97.20001,80.99986,30.16894
97.50001,81.24992,30.24312
97.80000,81.49993,30.51331
98.10001,81.74992,30.59872
98.40000,81.99986,30.67854
98.70001,82.24992,30.56172
99.00001,82.49986,30.90443
99.30000,82.74986,30.87223
99.60001,82.99986,30.83166
99.90000,83.24986,30.96460
100.20001,83.49986,31.08043
100.50001,83.74986,31.07558
100.80000,83.99987,31.25419
101.10001,84.24993,31.37007
101.40000,84.49992,31.40560
101.70001,84.74993,31.43152
102.00001,84.99986,31.75345
102.30000,85.24993,31.60498
102.60001,85.49985,31.72630
102.90000,85.74992,31.87653
103.20001,85.99993,31.90878
103.50001,86.24992,32.01496
103.80000,86.49986,32.08620
104.10001,86.74999,32.10012
104.40000,86.99981,32.19273
104.70001,87.24992,32.09944
105.00001,87.49993,32.32861
105.30000,87.74993,32.21483
105.60001,87.99979,32.46022
105.90000,88.24986,32.58904
106.20001,88.49992,32.92650
106.50001,88.74992,32.97266
106.80000,88.99986,32.85119
107.10001,89.24992,32.86770
107.40000,89.49992,33.03264
107.70001,89.74986,33.22844
108.00001,89.99993,33.23275
108.30000,90.24993,33.35241
108.60001,90.49992,33.14401
108.90000,90.74987,33.63107
109.20001,90.99992,33.54424
109.50001,91.24992,33.69222
109.80000,91.49986,33.91556
110.10001,91.74992,33.74299
110.40000,91.99993,33.93757
110.70001,92.24986,33.96212
111.00001,92.49986,34.12763
111.30000,92.74987,34.11970
111.60001,92.99998,34.13969
111.90000,93.24992,34.45035
112.20001,93.49986,34.22216
112.50001,93.74992,34.38753
112.80000,93.99986,34.63968
113.10001,94.24992,34.64753
113.40001,94.49986,34.84298
113.70001,94.74993,34.90825
114.00001,94.99992,34.89375
114.30000,95.24986,34.90693
114.60001,95.49987,35.14575
114.90001,95.74998,35.12616
115.20001,95.99992,35.09244
115.50001,96.24986,35.18873
115.80000,96.49999,35.32823
116.10001,96.74992,35.38027
116.40001,96.99985,35.42726
116.70001,97.24992,35.81235
117.00001,97.49993,35.80294
117.30000,97.74992,35.83415
117.60001,97.99986,35.95322
117.90001,98.24992,35.92907
118.20001,98.49992,36.06847
118.50001,98.74986,35.97866
118.80000,98.99992,36.32092
119.10001,99.24999,36.39133
119.40001,99.49992,36.33248
119.70001,99.74992,36.41911
120.00001,99.99992,36.69253
120.30000,100.24992,36.52828
120.60001,100.49986,36.65103
120.90001,100.74986,36.62428
121.20001,100.99986,36.92572
121.50001,101.24993,36.86555
121.80000,101.49992,37.04180
122.10001,101.74992,37.10173
122.40001,101.99992,37.29827
122.70001,102.24986,37.37059
123.00001,102.49992,37.46825
123.30000,102.74986,37.60270
123.60001,102.99992,37.54724
123.90001,103.24986,37.75019
124.20001,103.49993,37.78832
124.50001,103.74999,37.72682
124.80000,103.99986,37.72021
125.10001,104.24992,38.05056
125.40001,104.49992,38.26014
125.70001,104.74992,38.14479
126.00001,104.99992,38.22642
126.30000,105.24986,38.40356
126.60001,105.49992,38.26612
126.90001,105.74993,38.50293
127.20001,105.99992,38.61945
127.50001,106.24993,38.61901
127.80000,106.49992,38.58407
128.10001,106.74986,38.70540
128.40001,106.99986,38.88797
128.70002,107.24992,38.69922
129.00000,107.49992,39.03384
129.30000,107.74986,39.22754
129.60001,107.99985,39.06501
129.90001,108.24992,39.10475
130.20002,108.49993,39.20103
130.50000,108.74987,39.32877
130.80000,108.99992,39.43579
131.10000,109.24992,39.42246
131.40002,109.49992,39.41604
131.70002,109.74992,39.78286
132.00000,109.99999,39.83921
132.30000,110.24985,39.91476
132.60000,110.49992,40.09979
132.90002,110.74992,39.92103
133.20002,110.99998,40.07597
133.50000,111.24986,40.23782
133.80000,111.49986,40.43200
134.10000,111.74999,40.34924
134.40002,111.99986,40.29378
134.70002,112.24986,40.45602
135.00000,112.49992,40.66333
135.30000,112.74992,40.75487
135.60000,112.99992,40.88383
135.90002,113.24986,40.88310
136.20002,113.49992,41.06082
136.50000,113.74992,40.91877
136.80000,113.99986,40.98756
137.10000,114.24992,41.27573
137.40002,114.49993,41.29308
137.70002,114.74992,41.43773
138.00000,114.99986,41.60452
138.30000,115.24992,41.58732
138.60000,115.49992,41.53092
138.90002,115.74986,41.60207
139.20002,115.99992,41.72741
139.50000,116.24992,41.84452
139.80000,116.49992,42.00230
140.10000,116.74993,41.95355
140.40002,116.99992,42.14857
140.70002,117.24993,42.35496
141.00000,117.49987,42.31948
141.30000,117.74986,42.27827
141.60000,117.99992,42.38470
141.90002,118.24986,42.46653
142.20002,118.49992,42.63347
142.50000,118.74992,42.53449
142.80000,118.99993,42.58374
143.10000,119.24986,43.02101
143.40002,119.49993,42.65381
143.70002,119.74992,42.90924
144.00000,119.99992,42.97363
144.30000,120.24986,43.18790
144.60000,120.49992,43.32187
144.90002,120.74992,43.36269
145.20002,120.99986,43.30452
145.50000,121.24993,43.37131
145.80000,121.49992,43.40830
146.10000,121.74992,43.57941
146.40002,121.99986,43.57799
146.70002,122.24986,43.69515
147.00000,122.49992,44.04677
147.30000,122.74992,43.88424
147.60000,122.99986,44.10278
147.90002,123.24986,43.90389
148.20002,123.49992,44.06613
148.50000,123.74986,44.36865
148.80000,123.99986,44.23145
149.10000,124.24992,44.46557
149.40002,124.49986,44.52585
149.70002,124.74992,44.61444
150.00000,124.99992,44.48934
150.30000,125.24992,44.90476
150.60000,125.49998,44.85797
150.90002,125.74992,44.75085
151.20002,125.99997,45.10056
151.50000,126.24991,45.12879
151.80000,126.49992,45.25540
152.10000,126.74998,45.09312
152.40002,126.99991,45.28588
152.70002,127.24985,45.48340
153.00000,127.49985,45.43710
153.30000,127.74984,45.38486
153.60000,127.99992,45.65206
153.90002,128.24985,45.77514
154.20002,128.49986,45.84159
154.50000,128.74993,45.84497
154.80000,128.99986,46.08252
155.10000,129.24986,45.99584
155.40002,129.49985,46.04455
155.70002,129.74991,46.31204
156.00000,129.99984,46.36001
156.30000,130.24986,46.31743
156.60000,130.49997,46.41763
156.90002,130.74991,46.41616
157.20002,130.99985,46.41244
157.50000,131.24992,46.62436
157.80000,131.49998,46.85324
158.10000,131.74991,46.71148
158.40002,131.99992,46.82913
158.70002,132.24992,47.03464
159.00000,132.49986,47.16596
159.30000,132.74992,46.99857
159.60000,132.99991,46.94041
159.90002,133.24991,47.43668
160.20002,133.49985,47.30061
160.50000,133.74992,47.27552
160.80000,133.99998,47.26631
161.10000,134.24992,47.83000
161.40002,134.49991,47.57099
161.70002,134.74992,47.62303
162.00002,134.99992,47.81427
162.30000,135.24991,47.88449
162.60000,135.49991,47.90972
162.90002,135.74985,47.91394
163.20002,135.99992,48.12219
163.50002,136.24991,48.14125
163.80000,136.49992,48.34578
164.10000,136.74991,48.37101
164.40002,136.99993,48.46533
164.70002,137.24986,48.33730
165.00002,137.49997,48.50419
165.30000,137.74985,48.72312
165.60000,137.99985,48.55001
165.90002,138.24992,48.69117
166.20002,138.49986,49.03799
166.50002,138.74997,49.00938
166.80000,138.99985,49.06999
167.10000,139.24993,49.20989
167.40002,139.49992,49.26095
167.70002,139.74986,49.11120
168.00002,139.99991,49.49712
168.30000,140.24991,49.28113
168.60000,140.49992,49.39687
168.90002,140.74986,49.52436
169.20002,140.99992,49.73522
169.50002,141.24999,49.65054
169.80000,141.49993,49.78333
170.10000,141.74992,49.88270
170.40002,141.99992,49.98840
170.70002,142.24991,49.96017
171.00002,142.49991,50.12025
171.30000,142.74985,50.06694
171.60000,142.99992,50.03372
171.90002,143.24985,50.22163
172.20002,143.49991,50.43978
172.50002,143.74998,50.49143
172.80000,143.99998,50.62196
173.10000,144.24986,50.64994
173.40002,144.49986,50.75122
173.70002,144.74998,50.72197
174.00002,144.99999,50.78239
174.30000,145.24986,50.97633
174.60000,145.49986,50.88171
174.90002,145.74992,51.04890
175.20002,145.99998,51.21775
175.50002,146.24985,51.33349
175.80000,146.49986,51.40043
176.10000,146.74991,51.43242
176.40002,146.99985,51.47368
176.70002,147.24985,51.65831
177.00002,147.49992,51.51131
177.30000,147.74986,51.88684
177.60000,147.99992,51.86656
177.90002,148.24999,51.89508
178.20002,148.49992,51.93364
178.50002,148.74992,52.03884
178.80000,148.99991,51.88028
179.10000,149.24991,52.00420
179.40002,149.49991,52.20245
179.70002,149.74984,52.06619
180.00002,149.99992,52.33558
180.30000,150.24992,52.53850
180.60000,150.49986,52.33627
180.90002,150.74993,52.50326
181.20002,150.99992,52.65854
181.50002,151.24992,52.91482
181.80000,151.49985,52.71137
182.10000,151.74999,52.71832
182.40002,151.99992,53.01600
182.70002,152.24986,53.05294
183.00002,152.49992,52.99458
183.30000,152.74986,53.14217
183.60000,152.99991,53.23307
183.90002,153.24985,53.27261
184.20002,153.49992,53.39271
184.50002,153.74998,53.51604
184.80000,153.99992,53.41476
185.10000,154.24985,53.61424
185.40002,154.49998,53.93176
185.70002,154.74985,53.62977
186.00002,154.99991,53.87227
186.30000,155.24991,53.77309
186.60000,155.49992,53.96802
186.90002,155.74992,53.79946
187.20002,155.99986,53.98276
187.50002,156.24992,54.23982
187.80000,156.49991,54.34713
188.10000,156.74992,54.49109
188.40002,156.99985,54.34041
188.70002,157.24991,54.52730
189.00002,157.49991,54.57170
189.30000,157.74984,54.74329
189.60000,157.99992,54.68386
189.90002,158.24990,54.78185
190.20002,158.49991,54.79219
190.50002,158.74991,54.99094
190.80000,158.99984,55.10589
191.10000,159.24992,55.01034
191.40002,159.49979,55.25583
191.70002,159.74991,55.19762
192.00002,159.99991,55.36480
192.30000,160.24992,55.37975
192.60000,160.49985,55.51739
192.90002,160.74991,55.49818
193.20002,160.99991,55.77778
193.50002,161.24984,55.61578
193.80000,161.49985,55.79508
194.10000,161.74996,55.89739
194.40002,161.99991,55.88440
194.70002,162.24984,55.95075
195.00002,162.49992,56.04086
195.30000,162.74985,56.07466
195.60000,162.99985,56.01253
195.90002,163.24984,56.13004
196.20002,163.49992,56.20358
196.50002,163.74992,56.29776
196.80000,163.99985,56.26307
197.10000,164.24986,56.31785
197.40002,164.49990,56.50136
197.70002,164.74985,56.46167
198.00002,164.99985,56.62504
198.30000,165.24991,56.48592
198.60000,165.49991,56.77017
198.90002,165.74990,56.81197
199.20002,165.99992,56.91232
199.50002,166.24991,56.90972
199.80000,166.49991,57.06981
200.10000,166.74984,56.92766
200.40002,166.99998,57.38477
200.70002,167.24991,57.16344
201.00002,167.49986,57.39403
201.30000,167.74984,57.45862
201.60000,167.99990,57.50458
201.90002,168.24992,57.58019
202.20002,168.49985,57.60082
202.50002,168.74991,57.71969
202.80000,168.99984,57.86728
203.10000,169.24992,57.69705
203.40002,169.49978,58.12835
203.70002,169.74986,58.13962
204.00002,169.99992,58.07009
204.30000,170.24990,58.37698
204.60000,170.49998,58.40211
204.90002,170.74997,58.33160
205.20002,170.99986,58.54543
205.50002,171.24990,58.53549
205.80000,171.49990,58.54720
206.10000,171.74991,58.56626
206.40002,171.99986,58.71909
206.70002,172.24984,58.85717
207.00002,172.49990,58.93043
207.30000,172.74985,58.94233
207.60000,172.99986,58.76270
207.90002,173.24986,59.12643
208.20002,173.49990,58.85648
208.50002,173.74985,59.18057
208.80000,173.99991,59.21899
209.10000,174.24991,59.00785
209.40002,174.49984,59.22143
209.70002,174.74985,59.29905
210.00002,174.99998,59.48358
210.30000,175.24991,59.48991
210.60000,175.49992,59.58751
210.90002,175.74985,59.56189
211.20002,175.99998,59.66322
211.50002,176.24991,59.54910
211.80000,176.49986,59.61378
212.10000,176.74992,59.77773
212.40002,176.99990,59.95531
212.70002,177.24985,59.79400
213.00002,177.49984,59.82796
213.30000,177.74992,60.22544
213.60000,177.99990,60.19589
213.90002,178.24979,60.11818
214.20002,178.49991,60.26499
214.50002,178.74992,60.33540
214.80000,178.99992,60.48122
215.10000,179.24985,60.48896
215.40002,179.49985,60.65483
215.70002,179.74991,60.81006
216.00002,179.99992,60.63518
216.30000,180.24985,60.65993
216.60000,180.49991,60.79786
216.90002,180.74991,60.91502
217.20002,180.99984,60.88184
217.50002,181.24992,61.14483
217.80000,181.49991,61.00327
218.10000,181.74985,61.26640
218.40002,181.99991,61.30378
218.70002,182.24992,61.24557
219.00002,182.49985,61.25082
219.30000,182.74985,61.24234
219.60000,182.99984,61.38312
219.90002,183.24992,61.51644
220.20002,183.49985,61.70779
220.50002,183.74991,61.47214
220.80000,183.99991,61.76580
221.10000,184.24984,61.69299
221.40002,184.49984,61.87595
221.70002,184.74991,61.86233
222.00002,184.99991,61.98067
222.30000,185.24984,61.95396
222.60000,185.49984,61.98312
222.90002,185.74992,62.15221
223.20002,185.99985,62.18931
223.50002,186.24991,62.20283
223.80000,186.49984,62.24252
224.10000,186.74992,62.53324
224.40002,186.99985,62.33302
224.70002,187.24985,62.53231
225.00002,187.49991,62.70126
225.30002,187.74990,62.73394
225.60000,187.99985,62.86619
225.90002,188.24991,62.81087
226.20002,188.49997,62.87546
226.50002,188.74984,62.83650
226.80002,188.99985,63.09155
227.10000,189.24991,63.01432
227.40002,189.49991,63.02574
227.70002,189.74984,63.17479
228.00002,189.99984,63.39314
228.30002,190.24990,63.22472
228.60000,190.49997,63.20395
228.90002,190.74984,63.23844
229.20002,190.99990,63.41308
229.50002,191.24992,63.70159
229.80002,191.49985,63.46644
230.10000,191.74986,63.69478
230.40002,191.99990,63.73981
230.70002,192.24990,63.77955
231.00002,192.49983,63.91557
231.30002,192.74991,64.04317
231.60000,192.99991,64.15700
231.90002,193.24990,63.86800
232.20002,193.49985,64.03415
232.50002,193.74991,64.05523
232.80002,193.99991,64.26318
233.10000,194.24984,64.21590
233.40002,194.49985,64.14798
233.70002,194.74998,64.11736
234.00002,194.99991,64.29576
234.30002,195.24978,64.38220
234.60000,195.49990,64.33815
234.90002,195.74985,64.61681
235.20002,195.99983,64.44369
235.50002,196.24986,64.73583
235.80002,196.49984,64.69678
236.10000,196.74990,64.76979
236.40002,196.99983,64.74304
236.70002,197.24978,64.86029
237.00002,197.49997,64.90846
237.30002,197.74990,64.94080
237.60000,197.99991,64.84191
237.90002,198.24991,65.13508
238.20002,198.49991,65.41957
238.50002,198.74990,65.20157
238.80002,198.99985,65.20270
239.10000,199.24983,65.24827
239.40002,199.49991,65.43511
239.70002,199.74984,65.39042
240.00002,199.99990,65.46735
240.30002,200.24991,65.62670
240.60000,200.49984,65.40855
240.90002,200.74986,65.88802
241.20002,200.99990,65.79957
241.50002,201.24990,65.83568
241.80002,201.49983,66.06887
242.10000,201.74984,65.98983
242.40002,201.99992,66.17569
242.70002,202.24990,66.17834
243.00002,202.49985,66.22557
243.30002,202.74984,66.10038
243.60000,202.99992,66.25443
243.90002,203.24990,66.40261
244.20002,203.49991,66.60209
244.50002,203.74991,66.52477
244.80002,203.99984,66.51100
245.10000,204.24992,66.45725
245.40002,204.49990,66.68161
245.70002,204.74991,66.72258
246.00002,204.99984,66.67916
246.30002,205.24984,66.61179
246.60000,205.49998,66.67593
246.90002,205.74979,66.83983
247.20002,205.99991,66.95651
247.50002,206.24990,66.85581
247.80002,206.49992,66.82156
248.10000,206.74990,67.11134
248.40002,206.99985,67.26359
248.70002,207.24989,67.23923
249.00002,207.49992,67.35590
249.30002,207.74985,67.19827
249.60000,207.99991,67.21704
249.90002,208.24984,67.53039
250.20002,208.49984,67.61276
250.50002,208.74985,67.27240
250.80002,208.99991,67.57292
251.10000,209.24985,67.55293
251.40002,209.49984,67.73648
251.70002,209.74990,67.63035
252.00002,209.99990,67.98844
252.30002,210.24991,68.02803
252.60000,210.49984,67.79754
252.90002,210.74990,67.87383
253.20002,210.99992,68.02059
253.50002,211.24978,68.31640
253.80002,211.49991,68.35280
254.10000,211.74997,68.08247
254.40002,211.99984,68.29528
254.70002,212.24983,68.32732
255.00002,212.49991,68.34349
255.30002,212.74991,68.44684
255.60000,212.99984,68.55870
255.90002,213.24985,68.64474
256.20002,213.49985,68.70354
256.50000,213.74991,68.65758
256.80002,213.99984,68.51808
257.10000,214.24985,68.88651
257.40003,214.49991,69.03684
257.70002,214.74991,68.96991
258.00000,214.99991,69.11226
258.30002,215.24996,69.13876
258.60000,215.49990,69.24176
258.90003,215.74991,68.99730
259.20002,215.99986,69.06620
259.50000,216.24990,69.20932
259.80002,216.49990,69.39200
260.10000,216.74983,69.51498
260.40003,216.99991,69.35294
260.70002,217.24992,69.45172
261.00000,217.49984,69.45912
261.30002,217.74985,69.40414
261.60000,217.99991,69.66732
261.90003,218.24986,69.63062
262.20000,218.49984,69.89135
262.50000,218.74990,69.83745
262.80003,218.99983,69.70260
263.10000,219.24986,69.92898
263.40003,219.49984,69.78321
263.70000,219.74990,70.17471
264.00000,219.99998,70.00082
264.30003,220.24991,70.28227
264.60000,220.49997,69.96563
264.90003,220.74990,70.31657
265.20000,220.99990,70.25826
265.50000,221.24983,70.30756
265.80003,221.49984,70.18711
266.10000,221.74992,70.56603
266.40003,221.99985,70.62390
266.70000,222.24985,70.68274
267.00000,222.49991,70.51149
267.30003,222.74986,70.58278
267.60000,222.99990,70.73939
267.90003,223.24990,70.76673
268.20000,223.49991,70.74983
268.50000,223.74991,70.79354
268.80003,223.99984,70.99027
269.10000,224.24996,71.07842
269.40003,224.49991,70.97822
269.70000,224.74984,71.29691
270.00000,224.99992,71.22473
270.30003,225.24990,71.34370
270.60000,225.49991,71.32411
270.90003,225.74984,71.27006
271.20000,225.99991,71.35978
271.50000,226.24992,71.52589
271.80003,226.49990,71.39947
272.10000,226.74991,71.43641
272.40003,226.99989,71.50099
272.70000,227.24984,71.53088
273.00000,227.49985,71.55132
273.30003,227.74991,71.50531
273.60000,227.99991,71.78999
273.90003,228.24984,71.79015
274.20000,228.49992,71.75437
274.50000,228.74990,71.99378
274.80003,228.99991,71.93749
275.10000,229.24984,72.00574
275.40003,229.49992,72.04445
275.70000,229.74990,72.11153
276.00000,229.99991,72.30685
276.30003,230.24984,72.25133
276.60000,230.49990,72.44081
276.90003,230.74992,72.51946
277.20000,230.99985,72.47761
277.50000,231.24991,72.64112
277.80003,231.49984,72.62779
278.10000,231.74990,72.78406
278.40003,231.99985,72.76779
278.70000,232.24996,72.82536
279.00000,232.49991,73.07663
279.30003,232.74984,72.93635
279.60000,232.99992,72.86089
279.90003,233.24991,72.87471
280.20000,233.49985,72.81835
280.50000,233.74990,72.90528
280.80003,233.99984,72.97011
281.10000,234.24990,73.00441
281.40003,234.49985,72.99132
281.70000,234.74991,73.06429
282.00000,234.99990,73.12926
282.30003,235.24985,73.26886
282.60000,235.49991,73.18938
282.90003,235.74991,73.25896
283.20000,235.99990,73.58153
283.50000,236.24985,73.47020
283.80003,236.49983,73.45335
284.10000,236.74991,73.73941
284.40003,236.99984,73.66581
284.70000,237.24990,73.64062
285.00000,237.49990,73.93663
285.30003,237.74991,73.99068
285.60000,237.99991,74.07873
285.90003,238.24984,74.14120
286.20000,238.49990,74.21515
286.50000,238.74991,74.31589
286.80003,238.99985,74.20373
287.10000,239.24991,74.29462
287.40003,239.49990,74.33451
287.70000,239.74985,74.24068
288.00000,239.99991,74.43589
288.30003,240.24991,74.44099
288.60000,240.49990,74.36528
288.90003,240.74985,74.37695
289.20000,240.99983,74.65188
289.50000,241.24991,74.59377
289.80003,241.49984,74.60024
290.10000,241.74990,74.61694
290.40003,241.99998,74.75679
290.70000,242.24991,74.89791
291.00000,242.49991,74.95455
291.30003,242.74990,75.13223
291.60000,242.99990,75.18603
291.90003,243.24991,75.11228
292.20000,243.49991,75.18804
292.50000,243.74992,75.23395
292.80003,243.99990,75.21920
293.10000,244.24991,75.44014
293.40003,244.49991,75.52428
293.70000,244.74991,75.44842
294.00000,244.99990,75.75727
294.30003,245.24990,75.65452
294.60000,245.49991,75.90299
294.90003,245.74991,76.11193
295.20000,245.99984,76.17524
295.50000,246.24985,76.14603
295.80003,246.49991,76.36545
296.10000,246.74989,76.40063
296.40003,246.99984,76.33390
296.70000,247.24985,76.45807
297.00000,247.49996,76.62873
297.30003,247.74984,76.61384
297.60000,247.99984,76.60041
297.90003,248.24992,76.62672
298.20000,248.49990,76.68434
298.50000,248.74991,76.70218
298.80003,248.99984,77.04170
299.10000,249.24992,76.69503
299.40003,249.49985,77.04577
299.70000,249.74985,76.73158
300.00000,249.99997,76.95624
300.30003,250.24995,77.08370
300.60000,250.49990,77.04528
300.90003,250.74989,77.15538
301.20000,250.99991,77.23535
301.50000,251.24988,77.38764
301.80003,251.49984,77.46707
302.10000,251.74990,77.56904
302.40003,251.99989,77.81634
302.70000,252.24984,77.72956
303.00000,252.49988,77.71613
303.30003,252.74990,77.98426
303.60000,252.99991,77.75367
303.90003,253.24984,78.14493
304.20000,253.49990,78.00190
304.50000,253.74992,77.89655
304.80003,253.99983,78.31447
305.10000,254.24991,78.37685
305.40003,254.49982,78.53776
305.70000,254.74990,78.45510
306.00000,254.99990,78.36043
306.30003,255.24989,78.52488
306.60000,255.49997,78.62572
306.90003,255.74982,78.66036
307.20000,255.99984,78.91673
307.50000,256.24996,78.87714
307.80003,256.49989,78.77605
308.10000,256.74984,78.94706
308.40003,256.99988,79.03090
308.70000,257.24990,79.18995
309.00000,257.49991,79.35327
309.30003,257.74984,79.21323
309.60000,257.99984,79.27350
309.90003,258.24988,79.44569
310.20000,258.49983,79.35474
310.50000,258.74991,79.47435
310.80003,258.99990,79.26968
311.10000,259.24990,79.58195
311.40003,259.49989,79.69916
311.70000,259.74989,79.83734
312.00000,259.99997,79.86238
312.30003,260.24988,79.88365
312.60000,260.49990,80.01531
312.90003,260.74991,80.12120
313.20000,260.99995,80.07415
313.50000,261.24984,80.19136
313.80003,261.49983,79.89776
314.10000,261.74990,80.09704
314.40003,261.99991,80.10424
314.70000,262.24984,80.06406
315.00000,262.49990,80.30196
315.30003,262.74988,80.23816
315.60000,262.99983,80.39785
315.90003,263.24986,80.25423
316.20000,263.49990,80.16373
316.50000,263.74996,42.96162
316.80003,263.99983,0.70357
317.10000,264.24989,0.50154
317.40003,264.49984,0.67422
317.70000,264.74988,0.61899
318.00000,264.99990,0.47214
318.30003,265.24989,0.67573
318.60000,265.49989,0.50154
318.90003,265.74984,0.49689
319.20000,265.99983,0.73689
319.50000,266.24996,0.66618
319.80003,266.49982,0.60807
320.10000,266.74990,0.45754
320.40003,266.99990,0.80554
320.70000,267.24989,0.69960
321.00000,267.49989,0.72424
321.30003,267.74982,0.57622
321.60000,267.99990,0.60111
321.90003,268.24990,0.63776
322.20000,268.49989,0.67495
322.50003,268.74995,0.66148
322.80003,268.99997,0.65868
323.10000,269.24983,0.78603
323.40003,269.49985,0.59175
323.70000,269.74997,0.72978
324.00003,269.99990,0.57680
324.30003,270.24984,0.56475
324.60000,270.49994,0.48606
324.90003,270.74983,0.75330
325.20000,270.99987,0.61277
325.50003,271.24984,0.75781
325.80003,271.49985,0.48836
326.10000,271.74989,0.64090
326.40003,271.99989,0.66711
326.70000,272.24988,0.87722
327.00003,272.49996,0.65427
327.23603,272.69660,0.70768