File: V_8/EPR/RDSO EPR Tensile 50.is_tens_RawData/Specimen_RawData_7.csv
Time,Extension,Load
(sec),(mm),(N)
0.00000,0.00000,4.19618
0.30000,0.24925,4.66197
0.60000,0.49994,5.28814
0.90000,0.74994,5.40574
1.20000,0.99994,5.81185
1.50000,1.24987,6.08066
1.80000,1.49987,6.29612
2.10000,1.75000,6.65332
2.40000,1.99994,6.81096
2.70000,2.24987,6.93747
3.00000,2.49994,7.13156
3.30000,2.74994,7.49906
3.60000,2.99994,7.81031
3.90000,3.24987,7.61828
4.20000,3.49994,7.84314
4.50000,3.74994,8.02111
4.80000,3.99994,8.08569
5.10000,4.24994,8.36847
5.40000,4.49994,8.70485
5.70000,4.75000,8.46108
6.00000,4.99987,9.04246
6.30000,5.24994,8.93123
6.60000,5.50000,9.15447
6.90000,5.74994,9.42667
7.20000,5.99994,9.51800
7.50000,6.24994,9.60929
7.80000,6.49994,9.42637
8.10000,6.74994,9.79642
8.40000,6.99987,9.82459
8.70000,7.24994,9.73899
9.00000,7.49994,10.13021
9.30000,7.74987,10.23369
9.60000,7.99987,10.54685
9.90000,8.24994,10.52485
10.20000,8.49981,10.75535
10.50000,8.74994,10.70115
10.80000,8.99987,10.78852
11.10000,9.24994,11.00152
11.40000,9.49994,10.96330
11.70000,9.74987,11.15700
12.00000,10.00000,11.07061
12.30000,10.24994,11.30806
12.60000,10.49994,11.31855
12.90000,10.74994,11.62421
13.20000,10.99994,11.51676
13.50000,11.24987,11.75151
13.80000,11.49987,11.82261
14.10000,11.74994,11.70266
14.40000,11.99987,11.66028
14.70000,12.24987,12.02336
15.00000,12.49994,11.95898
15.30000,12.74987,12.24950
15.60000,12.99994,12.38155
15.90000,13.24987,12.11485
16.20000,13.49994,12.36646
16.50000,13.74987,12.52037
16.80000,13.99987,12.64027
17.10000,14.24994,12.55874
17.40000,14.49994,12.59725
17.70000,14.74994,12.79389
18.00000,14.99994,12.83921
18.30000,15.24994,12.81829
18.60000,15.50000,12.90918
18.90000,15.74987,12.88459
19.20000,15.99994,12.99449
19.50000,16.24993,13.35562
19.80000,16.49987,13.31221
20.10000,16.74994,13.04624
20.40000,16.99987,13.10023
20.70000,17.24993,13.23547
21.00000,17.49987,13.35332
21.30000,17.74987,13.65545
21.60000,17.99993,13.56926
21.90000,18.24987,13.42349
22.20000,18.49987,13.60552
22.50000,18.74994,13.59440
22.80000,18.99993,13.78648
23.10000,19.24987,13.74051
23.40000,19.49994,14.07087
23.70000,19.74987,13.93514
24.00000,19.99993,14.13055
24.30000,20.24994,14.05759
24.60000,20.49993,13.97753
24.90000,20.74993,13.97312
25.20000,20.99993,14.03329
25.50000,21.24987,14.12164
25.80000,21.49994,14.30504
26.10000,21.74993,14.30440
26.40000,21.99987,14.29808
26.70000,22.24993,14.51579
27.00000,22.49993,14.53073
27.30000,22.74993,14.50349
27.60000,22.99987,14.67793
27.90000,23.24993,14.66945
28.20000,23.49993,14.74281
28.50000,23.74993,14.77216
28.80000,23.99993,14.73555
29.10000,24.25000,14.64951
29.40000,24.49993,14.79597
29.70000,24.74987,15.09301
30.00000,24.99999,15.11334
30.30000,25.24993,14.97938
30.60000,25.49981,15.02906
30.90000,25.74987,15.16029
31.20000,25.99993,15.12888
31.50000,26.24993,15.34781
31.80000,26.49987,15.27798
32.10000,26.74993,15.53621
32.40000,26.99994,15.38044
32.70000,27.24993,15.43762
33.00000,27.49993,15.40004
33.30000,27.74987,15.70526
33.60000,28.00000,15.54057
33.90000,28.24987,15.44252
34.20000,28.49987,15.68566
34.50000,28.74993,15.81723
34.80000,28.99987,15.85363
35.10000,29.24993,15.92360
35.40000,29.49993,15.94276
35.70000,29.74994,15.81639
36.00000,29.99993,15.96736
36.30000,30.24987,16.05120
36.60000,30.49993,16.17267
36.90000,30.74987,16.12779
37.20000,30.99993,16.05845
37.50000,31.24993,16.29703
37.80000,31.49993,16.31761
38.10000,31.74993,16.55565
38.40000,31.99987,16.62754
38.70000,32.24993,16.52459
39.00000,32.49993,16.75097
39.30000,32.74993,16.71387
39.60000,32.99993,16.57574
39.90000,33.24993,16.78296
40.20000,33.49993,16.76351
40.50000,33.74987,17.08137
40.80000,33.99981,17.14689
41.10000,34.24987,16.99146
41.40000,34.49987,17.00959
41.70000,34.74993,17.13248
42.00000,34.99993,17.10215
42.30000,35.24987,17.22377
42.60000,35.49987,17.16869
42.90000,35.75000,17.22916
43.20000,35.99993,17.38997
43.50000,36.24987,17.49988
43.80000,36.49993,17.60357
44.10000,36.74993,17.70720
44.40000,36.99993,17.80064
44.70000,37.24993,17.64590
45.00000,37.49993,17.61831
45.30000,37.74993,17.74650
45.60000,37.99993,17.84611
45.90000,38.24993,17.88531
46.20000,38.49993,18.08646
46.50000,38.74987,18.00350
46.80000,38.99987,18.01467
47.10000,39.24993,18.10993
47.40000,39.49993,18.25546
47.70000,39.74987,18.29667
48.00000,39.99987,18.35243
48.30000,40.24993,18.31740
48.60000,40.49993,18.40016
48.90000,40.74987,18.45459
49.20000,40.99987,18.84919
49.50000,41.24993,18.43950
49.80000,41.49993,18.74418
50.10000,41.74993,18.72414
50.40000,41.99993,18.88805
50.70000,42.24993,18.86100
51.00000,42.49987,19.04534
51.30000,42.74987,19.11884
51.60000,42.99993,19.12560
51.90000,43.24993,19.31792
52.20000,43.49981,19.29274
52.50000,43.74993,19.30959
52.80000,43.99993,19.45306
53.10000,44.24993,19.27402
53.40000,44.49987,19.42215
53.70000,44.74993,19.46041
54.00000,44.99999,19.73692
54.30000,45.24987,19.82174
54.60000,45.49993,19.57483
54.90000,45.74993,19.76725
55.20000,45.99987,20.06512
55.50000,46.24993,19.93615
55.80000,46.49993,19.95384
56.10000,46.74993,20.03440
56.40000,46.99986,20.42865
56.70000,47.24993,20.09227
57.00000,47.49993,20.16199
57.30000,47.74987,20.31046
57.60000,47.99993,20.35883
57.90000,48.24987,20.51347
58.20000,48.49993,20.65248
58.50000,48.74993,20.30659
58.80000,48.99987,20.51896
59.10000,49.24993,20.82707
59.40000,49.49987,20.81585
59.70000,49.74993,20.77278
60.00000,49.99993,20.86514
60.30000,50.24993,20.97809
60.60000,50.49993,21.15674
60.90000,50.74987,21.15581
61.20000,50.99993,21.20564
61.50000,51.24993,21.18501
61.80000,51.49987,21.38572
62.10000,51.74993,21.49979
62.40000,51.99993,21.58030
62.70000,52.24993,21.62268
63.00000,52.49986,21.87047
63.30000,52.74993,21.62131
63.60000,52.99993,21.59994
63.90000,53.24993,21.91526
64.20000,53.49987,21.99518
64.50000,53.74993,21.86131
64.80000,53.99993,22.08558
65.10001,54.24987,22.12272
65.40000,54.49993,22.17192
65.70001,54.74993,22.30750
66.00000,54.99993,22.25086
66.30000,55.24987,22.60361
66.60001,55.49993,22.52629
66.90000,55.74993,22.34484
67.20001,55.99987,22.55162
67.50000,56.24993,22.70352
67.80000,56.49987,22.77687
68.10001,56.74987,22.90834
68.40000,56.99987,23.00786
68.70001,57.24987,23.02378
69.00000,57.49993,22.98468
69.30000,57.74986,23.00242
69.60001,57.99993,23.20689
69.90000,58.24993,23.24168
70.20001,58.49987,23.34865
70.50000,58.74987,23.39407
70.80000,58.99993,23.39187
71.10001,59.24993,23.69983
71.40000,59.49981,23.61786
71.70001,59.74993,23.77074
72.00000,59.99999,23.93141
72.30000,60.24993,23.87123
72.60001,60.49987,24.04553
72.90000,60.74993,23.89862
73.20001,60.99993,24.07448
73.50000,61.24993,24.22212
73.80000,61.49987,24.11540
74.10001,61.74993,24.29866
74.40000,61.99993,24.17209
74.70001,62.24987,24.54425
75.00000,62.49993,24.43047
75.30000,62.74993,24.66307
75.60001,62.99987,24.62461
75.90000,63.24986,24.71687
76.20001,63.49993,24.85094
76.50000,63.74999,24.98338
76.80000,63.99993,24.89146
77.10001,64.24987,25.13234
77.40000,64.49993,25.26312
77.70001,64.74993,25.26734
78.00000,64.99992,25.26342
78.30000,65.24993,25.44202
78.60001,65.49993,25.47088
78.90000,65.74986,25.44751
79.20001,65.99993,25.57417
79.50000,66.24993,25.70672
79.80000,66.49993,25.86817
80.10001,66.74992,25.92678
80.40000,66.99986,26.02600
80.70001,67.24992,26.10793
81.00001,67.49993,26.18981
81.30000,67.74987,26.08666
81.60001,67.99986,26.40908
81.90000,68.24993,26.19079
82.20001,68.49993,26.35107
82.50001,68.74999,26.51046
82.80000,68.99986,26.65516
83.10001,69.24986,26.65927
83.40000,69.49992,26.63463
83.70001,69.74993,26.74341
84.00001,69.99987,26.72572
84.30000,70.24986,26.88644
84.60001,70.49993,27.00620
84.90000,70.74993,27.09959
85.20001,70.99986,26.99590
85.50001,71.24986,27.14217
85.80000,71.49993,27.37555
86.10001,71.74992,27.39765
86.40000,71.99986,27.68964
86.70001,72.24993,27.35625
87.00001,72.49992,27.62800
87.30000,72.74993,27.66603
87.60001,72.99987,27.85404
87.90000,73.24993,28.22551
88.20001,73.49993,28.28127
88.50001,73.74987,28.17856
88.80000,73.99987,28.12937
89.10001,74.24993,28.12403
89.40000,74.49986,28.36922
89.70001,74.74986,28.40401
90.00001,74.99993,28.26363
90.30000,75.24987,28.43631
90.60001,75.49986,28.61324
90.90000,75.74987,28.67165
91.20001,75.99992,28.67513
91.50001,76.24993,28.72104
91.80000,76.49980,28.58938
92.10001,76.74999,29.11329
92.40000,76.99999,28.93934
92.70001,77.24993,29.19698
93.00001,77.49987,29.07404
93.30000,77.74986,29.09883
93.60001,77.99999,29.48720
93.90000,78.24986,29.49171
94.20001,78.49980,29.43017
94.50001,78.74993,29.31815
94.80000,78.99993,29.76675
95.10001,79.24986,29.82599
95.40000,79.49992,29.61343
95.70001,79.74987,29.88008
96.00001,79.99986,29.97157
96.30000,80.24986,29.99548
96.60001,80.49992,30.21671
96.90000,80.74992,30.35029
97.20001,80.99993,30.42540
97.50001,81.24992,30.38248
97.80000,81.49998,30.33343
98.10001,81.74987,30.30633
98.40000,81.99986,30.53928
98.70001,82.24992,30.66653
99.00001,82.49993,30.71048
99.30000,82.74986,30.77085
99.60001,82.99992,30.87654
99.90000,83.24986,31.05050
100.20001,83.49986,31.03535
100.50001,83.74986,31.12213
100.80000,83.99987,31.40021
101.10001,84.24993,31.50443
101.40000,84.49992,31.37938
101.70001,84.74993,31.32504
102.00001,84.99992,31.37977
102.30000,85.24993,31.61992
102.60001,85.49985,31.55259
102.90000,85.74992,31.87864
103.20001,85.99993,31.95145
103.50001,86.24992,31.93989
103.80000,86.49986,32.20581
104.10001,86.74999,32.09904
104.40000,86.99981,32.10541
104.70001,87.24986,32.15147
105.00001,87.49993,32.41073
105.30000,87.74986,32.29558
105.60001,87.99986,32.50971
105.90000,88.24993,32.75662
106.20001,88.49992,32.75358
106.50001,88.74992,32.57116
106.80000,88.99986,32.93297
107.10001,89.24986,33.04170
107.40000,89.49986,32.81694
107.70001,89.74986,33.21281
108.00001,89.99993,33.12343
108.30000,90.24986,33.22795
108.60001,90.49992,33.39749
108.90000,90.74987,33.49181
109.20001,90.99992,33.53959
109.50001,91.24992,33.45644
109.80000,91.49986,33.79008
110.10001,91.74986,33.59481
110.40000,91.99993,33.60393
110.70001,92.24992,33.91115
111.00001,92.49986,33.83393
111.30000,92.74987,34.19771
111.60001,92.99998,34.29610
111.90000,93.24992,34.10608
112.20001,93.49986,34.01513
112.50001,93.74999,34.43756
112.80000,93.99986,34.48651
113.10001,94.24992,34.48636
113.40001,94.49986,34.64189
113.70001,94.74993,34.57202
114.00001,94.99992,34.91007
114.30000,95.24986,34.89429
114.60001,95.49987,34.98812
114.90001,95.74993,35.13571
115.20001,95.99992,35.26590
115.50001,96.24986,35.37140
115.80000,96.49992,35.18118
116.10001,96.74999,35.27374
116.40001,96.99985,35.38296
116.70001,97.24986,35.41305
117.00001,97.49993,35.49777
117.30000,97.74987,35.74061
117.60001,97.99986,35.69441
117.90001,98.24986,35.85272
118.20001,98.49992,35.90481
118.50001,98.74986,35.94607
118.80000,98.99992,36.12649
119.10001,99.24993,36.22517
119.40001,99.49992,36.21283
119.70001,99.74986,36.30989
120.00001,99.99992,36.31332
120.30000,100.24992,36.48350
120.60001,100.49986,36.56504
120.90001,100.74986,36.62540
121.20001,100.99986,36.72865
121.50001,101.24993,36.70302
121.80000,101.49992,36.84188
122.10001,101.74992,36.89966
122.40001,101.99992,37.10291
122.70001,102.24986,37.13363
123.00001,102.49992,37.19620
123.30000,102.74986,37.18861
123.60001,102.99992,37.17082
123.90001,103.24992,37.40651
124.20001,103.49993,37.49030
124.50001,103.74999,37.71036
124.80000,103.99986,37.74235
125.10001,104.24992,37.64612
125.40001,104.49998,38.15866
125.70001,104.74992,38.02950
126.00001,104.99992,37.96893
126.30000,105.24986,38.10593
126.60001,105.49992,38.01440
126.90001,105.74993,38.40326
127.20001,105.99986,38.33437
127.50001,106.24993,38.61529
127.80000,106.49987,38.51964
128.10001,106.74986,38.61132
128.40001,106.99992,38.62239
128.70002,107.24992,38.72833
129.00000,107.49992,38.83344
129.30000,107.74986,38.81442
129.60001,107.99993,38.87876
129.90001,108.24992,39.13748
130.20002,108.49993,38.92031
130.50000,108.74987,39.13993
130.80000,108.99992,39.31138
131.10000,109.24999,39.39321
131.40002,109.49986,39.35009
131.70002,109.74986,39.57328
132.00000,109.99999,39.59935
132.30000,110.24985,39.82411
132.60000,110.49992,39.98400
132.90002,110.74992,39.79888
133.20002,110.99992,39.79143
133.50000,111.24986,39.99708
133.80000,111.49986,40.15011
134.10000,111.74999,40.17603
134.40002,111.99986,40.25399
134.70002,112.24993,40.32876
135.00000,112.49986,40.26487
135.30000,112.74992,40.31039
135.60000,112.99992,40.58582
135.90002,113.24986,40.67093
136.20002,113.49992,40.67137
136.50000,113.74986,40.84713
136.80000,113.99986,40.80950
137.10000,114.24992,41.00761
137.40002,114.49993,41.01256
137.70002,114.74986,40.97169
138.00000,114.99993,41.16583
138.30000,115.24992,41.16818
138.60000,115.49992,41.42102
138.90002,115.74986,41.40064
139.20002,115.99992,41.49564
139.50000,116.24992,41.59335
139.80000,116.49992,41.64073
140.10000,116.74993,41.67930
140.40002,116.99999,41.80234
140.70002,117.24993,41.98780
141.00000,117.49987,41.88417
141.30000,117.74986,42.20629
141.60000,117.99992,42.23260
141.90002,118.24986,42.16155
142.20002,118.49985,42.21531
142.50000,118.74992,42.49857
142.80000,118.99993,42.44467
143.10000,119.24986,42.30179
143.40002,119.49993,42.70192
143.70002,119.74992,42.62808
144.00000,119.99986,42.83251
144.30000,120.24986,42.93472
144.60000,120.49992,42.93502
144.90002,120.74992,43.07912
145.20002,120.99986,43.27360
145.50000,121.24993,43.22887
145.80000,121.49992,43.17903
146.10000,121.74992,43.22068
146.40002,121.99992,43.38748
146.70002,122.24986,43.49107
147.00000,122.49992,43.56476
147.30000,122.74992,43.86297
147.60000,122.99986,43.68167
147.90002,123.24986,43.73210
148.20002,123.49992,43.99772
148.50000,123.74992,43.81878
148.80000,123.99986,43.86802
149.10000,124.24992,44.17050
149.40002,124.49986,44.09308
149.70002,124.74986,44.27345
150.00000,124.99992,44.28604
150.30000,125.24992,44.27703
150.60000,125.49998,44.57244
150.90002,125.74992,44.65447
151.20002,125.99997,44.66755
151.50000,126.24991,44.54128
151.80000,126.49992,44.66946
152.10000,126.74998,44.74639
152.40002,126.99998,44.92970
152.70002,127.24985,45.26099
153.00000,127.49991,45.29196
153.30000,127.74984,45.18989
153.60000,127.99992,45.06656
153.90002,128.24985,45.37707
154.20002,128.49986,45.27495
154.50000,128.74993,45.31553
154.80000,128.99986,45.52770
155.10000,129.24986,45.51025
155.40002,129.49991,45.78950
155.70002,129.74991,45.65078
156.00000,129.99984,45.69459
156.30000,130.24986,45.97173
156.60000,130.49997,45.91377
156.90002,130.74991,46.20350
157.20002,130.99985,46.09433
157.50000,131.24998,46.08453
157.80000,131.49998,46.21051
158.10000,131.74991,46.42484
158.40002,131.99992,46.46046
158.70002,132.24992,46.61481
159.00000,132.49986,46.51245
159.30000,132.74992,46.60378
159.60000,132.99991,46.61054
159.90002,133.24991,46.67003
160.20002,133.49985,46.71173
160.50000,133.74986,46.91542
160.80000,133.99991,46.87833
161.10000,134.24992,47.01656
161.40002,134.49985,47.10064
161.70002,134.74986,47.33216
162.00002,134.99992,47.33094
162.30000,135.24991,47.43795
162.60000,135.49998,47.36740
162.90002,135.74985,47.34667
163.20002,135.99992,47.61935
163.50002,136.24991,47.79580
163.80000,136.49992,47.70888
164.10000,136.74991,47.79575
164.40002,136.99993,47.81290
164.70002,137.24978,48.05266
165.00002,137.49997,47.93869
165.30000,137.74991,47.95020
165.60000,137.99985,48.15909
165.90002,138.24992,48.28168
166.20002,138.49991,48.42937
166.50002,138.74997,48.42060
166.80000,138.99985,48.48836
167.10000,139.24993,48.42633
167.40002,139.49992,48.65295
167.70002,139.74986,48.64458
168.00002,139.99991,48.58666
168.30000,140.24991,48.84307
168.60000,140.49992,48.87870
168.90002,140.74986,49.16143
169.20002,140.99985,48.97483
169.50002,141.24999,49.16657
169.80000,141.49985,49.09670
170.10000,141.74992,49.32999
170.40002,141.99986,49.30220
170.70002,142.24991,49.29206
171.00002,142.49985,49.54837
171.30000,142.74985,49.56543
171.60000,142.99992,49.59032
171.90002,143.24992,49.72066
172.20002,143.49991,49.76584
172.50002,143.74998,49.94655
172.80000,143.99998,49.84012
173.10000,144.24986,49.96429
173.40002,144.49986,50.31111
173.70002,144.74991,50.14775
174.00002,144.99992,50.29048
174.30000,145.24986,50.04107
174.60000,145.49992,50.34585
174.90002,145.74992,50.42866
175.20002,145.99998,50.42455
175.50002,146.24985,50.68581
175.80000,146.49992,50.68596
176.10000,146.74991,50.61892
176.40002,146.99985,50.84560
176.70002,147.24985,50.97064
177.00002,147.49992,50.90675
177.30000,147.74986,50.86951
177.60000,147.99985,50.89337
177.90002,148.24999,51.06041
178.20002,148.49992,51.08335
178.50002,148.74992,51.25254
178.80000,148.99986,51.55026
179.10000,149.24991,51.37975
179.40002,149.49991,51.33467
179.70002,149.74984,51.77728
180.00002,149.99992,51.56874
180.30000,150.24992,51.73294
180.60000,150.49986,51.88949
180.90002,150.74993,51.79776
181.20002,150.99992,51.77488
181.50002,151.24992,52.08231
181.80000,151.49985,51.96976
182.10000,151.74991,52.28713
182.40002,151.99992,52.32583
182.70002,152.24986,52.18711
183.00002,152.49985,52.39899
183.30000,152.74991,52.49665
183.60000,152.99998,52.46837
183.90002,153.24985,52.66844
184.20002,153.49992,52.62552
184.50002,153.74998,52.66202
184.80000,153.99992,52.58744
185.10000,154.24985,52.88786
185.40002,154.49998,52.79354
185.70002,154.74985,52.74768
186.00002,154.99991,52.91727
186.30000,155.24991,52.95784
186.60000,155.49992,53.12159
186.90002,155.74992,53.21857
187.20002,155.99986,53.08136
187.50002,156.24992,53.36287
187.80000,156.49991,53.48640
188.10000,156.74992,53.48532
188.40002,156.99985,53.61090
188.70002,157.24991,53.64496
189.00002,157.49991,53.41691
189.30000,157.74984,53.58244
189.60000,157.99992,53.69097
189.90002,158.24990,54.12349
190.20002,158.49991,53.89295
190.50002,158.74991,54.13251
190.80000,158.99984,54.04499
191.10000,159.24992,54.24354
191.40002,159.49985,54.28162
191.70002,159.74991,54.41289
192.00002,159.99991,54.24129
192.30000,160.24992,54.55773
192.60000,160.49985,54.66195
192.90002,160.74991,54.82101
193.20002,160.99999,54.57336
193.50002,161.24984,54.79200
193.80000,161.49985,54.75873
194.10000,161.74996,54.93292
194.40002,161.99986,55.01397
194.70002,162.24984,55.00804
195.00002,162.49992,55.18032
195.30000,162.74985,55.06414
195.60000,162.99991,55.25211
195.90002,163.24984,55.41361
196.20002,163.49992,55.45859
196.50002,163.74992,55.28131
196.80000,163.99985,55.40371
197.10000,164.24986,55.45967
197.40002,164.49990,55.57046
197.70002,164.74985,55.70918
198.00002,164.99991,55.70085
198.30000,165.24991,55.55463
198.60000,165.49991,55.63906
198.90002,165.74990,55.84946
199.20002,165.99992,55.80522
199.50002,166.24991,55.98412
199.80000,166.49991,56.13538
200.10000,166.74984,56.12769
200.40002,166.99998,56.11837
200.70002,167.24991,56.39361
201.00002,167.49986,56.36754
201.30000,167.74984,56.13395
201.60000,167.99990,56.49764
201.90002,168.24985,56.60225
202.20002,168.49985,56.67060
202.50002,168.74991,56.94128
202.80000,168.99984,56.67830
203.10000,169.24992,56.79335
203.40002,169.49985,56.75939
203.70002,169.74986,56.72656
204.00002,169.99992,56.89693
204.30000,170.24990,56.90546
204.60000,170.49992,56.97043
204.90002,170.74991,57.17447
205.20002,170.99986,57.11787
205.50002,171.24990,57.37218
205.80000,171.49990,57.42231
206.10000,171.74991,57.42373
206.40002,171.99986,57.43000
206.70002,172.24984,57.44848
207.00002,172.49990,57.71126
207.30000,172.74985,57.77325
207.60000,172.99991,57.78530
207.90002,173.24986,57.83224
208.20002,173.49990,58.06504
208.50002,173.74985,57.95469
208.80000,173.99983,58.06641
209.10000,174.24991,58.16569
209.40002,174.49984,57.94254
209.70002,174.74985,58.16667
210.00002,174.99991,58.37682
210.30000,175.24991,58.19097
210.60000,175.49992,58.52814
210.90002,175.74985,58.61305
211.20002,175.99991,58.54450
211.50002,176.24991,58.41206
211.80000,176.49986,58.62986
212.10000,176.74992,58.63761
212.40002,176.99985,58.76373
212.70002,177.24991,58.88564
213.00002,177.49984,58.80420
213.30000,177.74992,58.92342
213.60000,177.99990,58.90862
213.90002,178.24979,58.73599
214.20002,178.49991,59.23095
214.50002,178.74997,59.07743
214.80000,178.99992,59.19263
215.10000,179.24985,59.19111
215.40002,179.49985,59.29215
215.70002,179.74997,59.50573
216.00002,179.99992,59.58016
216.30000,180.24985,59.37799
216.60000,180.49991,59.67126
216.90002,180.74991,59.73055
217.20002,180.99984,59.72501
217.50002,181.24992,59.72417
217.80000,181.49991,59.79929
218.10000,181.74985,59.98054
218.40002,181.99991,60.04243
218.70002,182.24992,59.90812
219.00002,182.49990,60.07418
219.30000,182.74985,60.13538
219.60000,182.99984,60.13190
219.90002,183.24992,60.10500
220.20002,183.49985,60.43776
220.50002,183.74991,60.29895
220.80000,183.99986,60.49695
221.10000,184.24984,60.51881
221.40002,184.49984,60.62043
221.70002,184.74991,60.46838
222.00002,184.99991,60.68982
222.30000,185.24984,60.78130
222.60000,185.49984,60.73333
222.90002,185.74992,60.76234
223.20002,185.99991,60.91022
223.50002,186.24991,60.88312
223.80000,186.49984,60.94040
224.10000,186.74985,61.04267
224.40002,186.99991,61.31550
224.70002,187.24985,61.32490
225.00002,187.49991,61.35710
225.30002,187.74984,61.47543
225.60000,187.99985,61.44015
225.90002,188.24991,61.58362
226.20002,188.49997,61.35249
226.50002,188.74984,61.56535
226.80002,188.99985,61.76169
227.10000,189.24996,61.71666
227.40002,189.49991,61.62464
227.70002,189.74984,61.81995
228.00002,189.99984,61.90599
228.30002,190.24983,61.90795
228.60000,190.49991,61.83176
228.90002,190.74984,61.97336
229.20002,190.99990,61.98704
229.50002,191.24992,61.95107
229.80002,191.49985,62.00909
230.10000,191.74986,62.23341
230.40002,191.99990,62.10631
230.70002,192.24990,62.09523
231.00002,192.49983,62.25992
231.30002,192.74991,62.46067
231.60000,192.99991,62.49752
231.90002,193.24990,62.60821
232.20002,193.49990,62.67382
232.50002,193.74991,62.66563
232.80002,193.99991,62.86894
233.10000,194.24984,62.80166
233.40002,194.49979,63.00035
233.70002,194.74998,62.93499
234.00002,194.99991,63.07258
234.30002,195.24978,62.93989
234.60000,195.49990,63.12908
234.90002,195.74990,63.35899
235.20002,195.99983,63.20140
235.50002,196.24991,63.42964
235.80002,196.49990,63.18420
236.10000,196.74990,63.43685
236.40002,196.99983,63.43361
236.70002,197.24978,63.47316
237.00002,197.49997,63.34742
237.30002,197.74990,63.68439
237.60000,197.99991,63.62045
237.90002,198.24991,63.71247
238.20002,198.49991,63.81517
238.50002,198.74984,63.76015
238.80002,198.99985,63.80244
239.10000,199.24983,63.92248
239.40002,199.49984,64.06674
239.70002,199.74984,63.92258
240.00002,199.99990,64.09144
240.30002,200.24985,64.27665
240.60000,200.49984,64.22192
240.90002,200.74986,64.12000
241.20002,200.99990,64.36559
241.50002,201.24990,64.31301
241.80002,201.49983,64.30297
242.10000,201.74991,64.29405
242.40002,201.99992,64.47167
242.70002,202.24990,64.50298
243.00002,202.49985,64.58888
243.30002,202.74984,64.75127
243.60000,202.99992,64.66307
243.90002,203.24990,64.68027
244.20002,203.49991,64.82393
244.50002,203.74991,64.83506
244.80002,203.99984,64.82129
245.10000,204.24992,65.21828
245.40002,204.49990,65.00264
245.70002,204.74985,64.98534
246.00002,204.99984,65.08966
246.30002,205.24984,65.13518
246.60000,205.49990,65.34407
246.90002,205.74979,65.29614
247.20002,205.99991,65.50753
247.50002,206.24990,65.43080
247.80002,206.49992,65.64870
248.10000,206.74990,65.64267
248.40002,206.99985,65.76444
248.70002,207.24989,65.75463
249.00002,207.49992,65.78756
249.30002,207.74985,65.81510
249.60000,207.99991,65.94573
249.90002,208.24984,65.81902
250.20002,208.49984,65.90310
250.50002,208.74985,66.03795
250.80002,208.99991,65.96955
251.10000,209.24991,66.07226
251.40002,209.49984,65.84235
251.70002,209.74990,66.27717
252.00002,209.99990,66.23929
252.30002,210.24985,66.32426
252.60000,210.49991,66.33607
252.90002,210.74990,66.46724
253.20002,210.99992,66.37149
253.50002,211.24985,66.47817
253.80002,211.49985,66.60135
254.10000,211.74997,66.62335
254.40002,211.99984,66.58283
254.70002,212.24983,66.80637
255.00002,212.49991,66.98228
255.30002,212.74991,66.90907
255.60000,212.99984,66.94901
255.90002,213.24985,66.89795
256.20002,213.49985,67.07312
256.50000,213.74991,67.08557
256.80002,213.99984,67.28265
257.10000,214.24985,67.16216
257.40003,214.49991,67.26280
257.70002,214.74991,67.37756
258.00000,214.99991,67.48913
258.30002,215.24996,67.49403
258.60000,215.49990,67.58042
258.90003,215.74983,67.56160
259.20002,215.99986,67.55714
259.50000,216.24997,67.65882
259.80002,216.49985,67.59473
260.10000,216.74983,67.71811
260.40003,216.99991,67.79215
260.70002,217.24992,67.78783
261.00000,217.49990,67.80827
261.30002,217.74985,67.89377
261.60000,217.99991,67.91847
261.90003,218.24986,68.00182
262.20000,218.49984,68.13770
262.50000,218.74990,68.21110
262.80003,218.99983,68.37652
263.10000,219.24986,68.09884
263.40003,219.49984,68.25358
263.70000,219.74990,68.27558
264.00000,219.99991,68.24677
264.30003,220.24984,68.23579
264.60000,220.49997,68.41993
264.90003,220.74990,68.56615
265.20000,220.99990,68.43826
265.50000,221.24991,68.26720
265.80003,221.49984,68.54674
266.10000,221.74997,68.39700
266.40003,221.99985,68.64984
266.70000,222.24991,68.61985
267.00000,222.49991,68.71129
267.30003,222.74986,68.57933
267.60000,222.99990,68.84304
267.90003,223.24990,68.98755
268.20000,223.49991,69.27787
268.50000,223.74991,68.99064
268.80003,223.99984,68.97584
269.10000,224.24996,69.25068
269.40003,224.49991,69.13028
269.70000,224.74984,69.25450
270.00000,224.99992,69.58275
270.30003,225.24990,69.38112
270.60000,225.49991,69.60421
270.90003,225.74984,69.66032
271.20000,225.99991,69.79781
271.50000,226.24992,69.70128
271.80003,226.49985,69.61719
272.10000,226.74991,69.79987
272.40003,226.99989,69.80271
272.70000,227.24992,69.91144
273.00000,227.49985,70.08186
273.30003,227.74991,70.17374
273.60000,227.99991,70.07025
273.90003,228.24984,70.03198
274.20000,228.49984,70.08490
274.50000,228.74990,70.11768
274.80003,228.99991,70.14850
275.10000,229.24984,70.26796
275.40003,229.49992,70.20892
275.70000,229.74990,70.44637
276.00000,229.99991,70.36038
276.30003,230.24984,70.57480
276.60000,230.49990,70.61660
276.90003,230.74985,70.52727
277.20000,230.99985,70.46632
277.50000,231.24991,71.01413
277.80003,231.49984,70.99605
278.10000,231.74984,70.87492
278.40003,231.99985,71.06941
278.70000,232.24991,71.27369
279.00000,232.49991,71.54804
279.30003,232.74984,71.38095
279.60000,232.99992,71.54382
279.90003,233.24991,71.73722
280.20000,233.49985,71.56690
280.50000,233.74990,71.64177
280.80003,233.99990,71.75271
281.10000,234.24983,71.77770
281.40003,234.49985,72.09301
281.70000,234.74984,72.08640
282.00000,234.99990,72.17798
282.30003,235.24985,72.44517
282.60000,235.49991,72.33894
282.90003,235.74991,72.53709
283.20000,235.99990,72.50686
283.50000,236.24985,72.31915
283.80003,236.49983,72.50662
284.10000,236.74997,72.41631
284.40003,236.99991,72.36329
284.70000,237.24990,72.41876
285.00000,237.49990,72.45591
285.30003,237.74991,72.57889
285.60000,237.99991,72.55439
285.90003,238.24984,72.70830
286.20000,238.49990,72.61520
286.50000,238.74991,72.79072
286.80003,238.99985,73.09961
287.10000,239.24991,73.22721
287.40003,239.49984,73.18816
287.70000,239.74985,73.08648
288.00000,239.99983,73.44703
288.30003,240.24986,73.41630
288.60000,240.49990,73.57482
288.90003,240.74985,73.66963
289.20000,240.99983,73.77155
289.50000,241.24991,73.85936
289.80003,241.49984,74.11303
290.10000,241.74990,74.09318
290.40003,241.99998,74.16301
290.70000,242.24991,74.17653
291.00000,242.49991,74.08544
291.30003,242.74990,74.21431
291.60000,242.99996,74.26885
291.90003,243.24991,74.14189
292.20000,243.49984,74.08515
292.50000,243.74984,74.07956
292.80003,243.99990,74.04913
293.10000,244.24991,74.25028
293.40003,244.49991,74.14057
293.70000,244.74991,74.07535
294.00000,244.99984,74.06310
294.30003,245.24990,74.30800
294.60000,245.49991,74.14375
294.90003,245.74997,74.38234
295.20000,245.99984,74.72514
295.50000,246.24985,74.60205
295.80003,246.49991,74.77183
296.10000,246.74989,74.79648
296.40003,246.99984,74.92981
296.70000,247.24985,74.84342
297.00000,247.49996,75.17883
297.30003,247.74991,75.32033
297.60000,247.99984,75.31559
297.90003,248.24992,75.33759
298.20000,248.49990,75.55892
298.50000,248.74991,75.57901
298.80003,248.99984,75.65466
299.10000,249.24992,75.63148
299.40003,249.49990,75.64771
299.70000,249.74985,75.78961
300.00000,249.99997,75.81411
300.30003,250.24990,75.93975
300.60000,250.49990,75.61277
300.90003,250.74989,75.74267
301.20000,250.99991,75.59410
301.50000,251.24988,75.63276
301.80003,251.49984,75.82190
302.10000,251.74990,75.91784
302.40003,251.99994,75.84287
302.70000,252.24984,76.04980
303.00000,252.49988,76.16965
303.30003,252.74990,76.02441
303.60000,252.99991,76.14775
303.90003,253.24984,76.40740
304.20000,253.49990,76.31812
304.50000,253.74992,76.17538
304.80003,253.99989,76.13422
305.10000,254.24991,76.38589
305.40003,254.49982,75.87330
305.70000,254.74990,75.65986
306.00000,254.99990,0.74776
306.30003,255.24989,0.44357
306.60000,255.49997,0.61341
306.90003,255.74982,0.59327
307.20000,255.99990,0.65339
307.50000,256.24996,0.50977
307.80003,256.49983,0.52041
308.10000,256.74984,0.57793
308.40003,256.99988,0.50061
308.70000,257.24990,0.58905
309.00000,257.49991,0.46866
309.30003,257.74984,0.49821
309.60000,257.99984,0.47611
309.90003,258.24988,0.24841
309.90803,258.25659,0.21719