File: V_7/FR/RDSO FR Tensile 50.is_tens_RawData/Specimen_RawData_5.csv
Time,Extension,Load
(sec),(mm),(N)
0.00000,0.00000,0.16597
0.20000,0.16469,1.17738
0.40000,0.33306,1.90615
0.60000,0.49994,2.14160
0.80000,0.66675,2.53619
1.00000,0.83337,3.08970
1.20000,0.99994,3.46597
1.40000,1.16675,3.84082
1.60000,1.33337,4.17235
1.80000,1.49987,4.52221
2.00000,1.66669,4.57008
2.20000,1.83344,4.97379
2.40000,1.99994,5.28582
2.60000,2.16662,5.43478
2.80000,2.33337,5.75411
3.00000,2.49994,5.97677
3.20000,2.66675,6.12097
3.40000,2.83331,6.55555
3.60000,2.99994,6.51180
3.80000,3.16675,6.59794
4.00000,3.33331,7.21318
4.20000,3.49994,7.22759
4.40000,3.66675,7.25679
4.60000,3.83337,7.68030
4.80000,3.99994,7.69818
5.00000,4.16669,7.95205
5.20000,4.33337,8.28912
5.40000,4.49994,8.46851
5.60000,4.66675,8.43484
5.80000,4.83331,8.42999
6.00000,4.99987,8.86609
6.20000,5.16675,8.90617
6.40000,5.33331,9.22776
6.60000,5.50000,9.01897
6.80000,5.66675,9.13246
7.00000,5.83331,9.53553
7.20000,5.99994,9.51309
7.40000,6.16675,9.81047
7.60000,6.33337,9.58629
7.80000,6.49994,9.92767
8.00000,6.66675,10.01921
8.20000,6.83337,10.14278
8.40000,6.99987,10.20340
8.60000,7.16675,10.21785
8.80000,7.33337,10.26617
9.00000,7.49994,10.54787
9.20000,7.66662,10.63048
9.40000,7.83325,10.82035
9.60000,7.99987,10.65459
9.80000,8.16681,10.81153
10.00000,8.33337,11.00312
10.20000,8.49981,11.03821
10.40000,8.66669,10.99974
10.60000,8.83331,11.11391
10.80000,8.99987,11.13964
11.00000,9.16675,11.23592
11.20000,9.33337,11.38155
11.40000,9.49987,11.42751
11.60000,9.66669,11.49258
11.80000,9.83337,11.69417
12.00000,10.00000,11.38860
12.20000,10.16675,11.49562
12.40000,10.33337,11.85214
12.60000,10.49994,11.83759
12.80000,10.66669,11.94706
13.00000,10.83337,12.01928
13.20000,10.99994,12.08048
13.40000,11.16669,12.10885
13.60000,11.33331,12.03810
13.80000,11.49987,12.16589
14.00000,11.66675,12.05324
14.20000,11.83337,12.28565
14.40000,11.99987,12.34773
14.60000,12.16662,12.22258
14.80000,12.33337,12.38781
15.00000,12.49994,12.58386
15.20000,12.66675,12.70459
15.40000,12.83337,12.56323
15.60000,12.99994,12.69117
15.80000,13.16675,12.80627
16.00000,13.33331,12.66329
16.20000,13.49994,12.67715
16.40000,13.66675,12.88437
16.60000,13.83331,12.79441
16.80000,13.99987,12.69504
17.00000,14.16669,12.90290
17.20000,14.33337,12.96758
17.40000,14.50000,12.96292
17.60000,14.66669,13.15676
17.80000,14.83331,13.22561
18.00000,14.99994,13.14339
18.20000,15.16675,13.20096
18.40000,15.33331,13.46336
18.60000,15.50000,13.23835
18.80000,15.66675,13.39113
19.00000,15.83337,13.35218
19.20000,15.99994,13.40735
19.40000,16.16675,13.39084
19.60000,16.33337,13.41818
19.80000,16.49987,13.41347
20.00000,16.66675,13.36550
20.20000,16.83337,13.45454
20.40000,16.99987,13.65254
20.60000,17.16669,13.58154
20.80000,17.33337,13.54220
21.00000,17.49994,13.62461
21.20000,17.66675,13.67092
21.40000,17.83337,13.60325
21.60000,17.99993,13.69655
21.80000,18.16675,13.62932
22.00000,18.33331,13.89696
22.20000,18.49987,13.83708
22.40000,18.66675,13.95904
22.60000,18.83337,14.02401
22.80000,18.99993,13.85202
23.00000,19.16662,14.03612
23.20000,19.33331,14.05537
23.40000,19.49994,13.92048
23.60000,19.66675,14.17542
23.80000,19.83337,14.08394
24.00000,19.99993,14.19340
24.20000,20.16675,14.30953
24.40000,20.33331,14.11785
24.60000,20.49993,14.08903
24.80000,20.66675,14.37147
25.00000,20.83337,14.20962
25.20000,20.99993,14.42522
25.40000,21.16675,14.43331
25.60000,21.33331,14.18106
25.80000,21.49994,14.36476
26.00000,21.66675,14.49387
26.20000,21.83337,14.38318
26.40000,21.99993,14.52068
26.60000,22.16668,14.51308
26.80000,22.33337,14.51087
27.00000,22.49993,14.53944
27.20000,22.66675,14.58256
27.40000,22.83331,14.66062
27.60000,22.99994,14.71295
27.80000,23.16675,14.77361
28.00000,23.33331,14.62455
28.20000,23.49993,14.48883
28.40000,23.66675,14.72089
28.60000,23.83331,14.76739
28.80000,23.99987,14.81021
29.00000,24.16675,14.64317
29.20000,24.33343,14.88710
29.40000,24.49993,14.99098
29.60000,24.66668,14.76754
29.80000,24.83331,15.05830
30.00000,24.99999,14.96339
30.20000,25.16675,15.01734
30.40000,25.33331,14.97069
30.60000,25.49981,15.04439
30.80000,25.66668,14.98372
31.00000,25.83337,15.09221
31.20000,25.99993,15.12190
31.40000,26.16675,15.34407
31.60000,26.33331,15.31707
31.80000,26.49987,15.21902
32.00000,26.66668,15.32903
32.20000,26.83337,15.13646
32.40000,26.99994,15.19971
32.60000,27.16674,15.07241
32.80000,27.33337,15.39081
33.00000,27.49993,15.31065
33.20000,27.66668,15.20314
33.40000,27.83337,15.37019
33.60000,28.00000,15.19104
33.80000,28.16675,15.48548
34.00000,28.33331,15.35411
34.20000,28.49987,15.47436
34.40000,28.66675,15.62743
34.60000,28.83331,15.69064
34.80000,28.99987,15.68942
35.00000,29.16669,15.53252
35.20000,29.33337,15.69001
35.40000,29.49993,15.56868
35.60000,29.66675,15.74665
35.80000,29.83331,15.62817
36.00000,29.99993,15.70799
36.20000,30.16675,15.76914
36.40000,30.33337,15.53742
36.60000,30.49993,15.81089
36.80000,30.66681,15.72436
37.00000,30.83331,15.73523
37.20000,30.99993,15.84102
37.40000,31.16675,15.79604
37.60000,31.33337,15.86753
37.80000,31.49993,15.86837
38.00000,31.66674,15.99964
38.20000,31.83331,16.01620
38.40000,31.99993,16.03639
38.60000,32.16675,16.00547
38.80000,32.33337,16.07358
39.00000,32.49993,16.18368
39.20000,32.66668,15.98327
39.40000,32.83324,16.25429
39.60000,32.99993,16.05530
39.80000,33.16681,16.17976
40.00000,33.33337,16.16575
40.20000,33.49993,16.19098
40.40000,33.66675,16.31427
40.60000,33.83337,16.30878
40.80000,33.99981,16.34940
41.00000,34.16675,16.37321
41.20000,34.33343,16.22949
41.40000,34.49987,16.31583
41.60000,34.66674,16.40153
41.80000,34.83337,16.48817
42.00000,34.99993,16.49439
42.20000,35.16668,16.44745
42.40000,35.33331,16.69646
42.60000,35.49987,16.63428
42.80000,35.66675,16.58180
43.00000,35.83337,16.68064
43.20000,35.99993,16.69382
43.40000,36.16675,16.69921
43.60000,36.33337,16.69147
43.80000,36.49993,16.97037
44.00000,36.66674,16.83371
44.20000,36.83337,16.70587
44.40000,36.99993,16.76673
44.60000,37.16668,16.96528
44.80000,37.33331,17.03520
45.00000,37.49993,16.93622
45.20000,37.66675,16.92652
45.40000,37.83331,17.04387
45.60000,37.99993,16.91882
45.80000,38.16674,17.12252
46.00000,38.33331,16.97978
46.20000,38.49993,17.20126
46.40000,38.66674,17.13629
46.60000,38.83331,17.14466
46.80000,38.99987,17.13918
47.00000,39.16668,17.00869
47.20000,39.33337,17.39530
47.40000,39.49993,17.27040
47.60000,39.66675,17.20984
47.80000,39.83330,16.96910
48.00000,39.99987,17.17024
48.20000,40.16674,17.21601
48.40000,40.33331,17.22458
48.60000,40.49993,17.35600
48.80000,40.66675,17.29661
49.00000,40.83330,17.47875
49.20000,40.99987,17.33655
49.40000,41.16681,17.70890
49.60000,41.33331,17.39594
49.80000,41.49993,17.51932
50.00000,41.66668,17.49599
50.20000,41.83331,17.66112
50.40000,41.99993,17.57332
50.60000,42.16674,17.49286
50.80000,42.33337,17.77304
51.00000,42.49987,18.01299
51.20000,42.66668,17.67132
51.40000,42.83337,17.86031
51.60000,42.99993,17.61585
51.80000,43.16675,17.76545
52.00000,43.33337,18.02460
52.20000,43.49981,17.75163
52.40000,43.66674,18.01270
52.60000,43.83337,17.91582
52.80000,43.99993,17.78656
53.00000,44.16674,18.07811
53.20000,44.33331,18.07013
53.40000,44.49987,18.09041
53.60000,44.66674,17.93420
53.80000,44.83337,18.14225
54.00000,44.99999,17.96992
54.20000,45.16668,18.29724
54.40000,45.33337,18.21017
54.60000,45.49993,18.27318
54.80000,45.66681,18.21987
55.00000,45.83337,18.32081
55.20000,45.99987,18.43802
55.40000,46.16675,18.10879
55.60000,46.33330,18.37378
55.80000,46.49993,18.34918
56.00000,46.66674,18.57169
56.20000,46.83337,18.54689
56.40000,46.99986,18.42836
56.60000,47.16674,18.58737
56.80000,47.33337,18.44243
57.00000,47.49993,18.49505
57.20000,47.66674,18.35687
57.40000,47.83330,18.75216
57.60000,47.99987,18.61559
57.80000,48.16674,18.70977
58.00000,48.33330,18.56576
58.20000,48.49993,18.75740
58.40000,48.66675,18.67954
58.60000,48.83330,18.72839
58.80000,48.99987,18.74735
59.00000,49.16674,18.75808
59.20000,49.33331,18.78836
59.40000,49.49987,18.93115
59.60000,49.66668,18.99897
59.80000,49.83330,18.94453
60.00000,49.99993,18.94296
60.20000,50.16674,19.01053
60.40000,50.33331,19.02915
60.60000,50.49987,18.95972
60.80000,50.66674,19.09608
61.00000,50.83337,19.21721
61.20000,50.99993,19.05688
61.40000,51.16674,19.00926
61.60000,51.33336,19.10059
61.80000,51.49987,19.33878
62.00000,51.66674,19.27920
62.20000,51.83343,19.41762
62.40000,51.99993,19.09089
62.60000,52.16668,19.39376
62.80000,52.33331,19.29762
63.00000,52.49986,19.36362
63.20000,52.66674,19.51866
63.40000,52.83337,19.50215
63.60000,52.99993,19.48789
63.80000,53.16674,19.64577
64.00000,53.33330,19.43551
64.20000,53.49987,19.66919
64.40000,53.66674,19.55879
64.60001,53.83337,19.84671
64.80000,53.99987,19.77116
65.00000,54.16668,19.52346
65.20000,54.33330,19.80874
65.40000,54.49993,19.81001
65.60001,54.66674,19.66154
65.80000,54.83331,19.98220
66.00000,54.99993,19.97612
66.20001,55.16674,19.63783
66.40000,55.33330,19.75263
66.60001,55.49993,19.87508
66.80000,55.66674,19.87650
67.00000,55.83331,19.95143
67.20001,55.99987,19.94878
67.40000,56.16674,20.16369
67.60001,56.33337,20.06711
67.80000,56.49993,20.31157
68.00000,56.66668,19.88092
68.20001,56.83331,20.32637
68.40000,56.99987,20.34308
68.60001,57.16674,20.24111
68.80000,57.33337,20.20681
69.00000,57.49993,20.43824
69.20001,57.66674,20.60107
69.40000,57.83324,20.35817
69.60001,57.99993,20.42550
69.80000,58.16680,20.38596
70.00000,58.33331,20.51311
70.20001,58.49987,20.64820
70.40000,58.66674,20.62468
70.60001,58.83330,20.32534
70.80000,58.99993,20.53614
71.00000,59.16674,20.66006
71.20001,59.33337,20.65889
71.40000,59.49981,20.59029
71.60001,59.66668,20.73528
71.80000,59.83337,20.47974
72.00000,59.99999,20.92667
72.20001,60.16674,21.04197
72.40000,60.33331,20.95950
72.60001,60.49987,20.89335
72.80000,60.66674,20.96435
73.00000,60.83337,21.13546
73.20001,60.99987,21.14207
73.40000,61.16681,21.09743
73.60001,61.33331,21.07387
73.80000,61.49987,21.09498
74.00000,61.66674,21.10900
74.20001,61.83343,21.24566
74.40000,61.99993,21.53471
74.60001,62.16668,21.20278
74.80000,62.33336,21.26129
75.00000,62.49993,21.43578
75.20001,62.66674,21.33582
75.40000,62.83330,21.38555
75.60001,62.99987,21.35454
75.80000,63.16674,21.60987
76.00000,63.33336,21.33209
76.20001,63.49993,21.28030
76.40000,63.66680,21.64266
76.60001,63.83331,21.55093
76.80000,63.99993,21.51589
77.00000,64.16667,21.75070
77.20001,64.33337,21.59361
77.40000,64.49993,21.74213
77.60001,64.66674,21.76315
77.80000,64.83330,21.52599
78.00000,64.99992,21.61571
78.20001,65.16674,21.99345
78.40000,65.33337,21.83684
78.60001,65.49993,21.94376
78.80000,65.66674,21.79073
79.00000,65.83330,21.95625
79.20001,65.99993,22.07513
79.40000,66.16674,22.17768
79.60001,66.33336,22.00045
79.80000,66.49987,22.05494
80.00000,66.66668,22.15779
80.20001,66.83336,22.37153
80.40000,66.99986,22.33125
80.60001,67.16674,22.41161
80.80000,67.33330,22.39995
81.00001,67.49993,22.42763
81.20001,67.66674,22.38540
81.40000,67.83336,22.28240
81.60001,67.99986,22.47747
81.80000,68.16674,22.50299
82.00001,68.33330,22.47330
82.20001,68.49993,22.60825
82.40000,68.66674,22.67175
82.60001,68.83337,22.67033
82.80000,68.99986,22.79895
83.00001,69.16674,22.58615
83.20001,69.33337,22.81076
83.40000,69.49992,22.75598
83.60001,69.66680,22.55964
83.80000,69.83336,22.70478
84.00001,69.99987,22.67435
84.20001,70.16668,22.68361
84.40000,70.33336,22.95443
84.60001,70.49993,22.84374
84.80000,70.66674,22.88039
85.00001,70.83330,23.10584
85.20001,70.99986,22.94404
85.40000,71.16674,22.91812
85.60001,71.33336,23.28885
85.80000,71.49993,23.11461
86.00001,71.66674,23.22383
86.20001,71.83337,23.10525
86.40000,71.99986,23.22756
86.60001,72.16674,23.36422
86.80000,72.33337,23.31203
87.00001,72.49992,23.36872
87.20001,72.66674,23.50553
87.40000,72.83330,23.39935
87.60001,72.99987,23.44570
87.80000,73.16674,23.47447
88.00001,73.33330,23.41900
88.20001,73.49993,23.52028
88.40000,73.66674,23.57825
88.60001,73.83336,23.72064
88.80000,73.99987,23.84045
89.00001,74.16674,23.79346
89.20001,74.33336,23.80850
89.40000,74.49986,23.81129
89.60001,74.66668,23.89243
89.80000,74.83337,23.91674
90.00001,74.99993,24.03140
90.20001,75.16674,23.90763
90.40000,75.33330,23.79777
90.60001,75.49986,24.15233
90.80000,75.66674,24.26728
91.00001,75.83336,24.24675
91.20001,75.99999,24.10867
91.40000,76.16674,24.17546
91.60001,76.33330,24.13435
91.80000,76.49980,24.11323
92.00001,76.66674,24.48283
92.20001,76.83337,24.43104
92.40000,76.99999,24.37797
92.60001,77.16674,24.30031
92.80000,77.33330,24.27983
93.00001,77.49987,24.43692
93.20001,77.66674,24.35063
93.40000,77.83336,24.55290
93.60001,77.99999,24.61866
93.80000,78.16673,24.69995
94.00001,78.33330,24.45329
94.20001,78.49980,24.73910
94.40000,78.66674,24.69785
94.60001,78.83342,24.68515
94.80000,78.99993,24.95970
95.00001,79.16667,24.75792
95.20001,79.33330,24.76992
95.40000,79.49992,24.92437
95.60001,79.66674,24.90541
95.80000,79.83330,24.95676
96.00001,79.99986,24.95539
96.20001,80.16674,24.98454
96.40000,80.33336,25.07279
96.60001,80.49992,25.07250
96.80000,80.66674,25.05162
97.00001,80.83330,25.25581
97.20001,80.99986,25.18069
97.40000,81.16674,25.09969
97.60001,81.33336,25.36517
97.80000,81.49998,25.32416
98.00001,81.66668,25.24610
98.20001,81.83336,25.44318
98.40000,81.99993,25.46631
98.60001,82.16674,25.47234
98.80000,82.33336,25.44333
99.00001,82.49993,25.52114
99.20001,82.66667,25.58195
99.40000,82.83329,25.50071
99.60001,82.99992,25.59430
99.80000,83.16667,25.60659
100.00001,83.33337,25.78402
100.20001,83.49986,25.65079
100.40000,83.66674,25.71508
100.60001,83.83336,25.82347
100.80000,83.99987,25.79642
101.00001,84.16673,25.86629
101.20001,84.33335,26.07866
101.40000,84.49992,25.93166
101.60001,84.66667,25.72571
101.80000,84.83330,26.11027
102.00001,84.99992,26.08547
102.20001,85.16674,26.07788
102.40000,85.33330,26.05740
102.60001,85.49985,26.00100
102.80000,85.66674,26.10963
103.00001,85.83331,26.21047
103.20001,85.99993,26.19528
103.40000,86.16674,26.30631
103.60001,86.33330,26.38236
103.80000,86.49986,26.28407
104.00001,86.66680,26.38172
104.20001,86.83336,26.24854
104.40000,86.99986,26.28666
104.60001,87.16667,26.40618
104.80000,87.33337,26.44185
105.00001,87.49993,26.84742
105.20001,87.66667,26.73903
105.40000,87.83337,26.66583
105.60001,87.99986,26.85766
105.80000,88.16673,26.74922
106.00001,88.33330,26.70390
106.20001,88.49992,26.89799
106.40000,88.66673,26.78191
106.60001,88.83336,26.97428
106.80000,88.99986,26.86418
107.00001,89.16673,27.08938
107.20001,89.33336,27.16484
107.40000,89.49992,26.98633
107.60001,89.66668,27.10124
107.80000,89.83336,27.11652
108.00001,89.99993,26.97756
108.20001,90.16674,27.16077
108.40000,90.33336,27.30625
108.60001,90.49986,27.18522
108.80000,90.66674,27.28224
109.00001,90.83330,27.33369
109.20001,90.99992,27.31993
109.40000,91.16674,27.43571
109.60001,91.33336,27.26661
109.80000,91.49986,27.25980
110.00001,91.66667,27.56125
110.20001,91.83336,27.42336
110.40000,91.99993,27.66018
110.60001,92.16674,27.35354
110.80000,92.33336,27.78028
111.00001,92.49986,27.59266
111.20001,92.66668,27.71133
111.40000,92.83336,27.71565
111.60001,92.99998,27.74392
111.80000,93.16674,27.79272
112.00001,93.33324,27.89214
112.20001,93.49986,28.01396
112.40000,93.66673,27.84520
112.60001,93.83336,27.96741
112.80000,93.99986,28.03027
113.00001,94.16673,28.03258
113.20001,94.33329,28.02082
113.40001,94.49986,28.21736
113.60001,94.66667,28.14832
113.80000,94.83336,28.58343
114.00001,94.99992,28.40277
114.20001,95.16673,28.37813
114.40001,95.33330,28.10892
114.60001,95.49987,28.47858
114.80000,95.66680,28.36009
115.00001,95.83335,28.48646
115.20001,95.99986,28.51968
115.40001,96.16673,28.55399
115.60001,96.33336,28.50533
115.80000,96.49992,28.54394
116.00001,96.66674,28.67791
116.20001,96.83330,28.62920
116.40001,96.99985,28.66962
116.60001,97.16667,28.68550
116.80000,97.33336,28.74949
117.00001,97.49993,28.71524
117.20001,97.66674,28.76581
117.40001,97.83329,28.63846
117.60001,97.99986,29.02453
117.80000,98.16674,28.98798
118.00001,98.33336,28.92207
118.20001,98.49992,29.17021
118.40001,98.66673,29.05501
118.60001,98.83329,28.93917
118.80000,98.99992,29.23945
119.00001,99.16673,29.08348
119.20001,99.33342,29.30702
119.40001,99.49992,29.07755
119.60001,99.66668,29.01076
119.80000,99.83336,29.44544
120.00001,99.99992,29.51776
120.20001,100.16673,29.40996
120.40001,100.33330,29.33254
120.60001,100.49992,29.31152
120.80000,100.66668,29.43476
121.00001,100.83336,29.54687
121.20001,100.99986,29.58597
121.40001,101.16674,29.62767
121.60001,101.33336,29.58832
121.80000,101.49992,29.54971
122.00001,101.66674,29.76409
122.20001,101.83336,29.83053
122.40001,101.99992,29.68877
122.60001,102.16674,29.80760
122.80000,102.33330,29.77016
123.00001,102.49992,30.01109
123.20001,102.66673,29.98321
123.40001,102.83330,30.22493
123.60001,102.99992,29.91290
123.80000,103.16667,30.08195
124.00001,103.33329,30.10841
124.20001,103.49993,30.26016
124.40001,103.66674,30.08994
124.60001,103.83330,30.19769
124.80000,103.99986,30.31529
125.00001,104.16668,30.46126
125.20001,104.33336,30.21827
125.40001,104.49992,30.27452
125.60001,104.66673,30.57964
125.80000,104.83336,30.37712
126.00001,104.99992,30.18245
126.20001,105.16667,30.52540
126.40001,105.33337,30.46640
126.60001,105.49986,30.61492
126.80000,105.66680,30.75579
127.00001,105.83330,30.63682
127.20001,105.99992,30.55465
127.40001,106.16673,30.88462
127.60001,106.33335,30.74947
127.80000,106.49987,30.58292
128.00000,106.66673,30.76442
128.20002,106.83335,31.03456
128.40001,106.99986,30.94454
128.60001,107.16673,30.92876
128.80000,107.33336,30.96786
129.00000,107.49992,31.02240
129.20002,107.66674,30.98952
129.40001,107.83330,31.22281
129.60001,107.99993,31.01383
129.80000,108.16674,31.20605
130.00000,108.33330,31.08150
130.20002,108.49993,31.20728
130.40001,108.66667,31.44370
130.60001,108.83336,31.44586
130.80000,108.99986,31.50662
131.00000,109.16674,31.47928
131.20002,109.33336,31.48251
131.40002,109.49986,31.56385
131.60000,109.66667,31.65190
131.80000,109.83337,31.48814
132.00000,109.99999,31.76357
132.20002,110.16673,31.42641
132.40002,110.33324,31.56179
132.60000,110.49992,32.09084
132.80000,110.66680,31.82007
133.00000,110.83342,31.75892
133.20002,110.99992,31.80811
133.40002,111.16673,31.96212
133.60000,111.33330,31.76009
133.80000,111.49986,31.94487
134.00000,111.66673,32.00353
134.20002,111.83330,31.86295
134.40002,111.99992,31.93336
134.60000,112.16667,32.02852
134.80000,112.33330,32.21094
135.00000,112.49992,32.05728
135.20002,112.66674,32.01592
135.40002,112.83336,32.10838
135.60000,112.99992,32.14768
135.80000,113.16674,32.34246
136.00000,113.33330,32.17194
136.20002,113.49992,32.32163
136.40002,113.66680,32.45614
136.60000,113.83330,32.39298
136.80000,113.99986,32.50225
137.00000,114.16674,32.53052
137.20002,114.33336,32.55914
137.40002,114.49993,32.69673
137.60000,114.66667,32.50538
137.80000,114.83336,32.70770
138.00000,114.99993,32.71177
138.20002,115.16673,32.74754
138.40002,115.33336,32.86274
138.60000,115.49992,32.93227
138.80000,115.66667,33.06236
139.00000,115.83329,32.88895
139.20002,115.99992,32.84113
139.40002,116.16673,32.90101
139.60000,116.33337,33.06251
139.80000,116.49992,33.04595
140.00000,116.66667,33.17825
140.20002,116.83336,33.23685
140.40002,116.99999,33.19148
140.60000,117.16673,33.26552
140.80000,117.33330,33.27919
141.00000,117.49987,33.53467
141.20002,117.66667,33.27174
141.40002,117.83335,33.27733
141.60000,117.99992,33.29090
141.80000,118.16673,33.45676
142.00000,118.33336,33.41237
142.20002,118.49992,33.45206
142.40002,118.66674,33.57172
142.60000,118.83330,33.54183
142.80000,118.99993,33.54967
143.00000,119.16674,33.66722
143.20002,119.33336,33.72670
143.40002,119.49986,33.70162
143.60000,119.66674,33.79359
143.80000,119.83336,33.70534
144.00000,119.99992,33.99620
144.20002,120.16667,33.81069
144.40002,120.33329,33.90384
144.60000,120.49992,33.77982
144.80000,120.66673,34.13355
145.00000,120.83329,34.06417
145.20002,120.99986,34.36395
145.40002,121.16673,34.07691
145.60000,121.33330,34.35223
145.80000,121.49992,34.15736
146.00000,121.66673,34.11905
146.20002,121.83330,34.20661
146.40002,121.99986,34.26918
146.60000,122.16668,34.12537
146.80000,122.33336,34.34430
147.00000,122.49992,34.50379
147.20002,122.66673,34.46302
147.40002,122.83336,34.31583
147.60000,122.99986,34.65324
147.80000,123.16674,34.64021
148.00000,123.33336,34.52506
148.20002,123.49992,34.79382
148.40002,123.66674,34.76060
148.60000,123.83330,34.72214
148.80000,123.99980,34.77613
149.00000,124.16674,34.74595
149.20002,124.33336,34.85199
149.40002,124.49986,35.00021
149.60000,124.66667,35.04901
149.80000,124.83330,34.93073
150.00000,124.99992,34.82499
150.20002,125.16673,35.10914
150.40002,125.33336,34.98198
150.60000,125.49992,35.04113
150.80000,125.66673,35.09012
151.00000,125.83329,35.27422
151.20002,125.99997,35.23418
151.40002,126.16667,35.16906
151.60000,126.33336,35.19959
151.80000,126.49992,35.36898
152.00000,126.66672,35.33228
152.20002,126.83335,35.25775
152.40002,126.99991,35.42577
152.60000,127.16673,35.61354
152.80000,127.33328,35.57713
153.00000,127.49991,35.62804
153.20002,127.66673,35.54249
153.40002,127.83336,35.46737
153.60000,127.99992,35.38961
153.80000,128.16667,35.71183
154.00000,128.33329,35.89960
154.20002,128.49986,35.55744
154.40002,128.66673,35.77029
154.60000,128.83335,35.67342
154.80000,128.99992,35.69184
155.00000,129.16672,35.89015
155.20002,129.33329,35.92621
155.40002,129.49991,35.91602
155.60000,129.66673,35.93013
155.80000,129.83336,36.15126
156.00000,129.99984,36.16543
156.20002,130.16673,35.94899
156.40002,130.33330,36.01544
156.60000,130.49997,36.16513
156.80000,130.66674,36.35035
157.00000,130.83323,36.31007
157.20002,130.99985,36.26519
157.40002,131.16673,36.35540
157.60000,131.33335,36.35398
157.80000,131.49998,36.39558
158.00000,131.66673,36.32120
158.20002,131.83328,36.48888
158.40002,131.99992,36.59491
158.60000,132.16667,36.54111
158.80000,132.33336,36.45692
159.00000,132.49986,36.70217
159.20002,132.66672,36.68203
159.40002,132.83329,36.71765
159.60000,132.99991,36.62597
159.80000,133.16673,36.66601
160.00000,133.33330,36.86343
160.20002,133.49985,36.76401
160.40002,133.66672,36.88278
160.60000,133.83329,37.14983
160.80000,133.99998,36.84986
161.00002,134.16673,36.96265
161.20002,134.33336,36.80277
161.40002,134.49985,36.93967
161.60000,134.66673,37.18737
161.80000,134.83335,37.03277
162.00002,134.99998,37.37523
162.20002,135.16674,37.07619
162.40002,135.33329,37.07682
162.60000,135.49991,37.09172
162.80000,135.66673,37.16017
163.00002,135.83330,37.25504
163.20002,135.99992,37.21574
163.40002,136.16673,37.35549
163.60000,136.33328,37.31535
163.80000,136.49992,37.48470
164.00002,136.66674,37.39875
164.20002,136.83336,37.55634
164.40002,136.99993,37.67506
164.60000,137.16673,37.58152
164.80000,137.33335,37.54252
165.00002,137.49997,37.71769
165.20002,137.66673,37.70108
165.40002,137.83336,37.81996
165.60000,137.99992,37.67648
165.80000,138.16667,37.66247
166.00002,138.33329,37.69123
166.20002,138.49986,37.91536
166.40002,138.66673,37.78659
166.60000,138.83329,37.86464
166.80000,138.99985,37.81236
167.00002,139.16667,37.86513
167.20002,139.33335,37.90982
167.40002,139.49992,38.05271
167.60000,139.66672,38.05819
167.80000,139.83329,37.95299
168.00002,139.99991,38.04516
168.20002,140.16673,38.15325
168.40002,140.33335,37.88566
168.60000,140.49992,37.78845
168.80000,140.66673,37.74146
169.00002,140.83329,37.79526
169.20002,140.99992,37.63826
169.40002,141.16674,37.55247
169.60000,141.33336,37.23936
169.80000,141.49993,0.43072
170.00002,141.66667,0.40029
170.20002,141.83329,0.51304
170.40002,141.99986,0.50593
170.50402,142.08667,0.33865