File: V_7/FR/RDSO FR Tensile 50.is_tens_RawData/Specimen_RawData_8.csv
Time,Extension,Load
(sec),(mm),(N)
0.00000,0.00000,-0.07453
0.20000,0.16469,0.19855
0.40000,0.33306,0.51416
0.60000,0.49994,0.74108
0.80000,0.66669,1.28272
1.00000,0.83337,1.61587
1.20000,0.99994,2.16276
1.40000,1.16681,2.46234
1.60000,1.33331,2.85718
1.80000,1.49987,3.28863
2.00000,1.66662,3.41348
2.20000,1.83344,3.76152
2.40000,1.99994,3.72786
2.60000,2.16662,4.14740
2.80000,2.33331,4.52254
3.00000,2.49994,4.66538
3.20000,2.66675,4.97922
3.40000,2.83337,5.16777
3.60000,2.99994,5.36818
3.80000,3.16675,5.50303
4.00000,3.33337,5.87406
4.20000,3.49994,6.07799
4.40000,3.66681,6.04016
4.60000,3.83337,6.26924
4.80000,3.99987,6.48087
5.00000,4.16675,6.58377
5.20000,4.33344,6.89962
5.40000,4.49987,6.90594
5.60000,4.66669,7.00149
5.80000,4.83325,7.35973
6.00000,4.99987,7.54843
6.20000,5.16675,7.60752
6.40000,5.33337,7.62624
6.60000,5.50000,7.77540
6.80000,5.66675,7.83743
7.00000,5.83331,8.00663
7.20000,5.99994,8.05808
7.40000,6.16675,8.24829
7.60000,6.33337,8.51569
7.80000,6.49994,8.54660
8.00000,6.66675,8.74006
8.20000,6.83331,8.92993
8.40000,6.99994,8.87196
8.60000,7.16675,8.97477
8.80000,7.33337,9.01671
9.00000,7.49994,9.42321
9.20000,7.66669,9.19791
9.40000,7.83331,9.50362
9.60000,7.99987,9.55105
9.80000,8.16681,9.73397
10.00000,8.33331,9.77425
10.20000,8.49981,9.86073
10.40000,8.66669,9.89131
10.60000,8.83331,10.24269
10.80000,8.99987,10.15032
11.00000,9.16675,10.12509
11.20000,9.33337,10.34740
11.40000,9.49987,10.41810
11.60000,9.66675,10.33255
11.80000,9.83337,10.68907
12.00000,10.00000,10.66947
12.20000,10.16675,10.74606
12.40000,10.33337,10.96083
12.60000,10.49994,11.07127
12.80000,10.66669,11.07260
13.00000,10.83331,10.99013
13.20000,10.99994,11.27418
13.40000,11.16675,11.48449
13.60000,11.33331,11.60684
13.80000,11.49987,11.57651
14.00000,11.66675,11.67181
14.20000,11.83337,11.59783
14.40000,11.99987,11.70803
14.60000,12.16669,11.84919
14.80000,12.33337,11.85801
15.00000,12.49994,11.82249
15.20000,12.66675,11.89369
15.40000,12.83337,11.98213
15.60000,12.99994,11.92985
15.80000,13.16675,12.09194
16.00000,13.33331,12.13085
16.20000,13.49994,12.32998
16.40000,13.66675,12.29166
16.60000,13.83331,12.12595
16.80000,13.99987,12.22625
17.00000,14.16669,12.44087
17.20000,14.33337,12.54161
17.40000,14.50000,12.54333
17.60000,14.66669,12.66215
17.80000,14.83331,12.72825
18.00000,14.99994,12.75015
18.20000,15.16669,12.78862
18.40000,15.33331,12.85712
18.60000,15.50000,12.77510
18.80000,15.66675,12.69606
19.00000,15.83331,12.79161
19.20000,15.99994,12.81096
19.40000,16.16675,12.72948
19.60000,16.33337,12.96252
19.80000,16.49987,12.89970
20.00000,16.66681,12.89838
20.20000,16.83337,12.92254
20.40000,16.99987,12.95733
20.60000,17.16669,13.03102
20.80000,17.33337,13.17234
21.00000,17.49987,12.97629
21.20000,17.66675,13.17395
21.40000,17.83337,13.23903
21.60000,17.99993,13.12736
21.80000,18.16675,13.22398
22.00000,18.33331,13.28009
22.20000,18.49987,13.18420
22.40000,18.66681,13.26230
22.60000,18.83337,13.16097
22.80000,18.99993,13.49554
23.00000,19.16662,13.48290
23.20000,19.33331,13.54650
23.40000,19.49994,13.53557
23.60000,19.66675,13.53116
23.80000,19.83337,13.41557
24.00000,19.99993,13.76308
24.20000,20.16675,13.55757
24.40000,20.33331,13.32605
24.60000,20.49993,13.50059
24.80000,20.66675,13.62465
25.00000,20.83337,13.60182
25.20000,20.99987,13.55566
25.40000,21.16675,13.95560
25.60000,21.33331,13.87691
25.80000,21.49994,13.80880
26.00000,21.66675,13.76328
26.20000,21.83337,13.82737
26.40000,21.99987,13.94129
26.60000,22.16668,13.87696
26.80000,22.33331,13.76107
27.00000,22.49993,13.83540
27.20000,22.66675,13.76112
27.40000,22.83325,13.92012
27.60000,22.99994,14.05585
27.80000,23.16675,13.98289
28.00000,23.33337,14.01719
28.20000,23.49993,13.90645
28.40000,23.66675,14.11622
28.60000,23.83331,14.07815
28.80000,23.99993,14.09059
29.00000,24.16675,14.15914
29.20000,24.33337,14.26322
29.40000,24.49993,14.10706
29.60000,24.66668,14.05012
29.80000,24.83331,14.24685
30.00000,24.99999,14.26944
30.20000,25.16675,14.15292
30.40000,25.33331,14.35936
30.60000,25.49981,14.29532
30.80000,25.66668,14.11794
31.00000,25.83344,14.44339
31.20000,25.99993,14.46143
31.40000,26.16675,14.53296
31.60000,26.33331,14.37161
31.80000,26.49987,14.56359
32.00000,26.66668,14.27581
32.20000,26.83337,14.53610
32.40000,26.99994,14.36534
32.60000,27.16674,14.57256
32.80000,27.33337,14.59162
33.00000,27.49993,14.61587
33.20000,27.66668,14.45907
33.40000,27.83337,14.63469
33.60000,28.00000,14.72661
33.80000,28.16675,14.70716
34.00000,28.33331,14.67678
34.20000,28.49987,14.75753
34.40000,28.66675,14.72642
34.60000,28.83331,14.67634
34.80000,28.99987,14.82187
35.00000,29.16669,14.83456
35.20000,29.33337,14.80467
35.40000,29.49993,15.04849
35.60000,29.66675,14.78615
35.80000,29.83337,14.87547
36.00000,29.99993,14.91169
36.20000,30.16668,14.79502
36.40000,30.33337,14.92653
36.60000,30.49999,15.04545
36.80000,30.66675,15.15076
37.00000,30.83331,14.98866
37.20000,30.99993,14.92972
37.40000,31.16681,15.04795
37.60000,31.33337,15.16697
37.80000,31.49993,15.00150
38.00000,31.66668,15.00361
38.20000,31.83331,15.20686
38.40000,31.99993,15.10808
38.60000,32.16675,15.19334
38.80000,32.33337,15.19603
39.00000,32.49993,15.23459
39.20000,32.66668,15.11440
39.40000,32.83331,15.26002
39.60000,33.00000,15.26963
39.80000,33.16674,15.33250
40.00000,33.33331,15.28732
40.20000,33.49993,15.31608
40.40000,33.66675,15.53349
40.60000,33.83337,15.55045
40.80000,33.99981,15.46210
41.00000,34.16675,15.43285
41.20000,34.33343,15.46259
41.40000,34.49987,15.30667
41.60000,34.66668,15.35175
41.80000,34.83337,15.49410
42.00000,34.99993,15.40320
42.20000,35.16668,15.55192
42.40000,35.33331,15.58411
42.60000,35.49987,15.70597
42.80000,35.66681,15.60342
43.00000,35.83337,15.59303
43.20000,35.99993,15.74948
43.40000,36.16675,15.68559
43.60000,36.33331,15.81784
43.80000,36.49993,15.80912
44.00000,36.66674,15.93593
44.20000,36.83337,15.84895
44.40000,36.99993,15.68255
44.60000,37.16668,15.92774
44.80000,37.33331,16.01962
45.00000,37.49993,15.85577
45.20000,37.66675,15.71925
45.40000,37.83331,16.05039
45.60000,37.99993,15.88178
45.80000,38.16674,16.19308
46.00000,38.33331,16.00732
46.20000,38.49993,16.04549
46.40000,38.66674,16.08724
46.60000,38.83331,16.20611
46.80000,38.99987,16.18642
47.00000,39.16668,16.28574
47.20000,39.33343,15.94000
47.40000,39.49993,16.22566
47.60000,39.66675,16.06480
47.80000,39.83330,16.36041
48.00000,39.99987,16.23199
48.20000,40.16681,16.28446
48.40000,40.33331,16.32592
48.60000,40.49999,16.22424
48.80000,40.66675,16.33768
49.00000,40.83330,16.40912
49.20000,40.99987,16.42382
49.40000,41.16681,16.24840
49.60000,41.33331,16.43764
49.80000,41.49993,16.57797
50.00000,41.66674,16.50188
50.20000,41.83337,16.37511
50.40000,41.99993,16.52750
50.60000,42.16674,16.42137
50.80000,42.33337,16.64339
51.00000,42.49987,16.41838
51.20000,42.66668,16.35022
51.40000,42.83337,16.53417
51.60000,42.99993,16.71169
51.80000,43.16675,16.65544
52.00000,43.33337,16.62771
52.20000,43.49981,16.70307
52.40000,43.66674,16.76898
52.60000,43.83331,16.77525
52.80000,43.99993,16.72674
53.00000,44.16674,16.87227
53.20000,44.33337,16.63530
53.40000,44.49987,16.81190
53.60000,44.66674,17.04631
53.80000,44.83337,16.84032
54.00000,44.99999,16.86497
54.20000,45.16668,16.96341
54.40000,45.33330,16.91220
54.60000,45.49993,17.17205
54.80000,45.66681,16.97164
55.00000,45.83337,17.09164
55.20000,45.99987,17.15504
55.40000,46.16668,17.02417
55.60000,46.33330,16.91936
55.80000,46.49993,17.03225
56.00000,46.66674,17.08733
56.20000,46.83337,17.05254
56.40000,46.99986,17.26280
56.60000,47.16674,17.28872
56.80000,47.33331,17.29023
57.00000,47.49993,17.34247
57.20000,47.66674,17.29327
57.40000,47.83330,17.36163
57.60000,47.99987,17.40426
57.80000,48.16674,17.43679
58.00000,48.33330,17.19003
58.20000,48.49993,17.38564
58.40000,48.66675,17.47158
58.60000,48.83330,17.41548
58.80000,48.99987,17.62554
59.00000,49.16674,17.34624
59.20000,49.33331,17.59227
59.40000,49.49987,17.65136
59.60000,49.66668,17.67283
59.80000,49.83330,17.51480
60.00000,49.99993,17.69174
60.20000,50.16674,17.78994
60.40000,50.33331,17.60315
60.60000,50.49993,17.75701
60.80000,50.66680,17.75818
61.00000,50.83337,17.83717
61.20000,50.99987,17.69860
61.40000,51.16674,17.85040
61.60000,51.33336,18.06571
61.80000,51.49987,17.84854
62.00000,51.66674,18.01935
62.20000,51.83337,17.96648
62.40000,51.99993,17.97001
62.60000,52.16668,17.97574
62.80000,52.33331,17.92640
63.00000,52.49986,18.08947
63.20000,52.66674,18.09114
63.40000,52.83337,18.14450
63.60000,52.99993,18.02371
63.80000,53.16668,18.13274
64.00000,53.33330,18.25230
64.20000,53.49993,18.13171
64.40000,53.66674,18.30919
64.60001,53.83337,18.23755
64.80000,53.99987,18.51268
65.00000,54.16675,18.35020
65.20000,54.33330,18.28307
65.40000,54.49993,18.45805
65.60001,54.66668,18.28077
65.80000,54.83337,18.36240
66.00000,54.99993,18.53302
66.20001,55.16668,18.54493
66.40000,55.33330,18.50592
66.60001,55.49993,18.66615
66.80000,55.66674,18.52685
67.00000,55.83324,18.40047
67.20001,55.99987,18.88121
67.40000,56.16674,18.67340
67.60001,56.33337,18.53282
67.80000,56.49993,18.72779
68.00000,56.66674,18.74083
68.20001,56.83336,18.83329
68.40000,56.99987,18.61108
68.60001,57.16674,18.69580
68.80000,57.33337,18.70819
69.00000,57.49993,18.84397
69.20001,57.66674,18.93036
69.40000,57.83331,18.79683
69.60001,57.99993,18.90806
69.80000,58.16680,18.64449
70.00000,58.33331,18.81320
70.20001,58.49987,18.95177
70.40000,58.66674,18.84157
70.60001,58.83330,19.18726
70.80000,58.99993,18.93550
71.00000,59.16674,18.97975
71.20001,59.33337,18.98426
71.40000,59.49981,19.16227
71.60001,59.66668,19.27174
71.80000,59.83337,19.30780
72.00000,59.99999,18.96642
72.20001,60.16674,19.19863
72.40000,60.33331,19.18344
72.60001,60.49993,19.26851
72.80000,60.66674,19.30452
73.00000,60.83337,19.19849
73.20001,60.99987,19.24856
73.40000,61.16681,19.60999
73.60001,61.33331,19.27130
73.80000,61.49987,19.47646
74.00000,61.66674,19.45167
74.20001,61.83337,19.74699
74.40000,61.99993,19.45133
74.60001,62.16668,19.54393
74.80000,62.33331,19.59338
75.00000,62.49987,19.67957
75.20001,62.66674,19.66653
75.40000,62.83330,19.67315
75.60001,62.99987,19.64478
75.80000,63.16680,19.60660
76.00000,63.33330,19.61645
76.20001,63.49993,19.73675
76.40000,63.66680,20.05887
76.60001,63.83331,20.01752
76.80000,63.99986,19.91800
77.00000,64.16667,19.89708
77.20001,64.33337,19.97925
77.40000,64.49993,19.88223
77.60001,64.66674,19.94779
77.80000,64.83330,20.09435
78.00000,64.99992,20.02796
78.20001,65.16674,19.82245
78.40000,65.33337,20.12253
78.60001,65.49993,20.05417
78.80000,65.66674,20.01914
79.00000,65.83330,20.02923
79.20001,65.99993,20.25154
79.40000,66.16674,20.22244
79.60001,66.33336,20.46930
79.80000,66.49987,20.55113
80.00000,66.66668,20.42265
80.20001,66.83336,20.28172
80.40000,66.99986,20.26585
80.60001,67.16674,20.39197
80.80000,67.33330,20.71283
81.00001,67.49993,20.56313
81.20001,67.66674,20.64947
81.40000,67.83336,20.64104
81.60001,67.99986,20.76060
81.80000,68.16674,20.45999
82.00001,68.33330,20.67451
82.20001,68.49993,20.81509
82.40000,68.66674,20.60243
82.60001,68.83337,20.57440
82.80000,68.99992,20.79554
83.00001,69.16680,20.76084
83.20001,69.33337,20.87683
83.40000,69.49992,20.79118
83.60001,69.66668,21.04852
83.80000,69.83336,20.89413
84.00001,69.99987,20.83013
84.20001,70.16668,21.00942
84.40000,70.33330,20.95611
84.60001,70.49993,21.12055
84.80000,70.66674,21.01168
85.00001,70.83330,21.15314
85.20001,70.99993,21.17940
85.40000,71.16674,21.04701
85.60001,71.33336,21.14667
85.80000,71.49993,21.25403
86.00001,71.66674,21.08116
86.20001,71.83337,21.18273
86.40000,71.99986,21.21777
86.60001,72.16674,21.33312
86.80000,72.33343,21.44640
87.00001,72.49992,21.27476
87.20001,72.66674,21.51853
87.40000,72.83330,21.39530
87.60001,72.99987,21.44121
87.80000,73.16674,21.56469
88.00001,73.33330,21.61119
88.20001,73.49993,21.61075
88.40000,73.66674,21.50579
88.60001,73.83336,21.76647
88.80000,73.99987,21.65245
89.00001,74.16674,21.84325
89.20001,74.33336,21.84428
89.40000,74.49993,21.81567
89.60001,74.66668,21.77529
89.80000,74.83337,21.76250
90.00001,74.99993,21.78994
90.20001,75.16674,21.85148
90.40000,75.33330,22.01995
90.60001,75.49986,21.94262
90.80000,75.66674,21.97977
91.00001,75.83336,22.06517
91.20001,75.99999,22.10839
91.40000,76.16674,22.15014
91.60001,76.33330,22.08306
91.80000,76.49980,22.09217
92.00001,76.66674,22.13078
92.20001,76.83337,22.20536
92.40000,76.99993,22.33590
92.60001,77.16674,22.15029
92.80000,77.33330,22.22349
93.00001,77.49987,22.28695
93.20001,77.66674,22.33541
93.40000,77.83336,22.30292
93.60001,77.99993,22.49250
93.80000,78.16673,22.44468
94.00001,78.33336,22.53248
94.20001,78.49980,22.45408
94.40000,78.66680,22.61490
94.60001,78.83336,22.53910
94.80000,78.99993,22.68198
95.00001,79.16674,22.54385
95.20001,79.33336,22.58041
95.40000,79.49992,22.64577
95.60001,79.66674,22.68541
95.80000,79.83330,22.83574
96.00001,79.99986,22.81570
96.20001,80.16674,22.91512
96.40000,80.33330,22.77209
96.60001,80.49992,22.89072
96.80000,80.66674,22.97162
97.00001,80.83330,22.86524
97.20001,80.99986,23.08662
97.40000,81.16674,22.96270
97.60001,81.33336,22.90400
97.80000,81.49993,23.02567
98.00001,81.66668,23.06776
98.20001,81.83330,23.13474
98.40000,81.99986,23.09735
98.60001,82.16674,23.28517
98.80000,82.33336,23.32971
99.00001,82.49986,23.20084
99.20001,82.66667,23.17737
99.40000,82.83329,23.24715
99.60001,82.99992,23.22328
99.80000,83.16674,23.20177
100.00001,83.33330,23.49063
100.20001,83.49986,23.19565
100.40000,83.66674,23.36284
100.60001,83.83336,23.48592
100.80000,83.99987,23.41242
101.00001,84.16673,23.72960
101.20001,84.33335,23.61543
101.40000,84.49992,23.59441
101.60001,84.66673,23.68364
101.80000,84.83324,23.73548
102.00001,84.99992,23.60881
102.20001,85.16674,23.59750
102.40000,85.33330,23.75939
102.60001,85.49985,23.83436
102.80000,85.66674,23.89630
103.00001,85.83331,23.99528
103.20001,85.99993,23.85425
103.40000,86.16674,24.04129
103.60001,86.33330,24.04442
103.80000,86.49986,23.94897
104.00001,86.66680,23.94446
104.20001,86.83336,24.01179
104.40000,86.99981,24.04143
104.60001,87.16667,24.26188
104.80000,87.33329,24.16428
105.00001,87.49993,24.18706
105.20001,87.66674,24.34367
105.40000,87.83337,24.39115
105.60001,87.99986,24.21298
105.80000,88.16673,24.34612
106.00001,88.33330,24.47538
106.20001,88.49992,24.46288
106.40000,88.66673,24.45431
106.60001,88.83330,24.31049
106.80000,88.99986,24.27644
107.00001,89.16673,24.51404
107.20001,89.33336,24.65290
107.40000,89.49992,24.81602
107.60001,89.66668,24.66721
107.80000,89.83336,24.57842
108.00001,89.99993,24.93406
108.20001,90.16674,24.69347
108.40000,90.33336,24.70685
108.60001,90.49986,24.81377
108.80000,90.66674,24.77854
109.00001,90.83330,24.91015
109.20001,90.99992,24.75448
109.40000,91.16674,24.75727
109.60001,91.33336,25.05279
109.80000,91.49986,24.94764
110.00001,91.66667,25.04716
110.20001,91.83336,25.11904
110.40000,91.99993,25.12350
110.60001,92.16674,25.02442
110.80000,92.33336,25.08533
111.00001,92.49986,25.20694
111.20001,92.66668,25.23781
111.40000,92.83330,25.44401
111.60001,92.99998,25.38545
111.80000,93.16674,25.40657
112.00001,93.33324,25.43352
112.20001,93.49986,25.36511
112.40000,93.66673,25.40456
112.60001,93.83336,25.53402
112.80000,93.99986,25.48306
113.00001,94.16673,25.47238
113.20001,94.33329,25.48512
113.40001,94.49986,25.61144
113.60001,94.66667,25.53936
113.80000,94.83336,25.73100
114.00001,94.99992,25.89015
114.20001,95.16673,25.64059
114.40001,95.33330,25.74923
114.60001,95.49987,25.82586
114.80000,95.66673,26.02137
115.00001,95.83335,25.82767
115.20001,95.99992,25.60546
115.40001,96.16673,25.87138
115.60001,96.33336,25.94370
115.80000,96.49992,25.69567
116.00001,96.66674,25.98428
116.20001,96.83330,25.89319
116.40001,96.99985,26.05111
116.60001,97.16667,26.07625
116.80000,97.33336,25.99045
117.00001,97.49993,26.15715
117.20001,97.66674,26.18773
117.40001,97.83329,26.27788
117.60001,97.99986,26.26563
117.80000,98.16674,26.34080
118.00001,98.33336,26.22893
118.20001,98.49992,26.60129
118.40001,98.66673,26.52048
118.60001,98.83329,26.50554
118.80000,98.99992,26.56184
119.00001,99.16673,26.57090
119.20001,99.33342,26.33830
119.40001,99.49992,26.56596
119.60001,99.66668,26.70394
119.80000,99.83336,26.83570
120.00001,99.99992,26.73290
120.20001,100.16673,26.56184
120.40001,100.33336,26.72192
120.60001,100.49992,26.69517
120.80000,100.66668,26.77896
121.00001,100.83336,26.91385
121.20001,100.99986,26.97383
121.40001,101.16674,27.13896
121.60001,101.33336,26.95452
121.80000,101.49992,26.94683
122.00001,101.66674,27.05336
122.20001,101.83330,27.22392
122.40001,101.99992,27.16013
122.60001,102.16674,27.18340
122.80000,102.33330,27.18017
123.00001,102.49986,26.98265
123.20001,102.66673,27.17889
123.40001,102.83330,27.26528
123.60001,102.99992,27.29762
123.80000,103.16667,27.16993
124.00001,103.33324,27.20129
124.20001,103.49993,27.40949
124.40001,103.66674,27.32981
124.60001,103.83330,27.44222
124.80000,103.99986,27.62420
125.00001,104.16668,27.52596
125.20001,104.33336,27.43751
125.40001,104.49998,27.68119
125.60001,104.66673,27.71583
125.80000,104.83329,27.67575
126.00001,104.99992,27.70892
126.20001,105.16667,27.69780
126.40001,105.33337,27.77856
126.60001,105.49992,27.49460
126.80000,105.66680,27.73705
127.00001,105.83330,27.83848
127.20001,105.99992,27.86318
127.40001,106.16673,28.09617
127.60001,106.33335,27.96475
127.80000,106.49992,27.95148
128.00000,106.66673,28.07530
128.20002,106.83335,28.24577
128.40001,106.99986,28.05614
128.60001,107.16673,28.00003
128.80000,107.33336,28.03821
129.00000,107.49992,28.13767
129.20002,107.66674,28.23376
129.40001,107.83330,28.05261
129.60001,107.99993,28.31295
129.80000,108.16674,28.12871
130.00000,108.33336,28.30437
130.20002,108.49993,28.25723
130.40001,108.66667,28.51184
130.60001,108.83336,28.42427
130.80000,108.99992,28.51037
131.00000,109.16674,28.51037
131.20002,109.33336,28.54393
131.40002,109.49986,28.55515
131.60000,109.66667,28.84322
131.80000,109.83337,28.71788
132.00000,109.99999,28.67706
132.20002,110.16673,28.72455
132.40002,110.33324,28.80951
132.60000,110.49986,28.79437
132.80000,110.66673,28.60905
133.00000,110.83336,28.84249
133.20002,110.99992,28.93372
133.40002,111.16673,28.91192
133.60000,111.33330,29.11836
133.80000,111.49986,28.98777
134.00000,111.66680,28.89242
134.20002,111.83330,29.08685
134.40002,111.99992,28.79795
134.60000,112.16667,28.93926
134.80000,112.33330,29.25644
135.00000,112.49992,29.00130
135.20002,112.66674,29.21543
135.40002,112.83336,29.38051
135.60000,112.99992,29.18906
135.80000,113.16674,29.42294
136.00000,113.33330,29.40613
136.20002,113.49992,29.35909
136.40002,113.66680,29.21425
136.60000,113.83330,29.33572
136.80000,113.99986,29.60071
137.00000,114.16667,29.46390
137.20002,114.33336,29.63006
137.40002,114.49993,29.38937
137.60000,114.66667,29.67769
137.80000,114.83336,29.35865
138.00000,114.99986,29.69881
138.20002,115.16673,29.62889
138.40002,115.33330,29.68132
138.60000,115.49992,29.57484
138.80000,115.66673,29.64398
139.00000,115.83329,29.54559
139.20002,115.99992,29.80323
139.40002,116.16673,29.74771
139.60000,116.33337,29.81518
139.80000,116.49992,29.92093
140.00000,116.66667,29.88212
140.20002,116.83336,29.81979
140.40002,116.99992,29.93812
140.60000,117.16673,30.15970
140.80000,117.33335,30.13172
141.00000,117.49987,30.00232
141.20002,117.66667,29.96826
141.40002,117.83335,30.11903
141.60000,117.99992,30.08875
141.80000,118.16673,30.24761
142.00000,118.33330,30.02789
142.20002,118.49992,30.40490
142.40002,118.66674,30.39319
142.60000,118.83330,30.38466
142.80000,118.99985,30.40318
143.00000,119.16674,30.50393
143.20002,119.33336,30.45287
143.40002,119.49986,30.26265
143.60000,119.66674,30.57821
143.80000,119.83336,30.50432
144.00000,119.99992,30.63250
144.20002,120.16667,30.63368
144.40002,120.33329,30.54660
144.60000,120.49992,30.68777
144.80000,120.66673,30.56763
145.00000,120.83329,30.79690
145.20002,120.99986,30.77700
145.40002,121.16673,30.67067
145.60000,121.33330,30.83105
145.80000,121.49992,30.95943
146.00000,121.66673,30.92268
146.20002,121.83330,30.87378
146.40002,121.99992,30.96109
146.60000,122.16668,31.04969
146.80000,122.33330,30.87789
147.00000,122.49999,31.13171
147.20002,122.66673,31.19943
147.40002,122.83330,31.02832
147.60000,122.99986,31.17214
147.80000,123.16674,31.08212
148.00000,123.33336,31.20511
148.20002,123.49992,31.33114
148.40002,123.66674,31.30091
148.60000,123.83330,31.33874
148.80000,123.99986,31.29057
149.00000,124.16674,31.31659
149.20002,124.33336,31.50249
149.40002,124.49986,31.27719
149.60000,124.66667,31.42248
149.80000,124.83330,31.39004
150.00000,124.99992,31.56379
150.20002,125.16673,31.76523
150.40002,125.33336,31.82967
150.60000,125.49992,31.58501
150.80000,125.66673,31.76381
151.00000,125.83329,31.61333
151.20002,125.99997,31.62494
151.40002,126.16667,31.60089
151.60000,126.33336,31.62808
151.80000,126.49992,31.84691
152.00000,126.66672,31.91399
152.20002,126.83335,31.83153
152.40002,126.99998,31.81492
152.60000,127.16666,31.93178
152.80000,127.33328,32.12440
153.00000,127.49985,32.02390
153.20002,127.66673,32.09485
153.40002,127.83336,31.86651
153.60000,127.99992,32.30560
153.80000,128.16667,32.04487
154.00000,128.33329,32.17002
154.20002,128.49986,32.14238
154.40002,128.66673,32.20603
154.60000,128.83335,32.32535
154.80000,128.99992,32.52527
155.00000,129.16672,32.27272
155.20002,129.33329,32.20593
155.40002,129.49985,32.15552
155.60000,129.66673,32.55829
155.80000,129.83336,32.33191
156.00000,129.99984,32.48136
156.20002,130.16673,32.59235
156.40002,130.33330,32.29615
156.60000,130.49997,32.54188
156.80000,130.66674,32.44491
157.00000,130.83323,32.51797
157.20002,130.99985,32.52380
157.40002,131.16673,32.65379
157.60000,131.33335,32.64002
157.80000,131.49992,32.85440
158.00000,131.66673,32.89233
158.20002,131.83328,32.69491
158.40002,131.99992,32.78707
158.60000,132.16667,32.91158
158.80000,132.33336,32.90575
159.00000,132.49986,32.88831
159.20002,132.66667,32.85744
159.40002,132.83329,33.10690
159.60000,132.99991,32.96582
159.80000,133.16673,33.02007
160.00000,133.33330,33.10268
160.20002,133.49985,32.74395
160.40002,133.66672,33.07372
160.60000,133.83335,33.15604
160.80000,133.99998,33.14909
161.00002,134.16673,33.15403
161.20002,134.33336,33.26311
161.40002,134.49991,33.11091
161.60000,134.66673,32.98876
161.80000,134.83335,33.15903
162.00002,134.99992,33.32161
162.20002,135.16674,33.29069
162.40002,135.33329,33.03800
162.60000,135.49991,33.31946
162.80000,135.66673,33.42564
163.00002,135.83330,33.20529
163.20002,135.99992,33.32098
163.40002,136.16673,33.30520
163.60000,136.33328,33.36189
163.80000,136.49992,33.32078
164.00002,136.66674,33.33651
164.20002,136.83341,33.38987
164.40002,136.99993,33.56784
164.60000,137.16667,33.44063
164.80000,137.33335,33.53604
165.00002,137.49997,33.68583
165.20002,137.66673,33.46479
165.40002,137.83328,33.41295
165.60000,137.99985,33.33621
165.80000,138.16672,33.33773
166.00002,138.33329,33.34249
166.20002,138.49986,33.30711
166.40002,138.66673,33.19485
166.60000,138.83322,33.16153
166.80000,138.99985,33.22778
167.00002,139.16667,32.73504
167.20002,139.33335,-0.93585
167.40002,139.49992,0.20330
167.60000,139.66672,0.46183
167.80000,139.83329,0.13720
168.00002,139.99991,0.30091
168.20002,140.16673,0.45453
168.40002,140.33335,0.30782
168.60000,140.49992,0.05278
168.80000,140.66673,0.05116
169.00002,140.83329,0.16523
169.20002,140.99992,0.10075
169.40002,141.16679,0.15626
169.60000,141.33336,0.36299
169.80000,141.49985,0.31561
170.00002,141.66667,0.15092
170.12800,141.77322,0.44252