File: V_7/FR/RDSO FR Tensile 50.is_tens_RawData/Specimen_RawData_2.csv
Time,Extension,Load
(sec),(mm),(N)
0.00000,0.00000,0.33767
0.20000,0.16462,1.25896
0.40000,0.33306,2.05864
0.60000,0.49994,2.29012
0.80000,0.66675,2.86547
1.00000,0.83337,2.99714
1.20000,0.99994,3.50139
1.40000,1.16675,3.70901
1.60000,1.33331,4.01354
1.80000,1.49987,4.43406
2.00000,1.66662,4.98981
2.20000,1.83337,5.11315
2.40000,2.00000,5.46046
2.60000,2.16656,5.62446
2.80000,2.33337,5.80938
3.00000,2.49994,5.95511
3.20000,2.66675,6.12195
3.40000,2.83331,6.41243
3.60000,2.99994,6.77267
3.80000,3.16675,6.91409
4.00000,3.33331,7.07951
4.20000,3.49994,7.19549
4.40000,3.66681,7.34646
4.60000,3.83337,7.39198
4.80000,3.99994,7.81906
5.00000,4.16669,7.91608
5.20000,4.33337,8.05093
5.40000,4.49994,8.22081
5.60000,4.66675,8.46645
5.80000,4.83325,8.59292
6.00000,4.99987,8.68597
6.20000,5.16669,8.74105
6.40000,5.33331,9.00256
6.60000,5.50000,9.04029
6.80000,5.66675,9.19792
7.00000,5.83331,9.36829
7.20000,5.99994,9.50819
7.40000,6.16675,9.49505
7.60000,6.33337,9.71413
7.80000,6.49994,9.65176
8.00000,6.66675,10.08433
8.20000,6.83337,10.17458
8.40000,6.99987,9.94071
8.60000,7.16675,10.41522
8.80000,7.33337,10.41022
9.00000,7.49994,10.33771
9.20000,7.66662,10.66311
9.40000,7.83325,10.77420
9.60000,7.99987,10.52366
9.80000,8.16681,10.75714
10.00000,8.33337,11.04399
10.20000,8.49981,10.93398
10.40000,8.66669,11.05634
10.60000,8.83331,11.27659
10.80000,8.99987,11.36631
11.00000,9.16675,11.56486
11.20000,9.33337,11.54732
11.40000,9.49994,11.61244
11.60000,9.66669,11.91565
11.80000,9.83337,11.87792
12.00000,10.00000,11.74160
12.20000,10.16675,11.96597
12.40000,10.33337,11.94485
12.60000,10.49994,12.02702
12.80000,10.66669,12.32034
13.00000,10.83337,12.25139
13.20000,10.99994,12.48321
13.40000,11.16669,12.41236
13.60000,11.33331,12.59033
13.80000,11.49987,12.50791
14.00000,11.66675,12.55539
14.20000,11.83337,12.70356
14.40000,11.99987,12.63673
14.60000,12.16669,12.87712
14.80000,12.33337,13.01682
15.00000,12.50000,12.84753
15.20000,12.66675,12.93994
15.40000,12.83331,13.05533
15.60000,12.99987,13.31141
15.80000,13.16675,13.31317
16.00000,13.33331,12.99433
16.20000,13.49994,13.35399
16.40000,13.66681,13.44699
16.60000,13.83337,13.39265
16.80000,13.99987,13.57851
17.00000,14.16669,13.68831
17.20000,14.33331,13.50966
17.40000,14.49994,13.93243
17.60000,14.66669,13.52480
17.80000,14.83331,13.91660
18.00000,14.99994,13.78568
18.20000,15.16675,13.70929
18.40000,15.33331,13.82228
18.60000,15.50000,13.81091
18.80000,15.66675,14.00520
19.00000,15.83337,14.02494
19.20000,15.99994,14.10256
19.40000,16.16675,14.05140
19.60000,16.33337,14.23069
19.80000,16.49987,14.01431
20.00000,16.66681,14.16332
20.20000,16.83337,14.34663
20.40000,16.99987,14.19968
20.60000,17.16669,14.54375
20.80000,17.33337,14.36628
21.00000,17.49994,14.46829
21.20000,17.66675,14.33511
21.40000,17.83337,14.54567
21.60000,17.99993,14.53572
21.80000,18.16675,14.67414
22.00000,18.33331,14.65440
22.20000,18.49987,14.54860
22.40000,18.66681,14.68144
22.60000,18.83337,14.84701
22.80000,18.99993,14.82555
23.00000,19.16662,14.91272
23.20000,19.33331,14.84471
23.40000,19.50000,14.89631
23.60000,19.66675,14.86078
23.80000,19.83337,15.06746
24.00000,19.99993,14.92590
24.20000,20.16675,14.90086
24.40000,20.33331,15.12994
24.60000,20.49993,15.27841
24.80000,20.66675,15.34245
25.00000,20.83337,15.28096
25.20000,20.99993,15.35343
25.40000,21.16675,15.29262
25.60000,21.33331,15.23215
25.80000,21.49994,15.33775
26.00000,21.66675,15.47328
26.20000,21.83337,15.38062
26.40000,21.99993,15.62846
26.60000,22.16668,15.50386
26.80000,22.33331,15.68236
27.00000,22.49993,15.75817
27.20000,22.66675,15.55452
27.40000,22.83331,15.75964
27.60000,22.99994,15.45912
27.80000,23.16675,15.93966
28.00000,23.33331,15.65326
28.20000,23.49993,16.05368
28.40000,23.66675,15.93692
28.60000,23.83331,15.80099
28.80000,23.99987,15.77693
29.00000,24.16675,15.84916
29.20000,24.33343,15.85793
29.40000,24.49993,16.04011
29.60000,24.66668,15.98484
29.80000,24.83331,16.08921
30.00000,24.99999,16.28139
30.20000,25.16675,16.22842
30.40000,25.33331,16.17334
30.60000,25.49981,16.33406
30.80000,25.66668,16.31392
31.00000,25.83337,16.29614
31.20000,25.99993,16.26639
31.40000,26.16675,16.42892
31.60000,26.33331,16.37454
31.80000,26.49987,16.59038
32.00000,26.66668,16.50458
32.20000,26.83337,16.35616
32.40000,26.99994,16.47660
32.60000,27.16674,16.36302
32.80000,27.33337,16.34460
33.00000,27.49993,16.55765
33.20000,27.66668,16.48228
33.40000,27.83337,16.44534
33.60000,28.00000,16.72332
33.80000,28.16675,16.67436
34.00000,28.33331,16.78020
34.20000,28.49987,16.66667
34.40000,28.66675,16.89192
34.60000,28.83331,16.64516
34.80000,28.99987,16.76575
35.00000,29.16669,16.92529
35.20000,29.33337,16.96645
35.40000,29.49993,16.82225
35.60000,29.66675,17.00261
35.80000,29.83337,17.11855
36.00000,29.99993,17.13599
36.20000,30.16675,17.16343
36.40000,30.33337,17.13300
36.60000,30.49993,17.10120
36.80000,30.66681,17.26868
37.00000,30.83331,17.31411
37.20000,30.99993,17.39706
37.40000,31.16675,17.27339
37.60000,31.33337,17.43161
37.80000,31.49993,17.32949
38.00000,31.66674,17.45238
38.20000,31.83331,17.40245
38.40000,31.99993,17.54646
38.60000,32.16675,17.40662
38.80000,32.33337,17.50143
39.00000,32.49993,17.57008
39.20000,32.66668,17.56827
39.40000,32.83324,17.47105
39.60000,33.00000,17.70400
39.80000,33.16674,17.58664
40.00000,33.33331,17.72282
40.20000,33.49993,17.50212
40.40000,33.66675,17.61428
40.60000,33.83337,17.66103
40.80000,33.99981,18.04910
41.00000,34.16675,17.82028
41.20000,34.33337,18.02411
41.40000,34.49987,17.98614
41.60000,34.66668,17.99178
41.80000,34.83337,17.89431
42.00000,34.99993,17.97757
42.20000,35.16668,18.23888
42.40000,35.33331,17.96120
42.60000,35.49987,18.26779
42.80000,35.66675,18.32448
43.00000,35.83337,18.30640
43.20000,35.99993,18.24256
43.40000,36.16675,18.22369
43.60000,36.33337,18.23893
43.80000,36.49993,18.23530
44.00000,36.66674,18.44674
44.20000,36.83337,18.30444
44.40000,36.99993,18.42714
44.60000,37.16668,18.52529
44.80000,37.33331,18.54587
45.00000,37.49993,18.65234
45.20000,37.66675,18.55312
45.40000,37.83331,18.74378
45.60000,37.99993,18.67003
45.80000,38.16668,18.67013
46.00000,38.33331,18.62074
46.20000,38.49993,18.89239
46.40000,38.66674,18.83712
46.60000,38.83331,18.78881
46.80000,38.99987,18.99049
47.00000,39.16668,19.03116
47.20000,39.33337,18.89274
47.40000,39.49999,19.06110
47.60000,39.66675,18.82463
47.80000,39.83330,19.01082
48.00000,39.99993,19.14357
48.20000,40.16674,19.13572
48.40000,40.33331,19.09442
48.60000,40.49993,19.12509
48.80000,40.66675,19.07928
49.00000,40.83325,19.32531
49.20000,40.99987,19.22780
49.40000,41.16681,19.16635
49.60000,41.33331,19.42742
49.80000,41.49993,19.41258
50.00000,41.66674,19.35172
50.20000,41.83331,19.29860
50.40000,41.99993,19.46324
50.60000,42.16681,19.56384
50.80000,42.33337,19.51356
51.00000,42.49987,19.44658
51.20000,42.66668,19.58829
51.40000,42.83337,19.54541
51.60000,42.99993,19.66566
51.80000,43.16675,19.76180
52.00000,43.33337,19.69447
52.20000,43.49987,19.79183
52.40000,43.66674,19.85289
52.60000,43.83331,19.71049
52.80000,43.99993,19.69550
53.00000,44.16674,20.09798
53.20000,44.33337,19.79115
53.40000,44.49987,19.98602
53.60000,44.66674,19.81124
53.80000,44.83337,20.05090
54.00000,44.99999,20.15674
54.20000,45.16668,19.99959
54.40000,45.33337,20.36111
54.60000,45.49993,20.35136
54.80000,45.66681,20.16227
55.00000,45.83331,20.31226
55.20000,45.99987,20.20760
55.40000,46.16668,20.46504
55.60000,46.33330,20.48459
55.80000,46.49993,20.74365
56.00000,46.66674,20.22416
56.20000,46.83337,20.42962
56.40000,46.99986,20.41830
56.60000,47.16674,20.73567
56.80000,47.33331,20.38184
57.00000,47.49999,20.57720
57.20000,47.66674,20.70230
57.40000,47.83337,20.69867
57.60000,47.99993,20.52977
57.80000,48.16674,20.70950
58.00000,48.33330,20.98488
58.20000,48.49987,20.85018
58.40000,48.66675,20.97146
58.60000,48.83330,21.07401
58.80000,48.99987,20.94122
59.00000,49.16674,20.78094
59.20000,49.33331,20.82044
59.40000,49.49987,20.96367
59.60000,49.66668,20.99424
59.80000,49.83330,20.96558
60.00000,49.99999,21.02776
60.20000,50.16674,21.25330
60.40000,50.33331,21.15947
60.60000,50.49993,21.35532
60.80000,50.66674,21.30755
61.00000,50.83337,21.14153
61.20000,50.99987,21.25913
61.40000,51.16674,21.34136
61.60000,51.33336,21.32494
61.80000,51.49987,21.48605
62.00000,51.66674,21.46655
62.20000,51.83337,21.44881
62.40000,51.99993,21.50242
62.60000,52.16668,21.89868
62.80000,52.33331,21.77672
63.00000,52.49986,21.67990
63.20000,52.66674,21.62110
63.40000,52.83337,21.64138
63.60000,52.99993,21.77050
63.80000,53.16674,21.71777
64.00000,53.33330,21.99937
64.20000,53.49987,22.20792
64.40000,53.66674,22.00349
64.60001,53.83337,21.95978
64.80000,53.99987,21.89231
65.00000,54.16675,22.03931
65.20000,54.33330,22.11036
65.40000,54.49993,22.06430
65.60001,54.66674,22.18111
65.80000,54.83337,22.27069
66.00000,54.99993,22.21992
66.20001,55.16674,22.31199
66.40000,55.33330,22.38422
66.60001,55.49993,22.47164
66.80000,55.66674,22.28980
67.00000,55.83331,22.29822
67.20001,55.99987,22.49511
67.40000,56.16674,22.59453
67.60001,56.33337,22.56718
67.80000,56.49987,22.76906
68.00000,56.66674,22.61354
68.20001,56.83331,22.65205
68.40000,56.99987,22.85109
68.60001,57.16674,22.88681
68.80000,57.33337,22.89931
69.00000,57.49993,22.94453
69.20001,57.66674,22.79278
69.40000,57.83331,22.96903
69.60001,57.99993,22.99873
69.80000,58.16680,23.04420
70.00000,58.33331,22.96913
70.20001,58.49987,22.73481
70.40000,58.66674,23.18801
70.60001,58.83330,23.31580
70.80000,58.99993,23.32129
71.00000,59.16681,23.40719
71.20001,59.33330,23.23745
71.40000,59.49981,23.23956
71.60001,59.66668,23.25225
71.80000,59.83337,23.22908
72.00000,59.99999,23.37039
72.20001,60.16674,23.52582
72.40000,60.33331,23.53596
72.60001,60.49993,23.65528
72.80000,60.66674,23.66258
73.00000,60.83337,23.59133
73.20001,60.99987,23.96148
73.40000,61.16681,23.74548
73.60001,61.33331,23.74769
73.80000,61.49987,23.74156
74.00000,61.66674,23.64126
74.20001,61.83337,23.91532
74.40000,61.99993,23.89817
74.60001,62.16668,24.00528
74.80000,62.33336,23.91934
75.00000,62.49993,24.00577
75.20001,62.66674,24.03507
75.40000,62.83330,24.22882
75.60001,62.99987,24.16527
75.80000,63.16674,24.20574
76.00000,63.33330,24.20069
76.20001,63.49993,24.15311
76.40000,63.66674,24.21907
76.60001,63.83331,24.43398
76.80000,63.99993,24.23950
77.00000,64.16667,24.53761
77.20001,64.33337,24.62072
77.40000,64.49993,24.40468
77.60001,64.66674,24.41325
77.80000,64.83330,24.51400
78.00000,64.99992,24.65100
78.20001,65.16674,24.72661
78.40000,65.33337,24.67918
78.60001,65.49993,24.77953
78.80000,65.66674,24.77914
79.00000,65.83330,24.83514
79.20001,65.99993,24.87674
79.40000,66.16680,24.87116
79.60001,66.33336,24.98930
79.80000,66.49987,24.87571
80.00000,66.66668,25.18378
80.20001,66.83331,25.00684
80.40000,66.99986,25.20602
80.60001,67.16674,24.99763
80.80000,67.33330,25.10552
81.00001,67.49993,25.41114
81.20001,67.66674,25.17584
81.40000,67.83336,25.39477
81.60001,67.99986,25.16295
81.80000,68.16674,25.31025
82.00001,68.33330,25.50110
82.20001,68.49993,25.35645
82.40000,68.66674,25.49262
82.60001,68.83337,25.44583
82.80000,68.99986,25.54290
83.00001,69.16674,25.77883
83.20001,69.33330,25.87781
83.40000,69.49992,25.74830
83.60001,69.66680,25.78020
83.80000,69.83336,25.78603
84.00001,69.99987,25.94935
84.20001,70.16668,25.92436
84.40000,70.33330,26.11203
84.60001,70.49993,26.23404
84.80000,70.66674,26.09650
85.00001,70.83330,26.10924
85.20001,70.99993,26.27309
85.40000,71.16674,26.11183
85.60001,71.33331,26.17813
85.80000,71.49993,26.21782
86.00001,71.66680,26.42842
86.20001,71.83337,26.03579
86.40000,71.99993,26.30999
86.60001,72.16667,26.37614
86.80000,72.33337,26.47487
87.00001,72.49992,26.53887
87.20001,72.66674,26.54293
87.40000,72.83330,26.44018
87.60001,72.99987,26.47649
87.80000,73.16674,26.66342
88.00001,73.33330,26.75574
88.20001,73.49993,26.92891
88.40000,73.66674,26.81856
88.60001,73.83336,26.86231
88.80000,73.99987,26.83566
89.00001,74.16674,27.01936
89.20001,74.33336,26.93836
89.40000,74.49993,27.08144
89.60001,74.66668,26.94694
89.80000,74.83337,27.39166
90.00001,74.99993,26.89167
90.20001,75.16674,27.22437
90.40000,75.33330,27.22339
90.60001,75.49986,27.29773
90.80000,75.66674,27.16396
91.00001,75.83336,27.39921
91.20001,75.99999,27.33688
91.40000,76.16674,27.54665
91.60001,76.33330,27.60525
91.80000,76.49980,27.49084
92.00001,76.66674,27.66513
92.20001,76.83337,27.46634
92.40000,76.99999,27.63568
92.60001,77.16674,27.45869
92.80000,77.33330,27.80042
93.00001,77.49987,27.68390
93.20001,77.66674,27.62936
93.40000,77.83336,27.90856
93.60001,77.99999,27.84859
93.80000,78.16673,27.90317
94.00001,78.33336,27.86392
94.20001,78.49980,28.10304
94.40000,78.66680,28.11862
94.60001,78.83336,28.22853
94.80000,78.99993,28.12367
95.00001,79.16667,28.20613
95.20001,79.33330,28.30227
95.40000,79.49986,28.55893
95.60001,79.66674,28.40248
95.80000,79.83330,28.66835
96.00001,79.99986,28.26410
96.20001,80.16674,28.58593
96.40000,80.33336,28.37817
96.60001,80.49992,28.52860
96.80000,80.66674,28.66036
97.00001,80.83330,28.62180
97.20001,80.99986,28.48387
97.40000,81.16674,28.75621
97.60001,81.33336,28.65919
97.80000,81.49993,28.71926
98.00001,81.66668,28.80486
98.20001,81.83336,28.90414
98.40000,81.99993,28.83872
98.60001,82.16674,29.05339
98.80000,82.33336,29.06010
99.00001,82.49993,29.11435
99.20001,82.66667,29.12410
99.40000,82.83329,29.25008
99.60001,82.99986,29.22827
99.80000,83.16674,29.23430
100.00001,83.33337,29.32074
100.20001,83.49986,29.36244
100.40000,83.66674,29.45024
100.60001,83.83336,29.45784
100.80000,83.99987,29.34528
101.00001,84.16673,29.44382
101.20001,84.33335,29.57838
101.40000,84.49992,29.79319
101.60001,84.66673,29.58092
101.80000,84.83330,29.57975
102.00001,84.99992,29.62654
102.20001,85.16674,29.66364
102.40000,85.33330,29.96092
102.60001,85.49985,29.98738
102.80000,85.66674,29.97831
103.00001,85.83336,30.00291
103.20001,85.99993,30.10723
103.40000,86.16674,29.92461
103.60001,86.33330,30.02893
103.80000,86.49986,30.22444
104.00001,86.66680,30.28005
104.20001,86.83336,30.21361
104.40000,86.99986,30.38148
104.60001,87.16667,30.41382
104.80000,87.33329,30.46861
105.00001,87.49993,30.44523
105.20001,87.66667,30.40662
105.40000,87.83337,30.64285
105.60001,87.99986,30.49575
105.80000,88.16673,30.54078
106.00001,88.33330,30.69739
106.20001,88.49992,30.67710
106.40000,88.66673,30.70993
106.60001,88.83336,30.68239
106.80000,88.99986,30.72252
107.00001,89.16673,30.87824
107.20001,89.33336,30.83669
107.40000,89.49986,30.82003
107.60001,89.66668,31.07140
107.80000,89.83336,30.88804
108.00001,89.99986,31.09801
108.20001,90.16674,31.30082
108.40000,90.33336,31.23780
108.60001,90.49992,31.10757
108.80000,90.66674,31.13172
109.00001,90.83330,31.18101
109.20001,90.99992,31.16700
109.40000,91.16674,31.39622
109.60001,91.33336,31.51073
109.80000,91.49986,31.48570
110.00001,91.66667,31.51142
110.20001,91.83336,31.48942
110.40000,91.99993,31.54832
110.60001,92.16674,31.67503
110.80000,92.33336,31.74324
111.00001,92.49986,31.71109
111.20001,92.66668,31.69703
111.40000,92.83336,32.13127
111.60001,92.99998,32.01827
111.80000,93.16674,31.87314
112.00001,93.33324,31.78043
112.20001,93.49986,32.00103
112.40000,93.66673,31.92415
112.60001,93.83336,32.20957
112.80000,93.99986,32.05914
113.00001,94.16673,32.24485
113.20001,94.33329,32.31865
113.40001,94.49986,32.24867
113.60001,94.66667,32.34153
113.80000,94.83336,32.30924
114.00001,94.99992,32.51749
114.20001,95.16673,32.46349
114.40001,95.33330,32.44311
114.60001,95.49987,32.52728
114.80000,95.66673,32.69178
115.00001,95.83335,32.76018
115.20001,95.99986,32.88876
115.40001,96.16673,32.77395
115.60001,96.33336,32.64136
115.80000,96.49992,32.83236
116.00001,96.66674,32.89425
116.20001,96.83336,32.96593
116.40001,96.99985,32.99303
116.60001,97.16667,33.07368
116.80000,97.33336,33.05188
117.00001,97.49993,32.96735
117.20001,97.66674,33.13723
117.40001,97.83329,33.16556
117.60001,97.99986,33.43001
117.80000,98.16674,33.51003
118.00001,98.33336,33.53996
118.20001,98.49992,33.36386
118.40001,98.66673,33.29845
118.60001,98.83329,33.56177
118.80000,98.99992,33.47955
119.00001,99.16673,33.49650
119.20001,99.33342,33.56133
119.40001,99.49992,33.51429
119.60001,99.66668,33.60705
119.80000,99.83336,33.79153
120.00001,99.99992,33.70490
120.20001,100.16673,33.85386
120.40001,100.33330,33.58142
120.60001,100.49992,33.75218
120.80000,100.66673,34.19573
121.00001,100.83336,33.90104
121.20001,100.99986,34.14438
121.40001,101.16674,34.15800
121.60001,101.33336,34.23209
121.80000,101.49992,34.20808
122.00001,101.66674,34.51634
122.20001,101.83330,34.39732
122.40001,101.99992,34.27114
122.60001,102.16674,34.61659
122.80000,102.33330,34.41290
123.00001,102.49992,34.44945
123.20001,102.66673,34.56798
123.40001,102.83336,34.56587
123.60001,102.99992,34.71773
123.80000,103.16667,34.65672
124.00001,103.33324,34.84228
124.20001,103.49993,34.72517
124.40001,103.66674,34.75521
124.60001,103.83330,34.87256
124.80000,103.99986,35.03858
125.00001,104.16668,34.86801
125.20001,104.33336,35.00663
125.40001,104.49998,35.04794
125.60001,104.66673,35.04171
125.80000,104.83336,35.15961
126.00001,104.99992,35.21978
126.20001,105.16667,35.47316
126.40001,105.33337,35.46287
126.60001,105.49986,35.39059
126.80000,105.66674,35.47840
127.00001,105.83330,35.32037
127.20001,105.99992,35.39245
127.40001,106.16673,35.36624
127.60001,106.33335,35.73766
127.80000,106.49992,35.39672
128.00000,106.66673,35.70448
128.20002,106.83335,35.81503
128.40001,106.99986,35.97222
128.60001,107.16673,35.83404
128.80000,107.33336,35.67935
129.00000,107.49992,35.97080
129.20002,107.66674,35.86241
129.40001,107.83330,35.93033
129.60001,107.99993,35.81968
129.80000,108.16674,35.99545
130.00000,108.33336,36.11187
130.20002,108.49993,36.09933
130.40001,108.66667,36.09472
130.60001,108.83329,36.18174
130.80000,108.99992,36.38935
131.00000,109.16674,36.29219
131.20002,109.33336,36.34633
131.40002,109.49986,36.38514
131.60000,109.66667,36.38901
131.80000,109.83337,36.58403
132.00000,109.99999,36.57217
132.20002,110.16673,36.63068
132.40002,110.33330,36.68850
132.60000,110.49992,36.69379
132.80000,110.66673,36.95021
133.00000,110.83336,36.91507
133.20002,110.99992,36.79360
133.40002,111.16673,36.79478
133.60000,111.33330,36.84932
133.80000,111.49986,37.02944
134.00000,111.66673,36.91052
134.20002,111.83336,36.90165
134.40002,111.99992,37.16924
134.60000,112.16667,36.96461
134.80000,112.33330,37.15988
135.00000,112.49992,37.39356
135.20002,112.66674,37.26126
135.40002,112.83336,37.25410
135.60000,112.99992,37.30898
135.80000,113.16674,37.47627
136.00000,113.33330,37.58025
136.20002,113.49992,37.46049
136.40002,113.66673,37.48597
136.60000,113.83330,37.47705
136.80000,113.99986,37.54232
137.00000,114.16674,37.74018
137.20002,114.33336,37.76361
137.40002,114.49993,37.89738
137.60000,114.66667,37.99170
137.80000,114.83336,37.94926
138.00000,114.99993,38.06917
138.20002,115.16673,38.03477
138.40002,115.33336,38.01762
138.60000,115.49992,37.97720
138.80000,115.66667,38.06089
139.00000,115.83329,38.13742
139.20002,115.99992,38.34161
139.40002,116.16673,38.12576
139.60000,116.33337,38.47773
139.80000,116.49992,38.51707
140.00000,116.66674,38.63727
140.20002,116.83336,38.34303
140.40002,116.99999,38.49498
140.60000,117.16673,38.60229
140.80000,117.33330,38.56171
141.00000,117.49987,38.60297
141.20002,117.66667,38.77178
141.40002,117.83335,38.77962
141.60000,117.99999,38.91540
141.80000,118.16667,38.76923
142.00000,118.33330,38.86645
142.20002,118.49992,38.82548
142.40002,118.66674,38.95856
142.60000,118.83330,39.00281
142.80000,118.99993,38.96925
143.00000,119.16674,39.09934
143.20002,119.33336,39.24468
143.40002,119.49993,39.20508
143.60000,119.66674,39.10875
143.80000,119.83329,39.32151
144.00000,119.99992,39.27711
144.20002,120.16667,39.30896
144.40002,120.33329,39.39368
144.60000,120.49992,39.42877
144.80000,120.66673,39.38109
145.00000,120.83329,39.43568
145.20002,120.99979,39.67176
145.40002,121.16673,39.49114
145.60000,121.33330,39.87084
145.80000,121.49992,39.55288
146.00000,121.66673,39.65426
146.20002,121.83330,39.86580
146.40002,121.99992,40.06890
146.60000,122.16668,39.95209
146.80000,122.33336,39.94175
147.00000,122.49992,39.76025
147.20002,122.66673,39.92959
147.40002,122.83330,40.26230
147.60000,122.99986,40.00260
147.80000,123.16674,40.03833
148.00000,123.33336,40.39294
148.20002,123.49992,40.33786
148.40002,123.66674,40.18552
148.60000,123.83330,40.12368
148.80000,123.99986,40.21801
149.00000,124.16674,40.25309
149.20002,124.33336,40.42292
149.40002,124.49986,40.56355
149.60000,124.66667,40.65562
149.80000,124.83330,40.68708
150.00000,124.99986,40.48589
150.20002,125.16673,40.41567
150.40002,125.33336,40.81870
150.60000,125.49992,40.79189
150.80000,125.66673,40.85270
151.00000,125.83335,40.92194
151.20002,125.99997,40.97937
151.40002,126.16673,40.91165
151.60000,126.33330,40.93174
151.80000,126.49992,41.05257
152.00000,126.66672,41.20869
152.20002,126.83335,41.12240
152.40002,126.99998,40.91763
152.60000,127.16673,41.20810
152.80000,127.33328,41.15650
153.00000,127.49985,41.16684
153.20002,127.66673,41.45349
153.40002,127.83336,41.42571
153.60000,127.99992,41.52493
153.80000,128.16667,41.54316
154.00000,128.33335,41.49578
154.20002,128.49986,41.64415
154.40002,128.66673,41.52082
154.60000,128.83335,41.69359
154.80000,128.99986,41.56188
155.00000,129.16672,41.54527
155.20002,129.33329,41.78831
155.40002,129.49991,41.70285
155.60000,129.66673,41.80462
155.80000,129.83336,41.98097
156.00000,129.99984,41.71574
156.20002,130.16673,41.99317
156.40002,130.33330,42.02091
156.60000,130.49997,42.07094
156.80000,130.66674,42.02787
157.00000,130.83328,41.99494
157.20002,130.99985,42.26331
157.40002,131.16673,42.19437
157.60000,131.33335,42.35063
157.80000,131.49998,42.28438
158.00000,131.66673,42.26512
158.20002,131.83328,42.18001
158.40002,131.99992,42.34034
158.60000,132.16667,42.53467
158.80000,132.33336,42.48538
159.00000,132.49986,42.54707
159.20002,132.66667,42.34401
159.40002,132.83329,42.71499
159.60000,132.99991,42.77506
159.80000,133.16673,42.64277
160.00000,133.33330,42.43212
160.20002,133.49985,42.71347
160.40002,133.66672,42.73376
160.60000,133.83335,42.80040
160.80000,133.99998,42.66849
161.00002,134.16673,42.88644
161.20002,134.33342,42.78594
161.40002,134.49991,42.72504
161.60000,134.66666,42.72734
161.80000,134.83330,42.94397
162.00002,134.99998,42.69931
162.20002,135.16674,-1.57930
162.40002,135.33329,0.07567
162.60000,135.49991,0.16592
162.80000,135.66673,0.03456
163.00002,135.83330,0.12824
163.20002,135.99992,0.03828
163.40002,136.16673,0.17141
163.60000,136.33335,0.14730
163.80000,136.49992,-0.04742
164.00002,136.66674,0.13079
164.20002,136.83336,0.04245
164.40002,136.99993,-0.04830
164.60000,137.16667,0.21831
164.80000,137.33335,0.35168
165.00002,137.49997,0.25285
165.20002,137.66673,0.03416
165.40002,137.83336,0.12271
165.60000,137.99992,0.37907
165.80000,138.16672,0.12408
166.00002,138.33329,0.10090
166.04200,138.36841,0.05739