File: V_8/NatR/RDSO NatR Tensile 250.is_tens_RawData/Specimen_RawData_3.csv
Time,Extension,Load,
(sec),(mm),(N),(kgf)
0,0,-0.107677017,-0.01098
0.02,0.0115,0.041874396,0.00427
0.04,0.068,0.491803498,0.05015
0.06,0.16519,0.905055729,0.09229
0.08,0.27769,1.26898051,0.1294
0.1,0.38556,1.451972599,0.14806
0.12,0.48231,1.635062755,0.16673
0.14,0.57056,1.677819749,0.17109
0.16,0.65512,1.91259095,0.19503
0.18,0.73925,2.214439637,0.22581
0.2,0.82419,2.631516461,0.26834
0.22,0.90956,2.968669088,0.30272
0.24,0.99475,3.122633493,0.31842
0.26,1.07956,3.395454496,0.34624
0.28,1.16394,3.781051974,0.38556
0.3,1.24787,3.842833869,0.39186
0.32,1.33169,3.800763341,0.38757
0.34,1.41537,4.048087054,0.41279
0.36,1.49894,4.52900517,0.46183
0.38,1.58256,4.755636851,0.48494
0.4,1.66619,4.826538931,0.49217
0.42,1.74956,4.985602794,0.50839
0.44,1.833,5.23508397,0.53383
0.46,1.9165,5.466324777,0.55741
0.48,1.99981,5.532225465,0.56413
0.5,2.08319,5.588613702,0.56988
0.52,2.16656,5.833387686,0.59484
0.54,2.24981,6.134353775,0.62553
0.56,2.33312,6.195645337,0.63178
0.58,2.41656,6.303028155,0.64273
0.6,2.49987,6.608995635,0.67393
0.62,2.58331,6.837882846,0.69727
0.64,2.66675,6.970272621,0.71077
0.66,2.75006,7.139633466,0.72804
0.68,2.83344,7.161796495,0.7303
0.7,2.91675,7.315858967,0.74601
0.72,2.99994,7.52787874,0.76763
0.74,3.08325,7.722834942,0.78751
0.76,3.16662,7.958684874,0.81156
0.78,3.24994,8.142657628,0.83032
0.8,3.33331,8.164232258,0.83252
0.82,3.41669,8.276224201,0.84394
0.84,3.5,8.415968964,0.85819
0.86,3.58337,8.516585193,0.86845
0.88,3.66675,8.662017812,0.88328
0.9,3.75006,8.967789159,0.91446
0.92,3.83337,9.251201344,0.94336
0.94,3.91669,9.333675271,0.95177
0.96,3.99994,9.254927871,0.94374
0.98,4.08331,9.332106207,0.95161
1,4.16669,9.427328778,0.96132
1.02,4.24994,9.773405457,0.99661
1.04,4.33325,9.892850454,1.00879
1.06,4.41669,9.994447348,1.01915
1.08,4.5,10.16537726,1.03658
1.1,4.58337,10.29011785,1.0493
1.12,4.66675,10.42378248,1.06293
1.14,4.75006,10.6134431,1.08227
1.16,4.83337,10.72161045,1.0933
1.18,4.91669,10.80153464,1.10145
1.2,4.99994,10.8672392,1.10815
1.22,5.08325,11.03640391,1.1254
1.24,5.16669,11.31608957,1.15392
1.26,5.25,11.53615079,1.17636
1.28,5.33331,11.64735821,1.1877
1.3,5.41675,11.76062501,1.19925
1.32,5.5,11.95999421,1.21958
1.34,5.58331,12.05374578,1.22914
1.36,5.66669,12.12925699,1.23684
1.38,5.74994,12.11415475,1.2353
1.4,5.83325,12.31989826,1.25628
1.42,5.91662,12.47758919,1.27236
1.44,5.99994,12.44042199,1.26857
1.46,6.08331,12.73648475,1.29876
1.48,6.16669,12.83955265,1.30927
1.5,6.25,12.83710098,1.30902
1.52,6.33344,13.00646183,1.32629
1.54,6.41681,13.11806151,1.33767
1.56,6.50006,13.46119619,1.37266
1.58,6.58337,13.68478781,1.39546
1.6,6.66669,13.7893267,1.40612
1.62,6.75,13.94662536,1.42216
1.64,6.83331,14.07754414,1.43551
1.66,6.91669,14.11686881,1.43952
1.68,6.99994,14.21375851,1.4494
1.7,7.08331,14.19836207,1.44783
1.72,7.16669,14.3566414,1.46397
1.74,7.25,14.40067326,1.46846
1.76,7.33337,14.54904787,1.48359
1.78,7.41675,14.68604677,1.49756
1.8,7.5,14.85374049,1.51466
1.82,7.58331,14.94249067,1.52371
1.84,7.66669,15.07948957,1.53768
1.86,7.74994,15.26797339,1.5569
1.88,7.83325,15.29543201,1.5597
1.9,7.91669,15.47479563,1.57799
1.92,8.00006,15.64170482,1.59501
1.94,8.08337,15.82960023,1.61417
1.96,8.16681,15.90658243,1.62202
1.98,8.25012,16.10408836,1.64216
2,8.3335,16.29129731,1.66125
2.02,8.41675,16.30198656,1.66234
2.04,8.5,16.3156178,1.66373
2.06,8.58325,16.37514417,1.6698
2.08,8.66656,16.47330874,1.67981
2.1,8.74981,16.74514907,1.70753
2.12,8.83319,17.08563596,1.74225
2.14,8.91669,17.23155891,1.75713
2.16,9.00006,17.28333803,1.76241
2.18,9.0835,17.27549271,1.76161
2.2,9.16687,17.32393756,1.76655
2.22,9.25012,17.39150538,1.77344
2.24,9.33331,17.32874282,1.76704
2.26,9.41656,17.42739772,1.7771
2.28,9.49987,17.42318086,1.77667
2.3,9.58325,17.5940127,1.79409
2.32,9.66662,17.90037244,1.82533
2.34,9.74994,18.06943909,1.84257
2.36,9.83331,18.16466166,1.85228
2.38,9.91675,18.24929305,1.86091
2.4,10.00006,18.37354331,1.87358
2.42,10.08337,18.48072999,1.88451
2.44,10.16675,18.56085032,1.89268
2.46,10.25,18.48573138,1.88502
2.48,10.33325,18.71559926,1.90846
2.5,10.41662,18.87574185,1.92479
2.52,10.49987,18.91791045,1.92909
2.54,10.58325,18.97851555,1.93527
2.56,10.66662,19.15140679,1.9529
2.58,10.75,19.14150207,1.95189
2.6,10.83337,19.35499284,1.97366
2.62,10.91675,19.43521124,1.98184
2.64,11,19.65409566,2.00416
2.66,11.08337,19.64880007,2.00362
2.68,11.16675,19.6308539,2.00179
2.7,11.25,19.72990107,2.01189
2.72,11.33331,19.89043593,2.02826
2.74,11.41669,19.86209471,2.02537
2.76,11.49994,19.91701195,2.03097
2.78,11.58325,19.99164056,2.03858
2.8,11.66669,20.30535529,2.07057
2.82,11.75006,20.30643402,2.07068
2.84,11.83337,20.39645907,2.07986
2.86,11.91681,20.35664407,2.0758
2.88,12.00006,20.359488,2.07609
2.9,12.08331,20.46765535,2.08712
2.92,12.16662,20.56631025,2.09718
2.94,12.24987,20.65388363,2.10611
2.96,12.33325,20.72380505,2.11324
2.98,12.41669,20.83795445,2.12488
3,12.5,20.92052645,2.1333
3.02,12.58337,21.07968837,2.14953
3.04,12.66675,21.03006673,2.14447
3.06,12.75006,21.37055361,2.17919
3.08,12.83337,21.53187301,2.19564
3.1,12.91669,21.42399986,2.18464
3.12,12.99994,21.29631727,2.17162
3.14,13.08331,21.29612114,2.1716
3.16,13.16669,21.34417373,2.1765
3.18,13.25,21.64798374,2.20748
3.2,13.33331,21.86010158,2.22911
3.22,13.41675,21.80900894,2.2239
3.24,13.5,22.05662685,2.24915
3.26,13.58337,22.03465995,2.24691
3.28,13.66675,22.11889908,2.2555
3.3,13.75,22.26688142,2.27059
3.32,13.83331,22.15106489,2.25878
3.34,13.91669,22.07820148,2.25135
3.36,13.99994,22.24481646,2.26834
3.38,14.08325,22.46497575,2.29079
3.4,14.16662,22.50832115,2.29521
3.42,14.24994,22.5356817,2.298
3.44,14.33331,22.76241145,2.32112
3.46,14.41675,22.89323216,2.33446
3.48,14.5,23.00600863,2.34596
3.5,14.58331,22.97119503,2.34241
3.52,14.66669,23.10348674,2.3559
3.54,14.74994,23.07965658,2.35347
3.56,14.83325,23.24362376,2.37019
3.58,14.91662,23.23872044,2.36969
3.6,14.99994,23.35130078,2.38117
3.62,15.08331,23.36659915,2.38273
3.64,15.16669,23.45583967,2.39183
3.66,15.25,23.499087,2.39624
3.68,15.33337,23.56773355,2.40324
3.7,15.41675,23.54478599,2.4009
3.72,15.5,23.47662977,2.39395
3.74,15.58331,23.60117422,2.40665
3.76,15.66668,23.65148234,2.41178
3.78,15.74993,23.80927134,2.42787
3.8,15.83325,23.79309036,2.42622
3.82,15.91668,23.84192748,2.4312
3.84,16,23.86742477,2.4338
3.86,16.08337,23.93518872,2.44071
3.88,16.16675,24.03394169,2.45078
3.9,16.25006,24.12690873,2.46026
3.92,16.33337,24.14779689,2.46239
3.94,16.41675,24.32431659,2.48039
3.96,16.5,24.43738727,2.49192
3.98,16.58331,24.49563877,2.49786
4,16.66668,24.53584603,2.50196
4.02,16.75,24.64303272,2.51289
4.04,16.83337,24.63332414,2.5119
4.06,16.91675,24.67706179,2.51636
4.08,17.00006,24.87358706,2.5364
4.1,17.08331,24.73805916,2.52258
4.12,17.16669,24.77051917,2.52589
4.14,17.24993,25.03304319,2.55266
4.16,17.33325,25.05471589,2.55487
4.18,17.41668,25.10110134,2.5596
4.2,17.5,25.19818718,2.5695
4.22,17.58337,25.27075639,2.5769
4.24,17.66675,25.2411403,2.57388
4.26,17.75006,25.30949265,2.58085
4.28,17.83337,25.12748123,2.56229
4.3,17.91668,25.20171757,2.56986
4.32,18,25.38088506,2.58813
4.34,18.08331,25.53298621,2.60364
4.36,18.16675,25.4583576,2.59603
4.38,18.25,25.45678854,2.59587
4.4,18.33331,25.55534537,2.60592
4.42,18.41668,25.63291597,2.61383
4.44,18.5,25.58466725,2.60891
4.46,18.58331,25.57446834,2.60787
4.48,18.66675,25.72784434,2.62351
4.5,18.75006,25.82355725,2.63327
4.52,18.83337,25.85493853,2.63647
4.54,18.91675,25.91877982,2.64298
4.56,19,25.9855631,2.64979
4.58,19.08337,25.98605344,2.64984
4.6,19.16668,25.97418739,2.64863
4.62,19.24993,26.0672525,2.65812
4.64,19.33325,26.16571126,2.66816
4.66,19.41668,26.1650248,2.66809
4.68,19.5,26.19297375,2.67094
4.7,19.58337,26.18973756,2.67061
4.72,19.66681,26.28898085,2.68073
4.74,19.75006,26.21082185,2.67276
4.76,19.83337,26.15355102,2.66692
4.78,19.91668,26.29368805,2.68121
4.8,19.99987,26.47128648,2.69932
4.82,20.08325,26.50688462,2.70295
4.84,20.16662,26.53718717,2.70604
4.86,20.24994,26.62642768,2.71514
4.88,20.33331,26.89228596,2.74225
4.9,20.41675,26.84737151,2.73767
4.92,20.5,26.78460895,2.73127
4.94,20.58337,26.80941977,2.7338
4.96,20.66675,26.97593669,2.75078
4.98,20.75006,26.96259964,2.74942
5,20.83331,26.88708844,2.74172
5.02,20.91669,26.87541852,2.74053
5.04,21,27.07567032,2.76095
5.06,21.08331,27.13990388,2.7675
5.08,21.16662,27.21786674,2.77545
5.1,21.24993,27.1658915,2.77015
5.12,21.33331,27.14019807,2.76753
5.14,21.41668,27.21414022,2.77507
5.16,21.5,27.25238615,2.77897
5.18,21.58337,27.27435305,2.78121
5.2,21.66675,27.38065713,2.79205
5.22,21.75006,27.43018072,2.7971
5.24,21.83331,27.58443932,2.81283
5.26,21.91675,27.67622956,2.82219
5.28,22,27.657695,2.8203
5.3,22.08331,27.66691325,2.82124
5.32,22.16668,27.68152515,2.82273
5.34,22.25,27.80489281,2.83531
5.36,22.33337,27.84353101,2.83925
5.38,22.41675,27.87952142,2.84292
5.4,22.50006,27.80312761,2.83513
5.42,22.58337,27.892172,2.84421
5.44,22.66668,27.91560989,2.8466
5.46,22.75,27.79430163,2.83423
5.48,22.83331,27.74252252,2.82895
5.5,22.91668,27.89266233,2.84426
5.52,22.99994,28.02819023,2.85808
5.54,23.08331,28.17940878,2.8735
5.56,23.16675,28.24001387,2.87968
5.58,23.25006,28.29444078,2.88523
5.6,23.33337,28.26835509,2.88257
5.62,23.41675,28.35053482,2.89095
5.64,23.50006,28.35230001,2.89113
5.66,23.58337,28.32945052,2.8888
5.68,23.66669,28.34925995,2.89082
5.7,23.74993,28.4568389,2.90179
5.72,23.83331,28.56265266,2.91258
5.74,23.91668,28.67415427,2.92395
5.76,23.99993,28.71396927,2.92801
5.78,24.08331,28.68082279,2.92463
5.8,24.16675,28.63551607,2.92001
5.82,24.25,28.55470927,2.91177
5.84,24.33337,28.55529767,2.91183
5.86,24.41674,28.78693074,2.93545
5.88,24.5,29.01934835,2.95915
5.9,24.58331,28.85802896,2.9427
5.92,24.66662,28.9521728,2.9523
5.94,24.74993,28.9709035,2.95421
5.96,24.83325,28.93716862,2.95077
5.98,24.91662,28.94609267,2.95168
6,24.99999,29.06112468,2.96341
6.02,25.08337,29.0862297,2.96597
6.04,25.16675,29.06190921,2.96349
6.06,25.25006,29.19135699,2.97669
6.08,25.33337,29.16036797,2.97353
6.1,25.41675,29.21999241,2.97961
6.12,25.5,29.21293162,2.97889
6.14,25.58318,29.42936438,3.00096
6.16,25.6665,29.45152741,3.00322
6.18,25.74987,29.50291426,3.00846
6.2,25.83331,29.55891023,3.01417
6.22,25.91675,29.62196699,3.0206
6.24,26.00012,29.70826551,3.0294
6.26,26.0835,29.6143178,3.01982
6.28,26.16681,29.61922113,3.02032
6.3,26.25006,29.69414393,3.02796
6.32,26.33331,29.95529502,3.05459
6.34,26.41656,29.96657267,3.05574
6.36,26.49981,30.00069981,3.05922
6.38,26.58318,29.93411266,3.05243
6.4,26.66668,30.07101349,3.06639
6.42,26.75,30.27597248,3.08729
6.44,26.83337,30.19183142,3.07871
6.46,26.91675,30.19693088,3.07923
6.48,27.00006,30.30872669,3.09063
6.5,27.08343,30.41405011,3.10137
6.52,27.16674,30.43278081,3.10328
6.54,27.24993,30.50397709,3.11054
6.56,27.33331,30.4992699,3.11006
6.58,27.41662,30.37305831,3.09719
6.6,27.49993,30.38590503,3.0985
6.62,27.58331,30.58223416,3.11852
6.64,27.66668,30.54428242,3.11465
6.66,27.74999,30.45543417,3.10559
6.68,27.83331,30.54732248,3.11496
6.7,27.91675,30.68520398,3.12902
6.72,28.00006,30.8523093,3.14606
6.74,28.08337,30.82259515,3.14303
6.76,28.16675,30.85554549,3.14639
6.78,28.25,30.88820164,3.14972
6.8,28.33331,30.84770017,3.14559
6.82,28.41668,31.02059141,3.16322
6.84,28.49993,30.94458988,3.15547
6.86,28.58331,30.95841725,3.15688
6.88,28.66675,30.9527294,3.1563
6.9,28.75006,30.91536606,3.15249
6.92,28.83337,30.89908702,3.15083
6.94,28.91675,30.98420874,3.15951
6.96,29,31.21721475,3.18327
6.98,29.08331,31.2823309,3.18991
7,29.16662,31.23908358,3.1855
7.02,29.24993,31.27379912,3.18904
7.04,29.33325,31.23310152,3.18489
7.06,29.41668,31.19358072,3.18086
7.08,29.5,31.50327473,3.21244
7.1,29.58337,31.59320171,3.22161
7.12,29.66675,31.62350426,3.2247
7.14,29.75,31.78835404,3.24151
7.16,29.83331,31.77746866,3.2404
7.18,29.91668,31.75471723,3.23808
7.2,29.99993,31.5791782,3.22018
7.22,30.08325,31.59898763,3.2222
7.24,30.16662,31.73304454,3.23587
7.26,30.25,31.89740399,3.25263
7.28,30.33331,31.76913301,3.23955
7.3,30.41668,31.814832,3.24421
7.32,30.50006,31.96183368,3.2592
7.34,30.58337,32.04038495,3.26721
7.36,30.66675,32.01478959,3.2646
7.38,30.75,32.1087373,3.27418
7.4,30.83331,32.05823305,3.26903
7.42,30.91668,32.31663828,3.29538
7.44,30.99993,32.34242977,3.29801
7.46,31.08331,32.18042391,3.28149
7.48,31.16668,32.44226146,3.30819
7.5,31.25,32.31928607,3.29565
7.52,31.33331,32.28358987,3.29201
7.54,31.41674,32.49011792,3.31307
7.56,31.50006,32.53454204,3.3176
7.58,31.58337,32.53748404,3.3179
7.6,31.66668,32.68203406,3.33264
7.62,31.74999,32.68438765,3.33288
7.64,31.83331,32.73822616,3.33837
7.66,31.91668,32.71057141,3.33555
7.68,31.99993,32.63898286,3.32825
7.7,32.08331,32.71370954,3.33587
7.72,32.16675,32.58357529,3.3226
7.74,32.25006,32.72430072,3.33695
7.76,32.33337,32.87385213,3.3522
7.78,32.41675,32.84815871,3.34958
7.8,32.5,32.8701256,3.35182
7.82,32.58331,32.89140603,3.35399
7.84,32.66668,32.98192141,3.36322
7.86,32.74993,33.20874923,3.38635
7.88,32.83331,33.11656672,3.37695
7.9,32.91668,33.17942734,3.38336
7.92,33.00006,33.01683309,3.36678
7.94,33.08343,32.99839659,3.3649
7.96,33.16674,33.10568134,3.37584
7.98,33.24999,33.33280335,3.399
8,33.33337,33.42155353,3.40805
8.02,33.41675,33.41331595,3.40721
8.04,33.49999,33.49559374,3.4156
8.06,33.58331,33.61415614,3.42769
8.08,33.66668,33.52275816,3.41837
8.1,33.74999,33.42979112,3.40889
8.12,33.83337,33.49500534,3.41554
8.14,33.91674,33.56777068,3.42296
8.16,34,33.64749875,3.43109
8.18,34.08331,33.78224212,3.44483
8.2,34.16662,33.79646176,3.44628
8.22,34.24993,33.81283887,3.44795
8.24,34.33324,33.86098952,3.45286
8.26,34.41668,34.00661827,3.46771
8.28,34.49999,34.01279646,3.46834
8.3,34.58337,33.87746469,3.45454
8.32,34.66674,33.89305726,3.45613
8.34,34.75,33.91904489,3.45878
8.36,34.83331,33.99612516,3.46664
8.38,34.91668,34.1297898,3.48027
8.4,34.99993,34.0876212,3.47597
8.42,35.08331,34.22707176,3.49019
8.44,35.16668,34.19039489,3.48645
8.46,35.24993,34.30081777,3.49771
8.48,35.33331,34.37672124,3.50545
8.5,35.41662,34.30581916,3.49822
8.52,35.49993,34.43389401,3.51128
8.54,35.58331,34.45517444,3.51345
8.56,35.66668,34.28022381,3.49561
8.58,35.75,34.45458604,3.51339
8.6,35.83337,34.37603478,3.50538
8.62,35.91675,34.42477383,3.51035
8.64,35.99999,34.39025442,3.50683
8.66,36.08331,34.48204466,3.51619
8.68,36.16668,34.37887871,3.50567
8.7,36.24993,34.43997414,3.5119
8.72,36.33325,34.32043107,3.49971
8.74,36.41662,23.34149413,2.38017
8.76,36.5,6.377754828,0.65035
8.78,36.58343,-0.912704916,-0.09307
8.8,36.66681,-1.764118269,-0.17989
8.82,36.75006,-1.049899949,-0.10706
8.84,36.83337,-0.676756917,-0.06901
8.86,36.91668,-0.573492892,-0.05848
8.88,36.99987,-0.550251132,-0.05611
8.9,37.08325,-0.52593064,-0.05363
8.92,37.16662,-0.470523067,-0.04798
8.94,37.24993,-0.395207995,-0.0403
8.96,37.33331,-0.536031489,-0.05466
8.98,37.41675,-0.383440015,-0.0391
9,37.50006,-0.29841636,-0.03043
9.02,37.58337,-0.376967626,-0.03844
9.04,37.66675,-0.587810601,-0.05994
9.06,37.75006,-0.712649256,-0.07267
9.08,37.83337,-0.760701841,-0.07757
9.1,37.91675,-0.493274495,-0.0503
9.12,37.99993,-0.3334261,-0.034
9.14,38.08331,-0.29841636,-0.03043
9.16,38.16668,-0.417371024,-0.04256
9.18,38.25,-0.386872343,-0.03945
9.2,38.33331,-0.356863994,-0.03639
9.22,38.41668,-0.485919508,-0.04955
9.24,38.5,-0.467973338,-0.04772
9.26,38.58337,-0.406681776,-0.04147
9.28,38.66674,-0.348528341,-0.03554
9.3,38.75006,-0.403641714,-0.04116
9.32,38.83331,-0.495824224,-0.05056
9.34,38.91662,-0.523184778,-0.05335
9.36,38.99993,-0.291355572,-0.02971
9.38,39.08325,-0.226827815,-0.02313
9.4,39.16668,-0.432865531,-0.04414
9.42,39.24999,-0.54162128,-0.05523
9.44,39.33337,-0.493568695,-0.05033
9.46,39.41674,-0.466012008,-0.04752
9.48,39.49999,-0.608208433,-0.06202
9.5,39.5833,-0.388441407,-0.03961
9.52,39.66662,-0.282921853,-0.02885
9.54,39.74993,-0.3138128,-0.032
9.56,39.83324,-0.655182287,-0.06681
9.58,39.91662,-0.745501533,-0.07602
9.6,39.99993,-0.723142371,-0.07374
9.62,40.08331,-0.475524459,-0.04849
9.64,40.16668,-0.519654384,-0.05299
9.66,40.25,-0.520242783,-0.05305
9.68,40.33337,-0.496020357,-0.05058
9.7,40.41674,-0.473366996,-0.04827
9.72,40.49999,-0.482291047,-0.04918
9.74,40.5833,-0.49651069,-0.05063
9.76,40.66668,-0.542798078,-0.05535
9.78,40.74993,-0.470032735,-0.04793
9.8,40.83325,-0.353823932,-0.03608
9.82,40.91662,-0.459833819,-0.04689
9.84,40.99999,-0.558684851,-0.05697
9.86,41.08331,-0.427275741,-0.04357
9.88,41.16668,-0.52171378,-0.0532
9.9,41.25,-0.512593596,-0.05227
9.92,41.33337,-0.536325689,-0.05469
9.94,41.41674,-0.608698766,-0.06207
9.96,41.49999,-0.511710997,-0.05218
9.98,41.58331,-0.582122744,-0.05936
10,41.66668,-0.604874172,-0.06168
10.02,41.74993,-0.530932031,-0.05414
10.04,41.83331,-0.391677601,-0.03994
10.06,41.91674,-0.346370878,-0.03532
10.08,42.00005,-0.273311336,-0.02787
10.1,42.08337,-0.397561591,-0.04054
10.12,42.16674,-0.370495237,-0.03778
10.14,42.25005,-0.432080999,-0.04406
10.16,42.33337,-0.644394972,-0.06571
10.18,42.41668,-0.63772645,-0.06503
10.2,42.49993,-0.540346415,-0.0551
10.22,42.58324,-0.417567157,-0.04258
10.24,42.66662,-0.411192835,-0.04193
10.26,42.74993,-0.383341949,-0.03909
10.28,42.8333,-0.469934668,-0.04792
10.3,42.91681,-0.625075871,-0.06374
10.32,43.00018,-0.444633511,-0.04534
10.34,43.08349,-0.393638931,-0.04014
10.36,43.16681,-0.38863754,-0.03963
10.38,43.24999,-0.57270836,-0.0584
10.39,43.29162,-0.500727549,-0.05106