File: FR/FR/RDSO FR Tensile 250.is_tens_RawData/Specimen_RawData_5.csv
Time,Extension,Load,
(sec),(mm),(N),(kgf)
0,0,0.036088472,0.00368
0.04,0.06787,0.579867215,0.05913
0.08,0.27762,1.472468498,0.15015
0.12,0.4825,1.811092122,0.18468
0.16,0.65519,2.741350941,0.27954
0.2,0.82406,3.260907258,0.33252
0.24,0.99487,3.660037913,0.37322
0.28,1.164,4.212838774,0.42959
0.32,1.33162,4.625894872,0.47171
0.36,1.49894,5.102007729,0.52026
0.4,1.666,5.542130181,0.56514
0.44,1.83294,5.746206568,0.58595
0.48,1.99987,6.119251534,0.62399
0.52,2.16669,6.485333778,0.66132
0.56,2.33312,6.907019728,0.70432
0.6,2.49987,7.109036718,0.72492
0.64,2.66669,7.452661734,0.75996
0.68,2.83337,7.705771371,0.78577
0.72,3.00012,7.991831351,0.81494
0.76,3.16675,8.304369287,0.84681
0.8,3.33325,8.561107384,0.87299
0.84,3.49994,8.749689263,0.89222
0.88,3.66662,9.022314133,0.92002
0.92,3.83337,9.160784031,0.93414
0.96,4.00006,9.536574859,0.97246
1,4.16669,9.698874917,0.98901
1.04,4.33325,9.95178842,1.0148
1.08,4.5,10.1611604,1.03615
1.12,4.66675,10.11163682,1.0311
1.16,4.83337,10.58539608,1.07941
1.2,5,10.47664033,1.06832
1.24,5.16662,10.84027091,1.1054
1.28,5.33331,10.9061716,1.11212
1.32,5.5,11.16408649,1.13842
1.36,5.66675,11.08818302,1.13068
1.4,5.83337,11.30775392,1.15307
1.44,6,11.71580862,1.19468
1.48,6.16669,11.6710903,1.19012
1.52,6.33331,11.65677259,1.18866
1.56,6.5,11.94008671,1.21755
1.6,6.66669,12.13033572,1.23695
1.64,6.83331,12.16397253,1.24038
1.68,7,12.28459432,1.25268
1.72,7.16662,12.58507008,1.28332
1.76,7.33337,12.59595546,1.28443
1.8,7.50006,12.6701918,1.292
1.84,7.66675,12.90810113,1.31626
1.88,7.83331,12.94075727,1.31959
1.92,7.99994,13.06677273,1.33244
1.96,8.16669,13.18749259,1.34475
2,8.3335,13.08364016,1.33416
2.04,8.50019,13.44315195,1.37082
2.08,8.66656,13.47865203,1.37444
2.12,8.83306,13.32792382,1.35907
2.16,9,13.68625881,1.39561
2.2,9.16681,13.68606267,1.39559
2.24,9.33337,13.68017868,1.39499
2.28,9.50006,13.85208926,1.41252
2.32,9.66662,13.91838221,1.41928
2.36,9.83319,14.1414835,1.44203
2.4,10,14.07823061,1.43558
2.44,10.16675,14.20650159,1.44866
2.48,10.33331,14.27338294,1.45548
2.52,10.50006,14.17845457,1.4458
2.56,10.66669,14.30329322,1.45853
2.6,10.83325,14.64672211,1.49355
2.64,11.00006,14.63407153,1.49226
2.68,11.16681,14.48932538,1.4775
2.72,11.33331,14.64417238,1.49329
2.76,11.49994,14.64672211,1.49355
2.8,11.66669,14.6897733,1.49794
2.84,11.83331,14.84540484,1.51381
2.88,12.00006,14.89031929,1.51839
2.92,12.16669,14.81637715,1.51085
2.96,12.33325,15.1043004,1.54021
3,12.5,14.9230735,1.52173
3.04,12.66675,14.9655363,1.52606
3.08,12.83337,15.24639876,1.5547
3.12,13.00006,15.15647177,1.54553
3.16,13.16669,15.17706574,1.54763
3.2,13.33325,15.22305893,1.55232
3.24,13.5,15.36780508,1.56708
3.28,13.66668,15.43821683,1.57426
3.32,13.83331,15.45155387,1.57562
3.36,14,15.45900693,1.57638
3.4,14.16662,15.32524422,1.56274
3.44,14.33325,15.63866476,1.5947
3.48,14.5,15.47626663,1.57814
3.52,14.66669,15.56913561,1.58761
3.56,14.83331,15.50853051,1.58143
3.6,14.99994,15.62189538,1.59299
3.64,15.16662,15.68299081,1.59922
3.68,15.33331,15.75928655,1.607
3.72,15.50006,15.91472195,1.62285
3.76,15.66675,15.92040981,1.62343
3.8,15.83331,15.71074363,1.60205
3.84,16,16.13988264,1.64581
3.88,16.16669,15.83116929,1.61433
3.92,16.33331,15.85244973,1.6165
3.96,16.50006,16.13399865,1.64521
4,16.66668,16.26952655,1.65903
4.04,16.83337,16.32777805,1.66497
4.08,17.00006,16.22412176,1.6544
4.12,17.16662,16.1200732,1.64379
4.16,17.33325,16.21078472,1.65304
4.2,17.50006,16.37004471,1.66928
4.24,17.66669,16.09634111,1.64137
4.28,17.83331,16.28659012,1.66077
4.32,18.00006,16.32797418,1.66499
4.36,18.16675,16.26354449,1.65842
4.4,18.33331,16.28688432,1.6608
4.44,18.49993,16.5354829,1.68615
4.48,18.66662,16.46830735,1.6793
4.52,18.83331,16.45261671,1.6777
4.56,19.00012,16.43378794,1.67578
4.6,19.16668,16.37357511,1.66964
4.64,19.33318,16.46409049,1.67887
4.68,19.49994,16.32689545,1.66488
4.72,19.66675,16.64708257,1.69753
4.76,19.83331,16.58765428,1.69147
4.8,20.00006,16.67463926,1.70034
4.84,20.16668,16.75162146,1.70819
4.88,20.33331,16.83635092,1.71683
4.92,20.5,16.64708257,1.69753
4.96,20.66668,16.7497582,1.708
5,20.83331,16.7491698,1.70794
5.04,21.00006,16.96266057,1.72971
5.08,21.16675,16.76780244,1.70984
5.12,21.33325,17.09867881,1.74358
5.16,21.5,16.97207496,1.73067
5.2,21.66675,16.95412879,1.72884
5.24,21.83337,17.15114438,1.74893
5.28,22,17.05141075,1.73876
5.32,22.16668,17.01679328,1.73523
5.36,22.33325,17.1227051,1.74603
5.4,22.5,17.1408474,1.74788
5.44,22.66675,16.85272803,1.7185
5.48,22.83337,17.06170774,1.73981
5.52,23,17.16065684,1.7499
5.56,23.16668,17.28323996,1.7624
5.6,23.33331,17.22626332,1.75659
5.64,23.50006,17.38130646,1.7724
5.68,23.66675,17.58244085,1.79291
5.72,23.83331,17.29216401,1.76331
5.76,23.99993,17.30873725,1.765
5.8,24.16662,17.27912117,1.76198
5.84,24.33337,17.38415039,1.77269
5.88,24.50006,17.44671682,1.77907
5.92,24.66668,17.48398209,1.78287
5.96,24.83325,17.50585092,1.7851
6,24.99993,17.44328449,1.77872
6.04,25.16675,17.30324553,1.76444
6.08,25.3335,17.40454822,1.77477
6.12,25.50006,17.61833319,1.79657
6.16,25.6665,17.54517558,1.78911
6.2,25.83312,17.62068679,1.79681
6.24,26.00006,17.67060264,1.8019
6.28,26.16681,17.5533151,1.78994
6.32,26.33337,17.83515822,1.81868
6.36,26.50006,17.68374355,1.80324
6.4,26.66668,17.4935926,1.78385
6.44,26.83325,17.67795762,1.80265
6.48,27,17.5539035,1.79
6.52,27.16674,17.53850706,1.78843
6.56,27.33337,17.7529785,1.8103
6.6,27.50006,17.58381378,1.79305
6.64,27.66668,17.89743045,1.82503
6.68,27.83325,17.92116254,1.82745
6.72,28.00006,17.78789017,1.81386
6.76,28.16675,17.90360864,1.82566
6.8,28.33331,17.67638856,1.80249
6.84,28.5,17.65952112,1.80077
6.88,28.66668,17.88281854,1.82354
6.92,28.83331,17.76170641,1.81119
6.96,29.00006,17.85271213,1.82047
7,29.16669,17.95823168,1.83123
7.04,29.33318,18.01579672,1.8371
7.08,29.5,17.99137816,1.83461
7.12,29.66675,18.13700691,1.84946
7.16,29.83337,17.96235047,1.83165
7.2,30.00006,18.16122933,1.85193
7.24,30.16668,17.95038636,1.83043
7.28,30.33325,18.02805503,1.83835
7.32,30.49999,18.08620846,1.84428
7.36,30.66675,18.22428609,1.85836
7.4,30.83337,18.22928749,1.85887
7.44,31,18.16525006,1.85234
7.48,31.16662,18.09474025,1.84515
7.52,31.33331,18.2986205,1.86594
7.56,31.50006,18.25527511,1.86152
7.6,31.66674,18.08297227,1.84395
7.64,31.83331,18.18878602,1.85474
7.68,31.99993,18.49975489,1.88645
7.72,32.16668,18.32735399,1.86887
7.76,32.33337,18.38364416,1.87461
7.8,32.50006,18.46003796,1.8824
7.84,32.66674,18.24223226,1.86019
7.88,32.83331,18.41649643,1.87796
7.92,33,18.51201321,1.8877
7.96,33.16668,18.64734498,1.9015
8,33.33331,18.57654096,1.89428
8.04,33.49999,18.48524105,1.88497
8.08,33.66675,18.54241382,1.8908
8.12,33.83337,18.5907606,1.89573
8.16,34.00006,18.58713214,1.89536
8.2,34.16656,18.58938767,1.89559
8.24,34.33324,18.71952192,1.90886
8.28,34.49999,18.46984461,1.8834
8.32,34.66668,18.69431883,1.90629
8.36,34.83331,18.7084404,1.90773
8.4,35.00006,18.77581209,1.9146
8.44,35.16675,18.65146377,1.90192
8.48,35.33325,18.61527723,1.89823
8.52,35.49999,18.59350647,1.89601
8.56,35.66662,18.95046853,1.93241
8.6,35.83337,18.69775116,1.90664
8.64,36.00012,18.72589624,1.90951
8.68,36.16668,18.45925343,1.88232
8.72,36.33318,18.61861149,1.89857
8.76,36.5,18.87613412,1.92483
8.8,36.66668,18.82827767,1.91995
8.84,36.83337,18.82308014,1.91942
8.88,37.00006,18.7699281,1.914
8.92,37.16674,18.97547548,1.93496
8.96,37.33331,19.01087749,1.93857
9,37.49999,18.76894744,1.9139
9.04,37.66668,19.04931956,1.94249
9.08,37.83337,18.90271014,1.92754
9.12,38.00006,19.02715653,1.94023
9.16,38.16668,18.88378331,1.92561
9.2,38.33318,19.00283604,1.93775
9.24,38.5,19.01833054,1.93933
9.28,38.66674,19.04167037,1.94171
9.32,38.83331,19.11384732,1.94907
9.36,38.99999,18.90261207,1.92753
9.4,39.16662,19.21014862,1.95889
9.44,39.33324,19.20612789,1.95848
9.48,39.49999,19.22917352,1.96083
9.52,39.66675,19.25221915,1.96318
9.56,39.8333,19.15974244,1.95375
9.6,39.99999,19.21662101,1.95955
9.64,40.16662,19.22093593,1.95999
9.68,40.33331,19.1434634,1.95209
9.72,40.50006,19.46884805,1.98527
9.76,40.66675,19.32017923,1.97011
9.8,40.8333,19.44021263,1.98235
9.84,40.99993,19.35401217,1.97356
9.88,41.16668,19.4566878,1.98403
9.92,41.33337,19.43226924,1.98154
9.96,41.50006,19.36734922,1.97492
10,41.66668,19.62300858,2.00099
10.04,41.83325,19.44364496,1.9827
10.08,41.99999,19.36156329,1.97433
10.12,42.16681,19.42481619,1.98078
10.16,42.3335,19.49993513,1.98844
10.2,42.50005,19.52955121,1.99146
10.24,42.66656,19.71970215,2.01085
10.28,42.83318,19.73558893,2.01247
10.32,43.00006,19.48022376,1.98643
10.36,43.16675,19.68714407,2.00753
10.4,43.33337,19.76334175,2.0153
10.44,43.50006,19.84434467,2.02356
10.48,43.66662,19.58750851,1.99737
10.52,43.83324,19.81757252,2.02083
10.56,44,19.9835991,2.03776
10.6,44.16674,19.80639294,2.01969
10.64,44.33337,19.85317066,2.02446
10.68,44.49999,19.89033786,2.02825
10.72,44.66656,19.99575935,2.039
10.76,44.83324,19.89749672,2.02898
10.8,45.00006,20.03792795,2.0433
10.84,45.16675,20.10294603,2.04993
10.88,45.33324,19.88445387,2.02765
10.92,45.49999,19.99389609,2.03881
10.96,45.66668,20.21591864,2.06145
11,45.83337,20.39194801,2.0794
11.04,46.00006,20.19640341,2.05946
11.08,46.16662,20.05822771,2.04537
11.12,46.33325,20.06254264,2.04581
11.16,46.49999,20.35988026,2.07613
11.2,46.66674,20.06930923,2.0465
11.24,46.83337,20.15511741,2.05525
11.28,47.00006,20.31065088,2.07111
11.32,47.16668,20.31830007,2.07189
11.36,47.33331,20.42440802,2.08271
11.4,47.50005,20.21680124,2.06154
11.44,47.66674,20.24867285,2.06479
11.48,47.8333,20.34065923,2.07417
11.52,47.99999,20.3606648,2.07621
11.56,48.16668,20.28113287,2.0681
11.6,48.3333,20.45196471,2.08552
11.64,48.50006,20.51090267,2.09153
11.68,48.66675,20.54914861,2.09543
11.72,48.83324,20.53983229,2.09448
11.76,48.99999,20.62093329,2.10275
11.8,49.16668,20.45716223,2.08605
11.84,49.33331,20.62034489,2.10269
11.88,49.5,20.68026352,2.1088
11.92,49.66668,20.708997,2.11173
11.96,49.83325,20.87198353,2.12835
12,49.99993,20.86894347,2.12804
12.04,50.16668,20.98544647,2.13992
12.08,50.33331,20.87276806,2.12843
12.12,50.50005,20.93690355,2.13497
12.16,50.66674,20.66614194,2.10736
12.2,50.83337,20.93533449,2.13481
12.24,50.99999,21.04752256,2.14625
12.28,51.16662,21.04350184,2.14584
12.32,51.33331,20.90248221,2.13146
12.36,51.49999,20.87070866,2.12822
12.4,51.66662,20.92278197,2.13353
12.44,51.8333,21.23816384,2.16569
12.48,52.00006,21.04105017,2.14559
12.52,52.16674,21.08655303,2.15023
12.56,52.33331,21.03997144,2.14548
12.6,52.49999,21.31828417,2.17386
12.64,52.66662,21.00564817,2.14198
12.68,52.83337,21.27797884,2.16975
12.72,53.00011,21.33789747,2.17586
12.76,53.16662,21.16755596,2.15849
12.8,53.33318,21.25561968,2.16747
12.84,53.49993,21.34231046,2.17631
12.88,53.66674,21.48901795,2.19127
12.92,53.83337,21.41409514,2.18363
12.96,54.00006,21.31867644,2.1739
13,54.16668,21.52893101,2.19534
13.04,54.33324,21.48136876,2.19049
13.08,54.49993,21.56874601,2.1994
13.12,54.66668,21.57835653,2.20038
13.16,54.83331,21.71113857,2.21392
13.2,55.00006,21.61022814,2.20363
13.24,55.16662,21.41841007,2.18407
13.28,55.33325,21.5576645,2.19827
13.32,55.50005,21.67485396,2.21022
13.36,55.66674,21.61630826,2.20425
13.4,55.83331,21.66975451,2.2097
13.44,55.99999,21.67338297,2.21007
13.48,56.16668,21.87402702,2.23053
13.52,56.3333,21.7113347,2.21394
13.56,56.50006,21.78723817,2.22168
13.6,56.66674,21.89824945,2.233
13.64,56.83331,21.91599949,2.23481
13.68,56.99999,22.05780365,2.24927
13.72,57.16668,21.97268192,2.24059
13.76,57.3333,22.08938106,2.25249
13.8,57.50006,22.23726534,2.26757
13.84,57.66674,22.07869181,2.2514
13.88,57.83331,22.11203442,2.2548
13.92,57.99993,22.05819591,2.24931
13.96,58.16668,22.24971979,2.26884
14,58.33337,22.27453061,2.27137
14.04,58.50005,22.43290801,2.28752
14.08,58.66668,22.17450278,2.26117
14.12,58.83324,22.46203376,2.29049
14.16,58.99993,22.43928233,2.28817
14.2,59.16681,22.15802761,2.25949
14.24,59.33343,22.35818134,2.2799
14.28,59.49999,22.66660048,2.31135
14.32,59.66649,22.42927955,2.28715
14.36,59.83318,22.62148989,2.30675
14.4,60.00006,22.77300263,2.3222
14.44,60.16681,22.6905287,2.31379
14.48,60.33337,22.4789012,2.29221
14.52,60.5,22.6331598,2.30794
14.56,60.66662,22.47399787,2.29171
14.6,60.83325,22.64277032,2.30892
14.64,61.00005,22.65149824,2.30981
14.68,61.16674,22.81016983,2.32599
14.72,61.33337,22.76064625,2.32094
14.76,61.49999,22.80614911,2.32558
14.8,61.66662,22.77202197,2.3221
14.84,61.8333,22.86341994,2.33142
14.88,62.00006,22.9472668,2.33997
14.92,62.16674,22.9671743,2.342
14.96,62.33331,23.15820784,2.36148
15,62.49999,23.14232107,2.35986
15.04,62.66674,22.92392697,2.33759
15.08,62.83336,23.03072139,2.34848
15.12,63.00006,23.180567,2.36376
15.16,63.16661,23.04749076,2.35019
15.2,63.33324,23.26627713,2.3725
15.24,63.49999,23.3401212,2.38003
15.28,63.66674,23.15359872,2.36101
15.32,63.83337,23.27333791,2.37322
15.36,63.99999,23.51212984,2.39757
15.4,64.16667,23.42759652,2.38895
15.44,64.33324,23.48074856,2.39437
15.48,64.49999,23.38356466,2.38446
15.52,64.66674,23.53929426,2.40034
15.56,64.8333,23.42112413,2.38829
15.6,64.99999,23.74150738,2.42096
15.64,65.16661,23.47427617,2.39371
15.68,65.3333,23.56724321,2.40319
15.72,65.50005,23.60794081,2.40734
15.76,65.66674,23.52615335,2.399
15.8,65.83324,23.73258333,2.42005
15.84,65.99999,23.77857652,2.42474
15.88,66.16674,23.77641906,2.42452
15.92,66.33336,23.74650878,2.42147
15.96,66.50005,23.86330598,2.43338
16,66.66668,23.79711109,2.42663
16.04,66.83331,24.00952313,2.44829
16.08,66.99999,24.00344301,2.44767
16.12,67.16674,23.95774402,2.44301
16.16,67.33336,24.1240648,2.45997
16.2,67.50006,24.14789496,2.4624
16.24,67.66674,24.05669312,2.4531
16.28,67.83336,24.19457461,2.46716
16.32,67.99999,24.31166602,2.4791
16.36,68.16661,24.36167993,2.4842
16.4,68.3333,24.36746585,2.48479
16.44,68.49999,24.3187268,2.47982
16.48,68.66661,24.35873794,2.4839
16.52,68.8333,24.31725581,2.47967
16.56,69.00005,24.40679052,2.4888
16.6,69.16668,24.3415763,2.48215
16.64,69.33324,24.42454056,2.49061
16.68,69.49992,24.36197413,2.48423
16.72,69.66662,24.41267451,2.4894
16.76,69.83336,24.46739562,2.49498
16.8,70.00005,24.56291239,2.50472
16.84,70.16661,24.61125917,2.50965
16.88,70.33318,24.70236295,2.51894
16.92,70.49999,24.52702005,2.50106
16.96,70.66674,24.75973185,2.52479
17,70.83336,24.72687958,2.52144
17.04,71.00006,24.67666953,2.51632
17.08,71.16668,24.60910171,2.50943
17.12,71.33331,24.6949099,2.51818
17.16,71.49999,24.89829982,2.53892
17.2,71.66667,24.93409409,2.54257
17.24,71.83337,24.9891094,2.54818
17.28,72.00005,24.90742,2.53985
17.32,72.16667,25.01029176,2.55034
17.36,72.3333,25.23868864,2.57363
17.4,72.50005,25.1843598,2.56809
17.44,72.66674,25.19602971,2.56928
17.48,72.8333,25.18024101,2.56767
17.52,72.99999,25.34950378,2.58493
17.56,73.16662,25.24369003,2.57414
17.6,73.33324,25.24565136,2.57434
17.64,73.49999,25.42982025,2.59312
17.68,73.66674,25.23741378,2.5735
17.72,73.8333,25.45227748,2.59541
17.76,73.99999,25.34352173,2.58432
17.8,74.16661,25.42707439,2.59284
17.84,74.3333,25.43109511,2.59325
17.88,74.50006,25.52053176,2.60237
17.92,74.66668,25.46394739,2.5966
17.96,74.83324,25.51817816,2.60213
18,74.99993,25.60271149,2.61075
18.04,75.16674,25.57201667,2.60762
18.08,75.33337,25.65105827,2.61568
18.12,75.50005,25.63056237,2.61359
18.16,75.66668,25.67037737,2.61765
18.2,75.83324,25.92897873,2.64402
18.24,76.00005,25.61114521,2.61161
18.28,76.16686,26.0476392,2.65612
18.32,76.33343,25.98007138,2.64923
18.36,76.49993,25.95555475,2.64673
18.4,76.66649,26.07568622,2.65898
18.44,76.8333,25.8137506,2.63227
18.48,77.00011,25.99115289,2.65036
18.52,77.1668,25.87278663,2.63829
18.56,77.33336,26.19983841,2.67164
18.6,77.49998,26.0452856,2.65588
18.64,77.66668,26.03145823,2.65447
18.68,77.83331,26.33036492,2.68495
18.72,77.99999,26.38410536,2.69043
18.76,78.16668,26.20807599,2.67248
18.8,78.3333,26.29339385,2.68118
18.84,78.49999,26.2232763,2.67403
18.88,78.66655,26.54768028,2.70711
18.92,78.8333,26.46834448,2.69902
18.96,79.00004,26.39008742,2.69104
19,79.16674,26.57445244,2.70984
19.04,79.33323,26.55346621,2.7077
19.08,79.49999,26.78823741,2.73164
19.12,79.66667,26.46216629,2.69839
19.16,79.8333,26.77460616,2.73025
19.2,79.99999,26.78137275,2.73094
19.24,80.16662,26.88679424,2.74169
19.28,80.33324,26.76862411,2.72964
19.32,80.50005,26.87816439,2.74081
19.36,80.6668,26.91680259,2.74475
19.4,80.83336,26.88326384,2.74133
19.44,81.00005,26.99584419,2.75281
19.48,81.16661,26.81177337,2.73404
19.52,81.3333,27.00045331,2.75328
19.56,81.50005,27.1082284,2.76427
19.6,81.66674,27.20982529,2.77463
19.64,81.83324,27.24787509,2.77851
19.68,81.99998,27.25483781,2.77922
19.72,82.16668,27.20796203,2.77444
19.76,82.33336,27.39007152,2.79301
19.8,82.50005,27.23649938,2.77735
19.84,82.66667,27.36241676,2.79019
19.88,82.83324,27.30043874,2.78387
19.92,82.99999,27.52559942,2.80683
19.96,83.16674,27.47107445,2.80127
20,83.3333,27.49980793,2.8042
20.04,83.49999,27.57531914,2.8119
20.08,83.66668,27.58355672,2.81274
20.12,83.83323,27.68711495,2.8233
20.16,83.99999,27.89874245,2.84488
20.2,84.16668,27.6755431,2.82212
20.24,84.3333,27.73330427,2.82801
20.28,84.49999,27.80440248,2.83526
20.32,84.66667,27.86893024,2.84184
20.36,84.8333,27.8678515,2.84173
20.4,84.99992,27.95758235,2.85088
20.44,85.16661,28.10723183,2.86614
20.48,85.3333,28.13861311,2.86934
20.52,85.50005,28.09261992,2.86465
20.56,85.66667,28.16950406,2.87249
20.6,85.83336,28.26845316,2.88258
20.64,86.00005,28.19921821,2.87552
20.68,86.16674,28.18588116,2.87416
20.72,86.3333,28.25168379,2.88087
20.76,86.49993,28.26266723,2.88199
20.8,86.66674,28.23334535,2.879
20.84,86.83342,28.40143133,2.89614
20.88,87.00005,28.26492276,2.88222
20.92,87.16661,28.61835443,2.91826
20.96,87.33324,28.3037571,2.88618
21,87.49999,28.45154331,2.90125
21.04,87.66667,28.45526984,2.90163
21.08,87.8333,28.43457781,2.89952
21.12,88.00005,28.52940811,2.90919
21.16,88.16668,28.60384059,2.91678
21.2,88.33324,28.6559139,2.92209
21.24,88.49998,28.64306719,2.92078
21.28,88.66673,28.76525805,2.93324
21.32,88.83336,28.70837948,2.92744
21.36,88.99999,28.94540621,2.95161
21.4,89.16661,28.9884574,2.956
21.44,89.33323,29.01424889,2.95863
21.48,89.50005,28.91990892,2.94901
21.52,89.66674,28.8912735,2.94609
21.56,89.83323,28.90372794,2.94736
21.6,89.99993,29.05886915,2.96318
21.64,90.16661,29.05651555,2.96294
21.68,90.3333,29.07563852,2.96489
21.72,90.50005,29.35708937,2.99359
21.76,90.66674,29.28020524,2.98575
21.8,90.8333,29.26353393,2.98405
21.84,90.99999,29.34071227,2.99192
21.88,91.16667,29.27745938,2.98547
21.92,91.3333,29.37935047,2.99586
21.96,91.50005,29.33453408,2.99129
22,91.66674,29.54831905,3.01309
22.04,91.8333,29.50399299,3.00857
22.08,91.99998,29.49908967,3.00807
22.12,92.16674,29.63000844,3.02142
22.16,92.33336,29.56695168,3.01499
22.2,92.50005,29.63765763,3.0222
22.24,92.66661,29.62726258,3.02114
22.28,92.83324,29.69012321,3.02755
22.32,92.99998,29.72797688,3.03141
22.36,93.1668,29.734057,3.03203
22.4,93.33336,29.91508776,3.05049
22.44,93.49986,29.94117345,3.05315
22.48,93.66655,29.75523936,3.03419
22.52,93.83329,30.07268062,3.06656
22.56,94.00005,30.09945278,3.06929
22.6,94.16673,29.96696494,3.05578
22.64,94.33337,30.14132717,3.07356
22.68,94.49992,30.24714093,3.08435
22.72,94.66661,30.23478455,3.08309
22.76,94.83323,30.25861471,3.08552
22.8,95.00004,30.23066576,3.08267
22.84,95.16673,30.10798456,3.07016
22.88,95.3333,30.51554894,3.11172
22.92,95.49998,30.46514276,3.10658
22.96,95.66661,30.40041887,3.09998
23,95.83335,30.47485134,3.10757
23.04,96.00011,30.59282534,3.1196
23.08,96.16667,30.51878513,3.11205
23.12,96.3333,30.598219,3.12015
23.16,96.49999,30.7366889,3.13427
23.2,96.66674,30.7717967,3.13785
23.24,96.83336,30.90448068,3.15138
23.28,96.99998,30.87839499,3.14872
23.32,97.16667,30.90977627,3.15192
23.36,97.3333,30.71540847,3.1321
23.4,97.50005,30.88790744,3.14969
23.44,97.66674,31.07599899,3.16887
23.48,97.83329,30.99989938,3.16111
23.52,97.99998,30.87604139,3.14848
23.56,98.16661,31.20780036,3.18231
23.6,98.33329,31.07305699,3.16857
23.64,98.50005,31.23623965,3.18521
23.68,98.66667,31.20701583,3.18223
23.72,98.83324,31.31047599,3.19278
23.76,98.99999,31.27487785,3.18915
23.8,99.16667,31.20015117,3.18153
23.84,99.3333,31.30204227,3.19192
23.88,99.50005,31.18867739,3.18036
23.92,99.66668,31.17563455,3.17903
23.96,99.83324,31.48424983,3.2105
24,99.99998,31.49395841,3.21149
24.04,100.16668,31.52720295,3.21488
24.08,100.3333,31.72833734,3.23539
24.12,100.50005,31.64851121,3.22725
24.16,100.66673,31.83915249,3.24669
24.2,100.83323,31.853176,3.24812
24.24,101.00004,31.68705135,3.23118
24.28,101.16674,31.8332685,3.24609
24.32,101.33336,32.06244991,3.26946
24.36,101.50004,32.14963103,3.27835
24.4,101.6668,32.0291073,3.26606
24.44,101.83336,32.20954966,3.28446
24.48,101.99999,32.23661601,3.28722
24.52,102.16667,32.06294024,3.26951
24.56,102.3333,32.02077165,3.26521
24.6,102.49998,32.15649568,3.27905
24.64,102.66667,32.27397935,3.29103
24.68,102.83336,32.21455105,3.28497
24.72,103.00005,32.15276916,3.27867
24.76,103.16667,32.29859404,3.29354
24.8,103.33324,32.46756262,3.31077
24.84,103.49993,32.47285821,3.31131
24.88,103.66674,32.32222807,3.29595
24.92,103.83342,32.65182957,3.32956
24.96,104.00005,32.634766,3.32782
25,104.1666,32.61338751,3.32564
25.04,104.33324,32.64143453,3.3285
25.08,104.49998,32.62917621,3.32725
25.12,104.66673,32.69811696,3.33428
25.16,104.83336,32.76539058,3.34114
25.2,104.99999,32.75254387,3.33983
25.24,105.16661,32.92455251,3.35737
25.28,105.33324,33.03683865,3.36882
25.32,105.49999,32.99476812,3.36453
25.36,105.66667,32.8724792,3.35206
25.4,105.83336,32.92121825,3.35703
25.44,106.00004,32.96897664,3.3619
25.48,106.16668,33.03948645,3.36909
25.52,106.3333,33.31044419,3.39672
25.56,106.50005,33.3631059,3.40209
25.6,106.66673,33.25748828,3.39132
25.64,106.8333,33.17354335,3.38276
25.68,106.99999,33.1663845,3.38203
25.72,107.16667,33.40331316,3.40619
25.76,107.3333,33.38507279,3.40433
25.8,107.50005,33.35516251,3.40128
25.84,107.66667,33.46617379,3.4126
25.88,107.8333,33.50059513,3.41611
25.92,107.99998,33.46519313,3.4125
25.96,108.16667,33.64975428,3.43132
26,108.3333,33.51412831,3.41749
26.04,108.50005,33.80793554,3.44745
26.08,108.66667,33.77547553,3.44414
26.12,108.83324,33.84216075,3.45094
26.16,108.99998,33.69172674,3.4356
26.2,109.16674,33.61523487,3.4278
26.24,109.33336,33.87952409,3.45475
26.28,109.49999,33.76429595,3.443
26.32,109.66661,34.01318873,3.46838
26.36,109.83324,34.35357755,3.50309
26.4,110.00005,34.21510765,3.48897
26.44,110.16686,34.22962149,3.49045
26.48,110.33336,34.22324717,3.4898
26.52,110.49986,34.37436765,3.50521
26.56,110.66655,34.30856503,3.4985
26.6,110.83336,34.46988442,3.51495
26.64,111.00011,34.55284868,3.52341
26.68,111.1668,34.5601056,3.52415
26.72,111.3333,34.46684436,3.51464
26.76,111.49992,34.57187358,3.52535
26.8,111.66661,34.35053749,3.50278
26.84,111.8333,34.62835988,3.53111
26.88,112.00004,34.68366939,3.53675
26.92,112.16674,34.72799545,3.54127
26.96,112.3333,34.72348439,3.54081
27,112.49992,34.84861724,3.55357
27.04,112.66661,34.79046381,3.54764
27.08,112.83336,35.00258165,3.56927
27.12,113.00005,34.8112539,3.54976
27.16,113.16667,34.96306085,3.56524
27.2,113.33324,34.98237995,3.56721
27.24,113.49998,35.07887738,3.57705
27.28,113.66673,35.20773676,3.59019
27.32,113.8333,35.13673662,3.58295
27.36,113.99998,35.0668152,3.57582
27.4,114.16661,34.95080253,3.56399
27.44,114.33324,35.21214976,3.59064
27.48,114.49998,35.44142923,3.61402
27.52,114.66667,35.15664412,3.58498
27.56,114.8333,35.36228957,3.60595
27.6,114.99998,35.38827719,3.6086
27.64,115.1666,35.54881205,3.62497
27.68,115.3333,35.57372094,3.62751
27.72,115.50005,35.80152942,3.65074
27.76,115.66673,35.78593685,3.64915
27.8,115.83329,35.64452495,3.63473
27.84,115.99999,35.67051258,3.63738
27.88,116.16673,35.61059395,3.63127
27.92,116.33337,35.58519472,3.62868
27.96,116.50004,35.87753096,3.65849
28,116.66667,35.8340875,3.65406
28.04,116.83323,35.91234457,3.66204
28.08,117.00004,35.92362221,3.66319
28.12,117.16673,35.72474335,3.64291
28.16,117.33335,35.90842191,3.66164
28.2,117.50005,35.93087913,3.66393
28.24,117.66667,36.04640147,3.67571
28.28,117.83324,36.22586317,3.69401
28.32,117.99999,36.27146409,3.69866
28.36,118.16673,36.286076,3.70015
28.4,118.3333,36.40963979,3.71275
28.44,118.50005,36.43415641,3.71525
28.48,118.66674,36.39081102,3.71083
28.52,118.8333,36.05807139,3.6769
28.56,118.99998,36.53791077,3.72583
28.6,119.16667,36.70079923,3.74244
28.64,119.33323,36.44023654,3.71587
28.68,119.49998,36.39904861,3.71167
28.72,119.66667,36.48956399,3.7209
28.76,119.83336,36.56262353,3.72835
28.8,120.00005,36.55821054,3.7279
28.84,120.16667,36.56988045,3.72909
28.88,120.33324,36.61263744,3.73345
28.92,120.49999,36.80504392,3.75307
28.96,120.6668,36.68814865,3.74115
29,120.83342,36.86309928,3.75899
29.04,120.99999,37.15416066,3.78867
29.08,121.16661,36.82338235,3.75494
29.12,121.33324,36.95302626,3.76816
29.16,121.50005,37.08541604,3.78166
29.2,121.66673,36.88741978,3.76147
29.24,121.83336,37.09757629,3.7829
29.28,122.00005,37.07855138,3.78096
29.32,122.16668,37.29459188,3.80299
29.36,122.3333,37.26115121,3.79958
29.4,122.49999,37.36519976,3.81019
29.44,122.66668,37.46885605,3.82076
29.48,122.8333,37.30763473,3.80432
29.52,122.99999,37.35902157,3.80956
29.56,123.16661,37.45512674,3.81936
29.6,123.3333,37.29694548,3.80323
29.64,123.50004,37.33676048,3.80729
29.68,123.66674,37.58074993,3.83217
29.72,123.8333,37.53132441,3.82713
29.76,123.99992,37.82189545,3.85676
29.8,124.16661,37.66351806,3.84061
29.84,124.3333,37.63478457,3.83768
29.88,124.50005,37.71235517,3.84559
29.92,124.66667,37.69656647,3.84398
29.96,124.83324,38.07353409,3.88242
30,124.99992,37.82591618,3.85717
30.04,125.16673,38.00263201,3.87519
30.08,125.33336,37.81787473,3.85635
30.12,125.50004,38.02430471,3.8774
30.16,125.66666,37.97468306,3.87234
30.2,125.83323,38.03930888,3.87893
30.24,126.00005,38.25299579,3.90072
30.28,126.16679,38.02499118,3.87747
30.32,126.33336,38.15002596,3.89022
30.36,126.50005,38.26446957,3.90189
30.4,126.6666,38.17807298,3.89308
30.44,126.83329,38.2040606,3.89573
30.48,127.00011,38.34988549,3.9106
30.52,127.1668,38.31114922,3.90665
30.56,127.33328,38.56494532,3.93253
30.6,127.49985,38.31134536,3.90667
30.64,127.66661,38.50375183,3.92629
30.68,127.83329,38.60799652,3.93692
30.72,128.00003,38.4812946,3.924
30.76,128.16672,38.49394518,3.92529
30.8,128.33329,38.69311824,3.9456
30.84,128.49991,38.52405159,3.92836
30.88,128.66661,38.73234484,3.9496
30.92,128.8333,38.7754941,3.954
30.96,128.99998,38.82599835,3.95915
31,129.16672,38.80197206,3.9567
31.04,129.33329,38.66869968,3.94311
31.08,129.49985,38.57681137,3.93374
31.12,129.66667,38.57230031,3.93328
31.16,129.83336,38.50845902,3.92677
31.2,130.00011,37.98282258,3.87317
31.24,130.16666,21.81891365,2.22491
31.28,130.3333,-1.396270827,-0.14238
31.32,130.50004,-0.821110805,-0.08373
31.36,130.66679,-0.425510544,-0.04339
31.4,130.83336,-0.401484251,-0.04094
31.44,130.99998,0.016475172,0.00168
31.48,131.16667,-0.223493554,-0.02279
31.52,131.33335,-0.153081807,-0.01561
31.56,131.50004,-0.337054561,-0.03437
31.6,131.6668,-0.128957448,-0.01315
31.64,131.83336,-0.196133,-0.02
31.68,131.99999,-0.208881645,-0.0213
31.72,132.16667,0.019319101,0.00197
31.76,132.33329,-0.154454738,-0.01575
31.8,132.50004,-0.179265562,-0.01828
31.84,132.66667,-0.171812508,-0.01752
31.88,132.83323,-0.215844367,-0.02201
31.92,132.99991,-0.354510398,-0.03615
31.96,133.16668,-0.279489525,-0.0285
32,133.33336,-0.177500365,-0.0181
32.04,133.50004,-0.216726965,-0.0221
32.08,133.66661,-0.102479493,-0.01045
32.12,133.83323,-0.285079316,-0.02907
32.16,133.99998,-0.48670404,-0.04963
32.2,134.16673,-0.297337628,-0.03032
32.24,134.33329,-0.315872197,-0.03221
32.28,134.49999,-0.309301741,-0.03154
32.32,134.66661,-0.228985278,-0.02335
32.36,134.83323,0.026870221,0.00274
32.4,134.99998,-0.169556979,-0.01729
32.44,135.16674,-0.299397025,-0.03053
32.48,135.33329,-0.208489379,-0.02126
32.52,135.50005,-0.22192449,-0.02263
32.56,135.66679,-0.29812216,-0.0304
32.6,135.8333,-0.214177236,-0.02184
32.64,135.99998,-0.117483667,-0.01198
32.68,136.16666,-0.211137175,-0.02153
32.72,136.33328,0.104440823,0.01065
32.76,136.50005,-0.090809579,-0.00926
32.8,136.66674,-0.191425808,-0.01952
32.84,136.83336,-0.299200892,-0.03051
32.88,137.00004,-0.233496337,-0.02381
32.92,137.16667,-0.244087519,-0.02489
32.96,137.33323,-0.218099896,-0.02224
33,137.49997,-0.296945362,-0.03028
33.04,137.66673,-0.404818512,-0.04128
33.08,137.83336,-0.310282406,-0.03164
33.12,137.99998,-0.227416214,-0.02319
33.16,138.16661,-0.048346785,-0.00493
33.2,138.33323,-0.367455176,-0.03747
33.24,138.50003,-0.26477955,-0.027
33.28,138.66673,-0.246735314,-0.02516
33.32,138.83336,-0.083356525,-0.0085
33.36,138.99999,-0.169851178,-0.01732
33.4,139.16661,-0.157298666,-0.01604
33.44,139.33323,-0.257620696,-0.02627
33.48,139.49998,-0.350097405,-0.0357
33.52,139.66672,-0.183972754,-0.01876
33.56,139.83329,-0.190052877,-0.01938
33.6,139.99998,-0.171126043,-0.01745
33.64,140.16667,-0.248108245,-0.0253
33.68,140.33335,-0.428354472,-0.04368
33.72,140.5001,-0.31185147,-0.0318
33.76,140.66666,-0.201722791,-0.02057
33.8,140.83329,-0.335779696,-0.03424
33.84,140.99997,-0.250756041,-0.02557
33.88,141.16667,-0.418547822,-0.04268
33.92,141.33336,-0.203782187,-0.02078
33.96,141.50004,-0.259876225,-0.0265
34,141.66667,-0.149845612,-0.01528
34.04,141.83329,-0.486507907,-0.04961
34.08,141.99997,-0.23339827,-0.0238
34.12,142.16674,-0.304790682,-0.03108
34.16,142.33336,-0.357354326,-0.03644
34.2,142.50005,-0.251834772,-0.02568
34.24,142.66667,-0.324011716,-0.03304
34.28,142.83324,-0.137979566,-0.01407
34.32,142.99998,-0.172498974,-0.01759
34.36,143.16666,-0.194563936,-0.01984
34.4,143.33329,-0.307438478,-0.03135
34.44,143.49997,-0.110226746,-0.01124
34.458,143.57491,-0.142490625,-0.01453