File: FR/FR/RDSO FR Tensile 250.is_tens_RawData/Specimen_RawData_4.csv
Time,Extension,Load,
(sec),(mm),(N),(kgf)
0,0,0.556821587,0.05678
0.04,0.06794,1.048625085,0.10693
0.08,0.27781,1.837079745,0.18733
0.12,0.48256,2.079696266,0.21207
0.16,0.65519,2.777047147,0.28318
0.2,0.82412,3.337889461,0.34037
0.24,0.99494,3.804686001,0.38797
0.28,1.16406,4.201561126,0.42844
0.32,1.33162,4.810259892,0.49051
0.36,1.49894,5.076510439,0.51766
0.4,1.666,5.365316282,0.54711
0.44,1.83294,5.665399772,0.57771
0.48,1.99987,6.123174194,0.62439
0.52,2.16669,6.504162546,0.66324
0.56,2.33312,6.691567628,0.68235
0.6,2.49987,6.951934185,0.7089
0.64,2.66669,7.295363068,0.74392
0.68,2.83337,7.51581656,0.7664
0.72,3.00006,7.763630606,0.79167
0.76,3.16675,7.797169349,0.79509
0.8,3.33325,8.121573331,0.82817
0.84,3.49994,8.486772977,0.86541
0.88,3.66662,8.607885104,0.87776
0.92,3.83331,8.890905023,0.90662
0.96,4.00006,9.061148467,0.92398
1,4.16669,9.295429336,0.94787
1.04,4.33325,9.502447717,0.96898
1.08,4.5,9.640623416,0.98307
1.12,4.66675,9.917465145,1.0113
1.16,4.83337,9.907854628,1.01032
1.2,5,10.11693241,1.03164
1.24,5.16662,10.33081544,1.05345
1.28,5.33325,10.30590655,1.05091
1.32,5.50006,10.5917704,1.08006
1.36,5.66675,10.93755288,1.11532
1.4,5.83337,11.1011278,1.132
1.44,6,11.18762245,1.14082
1.48,6.16669,11.30618485,1.15291
1.52,6.33331,11.30069313,1.15235
1.56,6.5,11.6728555,1.1903
1.6,6.66669,11.70217738,1.19329
1.64,6.83331,11.74964156,1.19813
1.68,7,11.99627881,1.22328
1.72,7.16662,12.11307601,1.23519
1.76,7.33337,12.26753075,1.25094
1.8,7.50006,12.38864288,1.26329
1.84,7.66675,12.38177822,1.26259
1.88,7.83331,12.45366097,1.26992
1.92,7.99994,12.57761702,1.28256
1.96,8.16669,12.73746542,1.29886
2,8.3335,12.84896703,1.31023
2.04,8.50019,12.89554862,1.31498
2.08,8.66656,12.97998387,1.32359
2.12,8.83306,13.0434329,1.33006
2.16,9,13.2568256,1.35182
2.2,9.16681,13.45874453,1.37241
2.24,9.33337,13.45148761,1.37167
2.28,9.50006,13.42334252,1.3688
2.32,9.66662,13.46688405,1.37324
2.36,9.83319,13.6333029,1.39021
2.4,10,13.56553895,1.3833
2.44,10.16675,13.85905198,1.41323
2.48,10.33331,13.80894,1.40812
2.52,10.50006,13.90023991,1.41743
2.56,10.66669,14.08695853,1.43647
2.6,10.83325,14.08597786,1.43637
2.64,11.00006,14.20169633,1.44817
2.68,11.16681,14.20493253,1.4485
2.72,11.33331,14.17570871,1.44552
2.76,11.49994,14.15393795,1.4433
2.8,11.66669,14.2597517,1.45409
2.84,11.83331,14.47412507,1.47595
2.88,12.00006,14.21209138,1.44923
2.92,12.16669,14.51168454,1.47978
2.96,12.33325,14.57797749,1.48654
3,12.5,14.59298167,1.48807
3.04,12.66675,14.82098628,1.51132
3.08,12.83337,14.59572753,1.48835
3.12,13.00006,14.73409936,1.50246
3.16,13.16669,14.92640777,1.52207
3.2,13.33325,14.93121302,1.52256
3.24,13.5,15.05438455,1.53512
3.28,13.66675,14.94817853,1.52429
3.32,13.83331,15.05173675,1.53485
3.36,14,15.02368973,1.53199
3.4,14.16662,15.16912235,1.54682
3.44,14.33325,15.26003,1.55609
3.48,14.5,15.38349572,1.56868
3.52,14.66675,15.37241421,1.56755
3.56,14.83331,15.55903476,1.58658
3.6,14.99994,15.24502582,1.55456
3.64,15.16662,15.30955358,1.56114
3.68,15.33337,15.31347624,1.56154
3.72,15.50006,15.56256515,1.58694
3.76,15.66675,15.59963429,1.59072
3.8,15.83331,15.43880523,1.57432
3.84,16,15.67318416,1.59822
3.88,16.16669,15.7910601,1.61024
3.92,16.33331,15.61385393,1.59217
3.96,16.50006,15.79812088,1.61096
4,16.66668,15.87775088,1.61908
4.04,16.83337,15.81665545,1.61285
4.08,17.00006,15.69799499,1.60075
4.12,17.16669,15.84127014,1.61536
4.16,17.33325,15.84176048,1.61541
4.2,17.50006,16.01729951,1.63331
4.24,17.66669,15.95993061,1.62746
4.28,17.83331,16.02995009,1.6346
4.32,18.00006,16.22569082,1.65456
4.36,18.16675,16.04377747,1.63601
4.4,18.33331,16.21382478,1.65335
4.44,18.49993,16.12919339,1.64472
4.48,18.66662,16.04407167,1.63604
4.52,18.83331,16.14625696,1.64646
4.56,19.00006,16.31757913,1.66393
4.6,19.16668,16.16184953,1.64805
4.64,19.33318,16.21304025,1.65327
4.68,19.49994,16.32954325,1.66515
4.72,19.66675,16.34739135,1.66697
4.76,19.83331,16.36553365,1.66882
4.8,20.00006,16.24049887,1.65607
4.84,20.16668,16.38122429,1.67042
4.88,20.33331,16.58235868,1.69093
4.92,20.5,16.61079797,1.69383
4.96,20.66668,16.47124934,1.6796
5,20.83331,16.49066651,1.68158
5.04,21.00006,16.37151571,1.66943
5.08,21.16668,16.49096071,1.68161
5.12,21.33325,16.46938608,1.67941
5.16,21.5,16.61491676,1.69425
5.2,21.66675,16.51106434,1.68366
5.24,21.83337,16.47742753,1.68023
5.28,22,16.47203387,1.67968
5.32,22.16668,16.75809385,1.70885
5.36,22.33325,16.78280661,1.71137
5.4,22.5,16.89342562,1.72265
5.44,22.66675,16.93000443,1.72638
5.48,22.83337,16.77917815,1.711
5.52,23,16.85949461,1.71919
5.56,23.16668,16.71278713,1.70423
5.6,23.33331,16.71013933,1.70396
5.64,23.50006,16.79888952,1.71301
5.68,23.66675,16.99717998,1.73323
5.72,23.83331,17.02355987,1.73592
5.76,23.99993,16.89342562,1.72265
5.8,24.16662,16.91068533,1.72441
5.84,24.33337,17.00630016,1.73416
5.88,24.50006,17.10240533,1.74396
5.92,24.66668,16.94304727,1.72771
5.96,24.83325,16.9857062,1.73206
6,24.99993,17.19743177,1.75365
6.04,25.16675,17.24558242,1.75856
6.08,25.3335,17.12192057,1.74595
6.12,25.50006,17.00630016,1.73416
6.16,25.6665,17.24970122,1.75898
6.2,25.83312,17.28902588,1.76299
6.24,26.00006,17.10377827,1.7441
6.28,26.16675,17.17065962,1.75092
6.32,26.33337,17.11270232,1.74501
6.36,26.50006,17.24597469,1.7586
6.4,26.66668,17.26676479,1.76072
6.44,26.83325,17.44053863,1.77844
6.48,27,17.48898348,1.78338
6.52,27.16674,17.40984381,1.77531
6.56,27.33337,17.5749878,1.79215
6.6,27.50006,17.48172656,1.78264
6.64,27.66668,17.47221411,1.78167
6.68,27.83325,17.41916013,1.77626
6.72,28.00006,17.52507195,1.78706
6.76,28.16675,17.50241859,1.78475
6.8,28.33331,17.65520619,1.80033
6.84,28.5,17.55223637,1.78983
6.88,28.66668,17.52791588,1.78735
6.92,28.83331,17.40621535,1.77494
6.96,29.00006,17.64834154,1.79963
7,29.16669,17.48231496,1.7827
7.04,29.33318,17.64216335,1.799
7.08,29.5,17.63588709,1.79836
7.12,29.66675,17.573811,1.79203
7.16,29.83337,17.91939735,1.82727
7.2,30.00006,17.85761545,1.82097
7.24,30.16668,17.88075914,1.82333
7.28,30.33325,17.83221623,1.81838
7.32,30.49999,17.71757649,1.80669
7.36,30.66675,17.70247425,1.80515
7.4,30.83337,17.90498157,1.8258
7.44,31,17.93194986,1.82855
7.48,31.16668,17.8100532,1.81612
7.52,31.33331,18.0626725,1.84188
7.56,31.50006,17.94293331,1.82967
7.6,31.66674,17.99441822,1.83492
7.64,31.83331,18.17182052,1.85301
7.68,31.99993,17.87840555,1.82309
7.72,32.16668,17.93155759,1.82851
7.76,32.33337,18.11749168,1.84747
7.8,32.50006,18.19290481,1.85516
7.84,32.66668,18.16789786,1.85261
7.88,32.83331,18.00952046,1.83646
7.92,33,18.06129957,1.84174
7.96,33.16668,18.21261618,1.85717
8,33.33331,18.09974164,1.84566
8.04,33.49999,18.10386043,1.84608
8.08,33.66668,18.15554148,1.85135
8.12,33.83337,18.25203891,1.86119
8.16,34.00006,18.23468114,1.85942
8.2,34.16662,18.12170854,1.8479
8.24,34.33324,18.21800984,1.85772
8.28,34.49999,18.21379298,1.85729
8.32,34.66668,18.23458308,1.85941
8.36,34.83331,18.2590997,1.86191
8.4,35.00006,18.34745762,1.87092
8.44,35.16675,18.40060966,1.87634
8.48,35.33331,18.4947535,1.88594
8.52,35.49999,18.58938767,1.89559
8.56,35.66662,18.50034329,1.88651
8.6,35.83337,18.46052829,1.88245
8.64,36.00012,18.60507831,1.89719
8.68,36.16668,18.53143037,1.88968
8.72,36.33318,18.47906286,1.88434
8.76,36.5,18.5143668,1.88794
8.8,36.66668,18.80003452,1.91707
8.84,36.83337,18.90221981,1.92749
8.88,37.00006,18.54466935,1.89103
8.92,37.16674,18.64754111,1.90152
8.96,37.33331,18.48582945,1.88503
9,37.49999,18.69186717,1.90604
9.04,37.66668,18.66705634,1.90351
9.08,37.83337,18.74737281,1.9117
9.12,38.00006,18.61988636,1.8987
9.16,38.16668,18.92526544,1.92984
9.2,38.33324,18.93467982,1.9308
9.24,38.5,18.73491836,1.91043
9.28,38.66674,18.77855795,1.91488
9.32,38.83331,19.11502411,1.94919
9.36,38.99993,18.9259519,1.92991
9.4,39.16662,18.90104301,1.92737
9.44,39.33324,18.95390085,1.93276
9.48,39.50006,18.89525709,1.92678
9.52,39.66675,18.89015763,1.92626
9.56,39.8333,18.96586497,1.93398
9.6,39.99999,19.02441067,1.93995
9.64,40.16662,18.90996706,1.92828
9.68,40.33331,19.03284439,1.94081
9.72,40.50006,19.2233876,1.96024
9.76,40.66675,19.15787917,1.95356
9.8,40.8333,19.17229495,1.95503
9.84,40.99999,19.28026617,1.96604
9.88,41.16668,19.2798739,1.966
9.92,41.33337,19.25496501,1.96346
9.96,41.50006,18.97802521,1.93522
10,41.66668,19.11159179,1.94884
10.04,41.83325,19.16346896,1.95413
10.08,41.99999,19.33077041,1.97119
10.12,42.16681,19.10776719,1.94845
10.16,42.3335,19.27075372,1.96507
10.2,42.50005,19.34067513,1.9722
10.24,42.66656,19.49091301,1.98752
10.28,42.83318,19.46757318,1.98514
10.32,43.00006,19.45119608,1.98347
10.36,43.16675,19.73598119,2.01251
10.4,43.33337,19.43158278,1.98147
10.44,43.50006,19.42403166,1.9807
10.48,43.66662,19.44315462,1.98265
10.52,43.83324,19.44217396,1.98255
10.56,44,19.73872705,2.01279
10.6,44.16674,19.54818384,1.99336
10.64,44.33337,19.58858724,1.99748
10.68,44.49999,19.63183457,2.00189
10.72,44.66656,19.46296406,1.98467
10.76,44.83324,19.57662313,1.99626
10.8,45.00006,19.60221849,1.99887
10.84,45.16675,19.70195212,2.00904
10.88,45.33324,19.76245915,2.01521
10.92,45.49999,19.7289204,2.01179
10.96,45.66668,19.58741044,1.99736
11,45.83337,19.78766224,2.01778
11.04,46.00006,19.82835983,2.02193
11.08,46.16662,19.71058197,2.00992
11.12,46.33325,19.82492751,2.02158
11.16,46.49999,19.91554095,2.03082
11.2,46.66674,19.95751342,2.0351
11.24,46.83331,19.97879385,2.03727
11.28,47.00006,19.94143051,2.03346
11.32,47.16668,19.90210584,2.02945
11.36,47.33331,19.97251759,2.03663
11.4,47.50005,20.16286467,2.05604
11.44,47.66674,20.12108834,2.05178
11.48,47.8333,20.16178593,2.05593
11.52,47.99999,19.95653275,2.035
11.56,48.16662,20.47402967,2.08777
11.6,48.3333,20.27132622,2.0671
11.64,48.50006,20.27760247,2.06774
11.68,48.66675,20.39557647,2.07977
11.72,48.83324,20.28407486,2.0684
11.76,48.99999,20.25573364,2.06551
11.8,49.16668,20.46932248,2.08729
11.84,49.33331,20.68908951,2.1097
11.88,49.5,20.26406929,2.06636
11.92,49.66668,20.19228462,2.05904
11.96,49.83325,20.36978498,2.07714
12,49.99993,20.32810672,2.07289
12.04,50.16668,20.27966187,2.06795
12.08,50.33331,20.67938092,2.10871
12.12,50.50005,20.4748142,2.08785
12.16,50.66674,20.62054102,2.10271
12.2,50.83337,20.70978154,2.11181
12.24,50.99999,20.50815681,2.09125
12.28,51.16662,20.54728535,2.09524
12.32,51.33331,20.58003956,2.09858
12.36,51.49999,20.59288627,2.09989
12.4,51.66668,20.50835295,2.09127
12.44,51.8333,20.58258929,2.09884
12.48,52.00006,20.79608006,2.12061
12.52,52.16674,20.80372924,2.12139
12.56,52.33331,20.86247108,2.12738
12.6,52.49993,20.94376821,2.13567
12.64,52.66662,20.91787865,2.13303
12.68,52.83337,20.86217688,2.12735
12.72,53.00011,20.99084013,2.14047
12.76,53.16662,20.86070588,2.1272
12.8,53.33318,20.92327231,2.13358
12.84,53.49993,20.80284665,2.1213
12.88,53.66674,21.026046,2.14406
12.92,53.83337,21.30278966,2.17228
12.96,54.00006,21.15931837,2.15765
13,54.16668,20.92582204,2.13384
13.04,54.33324,21.07831544,2.14939
13.08,54.49993,21.03928498,2.14541
13.12,54.66668,21.25326608,2.16723
13.16,54.83331,21.20354636,2.16216
13.2,55.00006,21.17383221,2.15913
13.24,55.16662,21.27523298,2.16947
13.28,55.33325,20.98985946,2.14037
13.32,55.50005,21.13607661,2.15528
13.36,55.66674,21.20707676,2.16252
13.4,55.83331,21.35133258,2.17723
13.44,55.99999,21.54207192,2.19668
13.48,56.16668,21.27582137,2.16953
13.52,56.3333,21.5965969,2.20224
13.56,56.50006,21.62758591,2.2054
13.6,56.66674,21.691133,2.21188
13.64,56.83331,21.66720478,2.20944
13.68,56.99999,21.54981918,2.19747
13.72,57.16668,21.69044654,2.21181
13.76,57.3333,21.76978234,2.2199
13.8,57.50006,21.65739813,2.20844
13.84,57.66674,21.85804219,2.2289
13.88,57.83331,21.91109616,2.23431
13.92,57.99993,21.81626586,2.22464
13.96,58.16668,21.68701421,2.21146
14,58.33337,21.70868691,2.21367
14.04,58.50005,21.98199824,2.24154
14.08,58.66668,22.00504387,2.24389
14.12,58.83318,21.99043196,2.2424
14.16,58.99993,21.94061418,2.23732
14.2,59.16681,22.08879266,2.25243
14.24,59.33343,22.0664335,2.25015
14.28,59.49999,21.97179933,2.2405
14.32,59.66649,22.23040069,2.26687
14.36,59.83318,22.06427603,2.24993
14.4,60.00006,22.14812289,2.25848
14.44,60.16681,22.20578599,2.26436
14.48,60.33337,22.28816185,2.27276
14.52,60.5,22.30365636,2.27434
14.56,60.66662,22.34974762,2.27904
14.6,60.83325,22.32091607,2.2761
14.64,61.00005,22.48968851,2.29331
14.68,61.16674,22.42820082,2.28704
14.72,61.33337,22.35455287,2.27953
14.76,61.49999,22.47135008,2.29144
14.8,61.66662,22.42516075,2.28673
14.84,61.8333,22.58236135,2.30276
14.88,62.00006,22.62649128,2.30726
14.92,62.16674,22.58500915,2.30303
14.96,62.33331,22.58334202,2.30286
15,62.49999,22.70298315,2.31506
15.04,62.66674,22.72749977,2.31756
15.08,62.83336,23.02150314,2.34754
15.12,63.00006,22.89637029,2.33478
15.16,63.16661,22.69239197,2.31398
15.2,63.33324,22.6170769,2.3063
15.24,63.49999,22.72043899,2.31684
15.28,63.66674,22.92422117,2.33762
15.32,63.83337,22.99649618,2.34499
15.36,63.99999,22.69847209,2.3146
15.4,64.16667,22.90401947,2.33556
15.44,64.33324,22.88577911,2.3337
15.48,64.50005,22.9882586,2.34415
15.52,64.66674,22.98090361,2.3434
15.56,64.8333,22.87979705,2.33309
15.6,64.99999,23.11554891,2.35713
15.64,65.16661,22.98482627,2.3438
15.68,65.3333,23.11388178,2.35696
15.72,65.50005,23.15771751,2.36143
15.76,65.66674,23.27882964,2.37378
15.8,65.83324,23.21459608,2.36723
15.84,65.99999,23.24313343,2.37014
15.88,66.16674,23.47064771,2.39334
15.92,66.33336,23.34296513,2.38032
15.96,66.50005,23.17105455,2.36279
16,66.66668,23.32462669,2.37845
16.04,66.83331,23.42995011,2.38919
16.08,67.00005,23.38072073,2.38417
16.12,67.16674,23.70845897,2.41759
16.16,67.33336,23.7154217,2.4183
16.2,67.49999,23.63147677,2.40974
16.24,67.66674,23.54037299,2.40045
16.28,67.83336,23.42485066,2.38867
16.32,67.99999,23.70100592,2.41683
16.36,68.16668,23.51791576,2.39816
16.4,68.3333,23.75984582,2.42283
16.44,68.49999,23.90272871,2.4374
16.48,68.66661,23.83055177,2.43004
16.52,68.8333,23.85379353,2.43241
16.56,69.00005,23.8509496,2.43212
16.6,69.16668,24.25714104,2.47354
16.64,69.33324,24.04806326,2.45222
16.68,69.49992,23.98814463,2.44611
16.72,69.66662,24.10199984,2.45772
16.76,69.83336,24.18280663,2.46596
16.8,70.00005,24.07915034,2.45539
16.84,70.16661,24.05973318,2.45341
16.88,70.33318,24.2590043,2.47373
16.92,70.50005,24.21967964,2.46972
16.96,70.66674,24.28656099,2.47654
17,70.83336,24.2625347,2.47409
17.04,71.00006,24.31637321,2.47958
17.08,71.16668,24.24704019,2.47251
17.12,71.33331,24.23674321,2.47146
17.16,71.49999,24.32892572,2.48086
17.2,71.66667,24.29872124,2.47778
17.24,71.83337,24.40286786,2.4884
17.28,72.00005,24.33353484,2.48133
17.32,72.16667,24.55389027,2.5038
17.36,72.3333,24.47612354,2.49587
17.4,72.50005,24.62910728,2.51147
17.44,72.66674,24.72423178,2.52117
17.48,72.8333,24.62332135,2.51088
17.52,72.99993,24.67049134,2.51569
17.56,73.16662,24.73197903,2.52196
17.6,73.33324,24.80297918,2.5292
17.64,73.50005,24.89614236,2.5387
17.68,73.66674,24.87535226,2.53658
17.72,73.8333,24.94978473,2.54417
17.76,73.99999,24.89849595,2.53894
17.8,74.16661,25.05020483,2.55441
17.84,74.3333,25.13611108,2.56317
17.88,74.50006,25.05971728,2.55538
17.92,74.66668,25.12453923,2.56199
17.96,74.83324,25.2250574,2.57224
18,74.99993,25.32263356,2.58219
18.04,75.16674,25.14003374,2.56357
18.08,75.33337,25.34116813,2.58408
18.12,75.50005,25.30194153,2.58008
18.16,75.66668,25.18053521,2.5677
18.2,75.83324,25.14954619,2.56454
18.24,76.00005,25.23133365,2.57288
18.28,76.16686,25.34862119,2.58484
18.32,76.33343,25.4399211,2.59415
18.36,76.49993,25.40167516,2.59025
18.4,76.66655,25.6173234,2.61224
18.44,76.8333,25.52219889,2.60254
18.48,77.00011,25.59918109,2.61039
18.52,77.1668,25.56024869,2.60642
18.56,77.33336,25.57083988,2.6075
18.6,77.49998,25.58260786,2.6087
18.64,77.66668,25.5549531,2.60588
18.68,77.83324,25.72029322,2.62274
18.72,77.99999,25.78315385,2.62915
18.76,78.16668,26.0057648,2.65185
18.8,78.3333,25.91887788,2.64299
18.84,78.49999,25.76785547,2.62759
18.88,78.66655,25.83463876,2.6344
18.92,78.8333,25.88210295,2.63924
18.96,79.00004,26.0283201,2.65415
19,79.16667,26.13874298,2.66541
19.04,79.33323,25.99752722,2.65101
19.08,79.49992,26.07735335,2.65915
19.12,79.66667,26.24102634,2.67584
19.16,79.8333,26.3406619,2.686
19.2,79.99999,26.38126143,2.69014
19.24,80.16654,26.26328743,2.67811
19.28,80.33324,26.04008808,2.65535
19.32,80.50005,26.27505541,2.67931
19.36,80.6668,26.23857467,2.67559
19.4,80.83336,26.44765245,2.69691
19.44,80.99998,26.50462909,2.70272
19.48,81.16661,26.60112652,2.71256
19.52,81.3333,26.42019383,2.69411
19.56,81.50005,26.64986557,2.71753
19.6,81.66674,26.76283818,2.72905
19.64,81.8333,26.51423961,2.7037
19.68,81.99998,26.88600971,2.74161
19.72,82.16668,26.47628787,2.69983
19.76,82.33336,26.62838901,2.71534
19.8,82.50005,26.70125242,2.72277
19.84,82.66667,26.8093217,2.73379
19.88,82.83324,26.93563136,2.74667
19.92,82.99999,26.98437041,2.75164
19.96,83.16674,26.9902544,2.75224
20,83.3333,26.92052911,2.74513
20.04,83.49999,26.94004435,2.74712
20.08,83.66668,27.23679358,2.77738
20.12,83.83323,27.12931269,2.76642
20.16,83.99999,26.88218511,2.74122
20.2,84.16668,27.20256837,2.77389
20.24,84.3333,27.20933496,2.77458
20.28,84.49999,27.23208639,2.7769
20.32,84.66667,27.35957284,2.7899
20.36,84.8333,27.34368606,2.78828
20.4,84.99992,27.23443998,2.77714
20.44,85.16661,27.34162667,2.78807
20.48,85.3333,27.53550414,2.80784
20.52,85.49999,27.34888359,2.78881
20.56,85.66667,27.62601952,2.81707
20.6,85.83336,27.46499432,2.80065
20.64,86.00011,27.65573367,2.8201
20.68,86.16674,27.77115794,2.83187
20.72,86.3333,27.68534975,2.82312
20.76,86.49993,27.77763032,2.83253
20.8,86.66667,27.89511399,2.84451
20.84,86.83342,27.9302218,2.84809
20.88,87.00005,27.95346356,2.85046
20.92,87.16661,28.03015156,2.85828
20.96,87.33324,27.89795792,2.8448
21,87.49999,27.73153907,2.82783
21.04,87.66667,27.88560154,2.84354
21.08,87.83337,28.06192511,2.86152
21.12,88.00005,28.10419177,2.86583
21.16,88.16661,27.9489525,2.85
21.2,88.33324,28.12743353,2.8682
21.24,88.49992,28.21196685,2.87682
21.28,88.66673,28.07869448,2.86323
21.32,88.83336,28.18921543,2.8745
21.36,89.00005,28.20255247,2.87586
21.4,89.16661,28.36357766,2.89228
21.44,89.33323,28.43438168,2.8995
21.48,89.50005,28.60913618,2.91732
21.52,89.66674,28.4205543,2.89809
21.56,89.83323,28.30542423,2.88635
21.6,89.99993,28.35769367,2.89168
21.64,90.16661,28.50028236,2.90622
21.68,90.3333,28.54735428,2.91102
21.72,90.50005,28.66876061,2.9234
21.76,90.66674,28.56304492,2.91262
21.8,90.8333,28.4618403,2.9023
21.84,90.99999,28.87303313,2.94423
21.88,91.16674,28.77555503,2.93429
21.92,91.3333,28.72818891,2.92946
21.96,91.50005,28.98424054,2.95557
22,91.66674,28.84832037,2.94171
22.04,91.8333,29.01091463,2.95829
22.08,91.99998,28.94540621,2.95161
22.12,92.16674,28.99394912,2.95656
22.16,92.33336,29.08250317,2.96559
22.2,92.50005,28.97139383,2.95426
22.24,92.66661,29.13320355,2.97076
22.28,92.83324,29.18684593,2.97623
22.32,92.99998,29.13487068,2.97093
22.36,93.1668,29.09554602,2.96692
22.4,93.33336,29.29589588,2.98735
22.44,93.49992,29.53772787,3.01201
22.48,93.66655,29.28216657,2.98595
22.52,93.83329,29.4369155,3.00173
22.56,94.00005,29.49310761,3.00746
22.6,94.16673,29.34188907,2.99204
22.64,94.33337,29.54017953,3.01226
22.68,94.49992,29.58283846,3.01661
22.72,94.66661,29.57156081,3.01546
22.76,94.8333,29.62471285,3.02088
22.8,95.00004,29.84418568,3.04326
22.84,95.16673,29.72130835,3.03073
22.88,95.3333,29.58009259,3.01633
22.92,95.49998,29.81947292,3.04074
22.96,95.66661,29.80701848,3.03947
23,95.83335,29.6960072,3.02815
23.04,96.00011,30.04169161,3.0634
23.08,96.16667,30.09582432,3.06892
23.12,96.3333,30.08327181,3.06764
23.16,96.49999,30.17937698,3.07744
23.2,96.66674,30.24821966,3.08446
23.24,96.83336,29.96990693,3.05608
23.28,96.99998,30.10572903,3.06993
23.32,97.16661,30.02315704,3.06151
23.36,97.3333,30.13220699,3.07263
23.4,97.50005,30.32049467,3.09183
23.44,97.66674,30.25655531,3.08531
23.48,97.83329,30.1869281,3.07821
23.52,97.99998,30.29087859,3.08881
23.56,98.16661,30.28136614,3.08784
23.6,98.33324,30.32716319,3.09251
23.64,98.50005,30.41385398,3.10135
23.68,98.66667,30.56164019,3.11642
23.72,98.83324,30.56399379,3.11666
23.76,98.99999,30.70746508,3.13129
23.8,99.16667,30.68500785,3.129
23.84,99.3333,30.74708394,3.13533
23.88,99.50005,30.65803956,3.12625
23.92,99.66668,30.80278572,3.14101
23.96,99.83324,30.90065608,3.15099
24,99.99998,30.91968098,3.15293
24.04,100.16668,30.7709141,3.13776
24.08,100.3333,31.15474639,3.1769
24.12,100.50005,31.00754857,3.16189
24.16,100.66673,30.98038415,3.15912
24.2,100.83323,31.08521724,3.16981
24.24,101.00004,31.26340407,3.18798
24.28,101.16674,31.29341242,3.19104
24.32,101.33336,31.21848961,3.1834
24.36,101.50004,31.37068882,3.19892
24.4,101.6668,31.32675503,3.19444
24.44,101.83336,31.50298053,3.21241
24.48,101.99999,31.29056849,3.19075
24.52,102.16667,31.41148448,3.20308
24.56,102.3333,31.47032438,3.20908
24.6,102.49998,31.32793182,3.19456
24.64,102.66667,31.6148744,3.22382
24.68,102.83336,31.37255208,3.19911
24.72,103.00005,31.614286,3.22376
24.76,103.16667,31.73157354,3.23572
24.8,103.33324,31.53465601,3.21564
24.84,103.49993,31.80218142,3.24292
24.88,103.66674,31.79325737,3.24201
24.92,103.83342,31.92623554,3.25557
24.96,104.00005,31.89044127,3.25192
25,104.16655,31.86376718,3.2492
25.04,104.33324,31.72568955,3.23512
25.08,104.49998,32.09010466,3.27228
25.12,104.66673,32.05421232,3.26862
25.16,104.83336,32.03155896,3.26631
25.2,104.99999,32.06911843,3.27014
25.24,105.16667,32.07225656,3.27046
25.28,105.33324,32.26319203,3.28993
25.32,105.49999,32.25534671,3.28913
25.36,105.66667,32.2220041,3.28573
25.4,105.83336,32.44834159,3.30881
25.44,106.00004,32.41666611,3.30558
25.48,106.16668,32.55974513,3.32017
25.52,106.3333,32.39577794,3.30345
25.56,106.50005,32.49933617,3.31401
25.6,106.66673,32.63143174,3.32748
25.64,106.8333,32.46942588,3.31096
25.68,106.99999,32.55493987,3.31968
25.72,107.16667,32.42421723,3.30635
25.76,107.3333,32.62780328,3.32711
25.8,107.50005,32.69125231,3.33358
25.84,107.66667,32.7328325,3.33782
25.88,107.8333,32.92847517,3.35777
25.92,107.99998,32.90778314,3.35566
25.96,108.16661,32.70674681,3.33516
26,108.3333,32.93612436,3.35855
26.04,108.50005,33.09705148,3.37496
26.08,108.66674,33.05194089,3.37036
26.12,108.83324,32.92641577,3.35756
26.16,108.99998,33.15245906,3.38061
26.2,109.16674,33.13117863,3.37844
26.24,109.33336,33.2032575,3.38579
26.28,109.49999,33.31083645,3.39676
26.32,109.66661,33.31819144,3.39751
26.36,109.83324,33.19472572,3.38492
26.4,110.00005,33.49333821,3.41537
26.44,110.16686,33.48657162,3.41468
26.48,110.33336,33.30926739,3.3966
26.52,110.49986,33.39085872,3.40492
26.56,110.66655,33.5788522,3.42409
26.6,110.8333,33.50422359,3.41648
26.64,111.00011,33.53030928,3.41914
26.68,111.1668,33.53021121,3.41913
26.72,111.3333,33.51559931,3.41764
26.76,111.49999,33.6956494,3.436
26.8,111.66661,33.66907338,3.43329
26.84,111.8333,33.78587058,3.4452
26.88,112.00004,33.84529888,3.45126
26.92,112.16674,33.78390925,3.445
26.96,112.3333,33.82117452,3.4488
27,112.49992,33.99808649,3.46684
27.04,112.66661,34.07369576,3.47455
27.08,112.83336,33.98161131,3.46516
27.12,113.00005,33.99612516,3.46664
27.16,113.16667,34.09301486,3.47652
27.2,113.33324,34.28924592,3.49653
27.24,113.49998,34.25080386,3.49261
27.28,113.66673,34.21520572,3.48898
27.32,113.8333,34.06987116,3.47416
27.36,113.99998,34.37466185,3.50524
27.4,114.16661,34.21589218,3.48905
27.44,114.33324,34.44909432,3.51283
27.48,114.49998,34.47106122,3.51507
27.52,114.66667,34.38917569,3.50672
27.56,114.8333,34.46615789,3.51457
27.6,114.99998,34.72485732,3.54095
27.64,115.1666,34.55461387,3.52359
27.68,115.3333,34.43026555,3.51091
27.72,115.50005,34.57197164,3.52536
27.76,115.66673,34.62365269,3.53063
27.8,115.83329,34.81468623,3.55011
27.84,115.99999,34.89372783,3.55817
27.88,116.16673,34.67062654,3.53542
27.92,116.33337,34.93981909,3.56287
27.96,116.50004,34.81056744,3.54969
28,116.66667,35.0117999,3.57021
28.04,116.83323,34.82125669,3.55078
28.08,117.00004,35.0876053,3.57794
28.12,117.16673,35.06534421,3.57567
28.16,117.33335,35.09231249,3.57842
28.2,117.50005,35.11918271,3.58116
28.24,117.66661,35.11427939,3.58066
28.28,117.83324,35.4017123,3.60997
28.32,117.99999,35.16537204,3.58587
28.36,118.16673,35.14840653,3.58414
28.4,118.3333,35.34836412,3.60453
28.44,118.49998,35.47437958,3.61738
28.48,118.66674,35.39867224,3.60966
28.52,118.8333,35.52684515,3.62273
28.56,118.99998,35.72984281,3.64343
28.6,119.16667,35.40651756,3.61046
28.64,119.33323,35.52772775,3.62282
28.68,119.49998,35.5407706,3.62415
28.72,119.66667,35.58195853,3.62835
28.76,119.83336,35.60569062,3.63077
28.8,120.00005,35.72896021,3.64334
28.84,120.16667,35.67649463,3.63799
28.88,120.33324,35.80829601,3.65143
28.92,120.49992,35.90449925,3.66124
28.96,120.6668,35.93617473,3.66447
29,120.83337,35.88508208,3.65926
29.04,120.99999,35.92146475,3.66297
29.08,121.16661,36.1883037,3.69018
29.12,121.3333,36.11004663,3.6822
29.16,121.50005,36.19369735,3.69073
29.2,121.66673,36.23831761,3.69528
29.24,121.83336,36.14044725,3.6853
29.28,122.00005,36.37531651,3.70925
29.32,122.16668,36.33461892,3.7051
29.36,122.3333,36.40620746,3.7124
29.4,122.49999,36.442394,3.71609
29.44,122.66673,36.19163796,3.69052
29.48,122.8333,36.44219787,3.71607
29.52,122.99999,36.60489019,3.73266
29.56,123.16661,36.46838162,3.71874
29.6,123.3333,36.41699478,3.7135
29.64,123.50004,36.59527967,3.73168
29.68,123.66674,36.70864455,3.74324
29.72,123.8333,36.60096753,3.73226
29.76,123.99992,36.69638623,3.74199
29.8,124.16661,36.72413905,3.74482
29.84,124.3333,36.7538532,3.74785
29.88,124.50005,37.02647807,3.77565
29.92,124.66667,36.93684529,3.76651
29.96,124.83324,36.90311042,3.76307
30,124.99998,37.07011767,3.7801
30.04,125.16667,37.05530962,3.77859
30.08,125.33336,37.03726539,3.77675
30.12,125.50004,37.09590915,3.78273
30.16,125.66666,37.22820086,3.79622
30.2,125.83323,37.33587788,3.8072
30.24,126.00005,37.3024372,3.80379
30.28,126.16679,37.29488608,3.80302
30.32,126.33336,37.2081953,3.79418
30.36,126.49998,37.43374825,3.81718
30.4,126.6666,37.60575689,3.83472
30.44,126.83329,37.36431717,3.8101
30.48,127.00011,37.44934082,3.81877
30.52,127.1668,37.47483811,3.82137
30.56,127.33328,37.47022899,3.8209
30.6,127.49985,37.51543764,3.82551
30.64,127.66661,37.61036601,3.83519
30.68,127.83329,37.69215347,3.84353
30.72,128.00003,37.52465589,3.82645
30.76,128.16672,37.80561642,3.8551
30.8,128.33329,37.98341098,3.87323
30.84,128.49991,37.80218409,3.85475
30.88,128.66661,37.88279475,3.86297
30.92,128.8333,37.98703944,3.8736
30.96,128.99998,38.18935063,3.89423
31,129.16672,37.99341376,3.87425
31.04,129.33329,38.02322598,3.87729
31.08,129.49985,38.22789076,3.89816
31.12,129.6666,38.17375806,3.89264
31.16,129.83336,38.3074227,3.90627
31.2,130.00011,38.18376084,3.89366
31.24,130.16666,38.09726619,3.88484
31.28,130.33323,38.32870313,3.90844
31.32,130.49997,38.28123894,3.9036
31.36,130.66679,38.26446957,3.90189
31.4,130.83336,38.47433188,3.92329
31.44,130.99998,38.36283027,3.91192
31.48,131.16667,38.44981525,3.92079
31.52,131.33329,38.5606304,3.93209
31.56,131.50004,38.77971096,3.95443
31.6,131.6668,38.35880954,3.91151
31.64,131.83336,38.59240394,3.93533
31.68,131.99999,38.44098927,3.91989
31.72,132.16667,38.45138432,3.92095
31.76,132.33329,38.68782265,3.94506
31.8,132.50004,38.77029658,3.95347
31.84,132.66667,38.81423037,3.95795
31.88,132.83323,38.59858213,3.93596
31.92,132.99991,38.75725373,3.95214
31.96,133.16668,38.74646642,3.95104
32,133.33336,38.78745821,3.95522
32.04,133.50004,38.81717236,3.95825
32.08,133.66661,38.83904119,3.96048
32.12,133.83323,38.79049827,3.95553
32.16,133.99998,38.62653109,3.93881
32.2,134.16673,38.33233159,3.90881
32.24,134.33336,38.21661312,3.89701
32.28,134.50004,24.83406626,2.53237
32.32,134.66666,-1.092558877,-0.11141
32.36,134.83323,-0.987529655,-0.1007
32.4,134.99998,-0.106107953,-0.01082
32.44,135.16666,-0.240262925,-0.0245
32.48,135.33329,-0.222512889,-0.02269
32.52,135.50005,-0.219767027,-0.02241
32.56,135.66679,-0.236438332,-0.02411
32.6,135.8333,-0.236830598,-0.02415
32.64,135.99998,-0.076295737,-0.00778
32.68,136.16666,-0.056682437,-0.00578
32.72,136.33328,-0.149747546,-0.01527
32.76,136.50005,-0.149551413,-0.01525
32.8,136.66674,-0.100223963,-0.01022
32.84,136.83336,-0.026576022,-0.00271
32.88,137.00004,-0.149943679,-0.01529
32.92,137.16667,-0.130526512,-0.01331
32.96,137.33323,-0.08629852,-0.0088
33,137.49997,-0.164457521,-0.01677
33.04,137.66673,-0.035892339,-0.00366
33.08,137.83336,-0.308419143,-0.03145
33.12,137.99998,-0.172400907,-0.01758
33.16,138.16661,-0.215157901,-0.02194
33.2,138.33323,-0.143569356,-0.01464
33.24,138.49998,-0.261053023,-0.02662
33.28,138.66673,-0.121504394,-0.01239
33.32,138.83336,-0.240753258,-0.02455
33.36,138.99999,-0.291943971,-0.02977
33.4,139.16661,-0.106696352,-0.01088
33.44,139.33323,-0.129643913,-0.01322
33.48,139.49998,-0.37883089,-0.03863
33.52,139.66672,-0.339015891,-0.03457
33.56,139.83329,-0.165536252,-0.01688
33.6,139.99998,-0.158965797,-0.01621
33.616,140.06661,-0.154258605,-0.01573