File: V_7/NR/RDSO NR Tensile 50.is_tens_RawData/Specimen_RawData_1.csv
Time,Extension,Load
(sec),(mm),(N)
0.00000,0.00000,-0.10244
0.10000,0.07569,0.04196
0.20000,0.16469,0.35811
0.30000,0.24931,0.69625
0.40000,0.33294,0.71875
0.50000,0.41675,1.02793
0.60000,0.50000,1.08350
0.70000,0.58331,1.12353
0.80000,0.66675,1.21090
0.90000,0.74994,1.73554
1.00000,0.83325,1.62853
1.10000,0.91675,1.84932
1.20000,0.99994,2.10329
1.30000,1.08331,2.09393
1.40000,1.16681,2.44761
1.50000,1.25000,2.31844
1.60000,1.33325,2.62141
1.70000,1.41675,2.79428
1.80000,1.49994,2.79325
1.90000,1.58325,2.85832
2.00000,1.66669,3.00513
2.10000,1.75000,3.13934
2.20000,1.83331,3.41418
2.30000,1.91675,3.41163
2.40000,2.00000,3.53653
2.50000,2.08331,3.58533
2.60000,2.16681,3.65991
2.70000,2.24994,3.90952
2.80000,2.33325,3.91682
2.90000,2.41675,4.24566
3.00000,2.49994,4.14741
3.10000,2.58325,4.45293
3.20000,2.66669,4.48997
3.30000,2.75000,4.47963
3.40000,2.83325,4.50629
3.50000,2.91675,4.54034
3.60000,3.00000,4.82900
3.70000,3.08331,4.73953
3.80000,3.16681,5.18660
3.90000,3.24994,4.98266
4.00000,3.33331,5.11991
4.10000,3.41675,5.26275
4.20000,3.49994,5.33095
4.30000,3.58325,5.53004
4.40000,3.66681,5.50461
4.50000,3.75000,5.75216
4.60000,3.83331,5.75456
4.70000,3.91681,5.95477
4.80000,3.99994,5.92258
4.90000,4.08331,5.97540
5.00000,4.16669,5.87618
5.10000,4.24994,6.21256
5.20000,4.33331,6.35681
5.30000,4.41675,6.23113
5.40000,4.49994,6.13813
5.50000,4.58325,6.45016
5.60000,4.66681,6.55835
5.70000,4.74994,6.61357
5.80000,4.83325,6.72686
5.90000,4.91681,6.87901
6.00000,5.00000,6.71250
6.10000,5.08319,6.91188
6.20000,5.16669,7.06589
6.30000,5.25000,6.95344
6.40000,5.33325,7.39894
6.50000,5.41675,7.10524
6.60000,5.50000,7.27963
6.70000,5.58331,7.36744
6.80000,5.66681,7.54761
6.90000,5.74994,7.54565
7.00000,5.83325,7.55976
7.10000,5.91675,7.77982
7.20000,5.99994,7.69069
7.30000,6.08325,7.79021
7.40000,6.16675,7.93662
7.50000,6.25000,7.78967
7.60000,6.33325,8.15633
7.70000,6.41669,8.09376
7.80000,6.50000,8.23101
7.90000,6.58331,8.36272
8.00000,6.66675,8.18867
8.10000,6.75000,8.34146
8.20000,6.83331,8.38864
8.30000,6.91681,8.67701
8.40000,6.99994,8.66760
8.50000,7.08325,8.61179
8.60000,7.16675,8.52535
8.70000,7.24994,8.77697
8.80000,7.33325,8.89138
8.90000,7.41681,8.97243
9.00000,7.50006,8.84429
9.10000,7.58331,8.95567
9.20000,7.66675,9.11227
9.30000,7.74994,9.21772
9.40000,7.83319,9.31523
9.50000,7.91669,9.21478
9.60000,7.99994,9.21645
9.70000,8.08331,9.32297
9.80000,8.16687,9.41916
9.90000,8.25000,9.47605
10.00000,8.33325,9.76912
10.10000,8.41681,9.68709
10.20000,8.49994,9.56209
10.30000,8.58319,9.79009
10.40000,8.66675,9.81277
10.50000,8.75000,9.81655
10.60000,8.83325,9.97771
10.70000,8.91675,9.97673
10.80000,8.99994,10.12040
10.90000,9.08331,10.17175
11.00000,9.16675,10.03803
11.10000,9.25000,10.25064
11.20000,9.33331,10.12574
11.30000,9.41675,10.25416
11.40000,9.49994,10.39337
11.50000,9.58319,10.51553
11.60000,9.66675,10.57320
11.70000,9.74994,10.36804
11.80000,9.83325,10.58766
11.90000,9.91681,10.51793
12.00000,10.00000,10.72133
12.10000,10.08331,10.55664
12.20000,10.16675,10.54895
12.30000,10.25000,10.81394
12.40000,10.33325,10.92747
12.50000,10.41675,10.84123
12.60000,10.49994,10.91130
12.70000,10.58325,11.07751
12.80000,10.66675,10.94055
12.90000,10.74994,10.97657
13.00000,10.83325,11.01611
13.10000,10.91675,11.17071
13.20000,11.00000,11.02919
13.30000,11.08331,11.17590
13.40000,11.16669,11.17884
13.50000,11.25000,11.40542
13.60000,11.33325,11.28664
13.70000,11.41669,11.36778
13.80000,11.49994,11.29355
13.90000,11.58325,11.34088
14.00000,11.66675,11.59269
14.10000,11.75000,11.37264
14.20000,11.83331,11.44119
14.30000,11.91675,11.45868
14.40000,12.00000,11.47637
14.50000,12.08325,11.59656
14.60000,12.16669,11.54967
14.70000,12.25000,11.69187
14.80000,12.33325,11.62763
14.90000,12.41675,11.81858
15.00000,12.50000,11.92560
15.10000,12.58331,11.74048
15.20000,12.66675,12.05280
15.30000,12.74994,12.11111
15.40000,12.83325,11.81216
15.50000,12.91681,11.94951
15.60000,12.99994,12.13645
15.70000,13.08325,12.04089
15.80000,13.16681,11.96401
15.90000,13.24994,11.90933
16.00000,13.33319,12.34474
16.10000,13.41675,12.05290
16.20000,13.49994,12.27364
16.30000,13.58325,12.18589
16.40000,13.66675,12.22807
16.50000,13.75000,12.30662
16.60000,13.83331,12.19755
16.70000,13.91675,12.32127
16.80000,13.99994,12.24194
16.90000,14.08325,12.27972
17.00000,14.16675,12.31515
17.10000,14.25000,12.21063
17.20000,14.33325,12.66770
17.30000,14.41675,12.30255
17.40000,14.50000,12.54398
17.50000,14.58325,12.46974
17.60000,14.66675,12.54736
17.70000,14.75000,12.70602
17.80000,14.83331,12.53476
17.90000,14.91669,12.64457
18.00000,15.00000,12.60831
18.10000,15.08319,12.62306
18.20000,15.16675,12.47430
18.30000,15.24994,12.69558
18.40000,15.33331,12.93627
18.50000,15.41681,12.77790
18.60000,15.50000,12.72513
18.70000,15.58331,12.80421
18.80000,15.66668,12.64776
18.90000,15.74993,12.84513
19.00000,15.83318,12.85483
19.10000,15.91668,12.73552
19.20000,15.99994,12.94558
19.30000,16.08331,12.89222
19.40000,16.16681,12.82401
19.50000,16.25000,12.91936
19.60000,16.33325,12.86174
19.70000,16.41675,13.01746
19.80000,16.49993,12.91197
19.90000,16.58325,13.11502
20.00000,16.66675,13.02275
20.10000,16.75000,13.02011
20.20000,16.83325,13.23301
20.30000,16.91675,13.09704
20.40000,16.99987,13.10037
20.50000,17.08325,13.13927
20.60000,17.16675,13.23531
20.70000,17.25000,13.03535
20.80000,17.33331,13.13075
20.90000,17.41687,13.24061
21.00000,17.50000,13.11046
21.10000,17.58325,13.26741
21.20000,17.66675,13.15152
21.30000,17.74994,13.29029
21.40000,17.83318,13.31195
21.50000,17.91681,13.17651
21.60000,18.00000,13.51520
21.70000,18.08331,13.41049
21.80000,18.16675,13.37046
21.90000,18.24994,13.54926
22.00000,18.33325,13.41764
22.10000,18.41668,13.46101
22.20000,18.49993,13.50844
22.30000,18.58325,13.50393
22.40000,18.66675,13.56440
22.50000,18.74994,13.61340
22.60000,18.83325,13.52211
22.70000,18.91675,13.59684
22.80000,19.00000,13.48668
22.90000,19.08331,13.49330
23.00000,19.16675,13.58998
23.10000,19.25000,13.83674
23.20000,19.33325,13.80151
23.30000,19.41668,13.49335
23.40000,19.49994,13.74075
23.50000,19.58325,13.74619
23.60000,19.66669,13.77510
23.70000,19.75000,13.58694
23.80000,19.83325,13.74604
23.90000,19.91675,13.81890
24.00000,20.00000,13.79700
24.10000,20.08325,13.69635
24.20000,20.16675,13.79764
24.30000,20.25000,13.81523
24.40000,20.33318,13.97316
24.50000,20.41668,13.82292
24.60000,20.50000,13.83444
24.70000,20.58331,13.89529
24.80000,20.66675,13.97409
24.90000,20.74993,14.05739
25.00000,20.83331,13.90304
25.10000,20.91675,13.94880
25.20000,20.99993,13.92190
25.30000,21.08331,14.03632
25.40000,21.16675,14.10119
25.50000,21.25000,14.06714
25.60000,21.33325,13.94523
25.70000,21.41668,14.20639
25.80000,21.50000,13.94763
25.90000,21.58331,14.14563
26.00000,21.66681,14.00295
26.10000,21.75000,14.20512
26.20000,21.83331,13.96458
26.30000,21.91675,14.16979
26.40000,21.99993,14.16024
26.50000,22.08325,14.34933
26.60000,22.16668,14.27563
26.70000,22.24993,14.30964
26.80000,22.33325,14.33913
26.90000,22.41687,14.26720
27.00000,22.49993,14.17072
27.10000,22.58325,14.31013
27.20000,22.66675,14.35315
27.30000,22.74993,14.14500
27.40000,22.83331,14.22560
27.50000,22.91675,14.21002
27.60000,22.99994,14.33610
27.70000,23.08325,14.37554
27.80000,23.16675,14.44782
27.90000,23.24993,14.30038
28.00000,23.33325,14.34158
28.10000,23.41675,14.48437
28.20000,23.50000,14.51867
28.30000,23.58325,14.34256
28.40000,23.66681,14.49069
28.50000,23.75000,14.40729
28.60000,23.83325,14.46967
28.70000,23.91668,14.49192
28.80000,24.00000,14.50495
28.90000,24.08325,14.54513
29.00000,24.16662,14.58364
29.10000,24.24994,14.59874
29.20000,24.33331,14.52759
29.30000,24.41681,14.41489
29.40000,24.50000,14.56595
29.50000,24.58331,14.64774
29.60000,24.66675,14.60413
29.70000,24.75000,14.70859
29.80000,24.83318,14.74941
29.90000,24.91681,14.44978
30.00000,24.99999,14.64970
30.10000,25.08325,14.75073
30.20000,25.16681,14.58565
30.30000,25.25000,14.79243
30.40000,25.33331,14.72721
30.50000,25.41675,14.71104
30.60000,25.49987,14.61192
30.70000,25.58324,14.84133
30.80000,25.66675,14.73897
30.90000,25.74987,14.81066
31.00000,25.83325,14.81443
31.10000,25.91675,14.86652
31.20000,26.00000,14.73079
31.30000,26.08331,14.71511
31.40000,26.16681,15.05208
31.50000,26.25006,14.83305
31.60000,26.33331,15.09834
31.70000,26.41669,14.87240
31.80000,26.49993,15.01053
31.90000,26.58325,15.03420
32.00000,26.66668,15.00852
32.10000,26.74993,15.06561
32.20000,26.83331,14.99132
32.30000,26.91681,14.84339
32.40000,27.00000,15.16757
32.50000,27.08325,14.90538
32.60000,27.16674,15.09305
32.70000,27.25000,15.08898
32.80000,27.33325,15.11794
32.90000,27.41675,14.93576
33.00000,27.49993,15.23686
33.10000,27.58331,15.19168
33.20000,27.66668,15.14964
33.30000,27.74999,15.10005
33.40000,27.83325,15.11867
33.50000,27.91675,15.19237
33.60000,28.00000,15.17233
33.70000,28.08325,15.12191
33.80000,28.16675,15.00049
33.90000,28.24993,15.12803
34.00000,28.33318,15.25132
34.10000,28.41675,15.19296
34.20000,28.50000,15.35137
34.30000,28.58325,15.28013
34.40000,28.66675,15.31751
34.50000,28.75006,15.23853
34.60000,28.83331,15.21569
34.70000,28.91675,15.40057
34.80000,28.99993,15.51729
34.90000,29.08325,15.55938
35.00000,29.16675,15.49382
35.10000,29.25000,15.43600
35.20000,29.33325,15.62744
35.30000,29.41675,15.41777
35.40000,29.50000,15.35740
35.50000,29.58325,15.40709
35.60000,29.66668,15.29370
35.70000,29.75000,15.24191
35.80000,29.83331,15.55786
35.90000,29.91674,15.43526
36.00000,30.00000,15.58197
36.10000,30.08325,15.61803
36.20000,30.16675,15.47319
36.30000,30.24993,15.52552
36.40000,30.33318,15.53870
36.50000,30.41681,15.42218
36.60000,30.49993,15.83549
36.70000,30.58331,15.64091
36.80000,30.66681,15.38749
36.90000,30.75000,15.62533
37.00000,30.83325,15.62592
37.10000,30.91675,15.64091
37.20000,30.99993,15.65718
37.30000,31.08324,15.64194
37.40000,31.16675,15.75744
37.50000,31.24993,15.85392
37.60000,31.33331,15.58878
37.70000,31.41674,15.63258
37.80000,31.49999,15.62185
37.90000,31.58325,15.74553
38.00000,31.66674,15.79639
38.10000,31.74993,15.86063
38.20000,31.83324,15.73548
38.30000,31.91675,15.91247
38.40000,31.99999,15.94084
38.50000,32.08318,15.94305
38.60000,32.16675,15.79614
38.70000,32.24999,16.01062
38.80000,32.33337,16.01042
38.90000,32.41681,15.74195
39.00000,32.50000,15.89101
39.10000,32.58331,16.05266
39.20000,32.66662,16.03649
39.30000,32.74987,15.74484
39.40000,32.83324,15.94540
39.50000,32.91681,16.04693
39.60000,32.99993,16.14017
39.70000,33.08331,15.99391
39.80000,33.16681,16.03497
39.90000,33.24999,16.06118
40.00000,33.33325,15.92060
40.10000,33.41675,16.19035
40.20000,33.49999,16.12052
40.30000,33.58331,16.16653
40.40000,33.66675,16.23014
40.50000,33.74999,16.03267
40.60000,33.83331,16.13919
40.70000,33.91674,16.21299
40.80000,33.99987,16.26444
40.90000,34.08324,16.25248
41.00000,34.16675,16.22475
41.10000,34.25000,16.31290
41.20000,34.33331,16.29496
41.30000,34.41674,16.35518
41.40000,34.49999,16.32451
41.50000,34.58325,16.20965
41.60000,34.66668,16.38537
41.70000,34.75000,16.32647
41.80000,34.83331,16.27262
41.90000,34.91674,16.46382
42.00000,34.99999,16.29462
42.10000,35.08325,16.51625
42.20000,35.16675,16.39277
42.30000,35.24993,16.57269
42.40000,35.33325,16.57740
42.50000,35.41674,16.40541
42.60000,35.49999,16.43569
42.70000,35.58324,16.42241
42.80000,35.66675,16.58671
42.90000,35.74993,16.38375
43.00000,35.83324,16.38272
43.10000,35.91675,16.47146
43.20000,35.99999,16.65526
43.30000,36.08331,16.54031
43.40000,36.16675,16.58004
43.50000,36.25000,16.50013
43.60000,36.33325,16.66369
43.70000,36.41674,16.87061
43.80000,36.50000,16.68608
43.90000,36.58318,16.42663
44.00000,36.66674,16.63737
44.10000,36.74999,16.72734
44.20000,36.83331,16.72998
44.30000,36.91674,16.74939
44.40000,36.99999,16.92682
44.50000,37.08331,16.88007
44.60000,37.16668,16.63639
44.70000,37.24999,16.67069
44.80000,37.33324,16.80819
44.90000,37.41675,16.85307
45.00000,37.49993,16.92883
45.10000,37.58324,16.88767
45.20000,37.66681,17.04393
45.30000,37.74999,17.00757
45.40000,37.83325,16.80152
45.50000,37.91675,17.07323
45.60000,38.00000,16.95970
45.70000,38.08324,17.10003
45.80000,38.16668,16.95347
45.90000,38.24993,17.11674
46.00000,38.33324,17.00095
46.10000,38.41668,17.10513
46.20000,38.49993,17.04589
46.30000,38.58331,17.00037
46.40000,38.66687,17.17794
46.50000,38.74999,17.11968
46.60000,38.83331,16.89756
46.70000,38.91675,17.21827
46.80000,38.99993,16.98175
46.90000,39.08318,17.18162
47.00000,39.16674,17.03888
47.10000,39.24999,17.05480
47.20000,39.33331,17.14746
47.30000,39.41681,17.33361
47.40000,39.49999,17.27060
47.50000,39.58330,17.07499
47.60000,39.66675,17.38350
47.70000,39.74993,17.37149
47.80000,39.83324,16.95372
47.90000,39.91681,17.23997
48.00000,39.99993,17.39158
48.10000,40.08318,17.21812
48.20000,40.16674,17.25644
48.30000,40.24993,17.47591
48.40000,40.33324,17.37291
48.50000,40.41681,17.39795
48.60000,40.49993,17.53564
48.70000,40.58330,17.36561
48.80000,40.66675,17.51589
48.90000,40.74999,17.27035
49.00000,40.83325,17.47679
49.10000,40.91668,17.42622
49.20000,40.99993,17.43450
49.30000,41.08324,17.77025
49.40000,41.16674,17.65138
49.50000,41.25000,17.47218
49.60000,41.33331,17.33474
49.70000,41.41680,17.49149
49.80000,41.50006,17.60409
49.90000,41.58324,17.76074
50.00000,41.66674,17.52030
50.10000,41.74993,17.55416
50.20000,41.83325,17.59816
50.30000,41.91674,17.70699
50.40000,41.99999,17.65814
50.50000,42.08324,17.67377
50.60000,42.16681,17.67931
50.70000,42.24999,17.70371
50.80000,42.33324,17.78142
50.90000,42.41674,17.85909
51.00000,42.49993,17.50786
51.10000,42.58324,17.90588
51.20000,42.66674,17.73634
51.30000,42.74993,17.98227
51.40000,42.83324,17.78280
51.50000,42.91675,17.95954
51.60000,42.99999,17.92372
51.70000,43.08337,17.90525
51.80000,43.16681,17.75050
51.90000,43.24993,17.88775
52.00000,43.33324,18.04279
52.10000,43.41675,17.81509
52.20000,43.50000,17.76824
52.30000,43.58324,18.10654
52.40000,43.66674,17.75462
52.50000,43.75000,18.08351
52.60000,43.83331,17.86139
52.70000,43.91674,17.89785
52.80000,44.00000,18.07861
52.90000,44.08325,17.94846
53.00000,44.16674,18.01064
53.10000,44.24999,18.13192
53.20000,44.33331,18.13035
53.30000,44.41674,17.99898
53.40000,44.49993,18.25344
53.50000,44.58318,18.33277
53.60000,44.66674,18.27652
53.70000,44.74993,17.99374
53.80000,44.83324,18.30553
53.90000,44.91674,18.31160
54.00000,44.99999,18.25104
54.10000,45.08324,18.26397
54.20000,45.16675,18.22566
54.30000,45.24993,18.26182
54.40000,45.33324,18.32758
54.50000,45.41674,18.27000
54.60000,45.49993,18.25711
54.70000,45.58324,18.35874
54.80000,45.66681,18.41230
54.90000,45.75000,18.18405
55.00000,45.83324,18.35668
55.10000,45.91674,18.30699
55.20000,45.99993,18.42749
55.30000,46.08324,18.46825
55.40000,46.16668,18.45017
55.50000,46.24999,18.26309
55.60000,46.33325,18.33409
55.70000,46.41668,18.36040
55.80000,46.49999,18.46046
55.90000,46.58324,18.53725
56.00000,46.66674,18.34962
56.10000,46.75000,18.52994
56.20000,46.83331,18.43900
56.30000,46.91674,18.70875
56.40000,46.99999,18.51843
56.50000,47.08318,18.59090
56.60000,47.16674,18.60624
56.70000,47.24999,18.65592
56.80000,47.33324,18.56704
56.90000,47.41680,18.80572
57.00000,47.49999,18.68768
57.10000,47.58331,18.73374
57.20000,47.66674,18.75382
57.30000,47.74993,18.69963
57.40000,47.83330,18.82478
57.50000,47.91674,18.56219
57.60000,47.99993,18.83026
57.70000,48.08324,18.73687
57.80000,48.16674,18.67738
57.90000,48.24999,18.57630
58.00000,48.33324,19.00343
58.10000,48.41681,18.92640
58.20000,48.49999,18.88441
58.30000,48.58330,18.81659
58.40000,48.66675,18.71360
58.50000,48.74999,18.97643
58.60000,48.83324,19.01220
58.70000,48.91668,18.91969
58.80000,48.99993,18.81091
58.90000,49.08324,19.02058
59.00000,49.16681,19.06831
59.10000,49.25005,18.84056
59.20000,49.33331,18.99427
59.30000,49.41680,19.00887
59.40000,49.50000,19.09844
59.50000,49.58318,19.00804
59.60000,49.66668,18.90558
59.70000,49.74993,19.02690
59.80000,49.83330,19.27180
59.90000,49.91674,18.89450
60.00000,49.99999,19.30845
60.10000,50.08331,19.30238
60.20000,50.16681,19.21648
60.30000,50.24987,19.32761
60.40000,50.33324,19.03621
60.50000,50.41681,19.07262
60.60000,50.49993,19.27264
60.70000,50.58330,19.31139
60.80000,50.66680,19.31213
60.90000,50.74999,19.19737
61.00000,50.83318,19.30934
61.10000,50.91662,19.19257
61.20000,50.99993,19.26666
61.30000,51.08324,19.18130
61.40000,51.16674,19.32208
61.50000,51.24999,19.47452
61.60000,51.33331,19.59060
61.70000,51.41674,19.27195
61.80000,51.49993,19.36319
61.90000,51.58324,19.39180
62.00000,51.66674,19.65866
62.10000,51.74999,19.46079
62.20000,51.83324,19.57839
62.30000,51.91681,19.49235
62.40000,51.99999,19.58231
62.50000,52.08324,19.44825
62.60000,52.16674,19.58545
62.70000,52.24993,19.64464
62.80000,52.33324,19.61510
62.90000,52.41668,19.48730
63.00000,52.49993,19.45634
63.10000,52.58324,19.57222
63.20000,52.66674,19.58344
63.30000,52.74993,19.59569
63.40000,52.83324,19.72971
63.50000,52.91680,19.78689
63.60000,52.99999,19.76200
63.70000,53.08331,19.95065
63.80000,53.16680,19.68899
63.90000,53.24999,19.69114
64.00000,53.33324,19.85358
64.10001,53.41668,19.66287
64.20000,53.49999,19.77395
64.30000,53.58324,19.56722
64.40000,53.66674,19.68237
64.50000,53.74999,19.93242
64.60001,53.83330,19.84476
64.70000,53.91681,19.84809
64.80000,53.99999,19.70521
64.90000,54.08324,19.96211
65.00000,54.16675,19.97235
65.10001,54.24999,20.04566
65.20000,54.33324,19.94927
65.30000,54.41674,20.08393
65.40000,54.49999,19.72691
65.50000,54.58324,19.75313
65.60001,54.66674,19.92188
65.70001,54.75000,20.02640
65.80000,54.83331,20.07898
65.90000,54.91674,20.04120
66.00000,55.00000,20.15988
66.10001,55.08318,20.11597
66.20001,55.16674,20.33819
66.30000,55.24993,20.14483
66.40000,55.33325,19.93144
66.50000,55.41674,20.12656
66.60001,55.49999,20.32530
66.70001,55.58331,20.35695
66.80000,55.66674,20.26772
66.90000,55.74999,20.13513
67.00000,55.83324,20.07795
67.10001,55.91668,20.31535
67.20001,55.99987,20.20050
67.30000,56.08324,20.44363
67.40000,56.16674,20.36680
67.50000,56.24993,20.16791
67.60001,56.33330,20.26047
67.70001,56.41674,20.30271
67.80000,56.49999,20.39983
67.90000,56.58324,20.29551
68.00000,56.66674,20.21074
68.10001,56.74999,20.34446
68.20001,56.83324,20.41026
68.30000,56.91674,20.49410
68.40000,56.99993,20.39321
68.50000,57.08324,20.44339
68.60001,57.16668,20.64919
68.70001,57.24993,20.44927
68.80000,57.33324,20.53046
68.90000,57.41687,20.42913
69.00000,57.49993,20.66345
69.10001,57.58324,20.36749
69.20001,57.66674,20.54477
69.30000,57.74999,20.70054
69.40000,57.83318,20.71558
69.50000,57.91674,20.61278
69.60001,57.99993,20.42550
69.70001,58.08318,20.62689
69.80000,58.16674,20.60347
69.90000,58.24999,20.69206
70.00000,58.33331,20.58343
70.10001,58.41680,20.61082
70.20001,58.49999,20.82544
70.30000,58.58331,20.65012
70.40000,58.66674,20.78070
70.50000,58.74987,20.96612
70.60001,58.83324,20.93951
70.70001,58.91668,20.85239
70.80000,58.99999,20.71695
70.90000,59.08330,20.95397
71.00000,59.16681,20.92535
71.10001,59.24999,20.95901
71.20001,59.33330,20.80089
71.30000,59.41668,20.82769
71.40000,59.49993,20.91168
71.50000,59.58318,21.04241
71.60001,59.66668,21.10249
71.70001,59.74993,20.88860
71.80000,59.83324,21.09528
71.90000,59.91681,20.98743
72.00000,59.99999,20.97695
72.10001,60.08324,20.87792
72.20001,60.16674,21.10988
72.30000,60.25000,20.90957
72.40000,60.33324,21.17795
72.50000,60.41668,21.13497
72.60001,60.49993,21.07818
72.70001,60.58331,21.06157
72.80000,60.66668,21.30696
72.90000,60.74987,21.16080
73.00000,60.83325,21.11919
73.10001,60.91674,21.24233
73.20001,60.99993,21.12537
73.30000,61.08331,21.20210
73.40000,61.16674,21.39506
73.50000,61.24999,21.26394
73.60001,61.33324,21.34842
73.70001,61.41668,21.37948
73.80000,61.49993,21.32083
73.90000,61.58324,21.43211
74.00000,61.66674,21.45563
74.10001,61.74999,21.40021
74.20001,61.83330,21.30280
74.30000,61.91680,21.40261
74.40000,61.99993,21.49679
74.50000,62.08324,21.41344
74.60001,62.16674,21.53491
74.70001,62.24993,21.59596
74.80000,62.33318,21.37909
74.90000,62.41681,21.44137
75.00000,62.49999,21.46210
75.10001,62.58324,21.63350
75.20001,62.66681,21.62453
75.30000,62.74993,21.55098
75.40000,62.83324,21.68059
75.50000,62.91674,21.43392
75.60001,62.99999,21.68774
75.70001,63.08330,21.63217
75.80000,63.16674,21.79231
75.90000,63.24993,21.69881
76.00000,63.33324,21.79226
76.10001,63.41674,21.62747
76.20001,63.49999,21.71199
76.30000,63.58324,21.77795
76.40000,63.66680,21.48272
76.50000,63.75005,21.64810
76.60001,63.83324,21.85194
76.70001,63.91668,21.88060
76.80000,63.99993,21.69411
76.90000,64.08324,21.85968
77.00000,64.16674,21.74414
77.10001,64.24999,21.87845
77.20001,64.33330,21.94906
77.30000,64.41674,21.84929
77.40000,64.49999,21.75624
77.50000,64.58324,22.07440
77.60001,64.66674,21.90628
77.70001,64.74993,21.93744
77.80000,64.83324,22.02750
77.90000,64.91674,22.02682
78.00000,64.99999,21.89040
78.10001,65.08324,21.85439
78.20001,65.16668,21.95102
78.30000,65.24993,22.05965
78.40000,65.33330,22.13869
78.50000,65.41674,22.07361
78.60001,65.49993,22.04470
78.70001,65.58330,22.04201
78.80000,65.66674,22.24340
78.90000,65.74993,22.08728
79.00000,65.83324,22.20675
79.10001,65.91674,22.09165
79.20001,65.99993,22.19102
79.30000,66.08331,22.22546
79.40000,66.16674,22.40275
79.50000,66.25005,22.43852
79.60001,66.33330,22.32753
79.70001,66.41674,22.28225
79.80000,66.49998,22.28711
79.90000,66.58318,22.46414
80.00000,66.66674,22.40265
80.10001,66.74992,22.45988
80.20001,66.83324,22.37550
80.30000,66.91680,22.31170
80.40000,66.99999,22.45787
80.50001,67.08324,22.37785
80.60001,67.16674,22.34684
80.70001,67.24992,22.29544
80.80000,67.33330,22.54754
80.90000,67.41674,22.65108
81.00001,67.49999,22.40338
81.10001,67.58330,22.47737
81.20001,67.66674,22.50520
81.30000,67.74993,22.45929
81.40000,67.83324,22.53735
81.50001,67.91674,22.49795
81.60001,67.99993,22.49251
81.70001,68.08330,22.62878
81.80000,68.16674,22.60188
81.90000,68.24999,22.60541
82.00001,68.33324,22.69694
82.10001,68.41668,22.40823
82.20001,68.49999,22.74016
82.30000,68.58324,22.70473
82.40000,68.66674,22.81694
82.50001,68.74993,22.61207
82.60001,68.83324,22.59164
82.70001,68.91680,22.74418
82.80000,68.99999,22.75579
82.90000,69.08331,22.72570
83.00001,69.16680,22.69420
83.10001,69.24999,22.76172
83.20001,69.33324,22.84615
83.30000,69.41680,22.92484
83.40000,69.49992,22.87295
83.50001,69.58318,22.98780
83.60001,69.66674,22.79832
83.70001,69.74999,22.92881
83.80000,69.83330,22.84786
83.90000,69.91674,22.99584
84.00001,69.99999,23.09497
84.10001,70.08330,22.97124
84.20001,70.16674,22.82037
84.30000,70.24992,22.80807
84.40000,70.33323,23.02201
84.50001,70.41674,23.25446
84.60001,70.49999,23.04469
84.70001,70.58330,22.99432
84.80000,70.66680,23.23535
84.90000,70.74999,22.97188
85.00001,70.83324,23.06586
85.10001,70.91674,23.12148
85.20001,70.99999,23.30630
85.30000,71.08324,23.18959
85.40000,71.16674,23.27685
85.50001,71.24993,23.31552
85.60001,71.33324,23.21448
85.70001,71.41673,23.03970
85.80000,71.49993,23.34276
85.90000,71.58324,23.36226
86.00001,71.66680,23.31409
86.10001,71.74999,23.07527
86.20001,71.83324,23.20963
86.30000,71.91674,23.15847
86.40000,71.99999,23.42243
86.50001,72.08318,23.31919
86.60001,72.16674,23.43615
86.70001,72.24993,23.31047
86.80000,72.33324,23.40234
86.90000,72.41681,23.31248
87.00001,72.49999,23.50833
87.10001,72.58330,23.46173
87.20001,72.66680,23.42792
87.30000,72.74993,23.44796
87.40000,72.83324,23.51289
87.50001,72.91668,23.49451
87.60001,72.99993,23.51788
87.70001,73.08324,23.67243
87.80000,73.16674,23.58462
87.90000,73.24999,23.66631
88.00001,73.33330,23.69987
88.10001,73.41674,23.79650
88.20001,73.49999,23.75852
88.30000,73.58330,23.64602
88.40000,73.66681,23.66836
88.50001,73.74993,23.65655
88.60001,73.83324,23.61961
88.70001,73.91667,23.59609
88.80000,73.99993,23.89670
88.90000,74.08318,23.75411
89.00001,74.16674,23.63754
89.10001,74.24999,23.94183
89.20001,74.33324,23.71354
89.30000,74.41680,23.79356
89.40000,74.49999,23.72158
89.50001,74.58330,23.87916
89.60001,74.66674,23.91028
89.70001,74.74992,23.94183
89.80000,74.83324,23.77116
89.90000,74.91674,24.04953
90.00001,74.99993,23.96858
90.10001,75.08317,23.95849
90.20001,75.16674,23.89474
90.30000,75.24999,23.92037
90.40000,75.33330,24.22701
90.50001,75.41680,23.95702
90.60001,75.49999,23.97981
90.70001,75.58330,23.91880
90.80000,75.66668,24.08795
90.90000,75.74987,24.18252
91.00001,75.83324,23.89165
91.10001,75.91668,24.22623
91.20001,75.99992,24.19550
91.30000,76.08336,24.07011
91.40000,76.16680,24.05061
91.50001,76.24999,24.03439
91.60001,76.33324,24.13298
91.70001,76.41668,24.15625
91.80000,76.49993,24.24406
91.90000,76.58318,24.26239
92.00001,76.66674,24.15954
92.10001,76.75005,24.41806
92.20001,76.83330,24.32854
92.30000,76.91680,24.39920
92.40000,76.99999,24.28630
92.50001,77.08324,24.52689
92.60001,77.16680,24.21897
92.70001,77.24993,24.39297
92.80000,77.33324,24.37710
92.90000,77.41680,24.49793
93.00001,77.49993,24.29429
93.10001,77.58324,24.38920
93.20001,77.66674,24.50479
93.30000,77.74999,24.60607
93.40000,77.83324,24.44428
93.50001,77.91674,24.28929
93.60001,77.99999,24.49063
93.70001,78.08330,24.63018
93.80000,78.16673,24.60161
93.90000,78.24999,24.42659
94.00001,78.33323,24.63351
94.10001,78.41674,24.63302
94.20001,78.49992,24.46966
94.30000,78.58329,24.78453
94.40000,78.66674,24.64091
94.50001,78.74999,24.62259
94.60001,78.83323,24.56477
94.70001,78.91674,24.69599
94.80000,78.99993,24.83907
94.90000,79.08324,24.81506
95.00001,79.16674,24.67502
95.10001,79.24993,24.75993
95.20001,79.33323,25.01199
95.30000,79.41674,24.84794
95.40000,79.49992,24.84088
95.50001,79.58324,24.55281
95.60001,79.66680,24.89444
95.70001,79.74993,24.84896
95.80000,79.83324,24.97715
95.90000,79.91680,24.99361
96.00001,79.99999,25.00214
96.10001,80.08324,24.89997
96.20001,80.16674,24.85950
96.30000,80.24992,25.00008
96.40000,80.33324,24.90375
96.50001,80.41673,25.01360
96.60001,80.49992,25.02517
96.70001,80.58324,25.05751
96.80000,80.66680,25.02497
96.90000,80.74999,25.11890
97.00001,80.83324,25.13542
97.10001,80.91674,25.05966
97.20001,80.99993,25.05574
97.30000,81.08323,25.18309
97.40000,81.16674,25.07466
97.50001,81.24999,25.15379
97.60001,81.33323,25.30187
97.70001,81.41674,25.20515
97.80000,81.49998,25.03492
97.90000,81.58323,25.46249
98.00001,81.66674,25.17898
98.10001,81.74999,25.41232
98.20001,81.83324,25.41937
98.30000,81.91674,25.18241
98.40000,81.99993,25.32725
98.50001,82.08317,25.41736
98.60001,82.16674,25.33181
98.70001,82.24999,25.22558
98.80000,82.33324,25.40839
98.90000,82.41680,25.25321
99.00001,82.49999,25.37846
99.10001,82.58330,25.51663
99.20001,82.66667,25.40619
99.30000,82.74992,25.28639
99.40000,82.83324,25.44902
99.50001,82.91667,25.46024
99.60001,82.99992,25.74787
99.70001,83.08330,25.35695
99.80000,83.16680,25.47807
99.90000,83.24998,25.63086
100.00001,83.33330,25.50115
100.10001,83.41667,25.74012
100.20001,83.49999,25.65349
100.30000,83.58317,25.70519
100.40000,83.66674,25.57936
100.50001,83.74998,25.66329
100.60001,83.83330,25.80328
100.70001,83.91674,25.82808
100.80000,83.99999,25.65394
100.90000,84.08330,25.70230
101.00001,84.16668,25.88335
101.10001,84.24993,25.62870
101.20001,84.33324,25.73126
101.30000,84.41680,25.76771
101.40000,84.49992,25.77491
101.50001,84.58324,25.97822
101.60001,84.66673,25.73508
101.70001,84.74993,25.81490
101.80000,84.83318,25.97767
101.90000,84.91680,25.91608
102.00001,84.99992,25.98625
102.10001,85.08329,25.91731
102.20001,85.16674,25.88232
102.30000,85.24999,26.05088
102.40000,85.33323,26.01330
102.50001,85.41674,26.02457
102.60001,85.49993,26.07043
102.70001,85.58324,25.92716
102.80000,85.66674,25.95945
102.90000,85.74999,26.05431
103.00001,85.83323,26.16388
103.10001,85.91673,26.08984
103.20001,85.99998,26.14756
103.30000,86.08324,26.20601
103.40000,86.16674,26.23380
103.50001,86.24999,26.19744
103.60001,86.33324,26.32077
103.70001,86.41673,26.17956
103.80000,86.49993,26.24870
103.90000,86.58324,26.18088
104.00001,86.66674,26.15648
104.10001,86.74999,26.27447
104.20001,86.83329,26.49923
104.30000,86.91681,26.37708
104.40000,86.99999,26.45827
104.50001,87.08323,26.39535
104.60001,87.16674,26.41706
104.70001,87.24999,26.31475
104.80000,87.33324,26.40108
104.90000,87.41674,26.20876
105.00001,87.49993,26.47644
105.10001,87.58330,26.42201
105.20001,87.66674,26.44092
105.30000,87.74993,26.44714
105.40000,87.83330,26.64564
105.50001,87.91680,26.52873
105.60001,87.99993,26.62251
105.70001,88.08331,26.46679
105.80000,88.16673,26.52006
105.90000,88.24993,26.58503
106.00001,88.33317,26.61218
106.10001,88.41667,26.58469
106.20001,88.49998,26.63922
106.30000,88.58330,26.60424
106.40000,88.66680,26.61928
106.50001,88.74998,26.77921
106.60001,88.83330,26.60541
106.70001,88.91680,26.57077
106.80000,88.99992,26.70978
106.90000,89.08317,26.76339
107.00001,89.16673,26.80680
107.10001,89.24992,26.70978
107.20001,89.33323,26.86825
107.30000,89.41674,26.79024
107.40000,89.49992,26.81366
107.50001,89.58324,26.79264
107.60001,89.66674,26.74825
107.70001,89.74993,26.88280
107.80000,89.83330,26.86315
107.90000,89.91674,26.84914
108.00001,89.99986,26.96174
108.10001,90.08324,26.79117
108.20001,90.16674,27.03274
108.30000,90.24998,27.02348
108.40000,90.33323,26.97179
108.50001,90.41680,26.93592
108.60001,90.49999,27.17631
108.70001,90.58330,26.85531
108.80000,90.66674,27.31934
108.90000,90.74998,27.04695
109.00001,90.83324,26.95552
109.10001,90.91668,27.19689
109.20001,90.99992,27.18832
109.30000,91.08324,27.11937
109.40000,91.16674,27.22423
109.50001,91.24999,27.05753
109.60001,91.33330,27.12177
109.70001,91.41673,27.22722
109.80000,91.49999,27.33365
109.90000,91.58324,27.33321
110.00001,91.66680,27.39431
110.10001,91.74992,27.35702
110.20001,91.83324,27.12123
110.30000,91.91674,27.53965
110.40000,91.99993,27.42440
110.50001,92.08323,27.35653
110.60001,92.16674,27.40950
110.70001,92.24999,27.34938
110.80000,92.33336,27.38608
110.90000,92.41686,27.51985
111.00001,92.49998,27.39490
111.10001,92.58323,27.41127
111.20001,92.66668,27.52823
111.30000,92.74992,27.38716
111.40000,92.83324,27.48618
111.50001,92.91674,27.52514
111.60001,93.00006,27.44885
111.70001,93.08336,27.70967
111.80000,93.16674,27.75975
111.90000,93.24999,27.46771
112.00001,93.33324,27.53842
112.10001,93.41667,27.47653
112.20001,93.49992,27.62005
112.30000,93.58324,27.83874
112.40000,93.66673,27.54499
112.50001,93.74999,27.80429
112.60001,93.83324,27.64730
112.70001,93.91680,27.63167
112.80000,93.99992,27.71011
112.90001,94.08324,27.96883
113.00001,94.16673,27.64612
113.10001,94.24998,27.84045
113.20001,94.33329,27.94051
113.30000,94.41674,27.77832
113.40001,94.49992,27.64519
113.50001,94.58323,27.90690
113.60001,94.66674,27.82644
113.70001,94.74993,27.85726
113.80000,94.83330,27.91783
113.90001,94.91679,27.84349
114.00001,94.99999,27.89969
114.10001,95.08323,27.96374
114.20001,95.16673,27.98020
114.30000,95.24993,28.02582
114.40001,95.33317,28.02548
114.50001,95.41674,27.96237
114.60001,95.49998,28.01543
114.70001,95.58330,28.15376
114.80000,95.66673,28.01979
114.90001,95.74998,28.21810
115.00001,95.83324,28.05713
115.10001,95.91680,28.06767
115.20001,95.99992,28.09687
115.30000,96.08324,28.16429
115.40001,96.16673,28.13715
115.50001,96.24992,28.18659
115.60001,96.33318,28.16875
115.70001,96.41673,28.16807
115.80000,96.49992,28.28375
115.90001,96.58324,28.26371
116.00001,96.66679,28.26367
116.10001,96.74999,28.19399
116.20001,96.83330,28.35534
116.30000,96.91673,28.24946
116.40001,96.99993,28.35711
116.50001,97.08324,28.36662
116.60001,97.16674,28.23789
116.70001,97.24992,28.38661
116.80000,97.33323,28.53150
116.90001,97.41680,28.45971
117.00001,97.49998,28.43164
117.10001,97.58330,28.39601
117.20001,97.66679,28.32251
117.30000,97.74992,28.47241
117.40001,97.83324,28.45285
117.50001,97.91673,28.49235
117.60001,97.99998,28.50974
117.70001,98.08330,28.71412
117.80000,98.16674,28.73000
117.90001,98.24992,28.53125
118.00001,98.33324,28.57829
118.10001,98.41673,28.44399
118.20001,98.49992,28.66115
118.30000,98.58323,28.74132
118.40001,98.66673,28.61862
118.50001,98.74999,28.56952
118.60001,98.83317,28.80355
118.70001,98.91674,28.88729
118.80000,98.99999,28.86607
118.90001,99.08323,28.80614
119.00001,99.16673,28.71123
119.10001,99.25004,28.80448
119.20001,99.33330,28.91409
119.30000,99.41679,28.93722
119.40001,99.49992,28.92247
119.50001,99.58323,28.84034
119.60001,99.66668,28.73049
119.70001,99.74992,28.89248
119.80000,99.83324,28.79502
119.90001,99.91674,28.86837
120.00001,99.99998,28.89567
120.10001,100.08324,28.91012
120.20001,100.16680,28.98935
120.30000,100.24998,28.96118
120.40001,100.33330,29.08339
120.50001,100.41674,28.96725
120.60001,100.49986,29.14135
120.70001,100.58329,28.98102
120.80000,100.66673,29.10695
120.90001,100.74992,28.96863
121.00001,100.83323,28.92031
121.10001,100.91674,29.32231
121.20001,100.99999,29.16257
121.30000,101.08329,29.03336
121.40001,101.16667,28.94775
121.50001,101.24998,29.41012
121.60001,101.33323,29.13733
121.70001,101.41673,29.22607
121.80000,101.49999,29.19844
121.90001,101.58330,29.23318
122.00001,101.66674,29.23176
122.10001,101.74992,29.15924
122.20001,101.83323,29.32588
122.30000,101.91679,29.33696
122.40001,101.99992,29.22014
122.50001,102.08324,29.30658
122.60001,102.16679,29.26483
122.70001,102.24998,29.43011
122.80000,102.33324,29.21617
122.90001,102.41680,29.46862
123.00001,102.49992,29.47303
123.10001,102.58324,29.54575
123.20001,102.66673,29.54668
123.30000,102.74992,29.43040
123.40001,102.83330,29.54918
123.50001,102.91680,29.56407
123.60001,102.99998,29.50709
123.70001,103.08329,29.42428
123.80000,103.16680,29.53859
123.90001,103.24992,29.55462
124.00001,103.33317,29.59999
124.10001,103.41674,29.55844
124.20001,103.49993,29.70196
124.30000,103.58323,29.56701
124.40001,103.66674,29.62954
124.50001,103.74999,29.63272
124.60001,103.83330,29.66996
124.70001,103.91674,29.89570
124.80000,103.99998,29.65369
124.90001,104.08323,29.95431
125.00001,104.16673,29.68334
125.10001,104.24992,29.77414
125.20001,104.33324,29.89903
125.30000,104.41673,29.93427
125.40001,104.49992,29.81309
125.50001,104.58324,29.82166
125.60001,104.66673,29.91452
125.70001,104.74999,29.90697
125.80000,104.83329,29.83205
125.90001,104.91680,29.92114
126.00001,104.99992,30.25982
126.10001,105.08330,30.06823
126.20001,105.16667,30.07558
126.30000,105.24986,29.96930
126.40001,105.33324,29.93554
126.50001,105.41674,30.09650
126.60001,105.49999,29.97459
126.70001,105.58330,30.16560
126.80000,105.66674,29.91001
126.90001,105.74998,30.21930
127.00001,105.83323,30.01718
127.10001,105.91674,30.30917
127.20001,105.99992,29.96068
127.30000,106.08330,30.14021
127.40001,106.16673,30.21974
127.50001,106.24993,29.87929
127.60001,106.33330,30.27981
127.70001,106.41679,30.24194
127.80000,106.49998,30.14389
127.90001,106.58330,30.32734
128.00000,106.66680,30.29422
128.10001,106.74998,30.28986
128.20002,106.83317,30.36674
128.30000,106.91673,30.33023
128.40001,106.99992,30.54172
128.50000,107.08317,30.30446
128.60001,107.16673,30.26668
128.70002,107.24992,30.40711
128.80000,107.33330,30.29927
128.90001,107.41680,30.45808
129.00000,107.49999,30.53221
129.10001,107.58329,30.40991
129.20002,107.66674,30.65309
129.30000,107.74992,30.63305
129.40001,107.83323,30.48777
129.50000,107.91673,30.29098
129.60001,107.99998,30.61997
129.70002,108.08324,30.71474
129.80000,108.16674,30.67338
129.90001,108.24999,30.44578
130.00000,108.33330,30.85934
130.10001,108.41673,30.58077
130.20002,108.49998,30.64565
130.30000,108.58330,30.63687
130.40001,108.66679,30.48194
130.50000,108.74998,30.65912
130.60001,108.83324,30.47410
130.70002,108.91673,30.82268
130.80000,108.99986,30.89329
130.90001,109.08323,30.78495
131.00000,109.16680,31.00040
131.10000,109.25005,30.77976
131.20002,109.33329,30.92882
131.30000,109.41680,30.66040
131.40002,109.49999,30.71013
131.50000,109.58323,30.67025
131.60000,109.66667,30.76550
131.70002,109.74992,30.80392
131.80000,109.83324,30.91294
131.90002,109.91674,30.78907
132.00000,109.99999,30.84552
132.10000,110.08330,31.03421
132.20002,110.16673,30.75825
132.30000,110.24999,30.96699
132.40002,110.33324,31.04147
132.50000,110.41667,31.00491
132.60000,110.49998,31.02103
132.70002,110.58323,31.10914
132.80000,110.66673,31.12536
132.90002,110.74998,31.08086
133.00000,110.83324,31.08126
133.10000,110.91674,31.16005
133.20002,110.99992,31.03725
133.30000,111.08330,31.30847
133.40002,111.16680,31.31596
133.50000,111.24992,31.19601
133.60000,111.33323,31.35604
133.70002,111.41674,31.24991
133.80000,111.49992,31.02162
133.90002,111.58324,31.28485
134.00000,111.66673,31.17087
134.10000,111.74999,31.29896
134.20002,111.83330,31.16950
134.30000,111.91680,31.17382
134.40002,111.99992,31.28157
134.50000,112.08324,31.23418
134.60000,112.16674,31.26481
134.70002,112.24993,31.19939
134.80000,112.33323,31.40460
134.90002,112.41673,31.38354
135.00000,112.49999,31.38795
135.10000,112.58330,31.48330
135.20002,112.66680,31.57733
135.30000,112.74998,31.38118
135.40002,112.83323,31.53000
135.50000,112.91673,31.73913
135.60000,112.99998,31.48178
135.70002,113.08324,31.60957
135.80000,113.16667,31.45958
135.90002,113.24992,31.63789
136.00000,113.33324,31.61187
136.10000,113.41673,31.52603
136.20002,113.49998,31.55332
136.30000,113.58330,31.58130
136.40002,113.66680,31.46370
136.50000,113.74999,31.69905
136.60000,113.83324,31.65999
136.70002,113.91673,31.52524
136.80000,113.99992,31.48144
136.90002,114.08318,31.73776
137.00000,114.16674,31.61344
137.10000,114.24999,31.72756
137.20002,114.33329,31.93302
137.30000,114.41674,31.76965
137.40002,114.49993,31.87353
137.50000,114.58330,31.77651
137.60000,114.66674,31.62755
137.70002,114.74992,31.86241
137.80000,114.83330,31.72379
137.90002,114.91674,31.82409
138.00000,114.99998,31.81988
138.10000,115.08323,31.84521
138.20002,115.16673,31.96041
138.30000,115.24999,31.88735
138.40002,115.33324,31.84085
138.50000,115.41673,31.92180
138.60000,115.49998,31.88304
138.70002,115.58330,31.67665
138.80000,115.66673,31.91494
138.90002,115.74992,31.83330
139.00000,115.83317,32.02945
139.10000,115.91673,31.89789
139.20002,115.99986,32.03567
139.30000,116.08324,31.87020
139.40002,116.16680,32.06032
139.50000,116.24998,31.98756
139.60000,116.33324,32.03317
139.70002,116.41674,32.13078
139.80000,116.49992,31.88662
139.90002,116.58323,31.99099
140.00000,116.66674,32.02788
140.10000,116.74993,32.11775
140.20002,116.83323,31.92640
140.30000,116.91674,32.03891
140.40002,116.99992,31.86452
140.50000,117.08323,31.96869
140.60000,117.16680,31.90769
140.70002,117.24993,32.10148
140.80000,117.33323,32.07821
140.90002,117.41679,32.06429
141.00000,117.49987,32.14367
141.10000,117.58317,32.07556
141.20002,117.66673,31.88686
141.30000,117.74998,32.06096
141.40002,117.83330,31.98388
141.50000,117.91673,32.09496
141.60000,117.99999,32.01745
141.70002,118.08329,31.84874
141.80000,118.16673,32.02421
141.90002,118.24999,31.89862
142.00000,118.33330,31.89921
142.10000,118.41673,31.74148
142.20002,118.49998,31.71507
142.30000,118.58324,31.79533
142.40002,118.66674,31.68714
142.50000,118.74992,31.41274
142.60000,118.83317,31.43317
142.70002,118.91673,31.28916
142.80000,118.99998,31.22997
142.90002,119.08330,30.62272
143.00000,119.16674,9.37462
143.10000,119.24999,-0.02316
143.20002,119.33330,0.12310
143.30000,119.41673,-0.09745
143.40002,119.49993,0.06386
143.50000,119.58323,0.19513
143.60000,119.66674,-0.01219
143.70002,119.74998,0.04666
143.80000,119.83329,0.12384
143.90002,119.91680,0.14089
144.00000,119.99992,0.25555
144.10000,120.08330,-0.14375
144.20002,120.16667,0.16353
144.30000,120.24992,-0.07192
144.40002,120.33324,0.15745
144.50000,120.41667,0.10017
144.60000,120.49992,0.04495
144.70002,120.58330,-0.06094
144.80000,120.66680,-0.04090
144.90002,120.74992,0.07871
145.00000,120.83324,0.08978
145.10000,120.91674,-0.11469
145.20002,120.99992,0.19822
145.30000,121.08323,0.05362
145.40002,121.16673,-0.10705
145.50000,121.24993,0.07935
145.60000,121.33324,-0.11876
145.70002,121.41667,0.04911
145.80000,121.49998,-0.11117
145.83602,121.52999,0.09708