File: V_7/FR/RDSO FR Tensile 500.is_tens_RawData/Specimen_RawData_1.csv
Time,Extension,Load,Tensile strain,Tensile stress,Corrected Position
(sec),(mm),(N),(mm/mm),(MPa),(mm)
0.00000,0.00000,-0.13119,0.00000,-0.01458,0.00000
0.02000,0.02000,0.04319,0.00017,0.00480,0.02000
0.04000,0.09775,0.62635,0.00085,0.06959,0.09775
0.06000,0.23369,1.40987,0.00203,0.15665,0.23369
0.08000,0.41675,2.21813,0.00362,0.24646,0.41675
0.10000,0.61937,2.79254,0.00539,0.31028,0.61937
0.12000,0.83169,3.35478,0.00723,0.37275,0.83169
0.14000,1.05044,3.94960,0.00913,0.43884,1.05044
0.16000,1.27062,4.36686,0.01105,0.48521,1.27062
0.18000,1.47275,4.89606,0.01281,0.54401,1.47275
0.20000,1.65306,5.41238,0.01437,0.60138,1.65306
0.22000,1.82087,5.84681,0.01583,0.64965,1.82087
0.24000,1.98587,6.40070,0.01727,0.71119,1.98587
0.26000,2.15275,7.04068,0.01872,0.78230,2.15275
0.28000,2.32181,7.43861,0.02019,0.82651,2.32181
0.30000,2.49150,7.77715,0.02167,0.86413,2.49150
0.32000,2.66081,7.79777,0.02314,0.86642,2.66081
0.34000,2.82925,8.04146,0.02460,0.89350,2.82925
0.36000,2.99700,8.31715,0.02606,0.92413,2.99700
0.38000,3.16425,8.90663,0.02752,0.98963,3.16425
0.40000,3.33137,9.17567,0.02897,1.01952,3.33137
0.42000,3.49837,9.50231,0.03042,1.05581,3.49837
0.44000,3.66537,9.79355,0.03187,1.08817,3.66537
0.46000,3.83244,9.96957,0.03333,1.10773,3.83244
0.48000,3.99937,10.11649,0.03478,1.12405,3.99937
0.50000,4.16619,10.39261,0.03623,1.15473,4.16619
0.52000,4.33294,10.56522,0.03768,1.17391,4.33294
0.54000,4.49962,10.95083,0.03913,1.21676,4.49962
0.56000,4.66637,11.18712,0.04058,1.24301,4.66637
0.58000,4.83319,11.12034,0.04203,1.23559,4.83319
0.60000,4.99987,11.34051,0.04348,1.26006,4.99987
0.62000,5.16650,11.58682,0.04493,1.28742,5.16650
0.64000,5.33319,11.78628,0.04638,1.30959,5.33319
0.66000,5.49994,11.97400,0.04783,1.33044,5.49994
0.68000,5.66662,12.33992,0.04927,1.37110,5.66662
0.70000,5.83331,12.41256,0.05072,1.37917,5.83331
0.72000,5.99994,12.66690,0.05217,1.40743,5.99994
0.74000,6.16656,12.85757,0.05362,1.42862,6.16656
0.76000,6.33331,12.92800,0.05507,1.43644,6.33331
0.78000,6.50000,13.10047,0.05652,1.45561,6.50000
0.80000,6.66669,13.23649,0.05797,1.47072,6.66669
0.82000,6.83331,13.32900,0.05942,1.48100,6.83331
0.84000,6.99994,13.67001,0.06087,1.51889,6.99994
0.86000,7.16656,13.79247,0.06232,1.53250,7.16656
0.88000,7.33331,13.65485,0.06377,1.51721,7.33331
0.90000,7.50000,13.75237,0.06522,1.52804,7.50000
0.92000,7.66662,13.87515,0.06667,1.54168,7.66662
0.94000,7.83331,13.96158,0.06812,1.55129,7.83331
0.96000,7.99994,14.33389,0.06956,1.59265,7.99994
0.98000,8.16656,14.52762,0.07101,1.61418,8.16656
1.00000,8.33337,14.42218,0.07246,1.60246,8.33337
1.02000,8.50006,14.53075,0.07391,1.61453,8.50006
1.04000,8.66669,14.76961,0.07536,1.64107,8.66669
1.06000,8.83331,14.88325,0.07681,1.65369,8.83331
1.08000,9.00000,15.00904,0.07826,1.66767,9.00000
1.10000,9.16669,15.22383,0.07971,1.69154,9.16669
1.12000,9.33344,15.11107,0.08116,1.67901,9.33344
1.14000,9.50006,15.19236,0.08261,1.68804,9.50006
1.16000,9.66669,15.18753,0.08406,1.68750,9.66669
1.18000,9.83331,15.29238,0.08551,1.69915,9.83331
1.20000,9.99994,15.53028,0.08696,1.72559,9.99994
1.22000,10.16669,15.69996,0.08841,1.74444,10.16669
1.24000,10.33337,15.74522,0.08986,1.74947,10.33337
1.26000,10.50000,15.87115,0.09130,1.76346,10.50000
1.28000,10.66656,15.96753,0.09275,1.77417,10.66656
1.30000,10.83325,15.90235,0.09420,1.76693,10.83325
1.32000,11.00000,15.97762,0.09565,1.77529,11.00000
1.34000,11.16669,16.12331,0.09710,1.79148,11.16669
1.36000,11.33337,16.07573,0.09855,1.78619,11.33337
1.38000,11.49994,16.13566,0.10000,1.79285,11.49994
1.40000,11.66650,16.38755,0.10145,1.82084,11.66650
1.42000,11.83325,16.37084,0.10290,1.81898,11.83325
1.44000,12.00000,16.46651,0.10435,1.82961,12.00000
1.46000,12.16669,16.48502,0.10580,1.83167,12.16669
1.48000,12.33331,16.60354,0.10725,1.84484,12.33331
1.50000,12.49994,16.69795,0.10870,1.85533,12.49994
1.52000,12.66662,16.76513,0.11014,1.86279,12.66662
1.54000,12.83337,16.71840,0.11159,1.85760,12.83337
1.56000,13.00000,16.95496,0.11304,1.88388,13.00000
1.58000,13.16662,17.12642,0.11449,1.90294,13.16662
1.60000,13.33331,17.15677,0.11594,1.90631,13.33331
1.62000,13.49994,17.13987,0.11739,1.90443,13.49994
1.64000,13.66668,17.17910,0.11884,1.90879,13.66668
1.66000,13.83337,17.20964,0.12029,1.91218,13.83337
1.68000,14.00006,17.35027,0.12174,1.92781,14.00006
1.70000,14.16662,17.51169,0.12319,1.94574,14.16662
1.72000,14.33331,17.50106,0.12464,1.94456,14.33331
1.74000,14.50006,17.48201,0.12609,1.94245,14.50006
1.76000,14.66669,17.47045,0.12754,1.94116,14.66669
1.78000,14.83331,17.54843,0.12899,1.94983,14.83331
1.80000,15.00000,17.59344,0.13043,1.95483,15.00000
1.82000,15.16662,17.80199,0.13188,1.97800,15.16662
1.84000,15.33331,17.60970,0.13333,1.95663,15.33331
1.86000,15.50006,17.58859,0.13478,1.95429,15.50006
1.88000,15.66668,17.72648,0.13623,1.96961,15.66668
1.90000,15.83331,17.75440,0.13768,1.97271,15.83331
1.92000,16.00000,17.85300,0.13913,1.98367,16.00000
1.94000,16.16656,18.02209,0.14058,2.00245,16.16656
1.96000,16.33331,17.95212,0.14203,1.99468,16.33331
1.98000,16.50006,17.93649,0.14348,1.99294,16.50006
2.00000,16.66668,18.10374,0.14493,2.01153,16.66668
2.02000,16.83337,18.15231,0.14638,2.01692,16.83337
2.04000,17.00000,18.19784,0.14783,2.02198,17.00000
2.06000,17.16662,18.31510,0.14927,2.03501,17.16662
2.08000,17.33331,18.31642,0.15072,2.03516,17.33331
2.10000,17.50000,18.23969,0.15217,2.02663,17.50000
2.12000,17.66662,18.28747,0.15362,2.03194,17.66662
2.14000,17.83325,18.31596,0.15507,2.03511,17.83325
2.16000,17.99993,18.52516,0.15652,2.05835,17.99993
2.18000,18.16662,18.51766,0.15797,2.05752,18.16662
2.20000,18.33337,18.50412,0.15942,2.05601,18.33337
2.22000,18.50006,18.49873,0.16087,2.05541,18.50006
2.24000,18.66662,18.58526,0.16232,2.06503,18.66662
2.26000,18.83331,18.48551,0.16377,2.05395,18.83331
2.28000,19.00006,18.51406,0.16522,2.05712,19.00006
2.30000,19.16675,18.68687,0.16667,2.07632,19.16675
2.32000,19.33337,18.61636,0.16812,2.06848,19.33337
2.34000,19.50000,18.50483,0.16957,2.05609,19.50000
2.36000,19.66662,18.59138,0.17101,2.06571,19.66662
2.38000,19.83337,18.61313,0.17246,2.06813,19.83337
2.40000,20.00006,18.78038,0.17391,2.08671,20.00006
2.42000,20.16668,18.91334,0.17536,2.10148,20.16668
2.44000,20.33331,18.73431,0.17681,2.08159,20.33331
2.46000,20.50000,18.80078,0.17826,2.08898,20.50000
2.48000,20.66662,18.82253,0.17971,2.09139,20.66662
2.50000,20.83337,18.80534,0.18116,2.08948,20.83337
2.52000,21.00000,18.88533,0.18261,2.09837,21.00000
2.54000,21.16662,18.98317,0.18406,2.10924,21.16662
2.56000,21.33331,18.94070,0.18551,2.10452,21.33331
2.58000,21.49994,18.98545,0.18696,2.10949,21.49994
2.60000,21.66662,19.05052,0.18841,2.11672,21.66662
2.62000,21.83337,18.96855,0.18986,2.10762,21.83337
2.64000,22.00000,19.05537,0.19130,2.11726,22.00000
2.66000,22.16662,19.13430,0.19275,2.12603,22.16662
2.68000,22.33325,19.07356,0.19420,2.11929,22.33325
2.70000,22.49993,19.22705,0.19565,2.13634,22.49993
2.72000,22.66662,19.41708,0.19710,2.15745,22.66662
2.74000,22.83331,19.32404,0.19855,2.14711,22.83331
2.76000,23.00000,19.33023,0.20000,2.14780,23.00000
2.78000,23.16662,19.37924,0.20145,2.15325,23.16662
2.80000,23.33331,19.26506,0.20290,2.14056,23.33331
2.82000,23.50000,19.36033,0.20435,2.15115,23.50000
2.84000,23.66669,19.42849,0.20580,2.15872,23.66669
2.86000,23.83337,19.36347,0.20725,2.15150,23.83337
2.88000,24.00006,19.29597,0.20870,2.14400,24.00006
2.90000,24.16662,19.44980,0.21014,2.16109,24.16662
2.92000,24.33337,19.39428,0.21159,2.15492,24.33337
2.94000,24.50006,19.46461,0.21304,2.16273,24.50006
2.96000,24.66668,19.49080,0.21449,2.16564,24.66668
2.98000,24.83331,19.61061,0.21594,2.17896,24.83331
3.00000,24.99993,19.65087,0.21739,2.18343,24.99993
3.02000,25.16662,19.65241,0.21884,2.18360,25.16662
3.04000,25.33337,19.48977,0.22029,2.16553,25.33337
3.06000,25.50012,19.50953,0.22174,2.16773,25.50012
3.08000,25.66662,19.65902,0.22319,2.18434,25.66662
3.10000,25.83325,19.57066,0.22464,2.17452,25.83325
3.12000,25.99987,19.66823,0.22609,2.18536,25.99987
3.14000,26.16662,19.73762,0.22754,2.19307,26.16662
3.16000,26.33337,19.70272,0.22899,2.18919,26.33337
3.18000,26.50006,19.82549,0.23044,2.20283,26.50006
3.20000,26.66662,19.94481,0.23188,2.21609,26.66662
3.22000,26.83331,19.83781,0.23333,2.20420,26.83331
3.24000,27.00000,19.84239,0.23478,2.20471,27.00000
3.26000,27.16668,19.92774,0.23623,2.21419,27.16668
3.28000,27.33331,19.84249,0.23768,2.20472,27.33331
3.30000,27.49993,19.81060,0.23913,2.20118,27.49993
3.32000,27.66656,19.97753,0.24058,2.21973,27.66656
3.34000,27.83331,19.91829,0.24203,2.21314,27.83331
3.36000,28.00006,20.18730,0.24348,2.24303,28.00006
3.38000,28.16675,20.32849,0.24493,2.25872,28.16675
3.40000,28.33337,20.10922,0.24638,2.23436,28.33337
3.42000,28.50000,20.10337,0.24783,2.23371,28.50000
3.44000,28.66662,20.16063,0.24927,2.24007,28.66662
3.46000,28.83337,20.22570,0.25072,2.24730,28.83337
3.48000,29.00006,19.98214,0.25217,2.22024,29.00006
3.50000,29.16669,20.05321,0.25362,2.22813,29.16669
3.52000,29.33331,20.10993,0.25507,2.23444,29.33331
3.54000,29.50000,20.26567,0.25652,2.25174,29.50000
3.56000,29.66662,20.33677,0.25797,2.25964,29.66662
3.58000,29.83337,20.20660,0.25942,2.24518,29.83337
3.60000,30.00006,20.28688,0.26087,2.25410,30.00006
3.62000,30.16668,20.35766,0.26232,2.26196,30.16668
3.64000,30.33337,20.32063,0.26377,2.25785,30.33337
3.66000,30.49999,20.20180,0.26522,2.24464,30.49999
3.68000,30.66662,20.28428,0.26667,2.25381,30.66662
3.70000,30.83337,20.21066,0.26812,2.24563,30.83337
3.72000,31.00000,20.32631,0.26957,2.25848,31.00000
3.74000,31.16662,20.38406,0.27101,2.26490,31.16662
3.76000,31.33331,20.27875,0.27246,2.25319,31.33331
3.78000,31.49999,20.47588,0.27391,2.27510,31.49999
3.80000,31.66668,20.66591,0.27536,2.29621,31.66668
3.82000,31.83337,20.58739,0.27681,2.28749,31.83337
3.84000,31.99999,20.66297,0.27826,2.29589,31.99999
3.86000,32.16656,20.79238,0.27971,2.31026,32.16656
3.88000,32.33331,20.64264,0.28116,2.29363,32.33331
3.90000,32.50000,20.52442,0.28261,2.28049,32.50000
3.92000,32.66668,20.70553,0.28406,2.30061,32.66668
3.94000,32.83331,20.71594,0.28551,2.30177,32.83331
3.96000,32.99993,20.85218,0.28696,2.31691,32.99993
3.98000,33.16662,20.73078,0.28841,2.30342,33.16662
4.00000,33.33337,20.79221,0.28986,2.31025,33.33337
4.02000,33.50006,20.88011,0.29130,2.32001,33.50006
4.04000,33.66675,20.92174,0.29275,2.32464,33.66675
4.06000,33.83337,20.77766,0.29420,2.30863,33.83337
4.08000,34.00000,20.85713,0.29565,2.31746,34.00000
4.10000,34.16668,20.93384,0.29710,2.32598,34.16668
4.12000,34.33337,20.89517,0.29855,2.32169,34.33337
4.14000,34.50006,20.88108,0.30000,2.32012,34.50006
4.16000,34.66662,20.99027,0.30145,2.33225,34.66662
4.18000,34.83331,20.93347,0.30290,2.32594,34.83331
4.20000,34.99999,21.01299,0.30435,2.33478,34.99999
4.22000,35.16668,21.16624,0.30580,2.35180,35.16668
4.24000,35.33337,21.08813,0.30725,2.34313,35.33337
4.26000,35.49999,21.03511,0.30870,2.33723,35.49999
4.28000,35.66662,21.04045,0.31014,2.33783,35.66662
4.30000,35.83331,20.98309,0.31159,2.33145,35.83331
4.32000,35.99999,21.19271,0.31304,2.35475,35.99999
4.34000,36.16662,21.13562,0.31449,2.34840,36.16662
4.36000,36.33337,21.04579,0.31594,2.33842,36.33337
4.38000,36.50000,21.31377,0.31739,2.36820,36.50000
4.40000,36.66662,21.30581,0.31884,2.36731,36.66662
4.42000,36.83331,20.95546,0.32029,2.32838,36.83331
4.44000,36.99999,20.94552,0.32174,2.32728,36.99999
4.46000,37.16662,21.04975,0.32319,2.33886,37.16662
4.48000,37.33324,21.14522,0.32464,2.34947,37.33324
4.50000,37.49993,21.27348,0.32609,2.36372,37.49993
4.52000,37.66656,21.48575,0.32754,2.38731,37.66656
4.54000,37.83331,21.35739,0.32899,2.37304,37.83331
4.56000,38.00006,21.49831,0.33044,2.38870,38.00006
4.58000,38.16668,21.50372,0.33188,2.38930,38.16668
4.60000,38.33331,21.54031,0.33333,2.39337,38.33331
4.62000,38.50000,21.58893,0.33478,2.39877,38.50000
4.64000,38.66668,21.63240,0.33623,2.40360,38.66668
4.66000,38.83337,21.44039,0.33768,2.38227,38.83337
4.68000,39.00006,21.58883,0.33913,2.39876,39.00006
4.70000,39.16662,21.72209,0.34058,2.41357,39.16662
4.72000,39.33331,21.77582,0.34203,2.41954,39.33331
4.74000,39.49999,21.79015,0.34348,2.42113,39.49999
4.76000,39.66668,21.75975,0.34493,2.41775,39.66668
4.78000,39.83337,21.62253,0.34638,2.40250,39.83337
4.80000,39.99999,21.66242,0.34783,2.40694,39.99999
4.82000,40.16662,21.86700,0.34927,2.42967,40.16662
4.84000,40.33331,21.81841,0.35072,2.42427,40.33331
4.86000,40.50006,21.81104,0.35217,2.42345,40.50006
4.88000,40.66668,21.86629,0.35362,2.42959,40.66668
4.90000,40.83337,21.77283,0.35507,2.41920,40.83337
4.92000,40.99999,21.97469,0.35652,2.44163,40.99999
4.94000,41.16662,22.14892,0.35797,2.46099,41.16662
4.96000,41.33337,22.15178,0.35942,2.46131,41.33337
4.98000,41.50006,22.16829,0.36087,2.46314,41.50006
5.00000,41.66668,22.13782,0.36232,2.45976,41.66668
5.02000,41.83331,22.15803,0.36377,2.46200,41.83331
5.04000,41.99993,22.25548,0.36522,2.47283,41.99993
5.06000,42.16662,22.32031,0.36667,2.48003,42.16662
5.08000,42.33337,22.20231,0.36812,2.46692,42.33337
5.10000,42.50005,22.19207,0.36957,2.46579,42.50005
5.12000,42.66662,22.23924,0.37101,2.47103,42.66662
5.14000,42.83324,22.25139,0.37246,2.47238,42.83324
5.16000,42.99993,22.32888,0.37391,2.48099,42.99993
5.18000,43.16668,22.47103,0.37536,2.49678,43.16668
5.20000,43.33337,22.41452,0.37681,2.49050,43.33337
5.22000,43.50006,22.31911,0.37826,2.47990,43.50006
5.24000,43.66668,22.21284,0.37971,2.46809,43.66668
5.26000,43.83337,22.23214,0.38116,2.47024,43.83337
5.28000,44.00006,22.37693,0.38261,2.48633,44.00006
5.30000,44.16674,22.57803,0.38406,2.50867,44.16674
5.32000,44.33337,22.56936,0.38551,2.50771,44.33337
5.34000,44.49999,22.65057,0.38696,2.51673,44.49999
5.36000,44.66662,22.78385,0.38841,2.53154,44.66662
5.38000,44.83331,22.53948,0.38985,2.50439,44.83331
5.40000,45.00006,22.57487,0.39130,2.50832,45.00006
5.42000,45.16675,22.68804,0.39275,2.52089,45.16675
5.44000,45.33337,22.69661,0.39420,2.52185,45.33337
5.46000,45.49999,22.82083,0.39565,2.53565,45.49999
5.48000,45.66662,22.88267,0.39710,2.54252,45.66662
5.50000,45.83331,22.85453,0.39855,2.53939,45.83331
5.52000,45.99999,22.91478,0.40000,2.54609,45.99999
5.54000,46.16668,23.01529,0.40145,2.55725,46.16668
5.56000,46.33330,22.96641,0.40290,2.55182,46.33330
5.58000,46.49993,23.21022,0.40435,2.57891,46.49993
5.60000,46.66662,23.10789,0.40580,2.56754,46.66662
5.62000,46.83337,22.83286,0.40725,2.53698,46.83337
5.64000,47.00006,23.07172,0.40870,2.56352,47.00006
5.66000,47.16662,23.08512,0.41014,2.56501,47.16662
5.68000,47.33324,23.06410,0.41159,2.56268,47.33324
5.70000,47.49993,23.29305,0.41304,2.58812,47.49993
5.72000,47.66662,23.40605,0.41449,2.60067,47.66662
5.74000,47.83337,23.26397,0.41594,2.58489,47.83337
5.76000,47.99999,23.30291,0.41739,2.58921,47.99999
5.78000,48.16656,23.29197,0.41884,2.58800,48.16656
5.80000,48.33330,23.28288,0.42029,2.58699,48.33330
5.82000,48.50006,23.37837,0.42174,2.59760,48.50006
5.84000,48.66675,23.62936,0.42319,2.62548,48.66675
5.86000,48.83343,23.36498,0.42464,2.59611,48.83343
5.88000,49.00006,23.35983,0.42609,2.59554,49.00006
5.90000,49.16668,23.53090,0.42754,2.61454,49.16668
5.92000,49.33337,23.31925,0.42899,2.59103,49.33337
5.94000,49.50006,23.38584,0.43044,2.59843,49.50006
5.96000,49.66668,23.43889,0.43188,2.60432,49.66668
5.98000,49.83330,23.37747,0.43333,2.59750,49.83330
6.00000,49.99993,23.63524,0.43478,2.62614,49.99993
6.02000,50.16662,23.71400,0.43623,2.63489,50.16662
6.04000,50.33337,23.54824,0.43768,2.61647,50.33337
6.06000,50.50005,23.73139,0.43913,2.63682,50.50005
6.08000,50.66668,23.85566,0.44058,2.65063,50.66668
6.10000,50.83330,23.77672,0.44203,2.64186,50.83330
6.12000,50.99999,23.77425,0.44348,2.64158,50.99999
6.14000,51.16662,23.67707,0.44493,2.63079,51.16662
6.16000,51.33331,23.64714,0.44638,2.62746,51.33331
6.18000,51.49999,23.86704,0.44783,2.65189,51.49999
6.20000,51.66662,23.98036,0.44927,2.66448,51.66662
6.22000,51.83330,23.95073,0.45072,2.66119,51.83330
6.24000,51.99999,23.93114,0.45217,2.65902,51.99999
6.26000,52.16668,24.01835,0.45362,2.66871,52.16668
6.28000,52.33337,24.03581,0.45507,2.67065,52.33337
6.30000,52.49999,24.05269,0.45652,2.67252,52.49999
6.32000,52.66655,24.32983,0.45797,2.70331,52.66655
6.34000,52.83324,24.26578,0.45942,2.69620,52.83324
6.36000,52.99999,24.23853,0.46087,2.69317,52.99999
6.38000,53.16668,24.35745,0.46232,2.70638,53.16668
6.40000,53.33337,24.27857,0.46377,2.69762,53.33337
6.42000,53.50005,24.33928,0.46522,2.70436,53.50005
6.44000,53.66668,24.53413,0.46667,2.72601,53.66668
6.46000,53.83343,24.43367,0.46812,2.71485,53.83343
6.48000,54.00012,24.52635,0.46957,2.72515,54.00012
6.50000,54.16675,24.54378,0.47102,2.72709,54.16675
6.52000,54.33330,24.57685,0.47246,2.73076,54.33330
6.54000,54.49993,24.72093,0.47391,2.74677,54.49993
6.56000,54.66662,24.75046,0.47536,2.75005,54.66662
6.58000,54.83337,24.52642,0.47681,2.72516,54.83337
6.60000,55.00006,24.63225,0.47826,2.73692,55.00006
6.62000,55.16668,24.78037,0.47971,2.75337,55.16668
6.64000,55.33330,24.87468,0.48116,2.76385,55.33330
6.66000,55.49999,24.81399,0.48261,2.75711,55.49999
6.68000,55.66668,24.85078,0.48406,2.76120,55.66668
6.70000,55.83337,24.80155,0.48551,2.75573,55.83337
6.72000,55.99999,24.84642,0.48696,2.76071,55.99999
6.74000,56.16656,24.83023,0.48840,2.75891,56.16656
6.76000,56.33330,24.70075,0.48985,2.74453,56.33330
6.78000,56.49999,24.74596,0.49130,2.74955,56.49999
6.80000,56.66668,24.88587,0.49275,2.76510,56.66668
6.82000,56.83336,24.95144,0.49420,2.77238,56.83336
6.84000,56.99999,24.93339,0.49565,2.77038,56.99999
6.86000,57.16662,25.09074,0.49710,2.78786,57.16662
6.88000,57.33330,25.03483,0.49855,2.78165,57.33330
6.90000,57.49999,25.31420,0.50000,2.81269,57.49999
6.92000,57.66662,25.44758,0.50145,2.82751,57.66662
6.94000,57.83331,25.32062,0.50290,2.81340,57.83331
6.96000,57.99993,25.46374,0.50435,2.82930,57.99993
6.98000,58.16662,25.53330,0.50580,2.83703,58.16662
7.00000,58.33337,25.23166,0.50725,2.80352,58.33337
7.02000,58.50005,25.30484,0.50870,2.81165,58.50005
7.04000,58.66668,25.46778,0.51015,2.82975,58.66668
7.06000,58.83337,25.51669,0.51159,2.83519,58.83337
7.08000,59.00005,25.66521,0.51304,2.85169,59.00005
7.10000,59.16668,25.78534,0.51449,2.86504,59.16668
7.12000,59.33343,25.62482,0.51594,2.84720,59.33343
7.14000,59.50006,25.71544,0.51739,2.85727,59.50006
7.16000,59.66661,25.82692,0.51884,2.86966,59.66661
7.18000,59.83324,25.64442,0.52029,2.84938,59.83324
7.20000,59.99999,25.74830,0.52174,2.86092,59.99999
7.22000,60.16674,25.89932,0.52319,2.87770,60.16674
7.24000,60.33343,25.91698,0.52464,2.87966,60.33343
7.26000,60.50006,25.98393,0.52609,2.88710,60.50006
7.28000,60.66662,26.03054,0.52754,2.89228,60.66662
7.30000,60.83325,26.06368,0.52898,2.89596,60.83325
7.32000,60.99993,26.05533,0.53043,2.89504,60.99993
7.34000,61.16662,26.12380,0.53188,2.90264,61.16662
7.36000,61.33331,26.12322,0.53333,2.90258,61.33331
7.38000,61.49993,26.21452,0.53478,2.91272,61.49993
7.40000,61.66662,26.22434,0.53623,2.91382,61.66662
7.42000,61.83337,26.16267,0.53768,2.90696,61.83337
7.44000,62.00006,26.22035,0.53913,2.91337,62.00006
7.46000,62.16674,26.48422,0.54058,2.94269,62.16674
7.48000,62.33331,26.51422,0.54203,2.94602,62.33331
7.50000,62.49987,26.63398,0.54348,2.95933,62.49987
7.52000,62.66655,26.73219,0.54493,2.97024,62.66655
7.54000,62.83336,26.52419,0.54638,2.94713,62.83336
7.56000,63.00006,26.46754,0.54783,2.94084,63.00006
7.58000,63.16668,26.53183,0.54928,2.94798,63.16668
7.60000,63.33336,26.53364,0.55072,2.94818,63.33336
7.62000,63.50006,26.66359,0.55217,2.96262,63.50006
7.64000,63.66674,26.74247,0.55362,2.97139,63.66674
7.66000,63.83342,26.69976,0.55507,2.96664,63.83342
7.68000,64.00005,26.76094,0.55652,2.97344,64.00005
7.70000,64.16661,26.83752,0.55797,2.98195,64.16661
7.72000,64.33330,26.85795,0.55942,2.98422,64.33330
7.74000,64.49999,26.99843,0.56087,2.99983,64.49999
7.76000,64.66668,27.03588,0.56232,3.00399,64.66668
7.78000,64.83336,26.98347,0.56377,2.99816,64.83336
7.80000,64.99999,26.89633,0.56522,2.98848,64.99999
7.82000,65.16661,27.07715,0.56667,3.00857,65.16661
7.84000,65.33337,27.13791,0.56812,3.01532,65.33337
7.86000,65.49999,27.33004,0.56957,3.03667,65.49999
7.88000,65.66662,27.44221,0.57101,3.04913,65.66662
7.90000,65.83330,27.21618,0.57246,3.02402,65.83330
7.92000,65.99993,27.18216,0.57391,3.02024,65.99993
7.94000,66.16662,27.17183,0.57536,3.01909,66.16662
7.96000,66.33330,27.22525,0.57681,3.02503,66.33330
7.98000,66.50005,27.40437,0.57826,3.04493,66.50005
8.00000,66.66668,27.49808,0.57971,3.05534,66.66668
8.02000,66.83336,27.43503,0.58116,3.04834,66.83336
8.04000,66.99999,27.56915,0.58261,3.06324,66.99999
8.06000,67.16661,27.68702,0.58406,3.07634,67.16661
8.08000,67.33336,27.65063,0.58551,3.07229,67.33336
8.10000,67.49999,27.79873,0.58696,3.08875,67.49999
8.12000,67.66662,27.85053,0.58841,3.09450,67.66662
8.14000,67.83330,27.95934,0.58985,3.10659,67.83330
8.16000,67.99993,28.02929,0.59130,3.11437,67.99993
8.18000,68.16661,28.00779,0.59275,3.11198,68.16661
8.20000,68.33337,27.82540,0.59420,3.09171,68.33337
8.22000,68.50005,27.90144,0.59565,3.10016,68.50005
8.24000,68.66667,28.02020,0.59710,3.11336,68.66667
8.26000,68.83330,27.91146,0.59855,3.10127,68.83330
8.28000,69.00005,28.03512,0.60000,3.11501,69.00005
8.30000,69.16674,28.08358,0.60145,3.12040,69.16674
8.32000,69.33343,28.00272,0.60290,3.11141,69.33343
8.34000,69.49999,28.14371,0.60435,3.12708,69.49999
8.36000,69.66662,28.31843,0.60580,3.14649,69.66662
8.38000,69.83330,28.27102,0.60725,3.14122,69.83330
8.40000,69.99999,28.17224,0.60870,3.13025,69.99999
8.42000,70.16668,28.35470,0.61015,3.15052,70.16668
8.44000,70.33336,28.33136,0.61159,3.14793,70.33336
8.46000,70.49999,28.36051,0.61304,3.15117,70.49999
8.48000,70.66661,28.44336,0.61449,3.16037,70.66661
8.50000,70.83336,28.47610,0.61594,3.16401,70.83336
8.52000,70.99999,28.62577,0.61739,3.18064,70.99999
8.54000,71.16661,28.79084,0.61884,3.19898,71.16661
8.56000,71.33324,28.70968,0.62029,3.18996,71.33324
8.58000,71.49993,28.65095,0.62174,3.18344,71.49993
8.60000,71.66667,28.63417,0.62319,3.18157,71.66667
8.62000,71.83337,28.67012,0.62464,3.18557,71.83337
8.64000,72.00005,29.00457,0.62609,3.22273,72.00005
8.66000,72.16662,29.02436,0.62754,3.22493,72.16662
8.68000,72.33330,28.88185,0.62899,3.20909,72.33330
8.70000,72.49999,29.01689,0.63043,3.22410,72.49999
8.72000,72.66662,28.99328,0.63188,3.22148,72.66662
8.74000,72.83330,28.94249,0.63333,3.21583,72.83330
8.76000,72.99999,29.13484,0.63478,3.23720,72.99999
8.78000,73.16662,29.35492,0.63623,3.26166,73.16662
8.80000,73.33330,29.27846,0.63768,3.25316,73.33330
8.82000,73.49999,29.30846,0.63913,3.25650,73.49999
8.84000,73.66668,29.38228,0.64058,3.26470,73.66668
8.86000,73.83336,29.24980,0.64203,3.24998,73.83336
8.88000,74.00006,29.31338,0.64348,3.25704,74.00006
8.90000,74.16668,29.43457,0.64493,3.27051,74.16668
8.92000,74.33336,29.45565,0.64638,3.27285,74.33336
8.94000,74.50006,29.48230,0.64783,3.27581,74.50006
8.96000,74.66668,29.63145,0.64928,3.29238,74.66668
8.98000,74.83337,29.59075,0.65072,3.28786,74.83337
9.00000,74.99999,29.73324,0.65217,3.30369,74.99999
9.02000,75.16661,29.74283,0.65362,3.30476,75.16661
9.04000,75.33337,29.66030,0.65507,3.29559,75.33337
9.06000,75.50005,29.85243,0.65652,3.31694,75.50005
9.08000,75.66662,29.90210,0.65797,3.32246,75.66662
9.10000,75.83330,29.89380,0.65942,3.32153,75.83330
9.12000,75.99999,29.85973,0.66087,3.31775,75.99999
9.14000,76.16668,30.02914,0.66232,3.33657,76.16668
9.16000,76.33343,30.12864,0.66377,3.34763,76.33343
9.18000,76.50005,30.06778,0.66522,3.34086,76.50005
9.20000,76.66655,30.07942,0.66667,3.34216,76.66655
9.22000,76.83324,29.89368,0.66812,3.32152,76.83324
9.24000,76.99999,30.09548,0.66957,3.34394,76.99999
9.26000,77.16668,30.24517,0.67101,3.36057,77.16668
9.28000,77.33336,30.16009,0.67246,3.35112,77.33336
9.30000,77.49998,30.35786,0.67391,3.37310,77.49998
9.32000,77.66661,30.53091,0.67536,3.39232,77.66661
9.34000,77.83331,30.37581,0.67681,3.37509,77.83331
9.36000,77.99999,30.48026,0.67826,3.38670,77.99999
9.38000,78.16661,30.73994,0.67971,3.41555,78.16661
9.40000,78.33330,30.59121,0.68116,3.39902,78.33330
9.42000,78.49999,30.48092,0.68261,3.38677,78.49999
9.44000,78.66661,30.58560,0.68406,3.39840,78.66661
9.46000,78.83336,30.65511,0.68551,3.40612,78.83336
9.48000,79.00012,30.79816,0.68696,3.42202,79.00012
9.50000,79.16674,30.88155,0.68841,3.43128,79.16674
9.52000,79.33336,30.96323,0.68986,3.44036,79.33336
9.54000,79.49992,31.13751,0.69130,3.45972,79.49992
9.56000,79.66661,31.02781,0.69275,3.44753,79.66661
9.58000,79.83330,30.90389,0.69420,3.43377,79.83330
9.60000,79.99999,30.90707,0.69565,3.43412,79.99999
9.62000,80.16667,31.07167,0.69710,3.45241,80.16667
9.64000,80.33336,31.07621,0.69855,3.45291,80.33336
9.66000,80.49999,31.19173,0.70000,3.46575,80.49999
9.68000,80.66667,31.18061,0.70145,3.46451,80.66667
9.70000,80.83336,31.16210,0.70290,3.46246,80.83336
9.72000,80.99998,31.31042,0.70435,3.47894,80.99998
9.74000,81.16661,31.59578,0.70580,3.51064,81.16661
9.76000,81.33323,31.63825,0.70725,3.51536,81.33323
9.78000,81.49993,31.54602,0.70869,3.50511,81.49993
9.80000,81.66668,31.37257,0.71015,3.48584,81.66668
9.82000,81.83336,31.28700,0.71159,3.47633,81.83336
9.84000,81.99993,31.31767,0.71304,3.47974,81.99993
9.86000,82.16655,31.47103,0.71449,3.49678,82.16655
9.88000,82.33330,31.54548,0.71594,3.50505,82.33330
9.90000,82.49999,31.62748,0.71739,3.51416,82.49999
9.92000,82.66667,31.68278,0.71884,3.52031,82.66667
9.94000,82.83329,31.72520,0.72029,3.52502,82.83329
9.96000,82.99992,31.94381,0.72174,3.54931,82.99992
9.98000,83.16656,32.09031,0.72319,3.56559,83.16656
10.00000,83.33337,31.96286,0.72464,3.55143,83.33337
10.02000,83.50004,32.08874,0.72609,3.56542,83.50004
10.04000,83.66668,32.17814,0.72754,3.57535,83.66668
10.06000,83.83336,32.16388,0.72899,3.57376,83.83336
10.08000,83.99999,32.31710,0.73043,3.59079,83.99999
10.10000,84.16668,32.22021,0.73188,3.58002,84.16668
10.12000,84.33343,32.40071,0.73333,3.60008,84.33343
10.14000,84.50005,32.57024,0.73478,3.61892,84.50005
10.16000,84.66662,32.64734,0.73623,3.62748,84.66662
10.18000,84.83330,32.52978,0.73768,3.61442,84.83330
10.20000,84.99999,32.61565,0.73913,3.62396,84.99999
10.22000,85.16667,32.62618,0.74058,3.62513,85.16667
10.24000,85.33343,32.57666,0.74203,3.61963,85.33343
10.26000,85.50005,32.61330,0.74348,3.62370,85.50005
10.28000,85.66661,32.64303,0.74493,3.62700,85.66661
10.30000,85.83331,32.70151,0.74638,3.63350,85.83331
10.32000,86.00005,32.88162,0.74783,3.65351,86.00005
10.34000,86.16667,32.96347,0.74928,3.66261,86.16667
10.36000,86.33330,32.89813,0.75072,3.65535,86.33330
10.38000,86.49998,32.96034,0.75217,3.66226,86.49998
10.40000,86.66655,33.06295,0.75362,3.67366,86.66655
10.42000,86.83329,33.03268,0.75507,3.67030,86.83329
10.44000,87.00005,32.97816,0.75652,3.66424,87.00005
10.46000,87.16667,32.99967,0.75797,3.66663,87.16667
10.48000,87.33329,33.09680,0.75942,3.67742,87.33329
10.50000,87.49999,33.22234,0.76087,3.69137,87.49999
10.52000,87.66661,33.46524,0.76232,3.71836,87.66661
10.54000,87.83330,33.52789,0.76377,3.72532,87.83330
10.56000,87.99993,33.50379,0.76522,3.72264,87.99993
10.58000,88.16655,33.43159,0.76667,3.71462,88.16655
10.60000,88.33330,33.36904,0.76812,3.70767,88.33330
10.62000,88.49998,33.56928,0.76957,3.72992,88.49998
10.64000,88.66668,33.72333,0.77101,3.74704,88.66668
10.66000,88.83343,33.71148,0.77246,3.74572,88.83343
10.68000,89.00005,33.85377,0.77391,3.76153,89.00005
10.70000,89.16668,33.89085,0.77536,3.76565,89.16668
10.72000,89.33330,33.71280,0.77681,3.74587,89.33330
10.74000,89.49999,33.82913,0.77826,3.75879,89.49999
10.76000,89.66668,33.86842,0.77971,3.76316,89.66668
10.78000,89.83336,33.86450,0.78116,3.76272,89.83336
10.80000,89.99999,33.93802,0.78261,3.77089,89.99999
10.82000,90.16661,34.10779,0.78406,3.78975,90.16661
10.84000,90.33330,34.06910,0.78551,3.78546,90.33330
10.86000,90.50005,34.23897,0.78696,3.80433,90.50005
10.88000,90.66674,34.38141,0.78841,3.82016,90.66674
10.90000,90.83336,34.27712,0.78986,3.80857,90.83336
10.92000,90.99999,34.27061,0.79130,3.80785,90.99999
10.94000,91.16654,34.36696,0.79275,3.81855,91.16654
10.96000,91.33330,34.24867,0.79420,3.80541,91.33330
10.98000,91.50005,34.27987,0.79565,3.80887,91.50005
11.00000,91.66667,34.65767,0.79710,3.85085,91.66667
11.02000,91.83330,34.70455,0.79855,3.85606,91.83330
11.04000,91.99998,34.80496,0.80000,3.86722,91.99998
11.06000,92.16661,34.84777,0.80145,3.87197,92.16661
11.08000,92.33336,34.68868,0.80290,3.85430,92.33336
11.10000,92.49998,34.71464,0.80435,3.85718,92.49998
11.12000,92.66655,34.82617,0.80580,3.86957,92.66655
11.14000,92.83324,34.91203,0.80725,3.87911,92.83324
11.16000,92.99998,34.93070,0.80870,3.88119,92.99998
11.18000,93.16674,35.03434,0.81015,3.89270,93.16674
11.20000,93.33342,35.07598,0.81159,3.89733,93.33342
11.22000,93.50005,35.09640,0.81304,3.89960,93.50005
11.24000,93.66661,35.23571,0.81449,3.91508,93.66661
11.26000,93.83336,35.19692,0.81594,3.91077,93.83336
11.28000,94.00005,35.31369,0.81739,3.92374,94.00005
11.30000,94.16673,35.22522,0.81884,3.91391,94.16673
11.32000,94.33337,35.30183,0.82029,3.92243,94.33337
11.34000,94.50004,35.45221,0.82174,3.93913,94.50004
11.36000,94.66661,35.53009,0.82319,3.94779,94.66661
11.38000,94.83336,35.44540,0.82464,3.93838,94.83336
11.40000,95.00004,35.55253,0.82609,3.95028,95.00004
11.42000,95.16668,35.74277,0.82754,3.97142,95.16668
11.44000,95.33335,35.72127,0.82899,3.96903,95.33335
11.46000,95.49998,35.77270,0.83043,3.97474,95.49998
11.48000,95.66661,35.65132,0.83188,3.96126,95.66661
11.50000,95.83330,35.65215,0.83333,3.96135,95.83330
11.52000,96.00005,35.81865,0.83478,3.97985,96.00005
11.54000,96.16667,35.96990,0.83623,3.99666,96.16667
11.56000,96.33330,36.11264,0.83768,4.01252,96.33330
11.58000,96.49992,36.13062,0.83913,4.01451,96.49992
11.60000,96.66661,36.01291,0.84058,4.00143,96.66661
11.62000,96.83336,35.81355,0.84203,3.97928,96.83336
11.64000,97.00004,35.95056,0.84348,3.99451,97.00004
11.66000,97.16661,36.23250,0.84493,4.02583,97.16661
11.68000,97.33323,36.38953,0.84638,4.04328,97.33323
11.70000,97.49993,36.47207,0.84783,4.05245,97.49993
11.72000,97.66667,36.52796,0.84928,4.05866,97.66667
11.74000,97.83336,36.36965,0.85072,4.04107,97.83336
11.76000,97.99998,36.45057,0.85217,4.05006,97.99998
11.78000,98.16661,36.47143,0.85362,4.05238,98.16661
11.80000,98.33329,36.42931,0.85507,4.04770,98.33329
11.82000,98.49999,36.60197,0.85652,4.06689,98.49999
11.84000,98.66673,36.72928,0.85797,4.08103,98.66673
11.86000,98.83337,36.78237,0.85942,4.08693,98.83337
11.88000,98.99999,36.85604,0.86087,4.09512,98.99999
11.90000,99.16661,36.77517,0.86232,4.08613,99.16661
11.92000,99.33336,36.70743,0.86377,4.07860,99.33336
11.94000,99.50005,37.03297,0.86522,4.11477,99.50005
11.96000,99.66673,37.16316,0.86667,4.12924,99.66673
11.98000,99.83336,36.93299,0.86812,4.10367,99.83336
12.00000,99.99998,36.97061,0.86957,4.10785,99.99998
12.02000,100.16668,37.03894,0.87101,4.11544,100.16668
12.04000,100.33342,37.29918,0.87246,4.14435,100.33342
12.06000,100.50005,37.34905,0.87391,4.14989,100.50005
12.08000,100.66661,37.51774,0.87536,4.16864,100.66661
12.10000,100.83330,37.40944,0.87681,4.15660,100.83330
12.12000,100.99999,37.52632,0.87826,4.16959,100.99999
12.14000,101.16661,37.47400,0.87971,4.16378,101.16661
12.16000,101.33336,37.33744,0.88116,4.14860,101.33336
12.18000,101.50004,37.63550,0.88261,4.18172,101.50004
12.20000,101.66661,37.76339,0.88406,4.19593,101.66661
12.22000,101.83336,37.60542,0.88551,4.17838,101.83336
12.24000,101.99999,37.60905,0.88696,4.17878,101.99999
12.26000,102.16661,37.82021,0.88841,4.20225,102.16661
12.28000,102.33330,37.86586,0.88985,4.20732,102.33330
12.30000,102.49998,37.95795,0.89130,4.21755,102.49998
12.32000,102.66654,38.05777,0.89275,4.22864,102.66654
12.34000,102.83330,38.00952,0.89420,4.22328,102.83330
12.36000,102.99998,38.14379,0.89565,4.23820,102.99998
12.38000,103.16667,38.19076,0.89710,4.24342,103.16667
12.40000,103.33336,38.13663,0.89855,4.23740,103.33336
12.42000,103.49998,38.25439,0.90000,4.25049,103.49998
12.44000,103.66661,38.34417,0.90145,4.26046,103.66661
12.46000,103.83330,38.19110,0.90290,4.24346,103.83330
12.48000,104.00005,38.36014,0.90435,4.26224,104.00005
12.50000,104.16673,38.56156,0.90580,4.28462,104.16673
12.52000,104.33336,38.49391,0.90725,4.27710,104.33336
12.54000,104.49998,38.58188,0.90870,4.28688,104.49998
12.56000,104.66667,38.59780,0.91014,4.28864,104.66667
12.58000,104.83336,38.64184,0.91159,4.29354,104.83336
12.60000,105.00005,38.81999,0.91304,4.31333,105.00005
12.62000,105.16661,38.82043,0.91449,4.31338,105.16661
12.64000,105.33329,38.63175,0.91594,4.29242,105.33329
12.66000,105.49999,38.87200,0.91739,4.31911,105.49999
12.68000,105.66667,38.91854,0.91884,4.32428,105.66667
12.70000,105.83336,38.93255,0.92029,4.32584,105.83336
12.72000,106.00004,39.02184,0.92174,4.33576,106.00004
12.74000,106.16661,39.19010,0.92319,4.35446,106.16661
12.76000,106.33330,39.00822,0.92464,4.33425,106.33330
12.78000,106.50005,39.03467,0.92609,4.33719,106.50005
12.80000,106.66673,39.27449,0.92754,4.36383,106.66673
12.82000,106.83330,39.32147,0.92899,4.36905,106.83330
12.84000,106.99992,39.32073,0.93043,4.36897,106.99992
12.86000,107.16654,39.54781,0.93188,4.39420,107.16654
12.88000,107.33330,39.61908,0.93333,4.40212,107.33330
12.90000,107.50005,39.77054,0.93478,4.41895,107.50005
12.92000,107.66667,39.65739,0.93623,4.40638,107.66667
12.94000,107.83330,39.51789,0.93768,4.39088,107.83330
12.96000,107.99998,39.66728,0.93913,4.40748,107.99998
12.98000,108.16661,39.78768,0.94058,4.42085,108.16661
13.00000,108.33336,39.83240,0.94203,4.42582,108.33336
13.02000,108.49998,39.98934,0.94348,4.44326,108.49998
13.04000,108.66667,39.98219,0.94493,4.44247,108.66667
13.06000,108.83336,39.86130,0.94638,4.42903,108.83336
13.08000,108.99998,39.92757,0.94783,4.43640,108.99998
13.10000,109.16667,40.08045,0.94928,4.45338,109.16667
13.12000,109.33336,39.92493,0.95072,4.43610,109.33336
13.14000,109.50005,40.12683,0.95217,4.45854,109.50005
13.16000,109.66667,40.30777,0.95362,4.47864,109.66667
13.18000,109.83329,40.43400,0.95507,4.49267,109.83329
13.20000,109.99999,40.46858,0.95652,4.49651,109.99999
13.22000,110.16667,40.48538,0.95797,4.49838,110.16667
13.24000,110.33342,40.49895,0.95942,4.49988,110.33342
13.26000,110.49998,40.46589,0.96087,4.49621,110.49998
13.28000,110.66660,40.56596,0.96232,4.50733,110.66660
13.30000,110.83330,40.56091,0.96377,4.50677,110.83330
13.32000,110.99998,40.82405,0.96522,4.53601,110.99998
13.34000,111.16668,40.84766,0.96667,4.53863,111.16668
13.36000,111.33336,40.84790,0.96812,4.53866,111.33336
13.38000,111.49999,40.81592,0.96957,4.53510,111.49999
13.40000,111.66661,40.84457,0.97101,4.53829,111.66661
13.42000,111.83330,40.96036,0.97246,4.55115,111.83330
13.44000,112.00004,41.07680,0.97391,4.56409,112.00004
13.46000,112.16667,41.24437,0.97536,4.58271,112.16667
13.48000,112.33330,41.10271,0.97681,4.56697,112.33330
13.50000,112.49992,41.04677,0.97826,4.56075,112.49992
13.52000,112.66661,41.07415,0.97971,4.56379,112.66661
13.54000,112.83336,41.14468,0.98116,4.57163,112.83336
13.56000,113.00005,41.28463,0.98261,4.58718,113.00005
13.58000,113.16667,41.26068,0.98406,4.58452,113.16667
13.60000,113.33330,41.34091,0.98551,4.59343,113.33330
13.62000,113.49992,41.43407,0.98696,4.60379,113.49992
13.64000,113.66667,41.48923,0.98841,4.60991,113.66667
13.66000,113.83343,41.52469,0.98986,4.61385,113.83343
13.68000,114.00005,41.53013,0.99130,4.61446,114.00005
13.70000,114.16667,41.62667,0.99275,4.62519,114.16667
13.72000,114.33336,41.84283,0.99420,4.64920,114.33336
13.74000,114.50005,41.98091,0.99565,4.66455,114.50005
13.76000,114.66674,41.95441,0.99710,4.66160,114.66674
13.78000,114.83336,41.94829,0.99855,4.66092,114.83336
13.80000,114.99998,41.94829,1.00000,4.66092,114.99998
13.82000,115.16660,42.05321,1.00145,4.67258,115.16660
13.84000,115.33336,41.99115,1.00290,4.66568,115.33336
13.86000,115.50005,42.10351,1.00435,4.67817,115.50005
13.88000,115.66667,42.32579,1.00580,4.70287,115.66667
13.90000,115.83336,42.23356,1.00725,4.69262,115.83336
13.92000,115.99999,42.26329,1.00870,4.69592,115.99999
13.94000,116.16661,42.42405,1.01014,4.71378,116.16661
13.96000,116.33329,42.39829,1.01159,4.71092,116.33329
13.98000,116.50004,42.56635,1.01304,4.72959,116.50004
14.00000,116.66667,42.73553,1.01449,4.74839,116.66667
14.02000,116.83330,42.65353,1.01594,4.73928,116.83330
14.04000,116.99992,42.70325,1.01739,4.74481,116.99992
14.06000,117.16661,42.76428,1.01884,4.75159,117.16661
14.08000,117.33335,42.73352,1.02029,4.74817,117.33335
14.10000,117.49999,42.76370,1.02174,4.75152,117.49999
14.12000,117.66661,42.81322,1.02319,4.75702,117.66661
14.14000,117.83330,42.77643,1.02464,4.75294,117.83330
14.16000,117.99992,43.02061,1.02609,4.78007,117.99992
14.18000,118.16661,43.26885,1.02754,4.80765,118.16661
14.20000,118.33336,43.23432,1.02899,4.80381,118.33336
14.22000,118.50005,43.11529,1.03044,4.79059,118.50005
14.24000,118.66667,43.28604,1.03188,4.80956,118.66667
14.26000,118.83336,43.16883,1.03333,4.79654,118.83336
14.28000,119.00004,43.19288,1.03478,4.79921,119.00004
14.30000,119.16674,43.29496,1.03623,4.81055,119.16674
14.32000,119.33336,43.42025,1.03768,4.82447,119.33336
14.34000,119.49998,43.53718,1.03913,4.83746,119.49998
14.36000,119.66661,43.72179,1.04058,4.85798,119.66661
14.38000,119.83336,43.64616,1.04203,4.84957,119.83336
14.40000,120.00005,43.58660,1.04348,4.84296,120.00005
14.42000,120.16674,43.72933,1.04493,4.85881,120.16674
14.44000,120.33342,43.71626,1.04638,4.85736,120.33342
14.46000,120.49999,43.93393,1.04783,4.88155,120.49999
14.48000,120.66661,43.96097,1.04927,4.88455,120.66661
14.50000,120.83329,43.78292,1.05072,4.86477,120.83329
14.52000,120.99999,43.92355,1.05217,4.88039,120.99999
14.54000,121.16661,43.99717,1.05362,4.88857,121.16661
14.56000,121.33330,43.78659,1.05507,4.86518,121.33330
14.58000,121.49998,43.89347,1.05652,4.87705,121.49998
14.60000,121.66668,44.09073,1.05797,4.89897,121.66668
14.62000,121.83336,43.93237,1.05942,4.88137,121.83336
14.64000,121.99998,44.04664,1.06087,4.89407,121.99998
14.66000,122.16661,44.07353,1.06232,4.89706,122.16661
14.68000,122.33330,44.13584,1.06377,4.90398,122.33330
14.70000,122.49999,44.40769,1.06522,4.93419,122.49999
14.72000,122.66661,44.56801,1.06667,4.95200,122.66661
14.74000,122.83330,44.49708,1.06812,4.94412,122.83330
14.76000,122.99999,44.52740,1.06957,4.94749,122.99999
14.78000,123.16661,44.62762,1.07101,4.95862,123.16661
14.80000,123.33330,44.60969,1.07246,4.95663,123.33330
14.82000,123.49999,44.73553,1.07391,4.97061,123.49999
14.84000,123.66667,44.88958,1.07536,4.98773,123.66667
14.86000,123.83336,44.87067,1.07681,4.98563,123.83336
14.88000,123.99998,44.88159,1.07826,4.98684,123.99998
14.90000,124.16661,44.84985,1.07971,4.98332,124.16661
14.92000,124.33330,44.96697,1.08116,4.99633,124.33330
14.94000,124.50005,45.09476,1.08261,5.01053,124.50005
14.96000,124.66667,45.18822,1.08406,5.02091,124.66667
14.98000,124.83336,45.10299,1.08551,5.01144,124.83336
15.00000,124.99998,45.32239,1.08696,5.03582,124.99998
15.02000,125.16667,45.42525,1.08841,5.04725,125.16667
15.04000,125.33336,45.34271,1.08986,5.03808,125.33336
15.06000,125.50004,45.35393,1.09130,5.03933,125.50004
15.08000,125.66666,45.49588,1.09275,5.05510,125.66666
15.10000,125.83329,45.49593,1.09420,5.05510,125.83329
15.12000,125.99997,45.45253,1.09565,5.05028,125.99997
15.14000,126.16660,45.40291,1.09710,5.04477,126.16660
15.16000,126.33336,45.53712,1.09855,5.05968,126.33336
15.18000,126.50005,45.75661,1.10000,5.08407,126.50005
15.20000,126.66660,45.82391,1.10145,5.09155,126.66660
15.22000,126.83329,45.80628,1.10290,5.08959,126.83329
15.24000,127.00004,46.02009,1.10435,5.11334,127.00004
15.26000,127.16666,45.82068,1.10580,5.09119,127.16666
15.28000,127.33336,45.69955,1.10725,5.07773,127.33336
15.30000,127.49991,45.93025,1.10869,5.10336,127.49991
15.32000,127.66654,46.11825,1.11014,5.12425,127.66654
15.34000,127.83329,46.08656,1.11159,5.12073,127.83329
15.36000,128.00003,46.11521,1.11304,5.12391,128.00003
15.38000,128.16672,45.97772,1.11449,5.10864,128.16672
15.40000,128.33335,46.12667,1.11594,5.12519,128.33335
15.42000,128.50004,46.47038,1.11739,5.16338,128.50004
15.44000,128.66667,46.43938,1.11884,5.15993,128.66667
15.46000,128.83342,46.26857,1.12029,5.14095,128.83342
15.48000,129.00010,46.41606,1.12174,5.15734,129.00010
15.50000,129.16672,46.69776,1.12319,5.18864,129.16672
15.52000,129.33329,46.59700,1.12464,5.17744,129.33329
15.54000,129.49998,46.79273,1.12609,5.19919,129.49998
15.56000,129.66667,46.85793,1.12754,5.20644,129.66667
15.58000,129.83342,47.00061,1.12899,5.22229,129.83342
15.60000,130.00011,46.94242,1.13044,5.21583,130.00011
15.62000,130.16666,46.73116,1.13188,5.19235,130.16666
15.64000,130.33330,46.66675,1.13333,5.18519,130.33330
15.66000,130.49997,46.92621,1.13478,5.21402,130.49997
15.68000,130.66660,47.03990,1.13623,5.22666,130.66660
15.70000,130.83328,46.91357,1.13768,5.21262,130.83328
15.72000,130.99998,47.00958,1.13913,5.22329,130.99998
15.74000,131.16661,47.20952,1.14058,5.24550,131.16661
15.76000,131.33329,47.28437,1.14203,5.25382,131.33329
15.78000,131.49998,47.29196,1.14348,5.25466,131.49998
15.80000,131.66666,47.30215,1.14493,5.25579,131.66666
15.82000,131.83336,47.28873,1.14638,5.25430,131.83336
15.84000,131.99999,47.35814,1.14783,5.26202,131.99999
15.86000,132.16661,47.43367,1.14927,5.27041,132.16661
15.88000,132.33324,47.48539,1.15072,5.27615,132.33324
15.90000,132.49998,47.54971,1.15217,5.28330,132.49998
15.92000,132.66660,47.72306,1.15362,5.30256,132.66660
15.94000,132.83329,47.58987,1.15507,5.28776,132.83329
15.96000,132.99991,47.53506,1.15652,5.28167,132.99991
15.98000,133.16660,47.60471,1.15797,5.28941,133.16660
16.00000,133.33336,47.77718,1.15942,5.30858,133.33336
16.02000,133.50004,47.85256,1.16087,5.31695,133.50004
16.04000,133.66672,47.95915,1.16232,5.32879,133.66672
16.06000,133.83329,47.94823,1.16377,5.32758,133.83329
16.08000,133.99998,47.89665,1.16522,5.32185,133.99998
16.10000,134.16666,47.98511,1.16667,5.33168,134.16666
16.12000,134.33336,48.02709,1.16812,5.33634,134.33336
16.14000,134.50004,48.08307,1.16957,5.34256,134.50004
16.16000,134.66661,48.09184,1.17101,5.34354,134.66661
16.18000,134.83330,47.91027,1.17246,5.32336,134.83330
16.20000,134.99998,35.80028,1.17391,3.97781,134.99998
16.22000,135.16666,11.21448,1.17536,1.24605,135.16666
16.24000,135.33342,-0.32205,1.17681,-0.03578,135.33342
16.26000,135.50005,-2.14769,1.17826,-0.23863,135.50005
16.28000,135.66667,-0.96626,1.17971,-0.10736,135.66667
16.30000,135.83335,-0.35562,1.18116,-0.03951,135.83335
16.32000,135.99998,-0.00898,1.18261,-0.00100,135.99998
16.34000,136.16666,0.00484,1.18406,0.00054,136.16666
16.36000,136.33335,-0.03330,1.18551,-0.00370,136.33335
16.38000,136.50005,-0.08992,1.18696,-0.00999,136.50005
16.40000,136.66660,-0.00910,1.18841,-0.00101,136.66660
16.42000,136.83336,-0.14630,1.18986,-0.01626,136.83336
16.44000,137.00004,0.06636,1.19130,0.00737,137.00004
16.46000,137.16660,0.03633,1.19275,0.00404,137.16660
16.48000,137.33329,0.05272,1.19420,0.00586,137.33329
16.50000,137.49992,-0.01936,1.19565,-0.00215,137.49992
16.52000,137.66654,0.03048,1.19710,0.00339,137.66654
16.54000,137.83328,-0.08874,1.19855,-0.00986,137.83328
16.56000,138.00004,-0.05436,1.20000,-0.00604,138.00004
16.58000,138.16667,-0.01965,1.20145,-0.00218,138.16667
16.60000,138.33336,-0.13386,1.20290,-0.01487,138.33336
16.61800,138.48335,0.03979,1.20420,0.00442,138.48335