File: V_7/FR/RDSO FR Tensile 500.is_tens_RawData/Specimen_RawData_2.csv
Time,Extension,Load,Tensile strain,Tensile stress,Corrected Position
(sec),(mm),(N),(mm/mm),(MPa),(mm)
0.00000,0.00000,0.16551,0.00000,0.01839,0.00000
0.03000,0.05144,0.49443,0.00045,0.05494,0.05144
0.06000,0.23412,1.37834,0.00204,0.15315,0.23412
0.09000,0.51825,2.18449,0.00451,0.24272,0.51825
0.12000,0.83500,3.25022,0.00726,0.36114,0.83500
0.15000,1.16600,4.17275,0.01014,0.46364,1.16600
0.18000,1.47344,4.68530,0.01281,0.52059,1.47344
0.21000,1.73625,5.21206,0.01510,0.57912,1.73625
0.24000,1.98475,5.86561,0.01726,0.65173,1.98475
0.27000,2.23675,6.74016,0.01945,0.74891,2.23675
0.30000,2.49150,7.25443,0.02167,0.80605,2.49150
0.33000,2.74506,7.74080,0.02387,0.86009,2.74506
0.36000,2.99687,8.04377,0.02606,0.89375,2.99687
0.39000,3.24775,8.59982,0.02824,0.95554,3.24775
0.42000,3.49831,8.96768,0.03042,0.99641,3.49831
0.45000,3.74887,9.29130,0.03260,1.03237,3.74887
0.48000,3.99937,9.46468,0.03478,1.05163,3.99937
0.51000,4.24956,9.91762,0.03695,1.10196,4.24956
0.54000,4.49962,10.27404,0.03913,1.14156,4.49962
0.57000,4.74975,10.67829,0.04130,1.18648,4.74975
0.60000,4.99987,10.87204,0.04348,1.20800,4.99987
0.63000,5.24987,11.01597,0.04565,1.22400,5.24987
0.66000,5.49994,11.25233,0.04783,1.25026,5.49994
0.69000,5.75000,11.67231,0.05000,1.29692,5.75000
0.72000,6.00000,11.99172,0.05217,1.33241,6.00000
0.75000,6.24994,12.02728,0.05435,1.33636,6.24994
0.78000,6.50000,12.36159,0.05652,1.37351,6.50000
0.81000,6.75000,12.53349,0.05870,1.39261,6.75000
0.84000,6.99994,12.74999,0.06087,1.41667,6.99994
0.87000,7.24994,13.00867,0.06304,1.44541,7.24994
0.90000,7.50000,13.11535,0.06522,1.45726,7.50000
0.93000,7.75000,13.23619,0.06739,1.47069,7.75000
0.96000,7.99994,13.52448,0.06956,1.50272,7.99994
0.99000,8.25000,13.78112,0.07174,1.53124,8.25000
1.02000,8.50006,13.80076,0.07391,1.53342,8.50006
1.05000,8.75000,13.95300,0.07609,1.55033,8.75000
1.08000,9.00000,13.99691,0.07826,1.55521,9.00000
1.11000,9.25006,14.35967,0.08044,1.59552,9.25006
1.14000,9.50006,14.54323,0.08261,1.61591,9.50006
1.17000,9.75000,14.60667,0.08478,1.62296,9.75000
1.20000,10.00000,14.70940,0.08696,1.63438,10.00000
1.23000,10.25006,14.90276,0.08913,1.65586,10.25006
1.26000,10.50000,14.91320,0.09130,1.65702,10.50000
1.29000,10.74994,15.09997,0.09348,1.67777,10.74994
1.32000,11.00000,15.25024,0.09565,1.69447,11.00000
1.35000,11.25006,15.35208,0.09783,1.70579,11.25006
1.38000,11.49994,15.37214,0.10000,1.70802,11.49994
1.41000,11.74994,15.36903,0.10217,1.70767,11.74994
1.44000,12.00000,15.75199,0.10435,1.75022,12.00000
1.47000,12.25000,15.79571,0.10652,1.75508,12.25000
1.50000,12.49994,15.79365,0.10870,1.75485,12.49994
1.53000,12.75000,15.80129,0.11087,1.75570,12.75000
1.56000,13.00006,15.81545,0.11304,1.75727,13.00006
1.59000,13.25000,16.04804,0.11522,1.78312,13.25000
1.62000,13.50000,16.18416,0.11739,1.79824,13.50000
1.65000,13.75006,16.24382,0.11957,1.80487,13.75006
1.68000,14.00006,16.27155,0.12174,1.80795,14.00006
1.71000,14.25000,16.46772,0.12391,1.82975,14.25000
1.74000,14.50006,16.47581,0.12609,1.83064,14.50006
1.77000,14.75006,16.59177,0.12826,1.84353,14.75006
1.80000,15.00000,16.67315,0.13043,1.85257,15.00000
1.83000,15.25000,16.66914,0.13261,1.85213,15.25000
1.86000,15.50006,16.75824,0.13478,1.86203,15.50006
1.89000,15.75006,16.66157,0.13696,1.85129,15.75006
1.92000,16.00000,16.68998,0.13913,1.85444,16.00000
1.95000,16.24993,16.80996,0.14130,1.86777,16.24993
1.98000,16.50006,17.00303,0.14348,1.88923,16.50006
2.01000,16.75006,17.11926,0.14565,1.90214,16.75006
2.04000,17.00006,17.06176,0.14783,1.89575,17.00006
2.07000,17.25000,17.08972,0.15000,1.89886,17.25000
2.10000,17.50000,17.16479,0.15217,1.90720,17.50000
2.13000,17.75000,17.25146,0.15435,1.91683,17.75000
2.16000,17.99993,17.26839,0.15652,1.91871,17.99993
2.19000,18.25006,17.34228,0.15870,1.92692,18.25006
2.22000,18.50006,17.38509,0.16087,1.93168,18.50006
2.25000,18.75000,17.38019,0.16304,1.93113,18.75000
2.28000,19.00006,17.55153,0.16522,1.95017,19.00006
2.31000,19.25006,17.44676,0.16739,1.93853,19.25006
2.34000,19.50000,17.36807,0.16957,1.92979,19.50000
2.37000,19.75000,17.41097,0.17174,1.93455,19.75000
2.40000,20.00006,17.68383,0.17391,1.96487,20.00006
2.43000,20.25000,17.65975,0.17609,1.96219,20.25000
2.46000,20.50000,17.61912,0.17826,1.95768,20.50000
2.49000,20.75000,17.61457,0.18043,1.95717,20.75000
2.52000,21.00006,17.75125,0.18261,1.97236,21.00006
2.55000,21.25000,17.81060,0.18478,1.97896,21.25000
2.58000,21.49994,17.82916,0.18696,1.98102,21.49994
2.61000,21.75000,17.92041,0.18913,1.99116,21.75000
2.64000,22.00000,18.04503,0.19130,2.00500,22.00000
2.67000,22.24993,18.09178,0.19348,2.01020,22.24993
2.70000,22.49993,17.96651,0.19565,1.99628,22.49993
2.73000,22.75000,18.08113,0.19783,2.00901,22.75000
2.76000,23.00000,18.22756,0.20000,2.02528,23.00000
2.79000,23.25000,18.09915,0.20217,2.01102,23.25000
2.82000,23.50006,18.04853,0.20435,2.00539,23.50006
2.85000,23.75006,18.15690,0.20652,2.01743,23.75006
2.88000,24.00006,18.07917,0.20870,2.00880,24.00006
2.91000,24.25000,18.21036,0.21087,2.02337,24.25000
2.94000,24.50006,18.28810,0.21304,2.03201,24.50006
2.97000,24.75000,18.27100,0.21522,2.03011,24.75000
3.00000,24.99993,18.23324,0.21739,2.02592,24.99993
3.03000,25.25006,18.22170,0.21957,2.02463,25.25006
3.06000,25.50012,18.50592,0.22174,2.05621,25.50012
3.09000,25.74993,18.52407,0.22391,2.05823,25.74993
3.12000,25.99987,18.38751,0.22609,2.04306,25.99987
3.15000,26.25000,18.26816,0.22826,2.02980,26.25000
3.18000,26.50006,18.53308,0.23044,2.05923,26.50006
3.21000,26.75000,18.28163,0.23261,2.03129,26.75000
3.24000,27.00000,18.33032,0.23478,2.03670,27.00000
3.27000,27.25006,18.72419,0.23696,2.08047,27.25006
3.30000,27.49993,18.59661,0.23913,2.06629,27.49993
3.33000,27.74993,18.39735,0.24130,2.04415,27.74993
3.36000,28.00006,18.47391,0.24348,2.05266,28.00006
3.39000,28.25006,18.69845,0.24565,2.07761,28.25006
3.42000,28.50000,18.66913,0.24783,2.07435,28.50000
3.45000,28.75000,18.60798,0.25000,2.06755,28.75000
3.48000,29.00006,18.70511,0.25217,2.07835,29.00006
3.51000,29.25006,18.68956,0.25435,2.07662,29.25006
3.54000,29.50000,18.62483,0.25652,2.06943,29.50000
3.57000,29.75006,18.69612,0.25870,2.07735,29.75006
3.60000,30.00006,18.75610,0.26087,2.08401,30.00006
3.63000,30.25006,18.83947,0.26304,2.09327,30.25006
3.66000,30.49999,18.91162,0.26522,2.10129,30.49999
3.69000,30.75000,18.90084,0.26739,2.10009,30.75000
3.72000,31.00000,18.83403,0.26957,2.09267,31.00000
3.75000,31.25000,18.95558,0.27174,2.10618,31.25000
3.78000,31.49999,19.06055,0.27391,2.11784,31.49999
3.81000,31.75006,18.92012,0.27609,2.10224,31.75006
3.84000,31.99999,19.06648,0.27826,2.11850,31.99999
3.87000,32.24993,18.85945,0.28043,2.09549,32.24993
3.90000,32.50000,18.92465,0.28261,2.10274,32.50000
3.93000,32.75000,18.88079,0.28478,2.09787,32.75000
3.96000,32.99993,19.03888,0.28696,2.11543,32.99993
3.99000,33.24999,19.15229,0.28913,2.12803,33.24999
4.02000,33.50006,19.26194,0.29130,2.14022,33.50006
4.05000,33.75006,19.33150,0.29348,2.14794,33.75006
4.08000,34.00000,19.27294,0.29565,2.14144,34.00000
4.11000,34.25006,19.31109,0.29783,2.14568,34.25006
4.14000,34.50006,19.10498,0.30000,2.12278,34.50006
4.17000,34.75000,19.15624,0.30217,2.12847,34.75000
4.20000,34.99999,19.13363,0.30435,2.12596,34.99999
4.23000,35.25006,19.33255,0.30652,2.14806,35.25006
4.26000,35.49999,19.27600,0.30870,2.14178,35.49999
4.29000,35.75000,19.38525,0.31087,2.15392,35.75000
4.32000,35.99999,19.37019,0.31304,2.15224,35.99999
4.35000,36.25000,19.55762,0.31522,2.17307,36.25000
4.38000,36.50000,19.48344,0.31739,2.16483,36.50000
4.41000,36.74999,19.42549,0.31957,2.15839,36.74999
4.44000,36.99999,19.52338,0.32174,2.16926,36.99999
4.47000,37.24993,19.60523,0.32391,2.17836,37.24993
4.50000,37.49993,19.67961,0.32609,2.18662,37.49993
4.53000,37.74999,19.66947,0.32826,2.18550,37.74999
4.56000,38.00006,19.55934,0.33044,2.17326,38.00006
4.59000,38.25000,19.60871,0.33261,2.17875,38.25000
4.62000,38.50000,19.83535,0.33478,2.20393,38.50000
4.65000,38.75006,19.74618,0.33696,2.19402,38.75006
4.68000,39.00006,19.73366,0.33913,2.19263,39.00006
4.71000,39.24999,19.77662,0.34130,2.19740,39.24999
4.74000,39.49999,19.87246,0.34348,2.20805,39.49999
4.77000,39.75006,19.78657,0.34565,2.19851,39.75006
4.80000,39.99999,19.68258,0.34783,2.18695,39.99999
4.83000,40.25000,19.73913,0.35000,2.19324,40.25000
4.86000,40.50006,19.98636,0.35217,2.22071,40.50006
4.89000,40.75006,19.77021,0.35435,2.19669,40.75006
4.92000,40.99993,19.88316,0.35652,2.20924,40.99993
4.95000,41.25000,20.01686,0.35870,2.22410,41.25000
4.98000,41.50006,19.97887,0.36087,2.21987,41.50006
5.01000,41.74999,20.11222,0.36304,2.23469,41.74999
5.04000,41.99993,20.23872,0.36522,2.24875,41.99993
5.07000,42.25005,20.17010,0.36739,2.24112,42.25005
5.10000,42.50005,20.14987,0.36957,2.23887,42.50005
5.13000,42.74993,19.87135,0.37174,2.20793,42.74993
5.16000,42.99993,20.08937,0.37391,2.23215,42.99993
5.19000,43.25006,20.25168,0.37609,2.25019,43.25006
5.22000,43.50006,20.24359,0.37826,2.24929,43.50006
5.25000,43.75006,20.24497,0.38044,2.24944,43.75006
5.28000,44.00006,20.52742,0.38261,2.28082,44.00006
5.31000,44.25006,20.48816,0.38478,2.27646,44.25006
5.34000,44.49999,20.33419,0.38696,2.25935,44.49999
5.37000,44.74999,20.41386,0.38913,2.26821,44.74999
5.40000,45.00006,20.42081,0.39130,2.26898,45.00006
5.43000,45.25006,20.44866,0.39348,2.27207,45.25006
5.46000,45.49999,20.49470,0.39565,2.27719,45.49999
5.49000,45.75000,20.54998,0.39783,2.28333,45.75000
5.52000,45.99999,20.54209,0.40000,2.28245,45.99999
5.55000,46.24999,20.67679,0.40217,2.29742,46.24999
5.58000,46.49993,20.69504,0.40435,2.29945,46.49993
5.61000,46.75006,20.69063,0.40652,2.29896,46.75006
5.64000,47.00006,20.66568,0.40870,2.29619,47.00006
5.67000,47.24999,20.88654,0.41087,2.32073,47.24999
5.70000,47.49993,20.64251,0.41304,2.29361,47.49993
5.73000,47.74999,20.66266,0.41522,2.29585,47.74999
5.76000,47.99999,20.89788,0.41739,2.32199,47.99999
5.79000,48.24993,20.73731,0.41956,2.30415,48.24993
5.82000,48.49999,20.78757,0.42174,2.30973,48.49999
5.85000,48.75012,20.99430,0.42391,2.33270,48.75012
5.88000,49.00006,20.95492,0.42609,2.32832,49.00006
5.91000,49.25000,21.04392,0.42826,2.33821,49.25000
5.94000,49.50006,21.22197,0.43044,2.35800,49.50006
5.97000,49.74999,21.16640,0.43261,2.35182,49.74999
6.00000,49.99993,21.11886,0.43478,2.34654,49.99993
6.03000,50.25005,21.06610,0.43696,2.34068,50.25005
6.06000,50.50005,21.28383,0.43913,2.36487,50.50005
6.09000,50.74999,21.15851,0.44130,2.35095,50.74999
6.12000,50.99999,21.01778,0.44348,2.33531,50.99999
6.15000,51.24993,21.24019,0.44565,2.36002,51.24993
6.18000,51.49999,21.42838,0.44783,2.38093,51.49999
6.21000,51.74999,21.50817,0.45000,2.38980,51.74999
6.24000,51.99999,21.54914,0.45217,2.39435,51.99999
6.27000,52.25006,21.44817,0.45435,2.38313,52.25006
6.30000,52.49999,21.52125,0.45652,2.39125,52.49999
6.33000,52.74993,21.50200,0.45870,2.38911,52.74993
6.36000,52.99999,21.42951,0.46087,2.38106,52.99999
6.39000,53.25005,21.57371,0.46304,2.39708,53.25005
6.42000,53.50005,21.60420,0.46522,2.40047,53.50005
6.45000,53.75005,21.57021,0.46739,2.39669,53.75005
6.48000,54.00006,21.72768,0.46957,2.41419,54.00006
6.51000,54.25006,21.69043,0.47174,2.41005,54.25006
6.54000,54.49993,21.65967,0.47391,2.40663,54.49993
6.57000,54.75005,21.82560,0.47609,2.42507,54.75005
6.60000,55.00006,21.76452,0.47826,2.41828,55.00006
6.63000,55.24999,21.81629,0.48043,2.42403,55.24999
6.66000,55.49999,22.02768,0.48261,2.44752,55.49999
6.69000,55.75005,22.23149,0.48478,2.47017,55.75005
6.72000,55.99999,21.98149,0.48696,2.44239,55.99999
6.75000,56.24993,21.87309,0.48913,2.43034,56.24993
6.78000,56.49999,22.03057,0.49130,2.44784,56.49999
6.81000,56.75005,22.14548,0.49348,2.46061,56.75005
6.84000,56.99999,22.14629,0.49565,2.46070,56.99999
6.87000,57.24999,22.03571,0.49783,2.44841,57.24999
6.90000,57.49999,22.13838,0.50000,2.45982,57.49999
6.93000,57.74999,22.23597,0.50217,2.47066,57.74999
6.96000,57.99999,22.18229,0.50435,2.46470,57.99999
6.99000,58.24999,22.20578,0.50652,2.46731,58.24999
7.02000,58.50011,22.22566,0.50870,2.46952,58.50011
7.05000,58.75005,22.44390,0.51087,2.49377,58.75005
7.08000,59.00005,22.50229,0.51304,2.50025,59.00005
7.11000,59.25005,22.43256,0.51522,2.49251,59.25005
7.14000,59.50006,22.52681,0.51739,2.50298,59.50006
7.17000,59.74993,22.58306,0.51956,2.50923,59.74993
7.20000,59.99999,22.73376,0.52174,2.52597,59.99999
7.23000,60.25005,22.52899,0.52391,2.50322,60.25005
7.26000,60.50006,22.53810,0.52609,2.50423,60.50006
7.29000,60.74993,22.49830,0.52826,2.49981,60.74993
7.32000,60.99993,22.67718,0.53043,2.51969,60.99993
7.35000,61.24999,22.76109,0.53261,2.52901,61.24999
7.38000,61.49993,22.87938,0.53478,2.54215,61.49993
7.41000,61.74999,22.65032,0.53696,2.51670,61.74999
7.44000,62.00006,22.90316,0.53913,2.54480,62.00006
7.47000,62.25005,23.05743,0.54130,2.56194,62.25005
7.50000,62.49987,23.08089,0.54348,2.56454,62.49987
7.53000,62.74999,23.12569,0.54565,2.56952,62.74999
7.56000,63.00006,23.36173,0.54783,2.59575,63.00006
7.59000,63.24999,23.20107,0.55000,2.57790,63.24999
7.62000,63.50006,23.00213,0.55217,2.55579,63.50006
7.65000,63.75011,23.03620,0.55435,2.55958,63.75011
7.68000,64.00005,23.27778,0.55652,2.58642,64.00005
7.71000,64.24999,23.38858,0.55870,2.59873,64.24999
7.74000,64.49999,23.45127,0.56087,2.60570,64.49999
7.77000,64.75005,23.48049,0.56304,2.60894,64.75005
7.80000,64.99999,23.48909,0.56522,2.60990,64.99999
7.83000,65.24999,23.38627,0.56739,2.59847,65.24999
7.86000,65.49999,23.42161,0.56957,2.60240,65.49999
7.89000,65.74999,23.47439,0.57174,2.60827,65.74999
7.92000,65.99993,23.58362,0.57391,2.62040,65.99993
7.95000,66.24999,23.55923,0.57609,2.61769,66.24999
7.98000,66.50005,23.68524,0.57826,2.63169,66.50005
8.01000,66.74999,23.57992,0.58043,2.61999,66.74999
8.04000,66.99999,23.62146,0.58261,2.62461,66.99999
8.07000,67.24999,23.81964,0.58478,2.64663,67.24999
8.10000,67.49999,23.88432,0.58696,2.65381,67.49999
8.13000,67.74999,24.02238,0.58913,2.66915,67.74999
8.16000,67.99993,24.00183,0.59130,2.66687,67.99993
8.19000,68.24999,24.11731,0.59348,2.67970,68.24999
8.22000,68.50005,23.88846,0.59565,2.65427,68.50005
8.25000,68.74999,24.16926,0.59783,2.68547,68.74999
8.28000,69.00005,24.15865,0.60000,2.68429,69.00005
8.31000,69.25012,24.13793,0.60217,2.68199,69.25012
8.34000,69.49999,24.33964,0.60435,2.70440,69.49999
8.37000,69.74993,24.33917,0.60652,2.70435,69.74993
8.40000,69.99999,24.42859,0.60870,2.71429,69.99999
8.43000,70.25005,24.43368,0.61087,2.71485,70.25005
8.46000,70.49999,24.40596,0.61304,2.71177,70.49999
8.49000,70.74999,24.28948,0.61522,2.69883,70.74999
8.52000,70.99999,24.40797,0.61739,2.71200,70.99999
8.55000,71.24993,24.60703,0.61956,2.73411,71.24993
8.58000,71.49993,24.56349,0.62174,2.72928,71.49993
8.61000,71.75006,24.77955,0.62391,2.75328,71.75006
8.64000,72.00005,24.70625,0.62609,2.74514,72.00005
8.67000,72.24999,24.76929,0.62826,2.75214,72.24999
8.70000,72.49999,24.73013,0.63043,2.74779,72.49999
8.73000,72.74999,24.71695,0.63261,2.74633,72.74999
8.76000,72.99999,24.75930,0.63478,2.75103,72.99999
8.79000,73.24993,25.07768,0.63696,2.78641,73.24993
8.82000,73.49999,25.06950,0.63913,2.78550,73.49999
8.85000,73.75005,24.81021,0.64130,2.75669,73.75005
8.88000,74.00006,24.82983,0.64348,2.75887,74.00006
8.91000,74.24999,25.07917,0.64565,2.78657,74.24999
8.94000,74.50006,25.07680,0.64783,2.78631,74.50006
8.97000,74.75005,25.34184,0.65000,2.81576,74.75005
9.00000,74.99999,25.23780,0.65217,2.80420,74.99999
9.03000,75.24999,25.46476,0.65435,2.82942,75.24999
9.06000,75.50005,25.28049,0.65652,2.80894,75.50005
9.09000,75.74999,25.42107,0.65870,2.82456,75.74999
9.12000,75.99999,25.67005,0.66087,2.85223,75.99999
9.15000,76.25006,25.35825,0.66304,2.81758,76.25006
9.18000,76.50005,25.53540,0.66522,2.83727,76.50005
9.21000,76.74993,25.68212,0.66739,2.85357,76.74993
9.24000,76.99999,25.64130,0.66957,2.84903,76.99999
9.27000,77.25005,25.40721,0.67174,2.82302,77.25005
9.30000,77.49998,25.64134,0.67391,2.84904,77.49998
9.33000,77.74999,25.79674,0.67609,2.86630,77.74999
9.36000,77.99999,25.74472,0.67826,2.86052,77.99999
9.39000,78.24999,25.80808,0.68043,2.86756,78.24999
9.42000,78.49999,25.87945,0.68261,2.87549,78.49999
9.45000,78.74999,25.82116,0.68478,2.86902,78.74999
9.48000,79.00012,25.96475,0.68696,2.88497,79.00012
9.51000,79.25005,26.11449,0.68913,2.90161,79.25005
9.54000,79.49992,26.22195,0.69130,2.91355,79.49992
9.57000,79.74998,26.12519,0.69348,2.90280,79.74998
9.60000,80.00005,26.22940,0.69565,2.91438,80.00005
9.63000,80.24999,26.31941,0.69783,2.92438,80.24999
9.66000,80.49999,26.34184,0.70000,2.92687,80.49999
9.69000,80.75004,26.49900,0.70217,2.94433,80.75004
9.72000,80.99998,26.32511,0.70435,2.92501,80.99998
9.75000,81.24992,26.44539,0.70652,2.93838,81.24992
9.78000,81.49993,26.59140,0.70869,2.95460,81.49993
9.81000,81.74999,26.62699,0.71087,2.95855,81.74999
9.84000,81.99993,26.60649,0.71304,2.95628,81.99993
9.87000,82.24992,26.69086,0.71522,2.96565,82.24992
9.90000,82.49999,26.65033,0.71739,2.96115,82.49999
9.93000,82.74999,26.75909,0.71957,2.97323,82.74999
9.96000,82.99992,26.87714,0.72174,2.98635,82.99992
9.99000,83.24998,26.98035,0.72391,2.99782,83.24998
10.02000,83.50004,27.06332,0.72609,3.00704,83.50004
10.05000,83.75005,27.15233,0.72826,3.01693,83.75005
10.08000,84.00005,27.13253,0.73044,3.01473,84.00005
10.11000,84.25005,27.10170,0.73261,3.01130,84.25005
10.14000,84.50005,27.22741,0.73478,3.02527,84.50005
10.17000,84.74999,27.24458,0.73696,3.02718,84.74999
10.20000,84.99999,27.37125,0.73913,3.04125,84.99999
10.23000,85.25005,27.35386,0.74130,3.03932,85.25005
10.26000,85.50005,27.36165,0.74348,3.04018,85.50005
10.29000,85.74999,27.34644,0.74565,3.03849,85.74999
10.32000,86.00005,27.30559,0.74783,3.03395,86.00005
10.35000,86.24999,27.45859,0.75000,3.05095,86.24999
10.38000,86.49998,27.71163,0.75217,3.07907,86.49998
10.41000,86.74999,27.71337,0.75435,3.07926,86.74999
10.44000,87.00005,27.69399,0.75652,3.07711,87.00005
10.47000,87.24999,27.71991,0.75870,3.07999,87.24999
10.50000,87.49999,27.74508,0.76087,3.08279,87.49999
10.53000,87.74999,27.81180,0.76304,3.09020,87.74999
10.56000,87.99993,27.96310,0.76522,3.10701,87.99993
10.59000,88.24993,27.99073,0.76739,3.11008,88.24993
10.62000,88.49998,27.89054,0.76957,3.09895,88.49998
10.65000,88.75005,27.94312,0.77174,3.10479,88.75005
10.68000,89.00005,27.91299,0.77391,3.10144,89.00005
10.71000,89.24999,28.17811,0.77609,3.13090,89.24999
10.74000,89.49999,28.27250,0.77826,3.14139,89.49999
10.77000,89.75005,28.18000,0.78044,3.13111,89.75005
10.80000,89.99999,28.17605,0.78261,3.13067,89.99999
10.83000,90.24998,28.28193,0.78478,3.14244,90.24998
10.86000,90.50005,28.52745,0.78696,3.16972,90.50005
10.89000,90.75006,28.74283,0.78913,3.19365,90.75006
10.92000,90.99999,28.40791,0.79130,3.15643,90.99999
10.95000,91.24999,28.41430,0.79348,3.15714,91.24999
10.98000,91.50005,28.52640,0.79565,3.16960,91.50005
11.01000,91.74999,28.78897,0.79783,3.19877,91.74999
11.04000,91.99998,28.74919,0.80000,3.19436,91.99998
11.07000,92.25004,28.92046,0.80217,3.21338,92.25004
11.10000,92.49998,28.87667,0.80435,3.20852,92.49998
11.13000,92.74987,29.04265,0.80652,3.22696,92.74987
11.16000,92.99993,29.01181,0.80870,3.22353,92.99993
11.19000,93.25005,29.14362,0.81087,3.23818,93.25005
11.22000,93.50005,29.25888,0.81304,3.25099,93.50005
11.25000,93.74999,29.05960,0.81522,3.22884,93.74999
11.28000,94.00005,29.23576,0.81739,3.24842,94.00005
11.31000,94.25011,29.12726,0.81957,3.23636,94.25011
11.34000,94.49999,29.04537,0.82174,3.22726,94.49999
11.37000,94.74998,29.15631,0.82391,3.23959,94.74998
11.40000,95.00004,29.43561,0.82609,3.27062,95.00004
11.43000,95.25005,29.51741,0.82826,3.27971,95.25005
11.46000,95.49998,29.50049,0.83043,3.27783,95.49998
11.49000,95.74998,29.63783,0.83261,3.29309,95.74998
11.52000,96.00005,29.64087,0.83478,3.29343,96.00005
11.55000,96.24999,29.70528,0.83696,3.30059,96.24999
11.58000,96.49992,29.62216,0.83913,3.29135,96.49992
11.61000,96.75005,29.79925,0.84130,3.31103,96.75005
11.64000,97.00004,29.60039,0.84348,3.28893,97.00004
11.67000,97.24999,29.61753,0.84565,3.29084,97.24999
11.70000,97.49993,29.79570,0.84783,3.31063,97.49993
11.73000,97.75005,29.99482,0.85000,3.33276,97.75005
11.76000,97.99998,30.16013,0.85217,3.35113,97.99998
11.79000,98.24992,30.05340,0.85435,3.33927,98.24992
11.82000,98.49999,30.18903,0.85652,3.35434,98.49999
11.85000,98.75004,30.46242,0.85870,3.38471,98.75004
11.88000,98.99999,30.30162,0.86087,3.36685,98.99999
11.91000,99.24999,30.09263,0.86304,3.34363,99.24999
11.94000,99.50005,30.19909,0.86522,3.35545,99.50005
11.97000,99.75005,30.38471,0.86739,3.37608,99.75005
12.00000,99.99998,30.51523,0.86957,3.39058,99.99998
12.03000,100.25005,30.49120,0.87174,3.38791,100.25005
12.06000,100.50005,30.60384,0.87391,3.40043,100.50005
12.09000,100.74999,30.64146,0.87609,3.40461,100.74999
12.12000,100.99999,30.59911,0.87826,3.39990,100.99999
12.15000,101.25005,30.73675,0.88044,3.41519,101.25005
12.18000,101.50004,30.95675,0.88261,3.43964,101.50004
12.21000,101.74998,31.09550,0.88478,3.45505,101.74998
12.24000,101.99999,30.96087,0.88696,3.44010,101.99999
12.27000,102.24998,30.97500,0.88913,3.44167,102.24998
12.30000,102.49998,31.01093,0.89130,3.44566,102.49998
12.33000,102.74992,31.04801,0.89348,3.44978,102.74992
12.36000,102.99998,31.10069,0.89565,3.45563,102.99998
12.39000,103.25004,31.08702,0.89783,3.45411,103.25004
12.42000,103.49998,31.28356,0.90000,3.47595,103.49998
12.45000,103.74992,31.49979,0.90217,3.49998,103.74992
12.48000,104.00005,31.36213,0.90435,3.48468,104.00005
12.51000,104.25005,31.35936,0.90652,3.48437,104.25005
12.54000,104.49998,31.40198,0.90870,3.48911,104.49998
12.57000,104.75005,31.44050,0.91087,3.49339,104.75005
12.60000,105.00005,31.65203,0.91304,3.51689,105.00005
12.63000,105.24998,31.70513,0.91522,3.52279,105.24998
12.66000,105.49999,31.64199,0.91739,3.51578,105.49999
12.69000,105.75005,31.66712,0.91957,3.51857,105.75005
12.72000,106.00004,31.78448,0.92174,3.53161,106.00004
12.75000,106.24998,31.74613,0.92391,3.52735,106.24998
12.78000,106.49998,31.97081,0.92609,3.55231,106.49998
12.81000,106.75005,32.02812,0.92826,3.55868,106.75005
12.84000,106.99992,32.14813,0.93043,3.57201,106.99992
12.87000,107.24992,32.17120,0.93261,3.57458,107.24992
12.90000,107.50005,32.00578,0.93478,3.55620,107.50005
12.93000,107.74999,32.00133,0.93696,3.55570,107.74999
12.96000,107.99998,32.11687,0.93913,3.56854,107.99998
12.99000,108.24999,32.09135,0.94130,3.56571,108.24999
13.02000,108.49998,32.37139,0.94348,3.59682,108.49998
13.05000,108.74998,32.43124,0.94565,3.60347,108.74998
13.08000,108.99998,32.59519,0.94783,3.62169,108.99998
13.11000,109.25005,32.55198,0.95000,3.61689,109.25005
13.14000,109.50005,32.34038,0.95217,3.59338,109.50005
13.17000,109.74999,32.62531,0.95435,3.62503,109.74999
13.20000,109.99999,32.82432,0.95652,3.64715,109.99999
13.23000,110.25004,32.94546,0.95870,3.66061,110.25004
13.26000,110.50005,32.91137,0.96087,3.65682,110.50005
13.29000,110.74998,32.81409,0.96304,3.64601,110.74998
13.32000,111.00005,32.82246,0.96522,3.64694,111.00005
13.35000,111.25005,32.91524,0.96739,3.65725,111.25005
13.38000,111.49999,33.01100,0.96957,3.66789,111.49999
13.41000,111.74999,33.21560,0.97174,3.69062,111.74999
13.44000,112.00004,33.17690,0.97391,3.68632,112.00004
13.47000,112.24998,33.12728,0.97609,3.68081,112.24998
13.50000,112.49992,33.24758,0.97826,3.69418,112.49992
13.53000,112.74998,33.32478,0.98043,3.70275,112.74998
13.56000,113.00005,33.34373,0.98261,3.70486,113.00005
13.59000,113.24998,33.55230,0.98478,3.72803,113.24998
13.62000,113.49992,33.51880,0.98696,3.72431,113.49992
13.65000,113.75004,33.30876,0.98913,3.70097,113.75004
13.68000,114.00005,33.45223,0.99130,3.71691,114.00005
13.71000,114.24999,33.70802,0.99348,3.74534,114.24999
13.74000,114.50005,33.57625,0.99565,3.73069,114.50005
13.77000,114.75012,33.76645,0.99783,3.75183,114.75012
13.80000,114.99998,33.69391,1.00000,3.74377,114.99998
13.83000,115.24999,33.88518,1.00217,3.76502,115.24999
13.86000,115.50005,33.97173,1.00435,3.77464,115.50005
13.89000,115.75005,34.06397,1.00652,3.78489,115.75005
13.92000,115.99992,34.05177,1.00870,3.78353,115.99992
13.95000,116.24998,34.03933,1.01087,3.78215,116.24998
13.98000,116.50004,34.25818,1.01304,3.80646,116.50004
14.01000,116.74998,34.24922,1.01522,3.80547,116.74998
14.04000,116.99999,34.31677,1.01739,3.81297,116.99999
14.07000,117.24998,34.29350,1.01957,3.81039,117.24998
14.10000,117.49999,34.41292,1.02174,3.82366,117.49999
14.13000,117.74993,34.53381,1.02391,3.83709,117.74993
14.16000,117.99992,34.53528,1.02609,3.83725,117.99992
14.19000,118.25005,34.65768,1.02826,3.85085,118.25005
14.22000,118.50005,34.60567,1.03044,3.84507,118.50005
14.25000,118.75005,34.58975,1.03261,3.84331,118.75005
14.28000,119.00004,34.67899,1.03478,3.85322,119.00004
14.31000,119.25004,34.71607,1.03696,3.85734,119.25004
14.34000,119.49998,34.65930,1.03913,3.85103,119.49998
14.37000,119.74998,34.88070,1.04130,3.87563,119.74998
14.40000,120.00005,34.96461,1.04348,3.88496,120.00005
14.43000,120.25005,35.00022,1.04565,3.88891,120.25005
14.46000,120.49999,35.14716,1.04783,3.90524,120.49999
14.49000,120.74999,34.95491,1.05000,3.88388,120.74999
14.52000,121.00005,35.19394,1.05217,3.91044,121.00005
14.55000,121.24998,35.41274,1.05435,3.93475,121.24998
14.58000,121.49998,35.28951,1.05652,3.92106,121.49998
14.61000,121.75005,35.27231,1.05870,3.91915,121.75005
14.64000,121.99998,35.36744,1.06087,3.92972,121.99998
14.67000,122.24992,35.46085,1.06304,3.94009,122.24992
14.70000,122.49992,35.70179,1.06522,3.96687,122.49992
14.73000,122.74999,35.64262,1.06739,3.96029,122.74999
14.76000,122.99999,35.56802,1.06957,3.95200,122.99999
14.79000,123.24998,35.66094,1.07174,3.96233,123.24998
14.82000,123.50004,35.83473,1.07391,3.98164,123.50004
14.85000,123.75005,35.70830,1.07609,3.96759,123.75005
14.88000,123.99998,35.85927,1.07826,3.98436,123.99998
14.91000,124.24998,35.83933,1.08043,3.98215,124.24998
14.94000,124.50005,35.92118,1.08261,3.99124,124.50005
14.97000,124.75004,35.97070,1.08478,3.99674,124.75004
15.00000,124.99998,36.12916,1.08696,4.01435,124.99998
15.03000,125.25004,36.23006,1.08913,4.02556,125.25004
15.06000,125.50004,36.25206,1.09130,4.02801,125.50004
15.09000,125.74998,36.21032,1.09348,4.02337,125.74998
15.12000,125.99992,36.27361,1.09565,4.03040,125.99992
15.15000,126.24999,36.37794,1.09783,4.04199,126.24999
15.18000,126.50005,36.45132,1.10000,4.05015,126.50005
15.21000,126.74998,36.60546,1.10217,4.06727,126.74998
15.24000,126.99998,36.56065,1.10435,4.06229,126.99998
15.27000,127.25005,36.51842,1.10652,4.05760,127.25005
15.30000,127.49991,36.55070,1.10869,4.06119,127.49991
15.33000,127.74984,36.75892,1.11087,4.08432,127.74984
15.36000,128.00003,36.81961,1.11304,4.09107,128.00003
15.39000,128.25004,36.76030,1.11522,4.08448,128.25004
15.42000,128.50004,36.82980,1.11739,4.09220,128.50004
15.45000,128.75005,37.01334,1.11957,4.11259,128.75005
15.48000,129.00010,37.08916,1.12174,4.12102,129.00010
15.51000,129.25004,37.00722,1.12391,4.11191,129.25004
15.54000,129.49998,36.97317,1.12609,4.10813,129.49998
15.57000,129.75005,37.15255,1.12826,4.12806,129.75005
15.60000,130.00011,37.24184,1.13044,4.13798,130.00011
15.63000,130.24998,37.24968,1.13261,4.13885,130.24998
15.66000,130.49997,37.31693,1.13478,4.14633,130.49997
15.69000,130.74997,37.23170,1.13696,4.13686,130.74997
15.72000,130.99998,37.37448,1.13913,4.15272,130.99998
15.75000,131.24998,37.57438,1.14130,4.17493,131.24998
15.78000,131.49998,37.45104,1.14348,4.16123,131.49998
15.81000,131.75005,37.60539,1.14565,4.17838,131.75005
15.84000,131.99999,37.66735,1.14783,4.18526,131.99999
15.87000,132.24992,37.85275,1.15000,4.20586,132.24992
15.90000,132.49998,37.72848,1.15217,4.19205,132.49998
15.93000,132.74997,37.78172,1.15435,4.19797,132.74997
15.96000,132.99991,37.81723,1.15652,4.20191,132.99991
15.99000,133.24998,37.86147,1.15870,4.20683,133.24998
16.02000,133.50010,37.89732,1.16087,4.21081,133.50010
16.05000,133.75004,37.98338,1.16304,4.22038,133.75004
16.08000,133.99998,37.96306,1.16522,4.21812,133.99998
16.11000,134.25005,38.16379,1.16739,4.24042,134.25005
16.14000,134.50004,38.18441,1.16957,4.24271,134.50004
16.17000,134.74998,38.23403,1.17174,4.24823,134.74998
16.20000,134.99998,38.31049,1.17391,4.25672,134.99998
16.23000,135.25004,38.36153,1.17609,4.26239,135.25004
16.26000,135.50005,38.44176,1.17826,4.27131,135.50005
16.29000,135.74998,38.41668,1.18043,4.26852,135.74998
16.32000,135.99998,38.67854,1.18261,4.29762,135.99998
16.35000,136.24998,38.71645,1.18478,4.30183,136.24998
16.38000,136.49997,38.59409,1.18696,4.28823,136.49997
16.41000,136.74999,38.53566,1.18913,4.28174,136.74999
16.44000,137.00004,38.65165,1.19130,4.29463,137.00004
16.47000,137.24998,38.59728,1.19348,4.28859,137.24998
16.50000,137.49992,38.81785,1.19565,4.31309,137.49992
16.53000,137.74998,38.79076,1.19783,4.31008,137.74998
16.56000,138.00004,38.90979,1.20000,4.32331,138.00004
16.59000,138.24998,39.17458,1.20217,4.35273,138.24998
16.62000,138.50003,39.26050,1.20435,4.36228,138.50003
16.65000,138.75005,39.22788,1.20652,4.35865,138.75005
16.68000,139.00004,39.22616,1.20870,4.35846,139.00004
16.71000,139.25004,39.49238,1.21087,4.38804,139.25004
16.74000,139.50004,39.45202,1.21304,4.38356,139.50004
16.77000,139.75011,39.45300,1.21522,4.38367,139.75011
16.80000,140.00005,39.39329,1.21739,4.37703,140.00005
16.83000,140.24998,39.35577,1.21957,4.37286,140.24998
16.86000,140.50004,39.46289,1.22174,4.38477,140.50004
16.89000,140.75004,39.39226,1.22391,4.37692,140.75004
16.92000,140.99992,39.40245,1.22609,4.37805,140.99992
16.95000,141.24991,39.47509,1.22826,4.38612,141.24991
16.98000,141.50004,39.55381,1.23044,4.39487,141.50004
17.01000,141.75004,39.65378,1.23261,4.40598,141.75004
17.04000,141.99992,39.59138,1.23478,4.39904,141.99992
17.07000,142.24998,39.72059,1.23696,4.41340,142.24998
17.10000,142.50005,39.72221,1.23913,4.41358,142.50005
17.13000,142.74999,39.98764,1.24130,4.44307,142.74999
17.16000,142.99998,40.01340,1.24348,4.44593,142.99998
17.19000,143.25003,39.96222,1.24565,4.44025,143.25003
17.22000,143.50004,39.90888,1.24783,4.43432,143.50004
17.25000,143.74998,40.11058,1.25000,4.45673,143.74998
17.28000,144.00004,40.09320,1.25217,4.45480,144.00004
17.31000,144.25009,40.20786,1.25435,4.46754,144.25009
17.34000,144.49998,40.33620,1.25652,4.48180,144.49998
17.37000,144.74998,40.25239,1.25870,4.47249,144.74998
17.40000,145.00004,40.39728,1.26087,4.48859,145.00004
17.43000,145.25004,40.25097,1.26304,4.47233,145.25004
17.46000,145.49998,40.50632,1.26522,4.50070,145.49998
17.49000,145.74997,40.48711,1.26739,4.49857,145.74997
17.52000,146.00004,40.48094,1.26957,4.49788,146.00004
17.55000,146.24998,40.58189,1.27174,4.50910,146.24998
17.58000,146.49997,40.55706,1.27391,4.50634,146.49997
17.61000,146.75003,40.61515,1.27609,4.51279,146.75003
17.64000,147.00005,40.54692,1.27826,4.50521,147.00005
17.67000,147.24992,40.81671,1.28043,4.53519,147.24992
17.70000,147.49992,40.47306,1.28261,4.49701,147.49992
17.73000,147.74998,40.47041,1.28478,4.49671,147.74998
17.76000,148.00005,40.39130,1.28696,4.48792,148.00005
17.79000,148.24999,40.18460,1.28913,4.46496,148.24999
17.82000,148.50005,36.29986,1.29130,4.03332,148.50005
17.85000,148.75010,7.01549,1.29348,0.77950,148.75010
17.88000,148.99998,-1.38916,1.29565,-0.15435,148.99998
17.91000,149.24997,-0.20670,1.29783,-0.02297,149.24997
17.94000,149.50004,0.38439,1.30000,0.04271,149.50004
17.97000,149.74998,0.32162,1.30217,0.03574,149.74998
18.00000,149.99998,0.34146,1.30435,0.03794,149.99998
18.03000,150.25004,0.39118,1.30652,0.04346,150.25004
18.06000,150.50011,0.38074,1.30870,0.04230,150.50011
18.09000,150.74998,0.24773,1.31087,0.02753,150.74998
18.12000,150.99992,0.32534,1.31304,0.03615,150.99992
18.15000,151.24998,0.22410,1.31522,0.02490,151.24998
18.18000,151.49998,0.34099,1.31739,0.03789,151.49998
18.21000,151.74999,0.46781,1.31957,0.05198,151.74999
18.24000,151.99998,0.46942,1.32174,0.05216,151.99998
18.27000,152.24998,0.46903,1.32391,0.05211,152.24998
18.30000,152.49997,0.35084,1.32609,0.03898,152.49997
18.33000,152.74997,0.40097,1.32826,0.04455,152.74997
18.36000,152.99998,0.36304,1.33043,0.04034,152.99998
18.39000,153.25004,0.44430,1.33261,0.04937,153.25004
18.42000,153.50004,0.45368,1.33478,0.05041,153.50004
18.45000,153.75005,0.68362,1.33696,0.07596,153.75005
18.48000,154.00010,0.51995,1.33913,0.05777,154.00010
18.51000,154.25004,0.30151,1.34130,0.03350,154.25004
18.54000,154.49992,0.26688,1.34348,0.02965,154.49992
18.57000,154.74997,0.34342,1.34565,0.03816,154.74997
18.60000,155.00004,0.30933,1.34783,0.03437,155.00004
18.63000,155.24998,0.33899,1.35000,0.03767,155.24998
18.66000,155.49998,0.34601,1.35217,0.03845,155.49998
18.69000,155.74998,0.22508,1.35435,0.02501,155.74998
18.72000,155.99998,0.13784,1.35652,0.01532,155.99998
18.75000,156.24992,0.24009,1.35869,0.02668,156.24992
18.78000,156.49999,0.28648,1.36087,0.03183,156.49999
18.81000,156.75010,0.31711,1.36304,0.03523,156.75010
18.84000,157.00003,0.29931,1.36522,0.03326,157.00003
18.87000,157.24996,0.47280,1.36739,0.05253,157.24996
18.90000,157.50004,0.32360,1.36957,0.03596,157.50004
18.93000,157.74997,0.34168,1.37174,0.03796,157.74997
18.96000,157.99992,0.22015,1.37391,0.02446,157.99992
18.99000,158.24998,0.39519,1.37609,0.04391,158.24998
19.02000,158.50009,0.23495,1.37826,0.02611,158.50009
19.05000,158.75004,0.32116,1.38044,0.03568,158.75004
19.08000,158.99997,0.35535,1.38261,0.03948,158.99997
19.11000,159.25003,0.32730,1.38478,0.03637,159.25003
19.14000,159.50004,0.12197,1.38696,0.01355,159.50004
19.17000,159.74997,0.37450,1.38913,0.04161,159.74997
19.20000,160.00004,0.30727,1.39130,0.03414,160.00004
19.23000,160.25003,0.33090,1.39348,0.03677,160.25003
19.26000,160.50003,0.41804,1.39565,0.04645,160.50003
19.29000,160.74996,0.43719,1.39783,0.04858,160.74996
19.32000,160.99999,0.38860,1.40000,0.04318,160.99999
19.35000,161.25003,0.42328,1.40217,0.04703,161.25003
19.38000,161.49998,0.32174,1.40435,0.03575,161.49998
19.41000,161.74996,0.20210,1.40652,0.02246,161.74996
19.44000,162.00004,0.30607,1.40870,0.03401,162.00004
19.47000,162.25005,0.13806,1.41087,0.01534,162.25005
19.50000,162.49992,0.14663,1.41304,0.01629,162.49992
19.53000,162.74998,0.25432,1.41522,0.02826,162.74998
19.56000,163.00002,0.25079,1.41739,0.02787,163.00002
19.59000,163.24999,0.31800,1.41957,0.03533,163.24999
19.62000,163.49997,0.25121,1.42174,0.02791,163.49997
19.65000,163.75003,0.42409,1.42391,0.04712,163.75003
19.68000,164.00011,0.36142,1.42609,0.04016,164.00011
19.71000,164.24991,0.30296,1.42826,0.03366,164.24991
19.74000,164.49990,0.28278,1.43043,0.03142,164.49990
19.77000,164.75003,0.33646,1.43261,0.03738,164.75003
19.80000,164.99998,0.37979,1.43478,0.04220,164.99998
19.83000,165.24997,0.21937,1.43696,0.02437,165.24997
19.86000,165.50004,0.18401,1.43913,0.02045,165.50004
19.89000,165.74997,0.45196,1.44130,0.05022,165.74997
19.92000,165.99992,0.40709,1.44348,0.04523,165.99992
19.95000,166.24996,0.23549,1.44565,0.02617,166.24996
19.98000,166.50004,0.19681,1.44783,0.02187,166.50004
20.01000,166.74997,0.32806,1.45000,0.03645,166.74997
20.04000,166.99998,0.37484,1.45217,0.04165,166.99998
20.07000,167.24998,0.25023,1.45435,0.02780,167.24998
20.10000,167.50002,0.30526,1.45652,0.03392,167.50002
20.13000,167.74997,0.39967,1.45870,0.04441,167.74997
20.16000,167.99998,0.35625,1.46087,0.03958,167.99998
20.19000,168.25004,0.36012,1.46304,0.04001,168.25004
20.22000,168.50004,0.20247,1.46522,0.02250,168.50004
20.25000,168.74997,0.41736,1.46739,0.04637,168.74997
20.28000,168.99997,0.42394,1.46957,0.04710,168.99997
20.31000,169.25003,0.41261,1.47174,0.04585,169.25003
20.34000,169.49998,0.43090,1.47391,0.04788,169.49998
20.37000,169.74997,0.42857,1.47609,0.04762,169.74997
20.40000,170.00005,0.42458,1.47826,0.04718,170.00005
20.43000,170.25003,0.29708,1.48044,0.03301,170.25003
20.46000,170.49998,0.34239,1.48261,0.03804,170.49998
20.49000,170.74997,0.46605,1.48478,0.05178,170.74997
20.52000,171.00003,0.45958,1.48696,0.05106,171.00003
20.55000,171.24997,0.23953,1.48913,0.02661,171.24997
20.58000,171.49998,0.18268,1.49130,0.02030,171.49998
20.61000,171.75004,0.32275,1.49348,0.03586,171.75004
20.64000,172.00002,0.19875,1.49565,0.02208,172.00002
20.67000,172.24997,0.36904,1.49783,0.04100,172.24997
20.70000,172.49998,0.49877,1.50000,0.05542,172.49998
20.73000,172.74998,0.42598,1.50217,0.04733,172.74998
20.76000,172.99997,0.07120,1.50435,0.00791,172.99997
20.79000,173.24997,0.08310,1.50652,0.00923,173.24997
20.82000,173.50005,0.32960,1.50870,0.03662,173.50005
20.85000,173.75004,0.27472,1.51087,0.03052,173.75004
20.88000,174.00004,0.26541,1.51304,0.02949,174.00004
20.91000,174.25003,0.21979,1.51522,0.02442,174.25003
20.94000,174.50003,0.21601,1.51739,0.02400,174.50003
20.97000,174.75003,0.30247,1.51957,0.03361,174.75003
21.00000,174.99998,0.36468,1.52174,0.04052,174.99998
21.03000,175.24997,0.30842,1.52391,0.03427,175.24997
21.06000,175.50003,0.29265,1.52609,0.03252,175.50003
21.09000,175.74998,0.35312,1.52826,0.03924,175.74998
21.12000,175.99991,0.14849,1.53043,0.01650,175.99991
21.15000,176.24998,0.25907,1.53261,0.02879,176.24998
21.18000,176.50003,0.36830,1.53478,0.04092,176.50003
21.21000,176.74997,0.23514,1.53696,0.02613,176.74997
21.24000,176.99996,0.29556,1.53913,0.03284,176.99996
21.27000,177.25004,0.40352,1.54130,0.04484,177.25004
21.30000,177.49997,0.52970,1.54348,0.05886,177.49997
21.33000,177.74997,0.38770,1.54565,0.04308,177.74997
21.36000,178.00003,0.38491,1.54783,0.04277,178.00003
21.39000,178.25004,0.30080,1.55000,0.03342,178.25004
21.42000,178.49999,0.27141,1.55217,0.03016,178.49999
21.45000,178.75003,0.35980,1.55435,0.03998,178.75003
21.48000,179.00011,0.37783,1.55652,0.04198,179.00011
21.51000,179.25004,0.11807,1.55870,0.01312,179.25004
21.54000,179.49998,0.20561,1.56087,0.02285,179.49998
21.57000,179.74997,0.40714,1.56304,0.04524,179.74997
21.60000,179.99997,0.43048,1.56522,0.04783,179.99997
21.63000,180.24998,0.40288,1.56739,0.04476,180.24998
21.66000,180.49996,0.12601,1.56956,0.01400,180.49996
21.69000,180.75004,0.33127,1.57174,0.03681,180.75004
21.72000,181.00003,0.52722,1.57391,0.05858,181.00003
21.75000,181.24992,0.35167,1.57609,0.03907,181.24992
21.78000,181.49996,0.29003,1.57826,0.03223,181.49996
21.81000,181.75004,0.26105,1.58044,0.02901,181.75004
21.84000,181.99997,0.36093,1.58261,0.04010,181.99997
21.87000,182.24992,0.28684,1.58478,0.03187,182.24992
21.90000,182.49998,0.33242,1.58696,0.03694,182.49998
21.93000,182.74996,0.25932,1.58913,0.02881,182.74996
21.96000,182.99991,0.30940,1.59130,0.03438,182.99991
21.99000,183.24992,0.36806,1.59348,0.04090,183.24992
22.02000,183.50003,0.31986,1.59565,0.03554,183.50003
22.05000,183.75004,0.37827,1.59783,0.04203,183.75004
22.08000,183.99997,0.55162,1.60000,0.06129,183.99997
22.11000,184.25005,0.48828,1.60217,0.05425,184.25005
22.14000,184.50009,0.50085,1.60435,0.05565,184.50009
22.17000,184.74998,0.49294,1.60652,0.05477,184.74998
22.20000,184.99997,0.46783,1.60870,0.05198,184.99997
22.23000,185.25004,0.42928,1.61087,0.04770,185.25004
22.26000,185.50003,0.37366,1.61304,0.04152,185.50003
22.29000,185.74992,0.42953,1.61522,0.04773,185.74992
22.32000,185.99996,0.37104,1.61739,0.04123,185.99996
22.35000,186.24997,0.31400,1.61956,0.03489,186.24997
22.38000,186.49997,0.39980,1.62174,0.04442,186.49997
22.41000,186.74998,0.29806,1.62391,0.03312,186.74998
22.44000,186.99998,0.31596,1.62609,0.03511,186.99998
22.47000,187.24997,0.39811,1.62826,0.04423,187.24997
22.50000,187.49991,0.35860,1.63043,0.03984,187.49991
22.53000,187.75003,0.44655,1.63261,0.04962,187.75003
22.56000,188.00003,0.38527,1.63478,0.04281,188.00003
22.59000,188.24996,0.44474,1.63696,0.04942,188.24996
22.62000,188.49997,0.49666,1.63913,0.05518,188.49997
22.65000,188.75003,0.38466,1.64130,0.04274,188.75003
22.68000,189.00009,0.27896,1.64348,0.03100,189.00009
22.71000,189.25004,0.36338,1.64565,0.04038,189.25004
22.74000,189.49997,0.44033,1.64783,0.04893,189.49997
22.77000,189.74997,0.44234,1.65000,0.04915,189.74997
22.78400,189.86665,0.46007,1.65101,0.05112,189.86665