File: V_7/FR/RDSO FR Tensile 500.is_tens_RawData/Specimen_RawData_5.csv
Time,Extension,Load,Tensile strain,Tensile stress,Corrected Position
(sec),(mm),(N),(mm/mm),(MPa),(mm)
0.00000,0.00000,-0.02841,0.00000,-0.00316,0.00000
0.02000,0.01994,0.32263,0.00017,0.03585,0.01994
0.04000,0.09781,0.85604,0.00085,0.09512,0.09781
0.06000,0.23412,1.42284,0.00204,0.15809,0.23412
0.08000,0.41825,2.14413,0.00364,0.23824,0.41825
0.10000,0.62262,2.77715,0.00541,0.30857,0.62262
0.12000,0.83687,3.50846,0.00728,0.38983,0.83687
0.14000,1.05787,4.16766,0.00920,0.46307,1.05787
0.16000,1.27581,4.53351,0.01109,0.50372,1.27581
0.18000,1.47275,5.03426,0.01281,0.55936,1.47275
0.20000,1.64981,5.44429,0.01435,0.60492,1.64981
0.22000,1.81725,5.88917,0.01580,0.65435,1.81725
0.24000,1.98337,6.34953,0.01725,0.70550,1.98337
0.26000,2.15150,6.79771,0.01871,0.75530,2.15150
0.28000,2.32125,7.21073,0.02018,0.80119,2.32125
0.30000,2.49125,7.56767,0.02166,0.84085,2.49125
0.32000,2.66050,7.86171,0.02313,0.87352,2.66050
0.34000,2.82894,8.22770,0.02460,0.91419,2.82894
0.36000,2.99669,8.60984,0.02606,0.95665,2.99669
0.38000,3.16400,9.04955,0.02751,1.00551,3.16400
0.40000,3.33119,9.24739,0.02897,1.02749,3.33119
0.42000,3.49825,9.45346,0.03042,1.05038,3.49825
0.44000,3.66525,9.80028,0.03187,1.08892,3.66525
0.46000,3.83237,9.97309,0.03332,1.10812,3.83237
0.48000,3.99931,10.12459,0.03478,1.12495,3.99931
0.50000,4.16619,10.30769,0.03623,1.14530,4.16619
0.52000,4.33294,10.37083,0.03768,1.15231,4.33294
0.54000,4.49962,10.73623,0.03913,1.19291,4.49962
0.56000,4.66637,11.10742,0.04058,1.23416,4.66637
0.58000,4.83312,11.15415,0.04203,1.23935,4.83312
0.60000,4.99987,11.40465,0.04348,1.26718,4.99987
0.62000,5.16650,11.58860,0.04493,1.28762,5.16650
0.64000,5.33319,11.65639,0.04638,1.29515,5.33319
0.66000,5.49994,11.94869,0.04783,1.32763,5.49994
0.68000,5.66662,12.23237,0.04927,1.35915,5.66662
0.70000,5.83331,12.30834,0.05072,1.36759,5.83331
0.72000,6.00000,12.45972,0.05217,1.38441,6.00000
0.74000,6.16656,12.58865,0.05362,1.39874,6.16656
0.76000,6.33331,12.63922,0.05507,1.40436,6.33331
0.78000,6.50000,12.90544,0.05652,1.43394,6.50000
0.80000,6.66669,13.15997,0.05797,1.46222,6.66669
0.82000,6.83337,13.32889,0.05942,1.48099,6.83337
0.84000,7.00000,13.47623,0.06087,1.49736,7.00000
0.86000,7.16656,13.58487,0.06232,1.50943,7.16656
0.88000,7.33331,13.58259,0.06377,1.50918,7.33331
0.90000,7.50000,13.65408,0.06522,1.51712,7.50000
0.92000,7.66662,13.92148,0.06667,1.54683,7.66662
0.94000,7.83331,14.00918,0.06812,1.55658,7.83331
0.96000,7.99994,13.97394,0.06956,1.55266,7.99994
0.98000,8.16662,14.23063,0.07101,1.58118,8.16662
1.00000,8.33337,14.44431,0.07246,1.60492,8.33337
1.02000,8.50006,14.81073,0.07391,1.64564,8.50006
1.04000,8.66669,14.83272,0.07536,1.64808,8.66669
1.06000,8.83331,14.90565,0.07681,1.65618,8.83331
1.08000,9.00000,14.76081,0.07826,1.64009,9.00000
1.10000,9.16669,14.87827,0.07971,1.65314,9.16669
1.12000,9.33344,14.83358,0.08116,1.64818,9.33344
1.14000,9.50006,15.04146,0.08261,1.67127,9.50006
1.16000,9.66669,15.26974,0.08406,1.69664,9.66669
1.18000,9.83331,15.36418,0.08551,1.70713,9.83331
1.20000,10.00000,15.67497,0.08696,1.74166,10.00000
1.22000,10.16669,15.79992,0.08841,1.75555,10.16669
1.24000,10.33337,15.48965,0.08986,1.72107,10.33337
1.26000,10.50000,15.57240,0.09130,1.73027,10.50000
1.28000,10.66662,15.85505,0.09275,1.76167,10.66662
1.30000,10.83331,15.81905,0.09420,1.75767,10.83331
1.32000,11.00000,15.89705,0.09565,1.76634,11.00000
1.34000,11.16669,16.16156,0.09710,1.79573,11.16669
1.36000,11.33337,16.16315,0.09855,1.79591,11.33337
1.38000,11.49994,16.29048,0.10000,1.81005,11.49994
1.40000,11.66656,16.24779,0.10145,1.80531,11.66656
1.42000,11.83331,16.20799,0.10290,1.80089,11.83331
1.44000,12.00000,16.42513,0.10435,1.82501,12.00000
1.46000,12.16669,16.45097,0.10580,1.82789,12.16669
1.48000,12.33331,16.53257,0.10725,1.83695,12.33331
1.50000,12.49994,16.68148,0.10870,1.85350,12.49994
1.52000,12.66662,16.66671,0.11014,1.85186,12.66662
1.54000,12.83337,16.52587,0.11159,1.83621,12.83337
1.56000,13.00006,16.63456,0.11304,1.84828,13.00006
1.58000,13.16662,16.82801,0.11449,1.86978,13.16662
1.60000,13.33331,16.81961,0.11594,1.86885,13.33331
1.62000,13.50000,16.93991,0.11739,1.88221,13.50000
1.64000,13.66668,17.01532,0.11884,1.89059,13.66668
1.66000,13.83337,16.98904,0.12029,1.88767,13.83337
1.68000,14.00006,17.05656,0.12174,1.89517,14.00006
1.70000,14.16669,17.22927,0.12319,1.91436,14.16669
1.72000,14.33331,17.17674,0.12464,1.90853,14.33331
1.74000,14.50006,17.33180,0.12609,1.92576,14.50006
1.76000,14.66669,17.37794,0.12754,1.93088,14.66669
1.78000,14.83331,17.28622,0.12899,1.92069,14.83331
1.80000,15.00000,17.35413,0.13043,1.92824,15.00000
1.82000,15.16662,17.50855,0.13188,1.94539,15.16662
1.84000,15.33337,17.56209,0.13333,1.95134,15.33337
1.86000,15.50006,17.56593,0.13478,1.95177,15.50006
1.88000,15.66668,17.52072,0.13623,1.94675,15.66668
1.90000,15.83337,17.55449,0.13768,1.95050,15.83337
1.92000,16.00000,17.71586,0.13913,1.96843,16.00000
1.94000,16.16656,17.73913,0.14058,1.97101,16.16656
1.96000,16.33331,17.85385,0.14203,1.98376,16.33331
1.98000,16.50006,17.95744,0.14348,1.99527,16.50006
2.00000,16.66668,17.84324,0.14493,1.98258,16.66668
2.02000,16.83337,17.80785,0.14638,1.97865,16.83337
2.04000,17.00000,17.84244,0.14783,1.98249,17.00000
2.06000,17.16662,17.90197,0.14927,1.98911,17.16662
2.08000,17.33331,17.83837,0.15072,1.98204,17.33331
2.10000,17.50000,17.89504,0.15217,1.98834,17.50000
2.12000,17.66669,17.98850,0.15362,1.99872,17.66669
2.14000,17.83325,18.03496,0.15507,2.00388,17.83325
2.16000,17.99993,18.20831,0.15652,2.02315,17.99993
2.18000,18.16662,18.33757,0.15797,2.03751,18.16662
2.20000,18.33337,18.16552,0.15942,2.01839,18.33337
2.22000,18.50006,18.17902,0.16087,2.01989,18.50006
2.24000,18.66662,18.36667,0.16232,2.04074,18.66662
2.26000,18.83331,18.30448,0.16377,2.03383,18.83331
2.28000,19.00006,18.49772,0.16522,2.05530,19.00006
2.30000,19.16675,18.44085,0.16667,2.04898,19.16675
2.32000,19.33337,18.52219,0.16812,2.05802,19.33337
2.34000,19.50000,18.74025,0.16957,2.08225,19.50000
2.36000,19.66662,18.86455,0.17101,2.09606,19.66662
2.38000,19.83337,18.61398,0.17246,2.06822,19.83337
2.40000,20.00006,18.50617,0.17391,2.05624,20.00006
2.42000,20.16668,18.67736,0.17536,2.07526,20.16668
2.44000,20.33331,18.66543,0.17681,2.07394,20.33331
2.46000,20.50000,18.59804,0.17826,2.06645,20.50000
2.48000,20.66662,18.66122,0.17971,2.07347,20.66662
2.50000,20.83337,18.81089,0.18116,2.09010,20.83337
2.52000,21.00006,18.84113,0.18261,2.09346,21.00006
2.54000,21.16662,19.01901,0.18406,2.11322,21.16662
2.56000,21.33331,18.91453,0.18551,2.10161,21.33331
2.58000,21.49994,18.92879,0.18696,2.10320,21.49994
2.60000,21.66662,19.00275,0.18841,2.11142,21.66662
2.62000,21.83337,18.96697,0.18986,2.10744,21.83337
2.64000,22.00000,18.87040,0.19130,2.09671,22.00000
2.66000,22.16662,18.91679,0.19275,2.10187,22.16662
2.68000,22.33331,18.72950,0.19420,2.08106,22.33331
2.70000,22.49993,18.80001,0.19565,2.08889,22.49993
2.72000,22.66662,18.88754,0.19710,2.09862,22.66662
2.74000,22.83331,18.96971,0.19855,2.10775,22.83331
2.76000,23.00000,19.10079,0.20000,2.12231,23.00000
2.78000,23.16662,19.23745,0.20145,2.13749,23.16662
2.80000,23.33331,19.21044,0.20290,2.13449,23.33331
2.82000,23.50006,19.27064,0.20435,2.14118,23.50006
2.84000,23.66675,19.36835,0.20580,2.15204,23.66675
2.86000,23.83337,19.29373,0.20725,2.14375,23.83337
2.88000,24.00006,19.21151,0.20870,2.13461,24.00006
2.90000,24.16668,19.29601,0.21015,2.14400,24.16668
2.92000,24.33337,19.19589,0.21159,2.13288,24.33337
2.94000,24.50006,19.31416,0.21304,2.14602,24.50006
2.96000,24.66668,19.34159,0.21449,2.14907,24.66668
2.98000,24.83331,19.25837,0.21594,2.13982,24.83331
3.00000,24.99993,19.35028,0.21739,2.15003,24.99993
3.02000,25.16662,19.55473,0.21884,2.17275,25.16662
3.04000,25.33337,19.42013,0.22029,2.15779,25.33337
3.06000,25.50012,19.39659,0.22174,2.15518,25.50012
3.08000,25.66668,19.38626,0.22319,2.15403,25.66668
3.10000,25.83325,19.38949,0.22464,2.15439,25.83325
3.12000,25.99987,19.45586,0.22609,2.16176,25.99987
3.14000,26.16662,19.86930,0.22754,2.20770,26.16662
3.16000,26.33337,19.92411,0.22899,2.21379,26.33337
3.18000,26.50006,19.82311,0.23044,2.20257,26.50006
3.20000,26.66662,19.81233,0.23188,2.20137,26.66662
3.22000,26.83331,19.65681,0.23333,2.18409,26.83331
3.24000,27.00000,19.73420,0.23478,2.19269,27.00000
3.26000,27.16668,19.80329,0.23623,2.20037,27.16668
3.28000,27.33331,19.86628,0.23768,2.20737,27.33331
3.30000,27.49993,19.73910,0.23913,2.19323,27.49993
3.32000,27.66656,19.77216,0.24058,2.19691,27.66656
3.34000,27.83331,19.75365,0.24203,2.19485,27.83331
3.36000,28.00006,19.81811,0.24348,2.20201,28.00006
3.38000,28.16675,19.87040,0.24493,2.20782,28.16675
3.40000,28.33337,19.87782,0.24638,2.20865,28.33337
3.42000,28.50000,20.13762,0.24783,2.23751,28.50000
3.44000,28.66662,19.89070,0.24927,2.21008,28.66662
3.46000,28.83337,19.69019,0.25072,2.18780,28.83337
3.48000,29.00006,19.71358,0.25217,2.19040,29.00006
3.50000,29.16669,20.01357,0.25362,2.22373,29.16669
3.52000,29.33337,20.14206,0.25507,2.23801,29.33337
3.54000,29.50000,20.17549,0.25652,2.24172,29.50000
3.56000,29.66662,20.22087,0.25797,2.24676,29.66662
3.58000,29.83337,20.06917,0.25942,2.22991,29.83337
3.60000,30.00006,20.02354,0.26087,2.22484,30.00006
3.62000,30.16668,20.21883,0.26232,2.24654,30.16668
3.64000,30.33337,20.11676,0.26377,2.23519,30.33337
3.66000,30.49999,20.23157,0.26522,2.24795,30.49999
3.68000,30.66662,20.31805,0.26667,2.25756,30.66662
3.70000,30.83337,20.38841,0.26812,2.26538,30.83337
3.72000,31.00000,20.37450,0.26957,2.26383,31.00000
3.74000,31.16662,20.43450,0.27101,2.27050,31.16662
3.76000,31.33331,20.26892,0.27246,2.25210,31.33331
3.78000,31.49999,20.23622,0.27391,2.24847,31.49999
3.80000,31.66668,20.39831,0.27536,2.26648,31.66668
3.82000,31.83337,20.25846,0.27681,2.25094,31.83337
3.84000,31.99999,20.32586,0.27826,2.25843,31.99999
3.86000,32.16656,20.53893,0.27971,2.28210,32.16656
3.88000,32.33331,20.53952,0.28116,2.28217,32.33331
3.90000,32.50000,20.54692,0.28261,2.28299,32.50000
3.92000,32.66668,20.56705,0.28406,2.28523,32.66668
3.94000,32.83331,20.53800,0.28551,2.28200,32.83331
3.96000,32.99993,20.72247,0.28696,2.30250,32.99993
3.98000,33.16662,20.72480,0.28841,2.30276,33.16662
4.00000,33.33337,20.50543,0.28986,2.27838,33.33337
4.02000,33.50006,20.62737,0.29130,2.29193,33.50006
4.04000,33.66675,20.70787,0.29275,2.30087,33.66675
4.06000,33.83337,20.56994,0.29420,2.28555,33.83337
4.08000,34.00006,20.52431,0.29565,2.28048,34.00006
4.10000,34.16668,20.84277,0.29710,2.31586,34.16668
4.12000,34.33337,20.69284,0.29855,2.29920,34.33337
4.14000,34.50006,20.75164,0.30000,2.30574,34.50006
4.16000,34.66668,20.88825,0.30145,2.32092,34.66668
4.18000,34.83331,20.78820,0.30290,2.30980,34.83331
4.20000,34.99999,20.84955,0.30435,2.31662,34.99999
4.22000,35.16675,20.91495,0.30580,2.32388,35.16675
4.24000,35.33337,20.78926,0.30725,2.30992,35.33337
4.26000,35.49999,20.76773,0.30870,2.30753,35.49999
4.28000,35.66662,20.85159,0.31014,2.31684,35.66662
4.30000,35.83331,20.76237,0.31159,2.30693,35.83331
4.32000,35.99999,20.85012,0.31304,2.31668,35.99999
4.34000,36.16662,20.97826,0.31449,2.33092,36.16662
4.36000,36.33331,21.04744,0.31594,2.33860,36.33331
4.38000,36.50000,21.01906,0.31739,2.33545,36.50000
4.40000,36.66662,21.07913,0.31884,2.34213,36.66662
4.42000,36.83337,21.20372,0.32029,2.35597,36.83337
4.44000,36.99999,21.22300,0.32174,2.35811,36.99999
4.46000,37.16662,21.33061,0.32319,2.37007,37.16662
4.48000,37.33324,21.12701,0.32464,2.34745,37.33324
4.50000,37.49993,21.30499,0.32609,2.36722,37.49993
4.52000,37.66656,21.38914,0.32754,2.37657,37.66656
4.54000,37.83337,21.32263,0.32899,2.36918,37.83337
4.56000,38.00006,21.35214,0.33044,2.37246,38.00006
4.58000,38.16668,21.46303,0.33188,2.38478,38.16668
4.60000,38.33331,21.33517,0.33333,2.37057,38.33331
4.62000,38.50000,21.20847,0.33478,2.35650,38.50000
4.64000,38.66668,21.45850,0.33623,2.38428,38.66668
4.66000,38.83337,21.49776,0.33768,2.38864,38.83337
4.68000,39.00006,21.66560,0.33913,2.40729,39.00006
4.70000,39.16662,21.59891,0.34058,2.39988,39.16662
4.72000,39.33331,21.58987,0.34203,2.39887,39.33331
4.74000,39.49999,21.64892,0.34348,2.40544,39.49999
4.76000,39.66668,21.73675,0.34493,2.41519,39.66668
4.78000,39.83337,21.54748,0.34638,2.39416,39.83337
4.80000,39.99999,21.46161,0.34783,2.38462,39.99999
4.82000,40.16662,21.55515,0.34927,2.39502,40.16662
4.84000,40.33331,21.69303,0.35072,2.41034,40.33331
4.86000,40.50006,21.84855,0.35217,2.42762,40.50006
4.88000,40.66668,21.92609,0.35362,2.43623,40.66668
4.90000,40.83337,21.66109,0.35507,2.40679,40.83337
4.92000,40.99999,21.66829,0.35652,2.40759,40.99999
4.94000,41.16662,21.69239,0.35797,2.41027,41.16662
4.96000,41.33337,21.75465,0.35942,2.41718,41.33337
4.98000,41.50006,21.76978,0.36087,2.41886,41.50006
5.00000,41.66668,21.82646,0.36232,2.42516,41.66668
5.02000,41.83331,21.83860,0.36377,2.42651,41.83331
5.04000,41.99993,21.95234,0.36522,2.43915,41.99993
5.06000,42.16662,21.91264,0.36667,2.43474,42.16662
5.08000,42.33337,21.69545,0.36812,2.41061,42.33337
5.10000,42.50005,21.86738,0.36957,2.42971,42.50005
5.12000,42.66662,22.04729,0.37101,2.44970,42.66662
5.14000,42.83324,22.03206,0.37246,2.44801,42.83324
5.16000,42.99993,22.10482,0.37391,2.45609,42.99993
5.18000,43.16668,22.15733,0.37536,2.46193,43.16668
5.20000,43.33337,22.08063,0.37681,2.45340,43.33337
5.22000,43.50006,22.05844,0.37826,2.45094,43.50006
5.24000,43.66668,22.25841,0.37971,2.47316,43.66668
5.26000,43.83337,22.22865,0.38116,2.46985,43.83337
5.28000,44.00006,22.24981,0.38261,2.47220,44.00006
5.30000,44.16674,22.37408,0.38406,2.48601,44.16674
5.32000,44.33337,22.40937,0.38551,2.48993,44.33337
5.34000,44.49999,22.44229,0.38696,2.49359,44.49999
5.36000,44.66662,22.41721,0.38841,2.49080,44.66662
5.38000,44.83331,22.43986,0.38985,2.49332,44.83331
5.40000,45.00006,22.51698,0.39130,2.50189,45.00006
5.42000,45.16668,22.60165,0.39275,2.51129,45.16668
5.44000,45.33337,22.57513,0.39420,2.50835,45.33337
5.46000,45.49999,22.45561,0.39565,2.49507,45.49999
5.48000,45.66662,22.63371,0.39710,2.51486,45.66662
5.50000,45.83331,22.54946,0.39855,2.50550,45.83331
5.52000,45.99999,22.76153,0.40000,2.52906,45.99999
5.54000,46.16662,22.81311,0.40145,2.53479,46.16662
5.56000,46.33330,22.69410,0.40290,2.52157,46.33330
5.58000,46.49993,22.61069,0.40435,2.51230,46.49993
5.60000,46.66662,22.63398,0.40580,2.51489,46.66662
5.62000,46.83343,22.65891,0.40725,2.51766,46.83343
5.64000,47.00006,22.86278,0.40870,2.54031,47.00006
5.66000,47.16668,22.82619,0.41015,2.53624,47.16668
5.68000,47.33324,22.77164,0.41159,2.53018,47.33324
5.70000,47.49993,22.95467,0.41304,2.55052,47.49993
5.72000,47.66662,23.11560,0.41449,2.56840,47.66662
5.74000,47.83337,22.88896,0.41594,2.54322,47.83337
5.76000,47.99999,23.00909,0.41739,2.55657,47.99999
5.78000,48.16662,23.19830,0.41884,2.57759,48.16662
5.80000,48.33330,23.10578,0.42029,2.56731,48.33330
5.82000,48.50006,23.06737,0.42174,2.56304,48.50006
5.84000,48.66675,23.10646,0.42319,2.56738,48.66675
5.86000,48.83343,22.93483,0.42464,2.54831,48.83343
5.88000,49.00006,23.02104,0.42609,2.55789,49.00006
5.90000,49.16662,23.24956,0.42754,2.58328,49.16662
5.92000,49.33337,23.25363,0.42899,2.58374,49.33337
5.94000,49.50006,23.50334,0.43044,2.61148,49.50006
5.96000,49.66668,23.58326,0.43188,2.62036,49.66668
5.98000,49.83330,23.48588,0.43333,2.60954,49.83330
6.00000,49.99993,23.57064,0.43478,2.61896,49.99993
6.02000,50.16662,23.52085,0.43623,2.61343,50.16662
6.04000,50.33337,23.35872,0.43768,2.59541,50.33337
6.06000,50.50005,23.44023,0.43913,2.60447,50.50005
6.08000,50.66668,23.52220,0.44058,2.61358,50.66668
6.10000,50.83330,23.56308,0.44203,2.61812,50.83330
6.12000,50.99999,23.68622,0.44348,2.63180,50.99999
6.14000,51.16662,23.60454,0.44493,2.62273,51.16662
6.16000,51.33331,23.50172,0.44638,2.61130,51.33331
6.18000,51.49999,23.58879,0.44783,2.62098,51.49999
6.20000,51.66662,23.67223,0.44927,2.63025,51.66662
6.22000,51.83330,23.69805,0.45072,2.63312,51.83330
6.24000,51.99999,23.86319,0.45217,2.65147,51.99999
6.26000,52.16668,23.98337,0.45362,2.66482,52.16668
6.28000,52.33337,23.82542,0.45507,2.64727,52.33337
6.30000,52.49999,23.82227,0.45652,2.64692,52.49999
6.32000,52.66655,23.82672,0.45797,2.64741,52.66655
6.34000,52.83324,23.75768,0.45942,2.63974,52.83324
6.36000,52.99993,23.95900,0.46087,2.66211,52.99993
6.38000,53.16668,24.11969,0.46232,2.67997,53.16668
6.40000,53.33337,24.02081,0.46377,2.66898,53.33337
6.42000,53.50005,24.15823,0.46522,2.68425,53.50005
6.44000,53.66668,24.20349,0.46667,2.68928,53.66668
6.46000,53.83343,24.22708,0.46812,2.69190,53.83343
6.48000,54.00012,24.43241,0.46957,2.71471,54.00012
6.50000,54.16675,24.48436,0.47102,2.72048,54.16675
6.52000,54.33330,24.33697,0.47246,2.70411,54.33330
6.54000,54.49993,24.29820,0.47391,2.69980,54.49993
6.56000,54.66662,24.42222,0.47536,2.71358,54.66662
6.58000,54.83337,24.26487,0.47681,2.69610,54.83337
6.60000,55.00006,24.35367,0.47826,2.70596,55.00006
6.62000,55.16668,24.35806,0.47971,2.70645,55.16668
6.64000,55.33330,24.43065,0.48116,2.71452,55.33330
6.66000,55.49999,24.50535,0.48261,2.72282,55.49999
6.68000,55.66668,24.61497,0.48406,2.73500,55.66668
6.70000,55.83337,24.53635,0.48551,2.72626,55.83337
6.72000,55.99999,24.61497,0.48696,2.73500,55.99999
6.74000,56.16656,24.65097,0.48840,2.73900,56.16656
6.76000,56.33330,24.60860,0.48985,2.73429,56.33330
6.78000,56.49999,24.69280,0.49130,2.74364,56.49999
6.80000,56.66668,24.82829,0.49275,2.75870,56.66668
6.82000,56.83336,24.82202,0.49420,2.75800,56.83336
6.84000,56.99999,24.93984,0.49565,2.77109,56.99999
6.86000,57.16662,25.00999,0.49710,2.77889,57.16662
6.88000,57.33330,24.76118,0.49855,2.75124,57.33330
6.90000,57.49999,24.94080,0.50000,2.77120,57.49999
6.92000,57.66662,24.93225,0.50145,2.77025,57.66662
6.94000,57.83331,24.92615,0.50290,2.76957,57.83331
6.96000,57.99999,25.04817,0.50435,2.78313,57.99999
6.98000,58.16662,25.18130,0.50580,2.79792,58.16662
7.00000,58.33337,25.15306,0.50725,2.79478,58.33337
7.02000,58.50011,25.13202,0.50870,2.79245,58.50011
7.04000,58.66668,25.24219,0.51015,2.80469,58.66668
7.06000,58.83330,25.33057,0.51159,2.81451,58.83330
7.08000,58.99999,25.51120,0.51304,2.83458,58.99999
7.10000,59.16668,25.57835,0.51449,2.84204,59.16668
7.12000,59.33343,25.38311,0.51594,2.82035,59.33343
7.14000,59.50006,25.43101,0.51739,2.82567,59.50006
7.16000,59.66661,25.43944,0.51884,2.82660,59.66661
7.18000,59.83324,25.37199,0.52029,2.81911,59.83324
7.20000,59.99999,25.51862,0.52174,2.83540,59.99999
7.22000,60.16668,25.61764,0.52319,2.84640,60.16668
7.24000,60.33343,25.62295,0.52464,2.84699,60.33343
7.26000,60.50006,25.75491,0.52609,2.86166,60.50006
7.28000,60.66662,25.81619,0.52754,2.86847,60.66662
7.30000,60.83325,25.68697,0.52898,2.85411,60.83325
7.32000,60.99999,25.77369,0.53043,2.86374,60.99999
7.34000,61.16662,25.83852,0.53188,2.87095,61.16662
7.36000,61.33331,25.82050,0.53333,2.86894,61.33331
7.38000,61.49993,25.93663,0.53478,2.88185,61.49993
7.40000,61.66662,25.94427,0.53623,2.88270,61.66662
7.42000,61.83337,25.88554,0.53768,2.87617,61.83337
7.44000,62.00006,26.01865,0.53913,2.89096,62.00006
7.46000,62.16674,25.89463,0.54058,2.87718,62.16674
7.48000,62.33331,25.80120,0.54203,2.86680,62.33331
7.50000,62.49987,25.83142,0.54348,2.87016,62.49987
7.52000,62.66655,25.98848,0.54493,2.88761,62.66655
7.54000,62.83336,25.91878,0.54638,2.87986,62.83336
7.56000,63.00006,26.19991,0.54783,2.91110,63.00006
7.58000,63.16661,26.36297,0.54927,2.92922,63.16661
7.60000,63.33336,26.41122,0.55072,2.93458,63.33336
7.62000,63.50006,26.49618,0.55217,2.94402,63.50006
7.64000,63.66674,26.46376,0.55362,2.94042,63.66674
7.66000,63.83349,26.48607,0.55507,2.94290,63.83349
7.68000,64.00005,26.63975,0.55652,2.95997,64.00005
7.70000,64.16661,26.67788,0.55797,2.96421,64.16661
7.72000,64.33330,26.44877,0.55942,2.93875,64.33330
7.74000,64.49999,26.62890,0.56087,2.95877,64.49999
7.76000,64.66668,26.56223,0.56232,2.95136,64.66668
7.78000,64.83336,26.39719,0.56377,2.93302,64.83336
7.80000,64.99999,26.61487,0.56522,2.95721,64.99999
7.82000,65.16661,26.73722,0.56667,2.97080,65.16661
7.84000,65.33330,26.80117,0.56812,2.97791,65.33330
7.86000,65.49999,26.83257,0.56957,2.98140,65.49999
7.88000,65.66667,26.77950,0.57101,2.97550,65.66667
7.90000,65.83330,26.95326,0.57246,2.99481,65.83330
7.92000,65.99993,26.99164,0.57391,2.99907,65.99993
7.94000,66.16655,27.12102,0.57536,3.01345,66.16655
7.96000,66.33330,27.16494,0.57681,3.01833,66.33330
7.98000,66.50005,27.00976,0.57826,3.00108,66.50005
8.00000,66.66668,27.11049,0.57971,3.01228,66.66668
8.02000,66.83336,27.28321,0.58116,3.03147,66.83336
8.04000,66.99999,27.35489,0.58261,3.03943,66.99999
8.06000,67.16661,27.34505,0.58406,3.03834,67.16661
8.08000,67.33330,27.31142,0.58551,3.03460,67.33330
8.10000,67.49999,27.50647,0.58696,3.05627,67.49999
8.12000,67.66662,27.53456,0.58841,3.05940,67.66662
8.14000,67.83330,27.43647,0.58985,3.04850,67.83330
8.16000,67.99993,27.32783,0.59130,3.03643,67.99993
8.18000,68.16661,27.46909,0.59275,3.05212,68.16661
8.20000,68.33337,27.37551,0.59420,3.04172,68.33337
8.22000,68.50005,27.54203,0.59565,3.06023,68.50005
8.24000,68.66661,27.76034,0.59710,3.08448,68.66661
8.26000,68.83330,27.62549,0.59855,3.06950,68.83330
8.28000,69.00005,27.78674,0.60000,3.08742,69.00005
8.30000,69.16674,27.85909,0.60145,3.09545,69.16674
8.32000,69.33343,27.82279,0.60290,3.09142,69.33343
8.34000,69.49999,27.84464,0.60435,3.09385,69.49999
8.36000,69.66662,27.92894,0.60580,3.10322,69.66662
8.38000,69.83330,27.81454,0.60725,3.09050,69.83330
8.40000,69.99999,28.01015,0.60870,3.11224,69.99999
8.42000,70.16674,28.00795,0.61015,3.11199,70.16674
8.44000,70.33330,27.96208,0.61159,3.10690,70.33330
8.46000,70.49999,27.93849,0.61304,3.10428,70.49999
8.48000,70.66668,28.14397,0.61449,3.12711,70.66668
8.50000,70.83336,28.15766,0.61594,3.12863,70.83336
8.52000,70.99999,28.20804,0.61739,3.13423,70.99999
8.54000,71.16661,28.30870,0.61884,3.14541,71.16661
8.56000,71.33324,28.18668,0.62029,3.13185,71.33324
8.58000,71.49993,28.31110,0.62174,3.14568,71.49993
8.60000,71.66667,28.53409,0.62319,3.17045,71.66667
8.62000,71.83337,28.57347,0.62464,3.17483,71.83337
8.64000,72.00005,28.79007,0.62609,3.19890,72.00005
8.66000,72.16662,28.57891,0.62754,3.17543,72.16662
8.68000,72.33330,28.49958,0.62899,3.16662,72.33330
8.70000,72.49999,28.68694,0.63043,3.18744,72.49999
8.72000,72.66662,28.73416,0.63188,3.19268,72.66662
8.74000,72.83330,28.58207,0.63333,3.17579,72.83330
8.76000,72.99999,28.70736,0.63478,3.18971,72.99999
8.78000,73.16662,28.88549,0.63623,3.20950,73.16662
8.80000,73.33330,28.90912,0.63768,3.21212,73.33330
8.82000,73.50005,28.91316,0.63913,3.21257,73.50005
8.84000,73.66668,29.00148,0.64058,3.22239,73.66668
8.86000,73.83343,28.76316,0.64203,3.19591,73.83343
8.88000,74.00006,28.84959,0.64348,3.20551,74.00006
8.90000,74.16668,28.92480,0.64493,3.21387,74.16668
8.92000,74.33336,28.99428,0.64638,3.22159,74.33336
8.94000,74.50006,29.17157,0.64783,3.24129,74.50006
8.96000,74.66668,29.43906,0.64928,3.27101,74.66668
8.98000,74.83337,29.28499,0.65072,3.25389,74.83337
9.00000,74.99999,29.31159,0.65217,3.25684,74.99999
9.02000,75.16661,29.24583,0.65362,3.24954,75.16661
9.04000,75.33337,29.21970,0.65507,3.24663,75.33337
9.06000,75.50005,29.42020,0.65652,3.26891,75.50005
9.08000,75.66662,29.60406,0.65797,3.28934,75.66662
9.10000,75.83330,29.48589,0.65942,3.27621,75.83330
9.12000,75.99999,29.55934,0.66087,3.28437,75.99999
9.14000,76.16668,29.64587,0.66232,3.29399,76.16668
9.16000,76.33343,29.55858,0.66377,3.28429,76.33343
9.18000,76.50005,29.63788,0.66522,3.29310,76.50005
9.20000,76.66655,29.80547,0.66667,3.31172,76.66655
9.22000,76.83324,29.83557,0.66812,3.31506,76.83324
9.24000,76.99999,29.98301,0.66957,3.33145,76.99999
9.26000,77.16668,30.05893,0.67101,3.33988,77.16668
9.28000,77.33336,30.00944,0.67246,3.33438,77.33336
9.30000,77.49998,30.01666,0.67391,3.33518,77.49998
9.32000,77.66661,30.03571,0.67536,3.33730,77.66661
9.34000,77.83331,30.12903,0.67681,3.34767,77.83331
9.36000,77.99999,30.26787,0.67826,3.36310,77.99999
9.38000,78.16668,30.33923,0.67971,3.37103,78.16668
9.40000,78.33330,30.26025,0.68116,3.36225,78.33330
9.42000,78.49999,30.30612,0.68261,3.36735,78.49999
9.44000,78.66661,30.35697,0.68406,3.37300,78.66661
9.46000,78.83336,30.39147,0.68551,3.37683,78.83336
9.48000,79.00012,30.50521,0.68696,3.38947,79.00012
9.50000,79.16674,30.63056,0.68841,3.40340,79.16674
9.52000,79.33330,30.48109,0.68985,3.38679,79.33330
9.54000,79.49992,30.63310,0.69130,3.40368,79.49992
9.56000,79.66661,30.61304,0.69275,3.40145,79.66661
9.58000,79.83336,30.49448,0.69420,3.38828,79.83336
9.60000,79.99999,30.65848,0.69565,3.40650,79.99999
9.62000,80.16667,30.74530,0.69710,3.41614,80.16667
9.64000,80.33330,30.85663,0.69855,3.42851,80.33330
9.66000,80.49999,31.00983,0.70000,3.44554,80.49999
9.68000,80.66667,30.88813,0.70145,3.43201,80.66667
9.70000,80.83336,30.82044,0.70290,3.42449,80.83336
9.72000,80.99998,31.01335,0.70435,3.44593,80.99998
9.74000,81.16661,31.17392,0.70580,3.46377,81.16661
9.76000,81.33323,31.11181,0.70725,3.45687,81.33323
9.78000,81.49993,31.00378,0.70869,3.44486,81.49993
9.80000,81.66668,31.16946,0.71015,3.46327,81.66668
9.82000,81.83336,31.18802,0.71159,3.46534,81.83336
9.84000,81.99998,31.23299,0.71304,3.47033,81.99998
9.86000,82.16655,31.38669,0.71449,3.48741,82.16655
9.88000,82.33330,31.38973,0.71594,3.48775,82.33330
9.90000,82.49999,31.48069,0.71739,3.49785,82.49999
9.92000,82.66667,31.55818,0.71884,3.50646,82.66667
9.94000,82.83329,31.43313,0.72029,3.49257,82.83329
9.96000,82.99992,31.58316,0.72174,3.50924,82.99992
9.98000,83.16656,31.61045,0.72319,3.51227,83.16656
10.00000,83.33337,31.68588,0.72464,3.52065,83.33337
10.02000,83.50004,31.74652,0.72609,3.52739,83.50004
10.04000,83.66674,31.89543,0.72754,3.54394,83.66674
10.06000,83.83336,31.78512,0.72899,3.53168,83.83336
10.08000,84.00005,31.77601,0.73044,3.53067,84.00005
10.10000,84.16668,31.89351,0.73188,3.54372,84.16668
10.12000,84.33343,31.77037,0.73333,3.53004,84.33343
10.14000,84.50005,31.87764,0.73478,3.54196,84.50005
10.16000,84.66662,32.10669,0.73623,3.56741,84.66662
10.18000,84.83330,32.07299,0.73768,3.56367,84.83330
10.20000,84.99999,32.07117,0.73913,3.56346,84.99999
10.22000,85.16667,32.14587,0.74058,3.57176,85.16667
10.24000,85.33336,32.23316,0.74203,3.58146,85.33336
10.26000,85.49999,32.39838,0.74348,3.59982,85.49999
10.28000,85.66661,32.34724,0.74493,3.59414,85.66661
10.30000,85.83331,32.29674,0.74638,3.58853,85.83331
10.32000,86.00005,32.46357,0.74783,3.60706,86.00005
10.34000,86.16667,32.54400,0.74928,3.61600,86.16667
10.36000,86.33330,32.46533,0.75072,3.60726,86.33330
10.38000,86.49998,32.47381,0.75217,3.60820,86.49998
10.40000,86.66655,32.51270,0.75362,3.61252,86.66655
10.42000,86.83329,32.52705,0.75507,3.61412,86.83329
10.44000,86.99999,32.72063,0.75652,3.63563,86.99999
10.46000,87.16667,32.60630,0.75797,3.62292,87.16667
10.48000,87.33329,32.59548,0.75942,3.62172,87.33329
10.50000,87.49999,32.69820,0.76087,3.63313,87.49999
10.52000,87.66667,32.79905,0.76232,3.64434,87.66667
10.54000,87.83330,32.67973,0.76377,3.63108,87.83330
10.56000,87.99993,32.81923,0.76522,3.64658,87.99993
10.58000,88.16661,32.96451,0.76667,3.66272,88.16661
10.60000,88.33330,33.02839,0.76812,3.66982,88.33330
10.62000,88.49998,33.08041,0.76957,3.67560,88.49998
10.64000,88.66668,33.12042,0.77101,3.68005,88.66668
10.66000,88.83343,33.01702,0.77246,3.66856,88.83343
10.68000,89.00005,33.18072,0.77391,3.68675,89.00005
10.70000,89.16661,33.20296,0.77536,3.68922,89.16661
10.72000,89.33330,33.39566,0.77681,3.71063,89.33330
10.74000,89.49992,33.46776,0.77826,3.71864,89.49992
10.76000,89.66668,33.36245,0.77971,3.70694,89.66668
10.78000,89.83336,33.25987,0.78116,3.69554,89.83336
10.80000,89.99999,33.44248,0.78261,3.71583,89.99999
10.82000,90.16661,33.54275,0.78406,3.72697,90.16661
10.84000,90.33330,33.52918,0.78551,3.72546,90.33330
10.86000,90.50005,33.69215,0.78696,3.74357,90.50005
10.88000,90.66667,33.78854,0.78841,3.75428,90.66667
10.90000,90.83336,33.88641,0.78986,3.76516,90.83336
10.92000,90.99999,34.04482,0.79130,3.78276,90.99999
10.94000,91.16654,33.86789,0.79275,3.76310,91.16654
10.96000,91.33330,33.71585,0.79420,3.74621,91.33330
10.98000,91.50005,33.87955,0.79565,3.76439,91.50005
11.00000,91.66667,34.13779,0.79710,3.79309,91.66667
11.02000,91.83336,34.12005,0.79855,3.79112,91.83336
11.04000,91.99998,34.17731,0.80000,3.79748,91.99998
11.06000,92.16661,34.24976,0.80145,3.80553,92.16661
11.08000,92.33336,34.27273,0.80290,3.80808,92.33336
11.10000,92.49998,34.43594,0.80435,3.82622,92.49998
11.12000,92.66655,34.45480,0.80580,3.82831,92.66655
11.14000,92.83324,34.33979,0.80725,3.81553,92.83324
11.16000,92.99998,34.49521,0.80870,3.83280,92.99998
11.18000,93.16668,34.57069,0.81015,3.84119,93.16668
11.20000,93.33342,34.46533,0.81159,3.82948,93.33342
11.22000,93.50005,34.69667,0.81304,3.85519,93.50005
11.24000,93.66661,34.79581,0.81449,3.86620,93.66661
11.26000,93.83336,34.74384,0.81594,3.86043,93.83336
11.28000,94.00011,34.78999,0.81739,3.86555,94.00011
11.30000,94.16673,34.90710,0.81884,3.87857,94.16673
11.32000,94.33342,34.72234,0.82029,3.85804,94.33342
11.34000,94.50004,34.84151,0.82174,3.87128,94.50004
11.36000,94.66661,35.15720,0.82319,3.90636,94.66661
11.38000,94.83336,34.97690,0.82464,3.88632,94.83336
11.40000,95.00004,35.01800,0.82609,3.89089,95.00004
11.42000,95.16668,35.06531,0.82754,3.89615,95.16668
11.44000,95.33335,35.14163,0.82899,3.90463,95.33335
11.46000,95.49998,35.33124,0.83043,3.92569,95.49998
11.48000,95.66661,35.40951,0.83188,3.93439,95.66661
11.50000,95.83330,35.48695,0.83333,3.94299,95.83330
11.52000,96.00005,35.42607,0.83478,3.93623,96.00005
11.54000,96.16661,35.47182,0.83623,3.94131,96.16661
11.56000,96.33330,35.42215,0.83768,3.93579,96.33330
11.58000,96.49992,35.47877,0.83913,3.94209,96.49992
11.60000,96.66661,35.43929,0.84058,3.93770,96.66661
11.62000,96.83336,35.42764,0.84203,3.93640,96.83336
11.64000,97.00004,35.60926,0.84348,3.95658,97.00004
11.66000,97.16661,35.74063,0.84493,3.97118,97.16661
11.68000,97.33323,35.68450,0.84638,3.96494,97.33323
11.70000,97.49993,35.82263,0.84783,3.98029,97.49993
11.72000,97.66667,35.94171,0.84928,3.99352,97.66667
11.74000,97.83336,36.02018,0.85072,4.00224,97.83336
11.76000,97.99998,35.97501,0.85217,3.99722,97.99998
11.78000,98.16654,36.06323,0.85362,4.00703,98.16654
11.80000,98.33329,35.93333,0.85507,3.99259,98.33329
11.82000,98.49999,36.04197,0.85652,4.00466,98.49999
11.84000,98.66673,36.17560,0.85797,4.01951,98.66673
11.86000,98.83337,36.10785,0.85942,4.01198,98.83337
11.88000,98.99999,36.38882,0.86087,4.04320,98.99999
11.90000,99.16661,36.44999,0.86232,4.05000,99.16661
11.92000,99.33336,36.45847,0.86377,4.05094,99.33336
11.94000,99.50005,36.46062,0.86522,4.05118,99.50005
11.96000,99.66673,36.52469,0.86667,4.05830,99.66673
11.98000,99.83336,36.34948,0.86812,4.03883,99.83336
12.00000,99.99998,36.50108,0.86957,4.05568,99.99998
12.02000,100.16668,36.63519,0.87101,4.07058,100.16668
12.04000,100.33342,36.58298,0.87246,4.06478,100.33342
12.06000,100.50005,36.73884,0.87391,4.08209,100.50005
12.08000,100.66668,36.88084,0.87536,4.09787,100.66668
12.10000,100.83330,36.79316,0.87681,4.08813,100.83330
12.12000,100.99999,36.74820,0.87826,4.08313,100.99999
12.14000,101.16667,36.94976,0.87971,4.10553,101.16667
12.16000,101.33336,36.97988,0.88116,4.10888,101.33336
12.18000,101.50004,37.06663,0.88261,4.11851,101.50004
12.20000,101.66667,37.03670,0.88406,4.11519,101.66667
12.22000,101.83336,37.01677,0.88551,4.11297,101.83336
12.24000,101.99999,37.14177,0.88696,4.12686,101.99999
12.26000,102.16667,37.10719,0.88841,4.12302,102.16667
12.28000,102.33330,37.09391,0.88985,4.12155,102.33330
12.30000,102.49998,37.42606,0.89130,4.15845,102.49998
12.32000,102.66654,37.49430,0.89275,4.16603,102.66654
12.34000,102.83330,37.46442,0.89420,4.16271,102.83330
12.36000,102.99998,37.53265,0.89565,4.17029,102.99998
12.38000,103.16667,37.64173,0.89710,4.18242,103.16667
12.40000,103.33336,37.68048,0.89855,4.18672,103.33336
12.42000,103.49998,37.75993,0.90000,4.19555,103.49998
12.44000,103.66655,37.81885,0.90145,4.20210,103.66655
12.46000,103.83330,37.73960,0.90290,4.19329,103.83330
12.48000,104.00005,37.75283,0.90435,4.19476,104.00005
12.50000,104.16673,37.83507,0.90580,4.20390,104.16673
12.52000,104.33336,37.78848,0.90725,4.19872,104.33336
12.54000,104.50005,37.91466,0.90870,4.21274,104.50005
12.56000,104.66667,37.97001,0.91014,4.21889,104.66667
12.58000,104.83336,37.90805,0.91159,4.21201,104.83336
12.60000,105.00005,38.12519,0.91304,4.23613,105.00005
12.62000,105.16667,38.37064,0.91449,4.26340,105.16667
12.64000,105.33329,38.19259,0.91594,4.24362,105.33329
12.66000,105.49999,38.22570,0.91739,4.24730,105.49999
12.68000,105.66667,38.31646,0.91884,4.25738,105.66667
12.70000,105.83342,38.16050,0.92029,4.24006,105.83342
12.72000,106.00004,38.30642,0.92174,4.25627,106.00004
12.74000,106.16661,38.50088,0.92319,4.27788,106.16661
12.76000,106.33330,38.60130,0.92464,4.28903,106.33330
12.78000,106.49998,38.74599,0.92609,4.30511,106.49998
12.80000,106.66673,38.82436,0.92754,4.31382,106.66673
12.82000,106.83335,38.69980,0.92899,4.29998,106.83335
12.84000,106.99992,38.82201,0.93043,4.31356,106.99992
12.86000,107.16654,38.93976,0.93188,4.32664,107.16654
12.88000,107.33330,38.89196,0.93333,4.32133,107.33330
12.90000,107.49999,38.83225,0.93478,4.31469,107.49999
12.92000,107.66667,38.86218,0.93623,4.31802,107.66667
12.94000,107.83330,38.76715,0.93768,4.30746,107.83330
12.96000,107.99998,39.02906,0.93913,4.33656,107.99998
12.98000,108.16661,39.24081,0.94058,4.36009,108.16661
13.00000,108.33336,39.27025,0.94203,4.36336,108.33336
13.02000,108.50005,39.31556,0.94348,4.36839,108.50005
13.04000,108.66667,39.30439,0.94493,4.36715,108.66667
13.06000,108.83336,39.22117,0.94638,4.35791,108.83336
13.08000,108.99998,39.41132,0.94783,4.37903,108.99998
13.10000,109.16667,39.47205,0.94928,4.38578,109.16667
13.12000,109.33336,39.49473,0.95072,4.38830,109.33336
13.14000,109.50005,39.54964,0.95217,4.39440,109.50005
13.16000,109.66667,39.56786,0.95362,4.39643,109.66667
13.18000,109.83329,39.59123,0.95507,4.39903,109.83329
13.20000,109.99999,39.70624,0.95652,4.41180,109.99999
13.22000,110.16667,39.70349,0.95797,4.41150,110.16667
13.24000,110.33342,39.55983,0.95942,4.39554,110.33342
13.26000,110.50005,39.85186,0.96087,4.42798,110.50005
13.28000,110.66660,39.98901,0.96232,4.44322,110.66660
13.30000,110.83330,39.89345,0.96377,4.43261,110.83330
13.32000,111.00005,40.01154,0.96522,4.44573,111.00005
13.34000,111.16668,40.08791,0.96667,4.45421,111.16668
13.36000,111.33336,40.00787,0.96812,4.44532,111.33336
13.38000,111.50005,40.23290,0.96957,4.47032,111.50005
13.40000,111.66661,40.39919,0.97101,4.48880,111.66661
13.42000,111.83330,40.24362,0.97246,4.47151,111.83330
13.44000,112.00004,40.36676,0.97391,4.48520,112.00004
13.46000,112.16667,40.53125,0.97536,4.50347,112.16667
13.48000,112.33330,40.43759,0.97681,4.49307,112.33330
13.50000,112.49992,40.59267,0.97826,4.51030,112.49992
13.52000,112.66655,40.63122,0.97971,4.51458,112.66655
13.54000,112.83336,40.61545,0.98116,4.51283,112.83336
13.56000,113.00005,40.56887,0.98261,4.50765,113.00005
13.58000,113.16667,40.60874,0.98406,4.51208,113.16667
13.60000,113.33330,40.73766,0.98551,4.52641,113.33330
13.62000,113.49998,40.79286,0.98696,4.53254,113.49998
13.64000,113.66667,40.82220,0.98841,4.53580,113.66667
13.66000,113.83343,40.73364,0.98986,4.52596,113.83343
13.68000,114.00005,40.95632,0.99130,4.55070,114.00005
13.70000,114.16667,41.03939,0.99275,4.55993,114.16667
13.72000,114.33336,41.05403,0.99420,4.56156,114.33336
13.74000,114.50005,41.09621,0.99565,4.56625,114.50005
13.76000,114.66674,41.22939,0.99710,4.58104,114.66674
13.78000,114.83336,41.04291,0.99855,4.56032,114.83336
13.80000,114.99998,41.15396,1.00000,4.57266,114.99998
13.82000,115.16660,41.32990,1.00145,4.59221,115.16660
13.84000,115.33336,41.35234,1.00290,4.59470,115.33336
13.86000,115.50005,41.43115,1.00435,4.60346,115.50005
13.88000,115.66673,41.57790,1.00580,4.61977,115.66673
13.90000,115.83336,41.52588,1.00725,4.61399,115.83336
13.92000,115.99992,41.68870,1.00870,4.63208,115.99992
13.94000,116.16661,41.75933,1.01014,4.63993,116.16661
13.96000,116.33329,41.51966,1.01159,4.61330,116.33329
13.98000,116.50004,41.53867,1.01304,4.61541,116.50004
14.00000,116.66667,41.71995,1.01449,4.63555,116.66667
14.02000,116.83336,41.73112,1.01594,4.63679,116.83336
14.04000,116.99992,41.75693,1.01739,4.63966,116.99992
14.06000,117.16661,42.02305,1.01884,4.66923,117.16661
14.08000,117.33330,42.01943,1.02029,4.66883,117.33330
14.10000,117.49999,41.97392,1.02174,4.66377,117.49999
14.12000,117.66661,42.02697,1.02319,4.66966,117.66661
14.14000,117.83330,42.05597,1.02464,4.67288,117.83330
14.16000,117.99992,42.11430,1.02609,4.67937,117.99992
14.18000,118.16661,42.01394,1.02754,4.66822,118.16661
14.20000,118.33336,42.13184,1.02899,4.68132,118.33336
14.22000,118.50005,42.54471,1.03044,4.72719,118.50005
14.24000,118.66667,42.48779,1.03188,4.72087,118.66667
14.26000,118.83336,42.31807,1.03333,4.70201,118.83336
14.28000,119.00004,42.48314,1.03478,4.72035,119.00004
14.30000,119.16674,42.67363,1.03623,4.74151,119.16674
14.32000,119.33342,42.57293,1.03768,4.73033,119.33342
14.34000,119.49998,42.61265,1.03913,4.73474,119.49998
14.36000,119.66661,42.75058,1.04058,4.75006,119.66661
14.38000,119.83329,42.66330,1.04203,4.74037,119.83329
14.40000,120.00005,42.62220,1.04348,4.73580,120.00005
14.42000,120.16674,42.76895,1.04493,4.75211,120.16674
14.44000,120.33336,42.69724,1.04638,4.74414,120.33336
14.46000,120.49999,42.93750,1.04783,4.77083,120.49999
14.48000,120.66661,43.10061,1.04927,4.78896,120.66661
14.50000,120.83329,43.06730,1.05072,4.78526,120.83329
14.52000,121.00005,43.15430,1.05217,4.79492,121.00005
14.54000,121.16661,43.19676,1.05362,4.79964,121.16661
14.56000,121.33330,43.14793,1.05507,4.79421,121.33330
14.58000,121.49998,43.22366,1.05652,4.80263,121.49998
14.60000,121.66668,43.32672,1.05797,4.81408,121.66668
14.62000,121.83336,43.46538,1.05942,4.82949,121.83336
14.64000,121.99998,43.72195,1.06087,4.85799,121.99998
14.66000,122.16661,43.64133,1.06232,4.84904,122.16661
14.68000,122.33323,43.52152,1.06377,4.83572,122.33323
14.70000,122.49999,43.65999,1.06522,4.85111,122.49999
14.72000,122.66668,43.86787,1.06667,4.87421,122.66668
14.74000,122.83330,43.73292,1.06812,4.85921,122.83330
14.76000,122.99999,43.69673,1.06957,4.85519,122.99999
14.78000,123.16661,43.81717,1.07101,4.86857,123.16661
14.80000,123.33330,43.67762,1.07246,4.85307,123.33330
14.82000,123.50004,43.91808,1.07391,4.87979,123.50004
14.84000,123.66667,44.15873,1.07536,4.90653,123.66667
14.86000,123.83336,44.08951,1.07681,4.89884,123.83336
14.88000,123.99998,44.11587,1.07826,4.90176,123.99998
14.90000,124.16661,44.15500,1.07971,4.90611,124.16661
14.92000,124.33336,44.14188,1.08116,4.90465,124.33336
14.94000,124.50005,44.21560,1.08261,4.91284,124.50005
14.96000,124.66667,44.35637,1.08406,4.92849,124.66667
14.98000,124.83336,44.25199,1.08551,4.91689,124.83336
15.00000,124.99998,44.43210,1.08696,4.93690,124.99998
15.02000,125.16667,44.64478,1.08841,4.96053,125.16667
15.04000,125.33336,44.55994,1.08986,4.95110,125.33336
15.06000,125.50004,44.68073,1.09130,4.96453,125.50004
15.08000,125.66666,44.82249,1.09275,4.98028,125.66666
15.10000,125.83329,44.71904,1.09420,4.96878,125.83329
15.12000,125.99992,44.80823,1.09565,4.97869,125.99992
15.14000,126.16660,44.91369,1.09710,4.99041,126.16660
15.16000,126.33336,44.93857,1.09855,4.99317,126.33336
15.18000,126.50005,45.07239,1.10000,5.00804,126.50005
15.20000,126.66660,45.06573,1.10145,5.00730,126.66660
15.22000,126.83329,44.93475,1.10290,4.99275,126.83329
15.24000,126.99998,44.83213,1.10435,4.98135,126.99998
15.26000,127.16666,45.02287,1.10580,5.00254,127.16666
15.28000,127.33336,45.05740,1.10725,5.00638,127.33336
15.30000,127.49991,45.13837,1.10869,5.01537,127.49991
15.32000,127.66647,45.02307,1.11014,5.00256,127.66647
15.34000,127.83329,45.05079,1.11159,5.00564,127.83329
15.36000,128.00003,45.30560,1.11304,5.03396,128.00003
15.38000,128.16672,45.37799,1.11449,5.04200,128.16672
15.40000,128.33342,45.44823,1.11594,5.04980,128.33342
15.42000,128.50004,45.60326,1.11739,5.06703,128.50004
15.44000,128.66667,45.68727,1.11884,5.07636,128.66667
15.46000,128.83342,45.64960,1.12029,5.07218,128.83342
15.48000,129.00010,45.72440,1.12174,5.08049,129.00010
15.50000,129.16672,45.88354,1.12319,5.09817,129.16672
15.52000,129.33329,45.69942,1.12464,5.07771,129.33329
15.54000,129.49998,45.69878,1.12609,5.07764,129.49998
15.56000,129.66667,45.76789,1.12754,5.08532,129.66667
15.58000,129.83342,45.79439,1.12899,5.08827,129.83342
15.60000,130.00011,46.04200,1.13044,5.11578,130.00011
15.62000,130.16666,45.92057,1.13188,5.10229,130.16666
15.64000,130.33330,45.90451,1.13333,5.10050,130.33330
15.66000,130.49997,46.21133,1.13478,5.13459,130.49997
15.68000,130.66660,46.15642,1.13623,5.12849,130.66660
15.70000,130.83328,46.02848,1.13768,5.11428,130.83328
15.72000,130.99998,46.29450,1.13913,5.14383,130.99998
15.74000,131.16653,46.38580,1.14058,5.15398,131.16653
15.76000,131.33329,46.28373,1.14203,5.14264,131.33329
15.78000,131.49998,46.38718,1.14348,5.15413,131.49998
15.80000,131.66666,46.44209,1.14493,5.16023,131.66666
15.82000,131.83336,46.60177,1.14638,5.17797,131.83336
15.84000,131.99999,46.68210,1.14783,5.18690,131.99999
15.86000,132.16661,46.76914,1.14927,5.19657,132.16661
15.88000,132.33324,46.65839,1.15072,5.18427,132.33324
15.90000,132.49998,46.69905,1.15217,5.18878,132.49998
15.92000,132.66660,46.63615,1.15362,5.18179,132.66660
15.94000,132.83329,46.74920,1.15507,5.19436,132.83329
15.96000,132.99991,46.77673,1.15652,5.19741,132.99991
15.98000,133.16660,46.81567,1.15797,5.20174,133.16660
16.00000,133.33336,46.84477,1.15942,5.20497,133.33336
16.02000,133.50004,47.00048,1.16087,5.22228,133.50004
16.04000,133.66672,46.96708,1.16232,5.21856,133.66672
16.06000,133.83329,46.86666,1.16377,5.20741,133.83329
16.08000,133.99998,47.01684,1.16522,5.22409,133.99998
16.10000,134.16666,47.30329,1.16667,5.25592,134.16666
16.12000,134.33342,47.36050,1.16812,5.26228,134.33342
16.14000,134.50004,47.31906,1.16957,5.25767,134.50004
16.16000,134.66661,47.30192,1.17101,5.25577,134.66661
16.18000,134.83330,47.33606,1.17246,5.25956,134.83330
16.20000,134.99998,47.52895,1.17391,5.28099,134.99998
16.22000,135.16666,47.59841,1.17536,5.28871,135.16666
16.24000,135.33342,47.59963,1.17681,5.28885,135.33342
16.26000,135.50005,47.85248,1.17826,5.31694,135.50005
16.28000,135.66661,47.90768,1.17971,5.32308,135.66661
16.30000,135.83330,47.80399,1.18116,5.31155,135.83330
16.32000,135.99998,47.90141,1.18261,5.32238,135.99998
16.34000,136.16666,47.92223,1.18406,5.32469,136.16666
16.36000,136.33335,47.90504,1.18551,5.32278,136.33335
16.38000,136.49997,48.01099,1.18696,5.33455,136.49997
16.40000,136.66660,48.29773,1.18841,5.36641,136.66660
16.42000,136.83336,48.18727,1.18986,5.35414,136.83336
16.44000,137.00004,48.21794,1.19130,5.35755,137.00004
16.46000,137.16667,48.14730,1.19275,5.34970,137.16667
16.48000,137.33329,47.97959,1.19420,5.33107,137.33329
16.50000,137.49992,48.15426,1.19565,5.35047,137.49992
16.52000,137.66654,48.14280,1.19710,5.34920,137.66654
16.54000,137.83336,48.23596,1.19855,5.35955,137.83336
16.56000,138.00004,48.33344,1.20000,5.37038,138.00004
16.58000,138.16667,48.48666,1.20145,5.38741,138.16667
16.60000,138.33336,48.40030,1.20290,5.37781,138.33336
16.62000,138.50003,48.56801,1.20435,5.39645,138.50003
16.64000,138.66673,48.70046,1.20580,5.41116,138.66673
16.66000,138.83342,48.74832,1.20725,5.41648,138.83342
16.68000,139.00004,48.85647,1.20870,5.42850,139.00004
16.70000,139.16667,48.98147,1.21014,5.44239,139.16667
16.72000,139.33335,48.76546,1.21159,5.41838,139.33335
16.74000,139.50004,48.71736,1.21304,5.41304,139.50004
16.76000,139.66672,48.82537,1.21449,5.42504,139.66672
16.78000,139.83342,48.86509,1.21594,5.42945,139.83342
16.80000,140.00005,49.01664,1.21739,5.44629,140.00005
16.82000,140.16667,49.18646,1.21884,5.46516,140.16667
16.84000,140.33335,49.03173,1.22029,5.44797,140.33335
16.86000,140.50004,49.06700,1.22174,5.45189,140.50004
16.88000,140.66666,48.92357,1.22319,5.43595,140.66666
16.90000,140.83329,48.91020,1.22464,5.43447,140.83329
16.92000,140.99992,49.23510,1.22609,5.47057,140.99992
16.94000,141.16654,49.34580,1.22754,5.48287,141.16654
16.96000,141.33330,49.35898,1.22899,5.48433,141.33330
16.98000,141.50004,47.33969,1.23044,5.25996,141.50004
17.00000,141.66673,21.68025,1.23188,2.40892,141.66673
17.02000,141.83329,3.35345,1.23333,0.37261,141.83329
17.04000,141.99997,-1.86348,1.23478,-0.20705,141.99997
17.06000,142.16661,-1.43682,1.23623,-0.15965,142.16661
17.08000,142.33336,-0.50973,1.23768,-0.05664,142.33336
17.10000,142.50005,0.00302,1.23913,0.00034,142.50005
17.12000,142.66661,0.10803,1.24058,0.01200,142.66661
17.14000,142.83329,0.07110,1.24203,0.00790,142.83329
17.16000,142.99998,0.20468,1.24348,0.02274,142.99998
17.18000,143.16666,0.16228,1.24493,0.01803,143.16666
17.20000,143.33342,-0.00301,1.24638,-0.00033,143.33342
17.22000,143.50004,-0.05042,1.24783,-0.00560,143.50004
17.24000,143.66667,-0.02625,1.24928,-0.00292,143.66667
17.26000,143.83336,-0.11753,1.25072,-0.01306,143.83336
17.28000,144.00004,-0.00088,1.25217,-0.00010,144.00004
17.30000,144.16672,-0.01072,1.25362,-0.00119,144.16672
17.32000,144.33342,0.03664,1.25507,0.00407,144.33342
17.34000,144.49998,-0.01241,1.25652,-0.00138,144.49998
17.36000,144.66660,0.02396,1.25797,0.00266,144.66660
17.38000,144.83335,-0.14726,1.25942,-0.01636,144.83335
17.40000,145.00004,-0.05990,1.26087,-0.00666,145.00004
17.42000,145.16667,0.03427,1.26232,0.00381,145.16667
17.44000,145.33335,-0.02983,1.26377,-0.00331,145.33335
17.46000,145.49998,0.05227,1.26522,0.00581,145.49998
17.48000,145.66666,0.03642,1.26667,0.00405,145.66666
17.50000,145.83336,-0.02441,1.26812,-0.00271,145.83336
17.52000,146.00004,0.11362,1.26957,0.01262,146.00004
17.54000,146.16661,0.04872,1.27101,0.00541,146.16661
17.56000,146.33330,-0.11079,1.27246,-0.01231,146.33330
17.58000,146.49997,0.00378,1.27391,0.00042,146.49997
17.60000,146.66661,0.11396,1.27536,0.01266,146.66661
17.62000,146.83335,-0.10149,1.27681,-0.01128,146.83335
17.64000,147.00005,-0.22421,1.27826,-0.02491,147.00005
17.66000,147.16660,-0.11520,1.27971,-0.01280,147.16660
17.68000,147.33324,-0.07244,1.28116,-0.00805,147.33324
17.70000,147.49992,0.10105,1.28261,0.01123,147.49992
17.72000,147.66661,0.07725,1.28406,0.00858,147.66661
17.74000,147.83335,-0.08990,1.28551,-0.00999,147.83335
17.76000,148.00005,-0.04293,1.28696,-0.00477,148.00005
17.78000,148.16660,0.02263,1.28841,0.00251,148.16660
17.80000,148.33330,-0.02427,1.28985,-0.00270,148.33330
17.82000,148.50005,0.01622,1.29130,0.00180,148.50005
17.84000,148.66672,0.14044,1.29275,0.01560,148.66672
17.86000,148.83341,0.00179,1.29420,0.00020,148.83341
17.88000,148.99998,-0.04097,1.29565,-0.00455,148.99998
17.90000,149.16660,0.05648,1.29710,0.00628,149.16660
17.92000,149.33336,0.12351,1.29855,0.01372,149.33336
17.94000,149.50004,0.14639,1.30000,0.01627,149.50004
17.96000,149.66667,0.07296,1.30145,0.00811,149.66667
17.98000,149.83329,-0.11510,1.30290,-0.01279,149.83329
18.00000,149.99998,-0.01256,1.30435,-0.00140,149.99998
18.02000,150.16660,-0.07073,1.30580,-0.00786,150.16660
18.04000,150.33342,-0.13849,1.30725,-0.01539,150.33342
18.06000,150.50004,0.04007,1.30870,0.00445,150.50004
18.08000,150.66667,0.12650,1.31015,0.01406,150.66667
18.10000,150.83330,-0.12483,1.31159,-0.01387,150.83330
18.12000,150.99992,-0.13019,1.31304,-0.01447,150.99992
18.14000,151.16661,-0.09277,1.31449,-0.01031,151.16661
18.16000,151.33335,-0.10408,1.31594,-0.01156,151.33335
18.18000,151.49998,-0.10239,1.31739,-0.01138,151.49998
18.20000,151.66660,-0.04538,1.31884,-0.00504,151.66660
18.22000,151.83322,-0.11258,1.32029,-0.01251,151.83322
18.24000,151.99998,0.21354,1.32174,0.02373,151.99998
18.26000,152.16666,0.37364,1.32319,0.04152,152.16666
18.28000,152.33335,0.22549,1.32464,0.02505,152.33335
18.30000,152.49997,0.09809,1.32609,0.01090,152.49997
18.32000,152.66660,-0.00624,1.32754,-0.00069,152.66660
18.34000,152.83328,0.06307,1.32899,0.00701,152.83328
18.36000,153.00005,0.26848,1.33044,0.02983,153.00005
18.36800,153.06673,0.15224,1.33101,0.01692,153.06673