File: FR/FR/RDSO FR Tensile 50.is_tens_RawData/Specimen_RawData_1.csv
Time,Extension,Load
(sec),(mm),(N)
0.00000,0.00000,0.00555
0.20000,0.16469,0.79645
0.40000,0.33306,1.45932
0.60000,0.49994,1.99029
0.80000,0.66675,2.37935
1.00000,0.83337,2.84499
1.20000,0.99994,3.21862
1.40000,1.16681,3.49140
1.60000,1.33331,3.73012
1.80000,1.49987,4.05627
2.00000,1.66662,4.39584
2.20000,1.83344,4.60894
2.40000,1.99994,4.93532
2.60000,2.16662,4.93630
2.80000,2.33331,5.31698
3.00000,2.49994,5.59143
3.20000,2.66675,5.58315
3.40000,2.83337,6.01543
3.60000,2.99994,6.39322
3.80000,3.16675,6.37445
4.00000,3.33337,6.59480
4.20000,3.49994,6.81246
4.40000,3.66681,6.97970
4.60000,3.83331,7.15311
4.80000,3.99994,7.13924
5.00000,4.16669,7.30471
5.20000,4.33337,7.52810
5.40000,4.49994,7.84856
5.60000,4.66669,7.80441
5.80000,4.83325,7.90261
6.00000,4.99994,8.06695
6.20000,5.16675,8.30446
6.40000,5.33337,8.16995
6.60000,5.50000,8.59801
6.80000,5.66675,8.67534
7.00000,5.83331,8.82351
7.20000,5.99994,8.79215
7.40000,6.16675,8.99060
7.60000,6.33337,9.25907
7.80000,6.49994,9.09615
8.00000,6.66675,9.40823
8.20000,6.83331,9.30106
8.40000,6.99987,9.69973
8.60000,7.16675,9.68155
8.80000,7.33337,9.68787
9.00000,7.49994,10.06884
9.20000,7.66669,9.92709
9.40000,7.83325,9.84727
9.60000,7.99987,10.12642
9.80000,8.16681,10.15405
10.00000,8.33337,10.38994
10.20000,8.49987,10.17307
10.40000,8.66669,10.39146
10.60000,8.83331,10.61436
10.80000,8.99987,10.75680
11.00000,9.16675,10.70712
11.20000,9.33337,10.70266
11.40000,9.49994,10.87959
11.60000,9.66669,10.95971
11.80000,9.83337,10.91963
12.00000,10.00000,10.91130
12.20000,10.16675,11.10612
12.40000,10.33331,11.18849
12.60000,10.49994,11.45823
12.80000,10.66669,11.34005
13.00000,10.83331,11.51208
13.20000,10.99994,11.34769
13.40000,11.16669,11.44966
13.60000,11.33331,11.70985
13.80000,11.49987,11.64507
14.00000,11.66675,11.68961
14.20000,11.83337,11.81103
14.40000,11.99987,11.66354
14.60000,12.16669,11.95313
14.80000,12.33337,11.98008
15.00000,12.50000,12.09817
15.20000,12.66675,12.13012
15.40000,12.83331,11.98944
15.60000,12.99994,12.20720
15.80000,13.16675,11.98366
16.00000,13.33325,12.13360
16.20000,13.50000,12.26884
16.40000,13.66681,12.18446
16.60000,13.83331,12.44034
16.80000,13.99987,12.46886
17.00000,14.16669,12.40805
17.20000,14.33337,12.35601
17.40000,14.50000,12.57915
17.60000,14.66669,12.68313
17.80000,14.83331,12.53966
18.00000,14.99994,12.78941
18.20000,15.16675,12.73777
18.40000,15.33331,12.70469
18.60000,15.50000,12.70464
18.80000,15.66675,12.80749
19.00000,15.83337,12.86992
19.20000,15.99994,12.88540
19.40000,16.16675,12.82283
19.60000,16.33337,12.91985
19.80000,16.49987,13.15191
20.00000,16.66681,13.03593
20.20000,16.83337,13.07180
20.40000,16.99987,13.23007
20.60000,17.16669,13.17068
20.80000,17.33337,12.95278
21.00000,17.49994,13.28652
21.20000,17.66675,13.21654
21.40000,17.83331,13.12384
21.60000,17.99993,13.22066
21.80000,18.16675,13.10041
22.00000,18.33331,13.30621
22.20000,18.49987,13.34198
22.40000,18.66681,13.23198
22.60000,18.83337,13.47732
22.80000,18.99993,13.20944
23.00000,19.16662,13.48756
23.20000,19.33331,13.60021
23.40000,19.49994,13.46086
23.60000,19.66675,13.52191
23.80000,19.83337,13.39422
24.00000,19.99993,13.56185
24.20000,20.16675,13.53220
24.40000,20.33331,13.72619
24.60000,20.49993,13.58860
24.80000,20.66675,13.79391
25.00000,20.83337,13.77833
25.20000,20.99993,13.77495
25.40000,21.16675,13.85986
25.60000,21.33331,13.75525
25.80000,21.49994,13.82635
26.00000,21.66675,13.81929
26.20000,21.83337,14.04944
26.40000,21.99993,13.96776
26.60000,22.16668,13.94948
26.80000,22.33331,14.02171
27.00000,22.49993,14.32468
27.20000,22.66675,14.15073
27.40000,22.83331,14.20306
27.60000,22.99994,14.01451
27.80000,23.16675,13.89250
28.00000,23.33331,13.96222
28.20000,23.49993,13.96776
28.40000,23.66675,13.95615
28.60000,23.83331,14.21006
28.80000,23.99993,14.13367
29.00000,24.16675,14.43399
29.20000,24.33343,14.36309
29.40000,24.49993,14.24231
29.60000,24.66668,14.30998
29.80000,24.83331,14.33497
30.00000,24.99999,14.24226
30.20000,25.16675,14.13049
30.40000,25.33331,14.32002
30.60000,25.49981,14.39842
30.80000,25.66668,14.52817
31.00000,25.83337,14.52440
31.20000,25.99993,14.32017
31.40000,26.16675,14.56997
31.60000,26.33331,14.53297
31.80000,26.49987,14.64058
32.00000,26.66668,14.56600
32.20000,26.83337,14.71231
32.40000,26.99994,14.59908
32.60000,27.16674,14.62152
32.80000,27.33337,14.54042
33.00000,27.49993,14.52954
33.20000,27.66668,14.73681
33.40000,27.83337,14.72314
33.60000,28.00000,14.82781
33.80000,28.16675,14.65400
34.00000,28.33331,14.83310
34.20000,28.49987,14.55988
34.40000,28.66675,14.67316
34.60000,28.83331,14.80184
34.80000,28.99987,14.93732
35.00000,29.16669,14.89773
35.20000,29.33337,14.88058
35.40000,29.49993,15.03978
35.60000,29.66675,14.64773
35.80000,29.83331,15.08163
36.00000,29.99993,14.89895
36.20000,30.16668,15.06403
36.40000,30.33337,14.95565
36.60000,30.49999,14.90238
36.80000,30.66675,14.91983
37.00000,30.83325,15.00994
37.20000,30.99993,15.13900
37.40000,31.16681,15.10211
37.60000,31.33337,15.15517
37.80000,31.49993,15.03013
38.00000,31.66674,15.19898
38.20000,31.83331,15.22544
38.40000,31.99993,15.27846
38.60000,32.16675,15.15174
38.80000,32.33337,15.25729
39.00000,32.49993,15.16742
39.20000,32.66668,15.29335
39.40000,32.83331,15.42884
39.60000,33.00000,15.40777
39.80000,33.16681,15.33598
40.00000,33.33337,15.28997
40.20000,33.49993,15.47715
40.40000,33.66675,15.17997
40.60000,33.83337,15.29953
40.80000,33.99981,15.50905
41.00000,34.16675,15.55771
41.20000,34.33343,15.44021
41.40000,34.49987,15.53835
41.60000,34.66674,15.68227
41.80000,34.83337,15.44413
42.00000,34.99993,15.54046
42.20000,35.16668,15.56457
42.40000,35.33331,15.62518
42.60000,35.49987,15.68227
42.80000,35.66675,15.53889
43.00000,35.83337,15.70588
43.20000,35.99987,15.73700
43.40000,36.16675,15.68761
43.60000,36.33331,15.76311
43.80000,36.49993,15.85891
44.00000,36.66674,15.96117
44.20000,36.83337,15.87831
44.40000,36.99993,15.96759
44.60000,37.16668,15.81197
44.80000,37.33331,16.01840
45.00000,37.49993,15.90497
45.20000,37.66675,16.03585
45.40000,37.83331,16.11043
45.60000,37.99993,15.86660
45.80000,38.16668,16.04589
46.00000,38.33331,15.90061
46.20000,38.49993,15.94696
46.40000,38.66674,16.08617
46.60000,38.83331,16.05751
46.80000,38.99987,16.01615
47.00000,39.16668,16.06466
47.20000,39.33337,15.98102
47.40000,39.49999,16.49405
47.60000,39.66675,16.12949
47.80000,39.83330,16.34479
48.00000,39.99987,16.17613
48.20000,40.16674,16.34759
48.40000,40.33331,16.34759
48.60000,40.49993,16.41535
48.80000,40.66675,16.54153
49.00000,40.83325,16.12410
49.20000,40.99987,16.37062
49.40000,41.16681,16.58798
49.60000,41.33331,16.42638
49.80000,41.49993,16.51585
50.00000,41.66674,16.60758
50.20000,41.83337,16.51169
50.40000,41.99993,16.51663
50.60000,42.16681,16.63374
50.80000,42.33337,16.71312
51.00000,42.49987,16.76291
51.20000,42.66674,16.38179
51.40000,42.83337,16.60331
51.60000,42.99993,16.60243
51.80000,43.16675,16.67280
52.00000,43.33337,16.90261
52.20000,43.49981,16.60263
52.40000,43.66674,16.72822
52.60000,43.83331,16.73459
52.80000,43.99987,16.81255
53.00000,44.16668,16.79133
53.20000,44.33337,16.99561
53.40000,44.49993,16.81279
53.60000,44.66674,16.92799
53.80000,44.83337,16.83606
54.00000,44.99999,16.94891
54.20000,45.16668,16.90662
54.40000,45.33330,17.05720
54.60000,45.49993,17.17838
54.80000,45.66681,16.99992
55.00000,45.83331,17.16368
55.20000,45.99987,17.19205
55.40000,46.16668,17.17166
55.60000,46.33330,17.25349
55.80000,46.49993,17.25202
56.00000,46.66674,17.30891
56.20000,46.83337,17.15452
56.40000,46.99986,17.15172
56.60000,47.16674,17.03770
56.80000,47.33331,17.46904
57.00000,47.49993,17.15143
57.20000,47.66668,17.29647
57.40000,47.83330,17.39104
57.60000,47.99993,17.48017
57.80000,48.16674,17.60747
58.00000,48.33330,17.47125
58.20000,48.49993,17.34297
58.40000,48.66675,17.47796
58.60000,48.83330,17.63030
58.80000,48.99987,17.64290
59.00000,49.16674,17.60115
59.20000,49.33331,17.56567
59.40000,49.49987,17.70821
59.60000,49.66668,17.60811
59.80000,49.83330,17.74472
60.00000,49.99999,17.72742
60.20000,50.16674,17.65843
60.40000,50.33331,17.72076
60.60000,50.49993,17.78078
60.80000,50.66674,17.69743
61.00000,50.83337,18.05543
61.20000,50.99987,17.86050
61.40000,51.16674,17.90176
61.60000,51.33336,17.96443
61.80000,51.49987,17.99045
62.00000,51.66674,17.86080
62.20000,51.83343,17.78441
62.40000,51.99993,17.79881
62.60000,52.16668,18.10761
62.80000,52.33331,18.00672
63.00000,52.49986,17.90117
63.20000,52.66674,18.04803
63.40000,52.83337,18.15097
63.60000,52.99993,18.14073
63.80000,53.16674,18.13133
64.00000,53.33330,18.02519
64.20000,53.49987,18.12314
64.40000,53.66674,18.30170
64.60001,53.83337,18.21531
64.80000,53.99993,18.26348
65.00000,54.16675,18.26039
65.20000,54.33330,18.31689
65.40000,54.49993,18.37559
65.60001,54.66674,18.54219
65.80000,54.83331,18.52553
66.00000,54.99993,18.47339
66.20001,55.16674,18.37941
66.40000,55.33330,18.51661
66.60001,55.49993,18.42802
66.80000,55.66674,18.41445
67.00000,55.83324,18.51901
67.20001,55.99993,18.59325
67.40000,56.16674,18.66689
67.60001,56.33337,18.62789
67.80000,56.49993,18.82869
68.00000,56.66668,18.67327
68.20001,56.83336,18.78337
68.40000,56.99987,18.79679
68.60001,57.16674,18.77504
68.80000,57.33337,18.94516
69.00000,57.49993,18.96913
69.20001,57.66674,18.86466
69.40000,57.83324,18.84026
69.60001,57.99993,19.04086
69.80000,58.16680,18.83594
70.00000,58.33331,18.95722
70.20001,58.49987,19.03763
70.40000,58.66674,19.03606
70.60001,58.83330,19.03841
70.80000,58.99993,19.05669
71.00000,59.16674,19.03728
71.20001,59.33337,18.93590
71.40000,59.49981,19.29488
71.60001,59.66668,19.00495
71.80000,59.83337,19.11534
72.00000,59.99999,19.11632
72.20001,60.16674,19.32246
72.40000,60.33331,19.22079
72.60001,60.49993,19.18850
72.80000,60.66674,19.58598
73.00000,60.83337,19.19105
73.20001,60.99987,19.62484
73.40000,61.16681,19.49906
73.60001,61.33331,19.56972
73.80000,61.49987,19.43693
74.00000,61.66674,19.50744
74.20001,61.83337,19.64380
74.40000,61.99993,19.45393
74.60001,62.16668,19.57604
74.80000,62.33331,19.47755
75.00000,62.49993,19.84779
75.20001,62.66674,19.44555
75.40000,62.83330,19.88136
75.60001,62.99987,19.65326
75.80000,63.16680,19.88488
76.00000,63.33336,19.87033
76.20001,63.49993,19.80276
76.40000,63.66680,19.86293
76.60001,63.83331,19.88827
76.80000,63.99993,19.90835
77.00000,64.16667,19.86259
77.20001,64.33337,19.99896
77.40000,64.49993,20.06148
77.60001,64.66674,19.99621
77.80000,64.83330,20.09647
78.00000,64.99992,20.19765
78.20001,65.16674,20.18917
78.40000,65.33337,20.07549
78.60001,65.49987,20.40761
78.80000,65.66674,20.24636
79.00000,65.83330,20.31520
79.20001,65.99993,20.31966
79.40000,66.16674,20.25841
79.60001,66.33336,20.51341
79.80000,66.49993,20.14909
80.00000,66.66674,20.54138
80.20001,66.83331,20.39047
80.40000,66.99986,20.35288
80.60001,67.16674,20.41183
80.80000,67.33330,20.62753
81.00001,67.49993,20.63394
81.20001,67.66674,20.54530
81.40000,67.83336,20.58191
81.60001,67.99986,20.63233
81.80000,68.16674,20.77849
82.00001,68.33330,20.92628
82.20001,68.49993,20.62802
82.40000,68.66674,20.60807
82.60001,68.83337,20.73126
82.80000,68.99992,20.79956
83.00001,69.16674,20.88463
83.20001,69.33324,20.93691
83.40000,69.49992,20.84366
83.60001,69.66680,20.99400
83.80000,69.83336,20.97591
84.00001,69.99987,20.97268
84.20001,70.16668,20.97249
84.40000,70.33330,21.04775
84.60001,70.49993,21.13477
84.80000,70.66674,21.19102
85.00001,70.83330,21.11958
85.20001,70.99986,21.09841
85.40000,71.16674,21.29451
85.60001,71.33331,21.43480
85.80000,71.49993,21.11106
86.00001,71.66680,21.30495
86.20001,71.83337,21.08269
86.40000,71.99993,21.25977
86.60001,72.16667,21.56661
86.80000,72.33337,21.32773
87.00001,72.49992,21.21739
87.20001,72.66674,21.42083
87.40000,72.83330,21.63815
87.60001,72.99987,21.50252
87.80000,73.16674,21.53917
88.00001,73.33330,21.39109
88.20001,73.49993,21.58949
88.40000,73.66674,21.48630
88.60001,73.83330,21.69563
88.80000,73.99987,21.68876
89.00001,74.16674,21.80215
89.20001,74.33336,21.84787
89.40000,74.49986,21.69327
89.60001,74.66668,21.64182
89.80000,74.83337,21.81219
90.00001,74.99993,21.76339
90.20001,75.16674,22.03024
90.40000,75.33330,21.85252
90.60001,75.49986,21.81714
90.80000,75.66674,21.93842
91.00001,75.83336,21.84669
91.20001,75.99999,22.19160
91.40000,76.16674,21.88574
91.60001,76.33324,21.89456
91.80000,76.49980,22.29161
92.00001,76.66667,22.15686
92.20001,76.83337,22.16387
92.40000,76.99999,22.36183
92.60001,77.16674,22.28774
92.80000,77.33330,22.20258
93.00001,77.49987,22.45899
93.20001,77.66674,22.47536
93.40000,77.83336,22.38863
93.60001,77.99993,22.43376
93.80000,78.16673,22.36536
94.00001,78.33336,22.42964
94.20001,78.49980,22.72139
94.40000,78.66674,22.44836
94.60001,78.83336,22.60756
94.80000,78.99993,22.93356
95.00001,79.16674,22.73800
95.20001,79.33330,22.69135
95.40000,79.49986,22.77999
95.60001,79.66674,22.77421
95.80000,79.83336,22.52627
96.00001,79.99992,22.86559
96.20001,80.16674,22.64759
96.40000,80.33336,22.76470
96.60001,80.49986,22.90470
96.80000,80.66674,22.96835
97.00001,80.83330,23.04498
97.20001,80.99993,22.85084
97.40000,81.16674,23.15146
97.60001,81.33336,23.08727
97.80000,81.49998,22.93655
98.00001,81.66668,22.93586
98.20001,81.83330,23.05694
98.40000,81.99993,23.15675
98.60001,82.16674,23.22712
98.80000,82.33336,23.24961
99.00001,82.49993,23.20683
99.20001,82.66667,23.43326
99.40000,82.83329,23.17287
99.60001,82.99992,23.44178
99.80000,83.16674,23.59643
100.00001,83.33337,23.52254
100.20001,83.49986,23.48378
100.40000,83.66674,23.43924
100.60001,83.83336,23.49539
100.80000,83.99987,23.53425
101.00001,84.16673,23.61220
101.20001,84.33335,23.57869
101.40000,84.49992,23.57452
101.60001,84.66667,23.71001
101.80000,84.83330,23.76900
102.00001,84.99986,23.82511
102.20001,85.16674,23.93203
102.40000,85.33330,23.90023
102.60001,85.49985,23.71069
102.80000,85.66679,23.85632
103.00001,85.83331,23.94643
103.20001,85.99993,23.94785
103.40000,86.16674,23.82227
103.60001,86.33330,23.98157
103.80000,86.49986,24.07844
104.00001,86.66680,23.99577
104.20001,86.83336,23.96231
104.40000,86.99981,23.80272
104.60001,87.16667,24.11288
104.80000,87.33337,24.19653
105.00001,87.49993,24.36151
105.20001,87.66667,24.29855
105.40000,87.83337,24.39395
105.60001,87.99986,24.27228
105.80000,88.16673,24.39801
106.00001,88.33330,24.68158
106.20001,88.49992,24.45221
106.40000,88.66673,24.63023
106.60001,88.83336,24.46495
106.80000,88.99986,24.50449
107.00001,89.16673,24.62430
107.20001,89.33336,24.38684
107.40000,89.49992,24.47235
107.60001,89.66674,24.62601
107.80000,89.83336,24.89639
108.00001,89.99993,24.75620
108.20001,90.16680,24.57270
108.40000,90.33336,24.70867
108.60001,90.49992,24.83019
108.80000,90.66674,24.98288
109.00001,90.83330,24.95147
109.20001,90.99992,24.82799
109.40000,91.16674,24.99385
109.60001,91.33336,24.88875
109.80000,91.49986,24.95406
110.00001,91.66674,25.08641
110.20001,91.83330,25.20240
110.40000,91.99993,25.14521
110.60001,92.16674,25.13683
110.80000,92.33336,25.18157
111.00001,92.49986,25.17819
111.20001,92.66668,25.22538
111.40000,92.83336,25.08916
111.60001,92.99998,25.22278
111.80000,93.16674,25.23435
112.00001,93.33324,25.29574
112.20001,93.49986,25.05995
112.40000,93.66673,25.38997
112.60001,93.83336,25.34352
112.80000,93.99986,25.70999
113.00001,94.16673,25.43010
113.20001,94.33329,25.37296
113.40001,94.49992,25.56651
113.60001,94.66667,25.71244
113.80000,94.83336,25.63271
114.00001,94.99992,25.61899
114.20001,95.16673,25.69783
114.40001,95.33330,25.64825
114.60001,95.49987,25.69896
114.80000,95.66680,25.58876
115.00001,95.83335,25.90104
115.20001,95.99992,26.00844
115.40001,96.16673,25.79814
115.60001,96.33336,25.84380
115.80000,96.49992,25.96552
116.00001,96.66674,26.06768
116.20001,96.83330,26.24002
116.40001,96.99985,26.10688
116.60001,97.16667,26.01746
116.80000,97.33342,26.37648
117.00001,97.49993,26.02843
117.20001,97.66674,26.17695
117.40001,97.83329,26.10512
117.60001,97.99986,26.25776
117.80000,98.16674,26.03436
118.00001,98.33336,26.11756
118.20001,98.49992,26.42891
118.40001,98.66673,26.44538
118.60001,98.83329,26.25290
118.80000,98.99992,26.34664
119.00001,99.16673,26.59679
119.20001,99.33342,26.46801
119.40001,99.49992,26.39789
119.60001,99.66668,26.58243
119.80000,99.83336,26.45611
120.00001,99.99992,26.54999
120.20001,100.16668,26.53358
120.40001,100.33330,26.57895
120.60001,100.49992,26.81150
120.80000,100.66673,26.60203
121.00001,100.83336,26.82189
121.20001,100.99986,26.62863
121.40001,101.16667,26.81057
121.60001,101.33336,26.95424
121.80000,101.49992,27.09462
122.00001,101.66680,26.89951
122.20001,101.83330,26.93532
122.40001,101.99992,26.84267
122.60001,102.16674,27.19694
122.80000,102.33330,27.10325
123.00001,102.49992,27.08071
123.20001,102.66673,26.92386
123.40001,102.83336,27.10496
123.60001,102.99986,27.28847
123.80000,103.16667,27.10320
124.00001,103.33324,27.30454
124.20001,103.49993,27.33173
124.40001,103.66674,27.34055
124.60001,103.83330,27.39200
124.80000,103.99986,27.22918
125.00001,104.16668,27.38999
125.20001,104.33336,27.32532
125.40001,104.49992,27.44336
125.60001,104.66673,27.38421
125.80000,104.83329,27.47584
126.00001,104.99992,27.49833
126.20001,105.16667,27.68674
126.40001,105.33329,27.56791
126.60001,105.49992,27.39009
126.80000,105.66680,27.69477
127.00001,105.83330,27.70688
127.20001,105.99986,27.50059
127.40001,106.16673,27.64680
127.60001,106.33335,27.90728
127.80000,106.49992,28.11397
128.00000,106.66673,27.91611
128.20002,106.83330,27.81820
128.40001,106.99992,28.11691
128.60001,107.16667,27.89959
128.80000,107.33336,27.85451
129.00000,107.49992,28.11568
129.20002,107.66674,27.97740
129.40001,107.83330,28.10887
129.60001,107.99993,28.03518
129.80000,108.16674,28.27488
130.00000,108.33336,28.35838
130.20002,108.49993,28.37763
130.40001,108.66667,28.23407
130.60001,108.83329,28.33187
130.80000,108.99992,28.30756
131.00000,109.16674,28.38739
131.20002,109.33336,28.29341
131.40002,109.49986,28.27346
131.60000,109.66667,28.65105
131.80000,109.83342,28.62391
132.00000,109.99999,28.53375
132.20002,110.16673,28.59745
132.40002,110.33324,28.60970
132.60000,110.49992,28.52067
132.80000,110.66680,28.69878
133.00000,110.83342,28.69437
133.20002,110.99992,28.66384
133.40002,111.16673,28.88910
133.60000,111.33330,28.64238
133.80000,111.49986,28.67306
134.00000,111.66673,28.87910
134.20002,111.83330,28.90556
134.40002,111.99992,28.99449
134.60000,112.16674,28.93785
134.80000,112.33330,28.93481
135.00000,112.49992,29.14355
135.20002,112.66674,28.91134
135.40002,112.83336,29.24581
135.60000,112.99992,29.03414
135.80000,113.16667,29.19848
136.00000,113.33330,29.27928
136.20002,113.49992,29.20064
136.40002,113.66680,29.24248
136.60000,113.83330,29.50341
136.80000,113.99986,29.10450
137.00000,114.16674,29.34852
137.20002,114.33329,29.43613
137.40002,114.49993,29.47288
137.60000,114.66667,29.51546
137.80000,114.83330,29.47474
138.00000,114.99993,29.61018
138.20002,115.16673,29.35705
138.40002,115.33330,29.49978
138.60000,115.49992,29.36910
138.80000,115.66667,29.82651
139.00000,115.83336,29.65648
139.20002,115.99992,29.60062
139.40002,116.16673,29.65193
139.60000,116.33337,29.78937
139.80000,116.49992,29.65486
140.00000,116.66667,29.95710
140.20002,116.83336,29.84763
140.40002,116.99992,29.93093
140.60000,117.16673,29.92373
140.80000,117.33330,29.86645
141.00000,117.49987,30.08391
141.20002,117.66667,29.96116
141.40002,117.83335,30.14888
141.60000,117.99992,30.21533
141.80000,118.16673,30.28897
142.00000,118.33336,29.93598
142.20002,118.49992,30.05627
142.40002,118.66674,30.14011
142.60000,118.83330,30.38026
142.80000,118.99985,30.29029
143.00000,119.16674,30.29137
143.20002,119.33336,30.24428
143.40002,119.49993,30.29632
143.60000,119.66674,30.43009
143.80000,119.83336,30.55303
144.00000,119.99992,30.52486
144.20002,120.16667,30.55171
144.40002,120.33329,30.45665
144.60000,120.49992,30.55181
144.80000,120.66673,30.48904
145.00000,120.83329,30.50212
145.20002,120.99986,30.71360
145.40002,121.16673,30.75829
145.60000,121.33336,30.79651
145.80000,121.49992,30.78044
146.00000,121.66673,30.73502
146.20002,121.83330,30.82106
146.40002,121.99986,30.74736
146.60000,122.16668,30.91411
146.80000,122.33336,30.83517
147.00000,122.49992,30.96767
147.20002,122.66668,30.78382
147.40002,122.83336,31.20091
147.60000,122.99986,31.05337
147.80000,123.16674,31.26348
148.00000,123.33336,31.05714
148.20002,123.49992,31.07008
148.40002,123.66667,31.20689
148.60000,123.83330,31.30827
148.80000,123.99986,31.30013
149.00000,124.16674,31.18562
149.20002,124.33336,31.43479
149.40002,124.49986,31.25486
149.60000,124.66667,31.37187
149.80000,124.83330,31.27681
150.00000,124.99986,31.60918
150.20002,125.16673,31.37309
150.40002,125.33336,31.53925
150.60000,125.49992,31.41866
150.80000,125.66673,31.52568
151.00000,125.83329,31.34007
151.20002,125.99997,31.49540
151.40002,126.16667,31.53768
151.60000,126.33336,31.69527
151.80000,126.49992,31.66503
152.00000,126.66672,31.75466
152.20002,126.83335,31.68846
152.40002,126.99991,31.62383
152.60000,127.16666,31.78293
152.80000,127.33328,31.80998
153.00000,127.49985,31.82923
153.20002,127.66673,31.77705
153.40002,127.83336,31.95982
153.60000,127.99992,31.88617
153.80000,128.16667,31.87819
154.00000,128.33329,32.13504
154.20002,128.49986,32.05321
154.40002,128.66673,32.17018
154.60000,128.83335,31.96619
154.80000,128.99992,32.28229
155.00000,129.16672,32.19193
155.20002,129.33329,32.16611
155.40002,129.49991,32.13651
155.60000,129.66673,32.05914
155.80000,129.83336,32.05360
156.00000,129.99984,32.27190
156.20002,130.16673,32.34888
156.40002,130.33330,32.43311
156.60000,130.49997,32.45281
156.80000,130.66674,32.48397
157.00000,130.83323,32.45158
157.20002,130.99991,32.48828
157.40002,131.16673,32.50117
157.60000,131.33335,32.55742
157.80000,131.49998,32.52146
158.00000,131.66673,32.59696
158.20002,131.83328,32.61750
158.40002,131.99992,32.76283
158.60000,132.16667,32.59731
158.80000,132.33336,32.69874
159.00000,132.49986,32.64293
159.20002,132.66667,32.90821
159.40002,132.83329,32.86117
159.60000,132.99991,32.89669
159.80000,133.16673,32.92350
160.00000,133.33330,33.03096
160.20002,133.49985,32.94045
160.40002,133.66672,33.22612
160.60000,133.83329,32.88312
160.80000,133.99998,32.95319
161.00002,134.16666,32.95981
161.20002,134.33336,33.08476
161.40002,134.49991,33.03316
161.60000,134.66673,33.12371
161.80000,134.83335,33.27429
162.00002,134.99992,33.17315
162.20002,135.16674,33.05820
162.40002,135.33329,33.42428
162.60000,135.49998,33.34480
162.80000,135.66673,33.25341
163.00002,135.83330,33.37969
163.20002,135.99992,33.31222
163.40002,136.16673,33.44280
163.60000,136.33328,33.37180
163.80000,136.49992,33.57632
164.00002,136.66674,33.53943
164.20002,136.83336,33.43050
164.40002,136.99993,33.53874
164.60000,137.16667,33.51169
164.80000,137.33335,33.55868
165.00002,137.49997,33.72881
165.20002,137.66673,33.75939
165.40002,137.83328,33.69975
165.60000,137.99985,33.62885
165.80000,138.16672,33.81618
166.00002,138.33329,33.90835
166.20002,138.49991,33.80074
166.40002,138.66673,33.88473
166.60000,138.83329,33.97317
166.80000,138.99985,33.80260
167.00002,139.16667,34.11219
167.20002,139.33335,33.75743
167.40002,139.49992,33.94485
167.60000,139.66672,34.04785
167.80000,139.83329,34.10483
168.00002,139.99991,34.07637
168.20002,140.16673,34.15908
168.40002,140.33335,34.16261
168.60000,140.49992,34.07068
168.80000,140.66673,34.43446
169.00002,140.83329,34.12233
169.20002,140.99992,34.44063
169.40002,141.16674,34.31612
169.60000,141.33330,34.30990
169.80000,141.49985,34.32039
170.00002,141.66667,34.41863
170.20002,141.83329,34.38115
170.40002,141.99992,34.56240
170.60000,142.16674,34.36581
170.80000,142.33328,34.66378
171.00002,142.49991,34.39487
171.20002,142.66667,34.54397
171.40002,142.83329,34.45180
171.60000,142.99992,34.53839
171.80000,143.16680,34.64859
172.00002,143.33329,34.67221
172.20002,143.49991,34.54520
172.40002,143.66673,34.61326
172.60000,143.83336,34.46381
172.80000,143.99998,34.55215
173.00002,144.16672,34.69097
173.20002,144.33323,34.62982
173.40002,144.49986,34.77256
173.60000,144.66673,34.77711
173.80000,144.83335,34.73826
174.00002,144.99992,34.78535
174.20002,145.16667,34.72855
174.40002,145.33335,34.81587
174.60000,145.49992,34.66236
174.80000,145.66674,34.79201
175.00002,145.83336,34.86963
175.20002,145.99998,35.01844
175.40002,146.16673,35.12100
175.60000,146.33330,34.95621
175.80000,146.49992,35.00320
176.00002,146.66679,35.27681
176.20002,146.83329,34.87408
176.40002,146.99985,35.03858
176.60000,147.16667,34.90422
176.80000,147.33336,34.91857
177.00002,147.49992,34.91912
177.20002,147.66666,35.07719
177.40002,147.83323,35.21390
177.60000,147.99992,34.82053
177.80000,148.16673,35.11658
178.00002,148.33330,34.92137
178.20002,148.49998,34.95454
178.40002,148.66672,34.92382
178.60000,148.83324,34.82229
178.80000,148.99986,34.77035
179.00002,149.16673,34.98326
179.20002,149.33336,34.99183
179.40002,149.49991,34.85444
179.60000,149.66667,34.69470
179.80000,149.83336,34.75565
180.00002,149.99986,34.64712
180.20002,150.16680,34.60081
180.40002,150.33329,34.71082
180.60000,150.49986,34.08592
180.80000,150.66673,-0.08437
181.00002,150.83330,0.31954
181.20002,150.99992,0.26544
181.40002,151.16672,-0.01944
181.60000,151.33329,0.12251
181.80000,151.49985,0.12736
182.00002,151.66673,-0.01513
182.20002,151.83336,0.25618
182.40002,151.99992,0.08512
182.52802,152.10680,0.00153