File: FR/FR/RDSO FR Tensile 50.is_tens_RawData/Specimen_RawData_6.csv
Time,Extension,Load
(sec),(mm),(N)
0.00000,0.00000,0.32508
0.10000,0.07594,0.41136
0.20000,0.16462,0.97119
0.30000,0.24925,1.22383
0.40000,0.33306,1.37201
0.50000,0.41669,1.83089
0.60000,0.49987,2.02336
0.70000,0.58331,2.58598
0.80000,0.66669,2.70221
0.90000,0.74994,2.90546
1.00000,0.83337,3.13125
1.10000,0.91675,3.43343
1.20000,0.99994,3.51575
1.30000,1.08331,3.76144
1.40000,1.16681,4.04260
1.50000,1.24987,4.00482
1.60000,1.33331,3.96723
1.70000,1.41669,4.59992
1.80000,1.49994,4.54651
1.90000,1.58331,4.89539
2.00000,1.66669,5.03734
2.10000,1.74994,4.97727
2.20000,1.83344,5.31747
2.30000,1.91675,5.34604
2.40000,1.99994,5.66170
2.50000,2.08337,5.64670
2.60000,2.16662,6.04816
2.70000,2.24987,5.89886
2.80000,2.33331,6.26797
2.90000,2.41675,6.18516
3.00000,2.49994,6.33344
3.10000,2.58337,6.46696
3.20000,2.66675,6.76831
3.30000,2.74994,6.93520
3.40000,2.83331,6.77649
3.50000,2.91675,7.03271
3.60000,2.99994,7.21735
3.70000,3.08331,6.99871
3.80000,3.16675,7.22661
3.90000,3.24987,7.52962
4.00000,3.33337,7.45955
4.10000,3.41669,7.67701
4.20000,3.49994,7.81485
4.30000,3.58337,8.13114
4.40000,3.66681,8.15863
4.50000,3.74994,8.10341
4.60000,3.83337,8.23561
4.70000,3.91675,8.38526
4.80000,3.99994,8.53652
4.90000,4.08331,8.60492
5.00000,4.16675,8.58327
5.10000,4.24994,8.88432
5.20000,4.33337,8.78612
5.30000,4.41675,9.08934
5.40000,4.49994,9.13922
5.50000,4.58337,9.18822
5.60000,4.66669,9.17783
5.70000,4.75000,9.17087
5.80000,4.83331,9.42430
5.90000,4.91675,9.66430
6.00000,4.99987,9.63813
6.10000,5.08331,9.50554
6.20000,5.16669,9.68081
6.30000,5.24994,9.70536
6.40000,5.33337,9.73780
6.50000,5.41675,9.92233
6.60000,5.50000,9.76597
6.70000,5.58337,9.92086
6.80000,5.66675,10.22819
6.90000,5.74994,10.12725
7.00000,5.83331,10.20100
7.10000,5.91669,10.43115
7.20000,5.99994,10.46118
7.30000,6.08331,10.52846
7.40000,6.16675,10.64415
7.50000,6.24994,10.60167
7.60000,6.33337,10.77199
7.70000,6.41669,10.70285
7.80000,6.49994,10.81232
7.90000,6.58337,10.78483
8.00000,6.66675,11.07829
8.10000,6.74994,10.82016
8.20000,6.83331,11.33598
8.30000,6.91669,11.10901
8.40000,6.99987,11.13973
8.50000,7.08337,11.47754
8.60000,7.16675,11.32882
8.70000,7.24994,11.48690
8.80000,7.33337,11.33289
8.90000,7.41675,11.39218
9.00000,7.49994,11.62233
9.10000,7.58331,11.62243
9.20000,7.66669,11.63748
9.30000,7.74994,11.54908
9.40000,7.83325,11.73778
9.50000,7.91675,11.88409
9.60000,7.99994,11.70181
9.70000,8.08344,11.78320
9.80000,8.16681,11.95034
9.90000,8.25000,11.86346
10.00000,8.33337,12.13007
10.10000,8.41675,12.15158
10.20000,8.49981,12.05299
10.30000,8.58325,12.13727
10.40000,8.66669,12.36150
10.50000,8.74987,12.42720
10.60000,8.83331,12.23380
10.70000,8.91675,12.46631
10.80000,8.99987,12.45773
10.90000,9.08337,12.20470
11.00000,9.16675,12.50913
11.10000,9.24994,12.52839
11.20000,9.33337,12.58748
11.30000,9.41669,12.61095
11.40000,9.49994,12.70797
11.50000,9.58325,12.65814
11.60000,9.66669,12.94072
11.70000,9.74987,12.75531
11.80000,9.83337,12.85698
11.90000,9.91675,13.06631
12.00000,10.00000,12.86629
12.10000,10.08337,12.91382
12.20000,10.16675,13.15892
12.30000,10.24994,13.07150
12.40000,10.33337,13.05734
12.50000,10.41669,13.08552
12.60000,10.49994,13.06763
12.70000,10.58331,13.25075
12.80000,10.66662,13.14549
12.90000,10.74987,13.38741
13.00000,10.83337,13.28622
13.10000,10.91675,13.48849
13.20000,10.99994,13.36296
13.30000,11.08337,13.30533
13.40000,11.16669,13.31543
13.50000,11.24987,13.45850
13.60000,11.33331,13.44018
13.70000,11.41669,13.49477
13.80000,11.49987,13.38452
13.90000,11.58337,13.58934
14.00000,11.66675,13.37251
14.10000,11.74994,13.53215
14.20000,11.83337,13.84982
14.30000,11.91675,13.80763
14.40000,11.99987,13.66318
14.50000,12.08331,13.82723
14.60000,12.16669,14.01754
14.70000,12.24987,13.71595
14.80000,12.33337,13.95218
14.90000,12.41675,13.75731
15.00000,12.49994,13.93939
15.10000,12.58337,13.78367
15.20000,12.66675,13.87260
15.30000,12.74994,13.78435
15.40000,12.83331,13.81116
15.50000,12.91669,14.12804
15.60000,12.99994,14.11074
15.70000,13.08331,14.14818
15.80000,13.16675,14.21982
15.90000,13.24987,14.19615
16.00000,13.33331,13.97565
16.10000,13.41669,14.21487
16.20000,13.49994,14.38137
16.30000,13.58337,14.22815
16.40000,13.66675,14.40048
16.50000,13.74987,14.22060
16.60000,13.83331,14.45144
16.70000,13.91675,14.46055
16.80000,13.99987,14.60314
16.90000,14.08331,14.31487
17.00000,14.16675,14.51597
17.10000,14.24994,14.53371
17.20000,14.33337,14.59094
17.30000,14.41675,14.49848
17.40000,14.50000,14.59609
17.50000,14.58331,14.47158
17.60000,14.66675,14.67605
17.70000,14.74994,14.82839
17.80000,14.83331,14.86970
17.90000,14.91669,14.74857
18.00000,14.99994,14.89655
18.10000,15.08331,14.78513
18.20000,15.16675,14.70918
18.30000,15.24994,14.98612
18.40000,15.33331,14.89596
18.50000,15.41675,14.81830
18.60000,15.49994,14.87156
18.70000,15.58331,14.93115
18.80000,15.66675,14.87857
18.90000,15.74987,14.83594
19.00000,15.83337,14.99563
19.10000,15.91668,14.83437
19.20000,15.99994,14.90660
19.30000,16.08337,15.02449
19.40000,16.16675,14.96251
19.50000,16.25000,14.96143
19.60000,16.33337,14.98490
19.70000,16.41668,15.13734
19.80000,16.49987,15.16145
19.90000,16.58331,15.09809
20.00000,16.66675,15.30399
20.10000,16.74994,15.19599
20.20000,16.83337,15.17272
20.30000,16.91675,15.34804
20.40000,16.99987,15.25699
20.50000,17.08331,15.18639
20.60000,17.16675,15.30208
20.70000,17.24993,15.31619
20.80000,17.33337,15.17492
20.90000,17.41681,15.43888
21.00000,17.49987,15.16125
21.10000,17.58337,15.37856
21.20000,17.66675,15.30967
21.30000,17.74987,15.55834
21.40000,17.83337,15.48881
21.50000,17.91675,15.56040
21.60000,17.99993,15.61925
21.70000,18.08331,15.37533
21.80000,18.16675,15.49602
21.90000,18.24987,15.46681
22.00000,18.33331,15.45701
22.10000,18.41668,15.83456
22.20000,18.49987,15.49004
22.30000,18.58331,15.68422
22.40000,18.66681,15.80525
22.50000,18.74994,15.79908
22.60000,18.83337,15.82142
22.70000,18.91675,15.76111
22.80000,18.99987,15.85391
22.90000,19.08331,15.59456
23.00000,19.16662,15.71696
23.10000,19.24987,15.98817
23.20000,19.33331,15.85425
23.30000,19.41675,16.00072
23.40000,19.49994,16.07103
23.50000,19.58337,15.86082
23.60000,19.66675,16.01590
23.70000,19.74987,15.88733
23.80000,19.83337,16.19961
23.90000,19.91675,16.01463
24.00000,19.99993,16.00468
24.10000,20.08331,15.73097
24.20000,20.16675,15.96578
24.30000,20.24987,15.94907
24.40000,20.33331,15.98567
24.50000,20.41668,16.16041
24.60000,20.49993,16.12238
24.70000,20.58337,16.19725
24.80000,20.66675,16.09470
24.90000,20.74993,16.20176
25.00000,20.83337,16.40932
25.10000,20.91669,16.04506
25.20000,20.99993,16.29378
25.30000,21.08337,16.20965
25.40000,21.16675,16.11983
25.50000,21.24987,16.33465
25.60000,21.33331,16.31314
25.70000,21.41675,16.24753
25.80000,21.50000,16.25909
25.90000,21.58331,16.20828
26.00000,21.66675,16.34636
26.10000,21.74993,16.32284
26.20000,21.83337,16.52874
26.30000,21.91668,16.40325
26.40000,21.99987,16.41040
26.50000,22.08331,16.38948
26.60000,22.16668,16.34425
26.70000,22.24987,16.44206
26.80000,22.33331,16.60322
26.90000,22.41681,16.58401
27.00000,22.49993,16.59087
27.10000,22.58331,16.42010
27.20000,22.66675,16.50365
27.30000,22.74993,16.62296
27.40000,22.83325,16.62894
27.50000,22.91668,16.63232
27.60000,22.99987,16.68279
27.70000,23.08337,16.51531
27.80000,23.16675,16.48062
27.90000,23.24993,16.76198
28.00000,23.33331,16.67015
28.10000,23.41675,16.83087
28.20000,23.49993,16.74752
28.30000,23.58337,16.96386
28.40000,23.66675,16.85895
28.50000,23.74987,16.95092
28.60000,23.83331,16.95753
28.70000,23.91668,16.75884
28.80000,23.99993,16.86733
28.90000,24.08331,17.03231
29.00000,24.16675,17.08665
29.10000,24.25000,17.00198
29.20000,24.33343,17.01046
29.30000,24.41668,16.95357
29.40000,24.49993,16.95651
29.50000,24.58331,16.76864
29.60000,24.66668,16.85753
29.70000,24.74987,16.92113
29.80000,24.83331,16.99247
29.90000,24.91675,17.13879
30.00000,24.99999,17.11453
30.10000,25.08337,17.06881
30.20000,25.16675,17.23257
30.30000,25.24993,17.18720
30.40000,25.33331,17.03775
30.50000,25.41675,16.94381
30.60000,25.49981,17.12482
30.70000,25.58331,17.14163
30.80000,25.66668,17.32312
30.90000,25.74987,17.18788
31.00000,25.83344,17.21405
31.10000,25.91675,17.48017
31.20000,25.99993,17.33096
31.30000,26.08337,17.52510
31.40000,26.16675,17.36884
31.50000,26.25000,17.28236
31.60000,26.33331,17.23992
31.70000,26.41669,17.30911
31.80000,26.49987,17.45366
31.90000,26.58331,17.24409
32.00000,26.66668,17.22934
32.10000,26.74993,17.42225
32.20000,26.83337,17.51780
32.30000,26.91675,17.55156
32.40000,26.99994,17.51251
32.50000,27.08337,17.39025
32.60000,27.16674,17.28559
32.70000,27.24993,17.34988
32.80000,27.33337,17.41235
32.90000,27.41675,17.60041
33.00000,27.49993,17.54916
33.10000,27.58325,17.39393
33.20000,27.66668,17.59747
33.30000,27.74993,17.41652
33.40000,27.83337,17.77966
33.50000,27.91675,17.75795
33.60000,28.00000,17.54651
33.70000,28.08337,17.78936
33.80000,28.16675,17.57057
33.90000,28.24987,17.64638
34.00000,28.33331,17.75839
34.10000,28.41668,17.75035
34.20000,28.49987,17.70356
34.30000,28.58337,17.82346
34.40000,28.66675,17.87119
34.50000,28.74993,18.15539
34.60000,28.83331,17.68048
34.70000,28.91668,17.68891
34.80000,28.99987,17.87231
34.90000,29.08331,17.94959
35.00000,29.16669,17.62197
35.10000,29.24987,18.00500
35.20000,29.33337,18.13373
35.30000,29.41675,17.84301
35.40000,29.49993,17.81528
35.50000,29.58337,17.83468
35.60000,29.66675,17.98614
35.70000,29.74994,18.09193
35.80000,29.83337,17.98825
35.90000,29.91674,17.95106
36.00000,29.99993,18.10472
36.10000,30.08331,18.01177
36.20000,30.16668,17.94483
36.30000,30.24987,18.13740
36.40000,30.33331,18.05645
36.50000,30.41675,17.91146
36.60000,30.49993,18.35594
36.70000,30.58337,18.21384
36.80000,30.66675,18.42827
36.90000,30.74993,18.17205
37.00000,30.83331,18.37500
37.10000,30.91668,18.38637
37.20000,30.99993,18.32081
37.30000,31.08331,18.06969
37.40000,31.16675,18.19164
37.50000,31.24993,18.30753
37.60000,31.33337,18.58002
37.70000,31.41674,18.39343
37.80000,31.49993,18.42675
37.90000,31.58331,18.35996
38.00000,31.66674,18.49157
38.10000,31.74993,18.43679
38.20000,31.83331,18.21531
38.30000,31.91675,18.53219
38.40000,31.99993,18.37304
38.50000,32.08331,18.42376
38.60000,32.16675,18.49050
38.70000,32.24993,18.71580
38.80000,32.33337,18.32453
38.90000,32.41675,18.52254
39.00000,32.49993,18.43782
39.10000,32.58331,18.69718
39.20000,32.66668,18.63754
39.30000,32.74993,18.58286
39.40000,32.83331,18.59844
39.50000,32.91674,18.45997
39.60000,32.99993,18.66087
39.70000,33.08337,18.65994
39.80000,33.16674,18.76161
39.90000,33.24993,18.55072
40.00000,33.33337,18.51735
40.10000,33.41668,18.91831
40.20000,33.49993,18.72231
40.30000,33.58337,18.48236
40.40000,33.66675,19.00553
40.50000,33.74993,18.70521
40.60000,33.83337,18.84202
40.70000,33.91668,18.70884
40.80000,33.99981,18.74333
40.90000,34.08331,18.99480
41.00000,34.16675,19.00764
41.10000,34.24993,18.94953
41.20000,34.33337,18.97153
41.30000,34.41668,19.04758
41.40000,34.49987,19.05478
41.50000,34.58331,18.78724
41.60000,34.66674,18.75333
41.70000,34.74993,18.94193
41.80000,34.83337,18.96178
41.90000,34.91681,19.00642
42.00000,34.99993,18.87069
42.10000,35.08337,19.09050
42.20000,35.16668,19.12147
42.30000,35.24987,19.07158
42.40000,35.33331,19.16851
42.50000,35.41674,19.14361
42.60000,35.49987,19.21937
42.70000,35.58331,19.06198
42.80000,35.66681,19.09285
42.90000,35.75000,19.17086
43.00000,35.83337,19.11779
43.10000,35.91675,19.08996
43.20000,35.99993,19.15567
43.30000,36.08324,19.32967
43.40000,36.16675,19.26092
43.50000,36.24993,19.13048
43.60000,36.33331,19.30022
43.70000,36.41674,19.25136
43.80000,36.49993,19.24617
43.90000,36.58331,19.22094
44.00000,36.66674,19.52194
44.10000,36.74993,19.33883
44.20000,36.83337,19.51778
44.30000,36.91674,19.31781
44.40000,36.99993,19.30860
44.50000,37.08331,19.59030
44.60000,37.16668,19.57231
44.70000,37.24987,19.72524
44.80000,37.33337,19.43869
44.90000,37.41675,19.58956
45.00000,37.49993,19.46059
45.10000,37.58337,19.50112
45.20000,37.66675,19.41929
45.30000,37.74993,19.48470
45.40000,37.83331,19.54977
45.50000,37.91675,19.53537
45.60000,37.99993,19.48970
45.70000,38.08331,19.62058
45.80000,38.16674,19.67722
45.90000,38.24987,19.64787
46.00000,38.33331,19.73328
46.10000,38.41674,19.86646
46.20000,38.49993,19.65655
46.30000,38.58343,19.71373
46.40000,38.66674,19.83623
46.50000,38.74987,19.76846
46.60000,38.83331,19.96960
46.70000,38.91675,19.87479
46.80000,38.99987,19.80722
46.90000,39.08331,19.98847
47.00000,39.16668,19.65596
47.10000,39.24993,19.86768
47.20000,39.33343,19.87450
47.30000,39.41674,19.70481
47.40000,39.49993,19.72338
47.50000,39.58330,19.83417
47.60000,39.66675,19.94643
47.70000,39.74987,19.92163
47.80000,39.83330,19.97509
47.90000,39.91674,19.92825
48.00000,39.99987,20.17148
48.10000,40.08331,19.97823
48.20000,40.16681,20.18883
48.30000,40.24993,20.17746
48.40000,40.33331,20.14120
48.50000,40.41674,20.11474
48.60000,40.49999,20.20015
48.70000,40.58337,20.07148
48.80000,40.66675,20.12626
48.90000,40.74987,20.27228
49.00000,40.83330,20.22705
49.10000,40.91674,20.20544
49.20000,40.99993,20.25361
49.30000,41.08337,20.32373
49.40000,41.16681,20.20329
49.50000,41.24993,20.23940
49.60000,41.33331,20.24116
49.70000,41.41668,20.38076
49.80000,41.49993,20.20662
49.90000,41.58324,20.34764
50.00000,41.66674,20.21774
50.10000,41.74993,20.47068
50.20000,41.83331,20.36224
50.30000,41.91674,20.30099
50.40000,41.99993,20.53403
50.50000,42.08343,20.34681
50.60000,42.16674,20.55295
50.70000,42.24993,20.35675
50.80000,42.33337,20.47651
50.90000,42.41674,20.54623
51.00000,42.49993,20.51507
51.10000,42.58330,20.59029
51.20000,42.66668,20.51164
51.30000,42.74987,20.45916
51.40000,42.83337,20.32931
51.50000,42.91675,20.44515
51.60000,42.99993,20.56353
51.70000,43.08337,20.83974
51.80000,43.16675,20.59690
51.90000,43.24993,20.88732
52.00000,43.33337,20.81221
52.10000,43.41675,20.67496
52.20000,43.49981,20.79084
52.30000,43.58331,20.83867
52.40000,43.66674,20.75184
52.50000,43.74993,20.82994
52.60000,43.83331,20.57127
52.70000,43.91674,20.90340
52.80000,43.99993,20.85356
52.90000,44.08337,20.69568
53.00000,44.16674,20.99194
53.10000,44.24993,20.76615
53.20000,44.33337,21.02570
53.30000,44.41674,20.75463
53.40000,44.49987,21.01365
53.50000,44.58318,20.83837
53.60000,44.66674,21.00233
53.70000,44.74993,21.11860
53.80000,44.83337,21.00051
53.90000,44.91681,20.96979
54.00000,44.99999,20.92442
54.10000,45.08330,21.10121
54.20000,45.16668,20.96254
54.30000,45.24987,21.19127
54.40000,45.33337,21.18309
54.50000,45.41674,20.79324
54.60000,45.49993,21.15653
54.70000,45.58337,20.98228
54.80000,45.66681,21.08229
54.90000,45.74987,21.09131
55.00000,45.83331,21.37326
55.10000,45.91668,21.36125
55.20000,45.99987,21.20783
55.30000,46.08330,21.27790
55.40000,46.16668,21.22444
55.50000,46.24993,21.24394
55.60000,46.33330,21.36796
55.70000,46.41674,21.37575
55.80000,46.49993,21.36590
55.90000,46.58337,21.39290
56.00000,46.66674,21.43637
56.10000,46.74993,21.50036
56.20000,46.83331,21.17515
56.30000,46.91680,21.52207
56.40000,46.99986,21.52824
56.50000,47.08331,21.48277
56.60000,47.16674,21.63482
56.70000,47.24993,21.65941
56.80000,47.33337,21.34753
56.90000,47.41680,21.49997
57.00000,47.49993,21.49477
57.10000,47.58331,21.36360
57.20000,47.66668,21.51129
57.30000,47.74987,21.68342
57.40000,47.83330,21.76672
57.50000,47.91668,21.58400
57.60000,47.99987,21.71615
57.70000,48.08336,21.80298
57.80000,48.16674,21.59689
57.90000,48.24993,21.67269
58.00000,48.33330,21.76521
58.10000,48.41674,21.85272
58.20000,48.49993,21.93087
58.30000,48.58330,21.76280
58.40000,48.66675,22.01554
58.50000,48.74987,21.81450
58.60000,48.83330,21.92803
58.70000,48.91668,21.92146
58.80000,48.99987,22.00467
58.90000,49.08337,21.89745
59.00000,49.16674,21.86967
59.10000,49.24993,21.86918
59.20000,49.33331,21.89579
59.30000,49.41674,21.96032
59.40000,49.49987,22.05538
59.50000,49.58331,21.93347
59.60000,49.66668,21.95694
59.70000,49.74993,21.95498
59.80000,49.83330,21.86276
59.90000,49.91674,22.07057
60.00000,49.99993,22.10521
60.10000,50.08331,22.31307
60.20000,50.16674,22.38843
60.30000,50.24993,22.19704
60.40000,50.33331,22.20660
60.50000,50.41674,22.31983
60.60000,50.49993,22.15333
60.70000,50.58337,22.26245
60.80000,50.66680,22.46659
60.90000,50.74987,22.29617
61.00000,50.83337,22.29342
61.10000,50.91668,22.39294
61.20000,50.99987,22.46237
61.30000,51.08330,22.28700
61.40000,51.16674,22.42832
61.50000,51.24993,22.46639
61.60000,51.33336,22.35080
61.70000,51.41668,22.46967
61.80000,51.49987,22.39451
61.90000,51.58330,22.43371
62.00000,51.66674,22.49089
62.10000,51.74993,22.55317
62.20000,51.83343,22.41729
62.30000,51.91674,22.48266
62.40000,51.99993,22.56395
62.50000,52.08330,22.76730
62.60000,52.16668,22.85222
62.70000,52.24993,22.76622
62.80000,52.33331,22.82311
62.90000,52.41674,22.73971
63.00000,52.49986,22.69057
63.10000,52.58337,22.63196
63.20000,52.66674,22.53318
63.30000,52.74999,22.79337
63.40000,52.83337,22.67739
63.50000,52.91674,22.79204
63.60000,52.99993,22.93076
63.70000,53.08324,22.82732
63.80000,53.16674,22.70233
63.90000,53.24987,22.84168
64.00000,53.33330,22.95693
64.10001,53.41674,22.89063
64.20000,53.49993,22.90274
64.30000,53.58336,23.11339
64.40000,53.66674,23.16121
64.50000,53.74993,23.03753
64.60001,53.83337,23.21927
64.70000,53.91668,23.03852
64.80000,53.99987,22.96609
64.90000,54.08330,23.06267
65.00000,54.16675,22.98638
65.10001,54.24987,23.12916
65.20000,54.33330,23.17473
65.30000,54.41674,23.19350
65.40000,54.49993,23.09746
65.50000,54.58337,23.30468
65.60001,54.66668,23.04430
65.70001,54.74993,23.23025
65.80000,54.83337,23.30664
65.90000,54.91674,23.05674
66.00000,54.99993,23.17405
66.10001,55.08331,23.37911
66.20001,55.16674,23.33609
66.30000,55.24987,23.42066
66.40000,55.33330,23.20080
66.50000,55.41680,23.35255
66.60001,55.49993,23.38014
66.70001,55.58337,23.42331
66.80000,55.66674,23.57918
66.90000,55.74987,23.54135
67.00000,55.83331,23.37666
67.10001,55.91668,23.40739
67.20001,55.99987,23.61049
67.30000,56.08337,23.46957
67.40000,56.16674,23.49632
67.50000,56.24993,23.44879
67.60001,56.33337,23.42012
67.70001,56.41674,23.62372
67.80000,56.49993,23.52381
67.90000,56.58330,23.50298
68.00000,56.66674,23.46780
68.10001,56.74993,23.62137
68.20001,56.83331,23.70976
68.30000,56.91674,23.64023
68.40000,56.99987,23.79458
68.50000,57.08330,23.93619
68.60001,57.16674,23.89415
68.70001,57.24987,23.89635
68.80000,57.33337,23.72559
68.90000,57.41674,23.97760
69.00000,57.49993,23.94839
69.10001,57.58330,23.64528
69.20001,57.66674,23.90488
69.30000,57.74986,23.77812
69.40000,57.83324,23.90390
69.50000,57.91674,24.13694
69.60001,57.99993,24.18011
69.70001,58.08337,24.16360
69.80000,58.16680,24.11847
69.90000,58.24993,24.03223
70.00000,58.33331,24.03365
70.10001,58.41674,24.19584
70.20001,58.49987,24.03738
70.30000,58.58331,24.32314
70.40000,58.66674,24.17575
70.50000,58.74987,24.30060
70.60001,58.83330,24.10945
70.70001,58.91674,24.46598
70.80000,58.99993,24.43089
70.90000,59.08336,24.38312
71.00000,59.16681,24.33681
71.10001,59.24999,24.44471
71.20001,59.33330,24.45608
71.30000,59.41662,24.51013
71.40000,59.49981,24.40272
71.50000,59.58330,24.45162
71.60001,59.66668,24.44393
71.70001,59.74993,24.50067
71.80000,59.83337,24.74111
71.90000,59.91681,24.35377
72.00000,59.99999,24.55668
72.10001,60.08337,24.58240
72.20001,60.16674,24.60308
72.30000,60.24993,24.45368
72.40000,60.33331,24.63228
72.50000,60.41668,24.36690
72.60001,60.49987,24.70995
72.70001,60.58331,24.62199
72.80000,60.66674,24.67119
72.90000,60.74993,24.73582
73.00000,60.83337,24.47627
73.10001,60.91668,24.72724
73.20001,60.99987,24.73263
73.30000,61.08337,24.66462
73.40000,61.16681,24.55643
73.50000,61.24993,24.69863
73.60001,61.33337,24.77605
73.70001,61.41668,24.45285
73.80000,61.49987,24.88894
73.90000,61.58337,25.00493
74.00000,61.66674,24.88056
74.10001,61.74993,24.94309
74.20001,61.83337,25.03702
74.30000,61.91680,24.98837
74.40000,61.99993,25.00272
74.50000,62.08330,25.05339
74.60001,62.16668,24.96916
74.70001,62.24987,25.09220
74.80000,62.33331,25.10621
74.90000,62.41681,25.18799
75.00000,62.49993,24.97847
75.10001,62.58330,25.18799
75.20001,62.66674,25.12973
75.30000,62.74993,25.12449
75.40000,62.83330,25.22871
75.50000,62.91674,25.07029
75.60001,62.99987,25.30789
75.70001,63.08330,25.25811
75.80000,63.16674,25.24713
75.90000,63.24986,25.38379
76.00000,63.33330,25.28001
76.10001,63.41674,25.27575
76.20001,63.49993,25.31990
76.30000,63.58337,25.41030
76.40000,63.66674,25.36150
76.50000,63.74992,25.38272
76.60001,63.83331,25.31294
76.70001,63.91668,25.61747
76.80000,63.99993,25.59229
76.90000,64.08330,25.45269
77.00000,64.16667,25.55108
77.10001,64.24993,25.42466
77.20001,64.33337,25.43735
77.30000,64.41674,25.72263
77.40000,64.49993,25.62634
77.50000,64.58330,25.55740
77.60001,64.66674,25.63320
77.70001,64.74993,25.60081
77.80000,64.83330,25.63051
77.90000,64.91674,25.69886
78.00000,64.99992,25.67853
78.10001,65.08330,25.58009
78.20001,65.16674,25.64516
78.30000,65.24993,25.82964
78.40000,65.33337,25.72532
78.50000,65.41674,25.98434
78.60001,65.49993,25.93798
78.70001,65.58336,25.84777
78.80000,65.66674,25.78603
78.90000,65.74986,25.92480
79.00000,65.83330,25.95533
79.10001,65.91674,26.06950
79.20001,65.99993,25.95587
79.30000,66.08337,25.97405
79.40000,66.16674,26.10139
79.50000,66.24993,25.89427
79.60001,66.33336,26.15284
79.70001,66.41674,26.02907
79.80000,66.49987,26.25932
79.90000,66.58330,26.13775
80.00000,66.66668,26.14976
80.10001,66.74986,26.18435
80.20001,66.83336,26.12864
80.30000,66.91680,25.98806
80.40000,66.99986,26.29553
80.50001,67.08330,26.10924
80.60001,67.16674,26.26824
80.70001,67.24992,26.29171
80.80000,67.33330,26.33209
80.90000,67.41674,26.38378
81.00001,67.49993,26.20978
81.10001,67.58337,26.39995
81.20001,67.66674,26.23345
81.30000,67.74987,26.37516
81.40000,67.83330,26.39932
81.50001,67.91674,26.41553
81.60001,67.99986,26.46120
81.70001,68.08336,26.55151
81.80000,68.16674,26.47159
81.90000,68.24993,26.50643
82.00001,68.33330,26.48252
82.10001,68.41668,26.46390
82.20001,68.49993,26.61888
82.30000,68.58336,26.42470
82.40000,68.66674,26.52804
82.50001,68.74999,26.55906
82.60001,68.83337,26.72570
82.70001,68.91668,26.61060
82.80000,68.99992,26.74182
82.90000,69.08331,26.76432
83.00001,69.16674,26.82287
83.10001,69.24986,26.78828
83.20001,69.33337,26.83517
83.30000,69.41674,26.93714
83.40000,69.49992,26.63329
83.50001,69.58331,26.84600
83.60001,69.66680,26.73281
83.70001,69.74993,26.94797
83.80000,69.83336,26.95419
83.90000,69.91674,27.02509
84.00001,69.99987,26.90142
84.10001,70.08330,26.99457
84.20001,70.16668,27.12069
84.30000,70.24986,27.10854
84.40000,70.33330,26.98090
84.50001,70.41674,27.05150
84.60001,70.49993,27.26789
84.70001,70.58337,27.21521
84.80000,70.66674,27.15009
84.90000,70.74993,27.32708
85.00001,70.83336,27.15656
85.10001,70.91668,27.15009
85.20001,70.99993,27.28068
85.30000,71.08337,27.15876
85.40000,71.16674,27.15622
85.50001,71.24986,27.17851
85.60001,71.33331,27.25872
85.70001,71.41668,27.51529
85.80000,71.49986,27.21698
85.90000,71.58336,27.35109
86.00001,71.66680,27.33752
86.10001,71.74992,27.50784
86.20001,71.83337,27.37951
86.30000,71.91674,27.59555
86.40000,71.99986,27.37804
86.50001,72.08330,27.51445
86.60001,72.16674,27.50171
86.70001,72.24993,27.70217
86.80000,72.33337,27.69962
86.90000,72.41674,27.74671
87.00001,72.49999,27.60251
87.10001,72.58330,27.67071
87.20001,72.66674,27.81879
87.30000,72.74993,27.93370
87.40000,72.83330,27.80791
87.50001,72.91674,27.75529
87.60001,72.99987,27.73348
87.70001,73.08330,27.77503
87.80000,73.16674,27.64371
87.90000,73.24993,27.77019
88.00001,73.33330,27.81546
88.10001,73.41674,27.52965
88.20001,73.49993,27.78273
88.30000,73.58336,28.01136
88.40000,73.66674,27.97476
88.50001,73.74987,28.06864
88.60001,73.83330,27.86216
88.70001,73.91674,28.10005
88.80000,73.99987,28.16253
88.90000,74.08337,28.05811
89.00001,74.16674,28.21628
89.10001,74.24993,28.25783
89.20001,74.33336,28.06702
89.30000,74.41674,28.28311
89.40000,74.49986,28.35500
89.50001,74.58330,28.26685
89.60001,74.66668,28.30267
89.70001,74.74980,28.22593
89.80000,74.83337,28.37866
89.90000,74.91674,28.31560
90.00001,74.99993,28.09148
90.10001,75.08336,28.36019
90.20001,75.16674,28.14954
90.30000,75.24987,28.31408
90.40000,75.33330,28.27400
90.50001,75.41674,28.54370
90.60001,75.49993,28.64581
90.70001,75.58330,28.46241
90.80000,75.66674,28.36989
90.90000,75.74987,28.37744
91.00001,75.83330,28.55242
91.10001,75.91674,28.56344
91.20001,75.99999,28.65017
91.30000,76.08343,28.62464
91.40000,76.16674,28.51057
91.50001,76.24993,28.66002
91.60001,76.33330,28.48308
91.70001,76.41668,28.70035
91.80000,76.49980,28.66541
91.90000,76.58330,28.59931
92.00001,76.66667,28.83319
92.10001,76.74999,28.74479
92.20001,76.83337,28.79727
92.30000,76.91680,28.74371
92.40000,76.99999,28.66051
92.50001,77.08337,28.76772
92.60001,77.16674,28.84235
92.70001,77.24993,28.92697
92.80000,77.33330,28.97886
92.90000,77.41674,28.87905
93.00001,77.49987,28.82211
93.10001,77.58330,28.99352
93.20001,77.66674,29.06932
93.30000,77.74992,29.07226
93.40000,77.83336,29.01728
93.50001,77.91674,29.08529
93.60001,77.99993,29.19363
93.70001,78.08330,29.07868
93.80000,78.16673,29.10597
93.90000,78.24986,29.13218
94.00001,78.33330,29.27374
94.10001,78.41667,29.17183
94.20001,78.49980,29.19402
94.30000,78.58337,29.31216
94.40000,78.66680,29.28477
94.50001,78.74993,29.24528
94.60001,78.83336,29.27899
94.70001,78.91674,29.55618
94.80000,78.99993,29.34715
94.90000,79.08330,29.42844
95.00001,79.16667,29.44784
95.10001,79.24986,29.53981
95.20001,79.33336,29.47185
95.30000,79.41674,29.36170
95.40000,79.49986,29.66329
95.50001,79.58336,29.51007
95.60001,79.66674,29.29295
95.70001,79.74993,29.60234
95.80000,79.83330,29.58524
95.90000,79.91673,29.39183
96.00001,79.99986,29.56451
96.10001,80.08324,29.56147
96.20001,80.16674,29.74081
96.30000,80.24986,29.71004
96.40000,80.33330,29.73807
96.50001,80.41680,29.93172
96.60001,80.49992,29.72288
96.70001,80.58337,29.73366
96.80000,80.66674,29.84263
96.90000,80.74986,29.84254
97.00001,80.83330,29.77707
97.10001,80.91667,29.98566
97.20001,80.99986,29.96204
97.30000,81.08330,29.87051
97.40000,81.16674,29.97910
97.50001,81.24992,29.86537
97.60001,81.33336,29.89447
97.70001,81.41674,30.17328
97.80000,81.49998,30.09660
97.90000,81.58330,30.22008
98.00001,81.66668,30.14653
98.10001,81.74992,30.13310
98.20001,81.83330,30.35860
98.30000,81.91674,30.12134
98.40000,81.99986,30.32200
98.50001,82.08330,30.11742
98.60001,82.16674,30.29049
98.70001,82.24992,30.32847
98.80000,82.33336,30.41186
98.90000,82.41673,30.42970
99.00001,82.49993,30.36884
99.10001,82.58330,30.40211
99.20001,82.66667,30.34792
99.30000,82.74986,30.44621
99.40000,82.83329,30.63359
99.50001,82.91674,30.68009
99.60001,82.99992,30.34787
99.70001,83.08343,30.76099
99.80000,83.16667,30.54882
99.90000,83.24986,30.60884
100.00001,83.33330,30.66299
100.10001,83.41674,30.73791
100.20001,83.49986,30.64648
100.30000,83.58336,30.53118
100.40000,83.66674,30.98080
100.50001,83.74993,30.80156
100.60001,83.83336,30.59512
100.70001,83.91668,30.86781
100.80000,83.99987,30.75917
100.90000,84.08336,30.86756
101.00001,84.16673,30.95806
101.10001,84.24993,30.81165
101.20001,84.33335,30.75540
101.30000,84.41674,30.97546
101.40000,84.49992,30.83346
101.50001,84.58330,30.89897
101.60001,84.66673,30.81763
101.70001,84.74993,30.86570
101.80000,84.83330,31.15651
101.90000,84.91674,30.81111
102.00001,84.99992,31.03019
102.10001,85.08329,30.96125
102.20001,85.16674,30.99903
102.30000,85.24993,31.16685
102.40000,85.33330,31.31454
102.50001,85.41674,31.21477
102.60001,85.49985,31.06239
102.70001,85.58337,31.02681
102.80000,85.66674,31.33522
102.90000,85.74992,31.38049
103.00001,85.83331,31.36334
103.10001,85.91673,31.23629
103.20001,85.99993,31.24501
103.30000,86.08330,31.43851
103.40000,86.16674,31.34717
103.50001,86.24992,31.53401
103.60001,86.33330,31.65916
103.70001,86.41668,31.42954
103.80000,86.49986,31.56591
103.90000,86.58336,31.63529
104.00001,86.66680,31.56160
104.10001,86.74992,31.48006
104.20001,86.83336,31.25691
104.30000,86.91681,31.45409
104.40000,86.99981,31.64936
104.50001,87.08330,31.78518
104.60001,87.16667,31.74540
104.70001,87.24992,31.52289
104.80000,87.33329,31.81247
104.90000,87.41674,31.64872
105.00001,87.49993,31.80277
105.10001,87.58336,31.75799
105.20001,87.66674,31.75833
105.30000,87.74993,31.81586
105.40000,87.83337,31.84325
105.50001,87.91674,32.11427
105.60001,87.99986,31.81772
105.70001,88.08336,31.82438
105.80000,88.16673,31.80503
105.90000,88.24986,31.96462
106.00001,88.33330,32.07036
106.10001,88.41667,31.94659
106.20001,88.49992,31.89156
106.30000,88.58336,32.08800
106.40000,88.66673,32.22030
106.50001,88.74992,32.04665
106.60001,88.83336,31.97991
106.70001,88.91667,32.17669
106.80000,88.99986,32.28689
106.90000,89.08330,32.27793
107.00001,89.16673,32.31468
107.10001,89.24992,32.08295
107.20001,89.33342,32.45393
107.30000,89.41674,32.29023
107.40000,89.49992,32.23574
107.50001,89.58329,32.48912
107.60001,89.66668,32.40978
107.70001,89.74980,32.21957
107.80000,89.83336,32.39925
107.90000,89.91674,32.49539
108.00001,89.99986,32.62989
108.10001,90.08336,32.45707
108.20001,90.16674,32.60583
108.30000,90.24986,32.34942
108.40000,90.33336,32.47030
108.50001,90.41674,32.63562
108.60001,90.49992,32.62876
108.70001,90.58336,32.74352
108.80000,90.66674,32.69295
108.90000,90.74987,32.85602
109.00001,90.83330,32.64072
109.10001,90.91668,32.76552
109.20001,90.99992,32.76390
109.30000,91.08336,32.92639
109.40000,91.16674,32.66096
109.50001,91.24992,32.84108
109.60001,91.33336,32.80962
109.70001,91.41673,32.86088
109.80000,91.49986,32.93937
109.90000,91.58337,32.77508
110.00001,91.66667,32.78125
110.10001,91.74986,32.89033
110.20001,91.83336,32.97387
110.30000,91.91674,33.03110
110.40000,91.99993,33.20064
110.50001,92.08336,33.07819
110.60001,92.16674,32.93252
110.70001,92.24992,32.87749
110.80000,92.33336,32.91257
110.90000,92.41668,32.97059
111.00001,92.49986,33.23171
111.10001,92.58336,33.23881
111.20001,92.66668,33.67138
111.30000,92.74987,33.26973
111.40000,92.83336,33.24322
111.50001,92.91674,33.25331
111.60001,92.99998,33.31354
111.70001,93.08343,33.33505
111.80000,93.16674,33.40698
111.90000,93.24992,33.41732
112.00001,93.33330,33.53163
112.10001,93.41662,33.35876
112.20001,93.49986,33.48004
112.30000,93.58330,33.39983
112.40000,93.66673,33.59328
112.50001,93.74992,33.65962
112.60001,93.83336,33.52130
112.70001,93.91673,33.58362
112.80000,93.99986,33.60861
112.90001,94.08336,33.81270
113.00001,94.16673,33.63042
113.10001,94.24992,33.57040
113.20001,94.33329,33.56829
113.30000,94.41674,33.69304
113.40001,94.49986,33.78854
113.50001,94.58336,33.78325
113.60001,94.66667,33.98567
113.70001,94.74993,33.92555
113.80000,94.83336,33.95769
113.90001,94.91679,33.88772
114.00001,94.99992,33.96671
114.10001,95.08330,33.98248
114.20001,95.16673,33.90438
114.30000,95.24986,33.99439
114.40001,95.33330,33.77570
114.50001,95.41667,33.94079
114.60001,95.49987,34.15188
114.70001,95.58336,34.30358
114.80000,95.66680,33.93481
114.90001,95.74998,34.17108
115.00001,95.83335,34.12331
115.10001,95.91667,34.17589
115.20001,95.99986,34.16084
115.30000,96.08329,34.17094
115.40001,96.16673,34.53055
115.50001,96.24986,34.22229
115.60001,96.33336,34.22268
115.70001,96.41673,34.44582
115.80000,96.49999,34.21812
115.90001,96.58337,34.30789
116.00001,96.66674,34.24159
116.10001,96.74992,34.47238
116.20001,96.83330,34.43485
116.30000,96.91673,34.61355
116.40001,96.99985,34.47454
116.50001,97.08336,34.56190
116.60001,97.16667,34.73169
116.70001,97.24992,34.54711
116.80000,97.33336,34.75232
116.90001,97.41673,34.72439
117.00001,97.49993,34.37585
117.10001,97.58336,34.74394
117.20001,97.66674,34.48772
117.30000,97.74992,34.57347
117.40001,97.83329,34.79916
117.50001,97.91673,34.76678
117.60001,97.99986,34.50957
117.70001,98.08330,34.94945
117.80000,98.16674,34.71415
117.90001,98.24986,34.90535
118.00001,98.33336,34.77559
118.10001,98.41667,35.00883
118.20001,98.49992,34.93058
118.30000,98.58330,35.07484
118.40001,98.66673,34.82724
118.50001,98.74986,34.94077
118.60001,98.83329,34.81671
118.70001,98.91674,34.96728
118.80000,98.99986,34.98830
118.90001,99.08336,34.94616
119.00001,99.16673,34.94347
119.10001,99.24993,35.19611
119.20001,99.33342,35.11982
119.30000,99.41667,35.07895
119.40001,99.49992,35.24379
119.50001,99.58323,35.39917
119.60001,99.66668,35.32679
119.70001,99.74986,35.36619
119.80000,99.83336,35.48428
119.90001,99.91674,35.43989
120.00001,99.99992,35.39701
120.10001,100.08336,35.34532
120.20001,100.16673,35.50094
120.30000,100.24992,35.34394
120.40001,100.33330,35.44268
120.50001,100.41674,35.34855
120.60001,100.49992,35.44498
120.70001,100.58336,35.61834
120.80000,100.66673,35.69385
120.90001,100.74986,35.48349
121.00001,100.83336,35.52269
121.10001,100.91674,35.67910
121.20001,100.99986,35.78666
121.30000,101.08336,35.75339
121.40001,101.16667,35.63490
121.50001,101.24993,35.71821
121.60001,101.33336,35.80327
121.70001,101.41673,35.75741
121.80000,101.49992,35.77210
121.90001,101.58336,35.94483
122.00001,101.66674,35.66509
122.10001,101.74992,35.67058
122.20001,101.83336,35.82630
122.30000,101.91668,35.88858
122.40001,101.99992,35.68866
122.50001,102.08330,35.94326
122.60001,102.16674,35.95483
122.70001,102.24986,35.99804
122.80000,102.33330,36.14602
122.90001,102.41673,36.00397
123.00001,102.49992,35.97820
123.10001,102.58336,36.27558
123.20001,102.66673,36.03631
123.30000,102.74986,36.12775
123.40001,102.83336,36.22246
123.50001,102.91673,36.17846
123.60001,102.99986,36.24623
123.70001,103.08329,36.35158
123.80000,103.16674,36.16445
123.90001,103.24986,36.34251
124.00001,103.33324,36.17821
124.10001,103.41674,36.30601
124.20001,103.49993,36.30718
124.30000,103.58342,36.46585
124.40001,103.66674,36.32526
124.50001,103.74999,36.33810
124.60001,103.83330,36.56992
124.70001,103.91667,36.49510
124.80000,103.99986,36.56061
124.90001,104.08330,36.58761
125.00001,104.16668,36.62588
125.10001,104.24992,36.49936
125.20001,104.33336,36.62544
125.30000,104.41673,36.73216
125.40001,104.49998,36.76313
125.50001,104.58330,36.80811
125.60001,104.66673,36.73123
125.70001,104.74992,36.83030
125.80000,104.83329,36.83814
125.90001,104.91667,36.71658
126.00001,104.99992,36.80355
126.10001,105.08330,36.81345
126.20001,105.16667,36.72383
126.30000,105.24986,36.89714
126.40001,105.33337,36.98083
126.50001,105.41674,36.97824
126.60001,105.49992,36.85530
126.70001,105.58343,37.06506
126.80000,105.66674,37.16586
126.90001,105.74985,37.06545
127.00001,105.83330,36.84976
127.10001,105.91661,37.12318
127.20001,105.99986,37.23259
127.30000,106.08336,37.07060
127.40001,106.16673,37.16659
127.50001,106.24993,37.06496
127.60001,106.33342,37.07628
127.70001,106.41674,37.41992
127.80000,106.49987,37.32844
127.90001,106.58336,37.29571
128.00000,106.66673,37.37229
128.10001,106.74993,37.21819
128.20002,106.83335,37.49969
128.30000,106.91673,37.25959
128.40001,106.99986,37.48514
128.50000,107.08329,37.58417
128.60001,107.16673,37.52738
128.70002,107.24992,37.48186
128.80000,107.33336,37.59661
128.90001,107.41673,37.55433
129.00000,107.49992,37.46461
129.10001,107.58329,37.59451
129.20002,107.66667,37.56040
129.30000,107.74986,37.70231
129.40001,107.83330,37.68197
129.50000,107.91673,37.76929
129.60001,107.99993,37.49371
129.70002,108.08336,37.65532
129.80000,108.16674,37.83392
129.90001,108.24992,37.84387
130.00000,108.33336,37.78389
130.10001,108.41668,37.74234
130.20002,108.49993,37.79776
130.30000,108.58330,37.81319
130.40001,108.66667,37.88576
130.50000,108.74992,37.92256
130.60001,108.83336,37.86543
130.70002,108.91673,37.94010
130.80000,108.99992,38.01835
130.90001,109.08335,37.98631
131.00000,109.16674,38.17898
131.10000,109.24999,37.92491
131.20002,109.33336,37.99126
131.30000,109.41667,38.10126
131.40002,109.49992,38.17432
131.50000,109.58323,38.25017
131.60000,109.66667,38.26081
131.70002,109.74992,38.07088
131.80000,109.83337,38.29187
131.90002,109.91674,38.33313
132.00000,109.99999,38.29614
132.10000,110.08336,38.19510
132.20002,110.16673,38.45607
132.30000,110.24985,38.36523
132.40002,110.33324,38.35548
132.50000,110.41661,38.47489
132.60000,110.49986,38.25321
132.70002,110.58330,38.34082
132.80000,110.66673,38.46460
132.90002,110.74992,38.68911
133.00000,110.83342,38.50203
133.10000,110.91674,38.54751
133.20002,110.99992,38.43922
133.30000,111.08336,38.45705
133.40002,111.16673,38.67089
133.50000,111.24986,38.54991
133.60000,111.33330,38.82940
133.70002,111.41667,38.74419
133.80000,111.49986,38.83876
133.90002,111.58329,38.76996
134.00000,111.66673,38.80456
134.10000,111.74999,38.72121
134.20002,111.83330,38.67657
134.30000,111.91674,38.75022
134.40002,111.99992,38.63600
134.50000,112.08336,38.89580
134.60000,112.16667,38.95700
134.70002,112.24986,38.67260
134.80000,112.33330,38.94822
134.90002,112.41667,38.95974
135.00000,112.49986,39.10659
135.10000,112.58336,38.87473
135.20002,112.66674,39.21851
135.30000,112.74986,39.04711
135.40002,112.83336,39.37452
135.50000,112.91673,38.97346
135.60000,112.99992,38.95969
135.70002,113.08330,38.98782
135.80000,113.16674,39.12791
135.90002,113.24992,39.16530
136.00000,113.33330,39.20562
136.10000,113.41673,39.11625
136.20002,113.49992,39.32210
136.30000,113.58336,39.32734
136.40002,113.66680,39.18754
136.50000,113.74992,39.23238
136.60000,113.83330,39.15647
136.70002,113.91667,39.41936
136.80000,113.99986,39.51114
136.90002,114.08329,39.60316
137.00000,114.16667,39.33038
137.10000,114.24992,39.35130
137.20002,114.33336,39.43587
137.30000,114.41674,39.48713
137.40002,114.49993,39.66799
137.50000,114.58336,39.76089
137.60000,114.66667,39.38374
137.70002,114.74986,39.74496
137.80000,114.83336,39.53083
137.90002,114.91674,39.70380
138.00000,114.99986,39.69547
138.10000,115.08330,39.62207
138.20002,115.16673,39.77549
138.30000,115.24992,39.73933
138.40002,115.33336,40.03220
138.50000,115.41673,39.79823
138.60000,115.49992,39.82983
138.70002,115.58335,39.76196
138.80000,115.66667,40.06944
138.90002,115.74986,40.07973
139.00000,115.83329,40.19503
139.10000,115.91667,39.89853
139.20002,115.99992,40.03646
139.30000,116.08336,40.05925
139.40002,116.16673,39.91058
139.50000,116.24992,40.35962
139.60000,116.33337,40.05111
139.70002,116.41667,40.03294
139.80000,116.49992,40.08860
139.90002,116.58323,40.04455
140.00000,116.66667,40.05205
140.10000,116.74993,40.12756
140.20002,116.83336,40.11266
140.30000,116.91674,40.22487
140.40002,116.99992,40.06792
140.50000,117.08330,40.44953
140.60000,117.16673,40.20532
140.70002,117.24993,40.33889
140.80000,117.33330,40.48481
140.90002,117.41674,40.24212
141.00000,117.49987,40.33825
141.10000,117.58330,40.39303
141.20002,117.66667,40.40426
141.30000,117.74993,40.38843
141.40002,117.83330,40.32664
141.50000,117.91667,40.38892
141.60000,117.99992,40.19385
141.70002,118.08336,40.34938
141.80000,118.16673,40.34144
141.90002,118.24992,40.30650
142.00000,118.33336,40.20199
142.10000,118.41673,40.21257
142.20002,118.49992,40.21850
142.30000,118.58337,39.91862
142.40002,118.66674,38.74929
142.50000,118.74992,2.07780
142.60000,118.83330,0.58433
142.70002,118.91667,0.47492
142.80000,118.99993,0.38530
142.90002,119.08330,0.54210
143.00000,119.16674,0.55915
143.10000,119.24986,0.56199
143.20002,119.33336,0.63255
143.30000,119.41673,0.62275
143.40002,119.49986,0.39637
143.50000,119.58336,0.40382
143.60000,119.66674,0.51691
143.70002,119.74992,0.70228
143.80000,119.83336,0.65210
143.90002,119.91673,0.33983
144.00000,119.99992,0.48751
144.10000,120.08330,0.50241
144.20002,120.16667,0.50897
144.30000,120.24986,0.48099
144.40002,120.33329,0.22566
144.50000,120.41667,0.44513
144.60000,120.49992,0.54670
144.70002,120.58348,0.55493
144.80000,120.66673,0.57008
144.90002,120.74992,0.51897
144.90202,120.75161,0.53710