File: NR/NR/RDSO NR Tensile 500.is_tens_RawData/Specimen_RawData_4.csv
Time,Extension,Load,Tensile strain,Tensile stress,Corrected Position
(sec),(mm),(N),(mm/mm),(MPa),(mm)
0.00000,0.00000,0.14820,0.00000,0.01647,0.00000
0.03000,0.05119,0.61574,0.00045,0.06842,0.05119
0.06000,0.23331,1.09775,0.00203,0.12197,0.23331
0.09000,0.51675,1.45020,0.00449,0.16113,0.51675
0.12000,0.83300,1.93307,0.00724,0.21479,0.83300
0.15000,1.16400,2.30644,0.01012,0.25627,1.16400
0.18000,1.47431,2.64596,0.01282,0.29400,1.47431
0.21000,1.73812,2.90515,0.01511,0.32279,1.73812
0.24000,1.98587,3.42088,0.01727,0.38010,1.98587
0.27000,2.23712,3.89185,0.01945,0.43243,2.23712
0.30000,2.49162,4.52443,0.02167,0.50271,2.49162
0.33000,2.74525,4.73226,0.02387,0.52581,2.74525
0.36000,2.99706,4.96882,0.02606,0.55209,2.99706
0.39000,3.24787,5.40192,0.02824,0.60021,3.24787
0.42000,3.49837,5.71191,0.03042,0.63466,3.49837
0.45000,3.74887,5.94322,0.03260,0.66036,3.74887
0.48000,3.99937,6.36626,0.03478,0.70736,3.99937
0.51000,4.24956,6.48440,0.03695,0.72049,4.24956
0.54000,4.49962,6.76970,0.03913,0.75219,4.49962
0.57000,4.74975,6.98885,0.04130,0.77654,4.74975
0.60000,4.99987,7.32195,0.04348,0.81355,4.99987
0.63000,5.24987,7.76110,0.04565,0.86234,5.24987
0.66000,5.49994,7.96555,0.04783,0.88506,5.49994
0.69000,5.75000,8.11493,0.05000,0.90166,5.75000
0.72000,6.00000,8.34255,0.05217,0.92695,6.00000
0.75000,6.24994,8.52324,0.05435,0.94703,6.24994
0.78000,6.50000,8.85057,0.05652,0.98340,6.50000
0.81000,6.75000,8.91613,0.05870,0.99068,6.75000
0.84000,6.99994,9.30434,0.06087,1.03382,6.99994
0.87000,7.24994,9.62409,0.06304,1.06934,7.24994
0.90000,7.50000,9.65875,0.06522,1.07319,7.50000
0.93000,7.75000,9.75512,0.06739,1.08390,7.75000
0.96000,7.99994,10.11411,0.06956,1.12379,7.99994
0.99000,8.25000,10.05822,0.07174,1.11758,8.25000
1.02000,8.50006,10.31901,0.07391,1.14656,8.50006
1.05000,8.75000,10.65885,0.07609,1.18432,8.75000
1.08000,8.99994,10.60822,0.07826,1.17869,8.99994
1.11000,9.25006,10.74079,0.08044,1.19342,9.25006
1.14000,9.50006,10.96121,0.08261,1.21791,9.50006
1.17000,9.75000,10.95061,0.08478,1.21673,9.75000
1.20000,10.00000,11.05930,0.08696,1.22881,10.00000
1.23000,10.25006,11.19545,0.08913,1.24394,10.25006
1.26000,10.50000,11.50595,0.09130,1.27844,10.50000
1.29000,10.74994,11.49394,0.09348,1.27710,10.74994
1.32000,11.00000,11.66345,0.09565,1.29594,11.00000
1.35000,11.25006,11.57680,0.09783,1.28631,11.25006
1.38000,11.49994,11.76129,0.10000,1.30681,11.49994
1.41000,11.74994,11.92369,0.10217,1.32485,11.74994
1.44000,12.00000,12.04157,0.10435,1.33795,12.00000
1.47000,12.25000,12.04962,0.10652,1.33885,12.25000
1.50000,12.49994,12.28055,0.10870,1.36451,12.49994
1.53000,12.75000,12.38883,0.11087,1.37654,12.75000
1.56000,13.00006,12.51278,0.11304,1.39031,13.00006
1.59000,13.25000,12.45662,0.11522,1.38407,13.25000
1.62000,13.50000,12.54442,0.11739,1.39382,13.50000
1.65000,13.75006,12.37800,0.11957,1.37533,13.75006
1.68000,14.00006,12.74689,0.12174,1.41632,14.00006
1.71000,14.25000,12.99726,0.12391,1.44414,14.25000
1.74000,14.50006,12.97245,0.12609,1.44138,14.50006
1.77000,14.75006,13.02197,0.12826,1.44689,14.75006
1.80000,15.00000,13.25856,0.13043,1.47317,15.00000
1.83000,15.25000,13.28559,0.13261,1.47618,15.25000
1.86000,15.50006,13.20377,0.13478,1.46709,15.50006
1.89000,15.75006,13.17222,0.13696,1.46358,15.75006
1.92000,16.00000,13.33262,0.13913,1.48140,16.00000
1.95000,16.24993,13.32488,0.14130,1.48054,16.24993
1.98000,16.50006,13.40555,0.14348,1.48951,16.50006
2.01000,16.75006,13.44785,0.14565,1.49421,16.75006
2.04000,17.00000,13.34726,0.14783,1.48303,17.00000
2.07000,17.25000,13.53389,0.15000,1.50376,17.25000
2.10000,17.50000,13.80057,0.15217,1.53340,17.50000
2.13000,17.74994,13.63569,0.15435,1.51508,17.74994
2.16000,17.99993,13.78054,0.15652,1.53117,17.99993
2.19000,18.25006,13.94166,0.15870,1.54907,18.25006
2.22000,18.50006,14.02633,0.16087,1.55848,18.50006
2.25000,18.75000,13.87970,0.16304,1.54219,18.75000
2.28000,19.00006,13.89182,0.16522,1.54354,19.00006
2.31000,19.25012,14.01851,0.16739,1.55761,19.25012
2.34000,19.50000,13.96339,0.16957,1.55149,19.50000
2.37000,19.75000,14.03252,0.17174,1.55917,19.75000
2.40000,20.00006,14.00928,0.17391,1.55659,20.00006
2.43000,20.25006,14.12806,0.17609,1.56978,20.25006
2.46000,20.50000,14.33739,0.17826,1.59304,20.50000
2.49000,20.75000,14.51627,0.18043,1.61292,20.75000
2.52000,21.00000,14.38282,0.18261,1.59809,21.00000
2.55000,21.25000,14.29678,0.18478,1.58853,21.25000
2.58000,21.49994,14.47949,0.18696,1.60883,21.49994
2.61000,21.75000,14.56680,0.18913,1.61853,21.75000
2.64000,22.00000,14.60868,0.19130,1.62319,22.00000
2.67000,22.24993,14.55975,0.19348,1.61775,22.24993
2.70000,22.49993,14.38894,0.19565,1.59877,22.49993
2.73000,22.75000,14.65186,0.19783,1.62798,22.75000
2.76000,23.00000,14.75097,0.20000,1.63900,23.00000
2.79000,23.25000,14.70143,0.20217,1.63349,23.25000
2.82000,23.50006,14.64453,0.20435,1.62717,23.50006
2.85000,23.75006,14.91136,0.20652,1.65682,23.75006
2.88000,24.00006,14.77806,0.20870,1.64201,24.00006
2.91000,24.25000,14.86493,0.21087,1.65166,24.25000
2.94000,24.50006,14.93603,0.21304,1.65956,24.50006
2.97000,24.75000,15.09578,0.21522,1.67731,24.75000
3.00000,24.99993,15.19811,0.21739,1.68868,24.99993
3.03000,25.25006,15.11381,0.21957,1.67931,25.25006
3.06000,25.50012,14.91014,0.22174,1.65668,25.50012
3.09000,25.74993,14.97007,0.22391,1.66334,25.74993
3.12000,25.99987,15.15591,0.22609,1.68399,25.99987
3.15000,26.25000,15.18993,0.22826,1.68777,26.25000
3.18000,26.50006,15.21148,0.23044,1.69016,26.50006
3.21000,26.75000,15.31887,0.23261,1.70210,26.75000
3.24000,27.00000,15.43765,0.23478,1.71529,27.00000
3.27000,27.25006,15.70701,0.23696,1.74522,27.25006
3.30000,27.49993,15.44755,0.23913,1.71639,27.49993
3.33000,27.74993,15.48659,0.24130,1.72073,27.74993
3.36000,28.00006,15.71193,0.24348,1.74577,28.00006
3.39000,28.25006,15.61539,0.24565,1.73504,28.25006
3.42000,28.50000,15.69454,0.24783,1.74384,28.50000
3.45000,28.75000,15.74247,0.25000,1.74916,28.75000
3.48000,29.00006,15.73147,0.25217,1.74794,29.00006
3.51000,29.25000,15.77267,0.25435,1.75252,29.25000
3.54000,29.50000,15.62709,0.25652,1.73634,29.50000
3.57000,29.75006,15.65252,0.25870,1.73917,29.75006
3.60000,30.00006,15.87766,0.26087,1.76418,30.00006
3.63000,30.25000,15.80032,0.26304,1.75559,30.25000
3.66000,30.49999,15.91802,0.26522,1.76867,30.49999
3.69000,30.75000,15.95787,0.26739,1.77310,30.75000
3.72000,31.00000,15.98780,0.26957,1.77642,31.00000
3.75000,31.25000,16.07070,0.27174,1.78563,31.25000
3.78000,31.49999,16.15500,0.27391,1.79500,31.49999
3.81000,31.75006,16.29399,0.27609,1.81044,31.75006
3.84000,31.99999,16.31427,0.27826,1.81270,31.99999
3.87000,32.24999,16.26599,0.28043,1.80733,32.24999
3.90000,32.50000,16.26778,0.28261,1.80753,32.50000
3.93000,32.75000,16.39315,0.28478,1.82146,32.75000
3.96000,32.99993,16.56528,0.28696,1.84059,32.99993
3.99000,33.24999,16.53221,0.28913,1.83691,33.24999
4.02000,33.50012,16.53998,0.29131,1.83778,33.50012
4.05000,33.75006,16.42323,0.29348,1.82480,33.75006
4.08000,34.00000,16.63015,0.29565,1.84779,34.00000
4.11000,34.25006,16.54933,0.29783,1.83881,34.25006
4.14000,34.50006,16.73284,0.30000,1.85920,34.50006
4.17000,34.75000,17.04591,0.30217,1.89399,34.75000
4.20000,34.99999,17.00095,0.30435,1.88899,34.99999
4.23000,35.25006,16.74355,0.30652,1.86039,35.25006
4.26000,35.49999,16.83791,0.30870,1.87088,35.49999
4.29000,35.74993,16.91077,0.31087,1.87897,35.74993
4.32000,35.99999,16.98295,0.31304,1.88699,35.99999
4.35000,36.25000,17.01302,0.31522,1.89034,36.25000
4.38000,36.50000,17.17768,0.31739,1.90863,36.50000
4.41000,36.74999,17.03543,0.31957,1.89283,36.74999
4.44000,36.99999,17.28184,0.32174,1.92020,36.99999
4.47000,37.24993,17.33417,0.32391,1.92602,37.24993
4.50000,37.49993,17.45741,0.32609,1.93971,37.49993
4.53000,37.74999,17.22974,0.32826,1.91442,37.74999
4.56000,38.00006,17.28502,0.33044,1.92056,38.00006
4.59000,38.25000,17.45825,0.33261,1.93981,38.25000
4.62000,38.50000,17.62241,0.33478,1.95805,38.50000
4.65000,38.75006,17.62871,0.33696,1.95875,38.75006
4.68000,39.00006,17.66098,0.33913,1.96233,39.00006
4.71000,39.24999,17.65087,0.34130,1.96121,39.24999
4.74000,39.49999,17.63302,0.34348,1.95922,39.49999
4.77000,39.75006,17.63828,0.34565,1.95981,39.75006
4.80000,39.99999,17.70370,0.34783,1.96708,39.99999
4.83000,40.25000,17.92441,0.35000,1.99160,40.25000
4.86000,40.50006,17.92417,0.35217,1.99157,40.50006
4.89000,40.75006,17.89811,0.35435,1.98868,40.75006
4.92000,40.99999,18.14064,0.35652,2.01563,40.99999
4.95000,41.25000,17.98378,0.35870,1.99820,41.25000
4.98000,41.50006,18.03839,0.36087,2.00427,41.50006
5.01000,41.74999,18.08693,0.36304,2.00966,41.74999
5.04000,41.99993,17.98468,0.36522,1.99830,41.99993
5.07000,42.24999,18.14939,0.36739,2.01660,42.24999
5.10000,42.50005,18.22460,0.36957,2.02496,42.50005
5.13000,42.74993,18.26352,0.37174,2.02928,42.74993
5.16000,42.99993,18.28784,0.37391,2.03198,42.99993
5.19000,43.25006,18.19587,0.37609,2.02176,43.25006
5.22000,43.50006,18.28313,0.37826,2.03146,43.50006
5.25000,43.75006,18.48237,0.38044,2.05360,43.75006
5.28000,44.00006,18.67639,0.38261,2.07515,44.00006
5.31000,44.25006,18.61122,0.38478,2.06791,44.25006
5.34000,44.49999,18.66137,0.38696,2.07349,44.49999
5.37000,44.74999,18.78118,0.38913,2.08680,44.74999
5.40000,44.99999,18.64942,0.39130,2.07216,44.99999
5.43000,45.25006,18.64815,0.39348,2.07202,45.25006
5.46000,45.49999,18.94273,0.39565,2.10475,45.49999
5.49000,45.75000,18.82471,0.39783,2.09163,45.75000
5.52000,45.99999,19.11600,0.40000,2.12400,45.99999
5.55000,46.24999,19.21367,0.40217,2.13485,46.24999
5.58000,46.49993,19.12117,0.40435,2.12457,46.49993
5.61000,46.75006,19.00731,0.40652,2.11192,46.75006
5.64000,47.00006,19.26503,0.40870,2.14056,47.00006
5.67000,47.24999,19.08309,0.41087,2.12034,47.24999
5.70000,47.49993,19.16359,0.41304,2.12929,47.49993
5.73000,47.75005,19.25817,0.41522,2.13980,47.75005
5.76000,47.99999,19.49841,0.41739,2.16649,47.99999
5.79000,48.24993,19.55060,0.41956,2.17229,48.24993
5.82000,48.50006,19.52351,0.42174,2.16928,48.50006
5.85000,48.75012,19.49402,0.42391,2.16600,48.75012
5.88000,49.00006,19.63022,0.42609,2.18114,49.00006
5.91000,49.25000,19.64996,0.42826,2.18333,49.25000
5.94000,49.50006,19.44744,0.43044,2.16083,49.50006
5.97000,49.74999,19.72152,0.43261,2.19128,49.74999
6.00000,49.99993,20.02262,0.43478,2.22474,49.99993
6.03000,50.25005,19.86636,0.43696,2.20737,50.25005
6.06000,50.50005,19.89095,0.43913,2.21011,50.50005
6.09000,50.74999,19.87564,0.44130,2.20841,50.74999
6.12000,50.99999,20.16187,0.44348,2.24021,50.99999
6.15000,51.24993,20.17297,0.44565,2.24144,51.24993
6.18000,51.49999,20.09643,0.44783,2.23294,51.49999
6.21000,51.74999,20.19136,0.45000,2.24348,51.74999
6.24000,51.99999,20.21389,0.45217,2.24599,51.99999
6.27000,52.25006,20.29750,0.45435,2.25528,52.25006
6.30000,52.49999,20.16736,0.45652,2.24082,52.49999
6.33000,52.74993,20.39951,0.45870,2.26661,52.74993
6.36000,52.99999,20.33209,0.46087,2.25912,52.99999
6.39000,53.25005,20.23647,0.46304,2.24850,53.25005
6.42000,53.50005,20.30576,0.46522,2.25620,53.50005
6.45000,53.75005,20.63240,0.46739,2.29249,53.75005
6.48000,54.00012,20.62490,0.46957,2.29166,54.00012
6.51000,54.25006,20.71929,0.47174,2.30214,54.25006
6.54000,54.49993,20.83168,0.47391,2.31463,54.49993
6.57000,54.75000,20.86668,0.47609,2.31852,54.75000
6.60000,55.00006,20.83790,0.47826,2.31532,55.00006
6.63000,55.24999,21.03141,0.48043,2.33682,55.24999
6.66000,55.49999,20.92507,0.48261,2.32501,55.49999
6.69000,55.75005,20.98100,0.48478,2.33122,55.75005
6.72000,55.99999,21.04581,0.48696,2.33842,55.99999
6.75000,56.24993,21.00574,0.48913,2.33397,56.24993
6.78000,56.49999,21.17032,0.49130,2.35226,56.49999
6.81000,56.75005,21.25249,0.49348,2.36139,56.75005
6.84000,56.99999,21.28016,0.49565,2.36446,56.99999
6.87000,57.24999,21.13855,0.49783,2.34873,57.24999
6.90000,57.49999,21.20326,0.50000,2.35592,57.49999
6.93000,57.74999,21.34237,0.50217,2.37137,57.74999
6.96000,57.99993,21.43992,0.50435,2.38221,57.99993
6.99000,58.24999,21.62728,0.50652,2.40303,58.24999
7.02000,58.50011,21.79056,0.50870,2.42117,58.50011
7.05000,58.75005,21.72331,0.51087,2.41370,58.75005
7.08000,59.00005,21.80151,0.51304,2.42239,59.00005
7.11000,59.25005,21.77314,0.51522,2.41924,59.25005
7.14000,59.50006,21.66972,0.51739,2.40775,59.50006
7.17000,59.74993,21.78708,0.51956,2.42079,59.74993
7.20000,59.99999,21.97799,0.52174,2.44200,59.99999
7.23000,60.25005,22.09885,0.52391,2.45543,60.25005
7.26000,60.50006,22.04811,0.52609,2.44979,60.50006
7.29000,60.74993,22.17208,0.52826,2.46356,60.74993
7.32000,60.99993,22.20108,0.53043,2.46679,60.99993
7.35000,61.24999,22.16324,0.53261,2.46258,61.24999
7.38000,61.49993,22.17343,0.53478,2.46371,61.49993
7.41000,61.74999,22.10152,0.53696,2.45572,61.74999
7.44000,62.00006,22.18619,0.53913,2.46513,62.00006
7.47000,62.25005,22.34869,0.54130,2.48319,62.25005
7.50000,62.49993,22.28761,0.54348,2.47640,62.49993
7.53000,62.74999,22.45535,0.54565,2.49504,62.74999
7.56000,63.00006,22.54584,0.54783,2.50509,63.00006
7.59000,63.24999,22.70969,0.55000,2.52330,63.24999
7.62000,63.50006,22.68941,0.55217,2.52105,63.50006
7.65000,63.75011,22.75884,0.55435,2.52876,63.75011
7.68000,64.00005,22.96520,0.55652,2.55169,64.00005
7.71000,64.24999,22.93971,0.55870,2.54886,64.24999
7.74000,64.49999,22.82803,0.56087,2.53645,64.49999
7.77000,64.75005,22.74554,0.56304,2.52728,64.75005
7.80000,64.99999,22.90628,0.56522,2.54514,64.99999
7.83000,65.24993,23.11293,0.56739,2.56810,65.24993
7.86000,65.50005,23.00319,0.56957,2.55591,65.50005
7.89000,65.74999,23.03831,0.57174,2.55981,65.74999
7.92000,65.99993,22.98541,0.57391,2.55393,65.99993
7.95000,66.24999,23.09234,0.57609,2.56581,66.24999
7.98000,66.50005,23.32534,0.57826,2.59171,66.50005
8.01000,66.74999,23.34104,0.58043,2.59345,66.74999
8.04000,66.99999,23.38704,0.58261,2.59856,66.99999
8.07000,67.24999,23.35449,0.58478,2.59494,67.24999
8.10000,67.49999,23.25589,0.58696,2.58399,67.49999
8.13000,67.74999,23.43093,0.58913,2.60344,67.74999
8.16000,67.99993,23.46793,0.59130,2.60755,67.99993
8.19000,68.24999,23.67087,0.59348,2.63010,68.24999
8.22000,68.50005,23.56269,0.59565,2.61808,68.50005
8.25000,68.74999,23.60454,0.59783,2.62273,68.74999
8.28000,69.00005,23.86733,0.60000,2.65193,69.00005
8.31000,69.25012,24.05827,0.60217,2.67314,69.25012
8.34000,69.50005,23.91225,0.60435,2.65692,69.50005
8.37000,69.74993,23.79376,0.60652,2.64375,69.74993
8.40000,69.99999,24.03684,0.60870,2.67076,69.99999
8.43000,70.25005,24.02141,0.61087,2.66905,70.25005
8.46000,70.49999,23.94223,0.61304,2.66025,70.49999
8.49000,70.74999,24.14719,0.61522,2.68302,70.74999
8.52000,70.99999,24.28177,0.61739,2.69797,70.99999
8.55000,71.24993,24.04832,0.61956,2.67204,71.24993
8.58000,71.49993,24.10879,0.62174,2.67875,71.49993
8.61000,71.75006,24.34165,0.62391,2.70463,71.75006
8.64000,72.00005,24.29894,0.62609,2.69988,72.00005
8.67000,72.24993,24.41988,0.62826,2.71332,72.24993
8.70000,72.49999,24.57941,0.63043,2.73105,72.49999
8.73000,72.74999,24.52896,0.63261,2.72544,72.74999
8.76000,72.99999,24.48534,0.63478,2.72059,72.99999
8.79000,73.24993,24.53454,0.63696,2.72606,73.24993
8.82000,73.49999,24.68340,0.63913,2.74260,73.49999
8.85000,73.75005,24.77537,0.64130,2.75282,73.75005
8.88000,74.00006,24.78161,0.64348,2.75351,74.00006
8.91000,74.24999,24.79817,0.64565,2.75535,74.24999
8.94000,74.50006,24.97908,0.64783,2.77545,74.50006
8.97000,74.74999,25.01881,0.65000,2.77987,74.74999
9.00000,74.99999,25.11400,0.65217,2.79044,74.99999
9.03000,75.24999,25.00304,0.65435,2.77812,75.24999
9.06000,75.50005,25.14411,0.65652,2.79379,75.50005
9.09000,75.74999,25.09370,0.65870,2.78819,75.74999
9.12000,75.99999,25.04979,0.66087,2.78331,75.99999
9.15000,76.25006,25.38098,0.66304,2.82011,76.25006
9.18000,76.50005,25.48074,0.66522,2.83119,76.50005
9.21000,76.74993,25.41571,0.66739,2.82397,76.74993
9.24000,76.99999,25.38429,0.66957,2.82048,76.99999
9.27000,77.25005,25.45583,0.67174,2.82843,77.25005
9.30000,77.49998,25.41045,0.67391,2.82338,77.49998
9.33000,77.74992,25.50936,0.67609,2.83437,77.74992
9.36000,77.99999,25.57748,0.67826,2.84194,77.99999
9.39000,78.24999,25.60074,0.68043,2.84453,78.24999
9.42000,78.49999,25.70147,0.68261,2.85572,78.49999
9.45000,78.75005,25.90397,0.68478,2.87822,78.75005
9.48000,79.00012,25.88842,0.68696,2.87649,79.00012
9.51000,79.25005,26.03115,0.68913,2.89235,79.25005
9.54000,79.49999,25.85508,0.69130,2.87279,79.49999
9.57000,79.74998,25.87497,0.69348,2.87500,79.74998
9.60000,79.99999,25.83515,0.69565,2.87057,79.99999
9.63000,80.24999,26.08704,0.69783,2.89856,80.24999
9.66000,80.49999,26.16186,0.70000,2.90687,80.49999
9.69000,80.75004,26.29475,0.70217,2.92164,80.75004
9.72000,80.99998,26.23215,0.70435,2.91468,80.99998
9.75000,81.24992,26.32617,0.70652,2.92513,81.24992
9.78000,81.49998,26.30807,0.70870,2.92312,81.49998
9.81000,81.74999,26.56410,0.71087,2.95157,81.74999
9.84000,81.99993,26.51793,0.71304,2.94644,81.99993
9.87000,82.24992,26.46151,0.71522,2.94017,82.24992
9.90000,82.49999,26.43533,0.71739,2.93726,82.49999
9.93000,82.74999,26.62391,0.71957,2.95821,82.74999
9.96000,82.99992,26.66334,0.72174,2.96259,82.99992
9.99000,83.24993,26.90979,0.72391,2.98998,83.24993
10.02000,83.50004,26.70958,0.72609,2.96773,83.50004
10.05000,83.75005,26.77984,0.72826,2.97554,83.75005
10.08000,83.99999,26.98591,0.73043,2.99843,83.99999
10.11000,84.25005,27.02605,0.73261,3.00289,84.25005
10.14000,84.50005,26.78124,0.73478,2.97569,84.50005
10.17000,84.74999,26.91996,0.73696,2.99111,84.74999
10.20000,84.99999,27.23969,0.73913,3.02663,84.99999
10.23000,85.25005,27.14491,0.74130,3.01610,85.25005
10.26000,85.50005,27.22962,0.74348,3.02551,85.50005
10.29000,85.74999,27.30971,0.74565,3.03441,85.74999
10.32000,86.00005,27.39864,0.74783,3.04429,86.00005
10.35000,86.24999,27.32193,0.75000,3.03577,86.24999
10.38000,86.49998,27.43956,0.75217,3.04884,86.49998
10.41000,86.74992,27.37993,0.75435,3.04221,86.74992
10.44000,87.00005,27.48553,0.75652,3.05395,87.00005
10.47000,87.24999,27.52910,0.75870,3.05879,87.24999
10.50000,87.49999,27.68139,0.76087,3.07571,87.49999
10.53000,87.74999,27.66064,0.76304,3.07340,87.74999
10.56000,87.99993,27.89960,0.76522,3.09996,87.99993
10.59000,88.24993,27.81932,0.76739,3.09104,88.24993
10.62000,88.49998,27.83218,0.76957,3.09246,88.49998
10.65000,88.75005,27.83215,0.77174,3.09246,88.75005
10.68000,89.00005,27.92872,0.77391,3.10319,89.00005
10.71000,89.24999,27.94361,0.77609,3.10485,89.24999
10.74000,89.49999,27.85473,0.77826,3.09497,89.49999
10.77000,89.75005,28.04819,0.78044,3.11647,89.75005
10.80000,89.99999,28.08250,0.78261,3.12028,89.99999
10.83000,90.24998,28.15414,0.78478,3.12824,90.24998
10.86000,90.50005,28.37199,0.78696,3.15244,90.50005
10.89000,90.75011,28.28717,0.78913,3.14302,90.75011
10.92000,90.99999,28.24613,0.79130,3.13846,90.99999
10.95000,91.24999,28.42827,0.79348,3.15870,91.24999
10.98000,91.50005,28.51898,0.79565,3.16878,91.50005
11.01000,91.74999,28.25676,0.79783,3.13964,91.74999
11.04000,91.99998,28.37965,0.80000,3.15330,91.99998
11.07000,92.24999,28.45229,0.80217,3.16137,92.24999
11.10000,92.49998,28.62305,0.80435,3.18034,92.49998
11.13000,92.74987,28.67078,0.80652,3.18564,92.74987
11.16000,92.99993,28.75464,0.80870,3.19496,92.99993
11.19000,93.25005,28.83132,0.81087,3.20348,93.25005
11.22000,93.50005,28.89806,0.81304,3.21090,93.50005
11.25000,93.74999,28.94824,0.81522,3.21647,93.74999
11.28000,94.00005,29.11799,0.81739,3.23533,94.00005
11.31000,94.25005,29.02850,0.81957,3.22539,94.25005
11.34000,94.50004,29.01490,0.82174,3.22388,94.50004
11.37000,94.74998,29.30429,0.82391,3.25603,94.74998
11.40000,95.00004,29.28347,0.82609,3.25372,95.00004
11.43000,95.25005,29.17143,0.82826,3.24127,95.25005
11.46000,95.49998,29.23359,0.83043,3.24818,95.49998
11.49000,95.74998,29.45006,0.83261,3.27223,95.74998
11.52000,96.00005,29.43669,0.83478,3.27074,96.00005
11.55000,96.24999,29.55045,0.83696,3.28338,96.24999
11.58000,96.49992,29.58624,0.83913,3.28736,96.49992
11.61000,96.74999,29.56299,0.84130,3.28478,96.74999
11.64000,97.00004,29.73105,0.84348,3.30345,97.00004
11.67000,97.24999,29.76088,0.84565,3.30676,97.24999
11.70000,97.49998,29.74001,0.84783,3.30445,97.49998
11.73000,97.75005,29.88713,0.85000,3.32079,97.75005
11.76000,97.99998,29.94045,0.85217,3.32672,97.99998
11.79000,98.24992,29.72189,0.85435,3.30243,98.24992
11.82000,98.49999,29.67737,0.85652,3.29749,98.49999
11.85000,98.75004,29.86107,0.85870,3.31790,98.75004
11.88000,98.99999,29.89426,0.86087,3.32158,98.99999
11.91000,99.24999,30.03484,0.86304,3.33720,99.24999
11.94000,99.50005,30.27365,0.86522,3.36374,99.50005
11.97000,99.75005,30.12874,0.86739,3.34764,99.75005
12.00000,99.99998,30.26914,0.86957,3.36324,99.99998
12.03000,100.25005,30.43115,0.87174,3.38124,100.25005
12.06000,100.50005,30.42552,0.87391,3.38061,100.50005
12.09000,100.74999,30.69500,0.87609,3.41056,100.74999
12.12000,100.99999,30.46784,0.87826,3.38532,100.99999
12.15000,101.25005,30.59324,0.88044,3.39925,101.25005
12.18000,101.50004,30.47759,0.88261,3.38640,101.50004
12.21000,101.74998,30.53255,0.88478,3.39251,101.74998
12.24000,101.99999,30.51457,0.88696,3.39051,101.99999
12.27000,102.25005,30.56064,0.88913,3.39563,102.25005
12.30000,102.49998,30.78557,0.89130,3.42062,102.49998
12.33000,102.74992,30.70925,0.89348,3.41214,102.74992
12.36000,102.99998,30.85752,0.89565,3.42861,102.99998
12.39000,103.25004,30.66669,0.89783,3.40741,103.25004
12.42000,103.49998,30.94206,0.90000,3.43801,103.49998
12.45000,103.74992,31.05661,0.90217,3.45073,103.74992
12.48000,104.00005,31.14093,0.90435,3.46010,104.00005
12.51000,104.25005,31.05480,0.90652,3.45053,104.25005
12.54000,104.50005,31.03756,0.90870,3.44862,104.50005
12.57000,104.75005,31.35643,0.91087,3.48405,104.75005
12.60000,105.00005,31.47942,0.91304,3.49771,105.00005
12.63000,105.24998,31.52605,0.91522,3.50289,105.24998
12.66000,105.49999,31.66859,0.91739,3.51873,105.49999
12.69000,105.75005,31.73070,0.91957,3.52563,105.75005
12.72000,106.00004,31.58954,0.92174,3.50995,106.00004
12.75000,106.24993,31.68104,0.92391,3.52012,106.24993
12.78000,106.49998,31.65527,0.92609,3.51725,106.49998
12.81000,106.75005,31.58366,0.92826,3.50930,106.75005
12.84000,106.99992,31.69793,0.93043,3.52199,106.99992
12.87000,107.24992,31.69348,0.93261,3.52150,107.24992
12.90000,107.50005,31.86119,0.93478,3.54013,107.50005
12.93000,107.74999,31.91209,0.93696,3.54579,107.74999
12.96000,107.99998,31.78027,0.93913,3.53114,107.99998
12.99000,108.24999,31.99011,0.94130,3.55446,108.24999
13.02000,108.50005,32.13848,0.94348,3.57094,108.50005
13.05000,108.75005,32.04943,0.94565,3.56105,108.75005
13.08000,108.99998,32.19530,0.94783,3.57726,108.99998
13.11000,109.25005,32.27808,0.95000,3.58645,109.25005
13.14000,109.50005,32.25271,0.95217,3.58363,109.50005
13.17000,109.74999,32.42792,0.95435,3.60310,109.74999
13.20000,109.99999,32.46906,0.95652,3.60767,109.99999
13.23000,110.25004,32.57506,0.95870,3.61945,110.25004
13.26000,110.50005,32.55948,0.96087,3.61772,110.50005
13.29000,110.74998,32.51721,0.96304,3.61302,110.74998
13.32000,111.00005,32.55552,0.96522,3.61728,111.00005
13.35000,111.25005,32.86156,0.96739,3.65128,111.25005
13.38000,111.50005,32.89320,0.96957,3.65480,111.50005
13.41000,111.74999,32.79131,0.97174,3.64348,111.74999
13.44000,112.00004,32.90446,0.97391,3.65605,112.00004
13.47000,112.25005,32.76800,0.97609,3.64089,112.25005
13.50000,112.49992,32.93954,0.97826,3.65995,112.49992
13.53000,112.74998,33.06194,0.98043,3.67355,112.74998
13.56000,113.00005,33.12077,0.98261,3.68009,113.00005
13.59000,113.24998,33.14712,0.98478,3.68301,113.24998
13.62000,113.49992,33.17818,0.98696,3.68646,113.49992
13.65000,113.75004,33.12660,0.98913,3.68073,113.75004
13.68000,114.00005,33.13576,0.99130,3.68175,114.00005
13.71000,114.25004,33.35265,0.99348,3.70585,114.25004
13.74000,114.50005,33.44915,0.99565,3.71657,114.50005
13.77000,114.75004,33.35305,0.99783,3.70589,114.75004
13.80000,114.99998,33.43426,1.00000,3.71492,114.99998
13.83000,115.24999,33.53810,1.00217,3.72646,115.24999
13.86000,115.50005,33.54163,1.00435,3.72685,115.50005
13.89000,115.75005,33.68328,1.00652,3.74259,115.75005
13.92000,115.99992,33.62333,1.00870,3.73593,115.99992
13.95000,116.24998,33.62054,1.01087,3.73562,116.24998
13.98000,116.50004,33.73917,1.01304,3.74880,116.50004
14.01000,116.75005,33.88960,1.01522,3.76551,116.75005
14.04000,116.99999,33.87931,1.01739,3.76437,116.99999
14.07000,117.24998,33.90375,1.01957,3.76708,117.24998
14.10000,117.49999,34.16953,1.02174,3.79661,117.49999
14.13000,117.74993,34.23933,1.02391,3.80437,117.74993
14.16000,117.99992,34.22165,1.02609,3.80241,117.99992
14.19000,118.25005,34.27450,1.02826,3.80828,118.25005
14.22000,118.50005,34.33720,1.03044,3.81524,118.50005
14.25000,118.75005,34.30310,1.03261,3.81146,118.75005
14.28000,119.00004,34.30502,1.03478,3.81167,119.00004
14.31000,119.25004,34.33254,1.03696,3.81473,119.25004
14.34000,119.49998,34.39534,1.03913,3.82170,119.49998
14.37000,119.74998,34.49869,1.04130,3.83319,119.74998
14.40000,120.00005,34.39740,1.04348,3.82193,120.00005
14.43000,120.25011,34.48669,1.04565,3.83185,120.25011
14.46000,120.49999,34.64799,1.04783,3.84978,120.49999
14.49000,120.74999,34.94169,1.05000,3.88241,120.74999
14.52000,121.00005,34.88325,1.05217,3.87592,121.00005
14.55000,121.24998,34.94247,1.05435,3.88250,121.24998
14.58000,121.49998,35.04514,1.05652,3.89390,121.49998
14.61000,121.75005,35.14928,1.05870,3.90548,121.75005
14.64000,121.99998,35.19003,1.06087,3.91000,121.99998
14.67000,122.24992,35.14746,1.06304,3.90527,122.24992
14.70000,122.49999,35.16412,1.06522,3.90712,122.49999
14.73000,122.74999,35.13806,1.06739,3.90423,122.74999
14.76000,122.99999,35.21114,1.06957,3.91235,122.99999
14.79000,123.24998,35.34790,1.07174,3.92754,123.24998
14.82000,123.50004,35.52727,1.07391,3.94747,123.50004
14.85000,123.75005,35.65810,1.07609,3.96201,123.75005
14.88000,123.99998,35.29872,1.07826,3.92208,123.99998
14.91000,124.24998,35.50875,1.08043,3.94542,124.24998
14.94000,124.50005,35.62509,1.08261,3.95834,124.50005
14.97000,124.75004,35.61044,1.08478,3.95672,124.75004
15.00000,124.99998,35.64850,1.08696,3.96094,124.99998
15.03000,125.25004,35.74622,1.08913,3.97180,125.25004
15.06000,125.50004,35.88234,1.09130,3.98693,125.50004
15.09000,125.74998,35.87387,1.09348,3.98599,125.74998
15.12000,125.99997,35.79907,1.09565,3.97767,125.99997
15.15000,126.24999,35.90801,1.09783,3.98978,126.24999
15.18000,126.50005,36.06896,1.10000,4.00766,126.50005
15.21000,126.74998,36.11810,1.10217,4.01312,126.74998
15.24000,126.99998,36.02469,1.10435,4.00274,126.99998
15.27000,127.25005,36.16860,1.10652,4.01873,127.25005
15.30000,127.49991,36.26362,1.10869,4.02929,127.49991
15.33000,127.74984,36.30570,1.11087,4.03397,127.74984
15.36000,128.00003,36.23443,1.11304,4.02605,128.00003
15.39000,128.25004,36.55786,1.11522,4.06198,128.25004
15.42000,128.50004,36.58783,1.11739,4.06531,128.50004
15.45000,128.75005,36.54576,1.11957,4.06064,128.75005
15.48000,129.00010,36.57882,1.12174,4.06431,129.00010
15.51000,129.25004,36.78185,1.12391,4.08687,129.25004
15.54000,129.49998,36.77882,1.12609,4.08653,129.49998
15.57000,129.75005,36.93262,1.12826,4.10362,129.75005
15.60000,130.00011,36.93385,1.13044,4.10376,130.00011
15.63000,130.24998,36.95403,1.13261,4.10600,130.24998
15.66000,130.49997,36.91984,1.13478,4.10220,130.49997
15.69000,130.74997,37.07482,1.13696,4.11942,130.74997
15.72000,130.99998,37.24660,1.13913,4.13851,130.99998
15.75000,131.24992,37.16764,1.14130,4.12974,131.24992
15.78000,131.49998,37.12331,1.14348,4.12481,131.49998
15.81000,131.75005,37.19472,1.14565,4.13275,131.75005
15.84000,131.99999,37.20966,1.14783,4.13441,131.99999
15.87000,132.24992,37.32306,1.15000,4.14701,132.24992
15.90000,132.49998,37.37459,1.15217,4.15273,132.49998
15.93000,132.74997,37.30856,1.15435,4.14540,132.74997
15.96000,132.99991,37.32374,1.15652,4.14708,132.99991
15.99000,133.24998,37.53197,1.15870,4.17022,133.24998
16.02000,133.50010,37.59124,1.16087,4.17680,133.50010
16.05000,133.75004,37.59893,1.16304,4.17766,133.75004
16.08000,133.99998,37.78609,1.16522,4.19845,133.99998
16.11000,134.25005,37.68249,1.16739,4.18694,134.25005
16.14000,134.50004,37.90850,1.16957,4.21206,134.50004
16.17000,134.74998,37.88053,1.17174,4.20895,134.74998
16.20000,134.99998,37.99490,1.17391,4.22166,134.99998
16.23000,135.25004,38.12201,1.17609,4.23578,135.25004
16.26000,135.50005,38.03418,1.17826,4.22602,135.50005
16.29000,135.74998,38.25157,1.18043,4.25017,135.74998
16.32000,135.99998,38.19347,1.18261,4.24372,135.99998
16.35000,136.24998,38.17310,1.18478,4.24146,136.24998
16.38000,136.49997,38.40640,1.18696,4.26738,136.49997
16.41000,136.74999,38.48575,1.18913,4.27619,136.74999
16.44000,137.00004,38.50764,1.19130,4.27863,137.00004
16.47000,137.24998,38.47115,1.19348,4.27457,137.24998
16.50000,137.49992,38.76353,1.19565,4.30706,137.49992
16.53000,137.74998,38.66037,1.19783,4.29560,137.74998
16.56000,138.00004,38.66723,1.20000,4.29636,138.00004
16.59000,138.24998,38.66346,1.20217,4.29594,138.24998
16.62000,138.50003,38.80757,1.20435,4.31195,138.50003
16.65000,138.75010,38.68192,1.20652,4.29799,138.75010
16.68000,139.00004,38.93330,1.20870,4.32592,139.00004
16.71000,139.25004,39.08368,1.21087,4.34263,139.25004
16.74000,139.50004,38.92850,1.21304,4.32539,139.50004
16.77000,139.75004,39.03999,1.21522,4.33778,139.75004
16.80000,140.00005,39.18688,1.21739,4.35410,140.00005
16.83000,140.24998,39.10528,1.21957,4.34503,140.24998
16.86000,140.50004,39.18282,1.22174,4.35365,140.50004
16.89000,140.75004,39.25570,1.22391,4.36174,140.75004
16.92000,140.99992,39.36635,1.22609,4.37404,140.99992
16.95000,141.24991,39.35088,1.22826,4.37232,141.24991
16.98000,141.50004,39.62180,1.23044,4.40242,141.50004
17.01000,141.74998,39.51839,1.23261,4.39093,141.74998
17.04000,141.99992,39.40275,1.23478,4.37808,141.99992
17.07000,142.24998,39.59172,1.23696,4.39908,142.24998
17.10000,142.50005,39.73289,1.23913,4.41477,142.50005
17.13000,142.74999,39.92270,1.24130,4.43585,142.74999
17.16000,142.99998,39.87729,1.24348,4.43081,142.99998
17.19000,143.25003,39.98378,1.24565,4.44264,143.25003
17.22000,143.50004,39.99769,1.24783,4.44419,143.50004
17.25000,143.74998,40.08424,1.25000,4.45380,143.74998
17.28000,144.00004,40.13072,1.25217,4.45897,144.00004
17.31000,144.25009,40.14889,1.25435,4.46099,144.25009
17.34000,144.49998,40.20258,1.25652,4.46695,144.49998
17.37000,144.74991,40.05348,1.25869,4.45039,144.74991
17.40000,144.99999,40.08762,1.26087,4.45418,144.99999
17.43000,145.25004,40.33615,1.26304,4.48179,145.25004
17.46000,145.49998,40.44039,1.26522,4.49338,145.49998
17.49000,145.74997,40.48193,1.26739,4.49799,145.74997
17.52000,146.00004,40.38215,1.26957,4.48691,146.00004
17.55000,146.24998,40.39474,1.27174,4.48830,146.24998
17.58000,146.49997,40.57641,1.27391,4.50849,146.49997
17.61000,146.75003,40.68266,1.27609,4.52030,146.75003
17.64000,147.00005,40.74090,1.27826,4.52677,147.00005
17.67000,147.24999,40.86066,1.28043,4.54007,147.24999
17.70000,147.49992,40.85870,1.28261,4.53986,147.49992
17.73000,147.74998,40.76970,1.28478,4.52997,147.74998
17.76000,148.00005,40.62505,1.28696,4.51390,148.00005
17.79000,148.24991,40.74472,1.28913,4.52719,148.24991
17.82000,148.50005,40.86492,1.29130,4.54055,148.50005
17.85000,148.75010,40.67981,1.29348,4.51998,148.75010
17.88000,149.00004,33.60511,1.29565,3.73390,149.00004
17.91000,149.24997,4.86657,1.29783,0.54073,149.24997
17.94000,149.50004,-1.56527,1.30000,-0.17392,149.50004
17.97000,149.75004,-0.56503,1.30217,-0.06278,149.75004
18.00000,150.00003,0.27637,1.30435,0.03071,150.00003
18.03000,150.25004,0.34781,1.30652,0.03865,150.25004
18.06000,150.50011,0.30563,1.30870,0.03396,150.50011
18.09000,150.74998,0.23138,1.31087,0.02571,150.74998
18.12000,150.99992,0.14718,1.31304,0.01635,150.99992
18.15000,151.24998,0.08191,1.31522,0.00910,151.24998
18.18000,151.49998,0.06716,1.31739,0.00746,151.49998
18.21000,151.74999,0.05142,1.31957,0.00571,151.74999
18.24000,151.99992,0.11923,1.32174,0.01325,151.99992
18.27000,152.24998,-0.06146,1.32391,-0.00683,152.24998
18.30000,152.49997,0.23637,1.32609,0.02626,152.49997
18.33000,152.74997,0.20880,1.32826,0.02320,152.74997
18.36000,152.99991,0.07223,1.33043,0.00803,152.99991
18.39000,153.25004,0.40663,1.33261,0.04518,153.25004
18.42000,153.49998,0.32483,1.33478,0.03609,153.49998
18.45000,153.75005,0.23843,1.33696,0.02649,153.75005
18.48000,154.00010,-0.01131,1.33913,-0.00126,154.00010
18.51000,154.25004,0.12232,1.34130,0.01359,154.25004
18.54000,154.49992,0.06089,1.34348,0.00677,154.49992
18.57000,154.74997,0.14495,1.34565,0.01611,154.74997
18.60000,155.00004,0.03346,1.34783,0.00372,155.00004
18.63000,155.24998,0.13153,1.35000,0.01461,155.24998
18.66000,155.50004,0.10023,1.35217,0.01114,155.50004
18.69000,155.75004,0.15320,1.35435,0.01702,155.75004
18.72000,155.99998,0.32493,1.35652,0.03610,155.99998
18.75000,156.24992,0.18942,1.35869,0.02105,156.24992
18.78000,156.49999,0.09692,1.36087,0.01077,156.49999
18.81000,156.75010,0.18193,1.36304,0.02021,156.75010
18.84000,156.99998,0.14380,1.36522,0.01598,156.99998
18.87000,157.24996,0.18778,1.36739,0.02086,157.24996
18.90000,157.50004,0.27850,1.36957,0.03094,157.50004
18.93000,157.74997,0.29902,1.37174,0.03322,157.74997
18.96000,157.99992,0.25305,1.37391,0.02812,157.99992
18.99000,158.24998,0.23826,1.37609,0.02647,158.24998
19.02000,158.50009,0.31227,1.37826,0.03470,158.50009
19.05000,158.75004,0.24465,1.38044,0.02718,158.75004
19.08000,158.99997,0.11019,1.38261,0.01224,158.99997
19.11000,159.25003,0.31479,1.38478,0.03498,159.25003
19.14000,159.50004,0.20493,1.38696,0.02277,159.50004
19.17000,159.74997,-0.05711,1.38913,-0.00635,159.74997
19.20000,159.99997,0.10133,1.39130,0.01126,159.99997
19.23000,160.25009,0.21889,1.39348,0.02432,160.25009
19.26000,160.50003,0.18697,1.39565,0.02077,160.50003
19.29000,160.74996,0.08467,1.39783,0.00941,160.74996
19.32000,160.99999,0.24247,1.40000,0.02694,160.99999
19.35000,161.25003,0.03187,1.40217,0.00354,161.25003
19.38000,161.49992,0.00856,1.40435,0.00095,161.49992
19.41000,161.74996,0.05546,1.40652,0.00616,161.74996
19.44000,162.00004,0.11676,1.40870,0.01297,162.00004
19.47000,162.25005,0.11916,1.41087,0.01324,162.25005
19.50000,162.49992,0.27179,1.41304,0.03020,162.49992
19.53000,162.74998,0.08291,1.41522,0.00921,162.74998
19.56000,163.00002,0.12609,1.41739,0.01401,163.00002
19.59000,163.25004,0.14465,1.41957,0.01607,163.25004
19.60000,163.33329,0.07231,1.42029,0.00803,163.33329