File: NR/NR/RDSO NR Tensile 500.is_tens_RawData/Specimen_RawData_1.csv
Time,Extension,Load,Tensile strain,Tensile stress,Corrected Position
(sec),(mm),(N),(mm/mm),(MPa),(mm)
0.00000,0.00000,0.00549,0.00000,0.00061,0.00000
0.03000,0.05131,0.54657,0.00045,0.06073,0.05131
0.06000,0.23350,1.03503,0.00203,0.11500,0.23350
0.09000,0.51781,1.33240,0.00450,0.14804,0.51781
0.12000,0.83544,1.71399,0.00726,0.19044,0.83544
0.15000,1.16737,2.08344,0.01015,0.23149,1.16737
0.18000,1.47362,2.17374,0.01281,0.24153,1.47362
0.21000,1.73562,2.72146,0.01509,0.30238,1.73562
0.24000,1.98425,3.52597,0.01725,0.39177,1.98425
0.27000,2.23656,3.90404,0.01945,0.43378,2.23656
0.30000,2.49137,4.08589,0.02166,0.45399,2.49137
0.33000,2.74500,4.42788,0.02387,0.49199,2.74500
0.36000,2.99681,4.63980,0.02606,0.51553,2.99681
0.39000,3.24775,5.07364,0.02824,0.56374,3.24775
0.42000,3.49831,5.26070,0.03042,0.58452,3.49831
0.45000,3.74881,5.75667,0.03260,0.63963,3.74881
0.48000,3.99937,6.00056,0.03478,0.66673,3.99937
0.51000,4.24956,6.28507,0.03695,0.69834,4.24956
0.54000,4.49962,6.58798,0.03913,0.73200,4.49962
0.57000,4.74975,6.82838,0.04130,0.75871,4.74975
0.60000,4.99987,7.03763,0.04348,0.78196,4.99987
0.63000,5.24981,7.42812,0.04565,0.82535,5.24981
0.66000,5.49994,7.55824,0.04783,0.83980,5.49994
0.69000,5.75000,7.70450,0.05000,0.85606,5.75000
0.72000,6.00000,8.00143,0.05217,0.88905,6.00000
0.75000,6.24994,8.27057,0.05435,0.91895,6.24994
0.78000,6.50000,8.58780,0.05652,0.95420,6.50000
0.81000,6.75000,8.73609,0.05870,0.97068,6.75000
0.84000,7.00000,8.85897,0.06087,0.98433,7.00000
0.87000,7.24994,9.24801,0.06304,1.02756,7.24994
0.90000,7.50000,9.25658,0.06522,1.02851,7.50000
0.93000,7.75000,9.29797,0.06739,1.03311,7.75000
0.96000,7.99994,9.70932,0.06956,1.07881,7.99994
0.99000,8.25000,9.81894,0.07174,1.09099,8.25000
1.02000,8.50006,9.88318,0.07391,1.09813,8.50006
1.05000,8.75000,9.99026,0.07609,1.11003,8.75000
1.08000,8.99994,10.17965,0.07826,1.13107,8.99994
1.11000,9.25006,10.44771,0.08044,1.16086,9.25006
1.14000,9.50006,10.44403,0.08261,1.16045,9.50006
1.17000,9.75000,10.60149,0.08478,1.17794,9.75000
1.20000,10.00000,10.87899,0.08696,1.20878,10.00000
1.23000,10.25006,10.98761,0.08913,1.22085,10.25006
1.26000,10.50000,11.08399,0.09130,1.23155,10.50000
1.29000,10.74994,11.15219,0.09348,1.23913,10.74994
1.32000,11.00000,11.23480,0.09565,1.24831,11.00000
1.35000,11.25006,11.19449,0.09783,1.24383,11.25006
1.38000,11.49994,11.42089,0.10000,1.26899,11.49994
1.41000,11.74994,11.57459,0.10217,1.28607,11.74994
1.44000,12.00000,11.69891,0.10435,1.29988,12.00000
1.47000,12.25000,11.76396,0.10652,1.30711,12.25000
1.50000,12.49994,11.93591,0.10870,1.32621,12.49994
1.53000,12.75000,11.93777,0.11087,1.32642,12.75000
1.56000,13.00006,12.21266,0.11304,1.35696,13.00006
1.59000,13.25000,12.23012,0.11522,1.35890,13.25000
1.62000,13.50000,12.22539,0.11739,1.35838,13.50000
1.65000,13.75006,12.12383,0.11957,1.34709,13.75006
1.68000,14.00006,12.16309,0.12174,1.35145,14.00006
1.71000,14.25000,12.51735,0.12391,1.39082,14.25000
1.74000,14.50006,12.47807,0.12609,1.38645,14.50006
1.77000,14.75006,12.56570,0.12826,1.39619,14.75006
1.80000,15.00000,12.68857,0.13043,1.40984,15.00000
1.83000,15.25000,12.81830,0.13261,1.42426,15.25000
1.86000,15.50006,12.99050,0.13478,1.44339,15.50006
1.89000,15.75006,12.90752,0.13696,1.43417,15.75006
1.92000,16.00000,12.86442,0.13913,1.42938,16.00000
1.95000,16.24993,12.84233,0.14130,1.42693,16.24993
1.98000,16.50006,12.98602,0.14348,1.44289,16.50006
2.01000,16.75006,12.91169,0.14565,1.43463,16.75006
2.04000,17.00000,13.30163,0.14783,1.47796,17.00000
2.07000,17.25000,13.37192,0.15000,1.48577,17.25000
2.10000,17.50000,13.27594,0.15217,1.47510,17.50000
2.13000,17.75000,13.32612,0.15435,1.48068,17.75000
2.16000,17.99993,13.43736,0.15652,1.49304,17.99993
2.19000,18.25006,13.43508,0.15870,1.49279,18.25006
2.22000,18.50006,13.54770,0.16087,1.50530,18.50006
2.25000,18.75000,13.50831,0.16304,1.50092,18.75000
2.28000,19.00006,13.61409,0.16522,1.51268,19.00006
2.31000,19.25012,13.75795,0.16739,1.52866,19.25012
2.34000,19.50000,13.70640,0.16957,1.52293,19.50000
2.37000,19.75000,13.59097,0.17174,1.51011,19.75000
2.40000,20.00006,13.74999,0.17391,1.52778,20.00006
2.43000,20.25006,13.86831,0.17609,1.54092,20.25006
2.46000,20.50000,13.99400,0.17826,1.55489,20.50000
2.49000,20.75000,13.95560,0.18043,1.55062,20.75000
2.52000,21.00006,14.08373,0.18261,1.56486,21.00006
2.55000,21.25000,14.06603,0.18478,1.56289,21.25000
2.58000,21.50000,13.96948,0.18696,1.55216,21.50000
2.61000,21.75000,14.02331,0.18913,1.55815,21.75000
2.64000,22.00000,14.18167,0.19130,1.57574,22.00000
2.67000,22.24993,14.38730,0.19348,1.59859,22.24993
2.70000,22.49993,14.16370,0.19565,1.57374,22.49993
2.73000,22.75000,14.28659,0.19783,1.58740,22.75000
2.76000,23.00000,14.36408,0.20000,1.59601,23.00000
2.79000,23.25000,14.45583,0.20217,1.60620,23.25000
2.82000,23.50006,14.32002,0.20435,1.59111,23.50006
2.85000,23.75006,14.44138,0.20652,1.60460,23.75006
2.88000,24.00006,14.51549,0.20870,1.61283,24.00006
2.91000,24.25000,14.66060,0.21087,1.62896,24.25000
2.94000,24.50006,14.59604,0.21304,1.62178,24.50006
2.97000,24.75006,14.60956,0.21522,1.62328,24.75006
3.00000,24.99993,14.63439,0.21739,1.62604,24.99993
3.03000,25.25006,14.66745,0.21957,1.62972,25.25006
3.06000,25.50012,14.67152,0.22174,1.63017,25.50012
3.09000,25.74993,14.88523,0.22391,1.65391,25.74993
3.12000,25.99987,14.99089,0.22609,1.66565,25.99987
3.15000,26.25000,14.92207,0.22826,1.65801,26.25000
3.18000,26.50006,14.93970,0.23044,1.65997,26.50006
3.21000,26.75000,15.11885,0.23261,1.67987,26.75000
3.24000,27.00000,14.91930,0.23478,1.65770,27.00000
3.27000,27.25000,14.81852,0.23696,1.64650,27.25000
3.30000,27.49993,14.97075,0.23913,1.66342,27.49993
3.33000,27.74993,15.06392,0.24130,1.67377,27.74993
3.36000,28.00006,15.16276,0.24348,1.68475,28.00006
3.39000,28.25006,15.19206,0.24565,1.68801,28.25006
3.42000,28.50000,15.17187,0.24783,1.68576,28.50000
3.45000,28.75000,15.24714,0.25000,1.69413,28.75000
3.48000,29.00006,15.37674,0.25217,1.70853,29.00006
3.51000,29.25000,15.33886,0.25435,1.70432,29.25000
3.54000,29.50000,15.32223,0.25652,1.70247,29.50000
3.57000,29.75006,15.38257,0.25870,1.70917,29.75006
3.60000,30.00006,15.49195,0.26087,1.72133,30.00006
3.63000,30.25006,15.42200,0.26304,1.71356,30.25006
3.66000,30.49999,15.53057,0.26522,1.72562,30.49999
3.69000,30.75000,15.54358,0.26739,1.72706,30.75000
3.72000,31.00000,15.45323,0.26957,1.71703,31.00000
3.75000,31.25000,15.54451,0.27174,1.72717,31.25000
3.78000,31.49999,15.96583,0.27391,1.77398,31.49999
3.81000,31.75006,16.00771,0.27609,1.77863,31.75006
3.84000,31.99999,15.83120,0.27826,1.75902,31.99999
3.87000,32.24999,15.89216,0.28043,1.76580,32.24999
3.90000,32.50000,15.97056,0.28261,1.77451,32.50000
3.93000,32.75000,15.86505,0.28478,1.76278,32.75000
3.96000,32.99993,16.06343,0.28696,1.78483,32.99993
3.99000,33.24999,16.13428,0.28913,1.79270,33.24999
4.02000,33.50006,16.13918,0.29130,1.79324,33.50006
4.05000,33.75006,16.19480,0.29348,1.79942,33.75006
4.08000,34.00006,16.13680,0.29565,1.79298,34.00006
4.11000,34.25006,16.19803,0.29783,1.79978,34.25006
4.14000,34.50006,16.35159,0.30000,1.81684,34.50006
4.17000,34.75000,16.28999,0.30217,1.81000,34.75000
4.20000,35.00006,16.33305,0.30435,1.81478,35.00006
4.23000,35.25006,16.49809,0.30652,1.83312,35.25006
4.26000,35.49999,16.60777,0.30870,1.84531,35.49999
4.29000,35.75000,16.59158,0.31087,1.84351,35.75000
4.32000,35.99999,16.59547,0.31304,1.84394,35.99999
4.35000,36.25000,16.47933,0.31522,1.83104,36.25000
4.38000,36.50000,16.75552,0.31739,1.86172,36.50000
4.41000,36.74999,16.72576,0.31957,1.85842,36.74999
4.44000,36.99999,16.81153,0.32174,1.86795,36.99999
4.47000,37.24993,16.90955,0.32391,1.87884,37.24993
4.50000,37.49993,16.86353,0.32609,1.87373,37.49993
4.53000,37.74999,17.08299,0.32826,1.89811,37.74999
4.56000,38.00006,17.04194,0.33044,1.89355,38.00006
4.59000,38.25000,17.00560,0.33261,1.88951,38.25000
4.62000,38.50000,16.88694,0.33478,1.87633,38.50000
4.65000,38.75006,17.10293,0.33696,1.90033,38.75006
4.68000,39.00006,17.22482,0.33913,1.91387,39.00006
4.71000,39.24999,17.31551,0.34130,1.92395,39.24999
4.74000,39.49999,17.32656,0.34348,1.92517,39.49999
4.77000,39.75006,17.32082,0.34565,1.92454,39.75006
4.80000,39.99999,17.30699,0.34783,1.92300,39.99999
4.83000,40.25000,17.41127,0.35000,1.93459,40.25000
4.86000,40.50006,17.55124,0.35217,1.95014,40.50006
4.89000,40.75006,17.53098,0.35435,1.94789,40.75006
4.92000,40.99999,17.51066,0.35652,1.94563,40.99999
4.95000,41.25000,17.61418,0.35870,1.95713,41.25000
4.98000,41.50006,17.48063,0.36087,1.94229,41.50006
5.01000,41.74999,17.57544,0.36304,1.95283,41.74999
5.04000,41.99993,17.88699,0.36522,1.98744,41.99993
5.07000,42.25005,17.91143,0.36739,1.99016,42.25005
5.10000,42.50005,17.80920,0.36957,1.97880,42.50005
5.13000,42.74993,17.75510,0.37174,1.97279,42.74993
5.16000,42.99993,18.02355,0.37391,2.00262,42.99993
5.19000,43.25006,18.15957,0.37609,2.01773,43.25006
5.22000,43.50006,18.19342,0.37826,2.02149,43.50006
5.25000,43.75006,18.20096,0.38044,2.02233,43.75006
5.28000,44.00006,18.22751,0.38261,2.02528,44.00006
5.31000,44.25006,18.08162,0.38478,2.00907,44.25006
5.34000,44.49999,18.10579,0.38696,2.01175,44.49999
5.37000,44.74999,18.34913,0.38913,2.03879,44.74999
5.40000,45.00006,18.29770,0.39130,2.03308,45.00006
5.43000,45.25006,18.42366,0.39348,2.04707,45.25006
5.46000,45.49999,18.46062,0.39565,2.05118,45.49999
5.49000,45.75000,18.31017,0.39783,2.03446,45.75000
5.52000,45.99999,18.42276,0.40000,2.04697,45.99999
5.55000,46.24999,18.60441,0.40217,2.06716,46.24999
5.58000,46.49993,18.69240,0.40435,2.07693,46.49993
5.61000,46.75006,18.86803,0.40652,2.09645,46.75006
5.64000,47.00006,18.86262,0.40870,2.09585,47.00006
5.67000,47.24999,19.03388,0.41087,2.11488,47.24999
5.70000,47.49993,19.01206,0.41304,2.11245,47.49993
5.73000,47.74999,18.92840,0.41522,2.10316,47.74999
5.76000,47.99999,19.01272,0.41739,2.11252,47.99999
5.79000,48.24993,18.98909,0.41956,2.10990,48.24993
5.82000,48.50006,19.06207,0.42174,2.11801,48.50006
5.85000,48.75012,19.28979,0.42391,2.14331,48.75012
5.88000,49.00006,19.32273,0.42609,2.14697,49.00006
5.91000,49.25000,19.22002,0.42826,2.13556,49.25000
5.94000,49.50006,19.34071,0.43044,2.14897,49.50006
5.97000,49.74999,19.41078,0.43261,2.15675,49.74999
6.00000,49.99993,19.35518,0.43478,2.15058,49.99993
6.03000,50.25005,19.35263,0.43696,2.15029,50.25005
6.06000,50.50005,19.39442,0.43913,2.15494,50.50005
6.09000,50.74999,19.48641,0.44130,2.16516,50.74999
6.12000,50.99999,19.67308,0.44348,2.18590,50.99999
6.15000,51.24993,19.62169,0.44565,2.18019,51.24993
6.18000,51.49999,19.58547,0.44783,2.17616,51.49999
6.21000,51.74999,19.80232,0.45000,2.20026,51.74999
6.24000,51.99999,19.77300,0.45217,2.19700,51.99999
6.27000,52.24999,19.75196,0.45435,2.19466,52.24999
6.30000,52.49999,19.90790,0.45652,2.21199,52.49999
6.33000,52.74993,19.79798,0.45870,2.19978,52.74993
6.36000,52.99993,19.82546,0.46087,2.20283,52.99993
6.39000,53.25005,20.12232,0.46304,2.23581,53.25005
6.42000,53.50005,20.07488,0.46522,2.23054,53.50005
6.45000,53.75005,20.19302,0.46739,2.24367,53.75005
6.48000,54.00012,20.22452,0.46957,2.24717,54.00012
6.51000,54.25006,20.20911,0.47174,2.24546,54.25006
6.54000,54.49993,20.38472,0.47391,2.26497,54.49993
6.57000,54.75005,20.42086,0.47609,2.26898,54.75005
6.60000,55.00006,20.43916,0.47826,2.27102,55.00006
6.63000,55.24999,20.48694,0.48043,2.27633,55.24999
6.66000,55.49999,20.54077,0.48261,2.28231,55.49999
6.69000,55.75005,20.46267,0.48478,2.27363,55.75005
6.72000,55.99999,20.59470,0.48696,2.28830,55.99999
6.75000,56.24993,20.78324,0.48913,2.30925,56.24993
6.78000,56.49999,20.63928,0.49130,2.29325,56.49999
6.81000,56.75005,20.75732,0.49348,2.30637,56.75005
6.84000,56.99999,20.69208,0.49565,2.29912,56.99999
6.87000,57.24999,20.78502,0.49783,2.30945,57.24999
6.90000,57.49999,20.68206,0.50000,2.29801,57.49999
6.93000,57.74993,20.89264,0.50217,2.32140,57.74993
6.96000,57.99993,20.86276,0.50435,2.31808,57.99993
6.99000,58.24999,21.06861,0.50652,2.34096,58.24999
7.02000,58.50005,21.09413,0.50870,2.34379,58.50005
7.05000,58.75005,21.16353,0.51087,2.35150,58.75005
7.08000,59.00005,21.30940,0.51304,2.36771,59.00005
7.11000,59.25005,21.30837,0.51522,2.36760,59.25005
7.14000,59.50006,21.25812,0.51739,2.36201,59.50006
7.17000,59.74993,21.40051,0.51956,2.37783,59.74993
7.20000,59.99999,21.56254,0.52174,2.39584,59.99999
7.23000,60.25005,21.54386,0.52391,2.39376,60.25005
7.26000,60.50006,21.53663,0.52609,2.39296,60.50006
7.29000,60.74993,21.48890,0.52826,2.38766,60.74993
7.32000,60.99993,21.51371,0.53043,2.39041,60.99993
7.35000,61.24999,21.61655,0.53261,2.40184,61.24999
7.38000,61.49993,21.74512,0.53478,2.41613,61.49993
7.41000,61.74999,21.44748,0.53696,2.38305,61.74999
7.44000,62.00006,21.56781,0.53913,2.39642,62.00006
7.47000,62.25005,21.78394,0.54130,2.42044,62.25005
7.50000,62.49993,21.85756,0.54348,2.42862,62.49993
7.53000,62.74999,21.91159,0.54565,2.43462,62.74999
7.56000,63.00006,21.80143,0.54783,2.42238,63.00006
7.59000,63.24999,21.74491,0.55000,2.41610,63.24999
7.62000,63.50006,22.01602,0.55217,2.44622,63.50006
7.65000,63.75011,22.04837,0.55435,2.44982,63.75011
7.68000,64.00005,22.32819,0.55652,2.48091,64.00005
7.71000,64.24999,22.31124,0.55870,2.47903,64.24999
7.74000,64.49999,22.28768,0.56087,2.47641,64.49999
7.77000,64.75005,22.14151,0.56304,2.46017,64.75005
7.80000,64.99999,22.24506,0.56522,2.47167,64.99999
7.83000,65.24999,22.62139,0.56739,2.51349,65.24999
7.86000,65.49999,22.69602,0.56957,2.52178,65.49999
7.89000,65.74999,22.66565,0.57174,2.51841,65.74999
7.92000,65.99993,22.54660,0.57391,2.50518,65.99993
7.95000,66.24993,22.67625,0.57609,2.51958,66.24993
7.98000,66.50005,22.73753,0.57826,2.52639,66.50005
8.01000,66.74999,22.92589,0.58043,2.54732,66.74999
8.04000,66.99999,22.83366,0.58261,2.53707,66.99999
8.07000,67.24999,22.84086,0.58478,2.53787,67.24999
8.10000,67.49999,22.86851,0.58696,2.54095,67.49999
8.13000,67.74999,22.93909,0.58913,2.54879,67.74999
8.16000,67.99993,22.99361,0.59130,2.55485,67.99993
8.19000,68.24999,23.09466,0.59348,2.56607,68.24999
8.22000,68.50005,23.20320,0.59565,2.57813,68.50005
8.25000,68.74999,23.32480,0.59783,2.59164,68.74999
8.28000,69.00005,23.24251,0.60000,2.58250,69.00005
8.31000,69.25012,23.27974,0.60217,2.58664,69.25012
8.34000,69.50005,23.41780,0.60435,2.60198,69.50005
8.37000,69.74993,23.32407,0.60652,2.59156,69.74993
8.40000,69.99999,23.17448,0.60870,2.57494,69.99999
8.43000,70.25005,23.34107,0.61087,2.59345,70.25005
8.46000,70.49999,23.59501,0.61304,2.62167,70.49999
8.49000,70.74999,23.64125,0.61522,2.62681,70.74999
8.52000,70.99999,23.47204,0.61739,2.60800,70.99999
8.55000,71.24993,23.83172,0.61956,2.64797,71.24993
8.58000,71.49999,24.10022,0.62174,2.67780,71.49999
8.61000,71.75006,23.92415,0.62391,2.65824,71.75006
8.64000,72.00005,23.79156,0.62609,2.64351,72.00005
8.67000,72.24999,23.73537,0.62826,2.63726,72.24999
8.70000,72.49999,23.84943,0.63043,2.64994,72.49999
8.73000,72.74999,23.93654,0.63261,2.65962,72.74999
8.76000,72.99999,23.98075,0.63478,2.66453,72.99999
8.79000,73.24993,24.16745,0.63696,2.68527,73.24993
8.82000,73.49999,24.19120,0.63913,2.68791,73.49999
8.85000,73.75005,24.27979,0.64130,2.69775,73.75005
8.88000,74.00006,24.30038,0.64348,2.70004,74.00006
8.91000,74.24999,24.29759,0.64565,2.69973,74.24999
8.94000,74.50006,24.41877,0.64783,2.71320,74.50006
8.97000,74.75005,24.35510,0.65000,2.70612,74.75005
9.00000,74.99999,24.40180,0.65217,2.71131,74.99999
9.03000,75.24999,24.45808,0.65435,2.71756,75.24999
9.06000,75.50005,24.36120,0.65652,2.70680,75.50005
9.09000,75.74999,24.56707,0.65870,2.72967,75.74999
9.12000,75.99999,24.58472,0.66087,2.73164,75.99999
9.15000,76.25006,24.77958,0.66304,2.75329,76.25006
9.18000,76.50005,24.86951,0.66522,2.76328,76.50005
9.21000,76.74993,24.77544,0.66739,2.75283,76.74993
9.24000,76.99999,24.87979,0.66957,2.76442,76.99999
9.27000,77.25005,24.85795,0.67174,2.76199,77.25005
9.30000,77.49998,25.02214,0.67391,2.78024,77.49998
9.33000,77.74999,25.03326,0.67609,2.78147,77.74999
9.36000,77.99999,24.95214,0.67826,2.77246,77.99999
9.39000,78.24999,25.06318,0.68043,2.78480,78.24999
9.42000,78.49992,25.11466,0.68261,2.79052,78.49992
9.45000,78.74999,25.10443,0.68478,2.78938,78.74999
9.48000,79.00012,25.26423,0.68696,2.80714,79.00012
9.51000,79.25005,25.48181,0.68913,2.83131,79.25005
9.54000,79.49999,25.47654,0.69130,2.83073,79.49999
9.57000,79.74998,25.30846,0.69348,2.81205,79.74998
9.60000,79.99999,25.47050,0.69565,2.83006,79.99999
9.63000,80.24999,25.58313,0.69783,2.84257,80.24999
9.66000,80.49999,25.64517,0.70000,2.84946,80.49999
9.69000,80.75004,25.76277,0.70217,2.86253,80.75004
9.72000,80.99998,25.53315,0.70435,2.83702,80.99998
9.75000,81.24992,25.69584,0.70652,2.85509,81.24992
9.78000,81.49998,25.75464,0.70870,2.86163,81.49998
9.81000,81.74999,25.90519,0.71087,2.87835,81.74999
9.84000,81.99993,25.94193,0.71304,2.88244,81.99993
9.87000,82.24992,25.68369,0.71522,2.85374,82.24992
9.90000,82.49999,25.89698,0.71739,2.87744,82.49999
9.93000,82.74999,26.19242,0.71957,2.91027,82.74999
9.96000,82.99992,26.06551,0.72174,2.89617,82.99992
9.99000,83.24998,26.09157,0.72391,2.89906,83.24998
10.02000,83.50004,26.18843,0.72609,2.90983,83.50004
10.05000,83.75005,26.30817,0.72826,2.92313,83.75005
10.08000,83.99999,26.30376,0.73043,2.92264,83.99999
10.11000,84.25005,26.20775,0.73261,2.91197,84.25005
10.14000,84.50005,26.39908,0.73478,2.93323,84.50005
10.17000,84.74999,26.50140,0.73696,2.94460,84.74999
10.20000,84.99999,26.49535,0.73913,2.94393,84.99999
10.23000,85.25005,26.60069,0.74130,2.95563,85.25005
10.26000,85.50005,26.74955,0.74348,2.97217,85.50005
10.29000,85.74999,26.46405,0.74565,2.94045,85.74999
10.32000,86.00005,26.58639,0.74783,2.95404,86.00005
10.35000,86.25005,26.63336,0.75000,2.95926,86.25005
10.38000,86.49998,26.73921,0.75217,2.97102,86.49998
10.41000,86.74999,26.73696,0.75435,2.97077,86.74999
10.44000,86.99999,26.83980,0.75652,2.98220,86.99999
10.47000,87.24999,27.14657,0.75870,3.01629,87.24999
10.50000,87.49999,27.06504,0.76087,3.00723,87.49999
10.53000,87.74999,26.98108,0.76304,2.99790,87.74999
10.56000,87.99993,27.23016,0.76522,3.02557,87.99993
10.59000,88.24993,27.27417,0.76739,3.03046,88.24993
10.62000,88.49998,26.98843,0.76957,2.99871,88.49998
10.65000,88.75005,27.34475,0.77174,3.03831,88.75005
10.68000,89.00005,27.38174,0.77391,3.04242,89.00005
10.71000,89.24999,27.33339,0.77609,3.03704,89.24999
10.74000,89.49999,27.31742,0.77826,3.03527,89.49999
10.77000,89.75005,27.40147,0.78044,3.04461,89.75005
10.80000,89.99999,27.53605,0.78261,3.05956,89.99999
10.83000,90.24998,27.53164,0.78478,3.05907,90.24998
10.86000,90.50005,27.64969,0.78696,3.07219,90.50005
10.89000,90.75006,27.60769,0.78913,3.06752,90.75006
10.92000,90.99999,27.74225,0.79130,3.08247,90.99999
10.95000,91.24999,27.81780,0.79348,3.09087,91.24999
10.98000,91.50005,27.90104,0.79565,3.10012,91.50005
11.01000,91.75004,27.92561,0.79783,3.10285,91.75004
11.04000,91.99998,27.82324,0.80000,3.09147,91.99998
11.07000,92.24999,27.93776,0.80217,3.10420,92.24999
11.10000,92.49998,28.31835,0.80435,3.14648,92.49998
11.13000,92.74987,28.22212,0.80652,3.13579,92.74987
11.16000,92.99998,28.17008,0.80870,3.13001,92.99998
11.19000,93.25005,28.33968,0.81087,3.14885,93.25005
11.22000,93.50005,28.36236,0.81304,3.15137,93.50005
11.25000,93.74999,28.25377,0.81522,3.13931,93.74999
11.28000,94.00005,28.31122,0.81739,3.14569,94.00005
11.31000,94.25005,28.18267,0.81957,3.13141,94.25005
11.34000,94.50004,28.36300,0.82174,3.15144,94.50004
11.37000,94.74998,28.56740,0.82391,3.17416,94.74998
11.40000,95.00004,28.64624,0.82609,3.18292,95.00004
11.43000,95.25005,28.58197,0.82826,3.17577,95.25005
11.46000,95.49998,28.57759,0.83043,3.17529,95.49998
11.49000,95.74998,28.82088,0.83261,3.20232,95.74998
11.52000,96.00005,28.87290,0.83478,3.20810,96.00005
11.55000,96.24999,28.94300,0.83696,3.21589,96.24999
11.58000,96.49992,29.00964,0.83913,3.22329,96.49992
11.61000,96.74999,28.90908,0.84130,3.21212,96.74999
11.64000,97.00004,28.88226,0.84348,3.20914,97.00004
11.67000,97.24999,29.04655,0.84565,3.22739,97.24999
11.70000,97.49998,29.00281,0.84783,3.22253,97.49998
11.73000,97.75005,29.04787,0.85000,3.22754,97.75005
11.76000,97.99998,28.99021,0.85217,3.22113,97.99998
11.79000,98.24992,29.20564,0.85435,3.24507,98.24992
11.82000,98.49999,29.14258,0.85652,3.23806,98.49999
11.85000,98.75004,29.37600,0.85870,3.26400,98.75004
11.88000,98.99999,29.45364,0.86087,3.27263,98.99999
11.91000,99.24999,29.32574,0.86304,3.25842,99.24999
11.94000,99.50005,29.50012,0.86522,3.27779,99.50005
11.97000,99.75005,29.53504,0.86739,3.28167,99.75005
12.00000,99.99998,29.40375,0.86957,3.26708,99.99998
12.03000,100.25005,29.73173,0.87174,3.30353,100.25005
12.06000,100.50005,29.90041,0.87391,3.32227,100.50005
12.09000,100.74999,29.80359,0.87609,3.31151,100.74999
12.12000,100.99999,29.74452,0.87826,3.30495,100.99999
12.15000,101.25005,29.96112,0.88044,3.32901,101.25005
12.18000,101.50004,30.01982,0.88261,3.33554,101.50004
12.21000,101.74998,29.80163,0.88478,3.31129,101.74998
12.24000,101.99999,29.98522,0.88696,3.33169,101.99999
12.27000,102.25005,30.02137,0.88913,3.33571,102.25005
12.30000,102.49998,30.07309,0.89130,3.34145,102.49998
12.33000,102.74992,30.02568,0.89348,3.33619,102.74992
12.36000,102.99998,30.19366,0.89565,3.35485,102.99998
12.39000,103.25004,30.21556,0.89783,3.35728,103.25004
12.42000,103.49998,30.31680,0.90000,3.36853,103.49998
12.45000,103.74992,30.24967,0.90217,3.36107,103.74992
12.48000,104.00005,30.36268,0.90435,3.37363,104.00005
12.51000,104.25005,30.43791,0.90652,3.38199,104.25005
12.54000,104.49998,30.60019,0.90870,3.40002,104.49998
12.57000,104.75005,30.65304,0.91087,3.40589,104.75005
12.60000,105.00005,30.67866,0.91304,3.40874,105.00005
12.63000,105.24998,30.48207,0.91522,3.38690,105.24998
12.66000,105.49999,30.82291,0.91739,3.42477,105.49999
12.69000,105.75005,30.66720,0.91957,3.40747,105.75005
12.72000,106.00004,31.01223,0.92174,3.44580,106.00004
12.75000,106.24998,31.03545,0.92391,3.44838,106.24998
12.78000,106.50005,30.96418,0.92609,3.44046,106.50005
12.81000,106.75005,30.97760,0.92826,3.44196,106.75005
12.84000,106.99992,31.13258,0.93043,3.45918,106.99992
12.87000,107.24992,31.04103,0.93261,3.44900,107.24992
12.90000,107.50005,31.11313,0.93478,3.45701,107.50005
12.93000,107.74999,31.11362,0.93696,3.45707,107.74999
12.96000,107.99998,31.23955,0.93913,3.47106,107.99998
12.99000,108.24999,31.40605,0.94130,3.48956,108.24999
13.02000,108.50005,31.22535,0.94348,3.46948,108.50005
13.05000,108.75005,31.21546,0.94565,3.46838,108.75005
13.08000,108.99998,31.25900,0.94783,3.47322,108.99998
13.11000,109.25005,31.47531,0.95000,3.49726,109.25005
13.14000,109.50005,31.50646,0.95217,3.50072,109.50005
13.17000,109.74999,31.49593,0.95435,3.49955,109.74999
13.20000,109.99999,31.66021,0.95652,3.51780,109.99999
13.23000,110.25004,31.79080,0.95870,3.53231,110.25004
13.26000,110.49998,31.88362,0.96087,3.54262,110.49998
13.29000,110.74998,31.87451,0.96304,3.54161,110.74998
13.32000,111.00005,31.87202,0.96522,3.54134,111.00005
13.35000,111.25005,32.17380,0.96739,3.57487,111.25005
13.38000,111.49999,32.21734,0.96957,3.57970,111.49999
13.41000,111.74999,32.00618,0.97174,3.55624,111.74999
13.44000,112.00004,32.10385,0.97391,3.56709,112.00004
13.47000,112.24998,32.01842,0.97609,3.55760,112.24998
13.50000,112.49992,32.21670,0.97826,3.57963,112.49992
13.53000,112.74998,32.36576,0.98043,3.59619,112.74998
13.56000,113.00005,32.30762,0.98261,3.58974,113.00005
13.59000,113.24998,32.35684,0.98478,3.59520,113.24998
13.62000,113.49998,32.34102,0.98696,3.59345,113.49998
13.65000,113.75004,32.33970,0.98913,3.59330,113.75004
13.68000,114.00005,32.48297,0.99130,3.60922,114.00005
13.71000,114.25004,32.44315,0.99348,3.60479,114.25004
13.74000,114.50005,32.51466,0.99565,3.61274,114.50005
13.77000,114.75004,32.53842,0.99783,3.61538,114.75004
13.80000,114.99998,32.79303,1.00000,3.64367,114.99998
13.83000,115.24999,32.89163,1.00217,3.65463,115.24999
13.86000,115.50005,32.92029,1.00435,3.65781,115.50005
13.89000,115.75005,32.83050,1.00652,3.64783,115.75005
13.92000,115.99992,32.94091,1.00870,3.66010,115.99992
13.95000,116.24992,33.00302,1.01087,3.66700,116.24992
13.98000,116.50004,33.08981,1.01304,3.67665,116.50004
14.01000,116.74998,33.18660,1.01522,3.68740,116.74998
14.04000,116.99999,33.11930,1.01739,3.67992,116.99999
14.07000,117.24998,33.05797,1.01957,3.67311,117.24998
14.10000,117.49999,33.26453,1.02174,3.69606,117.49999
14.13000,117.74993,33.35226,1.02391,3.70581,117.74993
14.16000,117.99992,33.38596,1.02609,3.70955,117.99992
14.19000,118.24999,33.35823,1.02826,3.70647,118.24999
14.22000,118.50005,33.56519,1.03044,3.72947,118.50005
14.25000,118.75005,33.52987,1.03261,3.72554,118.75005
14.28000,119.00004,33.56445,1.03478,3.72938,119.00004
14.31000,119.25004,33.46884,1.03696,3.71876,119.25004
14.34000,119.49998,33.60119,1.03913,3.73347,119.49998
14.37000,119.74998,33.71527,1.04130,3.74614,119.74998
14.40000,120.00005,33.68313,1.04348,3.74257,120.00005
14.43000,120.25005,33.76077,1.04565,3.75120,120.25005
14.46000,120.49999,33.94553,1.04783,3.77173,120.49999
14.49000,120.74999,34.00612,1.05000,3.77846,120.74999
14.52000,121.00005,33.97820,1.05217,3.77536,121.00005
14.55000,121.24998,33.99755,1.05435,3.77751,121.24998
14.58000,121.49998,34.03066,1.05652,3.78118,121.49998
14.61000,121.75005,34.12422,1.05870,3.79158,121.75005
14.64000,121.99998,34.17266,1.06087,3.79696,121.99998
14.67000,122.24992,34.28488,1.06304,3.80943,122.24992
14.70000,122.49999,34.25510,1.06522,3.80612,122.49999
14.73000,122.74999,34.33754,1.06739,3.81528,122.74999
14.76000,122.99999,34.53920,1.06957,3.83769,122.99999
14.79000,123.24998,34.54199,1.07174,3.83800,123.24998
14.82000,123.50004,34.52098,1.07391,3.83566,123.50004
14.85000,123.75005,34.64617,1.07609,3.84958,123.75005
14.88000,123.99998,34.66699,1.07826,3.85189,123.99998
14.91000,124.24998,34.70706,1.08043,3.85634,124.24998
14.94000,124.49998,34.70672,1.08261,3.85630,124.49998
14.97000,124.75004,34.73248,1.08478,3.85916,124.75004
15.00000,124.99998,34.81335,1.08696,3.86815,124.99998
15.03000,125.24999,34.88134,1.08913,3.87570,125.24999
15.06000,125.50004,34.96941,1.09130,3.88549,125.50004
15.09000,125.74998,35.10401,1.09348,3.90045,125.74998
15.12000,125.99992,35.07879,1.09565,3.89764,125.99992
15.15000,126.24999,35.14100,1.09783,3.90456,126.24999
15.18000,126.50005,35.29705,1.10000,3.92189,126.50005
15.21000,126.74998,35.21016,1.10217,3.91224,126.74998
15.24000,126.99998,35.22044,1.10435,3.91338,126.99998
15.27000,127.25005,35.47094,1.10652,3.94122,127.25005
15.30000,127.49991,35.52354,1.10869,3.94706,127.49991
15.33000,127.74984,35.41099,1.11087,3.93455,127.74984
15.36000,128.00003,35.43533,1.11304,3.93726,128.00003
15.39000,128.25004,35.69680,1.11522,3.96631,128.25004
15.42000,128.50004,35.68641,1.11739,3.96516,128.50004
15.45000,128.75005,35.62621,1.11957,3.95847,128.75005
15.48000,129.00010,35.83125,1.12174,3.98125,129.00010
15.51000,129.25004,36.06372,1.12391,4.00708,129.25004
15.54000,129.49998,35.82626,1.12609,3.98070,129.49998
15.57000,129.75005,35.95004,1.12826,3.99445,129.75005
15.60000,130.00011,36.13920,1.13044,4.01547,130.00011
15.63000,130.25003,36.13377,1.13261,4.01486,130.25003
15.66000,130.49997,36.11927,1.13478,4.01325,130.49997
15.69000,130.74997,36.10614,1.13696,4.01179,130.74997
15.72000,130.99998,36.21900,1.13913,4.02433,130.99998
15.75000,131.24992,36.07690,1.14130,4.00854,131.24992
15.78000,131.49998,36.29066,1.14348,4.03230,131.49998
15.81000,131.75005,36.38896,1.14565,4.04322,131.75005
15.84000,131.99999,36.52220,1.14783,4.05802,131.99999
15.87000,132.24992,36.66155,1.15000,4.07351,132.24992
15.90000,132.49998,36.62457,1.15217,4.06940,132.49998
15.93000,132.74997,36.57319,1.15435,4.06369,132.74997
15.96000,132.99991,36.69265,1.15652,4.07696,132.99991
15.99000,133.24998,36.71166,1.15870,4.07907,133.24998
16.02000,133.50010,36.91699,1.16087,4.10189,133.50010
16.05000,133.75004,36.79850,1.16304,4.08872,133.75004
16.08000,133.99998,36.72518,1.16522,4.08058,133.99998
16.11000,134.25005,36.94805,1.16739,4.10534,134.25005
16.14000,134.50004,36.94629,1.16957,4.10514,134.50004
16.17000,134.74992,36.96171,1.17174,4.10686,134.74992
16.20000,134.99998,37.09411,1.17391,4.12157,134.99998
16.23000,135.25004,36.98655,1.17609,4.10962,135.25004
16.26000,135.50005,37.06458,1.17826,4.11829,135.50005
16.29000,135.74998,37.18160,1.18043,4.13129,135.74998
16.32000,135.99998,37.21672,1.18261,4.13519,135.99998
16.35000,136.25003,37.38923,1.18478,4.15436,136.25003
16.38000,136.49997,37.36846,1.18696,4.15205,136.49997
16.41000,136.74999,37.26599,1.18913,4.14067,136.74999
16.44000,137.00004,37.34143,1.19130,4.14905,137.00004
16.47000,137.24998,37.50243,1.19348,4.16694,137.24998
16.50000,137.49992,37.41916,1.19565,4.15768,137.49992
16.53000,137.74998,37.59354,1.19783,4.17706,137.74998
16.56000,138.00004,37.84633,1.20000,4.20515,138.00004
16.59000,138.24998,37.89492,1.20217,4.21055,138.24998
16.62000,138.50003,37.74078,1.20435,4.19342,138.50003
16.65000,138.75005,37.85324,1.20652,4.20592,138.75005
16.68000,139.00004,37.94988,1.20870,4.21665,139.00004
16.71000,139.25004,38.08302,1.21087,4.23145,139.25004
16.74000,139.50004,37.93073,1.21304,4.21453,139.50004
16.77000,139.75004,38.10903,1.21522,4.23434,139.75004
16.80000,140.00005,38.32092,1.21739,4.25788,140.00005
16.83000,140.24998,38.44113,1.21957,4.27124,140.24998
16.86000,140.50004,38.35369,1.22174,4.26152,140.50004
16.89000,140.75004,38.20665,1.22391,4.24518,140.75004
16.92000,140.99992,38.19548,1.22609,4.24394,140.99992
16.95000,141.24999,38.55462,1.22826,4.28385,141.24999
16.98000,141.50004,38.54360,1.23044,4.28262,141.50004
17.01000,141.75004,38.56770,1.23261,4.28530,141.75004
17.04000,141.99992,38.56314,1.23478,4.28479,141.99992
17.07000,142.24998,38.53003,1.23696,4.28111,142.24998
17.10000,142.50005,38.61639,1.23913,4.29071,142.50005
17.13000,142.74999,38.87918,1.24130,4.31991,142.74999
17.16000,142.99998,38.85405,1.24348,4.31712,142.99998
17.19000,143.25003,39.00305,1.24565,4.33367,143.25003
17.22000,143.50004,38.84430,1.24783,4.31603,143.50004
17.25000,143.74998,38.90161,1.25000,4.32240,143.74998
17.28000,144.00004,38.89803,1.25217,4.32200,144.00004
17.31000,144.25009,38.93648,1.25435,4.32628,144.25009
17.34000,144.49998,39.06296,1.25652,4.34033,144.49998
17.37000,144.74991,39.25604,1.25869,4.36178,144.74991
17.40000,144.99999,39.36454,1.26087,4.37384,144.99999
17.43000,145.25004,39.28916,1.26304,4.36546,145.25004
17.46000,145.49998,39.30953,1.26522,4.36773,145.49998
17.49000,145.74997,39.71315,1.26739,4.41257,145.74997
17.52000,146.00004,39.57541,1.26957,4.39727,146.00004
17.55000,146.24998,39.66069,1.27174,4.40674,146.24998
17.58000,146.49997,39.67440,1.27391,4.40827,146.49997
17.61000,146.75003,39.75390,1.27609,4.41710,146.75003
17.64000,147.00005,39.73426,1.27826,4.41492,147.00005
17.67000,147.24999,39.86587,1.28043,4.42954,147.24999
17.70000,147.49992,39.67827,1.28261,4.40870,147.49992
17.73000,147.74998,39.84265,1.28478,4.42696,147.74998
17.76000,147.99997,39.98681,1.28696,4.44298,147.99997
17.79000,148.24999,39.99749,1.28913,4.44417,148.24999
17.82000,148.50005,40.11269,1.29130,4.45697,148.50005
17.85000,148.75010,40.33649,1.29348,4.48183,148.75010
17.88000,148.99998,40.29417,1.29565,4.47713,148.99998
17.91000,149.24997,40.13797,1.29783,4.45977,149.24997
17.94000,149.50004,40.42990,1.30000,4.49221,149.50004
17.97000,149.74998,40.21869,1.30217,4.46874,149.74998
18.00000,149.99998,40.28100,1.30435,4.47567,149.99998
18.03000,150.25004,40.38352,1.30652,4.48706,150.25004
18.06000,150.50004,40.62765,1.30870,4.51418,150.50004
18.09000,150.74998,40.67344,1.31087,4.51927,150.74998
18.12000,150.99992,40.64650,1.31304,4.51628,150.99992
18.15000,151.24998,40.79815,1.31522,4.53313,151.24998
18.18000,151.49998,40.87515,1.31739,4.54168,151.49998
18.21000,151.74999,41.07716,1.31957,4.56413,151.74999
18.24000,151.99998,41.09376,1.32174,4.56597,151.99998
18.27000,152.24998,41.12624,1.32391,4.56958,152.24998
18.30000,152.49997,41.02871,1.32609,4.55875,152.49997
18.33000,152.74997,41.10307,1.32826,4.56701,152.74997
18.36000,152.99998,41.14093,1.33043,4.57121,152.99998
18.39000,153.25004,41.28190,1.33261,4.58688,153.25004
18.42000,153.50004,41.39926,1.33478,4.59992,153.50004
18.45000,153.75005,41.38231,1.33696,4.59803,153.75005
18.48000,154.00010,41.36008,1.33913,4.59556,154.00010
18.51000,154.25004,41.51506,1.34130,4.61278,154.25004
18.54000,154.49992,41.43002,1.34348,4.60334,154.49992
18.57000,154.74997,41.37321,1.34565,4.59702,154.74997
18.60000,155.00004,41.60548,1.34783,4.62283,155.00004
18.63000,155.24998,41.64956,1.35000,4.62773,155.24998
18.66000,155.49998,41.68703,1.35217,4.63189,155.49998
18.69000,155.75004,41.84530,1.35435,4.64948,155.75004
18.72000,155.99998,41.91877,1.35652,4.65764,155.99998
18.75000,156.24992,41.95085,1.35869,4.66121,156.24992
18.78000,156.49999,42.03579,1.36087,4.67064,156.49999
18.81000,156.75010,42.04607,1.36304,4.67179,156.75010
18.84000,156.99998,42.27272,1.36522,4.69697,156.99998
18.87000,157.24996,42.28971,1.36739,4.69886,157.24996
18.90000,157.50004,42.27027,1.36957,4.69670,157.50004
18.93000,157.74991,42.22809,1.37174,4.69201,157.74991
18.96000,157.99992,42.37009,1.37391,4.70779,157.99992
18.99000,158.24998,42.39664,1.37609,4.71074,158.24998
19.02000,158.50004,42.52943,1.37826,4.72549,158.50004
19.05000,158.75004,42.48295,1.38044,4.72033,158.75004
19.08000,158.99997,42.51043,1.38261,4.72338,158.99997
19.11000,159.25003,42.51209,1.38478,4.72357,159.25003
19.14000,159.50004,42.72394,1.38696,4.74710,159.50004
19.17000,159.74997,42.74216,1.38913,4.74913,159.74997
19.20000,159.99997,42.83895,1.39130,4.75988,159.99997
19.23000,160.25003,42.86374,1.39348,4.76264,160.25003
19.26000,160.50003,42.95950,1.39565,4.77328,160.50003
19.29000,160.74996,43.03145,1.39783,4.78127,160.74996
19.32000,160.99999,43.07323,1.40000,4.78591,160.99999
19.35000,161.25003,43.02528,1.40217,4.78059,161.25003
19.38000,161.49998,43.11840,1.40435,4.79093,161.49998
19.41000,161.74991,43.30130,1.40652,4.81125,161.74991
19.44000,162.00004,43.29791,1.40870,4.81088,162.00004
19.47000,162.24997,43.20460,1.41087,4.80051,162.24997
19.50000,162.49992,43.19628,1.41304,4.79959,162.49992
19.53000,162.74998,43.28773,1.41522,4.80975,162.74998
19.56000,163.00002,43.43967,1.41739,4.82663,163.00002
19.59000,163.24999,43.37202,1.41957,4.81911,163.24999
19.62000,163.49997,43.54229,1.42174,4.83803,163.49997
19.65000,163.75003,43.68727,1.42391,4.85414,163.75003
19.68000,164.00011,43.74375,1.42609,4.86042,164.00011
19.71000,164.24991,43.72450,1.42826,4.85828,164.24991
19.74000,164.49997,43.84407,1.43043,4.87156,164.49997
19.77000,164.75003,43.86351,1.43261,4.87372,164.75003
19.80000,164.99998,44.01066,1.43478,4.89007,164.99998
19.83000,165.24997,43.88129,1.43696,4.87570,165.24997
19.86000,165.50004,43.97485,1.43913,4.88609,165.50004
19.89000,165.74997,43.81414,1.44130,4.86824,165.74997
19.92000,165.99992,43.99415,1.44348,4.88824,165.99992
19.95000,166.24996,43.92567,1.44565,4.88063,166.24996
19.98000,166.50004,40.43559,1.44783,4.49284,166.50004
20.01000,166.74997,7.76110,1.45000,0.86234,166.74997
20.04000,166.99998,-2.10337,1.45217,-0.23371,166.99998
20.07000,167.24998,-0.89909,1.45435,-0.09990,167.24998
20.10000,167.50002,-0.01261,1.45652,-0.00140,167.50002
20.13000,167.74997,-0.05329,1.45870,-0.00592,167.74997
20.16000,167.99998,-0.13291,1.46087,-0.01477,167.99998
20.19000,168.25004,-0.19186,1.46304,-0.02132,168.25004
20.22000,168.50004,0.02268,1.46522,0.00252,168.50004
20.25000,168.74997,-0.08449,1.46739,-0.00939,168.74997
20.28000,168.99997,-0.04697,1.46957,-0.00522,168.99997
20.31000,169.25003,-0.04040,1.47174,-0.00449,169.25003
20.34000,169.49998,0.10564,1.47391,0.01174,169.49998
20.37000,169.74997,0.08318,1.47609,0.00924,169.74997
20.40000,170.00005,-0.04374,1.47826,-0.00486,170.00005
20.43000,170.25003,-0.14417,1.48044,-0.01602,170.25003
20.46000,170.49998,-0.13516,1.48261,-0.01502,170.49998
20.49000,170.74997,-0.10641,1.48478,-0.01182,170.74997
20.52000,171.00003,-0.18093,1.48696,-0.02010,171.00003
20.55000,171.24997,-0.09627,1.48913,-0.01070,171.24997
20.58000,171.49998,-0.10697,1.49130,-0.01189,171.49998
20.61000,171.75004,-0.05106,1.49348,-0.00567,171.75004
20.64000,171.99997,0.03998,1.49565,0.00444,171.99997
20.67000,172.24997,-0.02441,1.49783,-0.00271,172.24997
20.70000,172.49998,-0.05471,1.50000,-0.00608,172.49998
20.73000,172.74998,-0.17648,1.50217,-0.01961,172.74998
20.76000,172.99997,-0.08748,1.50435,-0.00972,172.99997
20.79000,173.24997,0.01602,1.50652,0.00178,173.24997
20.82000,173.50005,0.05298,1.50870,0.00589,173.50005
20.85000,173.75009,-0.04988,1.51087,-0.00554,173.75009
20.88000,174.00004,0.02557,1.51304,0.00284,174.00004
20.91000,174.25003,-0.06933,1.51522,-0.00770,174.25003
20.94000,174.50003,-0.25318,1.51739,-0.02813,174.50003
20.97000,174.75003,-0.26127,1.51957,-0.02903,174.75003
21.00000,174.99998,-0.23041,1.52174,-0.02560,174.99998
21.03000,175.24997,-0.10237,1.52391,-0.01137,175.24997
21.06000,175.50003,-0.10073,1.52609,-0.01119,175.50003
21.09000,175.74998,-0.15554,1.52826,-0.01728,175.74998
21.12000,175.99991,0.03924,1.53043,0.00436,175.99991
21.15000,176.24998,-0.11473,1.53261,-0.01275,176.24998
21.18000,176.50003,-0.13119,1.53478,-0.01458,176.50003
21.21000,176.74997,-0.03431,1.53696,-0.00381,176.74997
21.24000,176.99996,0.00378,1.53913,0.00042,176.99996
21.26000,177.16667,0.01649,1.54058,0.00183,177.16667