File: V_8/NR/RDSO NR Tensile 500.is_tens_RawData/Specimen_RawData_6.csv
Time,Extension,Load,Tensile strain,Tensile stress,Corrected Position
(sec),(mm),(N),(mm/mm),(MPa),(mm)
0.00000,0.00000,-0.17691,0.00000,-0.01966,0.00000
0.02000,0.01987,-0.03611,0.00017,-0.00401,0.01987
0.04000,0.09769,0.49875,0.00085,0.05542,0.09769
0.06000,0.23400,0.91900,0.00203,0.10211,0.23400
0.08000,0.41781,1.21928,0.00363,0.13548,0.41781
0.10000,0.62175,1.15228,0.00541,0.12803,0.62175
0.12000,0.83537,1.34774,0.00726,0.14975,0.83537
0.14000,1.05575,1.73397,0.00918,0.19266,1.05575
0.16000,1.27475,2.22117,0.01108,0.24680,1.27475
0.18000,1.47337,2.30057,0.01281,0.25562,1.47337
0.20000,1.65131,2.49716,0.01436,0.27746,1.65131
0.22000,1.81869,2.79512,0.01581,0.31057,1.81869
0.24000,1.98431,3.32440,0.01725,0.36938,1.98431
0.26000,2.15200,3.68184,0.01871,0.40909,2.15200
0.28000,2.32150,3.90278,0.02019,0.43364,2.32150
0.30000,2.49137,4.08685,0.02166,0.45409,2.49137
0.32000,2.66069,4.33845,0.02314,0.48205,2.66069
0.34000,2.82912,4.52973,0.02460,0.50330,2.82912
0.36000,2.99681,4.81417,0.02606,0.53491,2.99681
0.38000,3.16412,5.05318,0.02751,0.56146,3.16412
0.40000,3.33131,5.11149,0.02897,0.56794,3.33131
0.42000,3.49831,5.39595,0.03042,0.59955,3.49831
0.44000,3.66531,5.76861,0.03187,0.64096,3.66531
0.46000,3.83237,5.98670,0.03332,0.66519,3.83237
0.48000,3.99937,6.18506,0.03478,0.68723,3.99937
0.50000,4.16619,6.33769,0.03623,0.70419,4.16619
0.52000,4.33294,6.37859,0.03768,0.70873,4.33294
0.54000,4.49962,6.72837,0.03913,0.74760,4.49962
0.56000,4.66637,6.94088,0.04058,0.77121,4.66637
0.58000,4.83312,6.91627,0.04203,0.76847,4.83312
0.60000,4.99987,7.19500,0.04348,0.79944,4.99987
0.62000,5.16650,7.40144,0.04493,0.82238,5.16650
0.64000,5.33319,7.59651,0.04638,0.84406,5.33319
0.66000,5.49994,7.86402,0.04783,0.87378,5.49994
0.68000,5.66662,7.96103,0.04927,0.88456,5.66662
0.70000,5.83331,7.89711,0.05072,0.87746,5.83331
0.72000,6.00000,8.03808,0.05217,0.89312,6.00000
0.74000,6.16656,8.39291,0.05362,0.93255,6.16656
0.76000,6.33331,8.52898,0.05507,0.94766,6.33331
0.78000,6.50000,8.75624,0.05652,0.97292,6.50000
0.80000,6.66669,8.79119,0.05797,0.97680,6.66669
0.82000,6.83331,8.78212,0.05942,0.97579,6.83331
0.84000,7.00000,8.99238,0.06087,0.99915,7.00000
0.86000,7.16656,9.26291,0.06232,1.02921,7.16656
0.88000,7.33331,9.22904,0.06377,1.02545,7.33331
0.90000,7.50000,9.54541,0.06522,1.06060,7.50000
0.92000,7.66669,9.84803,0.06667,1.09423,7.66669
0.94000,7.83331,9.86517,0.06812,1.09613,7.83331
0.96000,7.99994,9.95645,0.06956,1.10627,7.99994
0.98000,8.16662,10.00791,0.07101,1.11199,8.16662
1.00000,8.33337,10.11231,0.07246,1.12359,8.33337
1.02000,8.50006,10.22076,0.07391,1.13564,8.50006
1.04000,8.66675,10.31965,0.07536,1.14663,8.66675
1.06000,8.83331,10.33920,0.07681,1.14880,8.83331
1.08000,9.00000,10.45639,0.07826,1.16182,9.00000
1.10000,9.16669,10.70639,0.07971,1.18960,9.16669
1.12000,9.33344,10.73140,0.08116,1.19238,9.33344
1.14000,9.50006,10.89074,0.08261,1.21008,9.50006
1.16000,9.66669,11.11052,0.08406,1.23450,9.66669
1.18000,9.83331,10.98760,0.08551,1.22084,9.83331
1.20000,10.00000,11.01158,0.08696,1.22351,10.00000
1.22000,10.16669,11.22722,0.08841,1.24747,10.16669
1.24000,10.33337,11.33141,0.08986,1.25905,10.33337
1.26000,10.50000,11.38372,0.09130,1.26486,10.50000
1.28000,10.66662,11.50539,0.09275,1.27838,10.66662
1.30000,10.83331,11.56561,0.09420,1.28507,10.83331
1.32000,11.00000,11.61854,0.09565,1.29095,11.00000
1.34000,11.16669,11.62956,0.09710,1.29217,11.16669
1.36000,11.33337,11.69841,0.09855,1.29982,11.33337
1.38000,11.49994,11.73769,0.10000,1.30419,11.49994
1.40000,11.66656,11.85481,0.10145,1.31720,11.66656
1.42000,11.83331,11.98255,0.10290,1.33139,11.83331
1.44000,12.00000,11.99945,0.10435,1.33327,12.00000
1.46000,12.16669,12.29736,0.10580,1.36637,12.16669
1.48000,12.33331,12.30111,0.10725,1.36679,12.33331
1.50000,12.49994,12.15950,0.10870,1.35106,12.49994
1.52000,12.66662,12.23697,0.11014,1.35966,12.66662
1.54000,12.83337,12.30858,0.11159,1.36762,12.83337
1.56000,13.00006,12.52280,0.11304,1.39142,13.00006
1.58000,13.16662,12.70519,0.11449,1.41169,13.16662
1.60000,13.33331,12.61721,0.11594,1.40191,13.33331
1.62000,13.50000,12.60399,0.11739,1.40044,13.50000
1.64000,13.66668,12.71442,0.11884,1.41271,13.66668
1.66000,13.83337,12.62025,0.12029,1.40225,13.83337
1.68000,14.00006,12.80692,0.12174,1.42299,14.00006
1.70000,14.16669,13.01157,0.12319,1.44573,14.16669
1.72000,14.33331,12.89068,0.12464,1.43230,14.33331
1.74000,14.50006,12.89602,0.12609,1.43289,14.50006
1.76000,14.66669,13.13550,0.12754,1.45950,14.66669
1.78000,14.83337,13.00143,0.12899,1.44460,14.83337
1.80000,15.00000,13.09905,0.13043,1.45545,15.00000
1.82000,15.16662,13.18355,0.13188,1.46484,15.16662
1.84000,15.33337,13.08230,0.13333,1.45359,15.33337
1.86000,15.50006,13.11713,0.13478,1.45746,15.50006
1.88000,15.66668,13.20187,0.13623,1.46687,15.66668
1.90000,15.83337,13.18169,0.13768,1.46463,15.83337
1.92000,16.00000,13.33738,0.13913,1.48193,16.00000
1.94000,16.16656,13.48829,0.14058,1.49870,16.16656
1.96000,16.33331,13.49510,0.14203,1.49946,16.33331
1.98000,16.50006,13.42919,0.14348,1.49213,16.50006
2.00000,16.66675,13.56047,0.14493,1.50672,16.66675
2.02000,16.83337,13.62779,0.14638,1.51420,16.83337
2.04000,17.00000,13.71684,0.14783,1.52409,17.00000
2.06000,17.16662,13.83822,0.14927,1.53758,17.16662
2.08000,17.33331,13.72683,0.15072,1.52520,17.33331
2.10000,17.50000,13.64996,0.15217,1.51666,17.50000
2.12000,17.66669,13.73788,0.15362,1.52643,17.66669
2.14000,17.83325,13.63227,0.15507,1.51470,17.83325
2.16000,17.99993,13.83168,0.15652,1.53685,17.99993
2.18000,18.16662,13.96175,0.15797,1.55131,18.16662
2.20000,18.33337,13.77983,0.15942,1.53109,18.33337
2.22000,18.50006,13.85654,0.16087,1.53962,18.50006
2.24000,18.66662,13.84738,0.16232,1.53860,18.66662
2.26000,18.83337,13.80944,0.16377,1.53438,18.83337
2.28000,19.00006,13.67357,0.16522,1.51929,19.00006
2.30000,19.16675,13.84932,0.16667,1.53881,19.16675
2.32000,19.33337,13.84439,0.16812,1.53827,19.33337
2.34000,19.50000,13.95688,0.16957,1.55076,19.50000
2.36000,19.66662,14.11720,0.17101,1.56858,19.66662
2.38000,19.83337,14.07299,0.17246,1.56367,19.83337
2.40000,20.00006,14.25156,0.17391,1.58351,20.00006
2.42000,20.16668,14.31915,0.17536,1.59102,20.16668
2.44000,20.33331,14.14103,0.17681,1.57123,20.33331
2.46000,20.50000,14.14066,0.17826,1.57118,20.50000
2.48000,20.66662,14.23831,0.17971,1.58203,20.66662
2.50000,20.83337,14.19834,0.18116,1.57759,20.83337
2.52000,21.00006,14.23748,0.18261,1.58194,21.00006
2.54000,21.16662,14.37568,0.18406,1.59730,21.16662
2.56000,21.33331,14.49022,0.18551,1.61002,21.33331
2.58000,21.49994,14.43267,0.18696,1.60363,21.49994
2.60000,21.66662,14.54021,0.18841,1.61558,21.66662
2.62000,21.83337,14.39603,0.18986,1.59956,21.83337
2.64000,22.00000,14.42241,0.19130,1.60249,22.00000
2.66000,22.16662,14.55686,0.19275,1.61743,22.16662
2.68000,22.33331,14.59683,0.19420,1.62187,22.33331
2.70000,22.49993,14.54839,0.19565,1.61649,22.49993
2.72000,22.66662,14.67655,0.19710,1.63073,22.66662
2.74000,22.83331,14.65076,0.19855,1.62786,22.83331
2.76000,23.00000,14.82793,0.20000,1.64755,23.00000
2.78000,23.16662,14.90481,0.20145,1.65609,23.16662
2.80000,23.33331,14.77689,0.20290,1.64188,23.33331
2.82000,23.50006,14.78889,0.20435,1.64321,23.50006
2.84000,23.66675,14.76367,0.20580,1.64041,23.66675
2.86000,23.83337,14.61753,0.20725,1.62417,23.83337
2.88000,24.00006,14.82259,0.20870,1.64695,24.00006
2.90000,24.16668,15.00268,0.21015,1.66696,24.16668
2.92000,24.33337,14.89969,0.21159,1.65552,24.33337
2.94000,24.50006,15.00547,0.21304,1.66727,24.50006
2.96000,24.66668,14.86805,0.21449,1.65201,24.66668
2.98000,24.83331,14.78343,0.21594,1.64260,24.83331
3.00000,24.99999,15.05651,0.21739,1.67295,24.99999
3.02000,25.16662,15.11078,0.21884,1.67898,25.16662
3.04000,25.33337,15.04267,0.22029,1.67141,25.33337
3.06000,25.50012,15.14970,0.22174,1.68330,25.50012
3.08000,25.66668,15.16882,0.22319,1.68542,25.66668
3.10000,25.83325,15.10375,0.22464,1.67819,25.83325
3.12000,25.99993,15.19831,0.22609,1.68870,25.99993
3.14000,26.16662,15.29767,0.22754,1.69974,26.16662
3.16000,26.33337,15.34834,0.22899,1.70537,26.33337
3.18000,26.50006,15.12653,0.23044,1.68073,26.50006
3.20000,26.66662,15.14002,0.23188,1.68222,26.66662
3.22000,26.83331,15.15842,0.23333,1.68427,26.83331
3.24000,27.00000,15.25780,0.23478,1.69531,27.00000
3.26000,27.16668,15.36862,0.23623,1.70762,27.16668
3.28000,27.33331,15.36537,0.23768,1.70726,27.33331
3.30000,27.49993,15.40526,0.23913,1.71170,27.49993
3.32000,27.66656,15.54094,0.24058,1.72677,27.66656
3.34000,27.83331,15.64993,0.24203,1.73888,27.83331
3.36000,28.00006,15.83290,0.24348,1.75921,28.00006
3.38000,28.16675,15.71343,0.24493,1.74594,28.16675
3.40000,28.33337,15.50112,0.24638,1.72235,28.33337
3.42000,28.50000,15.50046,0.24783,1.72227,28.50000
3.44000,28.66662,15.64251,0.24927,1.73806,28.66662
3.46000,28.83337,15.62519,0.25072,1.73613,28.83337
3.48000,29.00006,15.76188,0.25217,1.75132,29.00006
3.50000,29.16669,15.83332,0.25362,1.75926,29.16669
3.52000,29.33337,15.57432,0.25507,1.73048,29.33337
3.54000,29.50000,15.57112,0.25652,1.73012,29.50000
3.56000,29.66662,15.56161,0.25797,1.72907,29.66662
3.58000,29.83337,15.56872,0.25942,1.72986,29.83337
3.60000,30.00006,15.74273,0.26087,1.74919,30.00006
3.62000,30.16668,15.93273,0.26232,1.77030,30.16668
3.64000,30.33337,15.86646,0.26377,1.76294,30.33337
3.66000,30.49999,15.95369,0.26522,1.77263,30.49999
3.68000,30.66662,16.05785,0.26667,1.78421,30.66662
3.70000,30.83337,15.96964,0.26812,1.77440,30.83337
3.72000,31.00000,16.06625,0.26957,1.78514,31.00000
3.74000,31.16662,16.04987,0.27101,1.78332,31.16662
3.76000,31.33331,15.89944,0.27246,1.76660,31.33331
3.78000,31.49999,16.06995,0.27391,1.78555,31.49999
3.80000,31.66668,16.28444,0.27536,1.80938,31.66668
3.82000,31.83337,16.15555,0.27681,1.79506,31.83337
3.84000,31.99999,16.20475,0.27826,1.80053,31.99999
3.86000,32.16656,16.23042,0.27971,1.80338,32.16656
3.88000,32.33331,16.25275,0.28116,1.80586,32.33331
3.90000,32.50000,16.34004,0.28261,1.81556,32.50000
3.92000,32.66668,16.50455,0.28406,1.83384,32.66668
3.94000,32.83331,16.46779,0.28551,1.82975,32.83331
3.96000,32.99993,16.34330,0.28696,1.81592,32.99993
3.98000,33.16662,16.37788,0.28841,1.81976,33.16662
4.00000,33.33337,16.39762,0.28986,1.82196,33.33337
4.02000,33.50006,16.36771,0.29130,1.81863,33.50006
4.04000,33.66675,16.47278,0.29275,1.83031,33.66675
4.06000,33.83337,16.57043,0.29420,1.84116,33.83337
4.08000,34.00006,16.58282,0.29565,1.84254,34.00006
4.10000,34.16668,16.65519,0.29710,1.85058,34.16668
4.12000,34.33337,16.56622,0.29855,1.84069,34.33337
4.14000,34.50006,16.68096,0.30000,1.85344,34.50006
4.16000,34.66662,16.71321,0.30145,1.85702,34.66662
4.18000,34.83331,16.55448,0.30290,1.83939,34.83331
4.20000,34.99999,16.60442,0.30435,1.84494,34.99999
4.22000,35.16675,16.72940,0.30580,1.85882,35.16675
4.24000,35.33337,16.71698,0.30725,1.85744,35.33337
4.26000,35.49999,16.87838,0.30870,1.87538,35.49999
4.28000,35.66662,17.04445,0.31014,1.89383,35.66662
4.30000,35.83331,16.90255,0.31159,1.87806,35.83331
4.32000,35.99999,16.89525,0.31304,1.87725,35.99999
4.34000,36.16662,17.07179,0.31449,1.89687,36.16662
4.36000,36.33337,17.11932,0.31594,1.90215,36.33337
4.38000,36.50000,17.28317,0.31739,1.92035,36.50000
4.40000,36.66662,17.08474,0.31884,1.89830,36.66662
4.42000,36.83337,17.05476,0.32029,1.89497,36.83337
4.44000,36.99999,17.20460,0.32174,1.91162,36.99999
4.46000,37.16662,17.33088,0.32319,1.92565,37.16662
4.48000,37.33324,17.38047,0.32464,1.93116,37.33324
4.50000,37.49993,17.37097,0.32609,1.93011,37.49993
4.52000,37.66662,17.34462,0.32754,1.92718,37.66662
4.54000,37.83337,17.20651,0.32899,1.91183,37.83337
4.56000,38.00006,17.19304,0.33044,1.91034,38.00006
4.58000,38.16668,17.19637,0.33188,1.91071,38.16668
4.60000,38.33331,17.29309,0.33333,1.92145,38.33331
4.62000,38.50000,17.39950,0.33478,1.93328,38.50000
4.64000,38.66668,17.40594,0.33623,1.93399,38.66668
4.66000,38.83337,17.32892,0.33768,1.92544,38.83337
4.68000,39.00006,17.53665,0.33913,1.94852,39.00006
4.70000,39.16668,17.63440,0.34058,1.95938,39.16668
4.72000,39.33331,17.57518,0.34203,1.95280,39.33331
4.74000,39.49999,17.75746,0.34348,1.97305,39.49999
4.76000,39.66668,17.79699,0.34493,1.97744,39.66668
4.78000,39.83337,17.60655,0.34638,1.95628,39.83337
4.80000,39.99999,17.66357,0.34783,1.96262,39.99999
4.82000,40.16662,17.72058,0.34927,1.96895,40.16662
4.84000,40.33331,17.68392,0.35072,1.96488,40.33331
4.86000,40.50006,17.83371,0.35217,1.98152,40.50006
4.88000,40.66668,17.92577,0.35362,1.99175,40.66668
4.90000,40.83337,17.79841,0.35507,1.97760,40.83337
4.92000,40.99999,17.91822,0.35652,1.99091,40.99999
4.94000,41.16662,17.94080,0.35797,1.99342,41.16662
4.96000,41.33337,17.93694,0.35942,1.99299,41.33337
4.98000,41.50006,18.02780,0.36087,2.00309,41.50006
5.00000,41.66662,18.03811,0.36232,2.00423,41.66662
5.02000,41.83325,18.00005,0.36377,2.00001,41.83325
5.04000,41.99993,18.07739,0.36522,2.00860,41.99993
5.06000,42.16662,18.19123,0.36667,2.02125,42.16662
5.08000,42.33337,18.03693,0.36812,2.00410,42.33337
5.10000,42.50005,18.18777,0.36957,2.02086,42.50005
5.12000,42.66662,18.31978,0.37101,2.03553,42.66662
5.14000,42.83324,18.27763,0.37246,2.03085,42.83324
5.16000,42.99993,18.27068,0.37391,2.03008,42.99993
5.18000,43.16668,18.39467,0.37536,2.04385,43.16668
5.20000,43.33337,18.31020,0.37681,2.03447,43.33337
5.22000,43.50006,18.45203,0.37826,2.05023,43.50006
5.24000,43.66668,18.47569,0.37971,2.05285,43.66668
5.26000,43.83337,18.33930,0.38116,2.03770,43.83337
5.28000,44.00006,18.39592,0.38261,2.04399,44.00006
5.30000,44.16674,18.49964,0.38406,2.05552,44.16674
5.32000,44.33337,18.60772,0.38551,2.06752,44.33337
5.34000,44.49999,18.68438,0.38696,2.07604,44.49999
5.36000,44.66662,18.59063,0.38841,2.06563,44.66662
5.38000,44.83331,18.46952,0.38985,2.05217,44.83331
5.40000,45.00006,18.57079,0.39130,2.06342,45.00006
5.42000,45.16668,18.55911,0.39275,2.06212,45.16668
5.44000,45.33337,18.73228,0.39420,2.08136,45.33337
5.46000,45.49999,18.90696,0.39565,2.10077,45.49999
5.48000,45.66655,18.99490,0.39710,2.11054,45.66655
5.50000,45.83331,18.80715,0.39855,2.08968,45.83331
5.52000,45.99999,18.78342,0.40000,2.08705,45.99999
5.54000,46.16662,18.77223,0.40145,2.08580,46.16662
5.56000,46.33330,18.71593,0.40290,2.07955,46.33330
5.58000,46.49993,18.81117,0.40435,2.09013,46.49993
5.60000,46.66662,18.99968,0.40580,2.11108,46.66662
5.62000,46.83343,18.96929,0.40725,2.10770,46.83343
5.64000,47.00006,19.08177,0.40870,2.12020,47.00006
5.66000,47.16662,19.05390,0.41014,2.11710,47.16662
5.68000,47.33331,19.09698,0.41159,2.12189,47.33331
5.70000,47.49993,19.45997,0.41304,2.16222,47.49993
5.72000,47.66662,19.41566,0.41449,2.15730,47.66662
5.74000,47.83337,19.17156,0.41594,2.13017,47.83337
5.76000,47.99999,19.16304,0.41739,2.12923,47.99999
5.78000,48.16662,19.30268,0.41884,2.14474,48.16662
5.80000,48.33330,19.32627,0.42029,2.14736,48.33330
5.82000,48.50006,19.47469,0.42174,2.16385,48.50006
5.84000,48.66675,19.61984,0.42319,2.17998,48.66675
5.86000,48.83343,19.62175,0.42464,2.18019,48.83343
5.88000,49.00006,19.72285,0.42609,2.19143,49.00006
5.90000,49.16668,19.75131,0.42754,2.19459,49.16668
5.92000,49.33337,19.63447,0.42899,2.18161,49.33337
5.94000,49.50006,19.74323,0.43044,2.19369,49.50006
5.96000,49.66668,19.59285,0.43188,2.17698,49.66668
5.98000,49.83330,19.53158,0.43333,2.17018,49.83330
6.00000,49.99993,19.68901,0.43478,2.18767,49.99993
6.02000,50.16662,19.93539,0.43623,2.21504,50.16662
6.04000,50.33337,19.87602,0.43768,2.20845,50.33337
6.06000,50.50005,20.08165,0.43913,2.23129,50.50005
6.08000,50.66662,20.02101,0.44058,2.22456,50.66662
6.10000,50.83330,20.02855,0.44203,2.22539,50.83330
6.12000,50.99999,19.98971,0.44348,2.22108,50.99999
6.14000,51.16662,20.03717,0.44493,2.22635,51.16662
6.16000,51.33331,19.94521,0.44638,2.21613,51.33331
6.18000,51.49999,20.02958,0.44783,2.22551,51.49999
6.20000,51.66662,20.13788,0.44927,2.23754,51.66662
6.22000,51.83330,20.13171,0.45072,2.23686,51.83330
6.24000,51.99999,20.14841,0.45217,2.23871,51.99999
6.26000,52.16668,20.21344,0.45362,2.24594,52.16668
6.28000,52.33337,20.16920,0.45507,2.24102,52.33337
6.30000,52.49999,20.23682,0.45652,2.24854,52.49999
6.32000,52.66662,20.30704,0.45797,2.25634,52.66662
6.34000,52.83324,20.22159,0.45942,2.24684,52.83324
6.36000,52.99999,20.50018,0.46087,2.27780,52.99999
6.38000,53.16668,20.58533,0.46232,2.28726,53.16668
6.40000,53.33337,20.44527,0.46377,2.27170,53.33337
6.42000,53.50005,20.45742,0.46522,2.27305,53.50005
6.44000,53.66668,20.36494,0.46667,2.26277,53.66668
6.46000,53.83343,20.30942,0.46812,2.25660,53.83343
6.48000,54.00012,20.45526,0.46957,2.27281,54.00012
6.50000,54.16675,20.55012,0.47102,2.28335,54.16675
6.52000,54.33330,20.50368,0.47246,2.27819,54.33330
6.54000,54.49993,20.77120,0.47391,2.30791,54.49993
6.56000,54.66662,20.77436,0.47536,2.30826,54.66662
6.58000,54.83337,20.78606,0.47681,2.30956,54.83337
6.60000,55.00006,20.82939,0.47826,2.31438,55.00006
6.62000,55.16668,20.93992,0.47971,2.32666,55.16668
6.64000,55.33330,20.92628,0.48116,2.32514,55.33330
6.66000,55.49999,21.00822,0.48261,2.33425,55.49999
6.68000,55.66668,21.10366,0.48406,2.34485,55.66668
6.70000,55.83337,20.93472,0.48551,2.32608,55.83337
6.72000,55.99999,20.81565,0.48696,2.31285,55.99999
6.74000,56.16656,20.84021,0.48840,2.31558,56.16656
6.76000,56.33330,20.83691,0.48985,2.31521,56.33330
6.78000,56.49999,21.00465,0.49130,2.33385,56.49999
6.80000,56.66668,21.17422,0.49275,2.35269,56.66668
6.82000,56.83336,21.10354,0.49420,2.34484,56.83336
6.84000,56.99999,21.05848,0.49565,2.33983,56.99999
6.86000,57.16662,21.17611,0.49710,2.35290,57.16662
6.88000,57.33330,21.18603,0.49855,2.35400,57.33330
6.90000,57.49999,21.32477,0.50000,2.36942,57.49999
6.92000,57.66662,21.54806,0.50145,2.39423,57.66662
6.94000,57.83331,21.46386,0.50290,2.38487,57.83331
6.96000,57.99999,21.31757,0.50435,2.36862,57.99999
6.98000,58.16662,21.36601,0.50580,2.37400,58.16662
7.00000,58.33337,21.18595,0.50725,2.35399,58.33337
7.02000,58.50011,21.33026,0.50870,2.37003,58.50011
7.04000,58.66668,21.47282,0.51015,2.38587,58.66668
7.06000,58.83337,21.54945,0.51159,2.39438,58.83337
7.08000,58.99999,21.69380,0.51304,2.41042,58.99999
7.10000,59.16668,21.78219,0.51449,2.42024,59.16668
7.12000,59.33343,21.68163,0.51594,2.40907,59.33343
7.14000,59.50006,21.72743,0.51739,2.41416,59.50006
7.16000,59.66661,21.61119,0.51884,2.40124,59.66661
7.18000,59.83324,21.54186,0.52029,2.39354,59.83324
7.20000,59.99999,21.63625,0.52174,2.40403,59.99999
7.22000,60.16668,21.96129,0.52319,2.44014,60.16668
7.24000,60.33343,21.92189,0.52464,2.43577,60.33343
7.26000,60.50006,21.71389,0.52609,2.41265,60.50006
7.28000,60.66662,21.90639,0.52754,2.43404,60.66662
7.30000,60.83330,21.90164,0.52899,2.43352,60.83330
7.32000,60.99999,22.00851,0.53043,2.44539,60.99999
7.34000,61.16662,22.05970,0.53188,2.45108,61.16662
7.36000,61.33331,22.06793,0.53333,2.45199,61.33331
7.38000,61.49993,21.97094,0.53478,2.44122,61.49993
7.40000,61.66662,22.00212,0.53623,2.44468,61.66662
7.42000,61.83337,22.13837,0.53768,2.45982,61.83337
7.44000,62.00006,22.37304,0.53913,2.48589,62.00006
7.46000,62.16668,22.34519,0.54058,2.48280,62.16668
7.48000,62.33331,22.25274,0.54203,2.47253,62.33331
7.50000,62.49987,22.35710,0.54348,2.48412,62.49987
7.52000,62.66662,22.40598,0.54493,2.48955,62.66662
7.54000,62.83336,22.40419,0.54638,2.48935,62.83336
7.56000,63.00006,22.51394,0.54783,2.50155,63.00006
7.58000,63.16661,22.43657,0.54927,2.49295,63.16661
7.60000,63.33336,22.31747,0.55072,2.47972,63.33336
7.62000,63.49999,22.38573,0.55217,2.48730,63.49999
7.64000,63.66674,22.45158,0.55362,2.49462,63.66674
7.66000,63.83342,22.41223,0.55507,2.49025,63.83342
7.68000,64.00005,22.43067,0.55652,2.49230,64.00005
7.70000,64.16661,22.50666,0.55797,2.50074,64.16661
7.72000,64.33330,22.59510,0.55942,2.51057,64.33330
7.74000,64.49999,22.70090,0.56087,2.52232,64.49999
7.76000,64.66668,22.72738,0.56232,2.52526,64.66668
7.78000,64.83336,22.71366,0.56377,2.52374,64.83336
7.80000,64.99999,22.80328,0.56522,2.53370,64.99999
7.82000,65.16661,22.85385,0.56667,2.53932,65.16661
7.84000,65.33330,22.73585,0.56812,2.52621,65.33330
7.86000,65.49999,22.84423,0.56957,2.53825,65.49999
7.88000,65.66667,22.98079,0.57101,2.55342,65.66667
7.90000,65.83330,22.88520,0.57246,2.54280,65.83330
7.92000,65.99999,23.03631,0.57391,2.55959,65.99999
7.94000,66.16662,23.04395,0.57536,2.56044,66.16662
7.96000,66.33330,22.97368,0.57681,2.55263,66.33330
7.98000,66.50005,23.16658,0.57826,2.57406,66.50005
8.00000,66.66668,23.14760,0.57971,2.57196,66.66668
8.02000,66.83331,23.10234,0.58116,2.56693,66.83331
8.04000,66.99999,23.37681,0.58261,2.59742,66.99999
8.06000,67.16661,23.37674,0.58406,2.59742,67.16661
8.08000,67.33330,23.16614,0.58551,2.57402,67.33330
8.10000,67.49999,23.32748,0.58696,2.59194,67.49999
8.12000,67.66662,23.43691,0.58841,2.60410,67.66662
8.14000,67.83330,23.33907,0.58985,2.59323,67.83330
8.16000,67.99993,23.46339,0.59130,2.60704,67.99993
8.18000,68.16661,23.43735,0.59275,2.60415,68.16661
8.20000,68.33337,23.50647,0.59420,2.61183,68.33337
8.22000,68.50005,23.70046,0.59565,2.63338,68.50005
8.24000,68.66661,23.80075,0.59710,2.64453,68.66661
8.26000,68.83330,23.59331,0.59855,2.62148,68.83330
8.28000,69.00005,23.57401,0.60000,2.61933,69.00005
8.30000,69.16674,23.71364,0.60145,2.63485,69.16674
8.32000,69.33343,23.65508,0.60290,2.62834,69.33343
8.34000,69.49999,23.73533,0.60435,2.63726,69.49999
8.36000,69.66655,23.77584,0.60580,2.64176,69.66655
8.38000,69.83330,23.74947,0.60725,2.63883,69.83330
8.40000,69.99999,23.77131,0.60870,2.64126,69.99999
8.42000,70.16668,23.77222,0.61015,2.64136,70.16668
8.44000,70.33336,23.67271,0.61159,2.63030,70.33336
8.46000,70.49999,23.97657,0.61304,2.66406,70.49999
8.48000,70.66668,23.97503,0.61449,2.66389,70.66668
8.50000,70.83336,23.98377,0.61594,2.66486,70.83336
8.52000,70.99999,24.25697,0.61739,2.69522,70.99999
8.54000,71.16661,24.37886,0.61884,2.70876,71.16661
8.56000,71.33331,24.01133,0.62029,2.66793,71.33331
8.58000,71.49993,24.05088,0.62174,2.67232,71.49993
8.60000,71.66667,24.24703,0.62319,2.69411,71.66667
8.62000,71.83337,24.25964,0.62464,2.69552,71.83337
8.64000,71.99999,24.30931,0.62609,2.70103,71.99999
8.66000,72.16662,24.34227,0.62754,2.70470,72.16662
8.68000,72.33330,24.31337,0.62899,2.70149,72.33330
8.70000,72.49999,24.40174,0.63043,2.71130,72.49999
8.72000,72.66662,24.53803,0.63188,2.72645,72.66662
8.74000,72.83330,24.52290,0.63333,2.72477,72.83330
8.76000,72.99999,24.67322,0.63478,2.74147,72.99999
8.78000,73.16655,24.40585,0.63623,2.71176,73.16655
8.80000,73.33330,24.30904,0.63768,2.70100,73.33330
8.82000,73.50005,24.59064,0.63913,2.73229,73.50005
8.84000,73.66668,24.69507,0.64058,2.74390,73.66668
8.86000,73.83343,24.47389,0.64203,2.71932,73.83343
8.88000,74.00006,24.61719,0.64348,2.73524,74.00006
8.90000,74.16668,24.67714,0.64493,2.74190,74.16668
8.92000,74.33336,24.72296,0.64638,2.74700,74.33336
8.94000,74.50006,24.86624,0.64783,2.76292,74.50006
8.96000,74.66668,24.89550,0.64928,2.76617,74.66668
8.98000,74.83337,24.78836,0.65072,2.75426,74.83337
9.00000,74.99999,24.71944,0.65217,2.74660,74.99999
9.02000,75.16661,24.84486,0.65362,2.76054,75.16661
9.04000,75.33337,24.74324,0.65507,2.74925,75.33337
9.06000,75.50005,24.90474,0.65652,2.76719,75.50005
9.08000,75.66662,25.04806,0.65797,2.78312,75.66662
9.10000,75.83330,25.15668,0.65942,2.79519,75.83330
9.12000,75.99999,25.23057,0.66087,2.80340,75.99999
9.14000,76.16661,25.32300,0.66232,2.81367,76.16661
9.16000,76.33337,25.24019,0.66377,2.80447,76.33337
9.18000,76.50005,25.17708,0.66522,2.79745,76.50005
9.20000,76.66662,25.17784,0.66667,2.79754,76.66662
9.22000,76.83330,25.18303,0.66812,2.79811,76.83330
9.24000,76.99999,25.24700,0.66957,2.80522,76.99999
9.26000,77.16668,25.41259,0.67101,2.82362,77.16668
9.28000,77.33336,25.41974,0.67246,2.82442,77.33336
9.30000,77.49998,25.48089,0.67391,2.83121,77.49998
9.32000,77.66661,25.46517,0.67536,2.82946,77.66661
9.34000,77.83331,25.29476,0.67681,2.81053,77.83331
9.36000,77.99999,25.33936,0.67826,2.81548,77.99999
9.38000,78.16661,25.49262,0.67971,2.83251,78.16661
9.40000,78.33330,25.41572,0.68116,2.82397,78.33330
9.42000,78.49999,25.60687,0.68261,2.84521,78.49999
9.44000,78.66661,25.71931,0.68406,2.85770,78.66661
9.46000,78.83336,25.64322,0.68551,2.84925,78.83336
9.48000,79.00012,25.65238,0.68696,2.85026,79.00012
9.50000,79.16674,25.77126,0.68841,2.86347,79.16674
9.52000,79.33330,25.59573,0.68985,2.84397,79.33330
9.54000,79.49992,25.65855,0.69130,2.85095,79.49992
9.56000,79.66661,25.78262,0.69275,2.86474,79.66661
9.58000,79.83336,25.87317,0.69420,2.87480,79.83336
9.60000,79.99999,25.94620,0.69565,2.88291,79.99999
9.62000,80.16667,25.94329,0.69710,2.88259,80.16667
9.64000,80.33336,25.89572,0.69855,2.87730,80.33336
9.66000,80.49999,26.09312,0.70000,2.89924,80.49999
9.68000,80.66667,26.21391,0.70145,2.91266,80.66667
9.70000,80.83336,26.12709,0.70290,2.90301,80.83336
9.72000,80.99998,26.22030,0.70435,2.91337,80.99998
9.74000,81.16661,26.18768,0.70580,2.90974,81.16661
9.76000,81.33323,26.07786,0.70725,2.89754,81.33323
9.78000,81.49993,25.95514,0.70869,2.88390,81.49993
9.80000,81.66668,26.13111,0.71015,2.90346,81.66668
9.82000,81.83336,26.12209,0.71159,2.90245,81.83336
9.84000,81.99993,26.28663,0.71304,2.92074,81.99993
9.86000,82.16655,26.40075,0.71449,2.93342,82.16655
9.88000,82.33330,26.35895,0.71594,2.92877,82.33330
9.90000,82.49999,26.45348,0.71739,2.93928,82.49999
9.92000,82.66667,26.58409,0.71884,2.95379,82.66667
9.94000,82.83329,26.50447,0.72029,2.94494,82.83329
9.96000,82.99992,26.47655,0.72174,2.94184,82.99992
9.98000,83.16656,26.52191,0.72319,2.94688,83.16656
10.00000,83.33330,26.41716,0.72464,2.93524,83.33330
10.02000,83.50004,26.61050,0.72609,2.95672,83.50004
10.04000,83.66674,26.56844,0.72754,2.95205,83.66674
10.06000,83.83336,26.44462,0.72899,2.93829,83.83336
10.08000,83.99999,26.66989,0.73043,2.96332,83.99999
10.10000,84.16673,26.73347,0.73188,2.97039,84.16673
10.12000,84.33343,26.64572,0.73333,2.96063,84.33343
10.14000,84.50005,26.77456,0.73478,2.97495,84.50005
10.16000,84.66667,26.80388,0.73623,2.97821,84.66667
10.18000,84.83330,26.78100,0.73768,2.97567,84.83330
10.20000,84.99999,26.95205,0.73913,2.99467,84.99999
10.22000,85.16667,26.85279,0.74058,2.98364,85.16667
10.24000,85.33343,26.81135,0.74203,2.97904,85.33343
10.26000,85.50005,27.10610,0.74348,3.01179,85.50005
10.28000,85.66661,27.19424,0.74493,3.02158,85.66661
10.30000,85.83331,27.03728,0.74638,3.00414,85.83331
10.32000,86.00005,27.17524,0.74783,3.01947,86.00005
10.34000,86.16667,27.29995,0.74928,3.03333,86.16667
10.36000,86.33330,27.19814,0.75072,3.02202,86.33330
10.38000,86.49998,27.21981,0.75217,3.02442,86.49998
10.40000,86.66655,27.30570,0.75362,3.03397,86.66655
10.42000,86.83329,27.25114,0.75507,3.02790,86.83329
10.44000,86.99999,27.25973,0.75652,3.02886,86.99999
10.46000,87.16667,27.28400,0.75797,3.03156,87.16667
10.48000,87.33329,27.27264,0.75942,3.03029,87.33329
10.50000,87.49999,27.45858,0.76087,3.05095,87.49999
10.52000,87.66667,27.49321,0.76232,3.05480,87.66667
10.54000,87.83330,27.54028,0.76377,3.06003,87.83330
10.56000,87.99993,27.58488,0.76522,3.06499,87.99993
10.58000,88.16655,27.76425,0.76667,3.08492,88.16655
10.60000,88.33330,27.61990,0.76812,3.06888,88.33330
10.62000,88.49998,27.52948,0.76957,3.05883,88.49998
10.64000,88.66668,27.59852,0.77101,3.06650,88.66668
10.66000,88.83343,27.61098,0.77246,3.06789,88.83343
10.68000,89.00005,27.79795,0.77391,3.08866,89.00005
10.70000,89.16668,27.89839,0.77536,3.09982,89.16668
10.72000,89.33330,27.89932,0.77681,3.09992,89.33330
10.74000,89.49999,27.91056,0.77826,3.10117,89.49999
10.76000,89.66668,27.98533,0.77971,3.10948,89.66668
10.78000,89.83336,27.79224,0.78116,3.08803,89.83336
10.80000,89.99999,27.95090,0.78261,3.10566,89.99999
10.82000,90.16661,28.01653,0.78406,3.11295,90.16661
10.84000,90.33336,27.88827,0.78551,3.09870,90.33336
10.86000,90.50005,27.95423,0.78696,3.10603,90.50005
10.88000,90.66667,28.02253,0.78841,3.11361,90.66667
10.90000,90.83336,27.97629,0.78986,3.10848,90.83336
10.92000,90.99999,28.17132,0.79130,3.13015,90.99999
10.94000,91.16654,28.35495,0.79275,3.15055,91.16654
10.96000,91.33330,28.32735,0.79420,3.14748,91.33330
10.98000,91.50005,28.41878,0.79565,3.15764,91.50005
11.00000,91.66667,28.38931,0.79710,3.15437,91.66667
11.02000,91.83330,28.36279,0.79855,3.15142,91.83330
11.04000,91.99998,28.46237,0.80000,3.16249,91.99998
11.06000,92.16667,28.50082,0.80145,3.16676,92.16667
11.08000,92.33336,28.42872,0.80290,3.15875,92.33336
11.10000,92.49998,28.28224,0.80435,3.14247,92.49998
11.12000,92.66655,28.43200,0.80580,3.15911,92.66655
11.14000,92.83324,28.42899,0.80725,3.15878,92.83324
11.16000,92.99998,28.61341,0.80870,3.17927,92.99998
11.18000,93.16668,28.61559,0.81015,3.17951,93.16668
11.20000,93.33342,28.49071,0.81159,3.16563,93.33342
11.22000,93.50005,28.58015,0.81304,3.17557,93.50005
11.24000,93.66661,28.67086,0.81449,3.18565,93.66661
11.26000,93.83336,28.61703,0.81594,3.17967,93.83336
11.28000,94.00005,28.67461,0.81739,3.18607,94.00005
11.30000,94.16673,28.77588,0.81884,3.19732,94.16673
11.32000,94.33342,28.76821,0.82029,3.19647,94.33342
11.34000,94.50004,28.93733,0.82174,3.21526,94.50004
11.36000,94.66661,29.04932,0.82319,3.22770,94.66661
11.38000,94.83336,28.92694,0.82464,3.21410,94.83336
11.40000,95.00004,29.00139,0.82609,3.22238,95.00004
11.42000,95.16673,29.06884,0.82754,3.22987,95.16673
11.44000,95.33335,28.99616,0.82899,3.22180,95.33335
11.46000,95.49998,29.17729,0.83043,3.24192,95.49998
11.48000,95.66661,29.24317,0.83188,3.24924,95.66661
11.50000,95.83330,29.15753,0.83333,3.23973,95.83330
11.52000,96.00005,29.26482,0.83478,3.25165,96.00005
11.54000,96.16667,29.24378,0.83623,3.24931,96.16667
11.56000,96.33330,29.12794,0.83768,3.23644,96.33330
11.58000,96.49992,29.16720,0.83913,3.24080,96.49992
11.60000,96.66661,29.26492,0.84058,3.25166,96.66661
11.62000,96.83336,29.40682,0.84203,3.26742,96.83336
11.64000,97.00004,29.32100,0.84348,3.25789,97.00004
11.66000,97.16661,29.25493,0.84493,3.25055,97.16661
11.68000,97.33323,29.26411,0.84638,3.25157,97.33323
11.70000,97.49993,29.54711,0.84783,3.28301,97.49993
11.72000,97.66661,29.64897,0.84927,3.29433,97.66661
11.74000,97.83336,29.58789,0.85072,3.28754,97.83336
11.76000,97.99998,29.57471,0.85217,3.28608,97.99998
11.78000,98.16654,29.63665,0.85362,3.29296,98.16654
11.80000,98.33329,29.62161,0.85507,3.29129,98.33329
11.82000,98.50005,29.71183,0.85652,3.30131,98.50005
11.84000,98.66667,29.84502,0.85797,3.31611,98.66667
11.86000,98.83337,29.85004,0.85942,3.31667,98.83337
11.88000,98.99999,29.94707,0.86087,3.32745,98.99999
11.90000,99.16661,30.06698,0.86232,3.34078,99.16661
11.92000,99.33336,29.89366,0.86377,3.32152,99.33336
11.94000,99.50005,29.88854,0.86522,3.32095,99.50005
11.96000,99.66673,29.94543,0.86667,3.32727,99.66673
11.98000,99.83336,30.03480,0.86812,3.33720,99.83336
12.00000,99.99998,30.26685,0.86957,3.36298,99.99998
12.02000,100.16668,30.37351,0.87101,3.37483,100.16668
12.04000,100.33342,29.99066,0.87246,3.33230,100.33342
12.06000,100.50005,30.02686,0.87391,3.33632,100.50005
12.08000,100.66668,30.12436,0.87536,3.34715,100.66668
12.10000,100.83330,30.06238,0.87681,3.34026,100.83330
12.12000,100.99999,30.11528,0.87826,3.34614,100.99999
12.14000,101.16667,30.11917,0.87971,3.34657,101.16667
12.16000,101.33336,30.20844,0.88116,3.35649,101.33336
12.18000,101.50004,30.51840,0.88261,3.39093,101.50004
12.20000,101.66667,30.59058,0.88406,3.39895,101.66667
12.22000,101.83330,30.51955,0.88551,3.39106,101.83330
12.24000,101.99999,30.41370,0.88696,3.37930,101.99999
12.26000,102.16667,30.53285,0.88841,3.39254,102.16667
12.28000,102.33336,30.51796,0.88986,3.39088,102.33336
12.30000,102.49998,30.57157,0.89130,3.39684,102.49998
12.32000,102.66654,30.52832,0.89275,3.39204,102.66654
12.34000,102.83330,30.49553,0.89420,3.38839,102.83330
12.36000,102.99998,30.68648,0.89565,3.40961,102.99998
12.38000,103.16667,30.84399,0.89710,3.42711,103.16667
12.40000,103.33336,30.80054,0.89855,3.42228,103.33336
12.42000,103.49998,30.86573,0.90000,3.42953,103.49998
12.44000,103.66655,30.96345,0.90145,3.44038,103.66655
12.46000,103.83330,30.88822,0.90290,3.43202,103.83330
12.48000,104.00005,30.81616,0.90435,3.42402,104.00005
12.50000,104.16673,30.89414,0.90580,3.43268,104.16673
12.52000,104.33336,30.83471,0.90725,3.42608,104.33336
12.54000,104.49998,30.95694,0.90870,3.43966,104.49998
12.56000,104.66667,30.94793,0.91014,3.43866,104.66667
12.58000,104.83336,30.80742,0.91159,3.42305,104.83336
12.60000,105.00005,30.98351,0.91304,3.44261,105.00005
12.62000,105.16667,31.03967,0.91449,3.44885,105.16667
12.64000,105.33329,31.12025,0.91594,3.45781,105.33329
12.66000,105.49999,31.31595,0.91739,3.47955,105.49999
12.68000,105.66667,31.40951,0.91884,3.48995,105.66667
12.70000,105.83342,31.30023,0.92029,3.47780,105.83342
12.72000,106.00004,31.32992,0.92174,3.48110,106.00004
12.74000,106.16661,31.44052,0.92319,3.49339,106.16661
12.76000,106.33330,31.34481,0.92464,3.48276,106.33330
12.78000,106.49998,31.50993,0.92609,3.50110,106.49998
12.80000,106.66673,31.64159,0.92754,3.51573,106.66673
12.82000,106.83330,31.46070,0.92899,3.49563,106.83330
12.84000,106.99992,31.35862,0.93043,3.48429,106.99992
12.86000,107.16654,31.58217,0.93188,3.50913,107.16654
12.88000,107.33330,31.65369,0.93333,3.51708,107.33330
12.90000,107.50005,31.62420,0.93478,3.51380,107.50005
12.92000,107.66667,31.62792,0.93623,3.51421,107.66667
12.94000,107.83330,31.61147,0.93768,3.51239,107.83330
12.96000,107.99998,31.75464,0.93913,3.52829,107.99998
12.98000,108.16661,31.80886,0.94058,3.53432,108.16661
13.00000,108.33336,31.83517,0.94203,3.53724,108.33336
13.02000,108.50005,31.96952,0.94348,3.55217,108.50005
13.04000,108.66667,31.83306,0.94493,3.53701,108.66667
13.06000,108.83336,31.73916,0.94638,3.52657,108.83336
13.08000,108.99998,31.88758,0.94783,3.54306,108.99998
13.10000,109.16667,31.88944,0.94928,3.54327,109.16667
13.12000,109.33336,31.98417,0.95072,3.55380,109.33336
13.14000,109.50005,31.99960,0.95217,3.55551,109.50005
13.16000,109.66667,32.14949,0.95362,3.57217,109.66667
13.18000,109.83329,32.06935,0.95507,3.56326,109.83329
13.20000,109.99999,32.11241,0.95652,3.56805,109.99999
13.22000,110.16667,32.24491,0.95797,3.58277,110.16667
13.24000,110.33342,32.23427,0.95942,3.58159,110.33342
13.26000,110.50005,32.26822,0.96087,3.58536,110.50005
13.28000,110.66660,32.33817,0.96232,3.59313,110.66660
13.30000,110.83330,32.29178,0.96377,3.58798,110.83330
13.32000,111.00005,32.53772,0.96522,3.61530,111.00005
13.34000,111.16668,32.65175,0.96667,3.62797,111.16668
13.36000,111.33336,32.51024,0.96812,3.61225,111.33336
13.38000,111.49999,32.58773,0.96957,3.62086,111.49999
13.40000,111.66661,32.52048,0.97101,3.61339,111.66661
13.42000,111.83336,32.41526,0.97246,3.60170,111.83336
13.44000,112.00004,32.60884,0.97391,3.62320,112.00004
13.46000,112.16667,32.80026,0.97536,3.64447,112.16667
13.48000,112.33330,32.76642,0.97681,3.64071,112.33330
13.50000,112.49992,32.75388,0.97826,3.63932,112.49992
13.52000,112.66655,32.71161,0.97971,3.63462,112.66655
13.54000,112.83336,32.68413,0.98116,3.63157,112.83336
13.56000,113.00005,32.73830,0.98261,3.63759,113.00005
13.58000,113.16667,32.78861,0.98406,3.64318,113.16667
13.60000,113.33330,32.85674,0.98551,3.65075,113.33330
13.62000,113.49998,33.01681,0.98696,3.66853,113.49998
13.64000,113.66667,33.05840,0.98841,3.67316,113.66667
13.66000,113.83343,33.01672,0.98986,3.66852,113.83343
13.68000,114.00005,33.04434,0.99130,3.67159,114.00005
13.70000,114.16667,33.12502,0.99275,3.68056,114.16667
13.72000,114.33336,33.09528,0.99420,3.67725,114.33336
13.74000,114.50005,33.12178,0.99565,3.68020,114.50005
13.76000,114.66674,33.23689,0.99710,3.69299,114.66674
13.78000,114.83342,33.21132,0.99855,3.69015,114.83342
13.80000,114.99998,33.20985,1.00000,3.68998,114.99998
13.82000,115.16660,33.35773,1.00145,3.70641,115.16660
13.84000,115.33336,33.37252,1.00290,3.70806,115.33336
13.86000,115.50005,33.54945,1.00435,3.72772,115.50005
13.88000,115.66673,33.58565,1.00580,3.73174,115.66673
13.90000,115.83336,33.53843,1.00725,3.72649,115.83336
13.92000,115.99992,33.75072,1.00870,3.75008,115.99992
13.94000,116.16655,33.69365,1.01014,3.74374,116.16655
13.96000,116.33329,33.53745,1.01159,3.72638,116.33329
13.98000,116.50004,33.61861,1.01304,3.73540,116.50004
14.00000,116.66667,33.65055,1.01449,3.73895,116.66667
14.02000,116.83336,33.66318,1.01594,3.74035,116.83336
14.04000,116.99992,33.72417,1.01739,3.74713,116.99992
14.06000,117.16661,33.72030,1.01884,3.74670,117.16661
14.08000,117.33335,33.73112,1.02029,3.74790,117.33335
14.10000,117.49999,33.81616,1.02174,3.75735,117.49999
14.12000,117.66661,33.75513,1.02319,3.75057,117.66661
14.14000,117.83330,33.64648,1.02464,3.73850,117.83330
14.16000,117.99992,33.96129,1.02609,3.77348,117.99992
14.18000,118.16661,34.10378,1.02754,3.78931,118.16661
14.20000,118.33336,34.06709,1.02899,3.78523,118.33336
14.22000,118.50005,34.18779,1.03044,3.79864,118.50005
14.24000,118.66667,34.00900,1.03188,3.77878,118.66667
14.26000,118.83336,33.97422,1.03333,3.77491,118.83336
14.28000,119.00004,34.18911,1.03478,3.79879,119.00004
14.30000,119.16674,34.37588,1.03623,3.81954,119.16674
14.32000,119.33342,34.23927,1.03768,3.80436,119.33342
14.34000,119.49998,34.23603,1.03913,3.80400,119.49998
14.36000,119.66661,34.34825,1.04058,3.81647,119.66661
14.38000,119.83329,34.36157,1.04203,3.81795,119.83329
14.40000,120.00005,34.32273,1.04348,3.81364,120.00005
14.42000,120.16674,34.38215,1.04493,3.82024,120.16674
14.44000,120.33342,34.41477,1.04638,3.82386,120.33342
14.46000,120.49999,34.52581,1.04783,3.83620,120.49999
14.48000,120.66661,34.65434,1.04927,3.85048,120.66661
14.50000,120.83329,34.68290,1.05072,3.85366,120.83329
14.52000,121.00005,34.65253,1.05217,3.85028,121.00005
14.54000,121.16661,34.53536,1.05362,3.83726,121.16661
14.56000,121.33330,34.44171,1.05507,3.82686,121.33330
14.58000,121.49998,34.50357,1.05652,3.83373,121.49998
14.60000,121.66668,34.72012,1.05797,3.85779,121.66668
14.62000,121.83336,34.74481,1.05942,3.86053,121.83336
14.64000,121.99998,34.71209,1.06087,3.85690,121.99998
14.66000,122.16661,34.80305,1.06232,3.86701,122.16661
14.68000,122.33323,34.69946,1.06377,3.85549,122.33323
14.70000,122.49999,34.80996,1.06522,3.86777,122.49999
14.72000,122.66668,35.01475,1.06667,3.89053,122.66668
14.74000,122.83330,35.08896,1.06812,3.89877,122.83330
14.76000,122.99999,35.12560,1.06957,3.90284,122.99999
14.78000,123.16655,35.15832,1.07101,3.90648,123.16655
14.80000,123.33330,35.14402,1.07246,3.90489,123.33330
14.82000,123.50004,35.18521,1.07391,3.90947,123.50004
14.84000,123.66667,35.22964,1.07536,3.91440,123.66667
14.86000,123.83336,35.17938,1.07681,3.90882,123.83336
14.88000,123.99998,35.28097,1.07826,3.92011,123.99998
14.90000,124.16661,35.27696,1.07971,3.91966,124.16661
14.92000,124.33336,35.23027,1.08116,3.91447,124.33336
14.94000,124.50005,35.41264,1.08261,3.93474,124.50005
14.96000,124.66667,35.42777,1.08406,3.93642,124.66667
14.98000,124.83336,35.32060,1.08551,3.92451,124.83336
15.00000,124.99998,35.39912,1.08696,3.93324,124.99998
15.02000,125.16667,35.55650,1.08841,3.95072,125.16667
15.04000,125.33336,35.47813,1.08986,3.94201,125.33336
15.06000,125.50004,35.49174,1.09130,3.94353,125.50004
15.08000,125.66666,35.61493,1.09275,3.95721,125.66666
15.10000,125.83329,35.48684,1.09420,3.94298,125.83329
15.12000,125.99997,35.63972,1.09565,3.95997,125.99997
15.14000,126.16660,35.68875,1.09710,3.96542,126.16660
15.16000,126.33336,35.69757,1.09855,3.96640,126.33336
15.18000,126.50005,35.80822,1.10000,3.97869,126.50005
15.20000,126.66660,35.72970,1.10145,3.96997,126.66660
15.22000,126.83329,35.69820,1.10290,3.96647,126.83329
15.24000,127.00004,35.97485,1.10435,3.99721,127.00004
15.26000,127.16666,35.97711,1.10580,3.99746,127.16666
15.28000,127.33336,35.74723,1.10725,3.97191,127.33336
15.30000,127.49991,35.84407,1.10869,3.98267,127.49991
15.32000,127.66654,35.97182,1.11014,3.99687,127.66654
15.34000,127.83329,36.13106,1.11159,4.01456,127.83329
15.36000,127.99998,36.29917,1.11304,4.03324,127.99998
15.38000,128.16672,36.34261,1.11449,4.03807,128.16672
15.40000,128.33335,36.21061,1.11594,4.02340,128.33335
15.42000,128.50004,36.23182,1.11739,4.02576,128.50004
15.44000,128.66667,36.27595,1.11884,4.03066,128.66667
15.46000,128.83342,36.14693,1.12029,4.01633,128.83342
15.48000,129.00010,36.17363,1.12174,4.01929,129.00010
15.50000,129.16672,36.21306,1.12319,4.02367,129.16672
15.52000,129.33329,36.23823,1.12464,4.02647,129.33329
15.54000,129.49998,36.37337,1.12609,4.04149,129.49998
15.56000,129.66667,36.50563,1.12754,4.05618,129.66667
15.58000,129.83342,36.51983,1.12899,4.05776,129.83342
15.60000,130.00011,36.64572,1.13044,4.07175,130.00011
15.62000,130.16666,36.63886,1.13188,4.07098,130.16666
15.64000,130.33330,36.55289,1.13333,4.06143,130.33330
15.66000,130.49997,36.72531,1.13478,4.08059,130.49997
15.68000,130.66660,36.87084,1.13623,4.09676,130.66660
15.70000,130.83336,36.74329,1.13768,4.08259,130.83336
15.72000,130.99998,36.67197,1.13913,4.07466,130.99998
15.74000,131.16661,36.58728,1.14058,4.06525,131.16661
15.76000,131.33329,36.51165,1.14203,4.05685,131.33329
15.78000,131.49998,36.93647,1.14348,4.10405,131.49998
15.80000,131.66666,37.17428,1.14493,4.13048,131.66666
15.82000,131.83336,37.06971,1.14638,4.11886,131.83336
15.84000,131.99999,37.12393,1.14783,4.12488,131.99999
15.86000,132.16654,36.96435,1.14927,4.10715,132.16654
15.88000,132.33324,36.86256,1.15072,4.09584,132.33324
15.90000,132.49998,37.22753,1.15217,4.13639,132.49998
15.92000,132.66660,37.26147,1.15362,4.14016,132.66660
15.94000,132.83329,37.04336,1.15507,4.11593,132.83329
15.96000,132.99991,36.97179,1.15652,4.10798,132.99991
15.98000,133.16660,37.25814,1.15797,4.13979,133.16660
16.00000,133.33336,37.30002,1.15942,4.14445,133.33336
16.02000,133.50010,37.30340,1.16087,4.14482,133.50010
16.04000,133.66672,37.30610,1.16232,4.14512,133.66672
16.06000,133.83329,37.33784,1.16377,4.14865,133.83329
16.08000,133.99998,37.54469,1.16522,4.17163,133.99998
16.10000,134.16666,37.58201,1.16667,4.17578,134.16666
16.12000,134.33342,37.52436,1.16812,4.16937,134.33342
16.14000,134.50004,37.61522,1.16957,4.17947,134.50004
16.16000,134.66661,37.66607,1.17101,4.18512,134.66661
16.18000,134.83330,37.51114,1.17246,4.16790,134.83330
16.20000,134.99998,37.65838,1.17391,4.18426,134.99998
16.22000,135.16666,37.66102,1.17536,4.18456,135.16666
16.24000,135.33336,37.75820,1.17681,4.19536,135.33336
16.26000,135.50005,37.82707,1.17826,4.20301,135.50005
16.28000,135.66661,38.06880,1.17971,4.22987,135.66661
16.30000,135.83330,37.85568,1.18116,4.20619,135.83330
16.32000,135.99998,37.91710,1.18261,4.21301,135.99998
16.34000,136.16666,38.05724,1.18406,4.22858,136.16666
16.36000,136.33335,37.96216,1.18551,4.21802,136.33335
16.38000,136.49997,37.85465,1.18696,4.20607,136.49997
16.40000,136.66660,37.99229,1.18841,4.22137,136.66660
16.42000,136.83336,37.96794,1.18986,4.21866,136.83336
16.44000,137.00004,37.92714,1.19130,4.21413,137.00004
16.46000,137.16660,38.01095,1.19275,4.22344,137.16660
16.48000,137.33329,37.90750,1.19420,4.21194,137.33329
16.50000,137.49992,38.10078,1.19565,4.23342,137.49992
16.52000,137.66654,38.23774,1.19710,4.24864,137.66654
16.54000,137.83328,38.21761,1.19855,4.24640,137.83328
16.56000,138.00004,38.25199,1.20000,4.25022,138.00004
16.58000,138.16667,38.37087,1.20145,4.26343,138.16667
16.60000,138.33336,38.02633,1.20290,4.22515,138.33336
16.62000,138.50003,38.09897,1.20435,4.23322,138.50003
16.64000,138.66666,38.35564,1.20580,4.26174,138.66666
16.66000,138.83342,38.26546,1.20725,4.25172,138.83342
16.68000,139.00004,38.36010,1.20870,4.26223,139.00004
16.70000,139.16667,38.28961,1.21014,4.25440,139.16667
16.72000,139.33335,38.26375,1.21159,4.25153,139.33335
16.74000,139.50004,38.36960,1.21304,4.26329,139.50004
16.76000,139.66672,38.44875,1.21449,4.27208,139.66672
16.78000,139.83342,38.41408,1.21594,4.26823,139.83342
16.80000,140.00005,38.50151,1.21739,4.27795,140.00005
16.82000,140.16667,38.81064,1.21884,4.31229,140.16667
16.84000,140.33335,38.75739,1.22029,4.30638,140.33335
16.86000,140.50004,38.85707,1.22174,4.31745,140.50004
16.88000,140.66666,38.85154,1.22319,4.31684,140.66666
16.90000,140.83335,38.76758,1.22464,4.30751,140.83335
16.92000,140.99992,38.87172,1.22609,4.31908,140.99992
16.94000,141.16654,38.92633,1.22754,4.32515,141.16654
16.96000,141.33330,38.82993,1.22899,4.31444,141.33330
16.98000,141.50004,38.87098,1.23044,4.31900,141.50004
17.00000,141.66667,38.94896,1.23188,4.32766,141.66667
17.02000,141.83329,38.84757,1.23333,4.31640,141.83329
17.04000,141.99992,38.96738,1.23478,4.32971,141.99992
17.06000,142.16661,39.00127,1.23623,4.33348,142.16661
17.08000,142.33336,38.87921,1.23768,4.31991,142.33336
17.10000,142.50005,38.86696,1.23913,4.31855,142.50005
17.12000,142.66661,38.87108,1.24058,4.31901,142.66661
17.14000,142.83329,39.01342,1.24203,4.33482,142.83329
17.16000,142.99998,39.12221,1.24348,4.34691,142.99998
17.18000,143.16666,39.23948,1.24493,4.35994,143.16666
17.20000,143.33342,39.21053,1.24638,4.35673,143.33342
17.22000,143.50004,39.00950,1.24783,4.33439,143.50004
17.24000,143.66659,38.83772,1.24927,4.31530,143.66659
17.26000,143.83336,36.03579,1.25072,4.00398,143.83336
17.28000,144.00004,15.63036,1.25217,1.73671,144.00004
17.30000,144.16672,2.04126,1.25362,0.22681,144.16672
17.32000,144.33342,-1.69007,1.25507,-0.18779,144.33342
17.34000,144.49998,-1.11832,1.25652,-0.12426,144.49998
17.36000,144.66660,-0.34369,1.25797,-0.03819,144.66660
17.38000,144.83335,-0.03750,1.25942,-0.00417,144.83335
17.40000,145.00004,0.19700,1.26087,0.02189,145.00004
17.42000,145.16667,0.20648,1.26232,0.02294,145.16667
17.44000,145.33335,0.03159,1.26377,0.00351,145.33335
17.46000,145.49998,0.16225,1.26522,0.01803,145.49998
17.48000,145.66660,0.22333,1.26667,0.02481,145.66660
17.50000,145.83336,0.22098,1.26812,0.02455,145.83336
17.52000,146.00004,0.30439,1.26957,0.03382,146.00004
17.54000,146.16667,0.20822,1.27101,0.02314,146.16667
17.56000,146.33330,-0.00939,1.27246,-0.00104,146.33330
17.58000,146.49997,0.04658,1.27391,0.00518,146.49997
17.60000,146.66661,0.03012,1.27536,0.00335,146.66661
17.62000,146.83335,-0.16028,1.27681,-0.01781,146.83335
17.64000,147.00005,-0.15606,1.27826,-0.01734,147.00005
17.66000,147.16660,-0.17345,1.27971,-0.01927,147.16660
17.68000,147.33324,-0.10980,1.28116,-0.01220,147.33324
17.70000,147.49992,-0.11049,1.28261,-0.01228,147.49992
17.72000,147.66661,-0.08991,1.28406,-0.00999,147.66661
17.74000,147.83335,-0.21088,1.28551,-0.02343,147.83335
17.76000,147.99997,-0.10569,1.28696,-0.01174,147.99997
17.78000,148.16660,0.02446,1.28841,0.00272,148.16660
17.80000,148.33330,-0.06716,1.28985,-0.00746,148.33330
17.82000,148.50005,-0.10551,1.29130,-0.01172,148.50005
17.84000,148.66672,-0.05739,1.29275,-0.00638,148.66672
17.86000,148.83341,-0.14279,1.29420,-0.01587,148.83341
17.88000,148.99998,0.07621,1.29565,0.00847,148.99998
17.89600,149.13330,0.11618,1.29681,0.01291,149.13330