File: V_8/NR/RDSO NR Tensile 500.is_tens_RawData/Specimen_RawData_5.csv
Time,Extension,Load,Tensile strain,Tensile stress,Corrected Position
(sec),(mm),(N),(mm/mm),(MPa),(mm)
0.00000,0.00000,0.00600,0.00000,0.00067,0.00000
0.03000,0.05119,0.42130,0.00045,0.04681,0.05119
0.06000,0.23337,1.02324,0.00203,0.11369,0.23337
0.09000,0.51700,1.43925,0.00450,0.15992,0.51700
0.12000,0.83362,1.55769,0.00725,0.17308,0.83362
0.15000,1.16494,2.22265,0.01013,0.24696,1.16494
0.18000,1.47412,2.44679,0.01282,0.27187,1.47412
0.21000,1.73750,2.88543,0.01511,0.32060,1.73750
0.24000,1.98544,3.44843,0.01726,0.38316,1.98544
0.27000,2.23700,4.12022,0.01945,0.45780,2.23700
0.30000,2.49156,4.37118,0.02167,0.48569,2.49156
0.33000,2.74519,4.41556,0.02387,0.49062,2.74519
0.36000,2.99700,4.61563,0.02606,0.51285,2.99700
0.39000,3.24787,5.26251,0.02824,0.58472,3.24787
0.42000,3.49837,5.54061,0.03042,0.61562,3.49837
0.45000,3.74887,5.83678,0.03260,0.64853,3.74887
0.48000,3.99937,5.93335,0.03478,0.65926,3.99937
0.51000,4.24956,6.42119,0.03695,0.71347,4.24956
0.54000,4.49962,6.62348,0.03913,0.73594,4.49962
0.57000,4.74975,7.01387,0.04130,0.77932,4.74975
0.60000,4.99987,7.19183,0.04348,0.79909,4.99987
0.63000,5.24987,7.36611,0.04565,0.81846,5.24987
0.66000,5.49994,7.69453,0.04783,0.85495,5.49994
0.69000,5.75000,7.86310,0.05000,0.87368,5.75000
0.72000,6.00000,8.02744,0.05217,0.89194,6.00000
0.75000,6.24994,8.26424,0.05435,0.91825,6.24994
0.78000,6.50000,8.59882,0.05652,0.95542,6.50000
0.81000,6.75006,8.77746,0.05870,0.97527,6.75006
0.84000,7.00000,8.89281,0.06087,0.98809,7.00000
0.87000,7.24994,9.14852,0.06304,1.01650,7.24994
0.90000,7.50000,9.43387,0.06522,1.04821,7.50000
0.93000,7.75000,9.43132,0.06739,1.04792,7.75000
0.96000,7.99994,9.73087,0.06956,1.08121,7.99994
0.99000,8.25000,10.00368,0.07174,1.11152,8.25000
1.02000,8.50006,10.06378,0.07391,1.11820,8.50006
1.05000,8.75006,10.27112,0.07609,1.14124,8.75006
1.08000,8.99994,10.50709,0.07826,1.16745,8.99994
1.11000,9.25006,10.81500,0.08044,1.20167,9.25006
1.14000,9.50006,10.77775,0.08261,1.19753,9.50006
1.17000,9.75000,10.71799,0.08478,1.19089,9.75000
1.20000,9.99994,10.95038,0.08696,1.21671,9.99994
1.23000,10.25006,11.01058,0.08913,1.22340,10.25006
1.26000,10.50000,11.10970,0.09130,1.23441,10.50000
1.29000,10.74994,11.31773,0.09348,1.25753,10.74994
1.32000,11.00000,11.37709,0.09565,1.26412,11.00000
1.35000,11.25006,11.27327,0.09783,1.25259,11.25006
1.38000,11.49994,11.41131,0.10000,1.26792,11.49994
1.41000,11.74994,11.71610,0.10217,1.30179,11.74994
1.44000,12.00000,11.86466,0.10435,1.31830,12.00000
1.47000,12.25006,11.95646,0.10652,1.32850,12.25006
1.50000,12.49994,12.10208,0.10870,1.34468,12.49994
1.53000,12.75000,12.13389,0.11087,1.34821,12.75000
1.56000,13.00006,12.20472,0.11304,1.35608,13.00006
1.59000,13.25000,12.28735,0.11522,1.36526,13.25000
1.62000,13.50000,12.40604,0.11739,1.37845,13.50000
1.65000,13.75006,12.42438,0.11957,1.38049,13.75006
1.68000,14.00006,12.59036,0.12174,1.39893,14.00006
1.71000,14.25000,12.64591,0.12391,1.40510,14.25000
1.74000,14.50006,12.71044,0.12609,1.41227,14.50006
1.77000,14.75006,12.67214,0.12826,1.40802,14.75006
1.80000,15.00000,12.78188,0.13043,1.42021,15.00000
1.83000,15.25000,12.89966,0.13261,1.43330,15.25000
1.86000,15.50006,12.85102,0.13478,1.42789,15.50006
1.89000,15.75006,13.00421,0.13696,1.44491,15.75006
1.92000,16.00000,13.24155,0.13913,1.47128,16.00000
1.95000,16.24993,13.25823,0.14130,1.47314,16.24993
1.98000,16.50006,13.33198,0.14348,1.48133,16.50006
2.01000,16.75006,13.20398,0.14565,1.46711,16.75006
2.04000,17.00000,13.08229,0.14783,1.45359,17.00000
2.07000,17.25000,13.27814,0.15000,1.47535,17.25000
2.10000,17.50000,13.44875,0.15217,1.49431,17.50000
2.13000,17.74994,13.58583,0.15435,1.50954,17.74994
2.16000,17.99993,13.56138,0.15652,1.50682,17.99993
2.19000,18.25006,13.50549,0.15870,1.50061,18.25006
2.22000,18.50006,13.52053,0.16087,1.50228,18.50006
2.25000,18.75000,13.55477,0.16304,1.50609,18.75000
2.28000,19.00006,13.75464,0.16522,1.52829,19.00006
2.31000,19.25006,13.74083,0.16739,1.52676,19.25006
2.34000,19.50000,13.80304,0.16957,1.53367,19.50000
2.37000,19.75000,13.94425,0.17174,1.54936,19.75000
2.40000,20.00006,13.95922,0.17391,1.55102,20.00006
2.43000,20.25006,13.74237,0.17609,1.52693,20.25006
2.46000,20.49993,14.11101,0.17826,1.56789,20.49993
2.49000,20.75000,14.08314,0.18043,1.56479,20.75000
2.52000,21.00006,14.08765,0.18261,1.56529,21.00006
2.55000,21.25000,14.03112,0.18478,1.55901,21.25000
2.58000,21.49994,14.14459,0.18696,1.57162,21.49994
2.61000,21.75000,14.13707,0.18913,1.57079,21.75000
2.64000,22.00000,14.28919,0.19130,1.58769,22.00000
2.67000,22.24993,14.52971,0.19348,1.61441,22.24993
2.70000,22.49993,14.51157,0.19565,1.61240,22.49993
2.73000,22.75000,14.33229,0.19783,1.59248,22.75000
2.76000,23.00000,14.49719,0.20000,1.61080,23.00000
2.79000,23.25000,14.44480,0.20217,1.60498,23.25000
2.82000,23.50006,14.58805,0.20435,1.62089,23.50006
2.85000,23.75006,14.61127,0.20652,1.62347,23.75006
2.88000,24.00006,14.56449,0.20870,1.61828,24.00006
2.91000,24.25000,14.39171,0.21087,1.59908,24.25000
2.94000,24.50006,14.64448,0.21304,1.62716,24.50006
2.97000,24.75006,14.77715,0.21522,1.64191,24.75006
3.00000,24.99993,14.61110,0.21739,1.62346,24.99993
3.03000,25.25006,14.77487,0.21957,1.64165,25.25006
3.06000,25.50012,14.86385,0.22174,1.65154,25.50012
3.09000,25.74993,14.97401,0.22391,1.66378,25.74993
3.12000,25.99987,14.75760,0.22609,1.63973,25.99987
3.15000,26.25000,14.80318,0.22826,1.64480,26.25000
3.18000,26.50006,14.93230,0.23044,1.65914,26.50006
3.21000,26.75000,14.97073,0.23261,1.66341,26.75000
3.24000,27.00000,15.10107,0.23478,1.67790,27.00000
3.27000,27.25006,15.14834,0.23696,1.68315,27.25006
3.30000,27.49993,15.05943,0.23913,1.67327,27.49993
3.33000,27.74993,15.17983,0.24130,1.68665,27.74993
3.36000,28.00006,15.25612,0.24348,1.69512,28.00006
3.39000,28.25006,15.18865,0.24565,1.68763,28.25006
3.42000,28.50000,15.26318,0.24783,1.69591,28.50000
3.45000,28.75000,15.54911,0.25000,1.72768,28.75000
3.48000,29.00006,15.75726,0.25217,1.75081,29.00006
3.51000,29.25000,15.70566,0.25435,1.74507,29.25000
3.54000,29.50000,15.50324,0.25652,1.72258,29.50000
3.57000,29.75006,15.63174,0.25870,1.73686,29.75006
3.60000,30.00006,15.61075,0.26087,1.73453,30.00006
3.63000,30.25000,15.75723,0.26304,1.75080,30.25000
3.66000,30.49999,15.74984,0.26522,1.74998,30.49999
3.69000,30.75000,15.87685,0.26739,1.76409,30.75000
3.72000,31.00000,15.93026,0.26957,1.77003,31.00000
3.75000,31.24993,15.94400,0.27174,1.77156,31.24993
3.78000,31.49999,15.77154,0.27391,1.75239,31.49999
3.81000,31.75006,15.83644,0.27609,1.75960,31.75006
3.84000,31.99999,16.04909,0.27826,1.78323,31.99999
3.87000,32.24999,16.16979,0.28043,1.79664,32.24999
3.90000,32.50000,15.95848,0.28261,1.77316,32.50000
3.93000,32.75000,16.15355,0.28478,1.79484,32.75000
3.96000,32.99993,16.02250,0.28696,1.78028,32.99993
3.99000,33.24999,16.20655,0.28913,1.80073,33.24999
4.02000,33.50006,16.22776,0.29130,1.80308,33.50006
4.05000,33.75006,16.18510,0.29348,1.79834,33.75006
4.08000,34.00000,16.17753,0.29565,1.79750,34.00000
4.11000,34.25006,16.14495,0.29783,1.79388,34.25006
4.14000,34.50006,16.35332,0.30000,1.81704,34.50006
4.17000,34.75000,16.29861,0.30217,1.81096,34.75000
4.20000,34.99999,16.49229,0.30435,1.83248,34.99999
4.23000,35.25006,16.59427,0.30652,1.84381,35.25006
4.26000,35.49999,16.63421,0.30870,1.84825,35.49999
4.29000,35.75000,16.64332,0.31087,1.84926,35.75000
4.32000,35.99999,16.61384,0.31304,1.84598,35.99999
4.35000,36.25000,16.78630,0.31522,1.86514,36.25000
4.38000,36.50000,16.79113,0.31739,1.86568,36.50000
4.41000,36.74999,17.01057,0.31957,1.89006,36.74999
4.44000,36.99999,17.08906,0.32174,1.89878,36.99999
4.47000,37.24993,17.11240,0.32391,1.90138,37.24993
4.50000,37.49993,16.81226,0.32609,1.86803,37.49993
4.53000,37.74999,16.90168,0.32826,1.87796,37.74999
4.56000,38.00006,17.17329,0.33044,1.90814,38.00006
4.59000,38.25000,17.33424,0.33261,1.92603,38.25000
4.62000,38.50000,17.15274,0.33478,1.90586,38.50000
4.65000,38.75006,17.17816,0.33696,1.90868,38.75006
4.68000,39.00006,17.26988,0.33913,1.91888,39.00006
4.71000,39.24999,17.36525,0.34130,1.92947,39.24999
4.74000,39.49999,17.35741,0.34348,1.92860,39.49999
4.77000,39.75006,17.36562,0.34565,1.92951,39.75006
4.80000,39.99999,17.46121,0.34783,1.94013,39.99999
4.83000,40.25000,17.69796,0.35000,1.96644,40.25000
4.86000,40.50006,17.64171,0.35217,1.96019,40.50006
4.89000,40.75006,17.39528,0.35435,1.93281,40.75006
4.92000,40.99999,17.67851,0.35652,1.96428,40.99999
4.95000,41.25000,17.52246,0.35870,1.94694,41.25000
4.98000,41.50006,17.53172,0.36087,1.94797,41.50006
5.01000,41.74999,17.91321,0.36304,1.99036,41.74999
5.04000,41.99993,17.83609,0.36522,1.98179,41.99993
5.07000,42.25005,17.83928,0.36739,1.98214,42.25005
5.10000,42.50005,18.05188,0.36957,2.00576,42.50005
5.13000,42.74993,18.06687,0.37174,2.00743,42.74993
5.16000,42.99993,18.10118,0.37391,2.01124,42.99993
5.19000,43.25006,17.96751,0.37609,1.99639,43.25006
5.22000,43.50006,18.05061,0.37826,2.00562,43.50006
5.25000,43.75000,18.05223,0.38043,2.00580,43.75000
5.28000,44.00006,18.12616,0.38261,2.01402,44.00006
5.31000,44.25006,18.30297,0.38478,2.03366,44.25006
5.34000,44.49999,18.42981,0.38696,2.04776,44.49999
5.37000,44.74999,18.38937,0.38913,2.04326,44.74999
5.40000,44.99999,18.16905,0.39130,2.01878,44.99999
5.43000,45.25006,18.36806,0.39348,2.04090,45.25006
5.46000,45.49999,18.48633,0.39565,2.05404,45.49999
5.49000,45.75000,18.64724,0.39783,2.07192,45.75000
5.52000,45.99999,18.68743,0.40000,2.07638,45.99999
5.55000,46.24999,18.64241,0.40217,2.07138,46.24999
5.58000,46.49993,18.64447,0.40435,2.07161,46.49993
5.61000,46.75006,18.84329,0.40652,2.09370,46.75006
5.64000,47.00006,18.86636,0.40870,2.09626,47.00006
5.67000,47.24999,18.69911,0.41087,2.07768,47.24999
5.70000,47.49993,18.82144,0.41304,2.09127,47.49993
5.73000,47.74999,18.96971,0.41522,2.10775,47.74999
5.76000,47.99999,18.91179,0.41739,2.10131,47.99999
5.79000,48.24993,18.94451,0.41956,2.10495,48.24993
5.82000,48.50006,19.07618,0.42174,2.11958,48.50006
5.85000,48.75012,19.02110,0.42391,2.11346,48.75012
5.88000,48.99999,19.21105,0.42609,2.13456,48.99999
5.91000,49.25000,19.35849,0.42826,2.15094,49.25000
5.94000,49.50006,19.43838,0.43044,2.15982,49.50006
5.97000,49.75006,19.37000,0.43261,2.15222,49.75006
6.00000,49.99993,19.49713,0.43478,2.16635,49.99993
6.03000,50.25005,19.48060,0.43696,2.16451,50.25005
6.06000,50.50005,19.59960,0.43913,2.17773,50.50005
6.09000,50.74999,19.51736,0.44130,2.16860,50.74999
6.12000,50.99999,19.54143,0.44348,2.17127,50.99999
6.15000,51.24999,19.58434,0.44565,2.17604,51.24999
6.18000,51.49999,19.82950,0.44783,2.20328,51.49999
6.21000,51.74999,19.94350,0.45000,2.21595,51.74999
6.24000,51.99999,19.74040,0.45217,2.19338,51.99999
6.27000,52.25006,19.94715,0.45435,2.21635,52.25006
6.30000,52.49999,19.89837,0.45652,2.21093,52.49999
6.33000,52.74987,20.04069,0.45869,2.22674,52.74987
6.36000,52.99993,20.04377,0.46087,2.22709,52.99993
6.39000,53.25005,20.19001,0.46304,2.24333,53.25005
6.42000,53.50005,20.27374,0.46522,2.25264,53.50005
6.45000,53.75005,20.25312,0.46739,2.25035,53.75005
6.48000,54.00012,20.23777,0.46957,2.24864,54.00012
6.51000,54.25006,20.30813,0.47174,2.25646,54.25006
6.54000,54.49993,20.24406,0.47391,2.24934,54.49993
6.57000,54.75000,20.32290,0.47609,2.25810,54.75000
6.60000,55.00006,20.31486,0.47826,2.25721,55.00006
6.63000,55.24999,20.55973,0.48043,2.28441,55.24999
6.66000,55.49999,20.57415,0.48261,2.28602,55.49999
6.69000,55.75005,20.44596,0.48478,2.27177,55.75005
6.72000,55.99999,20.62277,0.48696,2.29142,55.99999
6.75000,56.24993,20.67045,0.48913,2.29672,56.24993
6.78000,56.49999,20.63178,0.49130,2.29242,56.49999
6.81000,56.75005,20.61361,0.49348,2.29040,56.75005
6.84000,56.99999,20.77444,0.49565,2.30827,56.99999
6.87000,57.24999,20.80131,0.49783,2.31126,57.24999
6.90000,57.49999,20.95768,0.50000,2.32863,57.49999
6.93000,57.74999,20.99983,0.50217,2.33331,57.74999
6.96000,57.99993,20.94573,0.50435,2.32730,57.99993
6.99000,58.24999,21.08034,0.50652,2.34226,58.24999
7.02000,58.50011,21.11139,0.50870,2.34571,58.50011
7.05000,58.75005,21.18046,0.51087,2.35338,58.75005
7.08000,59.00005,21.31065,0.51304,2.36785,59.00005
7.11000,59.25005,21.35123,0.51522,2.37236,59.25005
7.14000,59.50006,21.21932,0.51739,2.35770,59.50006
7.17000,59.74993,21.28452,0.51956,2.36495,59.74993
7.20000,59.99999,21.49830,0.52174,2.38870,59.99999
7.23000,60.25005,21.53278,0.52391,2.39253,60.25005
7.26000,60.50006,21.61841,0.52609,2.40205,60.50006
7.29000,60.74993,21.58566,0.52826,2.39841,60.74993
7.32000,60.99993,21.69619,0.53043,2.41069,60.99993
7.35000,61.24999,21.79998,0.53261,2.42222,61.24999
7.38000,61.49993,21.87000,0.53478,2.43000,61.49993
7.41000,61.74999,21.68027,0.53696,2.40892,61.74999
7.44000,62.00006,21.81323,0.53913,2.42369,62.00006
7.47000,62.25005,21.96165,0.54130,2.44018,62.25005
7.50000,62.49993,22.00585,0.54348,2.44509,62.49993
7.53000,62.74999,21.98582,0.54565,2.44287,62.74999
7.56000,63.00006,22.02158,0.54783,2.44684,63.00006
7.59000,63.24999,22.08660,0.55000,2.45407,63.24999
7.62000,63.50006,22.10982,0.55217,2.45665,63.50006
7.65000,63.75011,22.18202,0.55435,2.46467,63.75011
7.68000,64.00005,22.13620,0.55652,2.45958,64.00005
7.71000,64.24999,22.38082,0.55870,2.48676,64.24999
7.74000,64.49999,22.39673,0.56087,2.48853,64.49999
7.77000,64.75005,22.40653,0.56304,2.48961,64.75005
7.80000,64.99999,22.30668,0.56522,2.47852,64.99999
7.83000,65.24999,22.53055,0.56739,2.50339,65.24999
7.86000,65.49999,22.74399,0.56957,2.52711,65.49999
7.89000,65.74999,22.68012,0.57174,2.52001,65.74999
7.92000,65.99993,22.68316,0.57391,2.52035,65.99993
7.95000,66.24999,22.79300,0.57609,2.53256,66.24999
7.98000,66.50005,22.66719,0.57826,2.51858,66.50005
8.01000,66.74999,22.75279,0.58043,2.52809,66.74999
8.04000,66.99999,22.94303,0.58261,2.54923,66.99999
8.07000,67.24999,22.93654,0.58478,2.54850,67.24999
8.10000,67.49999,22.99500,0.58696,2.55500,67.49999
8.13000,67.74999,23.04394,0.58913,2.56044,67.74999
8.16000,67.99993,22.93662,0.59130,2.54851,67.99993
8.19000,68.24999,22.98163,0.59348,2.55351,68.24999
8.22000,68.50005,23.21038,0.59565,2.57893,68.50005
8.25000,68.74999,23.22982,0.59783,2.58109,68.74999
8.28000,69.00005,23.35380,0.60000,2.59487,69.00005
8.31000,69.25012,23.29174,0.60217,2.58797,69.25012
8.34000,69.50005,23.38275,0.60435,2.59808,69.50005
8.37000,69.74993,23.41770,0.60652,2.60197,69.74993
8.40000,69.99999,23.39063,0.60870,2.59896,69.99999
8.43000,70.25005,23.49448,0.61087,2.61050,70.25005
8.46000,70.49999,23.62031,0.61304,2.62448,70.49999
8.49000,70.74999,23.71303,0.61522,2.63478,70.74999
8.52000,70.99999,23.81386,0.61739,2.64598,70.99999
8.55000,71.24993,23.74869,0.61956,2.63874,71.24993
8.58000,71.49999,23.86219,0.62174,2.65135,71.49999
8.61000,71.75006,23.67517,0.62391,2.63057,71.75006
8.64000,72.00005,23.93169,0.62609,2.65908,72.00005
8.67000,72.24999,24.02598,0.62826,2.66955,72.24999
8.70000,72.49999,24.02583,0.63043,2.66954,72.49999
8.73000,72.74999,23.91489,0.63261,2.65721,72.74999
8.76000,72.99999,23.98498,0.63478,2.66500,72.99999
8.79000,73.24999,24.11261,0.63696,2.67918,73.24999
8.82000,73.49999,24.31718,0.63913,2.70191,73.49999
8.85000,73.75005,24.26702,0.64130,2.69634,73.75005
8.88000,74.00006,24.22304,0.64348,2.69145,74.00006
8.91000,74.24999,24.30761,0.64565,2.70085,74.24999
8.94000,74.50006,24.30104,0.64783,2.70012,74.50006
8.97000,74.75005,24.30450,0.65000,2.70050,74.75005
9.00000,74.99999,24.39266,0.65217,2.71030,74.99999
9.03000,75.24999,24.71340,0.65435,2.74593,75.24999
9.06000,75.50005,24.66251,0.65652,2.74028,75.50005
9.09000,75.74999,24.75427,0.65870,2.75047,75.74999
9.12000,75.99999,24.50224,0.66087,2.72247,75.99999
9.15000,76.25006,24.63471,0.66304,2.73719,76.25006
9.18000,76.50005,24.80754,0.66522,2.75639,76.50005
9.21000,76.74993,24.62320,0.66739,2.73591,76.74993
9.24000,76.99999,24.82496,0.66957,2.75833,76.99999
9.27000,77.25005,25.07550,0.67174,2.78617,77.25005
9.30000,77.49998,25.07335,0.67391,2.78593,77.49998
9.33000,77.74992,24.89664,0.67609,2.76629,77.74992
9.36000,77.99999,24.86287,0.67826,2.76254,77.99999
9.39000,78.24999,24.98912,0.68043,2.77657,78.24999
9.42000,78.49999,25.12987,0.68261,2.79221,78.49999
9.45000,78.74999,25.23126,0.68478,2.80347,78.74999
9.48000,79.00012,25.35232,0.68696,2.81692,79.00012
9.51000,79.25005,25.31762,0.68913,2.81307,79.25005
9.54000,79.49992,25.50987,0.69130,2.83443,79.49992
9.57000,79.74998,25.57669,0.69348,2.84185,79.74998
9.60000,79.99999,25.62410,0.69565,2.84712,79.99999
9.63000,80.24999,25.46910,0.69783,2.82990,80.24999
9.66000,80.49999,25.49244,0.70000,2.83249,80.49999
9.69000,80.75004,25.76755,0.70217,2.86306,80.75004
9.72000,80.99998,25.90913,0.70435,2.87879,80.99998
9.75000,81.24992,25.84063,0.70652,2.87118,81.24992
9.78000,81.49993,25.78667,0.70869,2.86519,81.49993
9.81000,81.75005,25.64903,0.71087,2.84989,81.75005
9.84000,81.99993,25.87964,0.71304,2.87552,81.99993
9.87000,82.24992,26.06719,0.71522,2.89635,82.24992
9.90000,82.49999,26.23322,0.71739,2.91480,82.49999
9.93000,82.74999,26.03141,0.71957,2.89238,82.74999
9.96000,82.99992,26.03178,0.72174,2.89242,82.99992
9.99000,83.24998,26.07704,0.72391,2.89745,83.24998
10.02000,83.50004,25.98545,0.72609,2.88727,83.50004
10.05000,83.75005,26.02595,0.72826,2.89177,83.75005
10.08000,83.99999,26.23844,0.73043,2.91538,83.99999
10.11000,84.25005,26.37500,0.73261,2.93056,84.25005
10.14000,84.50005,26.36253,0.73478,2.92917,84.50005
10.17000,84.74999,26.50101,0.73696,2.94456,84.74999
10.20000,84.99999,26.49530,0.73913,2.94392,84.99999
10.23000,85.25005,26.53625,0.74130,2.94847,85.25005
10.26000,85.50005,26.55290,0.74348,2.95032,85.50005
10.29000,85.74999,26.66493,0.74565,2.96277,85.74999
10.32000,86.00005,26.88180,0.74783,2.98687,86.00005
10.35000,86.24999,26.81072,0.75000,2.97897,86.24999
10.38000,86.49998,27.00501,0.75217,3.00056,86.49998
10.41000,86.74999,27.00442,0.75435,3.00049,86.74999
10.44000,87.00005,27.03295,0.75652,3.00366,87.00005
10.47000,87.24999,26.93741,0.75870,2.99305,87.24999
10.50000,87.49999,27.12428,0.76087,3.01381,87.49999
10.53000,87.74999,27.14995,0.76304,3.01666,87.74999
10.56000,87.99993,27.09242,0.76522,3.01027,87.99993
10.59000,88.24993,27.06558,0.76739,3.00729,88.24993
10.62000,88.49998,27.26185,0.76957,3.02909,88.49998
10.65000,88.75005,27.29053,0.77174,3.03228,88.75005
10.68000,89.00005,27.45386,0.77391,3.05043,89.00005
10.71000,89.24999,27.26924,0.77609,3.02992,89.24999
10.74000,89.49999,27.42134,0.77826,3.04681,89.49999
10.77000,89.75005,27.38193,0.78044,3.04244,89.75005
10.80000,89.99999,27.53713,0.78261,3.05968,89.99999
10.83000,90.24998,27.54994,0.78478,3.06110,90.24998
10.86000,90.50005,27.64932,0.78696,3.07215,90.50005
10.89000,90.75006,27.71009,0.78913,3.07890,90.75006
10.92000,90.99999,27.69738,0.79130,3.07749,90.99999
10.95000,91.24999,27.70325,0.79348,3.07814,91.24999
10.98000,91.50005,27.88569,0.79565,3.09841,91.50005
11.01000,91.75004,27.88169,0.79783,3.09797,91.75004
11.04000,91.99998,28.15568,0.80000,3.12841,91.99998
11.07000,92.24999,28.05232,0.80217,3.11692,92.24999
11.10000,92.49998,28.00141,0.80435,3.11127,92.49998
11.13000,92.74987,27.99301,0.80652,3.11033,92.74987
11.16000,92.99998,28.03295,0.80870,3.11477,92.99998
11.19000,93.25005,28.00726,0.81087,3.11192,93.25005
11.22000,93.50005,28.11142,0.81304,3.12349,93.50005
11.25000,93.74992,28.12257,0.81522,3.12473,93.74992
11.28000,94.00005,28.27299,0.81739,3.14144,94.00005
11.31000,94.25005,28.36838,0.81957,3.15204,94.25005
11.34000,94.49999,28.35506,0.82174,3.15056,94.49999
11.37000,94.74998,28.46615,0.82391,3.16291,94.74998
11.40000,95.00004,28.57452,0.82609,3.17495,95.00004
11.43000,95.25005,28.76930,0.82826,3.19659,95.25005
11.46000,95.49998,28.66703,0.83043,3.18523,95.49998
11.49000,95.74998,28.64327,0.83261,3.18259,95.74998
11.52000,96.00005,28.68013,0.83478,3.18668,96.00005
11.55000,96.24999,28.74915,0.83696,3.19435,96.24999
11.58000,96.49992,28.77469,0.83913,3.19719,96.49992
11.61000,96.75005,28.82387,0.84130,3.20265,96.75005
11.64000,97.00004,28.85431,0.84348,3.20603,97.00004
11.67000,97.24999,29.01269,0.84565,3.22363,97.24999
11.70000,97.49993,29.11247,0.84783,3.23472,97.49993
11.73000,97.75005,29.16812,0.85000,3.24090,97.75005
11.76000,97.99998,29.17880,0.85217,3.24209,97.99998
11.79000,98.24992,29.18734,0.85435,3.24304,98.24992
11.82000,98.49999,29.09256,0.85652,3.23251,98.49999
11.85000,98.75004,29.17103,0.85870,3.24123,98.75004
11.88000,98.99999,29.16887,0.86087,3.24099,98.99999
11.91000,99.24999,29.07640,0.86304,3.23071,99.24999
11.94000,99.50005,29.44928,0.86522,3.27214,99.50005
11.97000,99.75005,29.65451,0.86739,3.29495,99.75005
12.00000,99.99998,29.58983,0.86957,3.28776,99.99998
12.03000,100.25005,29.53279,0.87174,3.28142,100.25005
12.06000,100.50005,29.80530,0.87391,3.31170,100.50005
12.09000,100.74999,29.77932,0.87609,3.30881,100.74999
12.12000,100.99999,29.75306,0.87826,3.30590,100.99999
12.15000,101.25005,29.82154,0.88044,3.31350,101.25005
12.18000,101.50004,29.87961,0.88261,3.31996,101.50004
12.21000,101.74998,29.73372,0.88478,3.30375,101.74998
12.24000,101.99999,29.69886,0.88696,3.29987,101.99999
12.27000,102.25005,29.89575,0.88913,3.32175,102.25005
12.30000,102.49998,30.10226,0.89130,3.34470,102.49998
12.33000,102.74992,30.24901,0.89348,3.36100,102.74992
12.36000,102.99998,30.18849,0.89565,3.35428,102.99998
12.39000,103.25004,30.29388,0.89783,3.36599,103.25004
12.42000,103.49998,30.37487,0.90000,3.37499,103.49998
12.45000,103.74999,30.38119,0.90217,3.37569,103.74999
12.48000,104.00005,30.42326,0.90435,3.38036,104.00005
12.51000,104.25005,30.57846,0.90652,3.39761,104.25005
12.54000,104.50005,30.56401,0.90870,3.39600,104.50005
12.57000,104.75005,30.55669,0.91087,3.39519,104.75005
12.60000,105.00005,30.64136,0.91304,3.40460,105.00005
12.63000,105.24998,30.84591,0.91522,3.42732,105.24998
12.66000,105.49999,30.83048,0.91739,3.42561,105.49999
12.69000,105.75005,30.73947,0.91957,3.41550,105.75005
12.72000,106.00004,30.83996,0.92174,3.42666,106.00004
12.75000,106.24998,30.90425,0.92391,3.43380,106.24998
12.78000,106.50005,30.85754,0.92609,3.42862,106.50005
12.81000,106.75005,30.97566,0.92826,3.44174,106.75005
12.84000,106.99992,31.06772,0.93043,3.45197,106.99992
12.87000,107.24992,31.08688,0.93261,3.45410,107.24992
12.90000,107.50005,30.86263,0.93478,3.42918,107.50005
12.93000,107.74999,31.21036,0.93696,3.46782,107.74999
12.96000,107.99998,31.49598,0.93913,3.49955,107.99998
12.99000,108.24999,31.35745,0.94130,3.48416,108.24999
13.02000,108.50005,31.34349,0.94348,3.48261,108.50005
13.05000,108.75005,31.42632,0.94565,3.49181,108.75005
13.08000,108.99998,31.50699,0.94783,3.50078,108.99998
13.11000,109.25005,31.53325,0.95000,3.50369,109.25005
13.14000,109.50005,31.37812,0.95217,3.48646,109.50005
13.17000,109.74999,31.57151,0.95435,3.50795,109.74999
13.20000,109.99999,31.62372,0.95652,3.51375,109.99999
13.23000,110.25004,31.83190,0.95870,3.53688,110.25004
13.26000,110.50005,31.74946,0.96087,3.52772,110.50005
13.29000,110.74998,31.84272,0.96304,3.53808,110.74998
13.32000,111.00005,31.83532,0.96522,3.53726,111.00005
13.35000,111.25005,31.91208,0.96739,3.54579,111.25005
13.38000,111.49999,31.95401,0.96957,3.55045,111.49999
13.41000,111.74999,31.90640,0.97174,3.54516,111.74999
13.44000,112.00004,31.83919,0.97391,3.53769,112.00004
13.47000,112.24998,31.97061,0.97609,3.55229,112.24998
13.50000,112.49992,32.12030,0.97826,3.56892,112.49992
13.53000,112.74998,32.15346,0.98043,3.57261,112.74998
13.56000,113.00005,32.22993,0.98261,3.58110,113.00005
13.59000,113.24998,32.26598,0.98478,3.58511,113.24998
13.62000,113.49992,32.47606,0.98696,3.60845,113.49992
13.65000,113.75004,32.48742,0.98913,3.60971,113.75004
13.68000,114.00005,32.39744,0.99130,3.59972,114.00005
13.71000,114.24999,32.39882,0.99348,3.59987,114.24999
13.74000,114.50005,32.54664,0.99565,3.61629,114.50005
13.77000,114.75004,32.50780,0.99783,3.61198,114.75004
13.80000,114.99998,32.64241,1.00000,3.62693,114.99998
13.83000,115.24999,32.68105,1.00217,3.63123,115.24999
13.86000,115.50005,32.80865,1.00435,3.64541,115.50005
13.89000,115.75005,32.96162,1.00652,3.66240,115.75005
13.92000,115.99999,32.90911,1.00870,3.65657,115.99999
13.95000,116.24998,33.02305,1.01087,3.66923,116.24998
13.98000,116.50004,33.16485,1.01304,3.68498,116.50004
14.01000,116.75005,33.02138,1.01522,3.66904,116.75005
14.04000,116.99999,33.12498,1.01739,3.68055,116.99999
14.07000,117.24998,33.31116,1.01957,3.70124,117.24998
14.10000,117.49999,33.39654,1.02174,3.71073,117.49999
14.13000,117.74998,33.41936,1.02391,3.71326,117.74998
14.16000,117.99992,33.42965,1.02609,3.71441,117.99992
14.19000,118.24999,33.49107,1.02826,3.72123,118.24999
14.22000,118.50005,33.41138,1.03044,3.71238,118.50005
14.25000,118.75005,33.33149,1.03261,3.70350,118.75005
14.28000,119.00004,33.55058,1.03478,3.72784,119.00004
14.31000,119.25004,33.52751,1.03696,3.72528,119.25004
14.34000,119.49998,33.56450,1.03913,3.72939,119.49998
14.37000,119.74998,33.60917,1.04130,3.73435,119.74998
14.40000,120.00005,33.86192,1.04348,3.76244,120.00005
14.43000,120.25005,33.92275,1.04565,3.76919,120.25005
14.46000,120.49999,33.98545,1.04783,3.77616,120.49999
14.49000,120.74999,33.95626,1.05000,3.77292,120.74999
14.52000,120.99999,33.86956,1.05217,3.76328,120.99999
14.55000,121.24998,34.09130,1.05435,3.78792,121.24998
14.58000,121.49998,33.93495,1.05652,3.77055,121.49998
14.61000,121.75005,33.99564,1.05870,3.77729,121.75005
14.64000,121.99998,34.05843,1.06087,3.78427,121.99998
14.67000,122.24992,34.22522,1.06304,3.80280,122.24992
14.70000,122.49999,33.98521,1.06522,3.77613,122.49999
14.73000,122.74999,34.15899,1.06739,3.79544,122.74999
14.76000,122.99999,34.38843,1.06957,3.82094,122.99999
14.79000,123.24998,34.31437,1.07174,3.81271,123.24998
14.82000,123.50004,34.36648,1.07391,3.81850,123.50004
14.85000,123.75005,34.34900,1.07609,3.81656,123.75005
14.88000,123.99998,34.54081,1.07826,3.83787,123.99998
14.91000,124.24998,34.70574,1.08043,3.85619,124.24998
14.94000,124.50005,34.68183,1.08261,3.85354,124.50005
14.97000,124.74999,34.69971,1.08478,3.85552,124.74999
15.00000,124.99998,34.83642,1.08696,3.87071,124.99998
15.03000,125.25004,34.90793,1.08913,3.87866,125.25004
15.06000,125.50004,34.88520,1.09130,3.87613,125.50004
15.09000,125.74998,34.91773,1.09348,3.87975,125.74998
15.12000,125.99992,35.02774,1.09565,3.89197,125.99992
15.15000,126.24999,35.06502,1.09783,3.89611,126.24999
15.18000,126.50005,35.14902,1.10000,3.90545,126.50005
15.21000,126.74998,35.34045,1.10217,3.92672,126.74998
15.24000,127.00004,35.20041,1.10435,3.91116,127.00004
15.27000,127.25005,35.28603,1.10652,3.92067,127.25005
15.30000,127.49991,35.28250,1.10869,3.92028,127.49991
15.33000,127.74984,35.32159,1.11087,3.92462,127.74984
15.36000,128.00003,35.35308,1.11304,3.92812,128.00003
15.39000,128.25011,35.38727,1.11522,3.93192,128.25011
15.42000,128.50004,35.50062,1.11739,3.94451,128.50004
15.45000,128.75005,35.63449,1.11957,3.95939,128.75005
15.48000,129.00010,35.64903,1.12174,3.96100,129.00010
15.51000,129.24998,35.68073,1.12391,3.96452,129.24998
15.54000,129.49998,35.80308,1.12609,3.97812,129.49998
15.57000,129.75005,35.96360,1.12826,3.99596,129.75005
15.60000,130.00011,35.92191,1.13044,3.99132,130.00011
15.63000,130.24998,36.03463,1.13261,4.00385,130.24998
15.66000,130.49997,36.01444,1.13478,4.00161,130.49997
15.69000,130.74997,36.07596,1.13696,4.00844,130.74997
15.72000,130.99998,36.11182,1.13913,4.01242,130.99998
15.75000,131.24998,36.09786,1.14130,4.01087,131.24998
15.78000,131.49998,36.10957,1.14348,4.01217,131.49998
15.81000,131.75005,36.17692,1.14565,4.01966,131.75005
15.84000,131.99999,36.37691,1.14783,4.04188,131.99999
15.87000,132.24992,36.41012,1.15000,4.04557,132.24992
15.90000,132.49998,36.42521,1.15217,4.04725,132.49998
15.93000,132.74997,36.57568,1.15435,4.06396,132.74997
15.96000,132.99991,36.59635,1.15652,4.06626,132.99991
15.99000,133.24998,36.48938,1.15870,4.05438,133.24998
16.02000,133.50010,36.55844,1.16087,4.06205,133.50010
16.05000,133.75004,36.69177,1.16304,4.07686,133.75004
16.08000,133.99998,36.85557,1.16522,4.09506,133.99998
16.11000,134.25005,36.85253,1.16739,4.09473,134.25005
16.14000,134.50004,36.87962,1.16957,4.09774,134.50004
16.17000,134.74998,37.01447,1.17174,4.11272,134.74998
16.20000,134.99998,37.05468,1.17391,4.11719,134.99998
16.23000,135.25004,37.12007,1.17609,4.12445,135.25004
16.26000,135.50005,37.16381,1.17826,4.12931,135.50005
16.29000,135.74998,37.11356,1.18043,4.12373,135.74998
16.32000,135.99998,37.10797,1.18261,4.12311,135.99998
16.35000,136.25003,37.20775,1.18478,4.13419,136.25003
16.38000,136.49997,37.16646,1.18696,4.12961,136.49997
16.41000,136.74999,37.38301,1.18913,4.15367,136.74999
16.44000,137.00004,37.52080,1.19130,4.16898,137.00004
16.47000,137.24998,37.41235,1.19348,4.15693,137.24998
16.50000,137.49992,37.34823,1.19565,4.14980,137.49992
16.53000,137.74998,37.44801,1.19783,4.16089,137.74998
16.56000,138.00004,37.64413,1.20000,4.18268,138.00004
16.59000,138.24998,37.65378,1.20217,4.18375,138.24998
16.62000,138.50003,37.63527,1.20435,4.18170,138.50003
16.65000,138.75010,37.85201,1.20652,4.20578,138.75010
16.68000,139.00004,37.95478,1.20870,4.21720,139.00004
16.71000,139.25004,37.92412,1.21087,4.21379,139.25004
16.74000,139.50004,38.07395,1.21304,4.23044,139.50004
16.77000,139.75004,38.12186,1.21522,4.23576,139.75004
16.80000,140.00005,38.05548,1.21739,4.22839,140.00005
16.83000,140.24998,38.13111,1.21957,4.23679,140.24998
16.86000,140.50004,38.09570,1.22174,4.23286,140.50004
16.89000,140.75004,38.21439,1.22391,4.24604,140.75004
16.92000,140.99992,38.39959,1.22609,4.26662,140.99992
16.95000,141.24991,38.46943,1.22826,4.27438,141.24991
16.98000,141.50004,38.40473,1.23044,4.26719,141.50004
17.01000,141.75004,38.41291,1.23261,4.26810,141.75004
17.04000,141.99992,38.46317,1.23478,4.27368,141.99992
17.07000,142.24998,38.58831,1.23696,4.28759,142.24998
17.10000,142.50005,38.71513,1.23913,4.30168,142.50005
17.13000,142.74999,38.63499,1.24130,4.29278,142.74999
17.16000,142.99998,38.67178,1.24348,4.29686,142.99998
17.19000,143.25003,38.82764,1.24565,4.31418,143.25003
17.22000,143.50004,38.71386,1.24783,4.30154,143.50004
17.25000,143.74998,38.73399,1.25000,4.30378,143.74998
17.28000,144.00004,39.06800,1.25217,4.34089,144.00004
17.31000,144.25009,39.12795,1.25435,4.34755,144.25009
17.34000,144.49998,38.96308,1.25652,4.32923,144.49998
17.37000,144.74991,39.06026,1.25869,4.34003,144.74991
17.40000,145.00004,39.17218,1.26087,4.35246,145.00004
17.43000,145.25004,39.16508,1.26304,4.35168,145.25004
17.46000,145.49998,39.32276,1.26522,4.36919,145.49998
17.49000,145.74997,39.27970,1.26739,4.36441,145.74997
17.52000,146.00004,39.46275,1.26957,4.38475,146.00004
17.55000,146.24998,39.39902,1.27174,4.37767,146.24998
17.58000,146.49992,39.43855,1.27391,4.38206,146.49992
17.61000,146.74998,39.56164,1.27609,4.39574,146.74998
17.64000,147.00005,39.73303,1.27826,4.41478,147.00005
17.67000,147.24999,39.60235,1.28043,4.40026,147.24999
17.70000,147.49992,39.80107,1.28261,4.42234,147.49992
17.73000,147.74998,39.89981,1.28478,4.43331,147.74998
17.76000,147.99997,39.88434,1.28696,4.43159,147.99997
17.79000,148.24991,39.98367,1.28913,4.44263,148.24991
17.82000,148.50005,39.87346,1.29130,4.43039,148.50005
17.85000,148.75010,39.96193,1.29348,4.44021,148.75010
17.88000,148.99998,40.11504,1.29565,4.45723,148.99998
17.91000,149.24997,40.27958,1.29783,4.47551,149.24997
17.94000,149.50004,40.18009,1.30000,4.46445,149.50004
17.97000,149.74998,40.19768,1.30217,4.46641,149.74998
18.00000,149.99998,40.30710,1.30435,4.47857,149.99998
18.03000,150.25004,40.38023,1.30652,4.48669,150.25004
18.06000,150.50011,40.34492,1.30870,4.48277,150.50011
18.09000,150.74998,40.30720,1.31087,4.47858,150.74998
18.12000,150.99992,40.54266,1.31304,4.50474,150.99992
18.15000,151.24998,40.66174,1.31522,4.51797,151.24998
18.18000,151.49998,40.80246,1.31739,4.53361,151.49998
18.21000,151.74999,40.63181,1.31957,4.51465,151.74999
18.24000,151.99992,40.75588,1.32174,4.52843,151.99992
18.27000,152.24998,40.90866,1.32391,4.54541,152.24998
18.30000,152.49997,40.98575,1.32609,4.55397,152.49997
18.33000,152.74997,41.01304,1.32826,4.55700,152.74997
18.36000,152.99998,40.86232,1.33043,4.54026,152.99998
18.39000,153.25004,41.08367,1.33261,4.56485,153.25004
18.42000,153.50004,41.05766,1.33478,4.56196,153.50004
18.45000,153.75005,41.15832,1.33696,4.57315,153.75005
18.48000,154.00010,41.17923,1.33913,4.57547,154.00010
18.51000,154.25004,41.30233,1.34130,4.58915,154.25004
18.54000,154.49992,41.26681,1.34348,4.58520,154.49992
18.57000,154.74997,41.32089,1.34565,4.59121,154.74997
18.60000,155.00004,41.45270,1.34783,4.60586,155.00004
18.63000,155.24998,41.56874,1.35000,4.61875,155.24998
18.66000,155.49998,41.38819,1.35217,4.59869,155.49998
18.69000,155.75004,41.62247,1.35435,4.62472,155.75004
18.72000,155.99998,41.48954,1.35652,4.60995,155.99998
18.75000,156.24992,41.67856,1.35869,4.63095,156.24992
18.78000,156.49999,41.92861,1.36087,4.65873,156.49999
18.81000,156.75010,41.98293,1.36304,4.66477,156.75010
18.84000,156.99998,41.91186,1.36522,4.65687,156.99998
18.87000,157.24996,41.83026,1.36739,4.64781,157.24996
18.90000,157.49998,41.99611,1.36957,4.66623,157.49998
18.93000,157.74997,42.08643,1.37174,4.67627,157.74997
18.96000,157.99992,42.20296,1.37391,4.68922,157.99992
18.99000,158.24998,42.12199,1.37609,4.68022,158.24998
19.02000,158.50009,42.11915,1.37826,4.67991,158.50009
19.05000,158.75004,42.24445,1.38044,4.69383,158.75004
19.08000,158.99997,42.36113,1.38261,4.70679,158.99997
19.11000,159.25003,42.24690,1.38478,4.69410,159.25003
19.14000,159.50004,42.44254,1.38696,4.71584,159.50004
19.17000,159.74997,42.67829,1.38913,4.74203,159.74997
19.20000,159.99997,42.69675,1.39130,4.74408,159.99997
19.23000,160.25003,42.51758,1.39348,4.72417,160.25003
19.26000,160.50003,42.59555,1.39565,4.73284,160.50003
19.29000,160.74996,42.77914,1.39783,4.75324,160.74996
19.32000,160.99999,42.69651,1.40000,4.74406,160.99999
19.35000,161.25003,42.77552,1.40217,4.75284,161.25003
19.38000,161.49992,42.91507,1.40435,4.76834,161.49992
19.41000,161.74996,42.99422,1.40652,4.77714,161.74996
19.44000,162.00004,42.94524,1.40870,4.77169,162.00004
19.47000,162.25005,43.08117,1.41087,4.78680,162.25005
19.50000,162.49992,43.02812,1.41304,4.78090,162.49992
19.53000,162.74998,43.19064,1.41522,4.79896,162.74998
19.56000,163.00002,43.22968,1.41739,4.80330,163.00002
19.59000,163.24999,43.13206,1.41957,4.79245,163.24999
19.62000,163.49997,43.08195,1.42174,4.78688,163.49997
19.65000,163.75003,43.24986,1.42391,4.80554,163.75003
19.68000,164.00004,43.53014,1.42609,4.83668,164.00004
19.71000,164.24991,43.42860,1.42826,4.82540,164.24991
19.74000,164.49990,43.37927,1.43043,4.81992,164.49990
19.77000,164.75003,43.32799,1.43261,4.81422,164.75003
19.80000,164.99998,43.29096,1.43478,4.81011,164.99998
19.83000,165.24997,43.09757,1.43696,4.78862,165.24997
19.86000,165.50004,26.41911,1.43913,2.93546,165.50004
19.89000,165.74997,1.44672,1.44130,0.16075,165.74997
19.92000,165.99998,-1.64622,1.44348,-0.18291,165.99998
19.95000,166.24996,-0.15267,1.44565,-0.01696,166.24996
19.98000,166.50004,0.23527,1.44783,0.02614,166.50004
20.01000,166.75005,0.13848,1.45000,0.01539,166.75005
20.04000,166.99998,0.11964,1.45217,0.01329,166.99998
20.07000,167.24998,0.05308,1.45435,0.00590,167.24998
20.10000,167.50002,0.22508,1.45652,0.02501,167.50002
20.13000,167.74997,0.19917,1.45870,0.02213,167.74997
20.16000,167.99998,0.15114,1.46087,0.01679,167.99998
20.19000,168.25004,0.20419,1.46304,0.02269,168.25004
20.22000,168.50004,0.30146,1.46522,0.03350,168.50004
20.25000,168.74997,0.34300,1.46739,0.03811,168.74997
20.28000,168.99997,-0.04606,1.46957,-0.00512,168.99997
20.31000,169.25003,0.17306,1.47174,0.01923,169.25003
20.34000,169.49998,0.27445,1.47391,0.03049,169.49998
20.37000,169.74997,0.08119,1.47609,0.00902,169.74997
20.40000,169.99997,0.01477,1.47826,0.00164,169.99997
20.43000,170.25003,0.16583,1.48044,0.01843,170.25003
20.46000,170.49998,0.13581,1.48261,0.01509,170.49998
20.49000,170.74997,0.11700,1.48478,0.01300,170.74997
20.52000,171.00003,0.23066,1.48696,0.02563,171.00003
20.55000,171.24997,0.07360,1.48913,0.00818,171.24997
20.58000,171.49998,0.02119,1.49130,0.00235,171.49998
20.61000,171.75004,0.06417,1.49348,0.00713,171.75004
20.64000,172.00002,0.18836,1.49565,0.02093,172.00002
20.67000,172.24992,0.14847,1.49783,0.01650,172.24992
20.70000,172.49998,0.05455,1.50000,0.00606,172.49998
20.73000,172.74998,0.21043,1.50217,0.02338,172.74998
20.76000,172.99997,0.17154,1.50435,0.01906,172.99997
20.79000,173.24997,-0.10122,1.50652,-0.01125,173.24997
20.82000,173.50005,0.09814,1.50870,0.01090,173.50005
20.85000,173.75009,0.26137,1.51087,0.02904,173.75009
20.88000,174.00004,0.12976,1.51304,0.01442,174.00004
20.91000,174.24997,0.10654,1.51522,0.01184,174.24997
20.94000,174.50003,0.10554,1.51739,0.01173,174.50003
20.97000,174.75003,0.03845,1.51957,0.00427,174.75003
21.00000,174.99998,0.12525,1.52174,0.01392,174.99998
21.03000,175.24997,0.19370,1.52391,0.02152,175.24997
21.06000,175.50003,0.09437,1.52609,0.01049,175.50003
21.09000,175.74998,0.13294,1.52826,0.01477,175.74998
21.12000,175.99991,0.36414,1.53043,0.04046,175.99991
21.15000,176.24998,0.16378,1.53261,0.01820,176.24998
21.18000,176.50003,0.12405,1.53478,0.01378,176.50003
21.21000,176.74997,0.05501,1.53696,0.00611,176.74997
21.24000,176.99996,0.04529,1.53913,0.00503,176.99996
21.27000,177.25004,0.08844,1.54130,0.00983,177.25004
21.30000,177.49997,0.16150,1.54348,0.01794,177.49997
21.33000,177.74992,-0.00671,1.54565,-0.00075,177.74992
21.36000,178.00003,-0.15902,1.54783,-0.01767,178.00003
21.39000,178.25004,0.07335,1.55000,0.00815,178.25004
21.42000,178.49999,0.14543,1.55217,0.01616,178.49999
21.45000,178.75003,0.21768,1.55435,0.02419,178.75003
21.48000,179.00011,0.22750,1.55652,0.02528,179.00011
21.51000,179.25004,0.05423,1.55870,0.00603,179.25004
21.54000,179.49998,0.01445,1.56087,0.00161,179.49998
21.57000,179.74997,0.09444,1.56304,0.01049,179.74997
21.60000,179.99997,0.24330,1.56522,0.02703,179.99997
21.63000,180.24998,0.28976,1.56739,0.03220,180.24998
21.66000,180.49996,0.16973,1.56956,0.01886,180.49996
21.69000,180.75004,0.17005,1.57174,0.01889,180.75004
21.72000,181.00003,0.07176,1.57391,0.00797,181.00003
21.73200,181.09998,0.07169,1.57478,0.00797,181.09998