File: V_8/NR/RDSO NR Tensile 500.is_tens_RawData/Specimen_RawData_2.csv
Time,Extension,Load,Tensile strain,Tensile stress,Corrected Position
(sec),(mm),(N),(mm/mm),(MPa),(mm)
0.00000,0.00000,-0.04616,0.00000,-0.00513,0.00000
0.02000,0.01975,0.12917,0.00017,0.01435,0.01975
0.04000,0.09731,0.59152,0.00085,0.06572,0.09731
0.06000,0.23331,1.10231,0.00203,0.12248,0.23331
0.08000,0.41719,1.38486,0.00363,0.15387,0.41719
0.10000,0.62131,1.47651,0.00540,0.16406,0.62131
0.12000,0.83537,1.65336,0.00726,0.18371,0.83537
0.14000,1.05612,1.95901,0.00918,0.21767,1.05612
0.16000,1.27525,2.32351,0.01109,0.25817,1.27525
0.18000,1.47362,2.49913,0.01281,0.27768,1.47362
0.20000,1.65137,2.68798,0.01436,0.29866,1.65137
0.22000,1.81862,2.99216,0.01581,0.33246,1.81862
0.24000,1.98425,3.31457,0.01725,0.36829,1.98425
0.26000,2.15194,3.77013,0.01871,0.41890,2.15194
0.28000,2.32150,4.09363,0.02019,0.45485,2.32150
0.30000,2.49137,4.37922,0.02166,0.48658,2.49137
0.32000,2.66069,4.40391,0.02314,0.48932,2.66069
0.34000,2.82912,4.62296,0.02460,0.51366,2.82912
0.36000,2.99681,5.01702,0.02606,0.55745,2.99681
0.38000,3.16412,5.19720,0.02751,0.57747,3.16412
0.40000,3.33131,5.27983,0.02897,0.58665,3.33131
0.42000,3.49831,5.58340,0.03042,0.62038,3.49831
0.44000,3.66531,6.00479,0.03187,0.66720,3.66531
0.46000,3.83237,6.11145,0.03332,0.67905,3.83237
0.48000,3.99937,6.26660,0.03478,0.69629,3.99937
0.50000,4.16619,6.43782,0.03623,0.71531,4.16619
0.52000,4.33294,6.40165,0.03768,0.71129,4.33294
0.54000,4.49962,6.59525,0.03913,0.73281,4.49962
0.56000,4.66637,6.99732,0.04058,0.77748,4.66637
0.58000,4.83319,7.17096,0.04203,0.79677,4.83319
0.60000,4.99987,7.24792,0.04348,0.80532,4.99987
0.62000,5.16650,7.38428,0.04493,0.82048,5.16650
0.64000,5.33319,7.54899,0.04638,0.83878,5.33319
0.66000,5.49994,7.83235,0.04783,0.87026,5.49994
0.68000,5.66662,8.03562,0.04927,0.89285,5.66662
0.70000,5.83331,8.10146,0.05072,0.90016,5.83331
0.72000,6.00000,8.33383,0.05217,0.92598,6.00000
0.74000,6.16656,8.35773,0.05362,0.92864,6.16656
0.76000,6.33331,8.38558,0.05507,0.93173,6.33331
0.78000,6.50000,8.72096,0.05652,0.96900,6.50000
0.80000,6.66669,9.06775,0.05797,1.00753,6.66669
0.82000,6.83331,8.85243,0.05942,0.98360,6.83331
0.84000,7.00000,8.90594,0.06087,0.98955,7.00000
0.86000,7.16656,9.16974,0.06232,1.01886,7.16656
0.88000,7.33331,9.27818,0.06377,1.03091,7.33331
0.90000,7.50000,9.58236,0.06522,1.06471,7.50000
0.92000,7.66662,9.71961,0.06667,1.07996,7.66662
0.94000,7.83331,9.77097,0.06812,1.08566,7.83331
0.96000,7.99994,9.89835,0.06956,1.09982,7.99994
0.98000,8.16662,10.08088,0.07101,1.12010,8.16662
1.00000,8.33337,10.02817,0.07246,1.11424,8.33337
1.02000,8.50006,10.18217,0.07391,1.13135,8.50006
1.04000,8.66669,10.39542,0.07536,1.15505,8.66669
1.06000,8.83331,10.52260,0.07681,1.16918,8.83331
1.08000,9.00000,10.66943,0.07826,1.18549,9.00000
1.10000,9.16669,10.81314,0.07971,1.20146,9.16669
1.12000,9.33344,10.77339,0.08116,1.19704,9.33344
1.14000,9.50006,11.01372,0.08261,1.22375,9.50006
1.16000,9.66669,11.12530,0.08406,1.23614,9.66669
1.18000,9.83331,11.08766,0.08551,1.23196,9.83331
1.20000,10.00000,11.22124,0.08696,1.24680,10.00000
1.22000,10.16669,11.27788,0.08841,1.25310,10.16669
1.24000,10.33337,11.36635,0.08986,1.26293,10.33337
1.26000,10.50000,11.41959,0.09130,1.26884,10.50000
1.28000,10.66662,11.32180,0.09275,1.25798,10.66662
1.30000,10.83331,11.42828,0.09420,1.26981,10.83331
1.32000,11.00000,11.63127,0.09565,1.29236,11.00000
1.34000,11.16669,11.81671,0.09710,1.31297,11.16669
1.36000,11.33337,11.91262,0.09855,1.32362,11.33337
1.38000,11.50000,12.15697,0.10000,1.35077,11.50000
1.40000,11.66656,12.11702,0.10145,1.34634,11.66656
1.42000,11.83331,12.01470,0.10290,1.33497,11.83331
1.44000,12.00000,12.17779,0.10435,1.35309,12.00000
1.46000,12.16669,12.22890,0.10580,1.35877,12.16669
1.48000,12.33331,12.11154,0.10725,1.34573,12.33331
1.50000,12.49994,12.26289,0.10870,1.36254,12.49994
1.52000,12.66662,12.40501,0.11014,1.37833,12.66662
1.54000,12.83337,12.43257,0.11159,1.38140,12.83337
1.56000,13.00006,12.47180,0.11304,1.38576,13.00006
1.58000,13.16662,12.52581,0.11449,1.39176,13.16662
1.60000,13.33331,12.63991,0.11594,1.40443,13.33331
1.62000,13.50000,12.73256,0.11739,1.41473,13.50000
1.64000,13.66668,12.91325,0.11884,1.43481,13.66668
1.66000,13.83337,12.89075,0.12029,1.43231,13.83337
1.68000,14.00006,13.04022,0.12174,1.44891,14.00006
1.70000,14.16669,13.15978,0.12319,1.46220,14.16669
1.72000,14.33337,13.06912,0.12464,1.45212,14.33337
1.74000,14.50006,13.02714,0.12609,1.44746,14.50006
1.76000,14.66669,12.98612,0.12754,1.44290,14.66669
1.78000,14.83337,12.80826,0.12899,1.42314,14.83337
1.80000,15.00000,13.02804,0.13043,1.44756,15.00000
1.82000,15.16662,13.22948,0.13188,1.46994,15.16662
1.84000,15.33337,13.19649,0.13333,1.46628,15.33337
1.86000,15.50006,13.29076,0.13478,1.47675,15.50006
1.88000,15.66668,13.21310,0.13623,1.46812,15.66668
1.90000,15.83337,13.29323,0.13768,1.47703,15.83337
1.92000,16.00000,13.40633,0.13913,1.48959,16.00000
1.94000,16.16656,13.48030,0.14058,1.49781,16.16656
1.96000,16.33331,13.34841,0.14203,1.48316,16.33331
1.98000,16.50006,13.44496,0.14348,1.49388,16.50006
2.00000,16.66675,13.59276,0.14493,1.51031,16.66675
2.02000,16.83337,13.48189,0.14638,1.49799,16.83337
2.04000,17.00000,13.47753,0.14783,1.49750,17.00000
2.06000,17.16662,13.73182,0.14927,1.52576,17.16662
2.08000,17.33331,13.72761,0.15072,1.52529,17.33331
2.10000,17.50000,13.59994,0.15217,1.51110,17.50000
2.12000,17.66669,13.73096,0.15362,1.52566,17.66669
2.14000,17.83325,13.79469,0.15507,1.53274,17.83325
2.16000,17.99993,13.65127,0.15652,1.51681,17.99993
2.18000,18.16662,13.68857,0.15797,1.52095,18.16662
2.20000,18.33337,13.81575,0.15942,1.53508,18.33337
2.22000,18.50006,13.92885,0.16087,1.54765,18.50006
2.24000,18.66662,13.83280,0.16232,1.53698,18.66662
2.26000,18.83331,13.96968,0.16377,1.55219,18.83331
2.28000,19.00006,14.14643,0.16522,1.57183,19.00006
2.30000,19.16675,14.17986,0.16667,1.57554,19.16675
2.32000,19.33337,14.20614,0.16812,1.57846,19.33337
2.34000,19.50000,14.26164,0.16957,1.58463,19.50000
2.36000,19.66662,14.25934,0.17101,1.58437,19.66662
2.38000,19.83337,14.17952,0.17246,1.57550,19.83337
2.40000,20.00006,14.10350,0.17391,1.56706,20.00006
2.42000,20.16668,14.21506,0.17536,1.57945,20.16668
2.44000,20.33331,14.11954,0.17681,1.56884,20.33331
2.46000,20.50000,14.36012,0.17826,1.59557,20.50000
2.48000,20.66662,14.45644,0.17971,1.60627,20.66662
2.50000,20.83337,14.27428,0.18116,1.58603,20.83337
2.52000,21.00006,14.46362,0.18261,1.60707,21.00006
2.54000,21.16662,14.43829,0.18406,1.60425,21.16662
2.56000,21.33331,14.32289,0.18551,1.59143,21.33331
2.58000,21.50000,14.37028,0.18696,1.59670,21.50000
2.60000,21.66662,14.63743,0.18841,1.62638,21.66662
2.62000,21.83337,14.52849,0.18986,1.61428,21.83337
2.64000,22.00000,14.65871,0.19130,1.62875,22.00000
2.66000,22.16662,14.94533,0.19275,1.66059,22.16662
2.68000,22.33331,14.79743,0.19420,1.64416,22.33331
2.70000,22.49993,14.80478,0.19565,1.64498,22.49993
2.72000,22.66662,14.98866,0.19710,1.66541,22.66662
2.74000,22.83331,14.71289,0.19855,1.63477,22.83331
2.76000,23.00000,14.68117,0.20000,1.63124,23.00000
2.78000,23.16662,14.81560,0.20145,1.64618,23.16662
2.80000,23.33331,14.79677,0.20290,1.64409,23.33331
2.82000,23.50006,14.90798,0.20435,1.65644,23.50006
2.84000,23.66675,15.05719,0.20580,1.67302,23.66675
2.86000,23.83337,14.89290,0.20725,1.65477,23.83337
2.88000,24.00006,14.88670,0.20870,1.65408,24.00006
2.90000,24.16668,14.93928,0.21015,1.65992,24.16668
2.92000,24.33337,14.80066,0.21159,1.64452,24.33337
2.94000,24.50006,14.88585,0.21304,1.65398,24.50006
2.96000,24.66668,15.13957,0.21449,1.68217,24.66668
2.98000,24.83331,15.16962,0.21594,1.68551,24.83331
3.00000,24.99999,15.25311,0.21739,1.69479,24.99999
3.02000,25.16662,15.21207,0.21884,1.69023,25.16662
3.04000,25.33343,14.95214,0.22029,1.66135,25.33343
3.06000,25.50012,14.96422,0.22174,1.66269,25.50012
3.08000,25.66668,15.07222,0.22319,1.67469,25.66668
3.10000,25.83325,15.25608,0.22464,1.69512,25.83325
3.12000,25.99987,15.50758,0.22609,1.72306,25.99987
3.14000,26.16662,15.50045,0.22754,1.72227,26.16662
3.16000,26.33337,15.31010,0.22899,1.70112,26.33337
3.18000,26.50006,15.29455,0.23044,1.69939,26.50006
3.20000,26.66662,15.31084,0.23188,1.70120,26.66662
3.22000,26.83331,15.17913,0.23333,1.68657,26.83331
3.24000,27.00000,15.21170,0.23478,1.69019,27.00000
3.26000,27.16668,15.26734,0.23623,1.69637,27.16668
3.28000,27.33331,15.38380,0.23768,1.70931,27.33331
3.30000,27.49993,15.67676,0.23913,1.74186,27.49993
3.32000,27.66656,15.60990,0.24058,1.73443,27.66656
3.34000,27.83331,15.32291,0.24203,1.70255,27.83331
3.36000,28.00006,15.41818,0.24348,1.71313,28.00006
3.38000,28.16675,15.57674,0.24493,1.73075,28.16675
3.40000,28.33337,15.58205,0.24638,1.73134,28.33337
3.42000,28.50000,15.70360,0.24783,1.74484,28.50000
3.44000,28.66662,15.69589,0.24927,1.74399,28.66662
3.46000,28.83337,15.68394,0.25072,1.74266,28.83337
3.48000,29.00006,15.74600,0.25217,1.74956,29.00006
3.50000,29.16669,15.83583,0.25362,1.75954,29.16669
3.52000,29.33337,15.64073,0.25507,1.73786,29.33337
3.54000,29.50000,15.66192,0.25652,1.74021,29.50000
3.56000,29.66668,15.79013,0.25797,1.75446,29.66668
3.58000,29.83337,15.75699,0.25942,1.75078,29.83337
3.60000,30.00006,15.88729,0.26087,1.76525,30.00006
3.62000,30.16668,16.02451,0.26232,1.78050,30.16668
3.64000,30.33337,15.95138,0.26377,1.77238,30.33337
3.66000,30.49999,16.06556,0.26522,1.78506,30.49999
3.68000,30.66662,16.19771,0.26667,1.79975,30.66662
3.70000,30.83337,16.08848,0.26812,1.78761,30.83337
3.72000,31.00006,15.99779,0.26957,1.77753,31.00006
3.74000,31.16662,16.06235,0.27101,1.78471,31.16662
3.76000,31.33331,15.92341,0.27246,1.76927,31.33331
3.78000,31.49999,15.97744,0.27391,1.77527,31.49999
3.80000,31.66674,16.25416,0.27536,1.80602,31.66674
3.82000,31.83337,16.29078,0.27681,1.81009,31.83337
3.84000,31.99999,16.36031,0.27826,1.81781,31.99999
3.86000,32.16656,16.49834,0.27971,1.83315,32.16656
3.88000,32.33331,16.35864,0.28116,1.81763,32.33331
3.90000,32.50000,16.43246,0.28261,1.82583,32.50000
3.92000,32.66668,16.38722,0.28406,1.82080,32.66668
3.94000,32.83331,16.22154,0.28551,1.80239,32.83331
3.96000,32.99993,16.49082,0.28696,1.83231,32.99993
3.98000,33.16662,16.59386,0.28841,1.84376,33.16662
4.00000,33.33337,16.62271,0.28986,1.84697,33.33337
4.02000,33.50006,16.58144,0.29130,1.84238,33.50006
4.04000,33.66675,16.60042,0.29275,1.84449,33.66675
4.06000,33.83337,16.53011,0.29420,1.83668,33.83337
4.08000,34.00006,16.70581,0.29565,1.85620,34.00006
4.10000,34.16668,16.77213,0.29710,1.86357,34.16668
4.12000,34.33337,16.63966,0.29855,1.84885,34.33337
4.14000,34.50006,16.75043,0.30000,1.86116,34.50006
4.16000,34.66668,16.85295,0.30145,1.87255,34.66668
4.18000,34.83331,16.63770,0.30290,1.84863,34.83331
4.20000,34.99999,16.76243,0.30435,1.86249,34.99999
4.22000,35.16675,16.82557,0.30580,1.86951,35.16675
4.24000,35.33337,16.78513,0.30725,1.86501,35.33337
4.26000,35.49999,16.89936,0.30870,1.87771,35.49999
4.28000,35.66662,16.95591,0.31014,1.88399,35.66662
4.30000,35.83331,17.00254,0.31159,1.88917,35.83331
4.32000,35.99999,17.12977,0.31304,1.90331,35.99999
4.34000,36.16662,17.12135,0.31449,1.90237,36.16662
4.36000,36.33331,16.89213,0.31594,1.87690,36.33331
4.38000,36.50000,17.03822,0.31739,1.89314,36.50000
4.40000,36.66662,17.13158,0.31884,1.90351,36.66662
4.42000,36.83331,17.18804,0.32029,1.90978,36.83331
4.44000,36.99999,17.29661,0.32174,1.92185,36.99999
4.46000,37.16662,17.23893,0.32319,1.91544,37.16662
4.48000,37.33324,16.91851,0.32464,1.87983,37.33324
4.50000,37.49993,17.04900,0.32609,1.89433,37.49993
4.52000,37.66662,17.22852,0.32754,1.91428,37.66662
4.54000,37.83337,17.35903,0.32899,1.92878,37.83337
4.56000,38.00006,17.42523,0.33044,1.93614,38.00006
4.58000,38.16668,17.61521,0.33188,1.95725,38.16668
4.60000,38.33331,17.45974,0.33333,1.93997,38.33331
4.62000,38.50000,17.65378,0.33478,1.96153,38.50000
4.64000,38.66668,17.58286,0.33623,1.95365,38.66668
4.66000,38.83337,17.68837,0.33768,1.96537,38.83337
4.68000,39.00006,17.85042,0.33913,1.98338,39.00006
4.70000,39.16662,17.71788,0.34058,1.96865,39.16662
4.72000,39.33331,17.58550,0.34203,1.95394,39.33331
4.74000,39.49999,17.58386,0.34348,1.95376,39.49999
4.76000,39.66668,17.68423,0.34493,1.96491,39.66668
4.78000,39.83337,17.73656,0.34638,1.97073,39.83337
4.80000,39.99999,17.92603,0.34783,1.99178,39.99999
4.82000,40.16662,18.05441,0.34927,2.00605,40.16662
4.84000,40.33331,17.91420,0.35072,1.99047,40.33331
4.86000,40.50006,17.94065,0.35217,1.99341,40.50006
4.88000,40.66675,17.94227,0.35362,1.99359,40.66675
4.90000,40.83337,17.82723,0.35507,1.98080,40.83337
4.92000,40.99999,17.89125,0.35652,1.98792,40.99999
4.94000,41.16662,17.93046,0.35797,1.99227,41.16662
4.96000,41.33337,17.98319,0.35942,1.99813,41.33337
4.98000,41.50006,18.22974,0.36087,2.02553,41.50006
5.00000,41.66668,18.19945,0.36232,2.02216,41.66668
5.02000,41.83331,18.17319,0.36377,2.01924,41.83331
5.04000,41.99993,18.28144,0.36522,2.03127,41.99993
5.06000,42.16668,18.28502,0.36667,2.03167,42.16668
5.08000,42.33337,18.19330,0.36812,2.02148,42.33337
5.10000,42.50005,18.30596,0.36957,2.03400,42.50005
5.12000,42.66662,18.47813,0.37101,2.05313,42.66662
5.14000,42.83324,18.39827,0.37246,2.04425,42.83324
5.16000,42.99993,18.39148,0.37391,2.04350,42.99993
5.18000,43.16668,18.43946,0.37536,2.04883,43.16668
5.20000,43.33337,18.33579,0.37681,2.03731,43.33337
5.22000,43.50006,18.52351,0.37826,2.05817,43.50006
5.24000,43.66668,18.51215,0.37971,2.05691,43.66668
5.26000,43.83337,18.54950,0.38116,2.06106,43.83337
5.28000,44.00006,18.71075,0.38261,2.07897,44.00006
5.30000,44.16674,18.68787,0.38406,2.07643,44.16674
5.32000,44.33337,18.56559,0.38551,2.06284,44.33337
5.34000,44.49999,18.71222,0.38696,2.07914,44.49999
5.36000,44.66662,18.72047,0.38841,2.08005,44.66662
5.38000,44.83331,18.63519,0.38985,2.07058,44.83331
5.40000,45.00006,18.71871,0.39130,2.07986,45.00006
5.42000,45.16668,18.66875,0.39275,2.07431,45.16668
5.44000,45.33337,18.59072,0.39420,2.06564,45.33337
5.46000,45.49999,18.72174,0.39565,2.08019,45.49999
5.48000,45.66662,18.89546,0.39710,2.09950,45.66662
5.50000,45.83331,19.00070,0.39855,2.11119,45.83331
5.52000,45.99999,19.32557,0.40000,2.14729,45.99999
5.54000,46.16662,19.33133,0.40145,2.14793,46.16662
5.56000,46.33330,19.08852,0.40290,2.12095,46.33330
5.58000,46.49993,19.01784,0.40435,2.11309,46.49993
5.60000,46.66662,18.94268,0.40580,2.10474,46.66662
5.62000,46.83343,18.87790,0.40725,2.09754,46.83343
5.64000,47.00006,18.99220,0.40870,2.11024,47.00006
5.66000,47.16662,19.28869,0.41014,2.14319,47.16662
5.68000,47.33331,19.25247,0.41159,2.13916,47.33331
5.70000,47.49993,19.37108,0.41304,2.15234,47.49993
5.72000,47.66662,19.54386,0.41449,2.17154,47.66662
5.74000,47.83337,19.25504,0.41594,2.13945,47.83337
5.76000,47.99999,19.22031,0.41739,2.13559,47.99999
5.78000,48.16662,19.36297,0.41884,2.15144,48.16662
5.80000,48.33330,19.30743,0.42029,2.14527,48.33330
5.82000,48.50006,19.29760,0.42174,2.14418,48.50006
5.84000,48.66675,19.35114,0.42319,2.15013,48.66675
5.86000,48.83343,19.39753,0.42464,2.15528,48.83343
5.88000,49.00006,19.59199,0.42609,2.17689,49.00006
5.90000,49.16662,19.66507,0.42754,2.18501,49.16662
5.92000,49.33337,19.44945,0.42899,2.16105,49.33337
5.94000,49.50006,19.74846,0.43044,2.19427,49.50006
5.96000,49.66668,19.83979,0.43188,2.20442,49.66668
5.98000,49.83330,19.71822,0.43333,2.19091,49.83330
6.00000,49.99993,19.94339,0.43478,2.21593,49.99993
6.02000,50.16662,19.92404,0.43623,2.21378,50.16662
6.04000,50.33337,19.81079,0.43768,2.20120,50.33337
6.06000,50.50005,19.76690,0.43913,2.19632,50.50005
6.08000,50.66668,19.75598,0.44058,2.19511,50.66668
6.10000,50.83330,19.92759,0.44203,2.21418,50.83330
6.12000,50.99999,20.19719,0.44348,2.24413,50.99999
6.14000,51.16662,20.08637,0.44493,2.23182,51.16662
6.16000,51.33331,20.10378,0.44638,2.23375,51.33331
6.18000,51.49999,20.16501,0.44783,2.24056,51.49999
6.20000,51.66662,20.05551,0.44927,2.22839,51.66662
6.22000,51.83330,20.11230,0.45072,2.23470,51.83330
6.24000,51.99999,20.35555,0.45217,2.26173,51.99999
6.26000,52.16668,20.32567,0.45362,2.25841,52.16668
6.28000,52.33337,20.25288,0.45507,2.25032,52.33337
6.30000,52.49999,20.33618,0.45652,2.25958,52.49999
6.32000,52.66662,20.36422,0.45797,2.26269,52.66662
6.34000,52.83324,20.28786,0.45942,2.25421,52.83324
6.36000,52.99999,20.35739,0.46087,2.26193,52.99999
6.38000,53.16668,20.45912,0.46232,2.27324,53.16668
6.40000,53.33337,20.34663,0.46377,2.26074,53.33337
6.42000,53.50005,20.40331,0.46522,2.26703,53.50005
6.44000,53.66668,20.47465,0.46667,2.27496,53.66668
6.46000,53.83343,20.50230,0.46812,2.27803,53.83343
6.48000,54.00006,20.51467,0.46957,2.27941,54.00006
6.50000,54.16675,20.50688,0.47102,2.27854,54.16675
6.52000,54.33330,20.60078,0.47246,2.28898,54.33330
6.54000,54.49993,20.81162,0.47391,2.31240,54.49993
6.56000,54.66662,20.91752,0.47536,2.32417,54.66662
6.58000,54.83337,20.82588,0.47681,2.31399,54.83337
6.60000,55.00006,20.91008,0.47826,2.32334,55.00006
6.62000,55.16668,20.80077,0.47971,2.31120,55.16668
6.64000,55.33330,20.76296,0.48116,2.30700,55.33330
6.66000,55.49999,20.85370,0.48261,2.31708,55.49999
6.68000,55.66668,20.95024,0.48406,2.32780,55.66668
6.70000,55.83337,20.85088,0.48551,2.31676,55.83337
6.72000,55.99999,20.99638,0.48696,2.33293,55.99999
6.74000,56.16656,21.10907,0.48840,2.34545,56.16656
6.76000,56.33330,21.04113,0.48985,2.33790,56.33330
6.78000,56.49999,21.15445,0.49130,2.35049,56.49999
6.80000,56.66668,21.05350,0.49275,2.33928,56.66668
6.82000,56.83336,21.02653,0.49420,2.33628,56.83336
6.84000,56.99999,21.15567,0.49565,2.35063,56.99999
6.86000,57.16662,21.36784,0.49710,2.37420,57.16662
6.88000,57.33330,21.30436,0.49855,2.36715,57.33330
6.90000,57.49999,21.50225,0.50000,2.38914,57.49999
6.92000,57.66662,21.52356,0.50145,2.39151,57.66662
6.94000,57.83331,21.42015,0.50290,2.38002,57.83331
6.96000,57.99999,21.47213,0.50435,2.38579,57.99999
6.98000,58.16662,21.40024,0.50580,2.37780,58.16662
7.00000,58.33337,21.30955,0.50725,2.36773,58.33337
7.02000,58.50005,21.65409,0.50870,2.40601,58.50005
7.04000,58.66668,21.88198,0.51015,2.43133,58.66668
7.06000,58.83337,21.65248,0.51159,2.40583,58.83337
7.08000,59.00005,21.55640,0.51304,2.39516,59.00005
7.10000,59.16668,21.52356,0.51449,2.39151,59.16668
7.12000,59.33343,21.52064,0.51594,2.39118,59.33343
7.14000,59.50006,21.76827,0.51739,2.41870,59.50006
7.16000,59.66661,21.89217,0.51884,2.43246,59.66661
7.18000,59.83324,21.90366,0.52029,2.43374,59.83324
7.20000,59.99999,22.01492,0.52174,2.44610,59.99999
7.22000,60.16668,21.96300,0.52319,2.44033,60.16668
7.24000,60.33343,21.92178,0.52464,2.43575,60.33343
7.26000,60.50006,21.92347,0.52609,2.43594,60.50006
7.28000,60.66662,22.06635,0.52754,2.45182,60.66662
7.30000,60.83325,22.02482,0.52898,2.44720,60.83325
7.32000,60.99993,21.97941,0.53043,2.44216,60.99993
7.34000,61.16662,22.08751,0.53188,2.45417,61.16662
7.36000,61.33331,22.01335,0.53333,2.44593,61.33331
7.38000,61.49993,22.12119,0.53478,2.45791,61.49993
7.40000,61.66662,22.19995,0.53623,2.46666,61.66662
7.42000,61.83337,22.10311,0.53768,2.45590,61.83337
7.44000,62.00006,22.12579,0.53913,2.45842,62.00006
7.46000,62.16674,22.15173,0.54058,2.46130,62.16674
7.48000,62.33331,22.12359,0.54203,2.45818,62.33331
7.50000,62.49993,22.28207,0.54348,2.47579,62.49993
7.52000,62.66662,22.27732,0.54493,2.47526,62.66662
7.54000,62.83336,22.43957,0.54638,2.49329,62.83336
7.56000,63.00006,22.49125,0.54783,2.49903,63.00006
7.58000,63.16661,22.48505,0.54927,2.49834,63.16661
7.60000,63.33336,22.38101,0.55072,2.48678,63.33336
7.62000,63.50006,22.44501,0.55217,2.49389,63.50006
7.64000,63.66674,22.60193,0.55362,2.51133,63.66674
7.66000,63.83349,22.61828,0.55507,2.51314,63.83349
7.68000,64.00005,22.87716,0.55652,2.54191,64.00005
7.70000,64.16661,22.70839,0.55797,2.52315,64.16661
7.72000,64.33330,22.55353,0.55942,2.50595,64.33330
7.74000,64.49999,22.65257,0.56087,2.51695,64.49999
7.76000,64.66668,22.79087,0.56232,2.53232,64.66668
7.78000,64.83336,22.77192,0.56377,2.53021,64.83336
7.80000,64.99999,22.96006,0.56522,2.55112,64.99999
7.82000,65.16661,23.02589,0.56667,2.55843,65.16661
7.84000,65.33330,22.93082,0.56812,2.54787,65.33330
7.86000,65.50005,22.97110,0.56957,2.55235,65.50005
7.88000,65.66667,23.13304,0.57101,2.57034,65.66667
7.90000,65.83330,22.94671,0.57246,2.54963,65.83330
7.92000,65.99993,22.89964,0.57391,2.54440,65.99993
7.94000,66.16655,22.88901,0.57536,2.54322,66.16655
7.96000,66.33330,23.03334,0.57681,2.55926,66.33330
7.98000,66.50005,23.10421,0.57826,2.56713,66.50005
8.00000,66.66668,23.09170,0.57971,2.56574,66.66668
8.02000,66.83331,23.14026,0.58116,2.57114,66.83331
8.04000,66.99999,23.34521,0.58261,2.59391,66.99999
8.06000,67.16661,23.36064,0.58406,2.59563,67.16661
8.08000,67.33330,23.25633,0.58551,2.58404,67.33330
8.10000,67.49999,23.40776,0.58696,2.60086,67.49999
8.12000,67.66662,23.53827,0.58841,2.61536,67.66662
8.14000,67.83330,23.42301,0.58985,2.60256,67.83330
8.16000,67.99993,23.50991,0.59130,2.61221,67.99993
8.18000,68.16661,23.51559,0.59275,2.61284,68.16661
8.20000,68.33337,23.37242,0.59420,2.59694,68.33337
8.22000,68.50005,23.40470,0.59565,2.60052,68.50005
8.24000,68.66661,23.54868,0.59710,2.61652,68.66661
8.26000,68.83330,23.46671,0.59855,2.60741,68.83330
8.28000,69.00005,23.62886,0.60000,2.62543,69.00005
8.30000,69.16674,23.75227,0.60145,2.63914,69.16674
8.32000,69.33343,23.66930,0.60290,2.62992,69.33343
8.34000,69.50005,23.77966,0.60435,2.64218,69.50005
8.36000,69.66662,23.95989,0.60580,2.66221,69.66662
8.38000,69.83330,23.87666,0.60725,2.65296,69.83330
8.40000,69.99999,23.84754,0.60870,2.64973,69.99999
8.42000,70.16668,23.84243,0.61015,2.64916,70.16668
8.44000,70.33336,23.70128,0.61159,2.63348,70.33336
8.46000,70.49999,23.92601,0.61304,2.65845,70.49999
8.48000,70.66661,23.98587,0.61449,2.66510,70.66661
8.50000,70.83336,23.88408,0.61594,2.65379,70.83336
8.52000,70.99999,24.08315,0.61739,2.67591,70.99999
8.54000,71.16661,24.23732,0.61884,2.69304,71.16661
8.56000,71.33331,24.17156,0.62029,2.68573,71.33331
8.58000,71.49993,24.17041,0.62174,2.68560,71.49993
8.60000,71.66667,24.11415,0.62319,2.67935,71.66667
8.62000,71.83337,24.18062,0.62464,2.68674,71.83337
8.64000,71.99999,24.22868,0.62609,2.69208,71.99999
8.66000,72.16662,24.22187,0.62754,2.69132,72.16662
8.68000,72.33330,24.27607,0.62899,2.69734,72.33330
8.70000,72.49999,24.36176,0.63043,2.70686,72.49999
8.72000,72.66662,24.33732,0.63188,2.70415,72.66662
8.74000,72.83337,24.42916,0.63333,2.71435,72.83337
8.76000,72.99999,24.56070,0.63478,2.72897,72.99999
8.78000,73.16662,24.56121,0.63623,2.72902,73.16662
8.80000,73.33330,24.55977,0.63768,2.72886,73.33330
8.82000,73.50005,24.55137,0.63913,2.72793,73.50005
8.84000,73.66668,24.60559,0.64058,2.73395,73.66668
8.86000,73.83343,24.52166,0.64203,2.72463,73.83343
8.88000,74.00006,24.70015,0.64348,2.74446,74.00006
8.90000,74.16668,24.86368,0.64493,2.76263,74.16668
8.92000,74.33336,24.70880,0.64638,2.74542,74.33336
8.94000,74.50006,24.63959,0.64783,2.73773,74.50006
8.96000,74.66668,24.85540,0.64928,2.76171,74.66668
8.98000,74.83337,24.85303,0.65072,2.76145,74.83337
9.00000,74.99999,24.89295,0.65217,2.76588,74.99999
9.02000,75.16661,24.98638,0.65362,2.77626,75.16661
9.04000,75.33337,24.72560,0.65507,2.74729,75.33337
9.06000,75.50005,24.89052,0.65652,2.76561,75.50005
9.08000,75.66662,24.93840,0.65797,2.77093,75.66662
9.10000,75.83330,24.93838,0.65942,2.77093,75.83330
9.12000,75.99992,25.10095,0.66087,2.78899,75.99992
9.14000,76.16668,25.26512,0.66232,2.80724,76.16668
9.16000,76.33343,25.23188,0.66377,2.80354,76.33343
9.18000,76.50005,25.41828,0.66522,2.82425,76.50005
9.20000,76.66655,25.41417,0.66667,2.82380,76.66655
9.22000,76.83324,25.21917,0.66812,2.80213,76.83324
9.24000,76.99999,25.15953,0.66957,2.79550,76.99999
9.26000,77.16668,25.19975,0.67101,2.79997,77.16668
9.28000,77.33336,25.08126,0.67246,2.78681,77.33336
9.30000,77.49998,25.21985,0.67391,2.80221,77.49998
9.32000,77.66661,25.39612,0.67536,2.82179,77.66661
9.34000,77.83331,25.35186,0.67681,2.81687,77.83331
9.36000,77.99999,25.24170,0.67826,2.80463,77.99999
9.38000,78.16661,25.40403,0.67971,2.82267,78.16661
9.40000,78.33330,25.47226,0.68116,2.83025,78.33330
9.42000,78.49999,25.72961,0.68261,2.85885,78.49999
9.44000,78.66661,25.74424,0.68406,2.86047,78.66661
9.46000,78.83336,25.56815,0.68551,2.84091,78.83336
9.48000,79.00012,25.64424,0.68696,2.84936,79.00012
9.50000,79.16674,25.84948,0.68841,2.87216,79.16674
9.52000,79.33330,25.80691,0.68985,2.86743,79.33330
9.54000,79.49999,25.87335,0.69130,2.87482,79.49999
9.56000,79.66661,25.96245,0.69275,2.88472,79.66661
9.58000,79.83336,25.87406,0.69420,2.87490,79.83336
9.60000,79.99999,25.97773,0.69565,2.88641,79.99999
9.62000,80.16667,26.02199,0.69710,2.89133,80.16667
9.64000,80.33330,25.72699,0.69855,2.85855,80.33330
9.66000,80.49999,25.82065,0.70000,2.86896,80.49999
9.68000,80.66667,26.07940,0.70145,2.89771,80.66667
9.70000,80.83336,26.09500,0.70290,2.89944,80.83336
9.72000,80.99998,26.15035,0.70435,2.90559,80.99998
9.74000,81.16661,26.25500,0.70580,2.91722,81.16661
9.76000,81.33330,26.11618,0.70725,2.90180,81.33330
9.78000,81.49993,26.29257,0.70869,2.92140,81.49993
9.80000,81.66668,26.23501,0.71015,2.91500,81.66668
9.82000,81.83336,26.01844,0.71159,2.89094,81.83336
9.84000,81.99993,26.17469,0.71304,2.90830,81.99993
9.86000,82.16655,26.26210,0.71449,2.91801,82.16655
9.88000,82.33330,26.32833,0.71594,2.92537,82.33330
9.90000,82.49999,26.33178,0.71739,2.92575,82.49999
9.92000,82.66667,26.29088,0.71884,2.92121,82.66667
9.94000,82.83329,26.25826,0.72029,2.91758,82.83329
9.96000,82.99992,26.37804,0.72174,2.93089,82.99992
9.98000,83.16656,26.59418,0.72319,2.95491,83.16656
10.00000,83.33330,26.49207,0.72464,2.94356,83.33330
10.02000,83.50004,26.61686,0.72609,2.95743,83.50004
10.04000,83.66674,26.66527,0.72754,2.96281,83.66674
10.06000,83.83330,26.66123,0.72899,2.96236,83.83330
10.08000,83.99999,26.84999,0.73043,2.98333,83.99999
10.10000,84.16668,26.85753,0.73188,2.98417,84.16668
10.12000,84.33343,26.73689,0.73333,2.97077,84.33343
10.14000,84.50005,26.71230,0.73478,2.96803,84.50005
10.16000,84.66662,26.79277,0.73623,2.97697,84.66662
10.18000,84.83330,26.89985,0.73768,2.98887,84.83330
10.20000,84.99999,26.90078,0.73913,2.98898,84.99999
10.22000,85.16667,26.95155,0.74058,2.99462,85.16667
10.24000,85.33343,26.95133,0.74203,2.99459,85.33343
10.26000,85.50005,27.01804,0.74348,3.00200,85.50005
10.28000,85.66661,27.19940,0.74493,3.02216,85.66661
10.30000,85.83331,27.17119,0.74638,3.01902,85.83331
10.32000,86.00005,27.11934,0.74783,3.01326,86.00005
10.34000,86.16667,27.12242,0.74928,3.01360,86.16667
10.36000,86.33330,27.03467,0.75072,3.00385,86.33330
10.38000,86.49998,27.15238,0.75217,3.01693,86.49998
10.40000,86.66662,27.36731,0.75362,3.04081,86.66662
10.42000,86.83329,27.35269,0.75507,3.03919,86.83329
10.44000,87.00005,27.52469,0.75652,3.05830,87.00005
10.46000,87.16667,27.58832,0.75797,3.06537,87.16667
10.48000,87.33329,27.42815,0.75942,3.04757,87.33329
10.50000,87.49999,27.52991,0.76087,3.05888,87.49999
10.52000,87.66667,27.38455,0.76232,3.04273,87.66667
10.54000,87.83330,27.29034,0.76377,3.03226,87.83330
10.56000,87.99993,27.41558,0.76522,3.04618,87.99993
10.58000,88.16655,27.46616,0.76667,3.05180,88.16655
10.60000,88.33330,27.56542,0.76812,3.06282,88.33330
10.62000,88.49998,27.71415,0.76957,3.07935,88.49998
10.64000,88.66668,27.73000,0.77101,3.08111,88.66668
10.66000,88.83343,27.67064,0.77246,3.07452,88.83343
10.68000,89.00005,27.78707,0.77391,3.08745,89.00005
10.70000,89.16668,28.01082,0.77536,3.11231,89.16668
10.72000,89.33330,28.00891,0.77681,3.11210,89.33330
10.74000,89.49999,28.03315,0.77826,3.11479,89.49999
10.76000,89.66668,28.04603,0.77971,3.11623,89.66668
10.78000,89.83336,27.84063,0.78116,3.09340,89.83336
10.80000,89.99999,27.98581,0.78261,3.10953,89.99999
10.82000,90.16661,27.93952,0.78406,3.10439,90.16661
10.84000,90.33336,27.90646,0.78551,3.10072,90.33336
10.86000,90.50005,28.12862,0.78696,3.12540,90.50005
10.88000,90.66674,28.21458,0.78841,3.13495,90.66674
10.90000,90.83336,28.21603,0.78986,3.13511,90.83336
10.92000,90.99999,28.19291,0.79130,3.13255,90.99999
10.94000,91.16654,28.03783,0.79275,3.11531,91.16654
10.96000,91.33330,27.98655,0.79420,3.10962,91.33330
10.98000,91.50005,28.19972,0.79565,3.13330,91.50005
11.00000,91.66667,28.49427,0.79710,3.16603,91.66667
11.02000,91.83330,28.40951,0.79855,3.15661,91.83330
11.04000,91.99998,28.32621,0.80000,3.14736,91.99998
11.06000,92.16661,28.49378,0.80145,3.16598,92.16661
11.08000,92.33336,28.43449,0.80290,3.15939,92.33336
11.10000,92.49998,28.51675,0.80435,3.16853,92.49998
11.12000,92.66655,28.66963,0.80580,3.18551,92.66655
11.14000,92.83324,28.62381,0.80725,3.18042,92.83324
11.16000,92.99993,28.58976,0.80870,3.17664,92.99993
11.18000,93.16668,28.51560,0.81015,3.16840,93.16668
11.20000,93.33342,28.66409,0.81159,3.18490,93.33342
11.22000,93.50005,28.62841,0.81304,3.18093,93.50005
11.24000,93.66661,28.79414,0.81449,3.19935,93.66661
11.26000,93.83329,28.62003,0.81594,3.18000,93.83329
11.28000,94.00005,28.74342,0.81739,3.19371,94.00005
11.30000,94.16673,28.73859,0.81884,3.19318,94.16673
11.32000,94.33342,28.68925,0.82029,3.18769,94.33342
11.34000,94.50004,28.83894,0.82174,3.20433,94.50004
11.36000,94.66661,29.02090,0.82319,3.22455,94.66661
11.38000,94.83336,28.95429,0.82464,3.21714,94.83336
11.40000,95.00004,29.01760,0.82609,3.22418,95.00004
11.42000,95.16668,29.00242,0.82754,3.22249,95.16668
11.44000,95.33335,28.93100,0.82899,3.21456,95.33335
11.46000,95.49998,29.02313,0.83043,3.22479,95.49998
11.48000,95.66661,29.08710,0.83188,3.23190,95.66661
11.50000,95.83335,29.13680,0.83333,3.23742,95.83335
11.52000,96.00005,29.22634,0.83478,3.24737,96.00005
11.54000,96.16661,29.37931,0.83623,3.26437,96.16661
11.56000,96.33330,29.23427,0.83768,3.24825,96.33330
11.58000,96.49992,29.38031,0.83913,3.26448,96.49992
11.60000,96.66661,29.54915,0.84058,3.28324,96.66661
11.62000,96.83336,29.59084,0.84203,3.28787,96.83336
11.64000,97.00004,29.55168,0.84348,3.28352,97.00004
11.66000,97.16661,29.37245,0.84493,3.26361,97.16661
11.68000,97.33323,29.21397,0.84638,3.24600,97.33323
11.70000,97.49993,29.24906,0.84783,3.24990,97.49993
11.72000,97.66661,29.52199,0.84927,3.28022,97.66661
11.74000,97.83336,29.65143,0.85072,3.29460,97.83336
11.76000,97.99998,29.64927,0.85217,3.29436,97.99998
11.78000,98.16654,29.47015,0.85362,3.27446,98.16654
11.80000,98.33329,29.44485,0.85507,3.27165,98.33329
11.82000,98.49999,29.67604,0.85652,3.29734,98.49999
11.84000,98.66673,29.67448,0.85797,3.29716,98.66673
11.86000,98.83342,29.61124,0.85942,3.29014,98.83342
11.88000,98.99999,29.64979,0.86087,3.29442,98.99999
11.90000,99.16661,29.81525,0.86232,3.31281,99.16661
11.92000,99.33336,29.87555,0.86377,3.31951,99.33336
11.94000,99.50005,29.94429,0.86522,3.32714,99.50005
11.96000,99.66673,30.02563,0.86667,3.33618,99.66673
11.98000,99.83330,29.88179,0.86812,3.32020,99.83330
12.00000,99.99998,30.01262,0.86957,3.33474,99.99998
12.02000,100.16668,30.11150,0.87101,3.34572,100.16668
12.04000,100.33342,29.99431,0.87246,3.33270,100.33342
12.06000,100.50005,30.09839,0.87391,3.34427,100.50005
12.08000,100.66661,30.17635,0.87536,3.35293,100.66661
12.10000,100.83330,30.11583,0.87681,3.34620,100.83330
12.12000,100.99999,30.32859,0.87826,3.36984,100.99999
12.14000,101.16667,30.42121,0.87971,3.38013,101.16667
12.16000,101.33336,30.29704,0.88116,3.36634,101.33336
12.18000,101.50004,30.26557,0.88261,3.36284,101.50004
12.20000,101.66667,30.33098,0.88406,3.37011,101.66667
12.22000,101.83336,30.42400,0.88551,3.38044,101.83336
12.24000,101.99999,30.46880,0.88696,3.38542,101.99999
12.26000,102.16661,30.46899,0.88841,3.38544,102.16661
12.28000,102.33330,30.24975,0.88985,3.36108,102.33330
12.30000,102.49998,30.39567,0.89130,3.37730,102.49998
12.32000,102.66654,30.46250,0.89275,3.38472,102.66654
12.34000,102.83330,30.52802,0.89420,3.39200,102.83330
12.36000,102.99998,30.62067,0.89565,3.40230,102.99998
12.38000,103.16667,30.71364,0.89710,3.41263,103.16667
12.40000,103.33336,30.77300,0.89855,3.41922,103.33336
12.42000,103.49998,30.98147,0.90000,3.44239,103.49998
12.44000,103.66655,30.86225,0.90145,3.42914,103.66655
12.46000,103.83330,30.54893,0.90290,3.39433,103.83330
12.48000,104.00005,30.58890,0.90435,3.39877,104.00005
12.50000,104.16673,30.69725,0.90580,3.41081,104.16673
12.52000,104.33336,30.81486,0.90725,3.42387,104.33336
12.54000,104.49998,31.07243,0.90870,3.45249,104.49998
12.56000,104.66667,31.16927,0.91014,3.46325,104.66667
12.58000,104.83336,30.98473,0.91159,3.44275,104.83336
12.60000,105.00005,31.06930,0.91304,3.45214,105.00005
12.62000,105.16673,30.97197,0.91449,3.44133,105.16673
12.64000,105.33329,30.85985,0.91594,3.42887,105.33329
12.66000,105.49999,31.02818,0.91739,3.44758,105.49999
12.68000,105.66667,31.16564,0.91884,3.46285,105.66667
12.70000,105.83342,31.11257,0.92029,3.45695,105.83342
12.72000,106.00004,31.33573,0.92174,3.48175,106.00004
12.74000,106.16661,31.54743,0.92319,3.50527,106.16661
12.76000,106.33330,31.48978,0.92464,3.49886,106.33330
12.78000,106.49998,31.42738,0.92609,3.49193,106.49998
12.80000,106.66673,31.46843,0.92754,3.49649,106.66673
12.82000,106.83330,31.41842,0.92899,3.49094,106.83330
12.84000,106.99992,31.49316,0.93043,3.49924,106.99992
12.86000,107.16654,31.61444,0.93188,3.51272,107.16654
12.88000,107.33330,31.59235,0.93333,3.51026,107.33330
12.90000,107.49999,31.58192,0.93478,3.50910,107.49999
12.92000,107.66667,31.63168,0.93623,3.51463,107.66667
12.94000,107.83330,31.61381,0.93768,3.51265,107.83330
12.96000,107.99993,31.79460,0.93913,3.53273,107.99993
12.98000,108.16661,31.69125,0.94058,3.52125,108.16661
13.00000,108.33330,31.48748,0.94203,3.49861,108.33330
13.02000,108.49998,31.48253,0.94348,3.49806,108.49998
13.04000,108.66667,31.63281,0.94493,3.51476,108.66667
13.06000,108.83329,31.71010,0.94638,3.52334,108.83329
13.08000,108.99998,31.91079,0.94783,3.54564,108.99998
13.10000,109.16667,31.93278,0.94928,3.54809,109.16667
13.12000,109.33336,31.93288,0.95072,3.54810,109.33336
13.14000,109.50005,32.03741,0.95217,3.55971,109.50005
13.16000,109.66667,32.22295,0.95362,3.58033,109.66667
13.18000,109.83329,32.16466,0.95507,3.57385,109.83329
13.20000,109.99999,32.18577,0.95652,3.57620,109.99999
13.22000,110.16673,32.12489,0.95797,3.56943,110.16673
13.24000,110.33342,31.94390,0.95942,3.54932,110.33342
13.26000,110.50005,31.97500,0.96087,3.55278,110.50005
13.28000,110.66660,32.15766,0.96232,3.57307,110.66660
13.30000,110.83330,32.17529,0.96377,3.57503,110.83330
13.32000,111.00005,32.24568,0.96522,3.58285,111.00005
13.34000,111.16668,32.44611,0.96667,3.60512,111.16668
13.36000,111.33336,32.43191,0.96812,3.60355,111.33336
13.38000,111.49999,32.42887,0.96957,3.60321,111.49999
13.40000,111.66661,32.35560,0.97101,3.59507,111.66661
13.42000,111.83330,32.33061,0.97246,3.59229,111.83330
13.44000,112.00004,32.57631,0.97391,3.61959,112.00004
13.46000,112.16667,32.59825,0.97536,3.62203,112.16667
13.48000,112.33330,32.47575,0.97681,3.60842,112.33330
13.50000,112.49992,32.62172,0.97826,3.62463,112.49992
13.52000,112.66655,32.78708,0.97971,3.64301,112.66655
13.54000,112.83336,32.75921,0.98116,3.63991,112.83336
13.56000,113.00005,32.76709,0.98261,3.64079,113.00005
13.58000,113.16667,32.86907,0.98406,3.65212,113.16667
13.60000,113.33330,32.82813,0.98551,3.64757,113.33330
13.62000,113.49998,32.81265,0.98696,3.64585,113.49998
13.64000,113.66667,32.99256,0.98841,3.66584,113.66667
13.66000,113.83343,32.90464,0.98986,3.65607,113.83343
13.68000,114.00005,33.01975,0.99130,3.66886,114.00005
13.70000,114.16667,32.99834,0.99275,3.66648,114.16667
13.72000,114.33336,32.96415,0.99420,3.66268,114.33336
13.74000,114.50005,33.07994,0.99565,3.67555,114.50005
13.76000,114.66674,33.03752,0.99710,3.67084,114.66674
13.78000,114.83342,33.00578,0.99855,3.66731,114.83342
13.80000,114.99998,33.15381,1.00000,3.68376,114.99998
13.82000,115.16660,33.12819,1.00145,3.68091,115.16660
13.84000,115.33336,33.06868,1.00290,3.67430,115.33336
13.86000,115.50005,33.40156,1.00435,3.71128,115.50005
13.88000,115.66673,33.39314,1.00580,3.71035,115.66673
13.90000,115.83336,33.21499,1.00725,3.69055,115.83336
13.92000,115.99999,33.20872,1.00870,3.68986,115.99999
13.94000,116.16661,33.39230,1.01014,3.71026,116.16661
13.96000,116.33329,33.46063,1.01159,3.71785,116.33329
13.98000,116.50004,33.53484,1.01304,3.72609,116.50004
14.00000,116.66667,33.56810,1.01449,3.72979,116.66667
14.02000,116.83336,33.59054,1.01594,3.73228,116.83336
14.04000,116.99999,33.63340,1.01739,3.73704,116.99999
14.06000,117.16661,33.64765,1.01884,3.73863,117.16661
14.08000,117.33335,33.61179,1.02029,3.73464,117.33335
14.10000,117.49999,33.68967,1.02174,3.74330,117.49999
14.12000,117.66661,33.76227,1.02319,3.75136,117.66661
14.14000,117.83330,33.78069,1.02464,3.75341,117.83330
14.16000,117.99992,33.82330,1.02609,3.75814,117.99992
14.18000,118.16661,33.89217,1.02754,3.76580,118.16661
14.20000,118.33336,33.71911,1.02899,3.74657,118.33336
14.22000,118.50005,33.62208,1.03044,3.73579,118.50005
14.24000,118.66674,33.57579,1.03188,3.73064,118.66674
14.26000,118.83336,33.76692,1.03333,3.75188,118.83336
14.28000,119.00004,34.03951,1.03478,3.78217,119.00004
14.30000,119.16674,34.18219,1.03623,3.79802,119.16674
14.32000,119.33336,34.03564,1.03768,3.78174,119.33336
14.34000,119.49998,34.10064,1.03913,3.78896,119.49998
14.36000,119.66661,34.10671,1.04058,3.78963,119.66661
14.38000,119.83336,34.11857,1.04203,3.79095,119.83336
14.40000,120.00005,34.33908,1.04348,3.81545,120.00005
14.42000,120.16674,34.41398,1.04493,3.82378,120.16674
14.44000,120.33336,34.39752,1.04638,3.82195,120.33336
14.46000,120.49999,34.35848,1.04783,3.81761,120.49999
14.48000,120.66661,34.31675,1.04927,3.81297,120.66661
14.50000,120.83329,34.26683,1.05072,3.80743,120.83329
14.52000,121.00005,34.42593,1.05217,3.82510,121.00005
14.54000,121.16661,34.56288,1.05362,3.84032,121.16661
14.56000,121.33330,34.53276,1.05507,3.83697,121.33330
14.58000,121.49998,34.60418,1.05652,3.84491,121.49998
14.60000,121.66668,34.43215,1.05797,3.82579,121.66668
14.62000,121.83336,34.27624,1.05942,3.80847,121.83336
14.64000,121.99998,34.68402,1.06087,3.85378,121.99998
14.66000,122.16661,34.81362,1.06232,3.86818,122.16661
14.68000,122.33323,34.71267,1.06377,3.85696,122.33323
14.70000,122.49999,34.74226,1.06522,3.86025,122.49999
14.72000,122.66668,34.81362,1.06667,3.86818,122.66668
14.74000,122.83330,34.70160,1.06812,3.85573,122.83330
14.76000,122.99999,34.85139,1.06957,3.87238,122.99999
14.78000,123.16661,34.88979,1.07101,3.87664,123.16661
14.80000,123.33330,34.98599,1.07246,3.88733,123.33330
14.82000,123.50004,35.00025,1.07391,3.88892,123.50004
14.84000,123.66667,35.00985,1.07536,3.88998,123.66667
14.86000,123.83336,34.92569,1.07681,3.88063,123.83336
14.88000,123.99998,35.05868,1.07826,3.89541,123.99998
14.90000,124.16661,35.17707,1.07971,3.90856,124.16661
14.92000,124.33336,35.13299,1.08116,3.90367,124.33336
14.94000,124.50005,35.23154,1.08261,3.91462,124.50005
14.96000,124.66667,35.27538,1.08406,3.91949,124.66667
14.98000,124.83336,35.31393,1.08551,3.92377,124.83336
15.00000,124.99998,35.44711,1.08696,3.93857,124.99998
15.02000,125.16660,35.51960,1.08841,3.94662,125.16660
15.04000,125.33336,35.49810,1.08986,3.94423,125.33336
15.06000,125.50004,35.39529,1.09130,3.93281,125.50004
15.08000,125.66666,35.48781,1.09275,3.94309,125.66666
15.10000,125.83329,35.55267,1.09420,3.95030,125.83329
15.12000,125.99992,35.60856,1.09565,3.95651,125.99992
15.14000,126.16660,35.63006,1.09710,3.95890,126.16660
15.16000,126.33336,35.52156,1.09855,3.94684,126.33336
15.18000,126.50005,35.70290,1.10000,3.96699,126.50005
15.20000,126.66660,35.87218,1.10145,3.98580,126.66660
15.22000,126.83329,35.79978,1.10290,3.97775,126.83329
15.24000,126.99998,35.87718,1.10435,3.98635,126.99998
15.26000,127.16673,35.74904,1.10580,3.97212,127.16673
15.28000,127.33336,35.70603,1.10725,3.96734,127.33336
15.30000,127.49991,35.94609,1.10869,3.99401,127.49991
15.32000,127.66647,36.17415,1.11014,4.01935,127.66647
15.34000,127.83323,36.18077,1.11159,4.02009,127.83323
15.36000,128.00003,36.16891,1.11304,4.01877,128.00003
15.38000,128.16672,35.96588,1.11449,3.99621,128.16672
15.40000,128.33342,35.98616,1.11594,3.99846,128.33342
15.42000,128.50004,36.08692,1.11739,4.00966,128.50004
15.44000,128.66667,36.25429,1.11884,4.02825,128.66667
15.46000,128.83342,36.19007,1.12029,4.02112,128.83342
15.48000,129.00010,36.28530,1.12174,4.03170,129.00010
15.50000,129.16672,36.19870,1.12319,4.02208,129.16672
15.52000,129.33329,36.15946,1.12464,4.01772,129.33329
15.54000,129.49998,36.50317,1.12609,4.05591,129.49998
15.56000,129.66667,36.57743,1.12754,4.06416,129.66667
15.58000,129.83342,36.43082,1.12899,4.04787,129.83342
15.60000,130.00004,36.52570,1.13044,4.05841,130.00004
15.62000,130.16666,36.58374,1.13188,4.06486,130.16666
15.64000,130.33330,36.50082,1.13333,4.05565,130.33330
15.66000,130.49997,36.55377,1.13478,4.06153,130.49997
15.68000,130.66660,36.65810,1.13623,4.07312,130.66660
15.70000,130.83328,36.59736,1.13768,4.06637,130.83328
15.72000,130.99998,36.65702,1.13913,4.07300,130.99998
15.74000,131.16661,36.68264,1.14058,4.07585,131.16661
15.76000,131.33329,36.63797,1.14203,4.07089,131.33329
15.78000,131.49998,36.72589,1.14348,4.08065,131.49998
15.80000,131.66666,36.77042,1.14493,4.08560,131.66666
15.82000,131.83336,36.71159,1.14638,4.07907,131.83336
15.84000,131.99999,36.99495,1.14783,4.11055,131.99999
15.86000,132.16661,37.10256,1.14927,4.12251,132.16661
15.88000,132.33324,37.01694,1.15072,4.11299,132.33324
15.90000,132.49998,37.17986,1.15217,4.13110,132.49998
15.92000,132.66660,37.21997,1.15362,4.13555,132.66660
15.94000,132.83329,37.10580,1.15507,4.12287,132.83329
15.96000,132.99991,37.13435,1.15652,4.12604,132.99991
15.98000,133.16660,37.24990,1.15797,4.13888,133.16660
16.00000,133.33336,37.18030,1.15942,4.13114,133.33336
16.02000,133.50010,37.33415,1.16087,4.14824,133.50010
16.04000,133.66672,37.28620,1.16232,4.14291,133.66672
16.06000,133.83329,37.14890,1.16377,4.12766,133.83329
16.08000,133.99998,37.22968,1.16522,4.13663,133.99998
16.10000,134.16666,37.37878,1.16667,4.15320,134.16666
16.12000,134.33342,37.36364,1.16812,4.15152,134.33342
16.14000,134.50004,37.54174,1.16957,4.17130,134.50004
16.16000,134.66661,37.49124,1.17101,4.16569,134.66661
16.18000,134.83330,37.38980,1.17246,4.15442,134.83330
16.20000,134.99998,37.60414,1.17391,4.17824,134.99998
16.22000,135.16666,37.65793,1.17536,4.18421,135.16666
16.24000,135.33336,37.56133,1.17681,4.17348,135.33336
16.26000,135.50005,37.59959,1.17826,4.17773,135.50005
16.28000,135.66661,37.69172,1.17971,4.18797,135.66661
16.30000,135.83330,37.79405,1.18116,4.19934,135.83330
16.32000,135.99998,37.99786,1.18261,4.22198,135.99998
16.34000,136.16666,38.00722,1.18406,4.22302,136.16666
16.36000,136.33335,37.86071,1.18551,4.20675,136.33335
16.38000,136.49997,37.94540,1.18696,4.21616,136.49997
16.40000,136.66660,38.12135,1.18841,4.23571,136.66660
16.42000,136.83336,38.11160,1.18986,4.23462,136.83336
16.44000,137.00004,38.10190,1.19130,4.23354,137.00004
16.46000,137.16667,38.08197,1.19275,4.23133,137.16667
16.48000,137.33329,38.00075,1.19420,4.22231,137.33329
16.50000,137.49992,38.08912,1.19565,4.23212,137.49992
16.52000,137.66654,38.05057,1.19710,4.22784,137.66654
16.54000,137.83336,38.01765,1.19855,4.22418,137.83336
16.56000,138.00004,38.18703,1.20000,4.24300,138.00004
16.58000,138.16667,38.39300,1.20145,4.26589,138.16667
16.60000,138.33336,38.34446,1.20290,4.26050,138.33336
16.62000,138.50003,38.35955,1.20435,4.26217,138.50003
16.64000,138.66673,38.44576,1.20580,4.27175,138.66673
16.66000,138.83342,38.49841,1.20725,4.27760,138.83342
16.68000,139.00004,38.64595,1.20870,4.29399,139.00004
16.70000,139.16667,38.76541,1.21014,4.30727,139.16667
16.72000,139.33330,38.52815,1.21159,4.28091,139.33330
16.74000,139.50004,38.54255,1.21304,4.28251,139.50004
16.76000,139.66672,38.62464,1.21449,4.29163,139.66672
16.78000,139.83342,38.69665,1.21594,4.29963,139.83342
16.80000,140.00005,38.83282,1.21739,4.31476,140.00005
16.82000,140.16667,38.92784,1.21884,4.32532,140.16667
16.84000,140.33335,38.76468,1.22029,4.30719,140.33335
16.86000,140.50004,38.73000,1.22174,4.30333,140.50004
16.88000,140.66666,38.60333,1.22319,4.28926,140.66666
16.90000,140.83335,38.70874,1.22464,4.30097,140.83335
16.92000,140.99992,39.06798,1.22609,4.34089,140.99992
16.94000,141.16654,39.24441,1.22754,4.36049,141.16654
16.96000,141.33330,38.94699,1.22899,4.32744,141.33330
16.98000,141.50004,38.93798,1.23044,4.32644,141.50004
17.00000,141.66673,39.08145,1.23188,4.34238,141.66673
17.02000,141.83329,39.13866,1.23333,4.34874,141.83329
17.04000,141.99992,39.29668,1.23478,4.36630,141.99992
17.06000,142.16661,39.30290,1.23623,4.36699,142.16661
17.08000,142.33336,39.23329,1.23768,4.35925,142.33336
17.10000,142.50005,39.23849,1.23913,4.35983,142.50005
17.12000,142.66661,39.25715,1.24058,4.36191,142.66661
17.14000,142.83329,39.35937,1.24203,4.37326,142.83329
17.16000,142.99998,39.48452,1.24348,4.38717,142.99998
17.18000,143.16666,39.55922,1.24493,4.39547,143.16666
17.20000,143.33342,39.43731,1.24638,4.38192,143.33342
17.22000,143.50004,39.43035,1.24783,4.38115,143.50004
17.24000,143.66659,39.52067,1.24927,4.39119,143.66659
17.26000,143.83336,39.34845,1.25072,4.37205,143.83336
17.28000,144.00004,39.70489,1.25217,4.41165,144.00004
17.30000,144.16672,39.86644,1.25362,4.42960,144.16672
17.32000,144.33335,39.73708,1.25507,4.41523,144.33335
17.34000,144.49998,39.72057,1.25652,4.41340,144.49998
17.36000,144.66660,39.69818,1.25797,4.41091,144.66660
17.38000,144.83330,39.57637,1.25942,4.39737,144.83330
17.40000,145.00004,39.65606,1.26087,4.40623,145.00004
17.42000,145.16667,39.84675,1.26232,4.42742,145.16667
17.44000,145.33335,39.77151,1.26377,4.41906,145.33335
17.46000,145.49998,39.74913,1.26522,4.41657,145.49998
17.48000,145.66660,39.79399,1.26667,4.42156,145.66660
17.50000,145.83336,39.82662,1.26812,4.42518,145.83336
17.52000,146.00004,39.90058,1.26957,4.43340,146.00004
17.54000,146.16661,39.84347,1.27101,4.42705,146.16661
17.56000,146.33330,39.74957,1.27246,4.41662,146.33330
17.58000,146.49997,40.01015,1.27391,4.44557,146.49997
17.60000,146.66661,39.92997,1.27536,4.43666,146.66661
17.62000,146.83335,39.30255,1.27681,4.36695,146.83335
17.64000,147.00005,20.63524,1.27826,2.29280,147.00005
17.66000,147.16660,4.14327,1.27971,0.46036,147.16660
17.68000,147.33329,-1.41254,1.28116,-0.15695,147.33329
17.70000,147.49992,-1.25913,1.28261,-0.13990,147.49992
17.72000,147.66661,-0.22465,1.28406,-0.02496,147.66661
17.74000,147.83335,0.03821,1.28551,0.00425,147.83335
17.76000,148.00005,0.15313,1.28696,0.01701,148.00005
17.78000,148.16660,0.09501,1.28841,0.01056,148.16660
17.80000,148.33330,0.03748,1.28985,0.00416,148.33330
17.82000,148.50005,0.05284,1.29130,0.00587,148.50005
17.84000,148.66672,0.31031,1.29275,0.03448,148.66672
17.86000,148.83341,0.17127,1.29420,0.01903,148.83341
17.88000,148.99998,0.04517,1.29565,0.00502,148.99998
17.90000,149.16660,0.05551,1.29710,0.00617,149.16660
17.92000,149.33336,0.11610,1.29855,0.01290,149.33336
17.94000,149.50004,0.14323,1.30000,0.01591,149.50004
17.96000,149.66667,0.23314,1.30145,0.02590,149.66667
17.98000,149.83329,0.13331,1.30290,0.01481,149.83329
18.00000,149.99998,0.22591,1.30435,0.02510,149.99998
18.02000,150.16667,0.27411,1.30580,0.03046,150.16667
18.04000,150.33334,0.24044,1.30725,0.02672,150.33334
18.06000,150.50004,0.14891,1.30870,0.01655,150.50004
18.08000,150.66667,0.09790,1.31015,0.01088,150.66667
18.10000,150.83330,0.04941,1.31159,0.00549,150.83330
18.12000,150.99992,0.32469,1.31304,0.03608,150.99992
18.14000,151.16661,0.44447,1.31449,0.04939,151.16661
18.16000,151.33335,0.19792,1.31594,0.02199,151.33335
18.18000,151.49998,0.16603,1.31739,0.01845,151.49998
18.20000,151.66660,0.25785,1.31884,0.02865,151.66660
18.22000,151.83330,0.13473,1.32029,0.01497,151.83330
18.24000,151.99998,0.14495,1.32174,0.01611,151.99998
18.26000,152.16661,0.24722,1.32319,0.02747,152.16661
18.28000,152.33335,-0.04204,1.32464,-0.00467,152.33335
18.30000,152.49997,-0.02304,1.32609,-0.00256,152.49997
18.32000,152.66660,0.05428,1.32754,0.00603,152.66660
18.34000,152.83328,-0.02387,1.32899,-0.00265,152.83328
18.36000,152.99998,0.09072,1.33043,0.01008,152.99998
18.38000,153.16667,0.08134,1.33188,0.00904,153.16667
18.40000,153.33335,0.07187,1.33333,0.00799,153.33335
18.42000,153.50004,0.10892,1.33478,0.01210,153.50004
18.44000,153.66666,0.05972,1.33623,0.00664,153.66666
18.46000,153.83342,0.00207,1.33768,0.00023,153.83342
18.48000,154.00010,0.12325,1.33913,0.01369,154.00010
18.50000,154.16673,0.26471,1.34058,0.02941,154.16673
18.52000,154.33329,0.08100,1.34203,0.00900,154.33329
18.54000,154.49992,0.31572,1.34348,0.03508,154.49992
18.56000,154.66660,0.39353,1.34493,0.04373,154.66660
18.58000,154.83335,0.27350,1.34638,0.03039,154.83335
18.60000,155.00004,0.28940,1.34783,0.03216,155.00004
18.62000,155.16668,0.24174,1.34928,0.02686,155.16668
18.64000,155.33336,0.08044,1.35072,0.00894,155.33336
18.66000,155.49998,0.21994,1.35217,0.02444,155.49998
18.68000,155.66667,0.22062,1.35362,0.02451,155.66667
18.70000,155.83335,-0.08378,1.35507,-0.00931,155.83335
18.72000,155.99998,0.03388,1.35652,0.00376,155.99998
18.74000,156.16654,0.15310,1.35797,0.01701,156.16654
18.76000,156.33328,0.16305,1.35942,0.01812,156.33328
18.78000,156.49999,0.24796,1.36087,0.02755,156.49999
18.80000,156.66673,0.12210,1.36232,0.01357,156.66673
18.82000,156.83340,-0.03220,1.36377,-0.00358,156.83340
18.84000,157.00003,0.10593,1.36522,0.01177,157.00003
18.86000,157.16659,0.31844,1.36667,0.03538,157.16659
18.88000,157.33328,0.26512,1.36812,0.02946,157.33328
18.90000,157.50004,0.16716,1.36957,0.01857,157.50004
18.92000,157.66660,0.12893,1.37101,0.01433,157.66660
18.94000,157.83329,-0.02181,1.37246,-0.00242,157.83329
18.96000,157.99992,0.18354,1.37391,0.02039,157.99992
18.98000,158.16661,0.25305,1.37536,0.02812,158.16661
19.00000,158.33335,0.26828,1.37681,0.02981,158.33335
19.02000,158.50009,0.18445,1.37826,0.02049,158.50009
19.04000,158.66673,0.10463,1.37971,0.01163,158.66673
19.06000,158.83336,0.15935,1.38116,0.01771,158.83336
19.08000,158.99997,0.28340,1.38261,0.03149,158.99997
19.10000,159.16666,0.42224,1.38406,0.04692,159.16666
19.12000,159.33335,0.29902,1.38551,0.03322,159.33335
19.14000,159.50004,0.33495,1.38696,0.03722,159.50004
19.16000,159.66665,0.25361,1.38841,0.02818,159.66665
19.18000,159.83336,0.12979,1.38986,0.01442,159.83336
19.20000,159.99997,0.05457,1.39130,0.00606,159.99997
19.21200,160.10003,0.02849,1.39217,0.00317,160.10003