File: V_7/EPR/RDSO EPR Tensile 50.is_tens_RawData/Specimen_RawData_4.csv
Time,Extension,Load
(sec),(mm),(N)
0.00000,0.00000,0.58322
0.30000,0.24925,1.24707
0.60000,0.49987,1.93248
0.90000,0.74994,2.57095
1.20000,0.99994,2.92262
1.50000,1.24987,2.89327
1.80000,1.49987,3.42085
2.10000,1.74994,3.58598
2.40000,1.99994,3.93726
2.70000,2.24987,4.60224
3.00000,2.49994,4.74302
3.30000,2.74994,4.97826
3.60000,2.99994,5.10155
3.90000,3.24987,5.37551
4.20000,3.49994,5.65103
4.50000,3.74994,5.95125
4.80000,3.99994,5.98546
5.10000,4.24994,6.29690
5.40000,4.49994,6.47085
5.70000,4.74994,6.56787
6.00000,4.99987,6.89141
6.30000,5.24994,6.93571
6.60000,5.50000,7.16028
6.90000,5.74994,7.36392
7.20000,5.99994,7.64827
7.50000,6.24994,7.73103
7.80000,6.49994,8.01513
8.10000,6.74994,7.98627
8.40000,6.99987,8.26816
8.70000,7.24994,8.36758
9.00000,7.49994,8.61704
9.30000,7.74987,8.59891
9.60000,7.99994,8.73498
9.90000,8.25000,9.18843
10.20000,8.49981,9.10033
10.50000,8.74987,9.22082
10.80000,8.99987,9.44088
11.10000,9.24994,9.74041
11.40000,9.49987,9.69092
11.70000,9.74987,9.82758
12.00000,10.00000,10.06082
12.30000,10.24994,10.03931
12.60000,10.49994,10.30964
12.90000,10.74994,10.47561
13.20000,10.99994,10.39990
13.50000,11.24994,10.65362
13.80000,11.49987,10.70791
14.10000,11.74994,10.98898
14.40000,11.99987,10.93807
14.70000,12.24994,10.89818
15.00000,12.49994,11.21399
15.30000,12.74994,11.22315
15.60000,12.99994,11.28312
15.90000,13.24987,11.48123
16.20000,13.49994,11.52136
16.50000,13.74987,11.68767
16.80000,13.99987,11.63529
17.10000,14.24994,11.79013
17.40000,14.49994,12.01405
17.70000,14.74994,11.92879
18.00000,14.99994,12.06178
18.30000,15.24994,12.19187
18.60000,15.50000,12.30511
18.90000,15.74987,12.38214
19.20000,15.99994,12.58142
19.50000,16.25000,12.70182
19.80000,16.49987,12.66551
20.10000,16.74994,12.59661
20.40000,16.99987,12.54948
20.70000,17.24993,12.71803
21.00000,17.49994,12.98312
21.30000,17.74987,12.95044
21.60000,17.99993,13.02071
21.90000,18.24987,13.14840
22.20000,18.49987,13.14571
22.50000,18.74994,13.19784
22.80000,18.99993,13.14649
23.10000,19.24987,13.33935
23.40000,19.50000,13.57573
23.70000,19.74993,13.55843
24.00000,19.99993,13.40173
24.30000,20.24994,13.57494
24.60000,20.49993,13.65594
24.90000,20.74993,13.57906
25.20000,20.99993,13.96087
25.50000,21.24987,13.93024
25.80000,21.49994,13.77359
26.10000,21.74993,14.05632
26.40000,21.99987,14.12614
26.70000,22.24993,14.18122
27.00000,22.49993,14.13839
27.30000,22.74993,14.16206
27.60000,22.99994,14.24031
27.90000,23.24993,14.07102
28.20000,23.49993,14.47032
28.50000,23.74987,14.37884
28.80000,23.99987,14.48198
29.10000,24.25000,14.58111
29.40000,24.49993,14.75246
29.70000,24.74987,14.53951
30.00000,24.99999,14.65064
30.30000,25.24993,14.82204
30.60000,25.49987,14.81704
30.90000,25.74987,14.84409
31.20000,25.99993,14.85854
31.50000,26.25000,15.07904
31.80000,26.49987,15.04254
32.10000,26.74993,15.16783
32.40000,26.99994,15.14240
32.70000,27.24993,14.97418
33.00000,27.49993,15.25304
33.30000,27.74993,15.42145
33.60000,28.00000,15.36403
33.90000,28.24987,15.45708
34.20000,28.49987,15.44689
34.50000,28.74993,15.27431
34.80000,28.99987,15.57590
35.10000,29.24993,15.53832
35.40000,29.49993,15.75701
35.70000,29.74994,15.44243
36.00000,29.99993,15.79689
36.30000,30.24987,15.76122
36.60000,30.49993,15.86740
36.90000,30.74987,16.20192
37.20000,30.99993,15.83075
37.50000,31.24993,16.00857
37.80000,31.49993,15.89871
38.10000,31.74993,16.09084
38.40000,31.99993,16.26690
38.70000,32.24993,16.12313
39.00000,32.49993,16.45834
39.30000,32.74993,16.30948
39.60000,33.00000,16.47157
39.90000,33.24993,16.49362
40.20000,33.49993,16.63729
40.50000,33.74993,16.53948
40.80000,33.99981,16.47554
41.10000,34.24987,16.65860
41.40000,34.49987,16.75200
41.70000,34.74993,16.48578
42.00000,34.99993,16.54169
42.30000,35.24993,16.83054
42.60000,35.49987,16.90306
42.90000,35.75000,17.04864
43.20000,35.99987,17.04854
43.50000,36.24987,17.25189
43.80000,36.49993,17.17369
44.10000,36.74993,17.44966
44.40000,36.99993,17.12234
44.70000,37.24993,17.19843
45.00000,37.49993,17.34543
45.30000,37.74993,17.54236
45.60000,37.99993,17.57328
45.90000,38.24993,17.62052
46.20000,38.49993,17.79011
46.50000,38.74987,17.83386
46.80000,38.99987,17.76713
47.10000,39.24993,17.86704
47.40000,39.49993,17.87698
47.70000,39.74987,17.92589
48.00000,39.99987,18.21793
48.30000,40.24987,18.06715
48.60000,40.49993,18.08332
48.90000,40.74987,18.25786
49.20000,40.99987,18.36649
49.50000,41.24993,18.28207
49.80000,41.49993,18.37423
50.10000,41.74993,18.48767
50.40000,41.99993,18.53515
50.70000,42.24993,18.64716
51.00000,42.49993,18.53750
51.30000,42.74987,18.71905
51.60000,42.99999,18.63070
51.90000,43.24993,18.94087
52.20000,43.49981,18.85982
52.50000,43.74993,19.03637
52.80000,43.99987,19.10811
53.10000,44.24993,19.02990
53.40000,44.49987,19.25207
53.70000,44.74993,19.29666
54.00000,44.99999,19.47149
54.30000,45.24987,19.41578
54.60000,45.49993,19.44909
54.90000,45.74993,19.69302
55.20000,45.99987,19.54185
55.50000,46.24993,19.56317
55.80000,46.49993,19.65279
56.10000,46.74993,19.66866
56.40000,46.99986,19.80356
56.70000,47.24993,19.82850
57.00000,47.49993,20.07012
57.30000,47.74987,19.99172
57.60000,47.99987,20.00936
57.90000,48.24993,20.05027
58.20000,48.49993,20.12696
58.50000,48.74987,20.47153
58.80000,48.99987,20.42826
59.10000,49.24993,20.38230
59.40000,49.49987,20.28322
59.70000,49.74993,20.55713
60.00000,49.99999,20.59608
60.30000,50.24993,20.54375
60.60000,50.49993,20.71760
60.90000,50.74987,20.70819
61.20000,50.99993,20.80257
61.50000,51.24993,20.85093
61.80000,51.49993,21.05947
62.10000,51.74993,21.10318
62.40000,51.99993,21.22250
62.70000,52.24993,21.29169
63.00000,52.49986,21.26253
63.30000,52.74993,21.63233
63.60000,52.99993,21.29820
63.90000,53.24987,21.32393
64.20000,53.49993,21.69652
64.50000,53.74993,21.65424
64.80000,53.99987,21.67746
65.10001,54.24987,21.68329
65.40000,54.49993,21.69221
65.70001,54.75000,21.96818
66.00000,54.99993,21.98278
66.30000,55.24987,21.95617
66.60001,55.49993,22.15599
66.90000,55.74993,22.13399
67.20001,55.99987,22.23758
67.50000,56.24993,22.47214
67.80000,56.49993,22.40629
68.10001,56.74993,22.66790
68.40000,56.99987,22.68588
68.70001,57.24993,22.57504
69.00000,57.49993,22.67970
69.30000,57.74986,22.67079
69.60001,57.99993,22.96895
69.90000,58.24993,22.91902
70.20001,58.49987,23.17348
70.50000,58.74987,23.01922
70.80000,58.99993,23.00109
71.10001,59.24993,23.29186
71.40000,59.49987,23.21571
71.70001,59.74993,23.43411
72.00000,59.99999,23.53191
72.30000,60.24987,23.53034
72.60001,60.49987,23.43690
72.90000,60.74993,23.82954
73.20001,60.99987,23.72781
73.50000,61.24993,23.84659
73.80000,61.49987,24.03421
74.10001,61.74999,23.98016
74.40000,61.99993,24.05591
74.70001,62.24987,24.12050
75.00000,62.49993,24.23697
75.30000,62.74993,24.10016
75.60001,62.99987,24.29998
75.90000,63.24986,24.61858
76.20001,63.49993,24.61363
76.50000,63.74992,24.52690
76.80000,63.99993,24.66890
77.10001,64.24993,24.50857
77.40000,64.49993,24.80228
77.70001,64.74993,24.73701
78.00000,64.99992,25.07300
78.30000,65.24993,25.01170
78.60001,65.49987,25.23196
78.90000,65.74986,25.18546
79.20001,65.99993,25.22564
79.50000,66.24993,25.33824
79.80000,66.49987,25.51243
80.10001,66.74992,25.38347
80.40000,66.99986,25.53238
80.70001,67.24992,25.52841
81.00001,67.49993,25.80628
81.30000,67.74987,25.79306
81.60001,67.99986,25.89664
81.90000,68.24993,26.09734
82.20001,68.49993,26.03678
82.50001,68.74993,25.92070
82.80000,68.99992,26.36106
83.10001,69.24986,26.34474
83.40000,69.49992,26.31231
83.70001,69.74999,26.56564
84.00001,69.99987,26.56495
84.30000,70.24986,26.58729
84.60001,70.49993,26.70215
84.90000,70.74993,26.85547
85.20001,70.99993,26.96273
85.50001,71.24993,27.01996
85.80000,71.49993,27.08930
86.10001,71.74992,27.14398
86.40000,71.99986,27.07347
86.70001,72.24993,27.21410
87.00001,72.49992,27.31249
87.30000,72.74986,27.43244
87.60001,72.99987,27.41579
87.90000,73.24993,27.54397
88.20001,73.49993,27.51907
88.50001,73.74987,27.93817
88.80000,73.99987,27.76525
89.10001,74.24993,27.57856
89.40000,74.49986,27.84953
89.70001,74.74986,27.94640
90.00001,74.99993,28.20380
90.30000,75.24987,28.26598
90.60001,75.49986,28.39186
90.90000,75.74987,28.29401
91.20001,75.99992,28.61809
91.50001,76.24993,28.44777
91.80000,76.49980,28.72476
92.10001,76.74999,28.70732
92.40000,76.99999,28.77538
92.70001,77.24993,28.93811
93.00001,77.49987,28.89044
93.30000,77.74986,29.04645
93.60001,77.99999,29.09123
93.90000,78.24986,29.10736
94.20001,78.49980,29.21359
94.50001,78.74993,29.27273
94.80000,78.99993,29.51680
95.10001,79.24993,29.49803
95.40000,79.49992,29.81168
95.70001,79.74987,29.56536
96.00001,79.99986,29.74666
96.30000,80.24986,29.94143
96.60001,80.49992,29.91316
96.90000,80.74986,29.88900
97.20001,80.99986,30.11661
97.50001,81.24992,30.24004
97.80000,81.49993,30.39635
98.10001,81.74992,30.33691
98.40000,81.99993,30.48905
98.70001,82.24992,30.34431
99.00001,82.49993,30.58514
99.30000,82.74986,30.42217
99.60001,82.99992,30.73332
99.90000,83.24986,30.92339
100.20001,83.49986,31.07950
100.50001,83.74986,31.02600
100.80000,83.99987,31.09459
101.10001,84.24993,31.20269
101.40000,84.49992,31.19931
101.70001,84.74993,31.58592
102.00001,84.99992,31.46601
102.30000,85.24993,31.51712
102.60001,85.49993,31.53447
102.90000,85.74992,31.71949
103.20001,85.99993,31.77506
103.50001,86.24992,31.91657
103.80000,86.49986,31.94058
104.10001,86.74992,31.97110
104.40000,86.99981,32.10086
104.70001,87.24992,32.11751
105.00001,87.49993,32.40647
105.30000,87.74993,32.17195
105.60001,87.99986,32.12707
105.90000,88.24986,32.55298
106.20001,88.49992,32.31263
106.50001,88.74992,32.72756
106.80000,88.99986,32.82076
107.10001,89.24986,32.79146
107.40000,89.49992,32.91567
107.70001,89.74986,32.96154
108.00001,89.99993,33.07340
108.30000,90.24986,33.21937
108.60001,90.49992,33.06380
108.90000,90.74987,33.43463
109.20001,90.99992,33.45007
109.50001,91.24992,33.49069
109.80000,91.49986,33.50416
110.10001,91.74986,33.54478
110.40000,91.99993,33.68649
110.70001,92.24992,33.86069
111.00001,92.49986,33.76798
111.30000,92.74987,34.10083
111.60001,92.99998,34.01459
111.90000,93.24992,34.22299
112.20001,93.49986,34.18722
112.50001,93.74992,34.43060
112.80000,93.99986,34.17624
113.10001,94.24992,34.28012
113.40001,94.49992,34.55349
113.70001,94.74993,34.58564
114.00001,94.99992,34.79139
114.30000,95.24986,34.77159
114.60001,95.49987,34.69280
114.90001,95.74998,35.07235
115.20001,95.99992,35.09367
115.50001,96.24986,35.11175
115.80000,96.49992,35.07985
116.10001,96.74992,35.27369
116.40001,96.99985,35.43128
116.70001,97.24992,35.46582
117.00001,97.49993,35.63105
117.30000,97.74987,35.54809
117.60001,97.99986,35.82842
117.90001,98.24986,36.01785
118.20001,98.49992,35.66858
118.50001,98.74986,35.91441
118.80000,98.99992,35.93441
119.10001,99.24993,36.29892
119.40001,99.49992,36.06573
119.70001,99.74986,36.34204
120.00001,99.99992,36.26084
120.30000,100.24992,36.48580
120.60001,100.49992,36.85222
120.90001,100.74986,36.79509
121.20001,100.99986,36.85438
121.50001,101.24993,36.81680
121.80000,101.49992,37.11775
122.10001,101.74992,36.92915
122.40001,101.99992,37.07228
122.70001,102.24986,37.20101
123.00001,102.49992,37.26951
123.30000,102.74986,37.29851
123.60001,102.99992,37.41293
123.90001,103.24986,37.46570
124.20001,103.49986,37.38348
124.50001,103.74992,37.49290
124.80000,103.99986,37.63671
125.10001,104.24992,37.64759
125.40001,104.49992,37.99799
125.70001,104.74992,37.86285
126.00001,104.99992,38.00161
126.30000,105.24986,38.09520
126.60001,105.49992,38.28581
126.90001,105.74985,38.33373
127.20001,105.99992,38.40361
127.50001,106.24993,38.53620
127.80000,106.49992,38.57276
128.10001,106.74993,38.71319
128.40001,106.99986,38.70942
128.70002,107.24992,38.74293
129.00000,107.49992,38.93511
129.30000,107.74986,39.08162
129.60001,107.99993,38.97162
129.90001,108.24992,39.06638
130.20002,108.49993,39.31951
130.50000,108.74987,39.43986
130.80000,108.99992,39.23415
131.10000,109.24999,39.43790
131.40002,109.49986,39.66349
131.70002,109.74992,39.57936
132.00000,109.99992,39.64027
132.30000,110.24985,39.85469
132.60000,110.49992,39.82166
132.90002,110.74992,39.96636
133.20002,110.99992,40.06627
133.50000,111.24992,40.13139
133.80000,111.49986,40.14418
134.10000,111.74999,40.08538
134.40002,111.99986,40.51942
134.70002,112.24993,40.52011
135.00000,112.49992,40.66343
135.30000,112.74992,40.61997
135.60000,112.99992,40.92867
135.90002,113.24986,40.63286
136.20002,113.49992,40.89006
136.50000,113.74986,40.81548
136.80000,113.99986,41.07964
137.10000,114.24992,41.13795
137.40002,114.49993,41.01030
137.70002,114.74992,41.17577
138.00000,114.99993,41.16490
138.30000,115.24992,41.33556
138.60000,115.49992,41.36139
138.90002,115.74986,41.65568
139.20002,115.99992,41.55650
139.50000,116.24992,41.79342
139.80000,116.49992,41.95311
140.10000,116.74993,41.99633
140.40002,116.99999,42.11692
140.70002,117.24993,42.17013
141.00000,117.49987,42.07335
141.30000,117.74993,42.22643
141.60000,117.99999,42.22413
141.90002,118.24986,42.35755
142.20002,118.49992,42.43835
142.50000,118.74992,42.58653
142.80000,118.99993,42.54885
143.10000,119.24986,42.79635
143.40002,119.49993,42.71133
143.70002,119.74992,42.87318
144.00000,119.99992,42.96682
144.30000,120.24986,43.12749
144.60000,120.49992,43.12714
144.90002,120.74992,43.20893
145.20002,120.99986,43.48759
145.50000,121.24993,43.54996
145.80000,121.49992,43.47519
146.10000,121.74992,43.66600
146.40002,121.99992,43.45044
146.70002,122.24986,43.91389
147.00000,122.49992,43.80947
147.30000,122.74986,43.77164
147.60000,122.99986,44.15506
147.90002,123.24993,43.88316
148.20002,123.49992,44.10489
148.50000,123.74992,43.98474
148.80000,123.99986,44.35146
149.10000,124.24992,44.57734
149.40002,124.49986,44.46205
149.70002,124.74992,44.63835
150.00000,124.99992,44.84611
150.30000,125.24992,44.74291
150.60000,125.49992,44.67740
150.90002,125.74992,44.94705
151.20002,125.99997,44.76384
151.50000,126.24991,44.94337
151.80000,126.49992,45.06572
152.10000,126.74998,45.07464
152.40002,126.99998,45.16485
152.70002,127.24985,45.32836
153.00000,127.49985,45.59424
153.30000,127.74984,45.52995
153.60000,127.99992,45.49888
153.90002,128.24985,45.48659
154.20002,128.49986,45.70351
154.50000,128.74993,45.77539
154.80000,128.99992,45.60472
155.10000,129.24992,45.87153
155.40002,129.49985,45.93959
155.70002,129.74999,45.91337
156.00000,129.99984,46.23320
156.30000,130.24986,46.25926
156.60000,130.49997,46.22869
156.90002,130.74991,46.41587
157.20002,130.99991,46.48481
157.50000,131.24998,46.32375
157.80000,131.49998,46.58550
158.10000,131.74991,46.86892
158.40002,131.99992,46.95325
158.70002,132.24992,46.78312
159.00000,132.49986,47.07060
159.30000,132.74992,46.89974
159.60000,132.99991,47.12455
159.90002,133.24991,47.12984
160.20002,133.49985,47.11064
160.50000,133.74986,47.11749
160.80000,133.99998,47.55242
161.10000,134.24992,47.41870
161.40002,134.49991,47.53850
161.70002,134.74992,47.76699
162.00002,134.99992,47.60544
162.30000,135.24991,47.92913
162.60000,135.49991,48.09377
162.90002,135.74985,47.99998
163.20002,135.99992,48.19853
163.50002,136.24991,48.18883
163.80000,136.49992,48.20735
164.10000,136.74991,47.99087
164.40002,136.99993,48.54344
164.70002,137.24986,48.42903
165.00002,137.49997,48.35954
165.30000,137.74991,48.64708
165.60000,137.99985,48.83754
165.90002,138.24992,48.57862
166.20002,138.49986,48.69382
166.50002,138.74992,48.78432
166.80000,138.99985,48.90526
167.10000,139.24993,48.96562
167.40002,139.49992,49.00869
167.70002,139.74992,49.13310
168.00002,139.99991,49.28172
168.30000,140.24991,49.27442
168.60000,140.49992,49.27305
168.90002,140.74986,49.44033
169.20002,140.99992,49.45606
169.50002,141.24999,49.72306
169.80000,141.49993,49.62761
170.10000,141.74992,49.82963
170.40002,141.99986,49.88211
170.70002,142.24998,49.99349
171.00002,142.49991,49.89510
171.30000,142.74985,49.90363
171.60000,142.99998,50.30866
171.90002,143.24992,50.13206
172.20002,143.49991,50.38407
172.50002,143.74998,50.50789
172.80000,143.99998,50.50015
173.10000,144.24986,50.53200
173.40002,144.49986,50.66097
173.70002,144.74998,50.85677
174.00002,144.99992,50.93272
174.30000,145.24986,50.75931
174.60000,145.49986,51.00446
174.90002,145.74992,51.10662
175.20002,145.99998,51.04679
175.50002,146.24985,51.11005
175.80000,146.49992,51.13989
176.10000,146.74991,51.40675
176.40002,146.99985,51.28121
176.70002,147.24985,51.51798
177.00002,147.49992,51.42066
177.30000,147.74986,51.41973
177.60000,147.99992,51.58422
177.90002,148.24999,51.89586
178.20002,148.49998,51.78336
178.50002,148.74992,51.84573
178.80000,148.99986,52.07123
179.10000,149.24991,52.16144
179.40002,149.49991,52.13067
179.70002,149.74984,52.16943
180.00002,149.99986,52.28727
180.30000,150.24992,52.38728
180.60000,150.49986,52.29467
180.90002,150.74993,52.60906
181.20002,150.99992,52.62699
181.50002,151.24992,52.56799
181.80000,151.49985,52.58544
182.10000,151.74991,52.90203
182.40002,151.99992,52.83666
182.70002,152.24992,52.95881
183.00002,152.49985,52.96215
183.30000,152.74986,53.08009
183.60000,152.99991,53.28285
183.90002,153.24985,53.12213
184.20002,153.49992,53.24875
184.50002,153.74998,53.56078
184.80000,153.99985,53.32274
185.10000,154.24985,53.54750
185.40002,154.49998,53.55725
185.70002,154.74985,53.50350
186.00002,154.99991,53.91544
186.30000,155.24991,53.92720
186.60000,155.49992,53.81969
186.90002,155.74986,54.11580
187.20002,155.99986,53.81435
187.50002,156.24992,53.77270
187.80000,156.49991,54.04892
188.10000,156.74992,53.92583
188.40002,156.99985,54.34086
188.70002,157.24991,54.50662
189.00002,157.49991,54.41323
189.30000,157.74984,54.44057
189.60000,157.99992,54.68660
189.90002,158.24990,54.61158
190.20002,158.49991,54.69777
190.50002,158.74984,54.71247
190.80000,158.99984,54.73457
191.10000,159.24992,54.85771
191.40002,159.49985,55.03489
191.70002,159.74991,55.34349
192.00002,159.99991,55.06145
192.30000,160.24992,55.20634
192.60000,160.49985,55.38436
192.90002,160.74991,55.40454
193.20002,160.99991,55.27940
193.50002,161.24984,55.42513
193.80000,161.49985,55.52788
194.10000,161.74996,55.70501
194.40002,161.99986,55.75332
194.70002,162.24984,56.00249
195.00002,162.49992,55.86750
195.30000,162.74985,55.89915
195.60000,162.99991,55.96902
195.90002,163.24984,56.22348
196.20002,163.49992,56.11411
196.50002,163.74992,56.35553
196.80000,163.99985,56.12955
197.10000,164.24986,56.36925
197.40002,164.49990,56.25454
197.70002,164.74985,56.40502
198.00002,164.99991,56.38244
198.30000,165.24991,56.49009
198.60000,165.49991,56.58113
198.90002,165.74990,56.68006
199.20002,165.99992,56.71005
199.50002,166.24996,56.80555
199.80000,166.49986,57.10984
200.10000,166.74984,56.97146
200.40002,166.99998,56.81275
200.70002,167.24985,56.89242
201.00002,167.49986,57.01443
201.30000,167.74984,57.36846
201.60000,167.99990,57.32024
201.90002,168.24992,57.21764
202.20002,168.49985,57.46656
202.50002,168.74997,57.48297
202.80000,168.99984,57.50419
203.10000,169.24992,57.74929
203.40002,169.49978,57.64550
203.70002,169.74986,57.75752
204.00002,169.99992,57.92794
204.30000,170.24985,57.96312
204.60000,170.49992,57.98419
204.90002,170.74991,58.08091
205.20002,170.99991,58.16319
205.50002,171.24990,58.12399
205.80000,171.49990,58.24369
206.10000,171.74991,58.19783
206.40002,171.99986,58.22963
206.70002,172.24984,58.35840
207.00002,172.49990,58.50217
207.30000,172.74985,58.52471
207.60000,172.99991,58.43832
207.90002,173.24986,58.59052
208.20002,173.49990,58.60174
208.50002,173.74985,58.96463
208.80000,173.99983,58.91823
209.10000,174.24991,58.82405
209.40002,174.49984,58.96732
209.70002,174.74985,58.95257
210.00002,174.99998,59.29136
210.30000,175.24991,59.32037
210.60000,175.49992,59.31772
210.90002,175.74985,59.41793
211.20002,175.99998,59.45894
211.50002,176.24991,59.57159
211.80000,176.49986,59.40587
212.10000,176.74992,59.52592
212.40002,176.99990,59.44522
212.70002,177.24985,59.71349
213.00002,177.49984,59.67625
213.30000,177.74992,59.84800
213.60000,177.99990,59.84393
213.90002,178.24979,60.02298
214.20002,178.49991,60.19237
214.50002,178.74992,60.12132
214.80000,178.99992,60.15400
215.10000,179.24985,60.38704
215.40002,179.49985,60.20937
215.70002,179.74997,60.35632
216.00002,179.99992,60.47721
216.30000,180.24985,60.53429
216.60000,180.49991,60.57521
216.90002,180.74999,60.71667
217.20002,180.99984,60.44481
217.50002,181.24992,60.64542
217.80000,181.49991,60.79242
218.10000,181.74985,60.87249
218.40002,181.99991,60.93633
218.70002,182.24992,60.77047
219.00002,182.49990,60.88111
219.30000,182.74985,60.89414
219.60000,182.99984,61.29888
219.90002,183.24992,61.29379
220.20002,183.49985,61.39282
220.50002,183.74991,61.28761
220.80000,183.99991,61.32348
221.10000,184.24984,61.20069
221.40002,184.49992,61.38390
221.70002,184.74985,61.52620
222.00002,184.99991,61.64022
222.30000,185.24984,61.66276
222.60000,185.49984,61.55711
222.90002,185.74992,61.82465
223.20002,185.99985,61.86753
223.50002,186.24991,61.99061
223.80000,186.49984,61.72499
224.10000,186.74985,61.97832
224.40002,186.99991,62.09018
224.70002,187.24991,62.31078
225.00002,187.49991,62.11331
225.30002,187.74984,62.15795
225.60000,187.99990,62.43940
225.90002,188.24991,62.50938
226.20002,188.49997,62.21205
226.50002,188.74984,62.42627
226.80002,188.99985,62.61434
227.10000,189.24991,62.78828
227.40002,189.49991,62.66275
227.70002,189.74984,63.06479
228.00002,189.99984,62.96664
228.30002,190.24990,62.92186
228.60000,190.49991,63.04230
228.90002,190.74984,62.89692
229.20002,190.99990,63.24202
229.50002,191.24992,63.12045
229.80002,191.49985,62.99119
230.10000,191.74986,63.04338
230.40002,191.99990,63.16053
230.70002,192.24990,63.09105
231.00002,192.49983,63.25903
231.30002,192.74991,63.25339
231.60000,192.99991,63.34497
231.90002,193.24990,63.28240
232.20002,193.49990,63.67121
232.50002,193.74991,63.68425
232.80002,193.99991,63.76230
233.10000,194.24984,63.64294
233.40002,194.49985,63.92194
233.70002,194.74998,63.94933
234.00002,194.99991,63.88980
234.30002,195.24978,64.00427
234.60000,195.49990,63.90989
234.90002,195.74990,63.91626
235.20002,195.99983,64.03376
235.50002,196.24986,64.27313
235.80002,196.49984,64.13902
236.10000,196.74990,64.13392
236.40002,196.99983,64.16067
236.70002,197.24978,64.46991
237.00002,197.49997,64.62656
237.30002,197.74990,64.53861
237.60000,197.99991,64.61637
237.90002,198.24991,64.59157
238.20002,198.49991,64.75053
238.50002,198.74990,64.99180
238.80002,198.99985,64.88969
239.10000,199.24983,64.96652
239.40002,199.49991,64.93820
239.70002,199.74984,65.09461
240.00002,199.99990,65.14601
240.30002,200.24985,65.13881
240.60000,200.49984,65.11254
240.90002,200.74986,65.13087
241.20002,200.99990,65.30781
241.50002,201.24990,65.39371
241.80002,201.49983,65.37401
242.10000,201.74991,65.39473
242.40002,201.99992,65.33054
242.70002,202.24990,65.56393
243.00002,202.49991,65.80971
243.30002,202.74984,65.66854
243.60000,202.99992,65.72514
243.90002,203.24990,65.88365
244.20002,203.49991,65.92981
244.50002,203.74991,65.96685
244.80002,203.99984,65.86837
245.10000,204.24992,66.13684
245.40002,204.49990,66.15212
245.70002,204.74991,66.16859
246.00002,204.99984,66.32142
246.30002,205.24984,66.13492
246.60000,205.49998,66.29099
246.90002,205.74979,66.40506
247.20002,205.99991,66.40697
247.50002,206.24997,66.44244
247.80002,206.49992,66.48866
248.10000,206.74990,66.56078
248.40002,206.99985,66.65658
248.70002,207.24989,66.68690
249.00002,207.49992,66.79265
249.30002,207.74985,66.90491
249.60000,207.99991,67.12066
249.90002,208.24984,67.06734
250.20002,208.49984,67.06249
250.50002,208.74985,66.90001
250.80002,208.99991,66.90358
251.10000,209.24985,67.15368
251.40002,209.49984,67.14202
251.70002,209.74990,67.06984
252.00002,209.99990,67.50908
252.30002,210.24991,66.96993
252.60000,210.49991,67.36859
252.90002,210.74990,67.30896
253.20002,210.99992,67.43856
253.50002,211.24985,67.47326
253.80002,211.49985,67.64706
254.10000,211.74997,67.83488
254.40002,211.99984,67.89461
254.70002,212.24983,67.94547
255.00002,212.49991,67.78940
255.30002,212.74991,67.92675
255.60000,212.99990,68.04234
255.90002,213.24985,68.00672
256.20002,213.49985,68.04293
256.50000,213.74991,68.33350
256.80002,213.99984,68.33139
257.10000,214.24985,68.34433
257.40003,214.49991,68.22085
257.70002,214.74985,68.53209
258.00000,214.99991,68.59501
258.30002,215.24996,68.62103
258.60000,215.49990,68.56875
258.90003,215.74991,68.62074
259.20002,215.99986,68.46105
259.50000,216.24990,68.63446
259.80002,216.49990,68.95996
260.10000,216.74978,68.70393
260.40003,216.99991,68.64666
260.70002,217.24992,68.65009
261.00000,217.49990,68.64514
261.30002,217.74985,68.86706
261.60000,217.99991,68.91189
261.90003,218.24986,68.78385
262.20000,218.49984,69.03905
262.50000,218.74990,68.99083
262.80003,218.99983,69.32031
263.10000,219.24986,69.25435
263.40003,219.49984,69.49229
263.70000,219.74990,69.37808
264.00000,219.99998,69.42164
264.30003,220.24984,69.58579
264.60000,220.49991,69.46088
264.90003,220.74990,69.64699
265.20000,220.99990,69.69271
265.50000,221.24991,69.67369
265.80003,221.49984,69.66139
266.10000,221.74992,69.85582
266.40003,221.99985,70.09014
266.70000,222.24991,70.16854
267.00000,222.49991,70.09524
267.30003,222.74986,70.29594
267.60000,222.99990,70.23273
267.90003,223.24990,70.07373
268.20000,223.49991,70.33622
268.50000,223.74991,70.35499
268.80003,223.99984,70.54672
269.10000,224.24996,70.44500
269.40003,224.49991,70.49473
269.70000,224.74984,70.47812
270.00000,224.99992,70.52776
270.30003,225.24990,70.68025
270.60000,225.49991,70.62458
270.90003,225.74984,70.61528
271.20000,225.99991,70.90800
271.50000,226.24984,70.53423
271.80003,226.49985,70.49297
272.10000,226.74991,70.74277
272.40003,226.99989,70.94019
272.70000,227.24984,70.99928
273.00000,227.49985,71.28348
273.30003,227.74991,70.99012
273.60000,227.99991,71.04682
273.90003,228.24984,71.18960
274.20000,228.49984,71.38776
274.50000,228.74990,71.29470
274.80003,228.99991,71.43078
275.10000,229.24984,71.62291
275.40003,229.49992,71.61414
275.70000,229.74990,72.06660
276.00000,229.99991,71.95939
276.30003,230.24984,71.90015
276.60000,230.49990,72.06258
276.90003,230.74992,71.91916
277.20000,230.99985,72.11986
277.50000,231.24991,72.21968
277.80003,231.49990,72.25035
278.10000,231.74984,72.13633
278.40003,231.99985,72.30626
278.70000,232.24996,72.58815
279.00000,232.49991,72.57693
279.30003,232.74984,72.77764
279.60000,232.99992,72.67243
279.90003,233.24991,72.76402
280.20000,233.49985,72.75500
280.50000,233.74990,73.06571
280.80003,233.99990,73.06987
281.10000,234.24990,73.18865
281.40003,234.49985,73.29233
281.70000,234.74984,73.46677
282.00000,234.99990,73.39068
282.30003,235.24985,73.24245
282.60000,235.49991,73.48902
282.90003,235.74991,73.31443
283.20000,235.99990,73.35221
283.50000,236.24985,73.32511
283.80003,236.49983,73.34197
284.10000,236.74997,73.52160
284.40003,236.99991,73.40567
284.70000,237.24990,73.60074
285.00000,237.49990,73.70746
285.30003,237.74991,73.95172
285.60000,237.99991,73.88910
285.90003,238.24984,74.09034
286.20000,238.49990,74.16576
286.50000,238.74991,74.42060
286.80003,238.99978,74.32192
287.10000,239.24991,74.52943
287.40003,239.49990,74.67413
287.70000,239.74985,74.81554
288.00000,239.99991,74.65213
288.30003,240.24991,74.80682
288.60000,240.49990,74.68868
288.90003,240.74985,74.90668
289.20000,240.99983,75.07568
289.50000,241.24991,74.87831
289.80003,241.49984,75.01286
290.10000,241.74990,75.12497
290.40003,241.99991,75.23684
290.70000,242.24991,75.20107
291.00000,242.49991,75.07539
291.30003,242.74984,75.40516
291.60000,242.99996,75.41167
291.90003,243.24991,75.52991
292.20000,243.49991,75.54966
292.50000,243.74984,75.49257
292.80003,243.99990,75.59155
293.10000,244.24991,75.75296
293.40003,244.49991,75.62457
293.70000,244.74991,75.66627
294.00000,244.99990,75.97512
294.30003,245.24990,76.18328
294.60000,245.49991,75.83993
294.90003,245.74991,75.95939
295.20000,245.99984,76.11134
295.50000,246.24985,76.07341
295.80003,246.49991,76.31136
296.10000,246.74997,76.48114
296.40003,246.99984,76.51593
296.70000,247.24985,76.53779
297.00000,247.49996,76.73320
297.30003,247.74991,76.70189
297.60000,247.99984,76.89691
297.90003,248.24992,76.87956
298.20000,248.49990,76.90882
298.50000,248.74991,76.97350
298.80003,248.99984,76.99917
299.10000,249.24992,77.20173
299.40003,249.49990,77.29831
299.70000,249.74985,77.23265
300.00000,249.99997,77.28886
300.30003,250.24995,77.35344
300.60000,250.49990,77.34281
300.90003,250.74989,77.28778
301.20000,250.99991,77.49912
301.50000,251.24988,77.10349
301.80003,251.49990,77.33864
302.10000,251.74990,77.57404
302.40003,251.99989,77.50759
302.70000,252.24984,77.81389
303.00000,252.49988,77.88573
303.30003,252.74990,77.79326
303.60000,252.99991,77.94707
303.90003,253.24984,78.06497
304.20000,253.49990,78.03841
304.50000,253.74992,78.22074
304.80003,253.99989,78.33172
305.10000,254.24991,78.45064
305.40003,254.49982,78.19344
305.70000,254.74990,78.51713
306.00000,254.99990,78.59010
306.30003,255.24989,78.49861
306.60000,255.49991,78.50013
306.90003,255.74982,78.57310
307.20000,255.99990,78.92251
307.50000,256.24996,78.84387
307.80003,256.49983,78.93898
308.10000,256.74984,79.12096
308.40003,256.99988,79.29756
308.70000,257.24990,78.93918
309.00000,257.49991,79.10533
309.30003,257.74984,79.08980
309.60000,257.99984,79.25478
309.90003,258.24998,79.23415
310.20000,258.49983,79.39124
310.50000,258.74991,79.47577
310.80003,258.99990,79.27061
311.10000,259.24990,79.40511
311.40003,259.49989,79.71724
311.70000,259.74983,79.51884
312.00000,259.99997,79.73184
312.30003,260.24988,79.79231
312.60000,260.49990,79.68005
312.90003,260.74996,79.69230
313.20000,260.99995,79.90040
313.50000,261.24984,79.90476
313.80003,261.49988,80.00335
314.10000,261.74990,79.92436
314.40003,261.99996,80.00394
314.70000,262.24984,80.19322
315.00000,262.49990,80.26075
315.30003,262.74988,80.37061
315.60000,262.99983,80.46699
315.90003,263.24986,80.52986
316.20000,263.49990,80.30818
316.50000,263.74990,80.43764
316.80003,263.99983,80.59904
317.10000,264.24989,79.92446
317.40003,264.49991,0.44098
317.70000,264.74988,0.38575
318.00000,264.99990,0.62438
318.30003,265.24989,0.60121
318.60000,265.49995,0.43676
318.90003,265.74984,0.59802
319.20000,265.99983,0.52369
319.50000,266.24991,0.47283
319.80003,266.49982,0.40604
320.10000,266.74990,0.55662
320.11203,266.75984,0.45362