File: V_7/EPR/RDSO EPR Tensile 50.is_tens_RawData/Specimen_RawData_8.csv
Time,Extension,Load
(sec),(mm),(N)
0.00000,0.00000,0.52609
0.30000,0.24925,1.14231
0.60000,0.49994,1.79362
0.90000,0.74994,2.14495
1.20000,0.99994,2.36633
1.50000,1.24987,2.93571
1.80000,1.49994,3.21579
2.10000,1.75000,3.61646
2.40000,2.00000,3.98504
2.70000,2.24987,3.92536
3.00000,2.49994,4.41075
3.30000,2.74994,4.66540
3.60000,2.99994,5.00561
3.90000,3.24987,5.12090
4.20000,3.49987,5.51109
4.50000,3.74994,5.60924
4.80000,3.99994,5.76868
5.10000,4.24994,6.08125
5.40000,4.49994,6.22658
5.70000,4.75000,6.43714
6.00000,4.99994,6.46075
6.30000,5.24994,6.93997
6.60000,5.50000,6.92454
6.90000,5.74994,7.17478
7.20000,5.99994,7.40616
7.50000,6.24994,7.50563
7.80000,6.49994,7.65728
8.10000,6.74994,7.93815
8.40000,6.99987,7.90419
8.70000,7.24994,8.25145
9.00000,7.49994,8.42006
9.30000,7.74987,8.41531
9.60000,7.99987,8.80447
9.90000,8.25000,8.78619
10.20000,8.49981,8.88037
10.50000,8.74987,9.18480
10.80000,8.99987,9.54162
11.10000,9.24994,9.38301
11.40000,9.49987,9.52290
11.70000,9.74987,9.51516
12.00000,10.00000,9.87693
12.30000,10.24994,9.92117
12.60000,10.49994,9.84493
12.90000,10.74994,10.07082
13.20000,10.99994,10.23967
13.50000,11.24994,10.48452
13.80000,11.49987,10.36810
14.10000,11.74994,10.64608
14.40000,11.99987,10.49624
14.70000,12.24987,10.85286
15.00000,12.49994,10.98104
15.30000,12.74994,11.16263
15.60000,12.99994,11.03665
15.90000,13.24987,11.15641
16.20000,13.49994,11.35589
16.50000,13.74987,11.52234
16.80000,13.99987,11.37098
17.10000,14.25000,11.62852
17.40000,14.50000,11.80669
17.70000,14.74994,11.89415
18.00000,14.99994,11.96133
18.30000,15.24994,11.83947
18.60000,15.50000,11.85877
18.90000,15.74993,12.05889
19.20000,15.99994,12.02469
19.50000,16.24993,12.11049
19.80000,16.49987,12.33809
20.10000,16.74994,12.24862
20.40000,16.99987,12.52899
20.70000,17.24993,12.39268
21.00000,17.49987,12.52282
21.30000,17.74987,12.59108
21.60000,17.99993,12.57182
21.90000,18.24987,12.69858
22.20000,18.49987,12.85661
22.50000,18.74994,12.89630
22.80000,18.99993,13.15007
23.10000,19.24993,13.06711
23.40000,19.50000,13.04393
23.70000,19.74987,13.05898
24.00000,19.99993,13.16893
24.30000,20.24987,13.36042
24.60000,20.49993,13.21788
24.90000,20.74993,13.52095
25.20000,20.99993,13.51330
25.50000,21.24987,13.49713
25.80000,21.49994,13.62968
26.10000,21.74993,13.51732
26.40000,21.99987,13.68902
26.70000,22.24993,13.69328
27.00000,22.49993,13.74664
27.30000,22.74993,13.93779
27.60000,22.99994,13.89820
27.90000,23.24993,13.87972
28.20000,23.49993,14.04554
28.50000,23.74993,14.04059
28.80000,23.99993,14.05112
29.10000,24.25000,14.08665
29.40000,24.49993,14.16505
29.70000,24.74987,14.16417
30.00000,24.99999,14.31430
30.30000,25.24993,14.31631
30.60000,25.49981,14.34022
30.90000,25.74987,14.55945
31.20000,25.99993,14.42372
31.50000,26.24993,14.60468
31.80000,26.49987,14.66250
32.10000,26.74993,14.70086
32.40000,26.99994,14.74340
32.70000,27.24993,14.70321
33.00000,27.49993,14.70777
33.30000,27.74993,14.84821
33.60000,28.00000,14.82959
33.90000,28.24987,14.82998
34.20000,28.49987,14.94155
34.50000,28.74993,15.08448
34.80000,28.99987,15.08502
35.10000,29.24993,15.08326
35.40000,29.49993,15.17479
35.70000,29.74994,15.25740
36.00000,29.99993,15.17361
36.30000,30.24987,15.22310
36.60000,30.49993,15.38348
36.90000,30.74987,15.43616
37.20000,30.99993,15.56434
37.50000,31.24993,15.49941
37.80000,31.49987,15.80630
38.10000,31.74993,15.56468
38.40000,31.99987,15.78253
38.70000,32.24999,15.58482
39.00000,32.49993,15.95232
39.30000,32.74993,15.84227
39.60000,33.00000,15.84888
39.90000,33.24993,16.13136
40.20000,33.49993,15.87157
40.50000,33.74987,16.13837
40.80000,33.99987,16.12833
41.10000,34.24987,16.05194
41.40000,34.49987,16.33800
41.70000,34.74993,16.30629
42.00000,34.99993,16.38337
42.30000,35.24987,16.51028
42.60000,35.49987,16.37313
42.90000,35.75000,16.64131
43.20000,35.99993,16.45329
43.50000,36.24987,16.73421
43.80000,36.49993,16.64361
44.10000,36.74993,16.61367
44.40000,36.99993,16.67771
44.70000,37.24993,16.74538
45.00000,37.49993,16.80163
45.30000,37.74993,17.10303
45.60000,37.99993,16.87538
45.90000,38.24987,17.04933
46.20000,38.49993,17.27135
46.50000,38.74987,17.16585
46.80000,38.99987,17.19628
47.10000,39.24993,17.27791
47.40000,39.49993,17.26453
47.70000,39.74987,17.34788
48.00000,39.99987,17.55148
48.30000,40.24993,17.42614
48.60000,40.49999,17.47621
48.90000,40.74987,17.71548
49.20000,40.99987,17.72959
49.50000,41.24993,17.60685
49.80000,41.49993,17.55662
50.10000,41.74993,17.83288
50.40000,41.99993,18.00531
50.70000,42.24993,18.19338
51.00000,42.49987,17.94103
51.30000,42.74987,18.11997
51.60000,42.99993,17.95137
51.90000,43.24993,18.21783
52.20000,43.49981,18.34400
52.50000,43.74993,18.48336
52.80000,43.99993,18.27834
53.10000,44.24993,18.58866
53.40000,44.49987,18.45459
53.70000,44.74993,18.72218
54.00000,44.99999,18.63805
54.30000,45.24987,18.67941
54.60000,45.49993,18.83170
54.90000,45.74993,18.84978
55.20000,45.99987,18.72257
55.50000,46.24993,18.94195
55.80000,46.49993,18.96659
56.10000,46.74993,19.00452
56.40000,46.99986,19.30308
56.70000,47.24993,19.30053
57.00000,47.49993,19.02706
57.30000,47.74987,19.45199
57.60000,47.99987,19.27113
57.90000,48.24993,19.39789
58.20000,48.49993,19.52715
58.50000,48.74987,19.54734
58.80000,48.99987,19.56140
59.10000,49.24993,19.73859
59.40000,49.49987,19.76843
59.70000,49.74993,19.78543
60.00000,49.99993,20.06473
60.30000,50.24993,20.03053
60.60000,50.49993,20.01058
60.90000,50.74987,20.04616
61.20000,50.99987,20.25088
61.50000,51.24993,20.15817
61.80000,51.49987,20.15244
62.10000,51.74993,20.28175
62.40000,51.99993,20.40910
62.70000,52.24986,20.25029
63.00000,52.49986,20.59932
63.30000,52.74993,20.43904
63.60000,52.99993,20.74205
63.90000,53.24987,20.61044
64.20000,53.49987,20.62847
64.50000,53.74993,20.85240
64.80000,53.99987,20.90145
65.10001,54.24987,21.08775
65.40000,54.49993,21.05036
65.70001,54.74993,21.08192
66.00000,54.99993,21.14155
66.30000,55.24987,21.16830
66.60001,55.49993,21.27267
66.90000,55.74993,21.52845
67.20001,55.99987,21.40355
67.50000,56.24993,21.66541
67.80000,56.49987,21.56545
68.10001,56.74993,21.62910
68.40000,56.99987,21.82059
68.70001,57.24987,21.80711
69.00000,57.49993,21.80785
69.30000,57.74980,22.09479
69.60001,57.99993,21.93123
69.90000,58.24993,22.15634
70.20001,58.49987,22.31676
70.50000,58.74993,22.04256
70.80000,58.99993,22.26571
71.10001,59.24999,22.42657
71.40000,59.49981,22.46827
71.70001,59.74993,22.66064
72.00000,59.99999,22.36640
72.30000,60.24993,22.75311
72.60001,60.49993,22.93436
72.90000,60.74993,22.68005
73.20001,60.99987,22.79662
73.50000,61.24993,23.07102
73.80000,61.49987,23.08155
74.10001,61.74993,22.98350
74.40000,61.99993,22.98301
74.70001,62.24987,23.13560
75.00000,62.49993,23.09463
75.30000,62.74993,23.44704
75.60001,62.99987,23.51133
75.90000,63.24986,23.41137
76.20001,63.49993,23.44920
76.50000,63.74992,23.77088
76.80000,63.99993,23.89495
77.10001,64.24993,23.82615
77.40000,64.49993,24.12128
77.70001,64.74987,23.90475
78.00000,64.99992,24.18620
78.30000,65.24993,24.26524
78.60001,65.49993,24.25534
78.90000,65.74986,24.29087
79.20001,65.99993,24.49652
79.50000,66.24993,24.49240
79.80000,66.49987,24.23246
80.10001,66.74992,24.69987
80.40000,66.99986,24.59976
80.70001,67.24992,24.65396
81.00001,67.49993,24.70095
81.30000,67.74993,24.69904
81.60001,67.99986,24.91116
81.90000,68.24993,24.94026
82.20001,68.49993,25.07879
82.50001,68.74999,25.05953
82.80000,68.99986,25.29247
83.10001,69.24986,25.43658
83.40000,69.49992,25.27513
83.70001,69.74999,25.60838
84.00001,69.99987,25.53943
84.30000,70.24986,25.59622
84.60001,70.49993,25.45349
84.90000,70.74993,25.64552
85.20001,70.99986,25.90071
85.50001,71.24986,26.08132
85.80000,71.49993,26.01561
86.10001,71.74992,25.84333
86.40000,71.99986,26.14433
86.70001,72.24993,26.11406
87.00001,72.49999,26.31329
87.30000,72.74986,26.55750
87.60001,72.99987,26.27502
87.90000,73.24993,26.53692
88.20001,73.49993,26.62684
88.50001,73.74987,26.54609
88.80000,73.99987,26.57573
89.10001,74.24993,26.67922
89.40000,74.49986,26.98851
89.70001,74.74986,26.80113
90.00001,74.99993,26.99914
90.30000,75.24987,26.87728
90.60001,75.49993,27.01021
90.90000,75.74987,27.29417
91.20001,75.99999,27.30073
91.50001,76.24999,27.43818
91.80000,76.49980,27.46625
92.10001,76.74999,27.50428
92.40000,76.99999,27.51040
92.70001,77.24993,27.59213
93.00001,77.49987,27.83047
93.30000,77.74992,27.75251
93.60001,77.99993,27.80117
93.90000,78.24986,28.17043
94.20001,78.49980,28.03857
94.50001,78.74993,28.20880
94.80000,78.99993,28.29166
95.10001,79.24993,28.51029
95.40000,79.49992,28.35864
95.70001,79.74993,28.34776
96.00001,79.99992,28.63632
96.30000,80.24986,28.71928
96.60001,80.49986,28.83570
96.90000,80.74986,29.02460
97.20001,80.99993,28.62383
97.50001,81.24992,28.99774
97.80000,81.49993,29.08962
98.10001,81.74992,29.04841
98.40000,81.99986,29.22442
98.70001,82.24992,28.94771
99.00001,82.49993,29.59981
99.30000,82.74986,29.59187
99.60001,82.99992,29.72721
99.90000,83.24986,29.57540
100.20001,83.49986,29.75935
100.50001,83.74986,29.78831
100.80000,83.99987,29.80663
101.10001,84.24993,29.87807
101.40000,84.49987,29.87558
101.70001,84.74993,29.94530
102.00001,84.99992,30.04223
102.30000,85.24993,30.18535
102.60001,85.49985,30.08108
102.90000,85.74992,30.31760
103.20001,85.99993,30.39728
103.50001,86.24992,30.55741
103.80000,86.49986,30.49552
104.10001,86.74992,30.57779
104.40000,86.99981,30.77752
104.70001,87.24992,31.08367
105.00001,87.49999,30.86738
105.30000,87.74986,31.10572
105.60001,87.99986,30.96298
105.90000,88.24986,31.14129
106.20001,88.49992,31.01585
106.50001,88.74992,31.33768
106.80000,88.99986,31.40790
107.10001,89.24986,31.50468
107.40000,89.49986,31.57092
107.70001,89.74986,31.73252
108.00001,89.99993,31.73154
108.30000,90.24986,31.70562
108.60001,90.49992,31.87977
108.90000,90.74987,31.80994
109.20001,90.99992,31.98497
109.50001,91.24992,31.96498
109.80000,91.49986,31.93171
110.10001,91.74986,32.41411
110.40000,91.99993,32.29597
110.70001,92.24986,32.43092
111.00001,92.49986,32.38378
111.30000,92.74987,32.61094
111.60001,92.99998,32.56219
111.90000,93.24992,32.74094
112.20001,93.49986,32.82694
112.50001,93.74999,32.84820
112.80000,93.99986,32.78058
113.10001,94.24992,33.28866
113.40001,94.49986,33.19928
113.70001,94.74993,33.36696
114.00001,94.99992,33.25568
114.30000,95.24986,33.18596
114.60001,95.49987,33.47996
114.90001,95.74998,33.47413
115.20001,95.99992,33.61005
115.50001,96.24986,33.89670
115.80000,96.49992,33.86191
116.10001,96.74992,33.77508
116.40001,96.99985,33.96069
116.70001,97.24992,33.96922
117.00001,97.49993,34.20623
117.30000,97.74987,34.35308
117.60001,97.99986,34.24798
117.90001,98.24986,34.08309
118.20001,98.49992,34.28253
118.50001,98.74986,34.48646
118.80000,98.99986,34.56829
119.10001,99.24993,34.60509
119.40001,99.49992,34.72852
119.70001,99.74986,34.89414
120.00001,99.99992,34.67046
120.30000,100.24992,34.74842
120.60001,100.49992,35.14389
120.90001,100.74986,35.10812
121.20001,100.99986,34.97460
121.50001,101.24993,35.22592
121.80000,101.49992,35.39389
122.10001,101.74992,35.48964
122.40001,101.99992,35.19608
122.70001,102.24986,35.57034
123.00001,102.49992,35.80392
123.30000,102.74986,35.71783
123.60001,102.99992,35.81730
123.90001,103.24986,35.81000
124.20001,103.49993,35.78447
124.50001,103.74999,36.08312
124.80000,103.99986,35.97621
125.10001,104.24992,36.27829
125.40001,104.49992,36.33650
125.70001,104.74992,36.37678
126.00001,104.99992,36.44940
126.30000,105.24986,36.57831
126.60001,105.49992,36.46356
126.90001,105.74993,36.66186
127.20001,105.99992,36.68283
127.50001,106.24993,36.87770
127.80000,106.49987,36.91911
128.10001,106.74986,36.85066
128.40001,106.99986,37.13745
128.70002,107.24992,37.05597
129.00000,107.49992,37.14857
129.30000,107.74986,37.42160
129.60001,107.99993,37.42082
129.90001,108.24992,37.32698
130.20002,108.49993,37.59658
130.50000,108.74987,37.54533
130.80000,108.99992,37.66400
131.10000,109.24992,37.68796
131.40002,109.49986,37.93061
131.70002,109.74986,37.91444
132.00000,109.99999,38.05203
132.30000,110.24985,37.66435
132.60000,110.49992,38.12176
132.90002,110.74992,38.12034
133.20002,110.99992,38.41782
133.50000,111.24986,38.42909
133.80000,111.49986,38.42414
134.10000,111.74999,38.70545
134.40002,111.99992,38.51195
134.70002,112.24986,38.75533
135.00000,112.49992,38.86548
135.30000,112.74986,38.80614
135.60000,112.99992,38.95084
135.90002,113.24986,39.07089
136.20002,113.49992,39.20848
136.50000,113.74992,39.09014
136.80000,113.99986,39.26772
137.10000,114.24992,39.39091
137.40002,114.49993,39.23739
137.70002,114.74992,39.51321
138.00000,114.99993,39.55912
138.30000,115.24992,39.72107
138.60000,115.49992,39.57794
138.90002,115.74986,39.71558
139.20002,115.99992,39.94740
139.50000,116.24992,39.84607
139.80000,116.49992,39.95382
140.10000,116.74993,39.98434
140.40002,116.99992,39.97116
140.70002,117.24993,40.14854
141.00000,117.49987,40.18294
141.30000,117.74993,40.29897
141.60000,117.99992,40.29701
141.90002,118.24986,40.63516
142.20002,118.49992,40.47493
142.50000,118.74992,40.67490
142.80000,118.99993,40.86830
143.10000,119.24986,40.88883
143.40002,119.49986,40.64584
143.70002,119.74987,41.02701
144.00000,119.99992,41.15421
144.30000,120.24986,41.05964
144.60000,120.49992,41.15764
144.90002,120.74992,41.32621
145.20002,120.99986,41.40142
145.50000,121.24993,41.13168
145.80000,121.49992,41.35742
146.10000,121.74992,41.68062
146.40002,121.99992,41.64191
146.70002,122.24986,41.77681
147.00000,122.49992,41.92072
147.30000,122.74992,42.00534
147.60000,122.99986,41.96114
147.90002,123.24986,41.98574
148.20002,123.49992,42.24549
148.50000,123.74992,42.09864
148.80000,123.99986,42.31193
149.10000,124.24992,42.52567
149.40002,124.49986,42.45977
149.70002,124.74992,42.49426
150.00000,124.99992,42.74612
150.30000,125.24992,42.81232
150.60000,125.49992,42.68458
150.90002,125.74992,42.58687
151.20002,125.99997,42.77141
151.50000,126.24991,43.16590
151.80000,126.49992,42.84775
152.10000,126.74992,43.21936
152.40002,126.99991,43.14983
152.70002,127.24985,43.28625
153.00000,127.49991,43.44550
153.30000,127.74984,43.38052
153.60000,127.99992,43.48313
153.90002,128.24985,43.40331
154.20002,128.49986,43.84935
154.50000,128.74993,43.74670
154.80000,128.99992,43.63875
155.10000,129.24986,43.83549
155.40002,129.49991,43.75665
155.70002,129.74999,43.98646
156.00000,129.99984,43.96994
156.30000,130.24986,44.03202
156.60000,130.49997,44.23175
156.90002,130.74991,44.29442
157.20002,130.99985,44.22445
157.50000,131.24998,44.50669
157.80000,131.49998,44.51242
158.10000,131.74991,44.43715
158.40002,131.99992,44.67515
158.70002,132.24992,44.61115
159.00000,132.49986,44.76423
159.30000,132.74992,44.84905
159.60000,132.99991,44.80078
159.90002,133.24998,45.14648
160.20002,133.49985,45.08101
160.50000,133.74992,45.12291
160.80000,133.99998,45.35659
161.10000,134.24992,45.40098
161.40002,134.49991,45.20278
161.70002,134.74992,45.49511
162.00002,134.99992,45.55656
162.30000,135.24991,45.71071
162.60000,135.49991,45.80920
162.90002,135.74985,45.74290
163.20002,135.99992,45.87966
163.50002,136.24991,45.93297
163.80000,136.49992,45.98628
164.10000,136.74991,45.91969
164.40002,136.99985,46.17337
164.70002,137.24986,46.14196
165.00002,137.49997,46.20581
165.30000,137.74991,46.11266
165.60000,137.99992,46.30522
165.90002,138.24992,46.57409
166.20002,138.49986,46.48491
166.50002,138.74992,46.68453
166.80000,138.99985,46.67224
167.10000,139.24993,46.78900
167.40002,139.49992,47.00386
167.70002,139.74986,47.05816
168.00002,139.99991,47.11220
168.30000,140.24991,46.96589
168.60000,140.49992,47.16023
168.90002,140.74986,47.17174
169.20002,140.99992,47.33868
169.50002,141.24999,47.32173
169.80000,141.49993,47.48838
170.10000,141.74992,47.48147
170.40002,141.99986,47.55222
170.70002,142.24998,47.70917
171.00002,142.49991,47.68678
171.30000,142.74985,47.71897
171.60000,142.99998,47.76219
171.90002,143.24992,48.00469
172.20002,143.49991,48.07456
172.50002,143.74998,48.17388
172.80000,143.99998,48.05290
173.10000,144.24986,48.31069
173.40002,144.49986,48.21098
173.70002,144.74998,48.44995
174.00002,144.99992,48.10078
174.30000,145.24986,48.52977
174.60000,145.49986,48.64301
174.90002,145.74992,48.64384
175.20002,145.99991,48.60601
175.50002,146.24985,48.86963
175.80000,146.49992,48.80721
176.10000,146.74991,48.99360
176.40002,146.99985,48.92127
176.70002,147.24985,49.08268
177.00002,147.49992,49.08028
177.30000,147.74986,49.19847
177.60000,147.99992,49.33513
177.90002,148.24999,49.29000
178.20002,148.49992,49.37227
178.50002,148.74992,49.42867
178.80000,148.99986,49.55005
179.10000,149.24991,49.55544
179.40002,149.49991,49.71953
179.70002,149.74984,49.90162
180.00002,149.99992,49.92151
180.30000,150.24992,49.87403
180.60000,150.49986,49.91171
180.90002,150.74993,50.10605
181.20002,150.99992,50.06312
181.50002,151.24992,50.19586
181.80000,151.49985,50.29950
182.10000,151.74991,50.41406
182.40002,151.99992,50.33179
182.70002,152.24986,50.47330
183.00002,152.49985,50.50686
183.30000,152.74986,50.38079
183.60000,152.99991,50.65724
183.90002,153.24985,50.66528
184.20002,153.49992,50.85079
184.50002,153.74991,50.87338
184.80000,153.99985,50.91625
185.10000,154.24985,50.89857
185.40002,154.49998,51.01793
185.70002,154.74985,51.18492
186.00002,154.99991,51.29669
186.30000,155.24985,51.27807
186.60000,155.49992,51.48823
186.90002,155.74986,51.33672
187.20002,155.99986,51.49705
187.50002,156.24992,51.42032
187.80000,156.49991,51.71804
188.10000,156.74992,51.70897
188.40002,156.99985,51.76141
188.70002,157.24991,51.76969
189.00002,157.49991,51.94207
189.30000,157.74984,51.95201
189.60000,157.99992,51.94976
189.90002,158.24990,52.22156
190.20002,158.49991,52.25993
190.50002,158.74991,52.20824
190.80000,158.99984,52.06364
191.10000,159.24998,52.36200
191.40002,159.49985,52.12101
191.70002,159.74991,52.34911
192.00002,159.99991,52.43222
192.30000,160.24992,52.30972
192.60000,160.49985,52.38650
192.90002,160.74991,52.58411
193.20002,160.99991,52.54658
193.50002,161.24984,52.55525
193.80000,161.49985,52.70142
194.10000,161.74996,52.87214
194.40002,161.99991,53.04050
194.70002,162.24984,52.97518
195.00002,162.49992,53.08921
195.30000,162.74985,53.32127
195.60000,162.99991,53.27438
195.90002,163.24991,53.20847
196.20002,163.49992,53.45773
196.50002,163.74992,53.57680
196.80000,163.99985,53.71439
197.10000,164.24986,53.55093
197.40002,164.49990,53.89741
197.70002,164.74985,53.85155
198.00002,164.99985,53.85982
198.30000,165.24991,53.84125
198.60000,165.49991,53.76423
198.90002,165.74990,54.06857
199.20002,165.99992,54.04965
199.50002,166.24991,54.40554
199.80000,166.49991,54.16583
200.10000,166.74984,54.25104
200.40002,166.99998,54.47330
200.70002,167.24985,54.35041
201.00002,167.49986,54.31293
201.30000,167.74984,54.64323
201.60000,167.99990,54.55200
201.90002,168.24985,54.63638
202.20002,168.49985,54.59178
202.50002,168.74991,54.73844
202.80000,168.99984,54.74564
203.10000,169.24992,54.97212
203.40002,169.49985,55.03136
203.70002,169.74986,54.93968
204.00002,169.99992,55.00030
204.30000,170.24985,55.04513
204.60000,170.49998,55.30336
204.90002,170.74991,55.25078
205.20002,170.99986,55.39274
205.50002,171.24984,55.42458
205.80000,171.49990,55.33595
206.10000,171.74991,55.57776
206.40002,171.99986,55.44330
206.70002,172.24984,55.61975
207.00002,172.49990,55.82609
207.30000,172.74985,55.55747
207.60000,172.99986,55.89949
207.90002,173.24992,55.79130
208.20002,173.49990,55.83996
208.50002,173.74985,55.86338
208.80000,173.99983,56.00484
209.10000,174.24991,55.98568
209.40002,174.49984,56.02728
209.70002,174.74985,56.12685
210.00002,174.99991,56.15748
210.30000,175.24991,56.27993
210.60000,175.49992,56.35823
210.90002,175.74985,56.29213
211.20002,175.99991,56.42066
211.50002,176.24991,56.47793
211.80000,176.49986,56.64811
212.10000,176.74984,56.73445
212.40002,176.99990,56.94843
212.70002,177.24985,56.57118
213.00002,177.49984,56.90659
213.30000,177.74992,56.77889
213.60000,177.99990,56.99690
213.90002,178.24979,57.09984
214.20002,178.49991,56.94956
214.50002,178.74992,57.29349
214.80000,178.99992,56.96455
215.10000,179.24985,57.26370
215.40002,179.49985,57.15066
215.70002,179.74997,57.31074
216.00002,179.99992,57.37796
216.30000,180.24985,57.46332
216.60000,180.49991,57.51100
216.90002,180.74991,57.57480
217.20002,180.99984,57.67280
217.50002,181.24992,57.62232
217.80000,181.49991,57.53981
218.10000,181.74985,57.52923
218.40002,181.99991,57.65212
218.70002,182.24992,57.93906
219.00002,182.49990,57.76477
219.30000,182.74985,58.03711
219.60000,182.99984,58.23816
219.90002,183.24992,57.85733
220.20002,183.49985,58.15687
220.50002,183.74991,58.20454
220.80000,183.99986,58.26011
221.10000,184.24984,58.22679
221.40002,184.49984,58.29157
221.70002,184.74985,58.39358
222.00002,184.99991,58.23159
222.30000,185.24984,58.54872
222.60000,185.49992,58.44239
222.90002,185.74992,58.44606
223.20002,185.99985,58.59135
223.50002,186.24991,58.61864
223.80000,186.49979,58.81322
224.10000,186.74992,58.85864
224.40002,186.99991,59.00260
224.70002,187.24985,58.91009
225.00002,187.49991,59.04479
225.30002,187.74990,58.88241
225.60000,187.99990,59.06165
225.90002,188.24991,59.04244
226.20002,188.49997,59.17170
226.50002,188.74984,59.25755
226.80002,188.99985,59.21859
227.10000,189.24991,59.27440
227.40002,189.49986,59.56380
227.70002,189.74984,59.41141
228.00002,189.99984,59.40631
228.30002,190.24983,59.51215
228.60000,190.49991,59.57061
228.90002,190.74984,59.36834
229.20002,190.99990,59.64847
229.50002,191.24992,59.76239
229.80002,191.49985,59.86255
230.10000,191.74986,59.82879
230.40002,191.99984,59.89200
230.70002,192.24990,59.90395
231.00002,192.49983,59.89254
231.30002,192.74991,59.82707
231.60000,192.99991,60.14469
231.90002,193.24984,60.02136
232.20002,193.49990,60.10427
232.50002,193.74991,60.09104
232.80002,193.99991,60.22897
233.10000,194.24984,60.34049
233.40002,194.49985,60.13362
233.70002,194.74998,60.30679
234.00002,194.99991,60.40033
234.30002,195.24978,60.47221
234.60000,195.49990,60.47809
234.90002,195.74990,60.53081
235.20002,195.99991,60.81482
235.50002,196.24986,60.64341
235.80002,196.49984,60.66889
236.10000,196.74990,60.76488
236.40002,196.99983,60.97985
236.70002,197.24978,60.80992
237.00002,197.49997,61.23038
237.30002,197.74990,61.17932
237.60000,197.99991,61.22887
237.90002,198.24997,61.30197
238.20002,198.49991,61.05349
238.50002,198.74990,60.99048
238.80002,198.99990,61.35023
239.10000,199.24983,61.17604
239.40002,199.49991,61.13145
239.70002,199.74984,61.24665
240.00002,199.99990,61.33147
240.30002,200.24991,61.30330
240.60000,200.49984,61.37395
240.90002,200.74992,61.44535
241.20002,200.99990,61.35509
241.50002,201.24990,61.59573
241.80002,201.49983,61.29462
242.10000,201.74991,61.67383
242.40002,201.99992,61.75836
242.70002,202.24990,61.72464
243.00002,202.49985,61.79721
243.30002,202.74984,62.00399
243.60000,202.99992,61.93721
243.90002,203.24990,61.78055
244.20002,203.49991,62.08509
244.50002,203.74991,62.09954
244.80002,203.99984,61.96758
245.10000,204.24992,62.04779
245.40002,204.49990,62.24076
245.70002,204.74985,62.26447
246.00002,204.99984,62.52716
246.30002,205.24984,62.32293
246.60000,205.49998,62.38859
246.90002,205.74979,62.28564
247.20002,205.99991,62.39697
247.50002,206.24990,62.63006
247.80002,206.49992,62.79985
248.10000,206.74990,62.99698
248.40002,206.99985,62.84365
248.70002,207.24989,62.75791
249.00002,207.49992,63.00819
249.30002,207.74985,63.00124
249.60000,207.99991,63.13839
249.90002,208.24984,63.24874
250.20002,208.49984,63.36663
250.50002,208.74985,63.26598
250.80002,208.99991,63.23673
251.10000,209.24985,63.22134
251.40002,209.49984,63.47036
251.70002,209.74990,63.59815
252.00002,209.99990,63.46644
252.30002,210.24991,63.56130
252.60000,210.49984,63.74358
252.90002,210.74990,63.69306
253.20002,210.99992,64.00441
253.50002,211.24985,63.99025
253.80002,211.49991,64.20580
254.10000,211.74997,64.13191
254.40002,211.99984,64.05821
254.70002,212.24983,64.09771
255.00002,212.49991,64.22584
255.30002,212.74991,64.19821
255.60000,212.99984,64.30199
255.90002,213.24985,64.40170
256.20002,213.49985,64.52381
256.50000,213.74991,64.28861
256.80002,213.99984,64.51714
257.10000,214.24985,64.80860
257.40003,214.49991,64.60598
257.70002,214.74985,64.70491
258.00000,214.99991,64.77895
258.30002,215.24996,64.95030
258.60000,215.49990,64.90865
258.90003,215.74983,64.96637
259.20002,215.99986,65.08647
259.50000,216.24997,65.01420
259.80002,216.49985,64.99676
260.10000,216.74983,65.27645
260.40003,216.99991,65.16938
260.70002,217.24992,65.38919
261.00000,217.49984,65.56119
261.30002,217.74985,65.40399
261.60000,217.99991,65.70799
261.90003,218.24986,65.75963
262.20000,218.49984,65.64032
262.50000,218.74990,65.66139
262.80003,218.99983,65.71000
263.10000,219.24986,65.73582
263.40003,219.49984,65.95274
263.70000,219.74990,65.77830
264.00000,219.99998,65.89438
264.30003,220.24991,66.03663
264.60000,220.49997,66.00674
264.90003,220.74990,66.22165
265.20000,220.99990,66.01791
265.50000,221.24991,66.05094
265.80003,221.49984,66.39345
266.10000,221.74992,66.48311
266.40003,221.99985,66.46082
266.70000,222.24991,66.42520
267.00000,222.49991,66.46023
267.30003,222.74986,66.74620
267.60000,222.99990,66.58479
267.90003,223.24990,66.76398
268.20000,223.49991,66.81338
268.50000,223.74991,66.74507
268.80003,223.99984,66.96332
269.10000,224.24990,66.98198
269.40003,224.49991,67.20425
269.70000,224.74984,67.10052
270.00000,224.99992,67.22664
270.30003,225.24990,67.40235
270.60000,225.49991,67.15299
270.90003,225.74984,67.28044
271.20000,225.99991,67.44249
271.50000,226.24992,67.53671
271.80003,226.49985,67.77559
272.10000,226.74991,67.73996
272.40003,226.99989,67.75516
272.70000,227.24992,67.88055
273.00000,227.49985,67.81131
273.30003,227.74991,67.99153
273.60000,227.99991,67.86819
273.90003,228.24984,67.74971
274.20000,228.49992,68.07968
274.50000,228.74990,67.73550
274.80003,228.99985,68.04219
275.10000,229.24984,68.16587
275.40003,229.49992,68.08076
275.70000,229.74990,68.06615
276.00000,229.99991,68.25529
276.30003,230.24984,68.07699
276.60000,230.49990,68.48682
276.90003,230.74985,68.45085
277.20000,230.99985,68.71384
277.50000,231.24991,68.57742
277.80003,231.49984,68.62480
278.10000,231.74984,68.62088
278.40003,231.99985,68.83290
278.70000,232.24991,68.98936
279.00000,232.49991,69.07923
279.30003,232.74984,69.02553
279.60000,232.99992,68.94409
279.90003,233.24991,69.10461
280.20000,233.49985,69.21976
280.50000,233.74990,69.28454
280.80003,233.99990,69.31560
281.10000,234.24983,69.18629
281.40003,234.49985,69.29909
281.70000,234.74991,69.18462
282.00000,234.99990,69.23725
282.30003,235.24985,69.28875
282.60000,235.49991,69.28870
282.90003,235.74991,69.40101
283.20000,235.99990,69.43747
283.50000,236.24985,69.43109
283.80003,236.49983,69.25920
284.10000,236.74991,69.37342
284.40003,236.99991,69.34736
284.70000,237.24990,69.56986
285.00000,237.49990,69.31237
285.30003,237.74991,69.28591
285.60000,237.99991,69.36666
285.90003,238.24984,69.23117
286.20000,238.49990,69.40302
286.50000,238.74991,69.53551
286.80003,238.99985,69.44104
287.10000,239.24991,69.43545
287.40003,239.49984,69.48921
287.70000,239.74985,69.32256
288.00000,239.99991,69.41321
288.30003,240.24986,69.51062
288.60000,240.49990,69.10510
288.90003,240.74990,69.25999
289.20000,240.99983,69.19967
289.50000,241.24991,69.02136
289.80003,241.49984,69.37097
290.10000,241.74985,69.21040
290.40003,241.99991,69.05703
290.70000,242.24991,68.99073
291.00000,242.49991,69.22652
291.30003,242.74984,69.06036
291.60000,242.99990,68.91454
291.90003,243.24991,68.48261
292.20000,243.49984,68.46928
292.50000,243.74984,68.56330
292.80003,243.99990,67.82331
293.10000,244.24991,67.41681
293.40003,244.49984,67.52500
293.70000,244.74991,67.19748
294.00000,244.99990,66.77584
294.30003,245.24985,66.11400
294.60000,245.49991,65.15802
294.90003,245.74997,64.20335
295.20000,245.99984,61.87282
295.50000,246.24985,-0.65177
295.80003,246.49991,0.26247
296.10000,246.74989,0.25341
296.40003,246.99984,0.42696
296.70000,247.24985,0.24184
297.00000,247.49996,0.35513
297.30003,247.74991,0.25556
297.60000,247.99984,0.18819
297.90003,248.24984,0.35434
298.20000,248.49990,0.14066
298.50000,248.74991,0.24517
298.80003,248.99984,0.44926
299.10000,249.24992,0.55402
299.40003,249.49985,0.35234
299.70000,249.74985,0.43020
300.00000,249.99997,0.38629
300.30003,250.24990,0.43377
300.60000,250.49990,0.33945
300.90003,250.74989,0.30922
301.20000,250.99991,0.40192
301.50000,251.24988,0.35346
301.80003,251.49990,0.34273
302.10000,251.74990,0.33842
302.40003,251.99989,0.38634
302.70000,252.24984,0.49693
303.00000,252.49988,0.26624
303.30003,252.74990,0.52663
303.60000,252.99991,0.35454
303.90003,253.24984,0.18980
304.20000,253.49990,0.39075
304.50000,253.74992,0.36890
304.80003,253.99983,0.39889
305.10000,254.24991,0.19181
305.38800,254.48991,0.37066