File: V_7/EPR/RDSO EPR Tensile 50.is_tens_RawData/Specimen_RawData_15.csv
Time,Extension,Load
(sec),(mm),(N)
0.00000,-0.00006,2.73426
0.30000,0.24931,3.42569
0.60000,0.49987,3.93167
0.90000,0.74987,4.18916
1.20000,0.99994,4.49296
1.50000,1.24994,4.77050
1.80000,1.49994,4.82944
2.10000,1.74994,5.28201
2.40000,1.99994,5.33007
2.70000,2.24987,5.74412
3.00000,2.49994,5.78553
3.30000,2.75000,6.29302
3.60000,2.99994,6.26871
3.90000,3.24987,6.75313
4.20000,3.49994,6.73549
4.50000,3.74994,7.29345
4.80000,3.99994,7.03306
5.10000,4.24987,7.41100
5.40000,4.49994,7.55016
5.70000,4.74994,7.80804
6.00000,4.99987,7.77580
6.30000,5.24994,8.01992
6.60000,5.49994,8.19740
6.90000,5.74987,8.39879
7.20000,5.99994,8.39854
7.50000,6.24987,8.63046
7.80000,6.49994,8.79015
8.10000,6.74987,8.71395
8.40000,6.99987,9.08763
8.70000,7.25000,9.19513
9.00000,7.49994,9.42323
9.30000,7.74994,9.40813
9.60000,7.99987,9.54058
9.90000,8.25000,9.56939
10.20000,8.49994,9.76730
10.50000,8.74994,9.91362
10.80000,8.99994,10.20188
11.10000,9.24987,10.00814
11.40000,9.49987,10.31400
11.70000,9.74994,10.18287
12.00000,9.99994,10.44757
12.30000,10.24994,10.53229
12.60000,10.49987,10.81757
12.90000,10.74994,10.79047
13.20000,10.99994,10.81928
13.50000,11.24987,10.90052
13.80000,11.49994,11.24666
14.10000,11.74994,11.22201
14.40000,11.99994,11.09892
14.70000,12.24994,11.32506
15.00000,12.50000,11.24754
15.30000,12.74994,11.52674
15.60000,12.99987,11.50401
15.90000,13.24994,11.50949
16.20000,13.49994,11.76630
16.50000,13.74987,11.71064
16.80000,13.99994,11.86411
17.10000,14.24994,12.05373
17.40000,14.49994,12.03026
17.70000,14.74994,12.27531
18.00000,14.99987,12.12258
18.30000,15.24994,12.30809
18.60000,15.49987,12.04433
18.90000,15.74987,12.43201
19.20000,15.99994,12.56358
19.50000,16.24993,12.56167
19.80000,16.49993,12.72528
20.10000,16.74994,12.71655
20.40000,16.99987,12.58004
20.70000,17.24993,12.85483
21.00000,17.49994,12.91873
21.30000,17.74994,12.73155
21.60000,17.99993,12.92093
21.90000,18.24994,13.09185
22.20000,18.49987,12.95347
22.50000,18.74994,13.13173
22.80000,19.00000,13.16231
23.10000,19.24993,13.13394
23.40000,19.49994,13.21420
23.70000,19.74993,13.24624
24.00000,19.99993,13.46787
24.30000,20.24994,13.50173
24.60000,20.49993,13.36615
24.90000,20.74993,13.78108
25.20000,20.99987,13.47145
25.50000,21.24993,13.54735
25.80000,21.50000,13.72042
26.10000,21.74993,13.69405
26.40000,21.99987,13.85810
26.70000,22.25000,13.87986
27.00000,22.49993,13.97678
27.30000,22.74987,14.16872
27.60000,22.99987,14.01584
27.90000,23.24993,14.00961
28.20000,23.49993,14.05533
28.50000,23.74987,14.40318
28.80000,23.99993,14.42155
29.10000,24.24994,14.43875
29.40000,24.49993,14.53509
29.70000,24.74993,14.38142
30.00000,24.99993,14.36761
30.30000,25.25000,14.50098
30.60000,25.49981,14.59207
30.90000,25.74987,14.67895
31.20000,25.99993,14.65955
31.50000,26.24993,14.80307
31.80000,26.49993,14.74726
32.10000,26.74993,14.76406
32.40000,26.99994,14.81620
32.70000,27.24993,15.01965
33.00000,27.49987,15.02656
33.30000,27.74993,14.94536
33.60000,27.99987,15.18311
33.90000,28.24993,14.90489
34.20000,28.49993,15.16895
34.50000,28.74987,15.29287
34.80000,28.99987,15.28606
35.10000,29.24993,15.42958
35.40000,29.50000,15.35662
35.70000,29.74994,15.31894
36.00000,29.99993,15.59407
36.30000,30.24993,15.52435
36.60000,30.49993,15.41429
36.90000,30.74993,15.55325
37.20000,30.99987,15.66527
37.50000,31.24987,15.76552
37.80000,31.49993,15.78640
38.10000,31.74987,15.98342
38.40000,31.99993,16.13728
38.70000,32.24993,16.01464
39.00000,32.49993,16.07275
39.30000,32.74987,16.18369
39.60000,33.00000,16.10690
39.90000,33.24993,16.17560
40.20000,33.49987,16.35377
40.50000,33.74993,16.32539
40.80000,33.99993,16.38209
41.10000,34.24993,16.33681
41.40000,34.49993,16.49253
41.70000,34.74993,16.71690
42.00000,34.99993,16.51757
42.30000,35.24993,16.96283
42.60000,35.49987,16.88664
42.90000,35.74993,16.82441
43.20000,35.99987,16.66624
43.50000,36.24987,16.79937
43.80000,36.49993,17.00880
44.10000,36.74993,17.10469
44.40000,36.99987,17.01703
44.70000,37.24987,17.11434
45.00000,37.49993,17.34939
45.30000,37.74999,17.27927
45.60000,37.99987,17.25762
45.90000,38.24987,17.36071
46.20000,38.49993,17.37566
46.50000,38.74993,17.69391
46.80000,38.99993,17.52099
47.10000,39.24993,17.38727
47.40000,39.49993,17.67382
47.70000,39.74993,17.61786
48.00000,39.99993,17.95243
48.30000,40.24993,17.90721
48.60000,40.49993,17.91593
48.90000,40.74987,17.81083
49.20000,40.99993,17.98688
49.50000,41.24993,18.17426
49.80000,41.49993,18.12981
50.10000,41.74987,18.38314
50.40000,41.99987,18.24300
50.70000,42.24999,18.31743
51.00000,42.49987,18.48864
51.30000,42.74993,18.47923
51.60000,42.99993,18.81101
51.90000,43.24987,18.37364
52.20000,43.49993,18.83566
52.50000,43.74993,18.99569
52.80000,43.99993,18.84492
53.10000,44.24987,18.95370
53.40000,44.49993,19.05454
53.70000,44.74993,19.27215
54.00000,44.99987,19.10682
54.30000,45.24993,19.16935
54.60000,45.49987,19.25745
54.90000,45.74993,19.24456
55.20000,45.99987,19.23594
55.50000,46.24987,19.61745
55.80000,46.49993,19.47922
56.10000,46.74986,19.61946
56.40000,46.99993,19.62617
56.70000,47.24999,19.58423
57.00000,47.49993,19.94247
57.30000,47.74987,19.90949
57.60000,47.99987,19.90621
57.90000,48.24993,20.00661
58.20000,48.49993,20.09603
58.50000,48.74987,20.04830
58.80000,48.99993,20.14528
59.10000,49.24993,20.20011
59.40000,49.49993,20.45006
59.70000,49.74987,20.41977
60.00000,49.99993,20.44315
60.30000,50.24993,20.60989
60.60000,50.49987,20.70412
60.90000,50.74993,20.57353
61.20000,50.99993,20.78742
61.50000,51.24987,20.70574
61.80000,51.49987,21.08299
62.10000,51.74993,20.71211
62.40000,51.99993,21.08539
62.70000,52.24993,21.00091
63.00000,52.49986,21.15110
63.30000,52.74993,21.19622
63.60000,52.99993,21.40482
63.90000,53.24987,21.37155
64.20000,53.49993,21.34014
64.50000,53.74987,21.51355
64.80000,53.99993,21.46548
65.10001,54.24987,21.65305
65.40000,54.49993,21.62017
65.70001,54.74993,21.76472
66.00000,54.99987,21.89947
66.30000,55.24993,21.87218
66.60001,55.49993,22.04426
66.90000,55.74987,21.91946
67.20001,55.99993,22.06563
67.50000,56.24993,22.31381
67.80000,56.49993,22.22787
68.10001,56.74987,22.21964
68.40000,56.99993,22.43269
68.70001,57.24993,22.59556
69.00000,57.49993,22.44793
69.30000,57.74993,22.63261
69.60001,57.99993,22.93542
69.90000,58.24987,22.75383
70.20001,58.49993,22.93645
70.50000,58.74987,23.19542
70.80000,58.99999,23.09673
71.10001,59.24993,23.09776
71.40000,59.49987,23.24540
71.70001,59.74993,23.35878
72.00000,59.99993,23.19493
72.30000,60.24987,23.37858
72.60001,60.49987,23.58805
72.90000,60.74993,23.56953
73.20001,60.99993,23.51950
73.50000,61.24993,23.69394
73.80000,61.49993,23.70732
74.10001,61.74993,23.78023
74.40000,61.99987,23.92360
74.70001,62.24993,23.98397
75.00000,62.49993,24.03038
75.30000,62.74993,24.00769
75.60001,62.99987,24.10701
75.90000,63.24993,24.34187
76.20001,63.49993,24.32408
76.50000,63.74992,24.37073
76.80000,63.99993,24.46153
77.10001,64.24987,24.61862
77.40000,64.49993,24.65816
77.70001,64.74993,24.84480
78.00000,64.99992,24.86930
78.30000,65.24986,24.92982
78.60001,65.49993,24.94246
78.90000,65.74993,25.12194
79.20001,65.99993,25.19427
79.50000,66.24986,25.19216
79.80000,66.49987,25.50978
80.10001,66.74992,25.23185
80.40000,66.99993,25.42065
80.70001,67.24987,25.37410
81.00001,67.49986,25.50017
81.30000,67.74993,25.54947
81.60001,67.99993,25.81818
81.90000,68.24993,25.76791
82.20001,68.49987,25.97278
82.50001,68.74993,25.98576
82.80000,68.99992,25.97013
83.10001,69.24993,26.07852
83.40000,69.49992,26.24816
83.70001,69.74999,26.33224
84.00001,69.99987,26.47870
84.30000,70.24986,26.42769
84.60001,70.49993,26.59213
84.90000,70.74993,26.61566
85.20001,70.99986,26.69518
85.50001,71.24986,26.66426
85.80000,71.49993,26.89618
86.10001,71.74992,26.92578
86.40000,71.99986,27.08017
86.70001,72.24993,27.23433
87.00001,72.49986,27.19557
87.30000,72.74993,27.29994
87.60001,72.99987,27.31988
87.90000,73.24993,27.43199
88.20001,73.49993,27.29592
88.50001,73.74987,27.57155
88.80000,73.99999,27.61324
89.10001,74.24999,27.74437
89.40000,74.49993,27.89563
89.70001,74.74986,27.86599
90.00001,74.99986,27.95350
90.30000,75.24999,28.01357
90.60001,75.49986,27.97001
90.90000,75.74980,28.18737
91.20001,75.99992,28.18502
91.50001,76.24993,28.18679
91.80000,76.49987,28.42728
92.10001,76.74993,28.56340
92.40000,76.99993,28.61039
92.70001,77.24986,28.72711
93.00001,77.49987,28.67737
93.30000,77.74992,28.78419
93.60001,77.99986,29.14890
93.90000,78.24986,29.11205
94.20001,78.49992,29.11607
94.50001,78.74993,29.15806
94.80000,78.99993,29.26924
95.10001,79.24986,29.40605
95.40000,79.49992,29.33765
95.70001,79.74993,29.54741
96.00001,79.99986,29.68839
96.30000,80.24992,29.67844
96.60001,80.49986,29.78261
96.90000,80.74986,29.96337
97.20001,80.99986,30.00978
97.50001,81.24992,30.14286
97.80000,81.49993,30.02732
98.10001,81.74987,30.16741
98.40000,81.99993,30.39404
98.70001,82.24992,30.40824
99.00001,82.49993,30.37571
99.30000,82.74986,30.55740
99.60001,82.99992,30.58503
99.90000,83.24993,30.63624
100.20001,83.49992,30.81411
100.50001,83.74993,30.72106
100.80000,83.99999,30.77138
101.10001,84.24980,30.93661
101.40000,84.49992,30.99918
101.70001,84.74993,31.25408
102.00001,84.99992,31.20841
102.30000,85.24986,31.41490
102.60001,85.49985,31.34542
102.90000,85.74992,31.50555
103.20001,85.99993,31.66186
103.50001,86.24987,31.74040
103.80000,86.49986,31.75074
104.10001,86.74992,31.88383
104.40000,86.99986,31.74320
104.70001,87.24992,31.97399
105.00001,87.49986,31.95066
105.30000,87.74993,32.06135
105.60001,87.99986,32.46075
105.90000,88.24993,32.21173
106.20001,88.49992,32.48290
106.50001,88.74992,32.50838
106.80000,88.99992,32.36358
107.10001,89.24992,32.90655
107.40000,89.49992,32.74960
107.70001,89.74986,32.50828
108.00001,89.99986,32.86931
108.30000,90.24998,33.09971
108.60001,90.49992,33.14900
108.90000,90.74987,33.18840
109.20001,90.99992,33.12612
109.50001,91.24986,33.56001
109.80000,91.49992,33.31109
110.10001,91.74992,33.38601
110.40000,91.99993,33.70853
110.70001,92.24992,33.57270
111.00001,92.49986,33.64699
111.30000,92.74987,33.89189
111.60001,92.99993,33.91012
111.90000,93.24992,33.90639
112.20001,93.49986,34.13385
112.50001,93.74992,34.39115
112.80000,93.99992,34.13238
113.10001,94.24986,34.30702
113.40001,94.49986,34.38306
113.70001,94.74985,34.46225
114.00001,94.99992,34.55848
114.30000,95.24986,34.45975
114.60001,95.49987,34.67505
114.90001,95.74993,34.76751
115.20001,95.99986,34.98213
115.50001,96.24992,34.93789
115.80000,96.49992,35.00678
116.10001,96.74992,35.12046
116.40001,96.99985,35.15084
116.70001,97.24992,35.28858
117.00001,97.49998,35.55475
117.30000,97.74992,35.46611
117.60001,97.99986,35.62952
117.90001,98.24986,35.60492
118.20001,98.49992,35.57489
118.50001,98.74992,35.81445
118.80000,98.99992,35.93597
119.10001,99.24993,35.95277
119.40001,99.49986,35.97781
119.70001,99.74992,36.24932
120.00001,99.99992,36.20493
120.30000,100.24992,36.23834
120.60001,100.49986,36.42837
120.90001,100.74992,36.56062
121.20001,100.99999,36.57978
121.50001,101.24986,36.62966
121.80000,101.49992,36.78778
122.10001,101.74992,36.80473
122.40001,101.99992,36.79974
122.70001,102.24992,36.96957
123.00001,102.49986,36.99872
123.30000,102.74992,36.94203
123.60001,102.99986,37.14146
123.90001,103.24986,37.29625
124.20001,103.49993,37.46452
124.50001,103.74992,37.44188
124.80000,103.99993,37.43041
125.10001,104.24986,37.71726
125.40001,104.49992,37.65076
125.70001,104.74992,37.82192
126.00001,104.99986,37.90174
126.30000,105.24992,37.92257
126.60001,105.49992,38.00758
126.90001,105.74993,38.07452
127.20001,105.99986,38.16223
127.50001,106.24993,38.20941
127.80000,106.49992,38.26953
128.10001,106.74986,38.55133
128.40001,106.99992,38.67476
128.70002,107.24992,38.54026
129.00000,107.49985,38.84083
129.30000,107.74992,38.80187
129.60001,107.99993,38.94157
129.90001,108.24992,39.18353
130.20002,108.49986,39.02061
130.50000,108.74987,39.14110
130.80000,108.99998,39.04172
131.10000,109.24992,39.27834
131.40002,109.49992,39.31010
131.70002,109.74992,39.36532
132.00000,109.99992,39.28256
132.30000,110.24993,39.53163
132.60000,110.49986,39.65427
132.90002,110.74992,39.59586
133.20002,110.99992,39.77265
133.50000,111.24986,39.89305
133.80000,111.49992,39.87315
134.10000,111.74992,40.05602
134.40002,111.99992,40.12359
134.70002,112.24986,40.06748
135.00000,112.49992,40.29470
135.30000,112.74992,40.41338
135.60000,112.99986,40.52083
135.90002,113.24992,40.45708
136.20002,113.49992,40.60600
136.50000,113.74992,40.58649
136.80000,113.99992,40.94350
137.10000,114.24992,40.91327
137.40002,114.49993,41.04445
137.70002,114.74986,41.12652
138.00000,114.99986,41.05376
138.30000,115.24992,41.27225
138.60000,115.49986,41.13608
138.90002,115.74992,41.25294
139.20002,115.99992,41.51803
139.50000,116.24992,41.75024
139.80000,116.49986,41.87215
140.10000,116.74993,41.51431
140.40002,116.99986,41.90915
140.70002,117.24986,41.82982
141.00000,117.49987,41.91439
141.30000,117.74993,42.11543
141.60000,117.99992,42.00210
141.90002,118.24986,42.14802
142.20002,118.49998,42.53360
142.50000,118.74992,42.53233
142.80000,118.99998,42.55697
143.10000,119.24992,42.44702
143.40002,119.49986,42.51665
143.70002,119.74992,42.63116
144.00000,119.99986,42.73519
144.30000,120.24986,42.80859
144.60000,120.49986,43.03183
144.90002,120.74992,43.04021
145.20002,120.99992,42.83559
145.50000,121.24985,43.05697
145.80000,121.49992,43.09813
146.10000,121.74986,43.43735
146.40002,121.99992,43.33984
146.70002,122.24992,43.41790
147.00000,122.49992,43.51806
147.30000,122.74992,43.52075
147.60000,122.99986,43.62541
147.90002,123.24998,43.81852
148.20002,123.49992,43.85076
148.50000,123.74992,43.81156
148.80000,123.99992,43.82994
149.10000,124.24992,44.10493
149.40002,124.49986,44.15378
149.70002,124.74986,44.11943
150.00000,124.99986,44.45028
150.30000,125.24992,44.21106
150.60000,125.49986,44.44043
150.90002,125.74992,44.48129
151.20002,125.99992,44.52843
151.50000,126.24991,44.82532
151.80000,126.49992,44.67842
152.10000,126.74992,44.75496
152.40002,126.99998,44.78132
152.70002,127.24985,44.97992
153.00000,127.49985,45.11094
153.30000,127.74998,45.42008
153.60000,127.99992,45.32640
153.90002,128.24985,45.31028
154.20002,128.49991,45.60511
154.50000,128.74993,45.51196
154.80000,128.99992,45.48618
155.10000,129.24986,45.73981
155.40002,129.49991,45.75465
155.70002,129.74985,45.68449
156.00000,129.99984,45.58408
156.30000,130.24992,45.89489
156.60000,130.49992,45.81919
156.90002,130.74986,46.21638
157.20002,130.99991,46.33898
157.50000,131.24992,46.28963
157.80000,131.49992,46.24681
158.10000,131.74991,46.39278
158.40002,131.99985,46.54296
158.70002,132.24992,46.41267
159.00000,132.49992,46.67727
159.30000,132.74992,46.60921
159.60000,132.99986,46.81589
159.90002,133.24991,46.62587
160.20002,133.49992,46.93001
160.50000,133.74992,46.83598
160.80000,133.99991,46.96122
161.10000,134.24985,47.15963
161.40002,134.49985,47.21211
161.70002,134.74998,47.44598
162.00002,134.99985,47.33152
162.30000,135.24991,47.21127
162.60000,135.49991,47.44079
162.90002,135.74985,47.58323
163.20002,135.99992,47.64933
163.50002,136.24991,47.81623
163.80000,136.49992,47.82460
164.10000,136.74991,47.82803
164.40002,136.99985,47.97293
164.70002,137.24992,48.08861
165.00002,137.49992,48.11723
165.30000,137.74991,48.32220
165.60000,137.99985,48.26800
165.90002,138.24992,48.30397
166.20002,138.49998,48.23400
166.50002,138.74992,48.55117
166.80000,138.99991,48.79505
167.10000,139.24985,48.60870
167.40002,139.49998,48.87702
167.70002,139.74986,48.73571
168.00002,139.99986,48.93175
168.30000,140.24991,49.04823
168.60000,140.49992,49.01834
168.90002,140.74991,49.04818
169.20002,140.99997,49.09169
169.50002,141.24991,49.10668
169.80000,141.49985,49.25785
170.10000,141.74986,49.44880
170.40002,141.99992,49.47183
170.70002,142.24991,49.76073
171.00002,142.49985,49.61991
171.30000,142.74985,49.61079
171.60000,142.99992,49.62495
171.90002,143.24998,49.72403
172.20002,143.49985,50.06644
172.50002,143.74991,50.14180
172.80000,143.99992,50.13734
173.10000,144.24986,50.20815
173.40002,144.49986,50.19762
173.70002,144.74991,50.43237
174.00002,144.99985,50.64979
174.30000,145.24992,50.58717
174.60000,145.49998,50.59050
174.90002,145.74992,50.81095
175.20002,145.99991,50.80129
175.50002,146.24985,50.87308
175.80000,146.49997,50.72784
176.10000,146.74991,50.97559
176.40002,146.99985,51.01342
176.70002,147.24985,50.96696
177.00002,147.49992,51.20941
177.30000,147.74992,51.18496
177.60000,147.99992,51.14743
177.90002,148.24991,51.26787
178.20002,148.49992,51.36989
178.50002,148.74986,51.60940
178.80000,148.99998,51.65713
179.10000,149.24991,51.72127
179.40002,149.49985,51.53561
179.70002,149.74984,51.81990
180.00002,149.99986,51.84960
180.30000,150.24992,51.72911
180.60000,150.49986,51.77291
180.90002,150.74993,51.83867
181.20002,150.99998,52.00532
181.50002,151.24986,52.00517
181.80000,151.49985,52.04682
182.10000,151.74999,52.08342
182.40002,151.99984,52.28158
182.70002,152.24992,52.57431
183.00002,152.49992,52.42813
183.30000,152.74991,52.82185
183.60000,152.99985,52.67593
183.90002,153.24985,52.77707
184.20002,153.49992,52.73581
184.50002,153.74991,52.98532
184.80000,153.99992,52.86791
185.10000,154.24985,53.29274
185.40002,154.49992,52.97351
185.70002,154.74992,53.16417
186.00002,154.99986,53.03858
186.30000,155.24991,53.35624
186.60000,155.49992,53.30773
186.90002,155.74992,53.17906
187.20002,155.99991,53.77299
187.50002,156.24985,53.53451
187.80000,156.49999,53.61109
188.10000,156.74986,53.80699
188.40002,156.99992,53.88740
188.70002,157.24991,54.15063
189.00002,157.49991,54.03940
189.30000,157.74984,54.12059
189.60000,157.99992,54.08453
189.90002,158.24998,54.13113
190.20002,158.49985,54.37436
190.50002,158.74991,54.19453
190.80000,158.99997,54.25814
191.10000,159.24985,54.35476
191.40002,159.49985,54.50877
191.70002,159.74991,54.40901
192.00002,159.99991,54.69090
192.30000,160.24992,54.75504
192.60000,160.49985,54.70472
192.90002,160.74991,54.87867
193.20002,160.99991,54.97696
193.50002,161.24984,55.02376
193.80000,161.49985,55.04032
194.10000,161.74991,54.96138
194.40002,161.99986,54.78714
194.70002,162.24990,54.97329
195.00002,162.49992,55.22838
195.30000,162.74991,55.42169
195.60000,162.99985,55.23225
195.90002,163.24991,55.69123
196.20002,163.49992,55.58074
196.50002,163.74985,55.67457
196.80000,163.99991,55.81962
197.10000,164.24997,55.67031
197.40002,164.49990,55.78080
197.70002,164.74985,55.75410
198.00002,164.99985,55.96323
198.30000,165.24991,56.15458
198.60000,165.49991,56.08975
198.90002,165.74990,56.28399
199.20002,165.99992,56.16482
199.50002,166.24985,56.41481
199.80000,166.49991,56.24322
200.10000,166.74984,56.27105
200.40002,166.99985,56.32814
200.70002,167.24991,56.67897
201.00002,167.49986,56.53315
201.30000,167.74997,56.63992
201.60000,167.99990,56.67344
201.90002,168.24985,56.74551
202.20002,168.49991,56.78148
202.50002,168.74991,56.86865
202.80000,168.99997,56.73650
203.10000,169.24985,57.12325
203.40002,169.49991,57.28427
203.70002,169.74991,57.10086
204.00002,169.99984,57.10606
204.30000,170.24985,57.38962
204.60000,170.49985,57.28730
204.90002,170.74991,57.19229
205.20002,170.99986,57.33385
205.50002,171.24984,57.68607
205.80000,171.49990,57.65652
206.10000,171.74983,57.79323
206.40002,171.99986,57.74644
206.70002,172.24992,57.65294
207.00002,172.49998,57.75118
207.30000,172.74993,57.93122
207.60000,172.99986,57.94077
207.90002,173.24992,58.05288
208.20002,173.49990,58.07870
208.50002,173.74985,58.11712
208.80000,173.99991,58.12574
209.10000,174.24986,58.50671
209.40002,174.49992,58.58992
209.70002,174.74990,58.48021
210.00002,174.99991,58.56444
210.30000,175.24991,58.84751
210.60000,175.49979,58.76847
210.90002,175.74990,58.79003
211.20002,175.99998,58.56963
211.50002,176.24991,58.67528
211.80000,176.49986,58.85241
212.10000,176.74984,58.75348
212.40002,176.99996,58.79361
212.70002,177.24991,59.01225
213.00002,177.49984,59.19501
213.30000,177.74992,59.04625
213.60000,177.99990,59.23829
213.90002,178.24985,59.34354
214.20002,178.49991,59.53262
214.50002,178.74992,59.41179
214.80000,178.99984,59.60593
215.10000,179.24991,59.68109
215.40002,179.49991,59.58104
215.70002,179.74991,59.73647
216.00002,179.99986,59.59250
216.30000,180.24990,59.66625
216.60000,180.49991,59.71358
216.90002,180.74984,59.51116
217.20002,180.99992,59.86421
217.50002,181.24985,59.79899
217.80000,181.49985,60.09950
218.10000,181.74985,59.92947
218.40002,181.99991,60.17477
218.70002,182.24992,60.12268
219.00002,182.49985,60.28693
219.30000,182.74991,60.38846
219.60000,182.99984,60.50895
219.90002,183.24992,60.57426
220.20002,183.49992,60.73493
220.50002,183.74985,60.78722
220.80000,183.99991,60.72989
221.10000,184.24990,60.58480
221.40002,184.49992,60.77517
221.70002,184.74991,60.67079
222.00002,184.99985,60.89369
222.30000,185.24984,60.98268
222.60000,185.49992,60.94828
222.90002,185.74992,60.91521
223.20002,185.99985,61.09361
223.50002,186.24986,60.81172
223.80000,186.49997,61.16667
224.10000,186.74992,61.04594
224.40002,186.99985,61.14624
224.70002,187.24985,61.37374
225.00002,187.49991,61.45602
225.30002,187.74997,61.56328
225.60000,187.99985,61.57048
225.90002,188.24985,61.51001
226.20002,188.49991,61.67265
226.50002,188.74984,61.68783
226.80002,188.99985,61.81318
227.10000,189.24991,61.91407
227.40002,189.49991,62.04171
227.70002,189.74984,62.17445
228.00002,189.99990,61.99207
228.30002,190.24998,62.22664
228.60000,190.49991,62.04848
228.90002,190.74984,61.97071
229.20002,190.99990,62.11016
229.50002,191.24992,62.18499
229.80002,191.49985,62.29210
230.10000,191.74978,62.59786
230.40002,191.99997,62.40995
230.70002,192.24990,62.53622
231.00002,192.49983,62.32057
231.30002,192.74991,62.63005
231.60000,192.99991,62.70056
231.90002,193.24990,62.61143
232.20002,193.49985,62.79562
232.50002,193.74983,62.67371
232.80002,193.99991,63.00299
233.10000,194.24984,63.08408
233.40002,194.49979,63.01152
233.70002,194.74998,63.24142
234.00002,194.99991,63.05459
234.30002,195.24992,63.15053
234.60000,195.49990,63.28234
234.90002,195.74990,63.13872
235.20002,195.99991,63.17145
235.50002,196.24986,63.38171
235.80002,196.49990,63.25039
236.10000,196.74990,63.27018
236.40002,196.99983,63.38617
236.70002,197.24991,63.55699
237.00002,197.49992,63.63548
237.30002,197.74990,63.57227
237.60000,197.99985,63.71584
237.90002,198.24991,63.80311
238.20002,198.49991,63.75935
238.50002,198.74984,63.73377
238.80002,198.99990,63.88553
239.10000,199.24991,64.03007
239.40002,199.49991,64.11063
239.70002,199.74984,64.24377
240.00002,199.99985,64.31477
240.30002,200.24991,64.19629
240.60000,200.49991,64.28884
240.90002,200.74992,64.27013
241.20002,200.99990,64.35206
241.50002,201.24985,64.32672
241.80002,201.49991,64.45221
242.10000,201.74991,64.69393
242.40002,201.99992,64.61111
242.70002,202.24985,64.70775
243.00002,202.49985,65.07701
243.30002,202.74997,64.64135
243.60000,202.99979,64.74293
243.90002,203.24990,64.99282
244.20002,203.49991,64.83578
244.50002,203.74991,64.92883
244.80002,203.99991,64.84617
245.10000,204.24992,64.84886
245.40002,204.49990,65.02820
245.70002,204.74991,65.09636
246.00002,204.99984,65.16036
246.30002,205.24992,65.27095
246.60000,205.49990,65.28830
246.90002,205.74985,65.48038
247.20002,205.99984,65.54158
247.50002,206.24990,65.60375
247.80002,206.49992,65.47690
248.10000,206.74985,65.59876
248.40002,206.99991,65.59528
248.70002,207.24984,65.51335
249.00002,207.49992,65.68314
249.30002,207.74985,65.59812
249.60000,207.99991,65.77962
249.90002,208.24984,65.90790
250.20002,208.49984,65.78819
250.50002,208.74992,66.08738
250.80002,208.99996,65.87629
251.10000,209.24985,65.94235
251.40002,209.49984,66.23816
251.70002,209.74990,66.20969
252.00002,209.99990,66.25296
252.30002,210.24985,66.22649
252.60000,210.49984,66.26031
252.90002,210.74984,66.13095
253.20002,210.99992,66.45782
253.50002,211.24985,66.32312
253.80002,211.49985,66.37060
254.10000,211.74990,66.48742
254.40002,211.99990,66.68680
254.70002,212.24990,66.66696
255.00002,212.49996,66.76745
255.30002,212.74991,66.85389
255.60000,212.99990,66.86565
255.90002,213.24985,66.73482
256.20002,213.49991,66.73904
256.50000,213.74991,66.95238
256.80002,213.99984,67.20576
257.10000,214.24990,67.11173
257.40003,214.49991,67.28680
257.70002,214.74991,67.36589
258.00000,214.99984,67.36584
258.30002,215.24990,67.42420
258.60000,215.49990,67.29048
258.90003,215.74983,67.51788
259.20002,215.99991,67.39735
259.50000,216.24984,67.50235
259.80002,216.49985,67.54268
260.10000,216.74983,67.48236
260.40003,216.99991,67.70379
260.70002,217.24992,67.81610
261.00000,217.49990,67.85314
261.30002,217.74998,67.70051
261.60000,217.99991,67.84104
261.90003,218.24991,67.89950
262.20000,218.49990,67.92360
262.50000,218.74985,67.74466
262.80003,218.99998,67.78542
263.10000,219.24986,68.04552
263.40003,219.49984,68.12950
263.70000,219.74990,68.00847
264.00000,219.99985,68.36200
264.30003,220.24991,68.28199
264.60000,220.49991,68.31659
264.90003,220.74990,68.31521
265.20000,220.99990,68.63151
265.50000,221.24978,68.57065
265.80003,221.49997,68.67526
266.10000,221.74992,68.47819
266.40003,221.99985,68.80506
266.70000,222.24991,68.95589
267.00000,222.49991,68.75361
267.30003,222.74991,68.87214
267.60000,222.99984,68.90512
267.90003,223.24996,69.01429
268.20000,223.49991,69.11964
268.50000,223.74984,69.02762
268.80003,223.99992,68.95711
269.10000,224.24990,68.95089
269.40003,224.49985,69.01978
269.70000,224.74984,69.24964
270.00000,224.99992,69.13625
270.30003,225.24990,69.00062
270.60000,225.49985,69.05521
270.90003,225.74984,69.40257
271.20000,225.99991,69.15468
271.50000,226.24992,69.43162
271.80003,226.49985,69.42256
272.10000,226.74991,69.62856
272.40003,226.99989,69.74081
272.70000,227.24984,69.67104
273.00000,227.49990,69.90016
273.30003,227.74991,69.76923
273.60000,227.99991,69.94058
273.90003,228.24984,70.15849
274.20000,228.49992,70.12061
274.50000,228.74990,70.25634
274.80003,228.99991,70.41089
275.10000,229.24984,70.51001
275.40003,229.49997,70.47008
275.70000,229.74990,70.36987
276.00000,229.99991,70.79588
276.30003,230.24991,70.83733
276.60000,230.49990,70.78662
276.90003,230.74985,71.10203
277.20000,230.99991,70.91166
277.50000,231.24991,70.92637
277.80003,231.49990,71.04877
278.10000,231.74984,71.02388
278.40003,231.99990,71.44214
278.70000,232.24996,71.34316
279.00000,232.49984,71.36702
279.30003,232.74990,71.45703
279.60000,232.99992,71.41078
279.90003,233.24991,71.56733
280.20000,233.49985,71.56743
280.50000,233.74984,71.38505
280.80003,233.99990,71.54910
281.10000,234.24983,71.50329
281.40003,234.49991,71.71399
281.70000,234.74991,71.65068
282.00000,234.99990,71.94742
282.30003,235.24992,71.90597
282.60000,235.49985,71.84055
282.90003,235.74991,71.92194
283.20000,235.99990,71.96629
283.50000,236.24985,72.00221
283.80003,236.49991,72.19600
284.10000,236.74991,72.33687
284.40003,236.99984,72.22893
284.70000,237.24990,72.35736
285.00000,237.49990,72.27322
285.30003,237.74991,72.73637
285.60000,237.99986,72.69085
285.90003,238.24990,72.62544
286.20000,238.49990,72.75587
286.50000,238.74983,72.88107
286.80003,238.99991,72.90135
287.10000,239.24997,72.78968
287.40003,239.49990,72.76798
287.70000,239.74990,73.00749
288.00000,239.99983,73.10612
288.30003,240.24997,73.02664
288.60000,240.49990,73.28669
288.90003,240.74985,73.31731
289.20000,240.99983,73.49582
289.50000,241.24991,73.67976
289.80003,241.49992,73.47338
290.10000,241.74985,73.35034
290.40003,241.99991,73.58122
290.70000,242.24991,73.71073
291.00000,242.49991,73.64385
291.30003,242.74990,74.02418
291.60000,242.99990,73.84931
291.90003,243.24983,73.85474
292.20000,243.49984,73.86690
292.50000,243.74992,74.17069
292.80003,243.99996,74.01639
293.10000,244.24985,74.01184
293.40003,244.49984,73.98145
293.70000,244.74997,74.20617
294.00000,244.99990,74.35920
294.30003,245.24985,74.41192
294.60000,245.49983,74.41873
294.90003,245.74991,74.44284
295.20000,245.99992,74.62370
295.50000,246.24985,74.46724
295.80003,246.49991,74.74389
296.10000,246.74984,74.50512
296.40003,246.99984,74.94352
296.70000,247.24998,74.90113
297.00000,247.49991,75.21214
297.30003,247.74991,75.02290
297.60000,247.99984,74.92451
297.90003,248.24992,75.31979
298.20000,248.49990,75.41671
298.50000,248.74985,75.24737
298.80003,248.99989,75.33008
299.10000,249.24992,75.34797
299.40003,249.49985,75.26226
299.70000,249.74991,75.34380
300.00000,249.99991,75.26893
300.30003,250.24990,75.18548
300.60000,250.49984,75.15745
300.90003,250.74989,75.19998
301.20000,250.99991,75.24281
301.50000,251.24982,74.82166
301.80003,251.49990,74.61022
302.10000,251.74985,38.11171
302.40003,251.99989,0.16284
302.70000,252.24989,-0.00106
303.00000,252.49988,0.12007
303.30003,252.74990,0.07249
303.60000,252.99985,-0.08142
303.90003,253.24984,0.08542
304.20000,253.49995,0.21782
304.50000,253.74992,0.02221
304.80003,253.99983,-0.02987
305.10000,254.24991,0.18617
305.40003,254.49989,0.20057
305.70000,254.74990,0.04985
306.00000,254.99983,0.21439
306.30003,255.24983,0.29372
306.60000,255.49991,0.18318
306.90003,255.74982,0.20185
307.13203,255.94328,0.00771