File: V_7/EPR/RDSO EPR Tensile 50.is_tens_RawData/Specimen_RawData_11.csv
Time,Extension,Load
(sec),(mm),(N)
0.00000,0.00000,3.08583
0.30000,0.24937,3.77124
0.60000,0.49987,4.11669
0.90000,0.74987,4.50340
1.20000,0.99994,4.71900
1.50000,1.24994,5.00785
1.80000,1.49994,5.36457
2.10000,1.74994,5.36001
2.40000,2.00000,5.59791
2.70000,2.24987,5.89945
3.00000,2.49994,6.12755
3.30000,2.75000,6.10079
3.60000,2.99994,6.47143
3.90000,3.24987,6.77640
4.20000,3.49994,6.87264
4.50000,3.74994,7.23342
4.80000,3.99994,7.14155
5.10000,4.24987,7.57040
5.40000,4.49994,7.57897
5.70000,4.74994,7.77531
6.00000,4.99994,7.83896
6.30000,5.24994,7.81481
6.60000,5.49994,8.02781
6.90000,5.74987,8.29074
7.20000,5.99987,8.28276
7.50000,6.24987,8.34993
7.80000,6.49994,8.46763
8.10000,6.74987,8.77956
8.40000,6.99987,9.04323
8.70000,7.25000,9.17583
9.00000,7.49994,9.26207
9.30000,7.74994,9.33400
9.60000,7.99987,9.43205
9.90000,8.25000,9.71875
10.20000,8.49987,9.73624
10.50000,8.74987,9.88544
10.80000,8.99994,9.96345
11.10000,9.24987,10.10134
11.40000,9.49994,10.23648
11.70000,9.74994,10.23432
12.00000,9.99994,10.36510
12.30000,10.24994,10.57409
12.60000,10.49987,10.41513
12.90000,10.75000,10.54248
13.20000,10.99994,10.67655
13.50000,11.24987,10.71236
13.80000,11.49994,11.18546
14.10000,11.74994,10.97838
14.40000,11.99994,11.45589
14.70000,12.24994,11.22745
15.00000,12.50000,11.48416
15.30000,12.74994,11.66781
15.60000,12.99987,11.43330
15.90000,13.24994,11.49764
16.20000,13.49994,11.74798
16.50000,13.74987,11.74881
16.80000,13.99994,11.68658
17.10000,14.24987,11.94329
17.40000,14.49994,11.97269
17.70000,14.74994,12.17511
18.00000,14.99994,12.11307
18.30000,15.24994,12.33534
18.60000,15.49987,12.30138
18.90000,15.74987,12.34950
19.20000,15.99994,12.43833
19.50000,16.24993,12.54236
19.80000,16.49993,12.60905
20.10000,16.74994,12.71905
20.40000,16.99987,12.63100
20.70000,17.24993,12.67015
21.00000,17.49987,12.71714
21.30000,17.74994,12.91574
21.60000,17.99993,13.07822
21.90000,18.24994,12.81323
22.20000,18.49987,12.99963
22.50000,18.74994,13.00659
22.80000,19.00000,13.31528
23.10000,19.24993,13.26746
23.40000,19.49994,13.34385
23.70000,19.74993,13.49854
24.00000,19.99993,13.39599
24.30000,20.24994,13.50535
24.60000,20.49993,13.26119
24.90000,20.74993,13.46714
25.20000,20.99987,13.43577
25.50000,21.24993,13.66426
25.80000,21.50000,13.58983
26.10000,21.74993,13.69528
26.40000,21.99987,13.58586
26.70000,22.25000,14.00192
27.00000,22.49993,13.92475
27.30000,22.74987,14.11374
27.60000,22.99987,13.80063
27.90000,23.24993,14.00643
28.20000,23.49993,14.07174
28.50000,23.74987,14.29710
28.80000,23.99993,14.44963
29.10000,24.24994,14.18768
29.40000,24.49993,14.38676
29.70000,24.74993,14.37843
30.00000,24.99993,14.44086
30.30000,25.25000,14.53945
30.60000,25.49981,14.53964
30.90000,25.74987,14.53739
31.20000,25.99993,14.73706
31.50000,26.24987,14.60271
31.80000,26.49987,14.62956
32.10000,26.74993,14.67699
32.40000,26.99994,14.90009
32.70000,27.24993,14.73525
33.00000,27.49987,14.92028
33.30000,27.74993,15.15396
33.60000,27.99987,14.90925
33.90000,28.24993,15.09383
34.20000,28.49993,15.18840
34.50000,28.74993,15.18581
34.80000,28.99993,15.32394
35.10000,29.24993,15.20149
35.40000,29.50000,15.28336
35.70000,29.74994,15.33766
36.00000,29.99993,15.36049
36.30000,30.24993,15.62514
36.60000,30.49993,15.42350
36.90000,30.74993,15.76822
37.20000,30.99987,15.86465
37.50000,31.24987,15.66243
37.80000,31.49987,15.70540
38.10000,31.74987,15.77086
38.40000,31.99993,15.66483
38.70000,32.24993,15.97794
39.00000,32.49993,16.05452
39.30000,32.74987,15.93021
39.60000,33.00000,16.03625
39.90000,33.24987,16.16948
40.20000,33.49987,16.38116
40.50000,33.74993,16.32623
40.80000,33.99987,16.35979
41.10000,34.24993,16.35146
41.40000,34.49993,16.48151
41.70000,34.74993,16.41943
42.00000,34.99993,16.49841
42.30000,35.24993,16.68177
42.60000,35.49993,16.57652
42.90000,35.74993,16.65012
43.20000,35.99987,16.93348
43.50000,36.24987,16.83901
43.80000,36.49993,16.77923
44.10000,36.74993,16.79222
44.40000,36.99993,17.14090
44.70000,37.24993,17.07514
45.00000,37.49987,17.05922
45.30000,37.74999,17.18902
45.60000,37.99987,17.14325
45.90000,38.24987,17.29074
46.20000,38.49993,17.37816
46.50000,38.74993,17.40163
46.80000,38.99993,17.38462
47.10000,39.24993,17.24958
47.40000,39.49993,17.47483
47.70000,39.74987,17.65432
48.00000,39.99987,17.47273
48.30000,40.25000,17.82131
48.60000,40.49993,17.83910
48.90000,40.74987,17.94499
49.20000,40.99993,18.13163
49.50000,41.24993,18.13143
49.80000,41.49993,18.06959
50.10000,41.74987,18.10399
50.40000,41.99987,18.13001
50.70000,42.24999,18.25486
51.00000,42.49987,18.42945
51.30000,42.74993,18.50770
51.60000,42.99993,18.67028
51.90000,43.24987,18.65774
52.20000,43.49993,18.52186
52.50000,43.74993,18.59948
52.80000,43.99993,18.81518
53.10000,44.24987,18.78391
53.40000,44.49993,18.81630
53.70000,44.74993,18.88221
54.00000,44.99987,18.80160
54.30000,45.24993,18.99221
54.60000,45.49987,19.04694
54.90000,45.74993,19.03945
55.20000,45.99987,19.38989
55.50000,46.24987,19.28655
55.80000,46.49993,19.45252
56.10000,46.74986,19.42596
56.40000,46.99993,19.61098
56.70000,47.24993,19.48819
57.00000,47.49993,19.53802
57.30000,47.74993,19.68105
57.60000,47.99987,19.75676
57.90000,48.24993,19.98250
58.20000,48.49993,20.04189
58.50000,48.74987,19.93756
58.80000,48.99993,20.05374
59.10000,49.24993,20.04184
59.40000,49.49987,20.25043
59.70000,49.74993,20.27733
60.00000,49.99993,20.15125
60.30000,50.24993,20.45383
60.60000,50.49987,20.44207
60.90000,50.74993,20.60156
61.20000,50.99993,20.72132
61.50000,51.24987,20.91918
61.80000,51.49987,20.79869
62.10000,51.74993,20.87136
62.40000,51.99993,20.70681
62.70000,52.24993,21.11474
63.00000,52.49986,21.02291
63.30000,52.74993,21.13576
63.60000,52.99993,21.06358
63.90000,53.24987,21.27654
64.20000,53.49993,21.23444
64.50000,53.74993,21.37297
64.80000,53.99993,21.52144
65.10001,54.24987,21.67799
65.40000,54.49993,21.69568
65.70001,54.74993,21.43652
66.00000,54.99980,21.84910
66.30000,55.24993,21.97738
66.60001,55.49993,22.07190
66.90000,55.74987,21.93989
67.20001,55.99987,22.06043
67.50000,56.24993,21.99649
67.80000,56.49993,22.24521
68.10001,56.74987,22.25516
68.40000,56.99993,22.24296
68.70001,57.24993,22.32288
69.00000,57.49993,22.57866
69.30000,57.74993,22.36384
69.60001,57.99993,22.41568
69.90000,58.24987,22.73095
70.20001,58.49993,22.77627
70.50000,58.74987,22.90039
70.80000,58.99999,22.94317
71.10001,59.24993,22.89941
71.40000,59.49987,23.01255
71.70001,59.74993,23.18356
72.00000,59.99993,23.28950
72.30000,60.24987,23.33326
72.60001,60.49987,23.46707
72.90000,60.74993,23.23080
73.20001,60.99993,23.63103
73.50000,61.24993,23.69821
73.80000,61.49993,23.72325
74.10001,61.74993,23.82634
74.40000,61.99987,23.85006
74.70001,62.24987,23.78719
75.00000,62.49993,23.91704
75.30000,62.74993,24.12651
75.60001,62.99987,23.94325
75.90000,63.24993,24.07158
76.20001,63.49993,24.05987
76.50000,63.74992,24.26700
76.80000,63.99993,24.41777
77.10001,64.24987,24.46290
77.40000,64.49993,24.60225
77.70001,64.74993,24.59064
78.00000,64.99992,24.68462
78.30000,65.24986,24.61431
78.60001,65.49987,24.74048
78.90000,65.74993,25.06540
79.20001,65.99993,24.96823
79.50000,66.24986,25.15698
79.80000,66.49987,25.23381
80.10001,66.74992,25.27855
80.40000,66.99999,25.54790
80.70001,67.24987,25.29339
81.00001,67.49986,25.55481
81.30000,67.74993,25.55971
81.60001,67.99993,25.49959
81.90000,68.24993,25.60611
82.20001,68.49993,25.93314
82.50001,68.74993,26.00095
82.80000,68.99992,25.71533
83.10001,69.24986,26.15574
83.40000,69.49992,26.09332
83.70001,69.74999,26.13899
84.00001,69.99987,26.38384
84.30000,70.24986,26.35071
84.60001,70.49993,26.20852
84.90000,70.74993,26.56435
85.20001,70.99986,26.50986
85.50001,71.24986,26.57249
85.80000,71.49993,26.81700
86.10001,71.74987,26.89976
86.40000,71.99986,26.92818
86.70001,72.24993,27.15451
87.00001,72.49986,26.92475
87.30000,72.74986,27.16367
87.60001,72.99987,26.93381
87.90000,73.24993,27.27725
88.20001,73.49999,27.30523
88.50001,73.74987,27.48031
88.80000,73.99999,27.47227
89.10001,74.24999,27.64519
89.40000,74.49993,27.61075
89.70001,74.74986,27.87030
90.00001,74.99986,27.64784
90.30000,75.24999,27.96614
90.60001,75.49986,28.09971
90.90000,75.74974,28.23633
91.20001,75.99992,28.20869
91.50001,76.24993,28.12010
91.80000,76.49987,28.40547
92.10001,76.74993,28.60142
92.40000,76.99993,28.39940
92.70001,77.24986,28.39626
93.00001,77.49987,28.67884
93.30000,77.74992,28.65410
93.60001,77.99986,28.82712
93.90000,78.24992,28.80781
94.20001,78.49992,28.95403
94.50001,78.74999,28.98651
94.80000,78.99993,29.16428
95.10001,79.24993,29.17472
95.40000,79.49992,29.09931
95.70001,79.74993,29.52081
96.00001,79.99986,29.60283
96.30000,80.24992,29.56535
96.60001,80.49986,29.52581
96.90000,80.74986,29.69706
97.20001,80.99993,29.71617
97.50001,81.24986,29.93540
97.80000,81.49993,29.93461
98.10001,81.74987,30.17824
98.40000,81.99993,30.23640
98.70001,82.24992,29.99870
99.00001,82.49993,30.20249
99.30000,82.74986,30.18211
99.60001,82.99986,30.35674
99.90000,83.24993,30.44436
100.20001,83.49992,30.57940
100.50001,83.74986,30.56877
100.80000,83.99999,30.79177
101.10001,84.24980,30.78574
101.40000,84.49992,30.95743
101.70001,84.74993,30.85561
102.00001,84.99992,31.13726
102.30000,85.24986,31.05901
102.60001,85.49985,31.19675
102.90000,85.74999,31.26466
103.20001,85.99993,31.45473
103.50001,86.24987,31.42117
103.80000,86.49993,31.37923
104.10001,86.74992,31.51300
104.40000,86.99986,31.69341
104.70001,87.24992,31.92979
105.00001,87.49986,31.79366
105.30000,87.74993,31.94949
105.60001,87.99986,32.00089
105.90000,88.24993,32.17474
106.20001,88.49992,32.09668
106.50001,88.74992,32.15205
106.80000,88.99992,32.39509
107.10001,89.24992,32.67488
107.40000,89.49992,32.32213
107.70001,89.74986,32.57144
108.00001,89.99986,32.59574
108.30000,90.24998,32.72652
108.60001,90.49992,32.63269
108.90000,90.74987,32.99725
109.20001,90.99992,33.04601
109.50001,91.24992,32.97652
109.80000,91.49992,33.18678
110.10001,91.74986,33.30428
110.40000,91.99998,33.18271
110.70001,92.24992,33.42806
111.00001,92.49986,33.52081
111.30000,92.74987,33.57834
111.60001,92.99993,33.68227
111.90000,93.24992,33.53904
112.20001,93.49986,33.82603
112.50001,93.74999,33.71255
112.80000,93.99992,34.02914
113.10001,94.24986,34.11244
113.40001,94.49992,33.87650
113.70001,94.74993,34.11180
114.00001,94.99992,34.19020
114.30000,95.24986,34.32676
114.60001,95.49992,34.19343
114.90001,95.74993,34.65139
115.20001,95.99986,34.61968
115.50001,96.24992,34.59136
115.80000,96.49992,34.78991
116.10001,96.74992,34.91598
116.40001,96.99985,34.93970
116.70001,97.24992,34.99860
117.00001,97.49993,35.12668
117.30000,97.74992,35.13330
117.60001,97.99986,35.10983
117.90001,98.24986,35.27305
118.20001,98.49992,35.33964
118.50001,98.74992,35.54142
118.80000,98.99992,35.46444
119.10001,99.24993,35.52270
119.40001,99.49992,35.87481
119.70001,99.74992,35.76873
120.00001,99.99986,35.88143
120.30000,100.24992,36.08718
120.60001,100.49986,35.90916
120.90001,100.74992,36.08561
121.20001,100.99999,36.24780
121.50001,101.24986,36.40818
121.80000,101.49992,36.37657
122.10001,101.74992,36.38686
122.40001,101.99992,36.52156
122.70001,102.24992,36.30175
123.00001,102.49986,36.65014
123.30000,102.74992,36.62417
123.60001,102.99992,36.76279
123.90001,103.24986,36.74270
124.20001,103.49993,37.23280
124.50001,103.74992,37.08697
124.80000,103.99993,37.03831
125.10001,104.24986,37.25896
125.40001,104.49992,37.29459
125.70001,104.74992,37.63587
126.00001,104.99986,37.43923
126.30000,105.24992,37.61289
126.60001,105.49992,37.56453
126.90001,105.74993,37.63695
127.20001,105.99986,37.88312
127.50001,106.24993,37.80614
127.80000,106.49992,37.83407
128.10001,106.74986,37.89572
128.40001,106.99992,38.10734
128.70002,107.24992,38.21260
129.00000,107.49985,38.13650
129.30000,107.74992,38.52654
129.60001,107.99993,38.55579
129.90001,108.24992,38.46652
130.20002,108.49986,38.37719
130.50000,108.74987,38.63203
130.80000,108.99998,38.82196
131.10000,109.24992,38.86650
131.40002,109.49992,38.98846
131.70002,109.74986,39.03428
132.00000,109.99992,39.03094
132.30000,110.24993,39.21734
132.60000,110.49986,39.37428
132.90002,110.74998,39.30769
133.20002,110.99992,39.38315
133.50000,111.24986,39.35184
133.80000,111.49992,39.47723
134.10000,111.74992,39.67132
134.40002,111.99986,39.69803
134.70002,112.24986,39.93734
135.00000,112.49992,39.85385
135.30000,112.74992,39.82508
135.60000,112.99986,39.98521
135.90002,113.24992,40.04117
136.20002,113.49992,40.32042
136.50000,113.74992,40.39285
136.80000,113.99992,40.39971
137.10000,114.24992,40.45508
137.40002,114.49993,40.57361
137.70002,114.74986,40.54377
138.00000,114.99993,40.73325
138.30000,115.24992,40.78999
138.60000,115.49986,40.85423
138.90002,115.74986,40.98952
139.20002,115.99992,40.84639
139.50000,116.24992,41.26186
139.80000,116.49986,41.18316
140.10000,116.74993,41.36809
140.40002,116.99986,41.39847
140.70002,117.24993,41.23084
141.00000,117.49987,41.36084
141.30000,117.74993,41.58241
141.60000,117.99992,41.72368
141.90002,118.24986,41.74171
142.20002,118.49998,41.78106
142.50000,118.74992,41.86039
142.80000,118.99993,42.12494
143.10000,119.24992,42.13396
143.40002,119.49986,42.13582
143.70002,119.74992,42.26263
144.00000,119.99986,42.35407
144.30000,120.24986,42.26165
144.60000,120.49992,42.53228
144.90002,120.74992,42.52566
145.20002,120.99992,42.46456
145.50000,121.24985,42.61911
145.80000,121.49992,42.61288
146.10000,121.74986,42.82833
146.40002,121.99992,42.88155
146.70002,122.24992,43.05398
147.00000,122.49992,42.85602
147.30000,122.74992,43.21847
147.60000,122.99986,43.14600
147.90002,123.24998,43.22705
148.20002,123.49992,43.33715
148.50000,123.74992,43.32642
148.80000,123.99998,43.53996
149.10000,124.24992,43.47494
149.40002,124.49992,43.49194
149.70002,124.74986,43.74752
150.00000,124.99986,43.92480
150.30000,125.24992,43.90805
150.60000,125.49986,44.06818
150.90002,125.74986,44.25389
151.20002,125.99992,44.08239
151.50000,126.24986,44.21777
151.80000,126.49985,44.28951
152.10000,126.74986,44.42999
152.40002,126.99998,44.42083
152.70002,127.24985,44.56807
153.00000,127.49985,44.38761
153.30000,127.74998,44.55852
153.60000,127.99992,44.66661
153.90002,128.24985,44.76246
154.20002,128.49991,45.00251
154.50000,128.74998,45.12991
154.80000,128.99992,45.08081
155.10000,129.24986,44.89138
155.40002,129.49991,45.18503
155.70002,129.74991,45.27896
156.00000,129.99992,45.39200
156.30000,130.24992,45.44145
156.60000,130.49992,45.45355
156.90002,130.74986,45.75088
157.20002,130.99991,45.63960
157.50000,131.24998,45.83604
157.80000,131.49998,45.75088
158.10000,131.74986,46.12348
158.40002,131.99992,46.07673
158.70002,132.24992,46.16052
159.00000,132.49992,46.15155
159.30000,132.74992,46.26925
159.60000,132.99986,46.35598
159.90002,133.24991,46.35039
160.20002,133.49992,46.46642
160.50000,133.74992,46.42840
160.80000,133.99991,46.46642
161.10000,134.24992,46.40233
161.40002,134.49985,46.52655
161.70002,134.74998,46.88704
162.00002,134.99992,46.97994
162.30000,135.24991,46.75327
162.60000,135.49991,47.15002
162.90002,135.74985,47.01978
163.20002,135.99992,47.00479
163.50002,136.24986,47.19554
163.80000,136.49992,47.33348
164.10000,136.74991,47.34044
164.40002,136.99985,47.65796
164.70002,137.24992,47.57657
165.00002,137.49992,47.52169
165.30000,137.74991,47.69652
165.60000,137.99992,47.75635
165.90002,138.24992,47.95788
166.20002,138.49998,47.98336
166.50002,138.74985,48.02903
166.80000,138.99991,47.94397
167.10000,139.24993,48.04834
167.40002,139.49992,48.18083
167.70002,139.74986,48.36821
168.00002,139.99986,48.40755
168.30000,140.24991,48.38756
168.60000,140.49992,48.38575
168.90002,140.74991,48.66466
169.20002,140.99997,48.56744
169.50002,141.24999,48.64138
169.80000,141.49985,48.87923
170.10000,141.74986,48.96405
170.40002,141.99997,48.73321
170.70002,142.24991,48.99305
171.00002,142.49985,49.09973
171.30000,142.74992,49.13706
171.60000,142.99992,49.11139
171.90002,143.24992,49.31165
172.20002,143.49985,49.14622
172.50002,143.74991,49.38177
172.80000,143.99992,49.45238
173.10000,144.24986,49.68728
173.40002,144.49986,49.54092
173.70002,144.74991,49.72398
174.00002,144.99985,49.88025
174.30000,145.24992,49.65416
174.60000,145.49998,49.79219
174.90002,145.74997,50.09021
175.20002,145.99991,50.00338
175.50002,146.24985,50.14905
175.80000,146.49992,50.21702
176.10000,146.74991,50.29326
176.40002,146.99991,50.17748
176.70002,147.24992,50.44354
177.00002,147.49992,50.33442
177.30000,147.74992,50.80825
177.60000,147.99992,50.64401
177.90002,148.24991,50.87812
178.20002,148.49992,50.80242
178.50002,148.74986,50.72118
178.80000,148.99998,50.80791
179.10000,149.24991,51.06403
179.40002,149.49985,51.08098
179.70002,149.74992,51.12964
180.00002,149.99992,51.21672
180.30000,150.24992,51.06859
180.60000,150.49991,51.49837
180.90002,150.74993,51.22818
181.20002,150.99992,51.50312
181.50002,151.24992,51.57436
181.80000,151.49985,51.56961
182.10000,151.74999,51.61160
182.40002,151.99984,51.80707
182.70002,152.24992,51.66153
183.00002,152.49992,51.96514
183.30000,152.74991,52.03834
183.60000,152.99985,52.02673
183.90002,153.24992,52.08038
184.20002,153.49992,52.27065
184.50002,153.74991,52.16383
184.80000,153.99992,52.37816
185.10000,154.24985,52.30677
185.40002,154.49992,52.42500
185.70002,154.74992,52.46802
186.00002,154.99986,52.54775
186.30000,155.24991,52.74933
186.60000,155.49992,52.77795
186.90002,155.74992,52.83018
187.20002,155.99991,52.92117
187.50002,156.24992,52.95915
187.80000,156.49999,53.02491
188.10000,156.74986,53.08532
188.40002,156.99992,53.23463
188.70002,157.24991,53.11830
189.00002,157.49991,53.49971
189.30000,157.74991,53.27882
189.60000,157.99992,53.25413
189.90002,158.24990,53.62878
190.20002,158.49985,53.54396
190.50002,158.74984,53.69101
190.80000,158.99992,53.72438
191.10000,159.24992,53.83174
191.40002,159.49991,53.62614
191.70002,159.74991,53.93890
192.00002,159.99991,53.99255
192.30000,160.24992,54.05425
192.60000,160.49985,54.20389
192.90002,160.74991,54.41440
193.20002,160.99991,54.17636
193.50002,161.24984,54.20076
193.80000,161.49985,54.53253
194.10000,161.74991,54.58844
194.40002,161.99986,54.61358
194.70002,162.24984,54.51685
195.00002,162.49992,54.73314
195.30000,162.74991,54.74946
195.60000,162.99985,54.90802
195.90002,163.24991,55.08780
196.20002,163.49992,54.71457
196.50002,163.74992,54.99059
196.80000,163.99991,55.17384
197.10000,164.24997,55.34044
197.40002,164.49990,55.19933
197.70002,164.74985,55.23813
198.00002,164.99985,55.46280
198.30000,165.24991,55.45745
198.60000,165.49991,55.62072
198.90002,165.74990,55.38641
199.20002,165.99992,55.62680
199.50002,166.24985,55.72157
199.80000,166.49991,55.67565
200.10000,166.74984,55.83108
200.40002,166.99992,55.85989
200.70002,167.24991,55.97470
201.00002,167.49986,56.10518
201.30000,167.74997,55.96362
201.60000,167.99990,56.15610
201.90002,168.24992,56.18878
202.20002,168.49991,56.38899
202.50002,168.74991,56.32000
202.80000,168.99997,56.40957
203.10000,169.24985,56.39947
203.40002,169.49991,56.54633
203.70002,169.74991,56.58357
204.00002,169.99984,56.44284
204.30000,170.24990,56.62316
204.60000,170.49992,56.71097
204.90002,170.74991,56.94304
205.20002,170.99986,56.96699
205.50002,171.24990,56.99630
205.80000,171.49990,56.96180
206.10000,171.74983,57.11301
206.40002,171.99986,57.02261
206.70002,172.24992,57.45371
207.00002,172.49998,57.22287
207.30000,172.74993,57.21155
207.60000,172.99986,57.36546
207.90002,173.24997,57.54284
208.20002,173.49990,57.54872
208.50002,173.74985,57.61556
208.80000,173.99991,57.68313
209.10000,174.24991,57.69185
209.40002,174.49992,57.79950
209.70002,174.74990,57.57934
210.00002,174.99991,57.92739
210.30000,175.24991,57.94684
210.60000,175.49979,58.10746
210.90002,175.74990,58.10742
211.20002,175.99998,58.04460
211.50002,176.24991,58.26809
211.80000,176.49991,58.28945
212.10000,176.74992,58.30768
212.40002,176.99996,58.39588
212.70002,177.24991,58.44223
213.00002,177.49984,58.67635
213.30000,177.74997,58.67964
213.60000,177.99990,58.68013
213.90002,178.24985,58.85530
214.20002,178.49991,58.95663
214.50002,178.74992,58.87020
214.80000,178.99984,58.90469
215.10000,179.24991,59.03028
215.40002,179.49991,59.22951
215.70002,179.74991,59.01249
216.00002,179.99986,59.22579
216.30000,180.24990,59.35975
216.60000,180.49991,59.21741
216.90002,180.74991,59.53311
217.20002,180.99992,59.35858
217.50002,181.24992,59.54101
217.80000,181.49985,59.79943
218.10000,181.74985,59.72857
218.40002,181.99991,59.74646
218.70002,182.24992,59.95530
219.00002,182.49985,59.97078
219.30000,182.74991,59.87313
219.60000,182.99991,59.89361
219.90002,183.24992,59.82422
220.20002,183.49992,60.03443
220.50002,183.74985,60.19109
220.80000,183.99991,60.16536
221.10000,184.24990,60.31701
221.40002,184.49992,60.46141
221.70002,184.74991,60.27997
222.00002,184.99985,60.29884
222.30000,185.24984,60.34696
222.60000,185.49992,60.54878
222.90002,185.74992,60.40919
223.20002,185.99985,60.44550
223.50002,186.24986,60.76355
223.80000,186.49990,60.80182
224.10000,186.74992,60.80589
224.40002,186.99985,60.69912
224.70002,187.24985,61.16162
225.00002,187.49991,60.86924
225.30002,187.74997,60.98836
225.60000,187.99985,61.09062
225.90002,188.24991,61.23630
226.20002,188.49991,61.46180
226.50002,188.74990,61.57979
226.80002,188.99985,61.19793
227.10000,189.24991,61.30922
227.40002,189.49991,61.73958
227.70002,189.74984,61.50698
228.00002,189.99984,61.42122
228.30002,190.24998,61.86619
228.60000,190.49991,61.61178
228.90002,190.74984,61.81499
229.20002,190.99990,61.92637
229.50002,191.24992,62.03990
229.80002,191.49985,61.77834
230.10000,191.74978,61.99987
230.40002,191.99997,62.17019
230.70002,192.24990,62.36883
231.00002,192.49983,62.11105
231.30002,192.74997,62.45684
231.60000,192.99991,62.44435
231.90002,193.24990,62.49011
232.20002,193.49985,62.43013
232.50002,193.74983,62.33684
232.80002,193.99991,62.56861
233.10000,194.24984,62.47609
233.40002,194.49985,62.69816
233.70002,194.74998,62.70581
234.00002,194.99991,62.77064
234.30002,195.24992,62.77730
234.60000,195.49990,63.09403
234.90002,195.74990,63.07326
235.20002,195.99991,62.90857
235.50002,196.24986,63.04292
235.80002,196.49984,63.17498
236.10000,196.74990,63.10653
236.40002,196.99983,63.33448
236.70002,197.24991,63.48520
237.00002,197.49984,63.40533
237.30002,197.74990,63.30429
237.60000,197.99991,63.41557
237.90002,198.24991,63.57997
238.20002,198.49991,63.62338
238.50002,198.74984,63.65665
238.80002,198.99990,63.90988
239.10000,199.24991,63.87450
239.40002,199.49991,64.03625
239.70002,199.74992,64.04698
240.00002,199.99990,64.06751
240.30002,200.24991,64.08721
240.60000,200.49991,64.17076
240.90002,200.74992,64.15576
241.20002,200.99990,64.47881
241.50002,201.24985,64.30600
241.80002,201.49991,64.34515
242.10000,201.74991,64.44898
242.40002,201.99992,64.63233
242.70002,202.24985,64.30271
243.00002,202.49985,64.53556
243.30002,202.74997,64.58274
243.60000,202.99979,64.80080
243.90002,203.24990,64.62601
244.20002,203.49996,64.69383
244.50002,203.74991,64.76943
244.80002,203.99991,65.07118
245.10000,204.24984,64.95779
245.40002,204.49990,65.02364
245.70002,204.74991,65.01184
246.00002,204.99984,65.19912
246.30002,205.24992,65.08696
246.60000,205.49990,65.08803
246.90002,205.74985,65.30941
247.20002,205.99984,65.35655
247.50002,206.24990,65.19661
247.80002,206.49992,65.37213
248.10000,206.74985,65.51252
248.40002,206.99991,65.65834
248.70002,207.24989,65.56147
249.00002,207.49992,65.58342
249.30002,207.74985,65.99105
249.60000,207.99991,65.81044
249.90002,208.24984,66.02359
250.20002,208.49984,66.11149
250.50002,208.74992,65.83043
250.80002,208.99996,66.24291
251.10000,209.24985,66.14422
251.40002,209.49984,66.31430
251.70002,209.74990,66.28147
252.00002,209.99990,66.49942
252.30002,210.24985,66.41970
252.60000,210.49984,66.63369
252.90002,210.74984,66.60149
253.20002,210.99992,66.65559
253.50002,211.24985,66.81944
253.80002,211.49985,66.73487
254.10000,211.74997,67.02813
254.40002,211.99984,66.95924
254.70002,212.24990,66.98575
255.00002,212.49991,66.86192
255.30002,212.74991,66.77044
255.60000,212.99984,66.99761
255.90002,213.24992,67.03024
256.20002,213.49991,67.15132
256.50000,213.74991,67.00956
256.80002,213.99984,67.18297
257.10000,214.24990,67.21982
257.40003,214.49991,67.25427
257.70002,214.74985,67.18802
258.00000,214.99984,67.58286
258.30002,215.24990,67.48069
258.60000,215.49985,67.40582
258.90003,215.74983,67.63152
259.20002,215.99991,67.67131
259.50000,216.24984,67.72912
259.80002,216.49985,67.68444
260.10000,216.74983,67.83678
260.40003,216.99991,67.79694
260.70002,217.24992,67.69218
261.00000,217.49990,67.67022
261.30002,217.74998,67.83835
261.60000,217.99991,68.11887
261.90003,218.24991,68.25367
262.20000,218.49984,68.18928
262.50000,218.74985,68.33712
262.80003,218.99998,68.32776
263.10000,219.24991,68.55575
263.40003,219.49992,68.57530
263.70000,219.74990,68.55276
264.00000,219.99985,68.46672
264.30003,220.24991,68.60181
264.60000,220.49991,68.68403
264.90003,220.74997,68.69423
265.20000,220.99990,68.71378
265.50000,221.24983,68.82285
265.80003,221.49997,68.89689
266.10000,221.74992,68.80384
266.40003,221.99990,68.95044
266.70000,222.24991,69.01797
267.00000,222.49991,69.19368
267.30003,222.74991,69.04786
267.60000,222.99990,69.37003
267.90003,223.24990,69.21245
268.20000,223.49991,69.29241
268.50000,223.74991,69.34362
268.80003,223.99992,69.32544
269.10000,224.24990,69.35945
269.40003,224.49985,69.58666
269.70000,224.74984,69.49753
270.00000,224.99992,69.58877
270.30003,225.24990,69.76752
270.60000,225.49985,69.76526
270.90003,225.74984,69.59651
271.20000,225.99991,69.83220
271.50000,226.24992,69.92236
271.80003,226.49985,69.64835
272.10000,226.74991,69.81750
272.40003,226.99989,69.93485
272.70000,227.24984,69.89933
273.00000,227.49985,70.09822
273.30003,227.74996,70.24203
273.60000,227.99991,70.14883
273.90003,228.24984,70.34292
274.20000,228.49992,70.33523
274.50000,228.74990,70.45405
274.80003,228.99991,70.66760
275.10000,229.24984,70.66529
275.40003,229.49997,70.48041
275.70000,229.74990,70.75291
276.00000,229.99991,70.48934
276.30003,230.24991,70.71322
276.60000,230.49990,70.89952
276.90003,230.74985,70.72145
277.20000,230.99991,70.91906
277.50000,231.24991,70.89652
277.80003,231.49984,70.92720
278.10000,231.74984,70.98276
278.40003,231.99985,71.00609
278.70000,232.24991,70.88319
279.00000,232.49991,71.15779
279.30003,232.74990,71.09012
279.60000,232.99992,71.25824
279.90003,233.24991,71.33919
280.20000,233.49985,71.36883
280.50000,233.74984,71.59962
280.80003,233.99990,71.51177
281.10000,234.24983,71.61231
281.40003,234.49991,71.45458
281.70000,234.74991,71.54773
282.00000,234.99990,71.68243
282.30003,235.24992,71.93429
282.60000,235.49991,72.00112
282.90003,235.74991,72.09046
283.20000,235.99984,72.20556
283.50000,236.24979,72.34167
283.80003,236.49991,72.17361
284.10000,236.74997,72.50764
284.40003,236.99984,72.51538
284.70000,237.24990,72.57379
285.00000,237.49990,72.50622
285.30003,237.74991,72.71133
285.60000,237.99986,72.81016
285.90003,238.24984,72.76504
286.20000,238.49990,73.08177
286.50000,238.74991,73.01768
286.80003,238.99991,73.00362
287.10000,239.24997,73.06105
287.40003,239.49990,73.33672
287.70000,239.74990,73.14140
288.00000,239.99991,73.15149
288.30003,240.24991,73.41928
288.60000,240.49990,73.14802
288.90003,240.74990,73.50993
289.20000,240.99983,73.40252
289.50000,241.24997,73.62111
289.80003,241.49992,73.46441
290.10000,241.74990,73.65360
290.40003,241.99991,73.58897
290.70000,242.24991,73.80354
291.00000,242.49991,73.77159
291.30003,242.74990,73.89272
291.60000,242.99996,73.86376
291.90003,243.24983,73.75586
292.20000,243.49984,74.16119
292.50000,243.74992,74.00380
292.80003,243.99996,74.15790
293.10000,244.24985,74.46058
293.40003,244.49984,74.58910
293.70000,244.74997,74.46934
294.00000,244.99990,74.53878
294.30003,245.24985,74.68926
294.60000,245.49983,74.77413
294.90003,245.74991,74.90672
295.20000,245.99984,74.84385
295.50000,246.24985,74.92250
295.80003,246.49991,74.98360
296.10000,246.74984,74.93974
296.40003,246.99984,75.09429
296.70000,247.24998,75.20390
297.00000,247.49991,75.28681
297.30003,247.74991,75.31719
297.60000,247.99991,75.31587
297.90003,248.24992,75.50957
298.20000,248.49990,75.34032
298.50000,248.74991,75.47350
298.80003,248.99997,75.47081
299.10000,249.24992,75.55474
299.40003,249.49985,75.54759
299.70000,249.74991,75.43930
300.00000,249.99991,75.43602
300.30003,250.24990,75.67116
300.60000,250.49984,75.64471
300.90003,250.74989,75.82939
301.20000,250.99991,75.83071
301.50000,251.24988,75.95605
301.80003,251.49990,76.12667
302.10000,251.74985,76.34281
302.40003,251.99989,76.23432
302.70000,252.24989,76.44130
303.00000,252.49988,76.46339
303.30003,252.74990,76.51504
303.60000,252.99985,76.55199
303.90003,253.24989,76.63142
304.20000,253.49995,76.45090
304.50000,253.74983,76.75794
304.80003,253.99983,76.78934
305.10000,254.24991,77.02939
305.40003,254.49989,77.00656
305.70000,254.74990,77.08084
306.00000,254.99990,76.99598
306.30003,255.24989,77.23485
306.60000,255.49991,77.06918
306.90003,255.74982,77.23539
307.20000,255.99984,77.14601
307.50000,256.24990,77.38783
307.80003,256.49989,77.34618
308.10000,256.74989,77.12607
308.40003,256.99988,77.07114
308.70000,257.24996,77.21604
309.00000,257.49991,77.28042
309.30003,257.74989,77.39111
309.60000,257.99990,77.56594
309.90003,258.24998,77.46030
310.20000,258.49983,77.54370
310.50000,258.74991,77.77483
310.80003,258.99995,77.89708
311.10000,259.24990,77.71236
311.40003,259.49989,77.92154
311.70000,259.74989,77.86612
312.00000,259.99991,77.80717
312.30003,260.24982,77.88841
312.60000,260.49985,77.78943
312.90003,260.74991,77.59544
313.20000,260.99989,52.10121
313.50000,261.24990,0.15339
313.80003,261.49994,0.16113
314.10000,261.74990,0.14692
314.40003,261.99996,0.25001
314.70000,262.24989,0.17019
315.00000,262.49990,0.12497
315.30003,262.74994,0.08209
315.60000,262.99983,0.12340
315.90003,263.24986,0.34630
316.20000,263.49995,0.26305
316.50000,263.74985,0.13359
316.80003,263.99989,0.28755
317.09803,264.24829,0.31210