File: V_7/EPR/RDSO EPR Tensile 50.is_tens_RawData/Specimen_RawData_12.csv
Time,Extension,Load
(sec),(mm),(N)
0.00000,-0.00006,4.45381
0.30000,0.24931,4.93935
0.60000,0.49987,5.70874
0.90000,0.74994,5.76681
1.20000,0.99987,6.17140
1.50000,1.24994,6.37406
1.80000,1.49994,6.60985
2.10000,1.74994,6.61603
2.40000,1.99994,6.84334
2.70000,2.24987,7.10029
3.00000,2.49994,7.40076
3.30000,2.75006,7.39360
3.60000,2.99994,7.54051
3.90000,3.24987,7.85254
4.20000,3.49994,8.03281
4.50000,3.74994,8.35998
4.80000,3.99994,8.24630
5.10000,4.24987,8.49703
5.40000,4.49994,8.71665
5.70000,4.74994,8.79956
6.00000,4.99994,8.83278
6.30000,5.24994,9.04887
6.60000,5.49994,9.03093
6.90000,5.74987,9.35551
7.20000,5.99987,9.30484
7.50000,6.24987,9.56072
7.80000,6.49994,9.70483
8.10000,6.74987,9.84512
8.40000,6.99987,9.97918
8.70000,7.25000,10.31640
9.00000,7.49994,10.02534
9.30000,7.74994,10.25270
9.60000,7.99987,10.32066
9.90000,8.25000,10.50490
10.20000,8.49987,10.49064
10.50000,8.74994,10.72751
10.80000,8.99994,10.85388
11.10000,9.24987,10.91405
11.40000,9.49994,11.14587
11.70000,9.75000,11.31839
12.00000,9.99994,11.29576
12.30000,10.24994,11.34441
12.60000,10.49987,11.51082
12.90000,10.75000,11.58525
13.20000,10.99994,11.55933
13.50000,11.24987,11.75366
13.80000,11.49994,11.88302
14.10000,11.74994,11.87640
14.40000,11.99994,12.14512
14.70000,12.24994,12.25111
15.00000,12.49994,12.19941
15.30000,12.74994,12.21151
15.60000,12.99987,12.42947
15.90000,13.24994,12.33798
16.20000,13.49994,12.45191
16.50000,13.74987,12.60645
16.80000,13.99994,12.70925
17.10000,14.24994,12.66687
17.40000,14.49994,12.93715
17.70000,14.74994,12.92211
18.00000,14.99987,12.96660
18.30000,15.24994,12.84278
18.60000,15.49987,12.98468
18.90000,15.74987,13.08900
19.20000,15.99994,13.11110
19.50000,16.24993,13.20631
19.80000,16.49993,13.41309
20.10000,16.74994,13.38624
20.40000,16.99987,13.50942
20.70000,17.24993,13.55847
21.00000,17.49994,13.57087
21.30000,17.74994,13.65485
21.60000,17.99993,13.79509
21.90000,18.24987,13.79088
22.20000,18.49987,13.72767
22.50000,18.74994,13.84135
22.80000,19.00000,13.81366
23.10000,19.24993,14.09149
23.40000,19.49994,14.00084
23.70000,19.74993,13.94067
24.00000,19.99993,14.22752
24.30000,20.24994,14.09531
24.60000,20.49993,14.19155
24.90000,20.74993,14.12844
25.20000,20.99993,14.29935
25.50000,21.24993,14.34443
25.80000,21.50000,14.43179
26.10000,21.74993,14.31199
26.40000,21.99987,14.47291
26.70000,22.25000,14.62201
27.00000,22.49993,14.68150
27.30000,22.74987,14.84481
27.60000,22.99987,14.85491
27.90000,23.24993,14.84388
28.20000,23.49993,14.70928
28.50000,23.74987,14.98755
28.80000,23.99993,14.91807
29.10000,24.24994,14.96893
29.40000,24.49993,15.10157
29.70000,24.74993,15.17948
30.00000,24.99993,15.13955
30.30000,25.25000,15.34643
30.60000,25.49981,15.41635
30.90000,25.74987,15.61612
31.20000,25.99993,15.22770
31.50000,26.24987,15.54752
31.80000,26.49993,15.44771
32.10000,26.74993,15.70295
32.40000,26.99994,15.55575
32.70000,27.24993,15.71863
33.00000,27.49987,15.83863
33.30000,27.74999,15.97750
33.60000,27.99987,15.73480
33.90000,28.24993,15.81638
34.20000,28.49993,16.02365
34.50000,28.74993,15.94893
34.80000,28.99993,16.02894
35.10000,29.24987,16.26424
35.40000,29.50000,16.09730
35.70000,29.74994,16.19241
36.00000,29.99993,16.34759
36.30000,30.24993,16.32304
36.60000,30.49987,16.44691
36.90000,30.74993,16.48224
37.20000,30.99993,16.55491
37.50000,31.24987,16.68505
37.80000,31.49993,16.65198
38.10000,31.74993,16.58916
38.40000,31.99993,16.73998
38.70000,32.24993,16.83499
39.00000,32.49987,16.73023
39.30000,32.74987,16.90482
39.60000,33.00000,16.92456
39.90000,33.24993,17.17887
40.20000,33.49987,17.05892
40.50000,33.74993,17.03619
40.80000,33.99987,17.18554
41.10000,34.24993,17.31122
41.40000,34.49993,17.36924
41.70000,34.74993,17.43852
42.00000,34.99993,17.63158
42.30000,35.24993,17.45636
42.60000,35.49987,17.71096
42.90000,35.74993,17.65530
43.20000,35.99987,17.71885
43.50000,36.24987,17.57004
43.80000,36.49993,17.89324
44.10000,36.74993,18.07616
44.40000,36.99993,17.97600
44.70000,37.24987,18.04901
45.00000,37.49987,18.05788
45.30000,37.74999,18.12535
45.60000,37.99987,18.24619
45.90000,38.24987,18.16715
46.20000,38.49993,18.27941
46.50000,38.74993,18.35080
46.80000,38.99993,18.50623
47.10000,39.24993,18.72026
47.40000,39.49993,18.56253
47.70000,39.74987,18.62711
48.00000,39.99987,18.65063
48.30000,40.25000,18.73217
48.60000,40.49993,18.78176
48.90000,40.74987,18.79420
49.20000,40.99993,18.97844
49.50000,41.24993,19.12789
49.80000,41.49993,19.08590
50.10000,41.74987,18.99221
50.40000,41.99993,19.28190
50.70000,42.24999,19.37245
51.00000,42.49987,19.27381
51.30000,42.74993,19.43208
51.60000,42.99987,19.52043
51.90000,43.24987,19.64033
52.20000,43.49993,19.62377
52.50000,43.74993,19.70482
52.80000,43.99993,19.74715
53.10000,44.24987,19.94423
53.40000,44.49993,19.90096
53.70000,44.74993,20.00656
54.00000,44.99993,19.88567
54.30000,45.24993,20.07981
54.60000,45.49987,20.23058
54.90000,45.74993,20.21887
55.20000,45.99987,20.44589
55.50000,46.24987,20.36127
55.80000,46.49993,20.54482
56.10000,46.74986,20.65375
56.40000,46.99993,20.75576
56.70000,47.24999,20.65159
57.00000,47.49993,20.76792
57.30000,47.74987,20.77674
57.60000,47.99987,20.74361
57.90000,48.24993,20.66943
58.20000,48.49993,21.07152
58.50000,48.74987,21.02227
58.80000,48.99993,20.96916
59.10000,49.24993,21.02360
59.40000,49.49993,21.36723
59.70000,49.74993,21.27355
60.00000,49.99993,21.41359
60.30000,50.24993,21.59415
60.60000,50.49987,21.54187
60.90000,50.74993,21.72748
61.20000,50.99993,21.63732
61.50000,51.24993,21.80495
61.80000,51.49987,21.81005
62.10000,51.74993,22.04647
62.40000,51.99999,22.03153
62.70000,52.24993,22.16387
63.00000,52.49986,22.24766
63.30000,52.74993,22.14197
63.60000,52.99993,22.34400
63.90000,53.24987,22.26070
64.20000,53.49993,22.58096
64.50000,53.74987,22.55024
64.80000,53.99993,22.57072
65.10001,54.24987,22.73722
65.40000,54.49993,22.80871
65.70001,54.74993,22.94366
66.00000,54.99987,22.94493
66.30000,55.24993,22.76750
66.60001,55.49993,23.14313
66.90000,55.74987,23.12319
67.20001,55.99993,23.11501
67.50000,56.24993,23.29881
67.80000,56.49993,23.29107
68.10001,56.74987,23.52283
68.40000,56.99993,23.37368
68.70001,57.24993,23.70369
69.00000,57.49993,23.62054
69.30000,57.74993,23.69830
69.60001,57.99993,23.75019
69.90000,58.24993,23.91248
70.20001,58.49993,23.85741
70.50000,58.74987,24.08481
70.80000,58.99999,23.88818
71.10001,59.24993,24.12774
71.40000,59.49987,24.22760
71.70001,59.74993,24.25092
72.00000,59.99993,24.41782
72.30000,60.24987,24.62489
72.60001,60.49987,24.50621
72.90000,60.74993,24.63685
73.20001,60.99993,24.74577
73.50000,61.24993,24.56119
73.80000,61.49993,24.93134
74.10001,61.74993,24.99018
74.40000,61.99987,25.11288
74.70001,62.24993,25.08559
75.00000,62.49993,25.19358
75.30000,62.74987,25.20211
75.60001,62.99987,25.36332
75.90000,63.24993,25.42707
76.20001,63.49993,25.43055
76.50000,63.74986,25.61459
76.80000,63.99993,25.57265
77.10001,64.24987,25.80407
77.40000,64.49993,25.70441
77.70001,64.74993,25.89462
78.00000,64.99992,26.04412
78.30000,65.24986,26.09283
78.60001,65.49993,26.07837
78.90000,65.74993,26.12997
79.20001,65.99999,26.28623
79.50000,66.24986,26.31730
79.80000,66.49987,26.40986
80.10001,66.74992,26.58327
80.40000,66.99999,26.71248
80.70001,67.24987,26.72742
81.00001,67.49986,26.71067
81.30000,67.74993,26.92960
81.60001,67.99993,26.71297
81.90000,68.24993,26.97693
82.20001,68.49987,27.18508
82.50001,68.74993,27.15681
82.80000,68.99992,27.34737
83.10001,69.24993,27.27044
83.40000,69.49992,27.16215
83.70001,69.74999,27.53347
84.00001,69.99987,27.38701
84.30000,70.24986,27.71825
84.60001,70.49993,27.62736
84.90000,70.74993,27.89965
85.20001,70.99986,27.93836
85.50001,71.24986,27.79322
85.80000,71.49993,28.19174
86.10001,71.74987,28.22854
86.40000,71.99986,28.43806
86.70001,72.24993,28.13921
87.00001,72.49986,28.53317
87.30000,72.74986,28.50921
87.60001,72.99987,28.63038
87.90000,73.24993,28.83427
88.20001,73.49993,28.56972
88.50001,73.74987,28.78258
88.80000,73.99999,28.78370
89.10001,74.24999,28.80316
89.40000,74.49993,28.99979
89.70001,74.74986,29.33672
90.00001,74.99986,29.25812
90.30000,75.24999,29.28737
90.60001,75.49986,29.51723
90.90000,75.74980,29.35828
91.20001,75.99992,29.61053
91.50001,76.24993,29.73670
91.80000,76.49987,29.69246
92.10001,76.74993,29.65345
92.40000,76.99993,29.78850
92.70001,77.24986,30.13860
93.00001,77.49993,29.94123
93.30000,77.74992,30.15957
93.60001,77.99986,30.23042
93.90000,78.24986,30.34846
94.20001,78.49992,30.44210
94.50001,78.74993,30.54397
94.80000,78.99993,30.44808
95.10001,79.24993,30.77324
95.40000,79.49992,31.05044
95.70001,79.74993,30.69318
96.00001,79.99986,30.95900
96.30000,80.24992,31.27794
96.60001,80.49986,31.05558
96.90000,80.74986,31.02569
97.20001,80.99993,31.36301
97.50001,81.24992,31.27887
97.80000,81.49993,31.39922
98.10001,81.74992,31.52720
98.40000,81.99993,31.54401
98.70001,82.24992,31.54225
99.00001,82.49993,31.74104
99.30000,82.74992,31.83786
99.60001,82.99986,31.98114
99.90000,83.24993,31.91842
100.20001,83.49992,32.00427
100.50001,83.74986,32.10839
100.80000,83.99992,32.13397
101.10001,84.24980,32.03744
101.40000,84.49992,32.37196
101.70001,84.74993,32.57796
102.00001,84.99986,32.66679
102.30000,85.24986,32.59310
102.60001,85.49985,32.72932
102.90000,85.74999,32.68233
103.20001,85.99993,32.67904
103.50001,86.24987,32.83506
103.80000,86.49993,33.09603
104.10001,86.74992,33.17938
104.40000,86.99986,33.33334
104.70001,87.24992,33.35000
105.00001,87.49986,33.49695
105.30000,87.74993,33.56795
105.60001,87.99986,33.63630
105.90000,88.24993,33.84602
106.20001,88.49992,33.86312
106.50001,88.74986,33.74504
106.80000,88.99992,33.76385
107.10001,89.24992,33.90923
107.40000,89.49992,34.04644
107.70001,89.74986,34.12856
108.00001,89.99986,34.22146
108.30000,90.24998,34.24728
108.60001,90.49992,34.37292
108.90000,90.74987,34.55667
109.20001,90.99999,34.47989
109.50001,91.24986,34.61463
109.80000,91.49992,34.72734
110.10001,91.74992,34.84743
110.40000,91.99993,34.75272
110.70001,92.24992,35.06132
111.00001,92.49986,35.03476
111.30000,92.74987,34.98248
111.60001,92.99998,35.15706
111.90000,93.24992,35.37972
112.20001,93.49986,35.52790
112.50001,93.74999,35.48875
112.80000,93.99992,35.54005
113.10001,94.24992,35.36184
113.40001,94.49992,35.67195
113.70001,94.74993,35.72340
114.00001,94.99986,35.90701
114.30000,95.24986,36.02074
114.60001,95.49987,36.11717
114.90001,95.74993,35.94851
115.20001,95.99986,36.30954
115.50001,96.24992,36.42513
115.80000,96.49999,36.39299
116.10001,96.74992,36.47178
116.40001,96.99985,36.72849
116.70001,97.24992,36.66023
117.00001,97.49993,36.68517
117.30000,97.74992,36.93924
117.60001,97.99986,36.87333
117.90001,98.24986,36.81199
118.20001,98.49992,37.14866
118.50001,98.74992,37.16768
118.80000,98.99999,37.28616
119.10001,99.24993,37.33481
119.40001,99.49986,37.30845
119.70001,99.74992,37.45810
120.00001,99.99992,37.65321
120.30000,100.24992,37.79531
120.60001,100.49986,37.85833
120.90001,100.74992,37.85196
121.20001,100.99999,37.96446
121.50001,101.24986,38.05604
121.80000,101.49992,38.15747
122.10001,101.74992,38.21108
122.40001,101.99992,38.18408
122.70001,102.24992,38.32304
123.00001,102.49986,38.47122
123.30000,102.74992,38.46632
123.60001,102.99986,38.58519
123.90001,103.24992,38.78080
124.20001,103.49993,38.78761
124.50001,103.74992,38.79756
124.80000,103.99993,38.56868
125.10001,104.24986,38.91344
125.40001,104.49992,39.18280
125.70001,104.74992,39.10552
126.00001,104.99980,39.36111
126.30000,105.24992,39.33959
126.60001,105.49992,39.43583
126.90001,105.74993,39.15908
127.20001,105.99986,39.40609
127.50001,106.24993,39.60821
127.80000,106.49992,39.86414
128.10001,106.74993,39.56455
128.40001,106.99992,40.09914
128.70002,107.24992,39.93284
129.00000,107.49985,40.11154
129.30000,107.74992,40.13584
129.60001,107.99993,40.18533
129.90001,108.24992,40.30455
130.20002,108.49986,40.70365
130.50000,108.74987,40.41044
130.80000,108.99998,40.23257
131.10000,109.24992,40.52485
131.40002,109.49992,40.63779
131.70002,109.74986,40.82924
132.00000,109.99992,41.08423
132.30000,110.24993,40.99804
132.60000,110.49986,41.05336
132.90002,110.74992,41.11755
133.20002,110.99986,41.32320
133.50000,111.24986,41.28768
133.80000,111.49992,41.39715
134.10000,111.74992,41.42473
134.40002,111.99992,41.53846
134.70002,112.24986,41.55997
135.00000,112.49992,41.77827
135.30000,112.74992,41.73402
135.60000,112.99986,41.85843
135.90002,113.24992,42.04052
136.20002,113.49992,42.02684
136.50000,113.74992,42.08594
136.80000,113.99992,41.82075
137.10000,114.24992,42.31780
137.40002,114.49993,42.41492
137.70002,114.74986,42.44922
138.00000,114.99993,42.48435
138.30000,115.24999,42.61273
138.60000,115.49986,42.50655
138.90002,115.74986,42.79893
139.20002,115.99992,42.73597
139.50000,116.24992,42.95539
139.80000,116.49986,42.85332
140.10000,116.74985,43.28717
140.40002,116.99992,43.25997
140.70002,117.24993,43.22376
141.00000,117.49987,43.48165
141.30000,117.74993,43.37752
141.60000,117.99992,43.45627
141.90002,118.24986,43.55574
142.20002,118.49992,43.73635
142.50000,118.74992,43.89795
142.80000,118.99993,43.84567
143.10000,119.24992,43.86934
143.40002,119.49986,43.93108
143.70002,119.74992,43.98199
144.00000,119.99992,44.19572
144.30000,120.24986,44.40868
144.60000,120.49986,44.10743
144.90002,120.74992,44.38805
145.20002,120.99992,44.42730
145.50000,121.24985,44.67141
145.80000,121.49992,44.76628
146.10000,121.74986,44.63006
146.40002,121.99992,44.80700
146.70002,122.24992,44.85114
147.00000,122.49992,44.88745
147.30000,122.74992,44.97639
147.60000,122.99986,44.99423
147.90002,123.24998,45.08017
148.20002,123.49992,45.29180
148.50000,123.74992,45.28460
148.80000,123.99992,45.31287
149.10000,124.24992,45.57904
149.40002,124.49992,45.52827
149.70002,124.74986,45.59080
150.00000,124.99986,45.62858
150.30000,125.24992,45.71668
150.60000,125.49986,45.82957
150.90002,125.74986,45.90984
151.20002,125.99992,45.85187
151.50000,126.24991,46.24671
151.80000,126.49992,46.31105
152.10000,126.74992,46.05992
152.40002,126.99998,46.20790
152.70002,127.24985,46.28718
153.00000,127.49985,46.45614
153.30000,127.74998,46.48367
153.60000,127.99992,46.80918
153.90002,128.24992,46.74641
154.20002,128.49991,46.74783
154.50000,128.74998,46.90365
154.80000,128.99992,46.88282
155.10000,129.24992,47.11450
155.40002,129.49991,46.95525
155.70002,129.74985,47.13816
156.00000,129.99992,47.39781
156.30000,130.24998,47.26454
156.60000,130.49992,47.47631
156.90002,130.74986,47.21377
157.20002,130.99985,47.43692
157.50000,131.24992,47.56152
157.80000,131.49992,47.92094
158.10000,131.74986,48.06505
158.40002,131.99992,47.67202
158.70002,132.24992,47.88316
159.00000,132.49992,48.13771
159.30000,132.74992,48.13075
159.60000,132.99986,48.23508
159.90002,133.24991,48.34586
160.20002,133.49992,48.47287
160.50000,133.74992,48.43519
160.80000,133.99998,48.64319
161.10000,134.24992,48.55578
161.40002,134.49985,48.51477
161.70002,134.74998,48.70484
162.00002,134.99992,48.64766
162.30000,135.24986,48.82503
162.60000,135.49991,49.06371
162.90002,135.74985,48.96140
163.20002,135.99992,49.10810
163.50002,136.24986,49.31474
163.80000,136.49992,49.25501
164.10000,136.74991,49.31684
164.40002,136.99985,49.54205
164.70002,137.24992,49.56385
165.00002,137.49997,49.40940
165.30000,137.74991,49.56380
165.60000,137.99985,49.58355
165.90002,138.24992,49.82002
166.20002,138.49998,49.97815
166.50002,138.74992,49.92709
166.80000,138.99991,49.83419
167.10000,139.24985,49.98544
167.40002,139.49992,50.04538
167.70002,139.74992,50.07208
168.00002,139.99986,50.30385
168.30000,140.24998,50.54277
168.60000,140.49992,50.41297
168.90002,140.74991,50.59755
169.20002,140.99997,50.53645
169.50002,141.24991,50.62901
169.80000,141.49985,50.78008
170.10000,141.74986,50.85735
170.40002,141.99997,50.82780
170.70002,142.24998,50.90949
171.00002,142.49985,51.18051
171.30000,142.74985,50.98480
171.60000,142.99992,51.24939
171.90002,143.24998,51.22671
172.20002,143.49991,51.53810
172.50002,143.74991,51.41796
172.80000,143.99992,51.35735
173.10000,144.24986,51.58867
173.40002,144.49986,51.66731
173.70002,144.74991,51.52684
174.00002,144.99985,51.68011
174.30000,145.24992,51.87591
174.60000,145.49992,51.89056
174.90002,145.74997,52.06662
175.20002,145.99991,52.15506
175.50002,146.24985,52.04417
175.80000,146.49997,52.31970
176.10000,146.74991,52.26227
176.40002,146.99985,52.35077
176.70002,147.24992,52.41809
177.00002,147.49992,52.50845
177.30000,147.74992,52.38825
177.60000,147.99992,52.70053
177.90002,148.24999,52.59817
178.20002,148.49992,52.82621
178.50002,148.74986,52.97483
178.80000,148.99998,52.95234
179.10000,149.24991,53.04975
179.40002,149.49985,53.13849
179.70002,149.74992,53.28436
180.00002,149.99986,53.22855
180.30000,150.24997,53.23752
180.60000,150.49991,53.40417
180.90002,150.74993,53.34978
181.20002,150.99992,53.54298
181.50002,151.24986,53.50202
181.80000,151.49985,53.46164
182.10000,151.74999,53.60756
182.40002,151.99984,53.70488
182.70002,152.24992,53.88343
183.00002,152.49992,53.88941
183.30000,152.74991,53.93160
183.60000,152.99985,54.15225
183.90002,153.24985,54.15533
184.20002,153.49992,54.30909
184.50002,153.74991,54.25216
184.80000,153.99992,54.41802
185.10000,154.24985,54.29699
185.40002,154.49992,54.56870
185.70002,154.74992,54.52205
186.00002,154.99986,54.44492
186.30000,155.24991,54.59545
186.60000,155.49992,54.66753
186.90002,155.74992,54.79355
187.20002,155.99991,54.92943
187.50002,156.24985,54.92046
187.80000,156.49999,55.07619
188.10000,156.74986,55.05693
188.40002,156.99992,55.25112
188.70002,157.24991,55.27537
189.00002,157.49991,55.42193
189.30000,157.74984,55.52821
189.60000,157.99992,55.39180
189.90002,158.24998,55.55227
190.20002,158.49985,55.48764
190.50002,158.74991,55.60979
190.80000,158.99997,55.58138
191.10000,159.24992,55.83814
191.40002,159.49991,55.90370
191.70002,159.74991,55.92791
192.00002,159.99991,55.90252
192.30000,160.24992,56.25993
192.60000,160.49985,56.05638
192.90002,160.74991,56.19284
193.20002,160.99991,56.42064
193.50002,161.24984,56.15620
193.80000,161.49985,56.46808
194.10000,161.74991,56.48797
194.40002,161.99986,56.52310
194.70002,162.24990,56.65100
195.00002,162.49992,56.53639
195.30000,162.74991,56.88281
195.60000,162.99985,56.72537
195.90002,163.24991,56.82847
196.20002,163.49992,57.07911
196.50002,163.74992,56.89001
196.80000,163.99991,56.92005
197.10000,164.24991,57.04603
197.40002,164.49990,56.98929
197.70002,164.74985,57.04226
198.00002,164.99985,57.21881
198.30000,165.24991,57.17656
198.60000,165.49984,57.54284
198.90002,165.74990,57.31925
199.20002,165.99992,57.40765
199.50002,166.24991,57.64402
199.80000,166.49991,57.63648
200.10000,166.74984,57.57934
200.40002,166.99985,58.06920
200.70002,167.24991,57.94136
201.00002,167.49986,58.12971
201.30000,167.74997,58.07909
201.60000,167.99990,58.16881
201.90002,168.24992,58.23227
202.20002,168.49991,58.14770
202.50002,168.74991,58.56752
202.80000,168.99997,58.28024
203.10000,169.24985,58.49226
203.40002,169.49991,58.39372
203.70002,169.74991,58.57987
204.00002,169.99984,58.66562
204.30000,170.24990,58.81061
204.60000,170.49985,58.87059
204.90002,170.74991,58.66092
205.20002,170.99986,58.80949
205.50002,171.24984,58.71286
205.80000,171.49990,59.20139
206.10000,171.74983,59.18179
206.40002,171.99986,59.04704
206.70002,172.24992,59.25641
207.00002,172.49998,59.34167
207.30000,172.74993,59.37279
207.60000,172.99986,59.45119
207.90002,173.24992,59.49852
208.20002,173.49990,59.29140
208.50002,173.74985,59.58393
208.80000,173.99991,59.63062
209.10000,174.24991,59.80658
209.40002,174.49992,59.71001
209.70002,174.74985,59.76351
210.00002,174.99991,59.99685
210.30000,175.24991,59.59500
210.60000,175.49986,60.20956
210.90002,175.74990,59.96485
211.20002,175.99991,60.14610
211.50002,176.24991,60.22764
211.80000,176.49991,60.46789
212.10000,176.74992,60.42232
212.40002,176.99996,60.39718
212.70002,177.24991,60.53737
213.00002,177.49984,60.43849
213.30000,177.74992,60.61440
213.60000,177.99990,60.50370
213.90002,178.24985,60.86135
214.20002,178.49991,60.80510
214.50002,178.74992,60.93833
214.80000,178.99984,60.96009
215.10000,179.24991,61.04893
215.40002,179.49991,61.07808
215.70002,179.74991,61.17789
216.00002,179.99986,61.03741
216.30000,180.24990,61.34837
216.60000,180.49991,61.37076
216.90002,180.74991,61.29481
217.20002,180.99992,61.38531
217.50002,181.24992,61.39996
217.80000,181.49985,61.60777
218.10000,181.74985,61.72704
218.40002,181.99991,61.59571
218.70002,182.24992,61.53358
219.00002,182.49985,61.71032
219.30000,182.74991,61.68195
219.60000,182.99991,61.94058
219.90002,183.24992,62.03583
220.20002,183.49992,62.01138
220.50002,183.74985,62.22948
220.80000,183.99991,62.18474
221.10000,184.24990,62.15618
221.40002,184.49992,62.20111
221.70002,184.74991,62.26285
222.00002,184.99985,62.28848
222.30000,185.24984,62.32336
222.60000,185.49992,62.58051
222.90002,185.74992,62.47477
223.20002,185.99985,62.53529
223.50002,186.24986,62.61104
223.80000,186.49997,62.87534
224.10000,186.74992,62.93919
224.40002,186.99985,62.97285
224.70002,187.24985,63.06091
225.00002,187.49991,63.08507
225.30002,187.74997,62.99285
225.60000,187.99985,63.18140
225.90002,188.24991,63.15479
226.20002,188.49991,63.42116
226.50002,188.74984,63.28538
226.80002,188.99985,63.30488
227.10000,189.24991,63.28479
227.40002,189.49991,63.45330
227.70002,189.74984,63.22138
228.00002,189.99984,63.52621
228.30002,190.24990,63.68448
228.60000,190.49991,63.73162
228.90002,190.74984,63.67547
229.20002,190.99990,63.81923
229.50002,191.24992,63.71422
229.80002,191.49985,63.94938
230.10000,191.74978,63.97025
230.40002,191.99997,63.86309
230.70002,192.24998,63.92448
231.00002,192.49983,64.03659
231.30002,192.74991,64.13567
231.60000,192.99991,64.40164
231.90002,193.24990,64.30095
232.20002,193.49985,64.47338
232.50002,193.74983,64.50934
232.80002,193.99997,64.49303
233.10000,194.24984,64.48568
233.40002,194.49979,64.54242
233.70002,194.74998,64.62450
234.00002,194.99991,64.78781
234.30002,195.24992,64.81393
234.60000,195.49990,64.94250
234.90002,195.74990,64.92741
235.20002,195.99991,64.90933
235.50002,196.24986,65.19902
235.80002,196.49984,65.05511
236.10000,196.74990,65.28374
236.40002,196.99983,65.22616
236.70002,197.24991,65.40178
237.00002,197.49992,65.33494
237.30002,197.74990,65.42324
237.60000,197.99985,65.23792
237.90002,198.24991,65.39669
238.20002,198.49991,65.50404
238.50002,198.74984,65.45671
238.80002,198.99990,65.53736
239.10000,199.24991,65.91716
239.40002,199.49984,65.74277
239.70002,199.74984,65.80730
240.00002,199.99985,65.86977
240.30002,200.24991,66.05985
240.60000,200.49991,66.04770
240.90002,200.74992,66.03236
241.20002,200.99990,66.16260
241.50002,201.24985,66.08268
241.80002,201.49991,66.16613
242.10000,201.74991,66.25991
242.40002,201.99992,66.43523
242.70002,202.24985,66.34713
243.00002,202.49985,66.40309
243.30002,202.74997,66.41358
243.60000,202.99979,66.36389
243.90002,203.24990,66.42627
244.20002,203.49991,66.66941
244.50002,203.74984,66.74790
244.80002,203.99991,66.76486
245.10000,204.24984,66.77260
245.40002,204.49985,66.68229
245.70002,204.74991,66.95610
246.00002,204.99984,66.83067
246.30002,205.24992,66.93896
246.60000,205.49990,67.02769
246.90002,205.74985,67.16273
247.20002,205.99984,67.16616
247.50002,206.24990,67.20331
247.80002,206.49992,67.29263
248.10000,206.74979,67.47143
248.40002,206.99985,67.40195
248.70002,207.24989,67.50534
249.00002,207.49992,67.66160
249.30002,207.74985,67.55165
249.60000,207.99991,67.72369
249.90002,208.24984,67.68860
250.20002,208.49984,67.58722
250.50002,208.74992,67.78396
250.80002,208.99996,67.83776
251.10000,209.24991,68.04772
251.40002,209.49984,68.05816
251.70002,209.74990,68.13690
252.00002,209.99990,68.13176
252.30002,210.24985,68.16224
252.60000,210.49984,68.13274
252.90002,210.74984,68.20168
253.20002,210.99998,68.29669
253.50002,211.24985,68.22182
253.80002,211.49985,68.15753
254.10000,211.74990,68.39880
254.40002,211.99990,68.54438
254.70002,212.24990,68.35500
255.00002,212.49991,68.54546
255.30002,212.74997,68.67021
255.60000,212.99990,68.64091
255.90002,213.24985,68.75876
256.20002,213.49996,68.70897
256.50000,213.74991,69.03076
256.80002,213.99984,68.98411
257.10000,214.24985,69.07490
257.40003,214.49991,69.16428
257.70002,214.74991,69.12028
258.00000,214.99984,69.27370
258.30002,215.24990,69.33259
258.60000,215.49985,69.44388
258.90003,215.74991,69.50527
259.20002,215.99991,69.71337
259.50000,216.24984,69.37934
259.80002,216.49985,69.56917
260.10000,216.74991,69.54839
260.40003,216.99991,69.68848
260.70002,217.24997,69.77110
261.00000,217.49984,69.96577
261.30002,217.74990,69.95553
261.60000,217.99991,70.15741
261.90003,218.24991,70.11620
262.20000,218.49984,70.08151
262.50000,218.74985,70.25854
262.80003,218.99998,70.39300
263.10000,219.24991,70.31416
263.40003,219.49992,70.38164
263.70000,219.74990,70.51344
264.00000,219.99985,70.56827
264.30003,220.24991,70.66921
264.60000,220.49991,70.61085
264.90003,220.74997,70.86036
265.20000,220.99985,70.84846
265.50000,221.24983,70.97262
265.80003,221.49997,70.79838
266.10000,221.74992,71.04289
266.40003,221.99985,71.12173
266.70000,222.24991,71.24996
267.00000,222.49991,71.39157
267.30003,222.74991,71.36614
267.60000,222.99990,71.39534
267.90003,223.24996,71.43268
268.20000,223.49983,71.58365
268.50000,223.74984,71.55592
268.80003,223.99992,71.65597
269.10000,224.24990,71.80375
269.40003,224.49985,71.69007
269.70000,224.74989,71.97133
270.00000,224.99992,71.96134
270.30003,225.24990,71.92302
270.60000,225.49985,72.01064
270.90003,225.74984,72.09678
271.20000,225.99984,72.38293
271.50000,226.24992,72.25328
271.80003,226.49990,72.42929
272.10000,226.74991,72.27896
272.40003,226.99989,72.53239
272.70000,227.24992,72.62196
273.00000,227.49985,72.60814
273.30003,227.74991,72.62166
273.60000,227.99991,72.69433
273.90003,228.24984,72.85407
274.20000,228.49992,72.84089
274.50000,228.74990,72.77175
274.80003,228.99991,72.90204
275.10000,229.24984,73.02385
275.40003,229.49997,73.08794
275.70000,229.74990,73.20770
276.00000,229.99991,73.25690
276.30003,230.24991,73.15076
276.60000,230.49990,73.23779
276.90003,230.74985,73.48871
277.20000,230.99991,73.52919
277.50000,231.24991,73.48592
277.80003,231.49990,73.58608
278.10000,231.74984,73.62503
278.40003,231.99990,73.95608
278.70000,232.24991,73.68677
279.00000,232.49984,73.81926
279.30003,232.74990,73.98719
279.60000,232.99992,73.91874
279.90003,233.24991,73.93721
280.20000,233.49985,73.91550
280.50000,233.74984,74.26364
280.80003,233.99990,74.18618
281.10000,234.24990,74.18471
281.40003,234.49991,74.43725
281.70000,234.74991,74.37732
282.00000,234.99990,74.51521
282.30003,235.24992,74.51854
282.60000,235.49991,74.38943
282.90003,235.74991,74.76403
283.20000,235.99990,74.66280
283.50000,236.24985,74.64070
283.80003,236.49991,74.78750
284.10000,236.74991,74.63031
284.40003,236.99984,74.88658
284.70000,237.24990,74.93813
285.00000,237.49990,74.98473
285.30003,237.74991,75.21797
285.60000,237.99991,75.16338
285.90003,238.24984,75.33155
286.20000,238.49990,75.17122
286.50000,238.74991,75.33429
286.80003,238.99991,75.45998
287.10000,239.24997,75.61609
287.40003,239.49990,75.50442
287.70000,239.74990,75.71444
288.00000,239.99983,75.92107
288.30003,240.24997,75.57895
288.60000,240.49990,75.83596
288.90003,240.74990,75.73345
289.20000,240.99983,75.86354
289.50000,241.24991,76.09296
289.80003,241.49992,76.14583
290.10000,241.74990,76.07723
290.40003,241.99991,76.11241
290.70000,242.24984,76.26887
291.00000,242.49991,76.52523
291.30003,242.74990,76.52229
291.60000,242.99996,76.57291
291.90003,243.24983,76.66062
292.20000,243.49984,76.74833
292.50000,243.74992,76.59476
292.80003,243.99996,76.55512
293.10000,244.24985,76.66489
293.40003,244.49991,76.65734
293.70000,244.74997,76.68781
294.00000,244.99984,76.96525
294.30003,245.24985,76.74475
294.60000,245.49983,76.98931
294.90003,245.74991,77.09049
295.20000,245.99984,76.91478
295.50000,246.24985,77.15018
295.80003,246.49991,77.33015
296.10000,246.74984,77.19756
296.40003,246.99984,77.06315
296.70000,247.24998,77.21804
297.00000,247.49991,77.42904
297.30003,247.74991,77.52204
297.60000,247.99984,77.67737
297.90003,248.24992,77.58118
298.20000,248.49990,77.57040
298.50000,248.74985,77.91370
298.80003,248.99989,78.02277
299.10000,249.24992,77.91296
299.40003,249.49990,78.07206
299.70000,249.74991,78.09828
300.00000,249.99991,78.22088
300.30003,250.24995,78.13664
300.60000,250.49984,78.03031
300.90003,250.74989,78.00709
301.20000,250.99991,78.17633
301.50000,251.24988,78.14948
301.80003,251.49990,78.32284
302.10000,251.74985,78.23259
302.40003,251.99994,78.40658
302.70000,252.24989,78.42084
303.00000,252.49988,78.56049
303.30003,252.74990,78.45725
303.60000,252.99985,78.49464
303.90003,253.24984,78.59494
304.20000,253.49995,78.75870
304.50000,253.74992,78.88977
304.80003,253.99989,78.75497
305.10000,254.24991,78.85410
305.40003,254.49989,79.03378
305.70000,254.74990,79.03167
306.00000,254.99990,79.25565
306.30003,255.24983,79.27623
306.60000,255.49991,79.38448
306.90003,255.74988,79.32920
307.20000,255.99990,79.52006
307.50000,256.24996,79.46870
307.80003,256.49989,79.62987
308.10000,256.74989,79.51937
308.40003,256.99988,79.54990
308.70000,257.24996,79.65118
309.00000,257.49991,79.44406
309.30003,257.74989,79.72463
309.60000,257.99990,79.79798
309.90003,258.24988,79.78539
310.20000,258.49983,79.85757
310.50000,258.74991,79.78358
310.80003,258.99990,79.88834
311.10000,259.24990,79.91269
311.40003,259.49983,80.00550
311.70000,259.74995,80.02779
312.00000,259.99991,79.93126
312.30003,260.24982,80.15676
312.60000,260.49985,80.12560
312.90003,260.74991,80.26049
313.20000,260.99989,80.38833
313.50000,261.24990,80.24413
313.80003,261.49988,80.22634
314.10000,261.74990,80.09306
314.40003,261.99991,80.39357
314.70000,262.24989,80.31371
315.00000,262.49990,80.42425
315.30003,262.74994,80.46894
315.60000,262.99983,80.69106
315.90003,263.24986,80.70286
316.20000,263.49995,80.70262
316.50000,263.74990,80.57106
316.80003,263.99989,80.89425
317.10000,264.24989,80.70551
317.40003,264.49991,81.04052
317.70000,264.74988,80.82585
318.00000,264.99985,80.63279
318.30003,265.24996,80.55915
318.60000,265.49989,80.80586
318.90003,265.74990,80.84829
319.20000,265.99994,80.85844
319.50000,266.24996,80.45179
319.80003,266.49991,80.67694
320.10000,266.74984,80.62280
320.40003,266.99996,80.62402
320.70000,267.24994,80.83986
321.00000,267.49983,80.84756
321.30003,267.74997,80.89244
321.60000,267.99990,81.14156
321.90003,268.24990,81.13950
322.20000,268.49983,81.15930
322.50003,268.74989,81.18728
322.80003,268.99992,81.31908
323.10000,269.24983,81.39411
323.40003,269.49991,81.42772
323.70000,269.74989,81.25009
324.00003,269.99990,81.46383
324.30003,270.24984,81.52165
324.60000,270.49994,81.57977
324.90003,270.74996,81.53008
325.20000,270.99982,81.50592
325.50003,271.24990,81.59343
325.80003,271.49990,81.54003
326.10000,271.74983,81.65493
326.40003,271.99984,81.46937
326.70000,272.24988,81.58290
327.00003,272.49996,81.79458
327.30003,272.74990,81.66277
327.60000,272.99989,81.45109
327.90003,273.24989,81.28327
328.20000,273.49992,80.81978
328.50003,273.74983,0.09081
328.80003,273.99991,0.05137
329.10000,274.24995,-0.03536
329.34600,274.45490,0.10929