File: V_8/NR/RDSO NR Tensile 50.is_tens_RawData/Specimen_RawData_3.csv
Time,Extension,Load
(sec),(mm),(N)
0.00000,0.00000,0.14143
0.10000,0.07569,0.49340
0.20000,0.16469,0.45282
0.30000,0.24931,0.83674
0.40000,0.33294,0.90568
0.50000,0.41675,1.03136
0.60000,0.50000,1.23623
0.70000,0.58331,1.58786
0.80000,0.66675,1.61740
0.90000,0.74994,1.69654
1.00000,0.83325,1.82678
1.10000,0.91675,1.88754
1.20000,0.99994,2.09990
1.30000,1.08331,2.29389
1.40000,1.16681,2.61411
1.50000,1.25000,2.59544
1.60000,1.33325,2.55139
1.70000,1.41675,2.87670
1.80000,1.49994,2.85627
1.90000,1.58325,3.02120
2.00000,1.66669,3.14174
2.10000,1.75000,3.33534
2.20000,1.83331,3.36366
2.30000,1.91675,3.56456
2.40000,2.00000,3.46254
2.50000,2.08331,3.86135
2.60000,2.16681,3.97782
2.70000,2.25000,4.03819
2.80000,2.33331,4.05064
2.90000,2.41675,4.35703
3.00000,2.49994,4.45503
3.10000,2.58325,4.33386
3.20000,2.66669,4.52785
3.30000,2.75000,4.71865
3.40000,2.83325,4.68876
3.50000,2.91675,4.82047
3.60000,3.00000,4.95057
3.70000,3.08331,5.02069
3.80000,3.16675,5.21335
3.90000,3.24994,5.35859
4.00000,3.33331,5.31900
4.10000,3.41675,5.42342
4.20000,3.49987,5.38309
4.30000,3.58325,5.58624
4.40000,3.66681,5.86829
4.50000,3.75000,5.81517
4.60000,3.83331,5.98569
4.70000,3.91681,6.08977
4.80000,3.99994,6.06693
4.90000,4.08325,6.16116
5.00000,4.16669,6.39636
5.10000,4.24994,6.33271
5.20000,4.33331,6.41429
5.30000,4.41675,6.56080
5.40000,4.49994,6.66400
5.50000,4.58325,6.67526
5.60000,4.66681,6.67531
5.70000,4.75000,6.81340
5.80000,4.83325,6.94050
5.90000,4.91681,7.03154
6.00000,5.00000,7.27875
6.10000,5.08319,7.19648
6.20000,5.16669,7.47739
6.30000,5.25000,7.36567
6.40000,5.33325,7.46700
6.50000,5.41675,7.50699
6.60000,5.50000,7.56216
6.70000,5.58331,7.57162
6.80000,5.66681,7.71274
6.90000,5.74994,7.73704
7.00000,5.83325,7.77516
7.10000,5.91675,8.02898
7.20000,5.99994,7.85155
7.30000,6.08325,8.16461
7.40000,6.16675,8.36292
7.50000,6.25000,8.37301
7.60000,6.33325,7.99650
7.70000,6.41669,8.24061
7.80000,6.50000,8.35464
7.90000,6.58331,8.58420
8.00000,6.66675,8.57553
8.10000,6.75000,8.38595
8.20000,6.83331,8.60561
8.30000,6.91681,8.62169
8.40000,6.99994,8.83856
8.50000,7.08325,8.89148
8.60000,7.16669,8.89251
8.70000,7.24994,9.05925
8.80000,7.33325,9.04803
8.90000,7.41681,8.97267
9.00000,7.50006,8.98183
9.10000,7.58331,8.92274
9.20000,7.66675,9.05925
9.30000,7.74994,9.34002
9.40000,7.83319,9.13819
9.50000,7.91669,9.26319
9.60000,7.99994,9.33096
9.70000,8.08331,9.36913
9.80000,8.16681,9.62148
9.90000,8.25000,9.60962
10.00000,8.33325,9.56239
10.10000,8.41681,9.61148
10.20000,8.49994,9.82052
10.30000,8.58319,9.86648
10.40000,8.66675,9.90921
10.50000,8.75000,9.91616
10.60000,8.83325,9.87138
10.70000,8.91675,10.06586
10.80000,9.00000,9.89112
10.90000,9.08331,10.10609
11.00000,9.16675,10.01691
11.10000,9.25000,10.28445
11.20000,9.33331,10.08492
11.30000,9.41681,10.01451
11.40000,9.49994,10.32370
11.50000,9.58325,10.39185
11.60000,9.66675,10.36574
11.70000,9.74994,10.35868
11.80000,9.83325,10.25598
11.90000,9.91675,10.38357
12.00000,10.00006,10.36770
12.10000,10.08331,10.56482
12.20000,10.16675,10.58384
12.30000,10.25000,10.55071
12.40000,10.33325,10.83168
12.50000,10.41675,10.64102
12.60000,10.49994,10.81281
12.70000,10.58325,10.68845
12.80000,10.66675,10.81565
12.90000,10.74994,11.11245
13.00000,10.83325,11.00234
13.10000,10.91675,10.97873
13.20000,11.00000,11.00528
13.30000,11.08331,11.03983
13.40000,11.16669,11.19947
13.50000,11.25000,11.00915
13.60000,11.33325,11.16919
13.70000,11.41669,11.21770
13.80000,11.49994,11.28728
13.90000,11.58325,11.17575
14.00000,11.66675,11.30105
14.10000,11.75000,11.29801
14.20000,11.83331,11.40551
14.30000,11.91681,11.36195
14.40000,11.99994,11.41899
14.50000,12.08325,11.52395
14.60000,12.16669,11.31712
14.70000,12.24994,11.57241
14.80000,12.33325,11.50792
14.90000,12.41675,11.75283
15.00000,12.49994,11.87704
15.10000,12.58331,11.60068
15.20000,12.66675,11.84186
15.30000,12.74994,11.76155
15.40000,12.83325,11.64223
15.50000,12.91675,11.87562
15.60000,12.99994,11.95784
15.70000,13.08325,11.92300
15.80000,13.16681,11.91908
15.90000,13.25000,11.87934
16.00000,13.33319,11.59725
16.10000,13.41675,11.84798
16.20000,13.49994,12.06495
16.30000,13.58331,12.01703
16.40000,13.66675,11.75797
16.50000,13.75000,11.88508
16.60000,13.83331,12.07838
16.70000,13.91675,12.24140
16.80000,13.99994,12.12081
16.90000,14.08325,12.14115
17.00000,14.16675,11.98763
17.10000,14.25000,12.10896
17.20000,14.33325,12.45519
17.30000,14.41675,12.29133
17.40000,14.50000,12.33308
17.50000,14.58325,12.40330
17.60000,14.66669,12.27864
17.70000,14.75000,12.06780
17.80000,14.83325,12.30064
17.90000,14.91669,12.44544
18.00000,15.00000,12.36650
18.10000,15.08319,12.40761
18.20000,15.16675,12.32044
18.30000,15.24994,12.48723
18.40000,15.33331,12.26316
18.50000,15.41681,12.44740
18.60000,15.50000,12.53344
18.70000,15.58325,12.66981
18.80000,15.66668,12.82362
18.90000,15.74993,12.54804
19.00000,15.83318,12.50777
19.10000,15.91668,12.71092
19.20000,15.99994,12.51487
19.30000,16.08337,12.60508
19.40000,16.16675,12.77530
19.50000,16.25000,12.71200
19.60000,16.33325,12.75820
19.70000,16.41675,12.63046
19.80000,16.49993,12.72258
19.90000,16.58325,12.87218
20.00000,16.66675,12.80078
20.10000,16.75000,12.62140
20.20000,16.83325,12.70323
20.30000,16.91675,12.84082
20.40000,16.99993,12.79917
20.50000,17.08325,12.79441
20.60000,17.16675,12.88129
20.70000,17.25000,12.84400
20.80000,17.33337,12.90951
20.90000,17.41681,12.79760
21.00000,17.50000,12.94024
21.10000,17.58325,12.89398
21.20000,17.66675,12.90951
21.30000,17.74994,13.02746
21.40000,17.83318,13.05019
21.50000,17.91681,13.09376
21.60000,18.00000,12.76359
21.70000,18.08331,13.27349
21.80000,18.16681,13.00374
21.90000,18.24994,13.07082
22.00000,18.33325,13.18347
22.10000,18.41675,13.35845
22.20000,18.49993,13.41377
22.30000,18.58325,13.26094
22.40000,18.66675,13.16814
22.50000,18.74994,13.17544
22.60000,18.83331,13.51212
22.70000,18.91675,13.47017
22.80000,18.99993,13.19489
22.90000,19.08325,13.12585
23.00000,19.16675,13.24291
23.10000,19.25006,13.40030
23.20000,19.33325,13.28020
23.30000,19.41668,13.30499
23.40000,19.49994,13.22703
23.50000,19.58325,13.54343
23.60000,19.66669,13.56567
23.70000,19.75000,13.21767
23.80000,19.83325,13.19058
23.90000,19.91681,13.49629
24.00000,20.00000,13.62932
24.10000,20.08325,13.22017
24.20000,20.16675,13.65201
24.30000,20.24994,13.49384
24.40000,20.33325,13.83400
24.50000,20.41668,13.44214
24.60000,20.50000,13.52187
24.70000,20.58331,13.53573
24.80000,20.66675,13.73663
24.90000,20.74993,13.63986
25.00000,20.83331,13.59865
25.10000,20.91675,13.47767
25.20000,20.99993,13.56925
25.30000,21.08331,13.64280
25.40000,21.16668,13.76329
25.50000,21.25000,13.83101
25.60000,21.33325,13.67862
25.70000,21.41668,13.78838
25.80000,21.50000,13.89642
25.90000,21.58331,13.74736
26.00000,21.66675,13.72629
26.10000,21.75000,14.01941
26.20000,21.83331,13.82420
26.30000,21.91675,13.76231
26.40000,21.99993,13.68729
26.50000,22.08325,13.75760
26.60000,22.16675,13.99182
26.70000,22.24993,13.75457
26.80000,22.33318,13.91225
26.90000,22.41687,13.75491
27.00000,22.50000,13.96355
27.10000,22.58325,13.94963
27.20000,22.66675,13.93655
27.30000,22.75000,13.98746
27.40000,22.83331,13.87511
27.50000,22.91675,14.12197
27.60000,22.99994,14.05538
27.70000,23.08325,13.91137
27.80000,23.16675,13.98707
27.90000,23.24993,13.99721
28.00000,23.33325,14.11873
28.10000,23.41675,14.17288
28.20000,23.50000,13.94047
28.30000,23.58331,14.13294
28.40000,23.66681,14.11486
28.50000,23.75000,14.14568
28.60000,23.83331,14.26343
28.70000,23.91675,14.05817
28.80000,23.99993,14.10972
28.90000,24.08325,14.04308
29.00000,24.16662,14.18885
29.10000,24.24994,14.15244
29.20000,24.33331,14.33022
29.30000,24.41681,14.10526
29.40000,24.50000,14.06253
29.50000,24.58331,14.25505
29.60000,24.66675,14.27808
29.70000,24.74993,14.39509
29.80000,24.83318,14.40440
29.90000,24.91675,14.12501
30.00000,24.99999,14.32718
30.10000,25.08325,14.36809
30.20000,25.16681,14.46511
30.30000,25.25000,14.38632
30.40000,25.33331,14.30434
30.50000,25.41675,14.41386
30.60000,25.49993,14.39975
30.70000,25.58324,14.56341
30.80000,25.66675,14.38338
30.90000,25.74987,14.41254
31.00000,25.83325,14.48339
31.10000,25.91675,14.54832
31.20000,25.99993,14.53043
31.30000,26.08325,14.42136
31.40000,26.16681,14.43983
31.50000,26.25000,14.39254
31.60000,26.33331,14.43380
31.70000,26.41669,14.36437
31.80000,26.49993,14.55684
31.90000,26.58325,14.57419
32.00000,26.66668,14.64558
32.10000,26.74993,14.46506
32.20000,26.83325,14.51980
32.30000,26.91675,14.61491
32.40000,27.00000,14.76975
32.50000,27.08325,14.59487
32.60000,27.16674,14.74529
32.70000,27.24993,14.62275
32.80000,27.33325,14.47628
32.90000,27.41675,14.85295
33.00000,27.49993,14.61677
33.10000,27.58331,14.67248
33.20000,27.66675,14.64249
33.30000,27.74999,14.89852
33.40000,27.83331,14.70786
33.50000,27.91675,14.82580
33.60000,28.00000,14.81585
33.70000,28.08325,14.85878
33.80000,28.16675,14.89274
33.90000,28.24993,14.79194
34.00000,28.33318,14.86299
34.10000,28.41668,14.81958
34.20000,28.50000,14.91861
34.30000,28.58325,14.94482
34.40000,28.66675,14.85496
34.50000,28.75006,14.86177
34.60000,28.83331,14.84334
34.70000,28.91675,14.94712
34.80000,28.99993,14.90004
34.90000,29.08325,14.89798
35.00000,29.16675,15.11167
35.10000,29.25000,14.96104
35.20000,29.33325,15.10392
35.30000,29.41675,14.89803
35.40000,29.50000,15.08726
35.50000,29.58325,15.00367
35.60000,29.66668,15.14312
35.70000,29.75000,15.21319
35.80000,29.83331,15.10138
35.90000,29.91674,15.11176
36.00000,30.00000,15.06409
36.10000,30.08325,15.18654
36.20000,30.16675,15.11260
36.30000,30.24993,15.32482
36.40000,30.33325,15.12887
36.50000,30.41681,15.16757
36.60000,30.49993,15.18874
36.70000,30.58331,15.30120
36.80000,30.66681,15.22633
36.90000,30.75000,15.34295
37.00000,30.83325,15.51048
37.10000,30.91675,15.24078
37.20000,30.99993,15.43222
37.30000,31.08324,15.31771
37.40000,31.16668,15.22736
37.50000,31.24993,15.57030
37.60000,31.33331,15.36490
37.70000,31.41674,15.28669
37.80000,31.49999,15.34721
37.90000,31.58325,15.30845
38.00000,31.66681,15.17199
38.10000,31.74993,15.38881
38.20000,31.83324,15.65302
38.30000,31.91675,15.34290
38.40000,31.99999,15.65885
38.50000,32.08318,15.51204
38.60000,32.16675,15.62220
38.70000,32.24999,15.49093
38.80000,32.33337,15.46647
38.90000,32.41681,15.50925
39.00000,32.50000,15.48318
39.10000,32.58324,15.51449
39.20000,32.66662,15.65694
39.30000,32.74987,15.67624
39.40000,32.83324,15.67796
39.50000,32.91681,15.62910
39.60000,33.00000,15.76150
39.70000,33.08331,15.71770
39.80000,33.16681,15.61146
39.90000,33.24999,15.71642
40.00000,33.33318,15.61808
40.10000,33.41675,15.51783
40.20000,33.49999,15.66091
40.30000,33.58331,15.90654
40.40000,33.66675,15.75626
40.50000,33.74999,15.96524
40.60000,33.83331,15.82844
40.70000,33.91674,15.84784
40.80000,33.99987,15.90527
40.90000,34.08324,15.79904
41.00000,34.16675,15.86141
41.10000,34.25000,15.71510
41.20000,34.33331,16.00121
41.30000,34.41674,16.01694
41.40000,34.49999,16.01905
41.50000,34.58318,16.13620
41.60000,34.66668,15.79614
41.70000,34.75000,15.87680
41.80000,34.83331,15.99807
41.90000,34.91674,15.77267
42.00000,34.99999,15.96309
42.10000,35.08331,16.05898
42.20000,35.16675,16.09509
42.30000,35.24993,16.17658
42.40000,35.33318,16.07687
42.50000,35.41674,16.12185
42.60000,35.49999,16.15718
42.70000,35.58324,16.11019
42.80000,35.66675,16.02512
42.90000,35.74993,16.19152
43.00000,35.83324,16.07579
43.10000,35.91675,16.37875
43.20000,35.99993,16.14238
43.30000,36.08331,16.02909
43.40000,36.16675,16.16595
43.50000,36.25000,16.21813
43.60000,36.33325,16.27267
43.70000,36.41674,16.15722
43.80000,36.49993,16.27262
43.90000,36.58318,16.04007
44.00000,36.66674,16.40007
44.10000,36.74999,16.23935
44.20000,36.83325,16.40115
44.30000,36.91674,16.48709
44.40000,36.99999,16.26086
44.50000,37.08331,16.71004
44.60000,37.16668,16.45808
44.70000,37.24999,16.23896
44.80000,37.33318,16.45852
44.90000,37.41675,16.37998
45.00000,37.49993,16.46004
45.10000,37.58324,16.48719
45.20000,37.66675,16.55187
45.30000,37.74999,16.22641
45.40000,37.83331,16.38321
45.50000,37.91675,16.49645
45.60000,38.00000,16.59176
45.70000,38.08324,16.64022
45.80000,38.16668,16.56559
45.90000,38.24993,16.62488
46.00000,38.33324,16.68657
46.10000,38.41668,16.49576
46.20000,38.49993,16.63635
46.30000,38.58331,16.46641
46.40000,38.66687,16.58602
46.50000,38.74999,16.61312
46.60000,38.83325,16.60258
46.70000,38.91675,16.83342
46.80000,38.99993,16.81632
46.90000,39.08318,16.58480
47.00000,39.16674,16.69774
47.10000,39.24999,16.58343
47.20000,39.33331,16.83401
47.30000,39.41681,16.81078
47.40000,39.49993,16.76291
47.50000,39.58330,16.98170
47.60000,39.66675,16.91618
47.70000,39.74993,16.85062
47.80000,39.83324,17.16496
47.90000,39.91674,16.91707
48.00000,39.99993,16.83631
48.10000,40.08318,16.91016
48.20000,40.16674,16.92407
48.30000,40.24993,16.93838
48.40000,40.33324,17.04750
48.50000,40.41674,17.11699
48.60000,40.49993,16.89663
48.70000,40.58330,16.83362
48.80000,40.66675,16.95230
48.90000,40.74993,17.04922
49.00000,40.83325,17.20572
49.10000,40.91668,17.09596
49.20000,40.99993,17.04074
49.30000,41.08324,17.13948
49.40000,41.16674,17.08195
49.50000,41.25000,16.93804
49.60000,41.33331,17.08484
49.70000,41.41680,17.10939
49.80000,41.50006,17.16260
49.90000,41.58324,17.09141
50.00000,41.66668,17.10282
50.10000,41.74993,17.15452
50.20000,41.83325,17.23684
50.30000,41.91674,17.16020
50.40000,41.99999,16.99370
50.50000,42.08324,16.96665
50.60000,42.16681,17.30480
50.70000,42.24999,17.24267
50.80000,42.33324,17.29461
50.90000,42.41674,17.33356
51.00000,42.49993,17.65990
51.10000,42.58318,17.31901
51.20000,42.66674,17.19558
51.30000,42.74993,17.31205
51.40000,42.83324,17.24566
51.50000,42.91675,17.40525
51.60000,42.99999,17.37487
51.70000,43.08330,17.67945
51.80000,43.16681,17.50683
51.90000,43.24999,17.51658
52.00000,43.33324,17.31078
52.10000,43.41675,17.65314
52.20000,43.50000,17.36801
52.30000,43.58324,17.64246
52.40000,43.66674,17.60537
52.50000,43.75000,17.59562
52.60000,43.83324,17.65535
52.70000,43.91674,17.64565
52.80000,44.00000,17.40305
52.90000,44.08325,17.85017
53.00000,44.16674,17.41535
53.10000,44.24999,17.55220
53.20000,44.33331,17.61737
53.30000,44.41674,17.78623
53.40000,44.49993,17.69195
53.50000,44.58318,17.76790
53.60000,44.66674,17.83704
53.70000,44.74993,17.70224
53.80000,44.83324,17.69195
53.90000,44.91674,17.67063
54.00000,44.99999,17.61512
54.10000,45.08324,17.93876
54.20000,45.16675,17.99457
54.30000,45.24993,17.90627
54.40000,45.33324,17.75771
54.50000,45.41674,17.81690
54.60000,45.49993,17.91759
54.70000,45.58331,17.89692
54.80000,45.66681,17.67656
54.90000,45.75000,18.05582
55.00000,45.83324,18.01785
55.10000,45.91674,17.93592
55.20000,45.99999,17.99903
55.30000,46.08324,18.03274
55.40000,46.16668,18.00731
55.50000,46.24999,17.89633
55.60000,46.33325,18.33184
55.70000,46.41668,18.11492
55.80000,46.49999,18.12751
55.90000,46.58324,17.94160
56.00000,46.66674,17.93092
56.10000,46.75000,17.96458
56.20000,46.83331,18.27671
56.30000,46.91674,18.20576
56.40000,46.99999,18.17945
56.50000,47.08318,17.98541
56.60000,47.16674,18.18974
56.70000,47.24999,18.12702
56.80000,47.33324,18.12976
56.90000,47.41680,18.17533
57.00000,47.49999,18.06513
57.10000,47.58331,18.38221
57.20000,47.66674,18.49893
57.30000,47.74993,18.26392
57.40000,47.83330,18.33424
57.50000,47.91674,18.12991
57.60000,47.99993,18.25471
57.70000,48.08324,18.37466
57.80000,48.16674,18.32571
57.90000,48.24999,18.50500
58.00000,48.33324,18.53538
58.10000,48.41674,18.28088
58.20000,48.49999,18.45698
58.30000,48.58330,18.38510
58.40000,48.66675,18.41401
58.50000,48.74999,18.34669
58.60000,48.83324,18.50020
58.70000,48.91668,18.38843
58.80000,48.99993,18.31361
58.90000,49.08324,18.64725
59.00000,49.16681,18.45130
59.10000,49.25000,18.69576
59.20000,49.33331,18.77078
59.30000,49.41680,18.53759
59.40000,49.50000,18.49099
59.50000,49.58318,18.55915
59.60000,49.66668,18.62618
59.70000,49.74993,18.81463
59.80000,49.83330,18.54063
59.90000,49.91674,18.68640
60.00000,49.99999,18.73094
60.10000,50.08331,18.81160
60.20000,50.16681,18.85511
60.30000,50.24987,18.79910
60.40000,50.33324,18.93184
60.50000,50.41681,18.80768
60.60000,50.49993,18.57110
60.70000,50.58330,18.70507
60.80000,50.66680,18.84702
60.90000,50.74993,18.98055
61.00000,50.83318,18.90318
61.10000,50.91668,19.01122
61.20000,50.99993,18.86133
61.30000,51.08324,18.85638
61.40000,51.16674,18.86432
61.50000,51.24999,18.95683
61.60000,51.33331,19.02225
61.70000,51.41674,18.87980
61.80000,51.49993,18.86858
61.90000,51.58318,19.13803
62.00000,51.66674,19.10966
62.10000,51.74999,18.90122
62.20000,51.83324,19.03949
62.30000,51.91681,18.85795
62.40000,52.00006,19.09579
62.50000,52.08324,18.93233
62.60000,52.16674,18.90999
62.70000,52.24999,19.09452
62.80000,52.33324,19.00005
62.90000,52.41668,19.26259
63.00000,52.49993,19.19179
63.10000,52.58324,19.30493
63.20000,52.66674,18.96521
63.30000,52.74993,19.29179
63.40000,52.83324,19.16606
63.50000,52.91680,19.16361
63.60000,52.99999,19.24730
63.70000,53.08331,19.33491
63.80000,53.16680,19.23388
63.90000,53.24999,19.34893
64.00000,53.33324,19.33565
64.10001,53.41668,19.13156
64.20000,53.49993,19.48583
64.30000,53.58324,19.36662
64.40000,53.66674,19.39817
64.50000,53.74999,19.35853
64.60001,53.83330,19.53238
64.70000,53.91681,19.40214
64.80000,53.99999,19.50161
64.90000,54.08324,19.50828
65.00000,54.16675,19.67576
65.10001,54.24999,19.38431
65.20000,54.33318,19.38695
65.30000,54.41674,19.58124
65.40000,54.49999,19.29047
65.50000,54.58324,19.51337
65.60001,54.66674,19.45874
65.70001,54.75000,19.56561
65.80000,54.83324,19.57830
65.90000,54.91674,19.55615
66.00000,55.00000,19.77694
66.10001,55.08318,19.62004
66.20001,55.16674,19.64121
66.30000,55.24993,19.64734
66.40000,55.33325,19.69261
66.50000,55.41674,19.61897
66.60001,55.50005,19.43223
66.70001,55.58331,19.79669
66.80000,55.66674,19.84206
66.90000,55.74999,19.92316
67.00000,55.83331,19.60868
67.10001,55.91668,19.67042
67.20001,55.99987,19.85250
67.30000,56.08324,19.61377
67.40000,56.16674,19.83604
67.50000,56.24993,19.61132
67.60001,56.33330,20.03811
67.70001,56.41674,20.03164
67.80000,56.49999,20.02312
67.90000,56.58324,19.83182
68.00000,56.66674,19.91728
68.10001,56.74999,19.99906
68.20001,56.83324,19.96633
68.30000,56.91674,19.78434
68.40000,56.99993,20.01131
68.50000,57.08324,20.22671
68.60001,57.16674,20.03850
68.70001,57.24993,19.97446
68.80000,57.33324,20.01391
68.90000,57.41687,20.06967
69.00000,57.49993,20.03894
69.10001,57.58324,20.30438
69.20001,57.66674,20.16664
69.30000,57.74999,20.16708
69.40000,57.83324,20.13748
69.50000,57.91674,20.26699
69.60001,57.99993,20.17369
69.70001,58.08318,20.16517
69.80000,58.16674,20.24337
69.90000,58.24999,20.33373
70.00000,58.33331,20.17801
70.10001,58.41680,20.20692
70.20001,58.49999,20.32770
70.30000,58.58324,20.27718
70.40000,58.66680,20.34446
70.50000,58.74987,20.44510
70.60001,58.83324,20.30031
70.70001,58.91674,20.40840
70.80000,58.99999,20.42879
70.90000,59.08324,20.34911
71.00000,59.16681,20.32525
71.10001,59.24999,20.49366
71.20001,59.33330,20.27566
71.30000,59.41668,20.53909
71.40000,59.49993,20.48700
71.50000,59.58318,20.47700
71.60001,59.66668,20.42300
71.70001,59.74993,20.33260
71.80000,59.83324,20.47377
71.90000,59.91681,20.47504
72.00000,59.99999,20.56025
72.10001,60.08324,20.61989
72.20001,60.16674,20.53095
72.30000,60.25000,20.55565
72.40000,60.33324,20.59161
72.50000,60.41668,20.75027
72.60001,60.50000,20.66286
72.70001,60.58331,20.72288
72.80000,60.66668,20.60582
72.90000,60.74993,20.66075
73.00000,60.83325,20.72298
73.10001,60.91674,20.59117
73.20001,60.99993,20.68354
73.30000,61.08331,20.78624
73.40000,61.16674,20.80197
73.50000,61.24999,20.65722
73.60001,61.33324,20.59039
73.70001,61.41668,20.77051
73.80000,61.49993,20.64223
73.90000,61.58324,20.92138
74.00000,61.66674,20.82863
74.10001,61.74999,21.06172
74.20001,61.83330,20.82294
74.30000,61.91680,21.04614
74.40000,61.99993,20.86782
74.50000,62.08318,21.08700
74.60001,62.16674,20.83892
74.70001,62.24993,21.03158
74.80000,62.33318,20.98930
74.90000,62.41681,20.84578
75.00000,62.49999,20.86689
75.10001,62.58324,21.23988
75.20001,62.66681,20.96862
75.30000,62.74993,21.12596
75.40000,62.83324,20.88723
75.50000,62.91674,20.99518
75.60001,62.99999,20.91491
75.70001,63.08330,21.11895
75.80000,63.16674,21.06113
75.90000,63.24993,21.05187
76.00000,63.33324,21.23988
76.10001,63.41674,21.09200
76.20001,63.49999,21.05064
76.30000,63.58324,21.05819
76.40000,63.66680,21.12199
76.50000,63.74999,21.24008
76.60001,63.83324,21.19382
76.70001,63.91668,21.19794
76.80000,63.99999,21.39727
76.90000,64.08324,21.18500
77.00000,64.16674,21.45230
77.10001,64.24999,21.32504
77.20001,64.33330,21.16481
77.30000,64.41674,21.47003
77.40000,64.49999,21.47822
77.50000,64.58324,21.16633
77.60001,64.66674,21.23194
77.70001,64.74993,21.38600
77.80000,64.83324,21.43965
77.90000,64.91674,21.45925
78.00000,64.99999,21.53662
78.10001,65.08324,21.46832
78.20001,65.16674,21.68833
78.30000,65.24993,21.65741
78.40000,65.33330,21.57284
78.50000,65.41674,21.38272
78.60001,65.49999,21.68220
78.70001,65.58330,21.64045
78.80000,65.66674,21.42593
78.90000,65.74993,21.43524
79.00000,65.83324,21.43608
79.10001,65.91674,21.55573
79.20001,65.99986,21.74664
79.30000,66.08331,21.63521
79.40000,66.16674,21.68240
79.50000,66.25005,21.72498
79.60001,66.33330,21.76844
79.70001,66.41674,21.56289
79.80000,66.49998,21.83641
79.90000,66.58318,21.82420
80.00000,66.66674,21.59067
80.10001,66.74992,21.63923
80.20001,66.83331,21.91975
80.30000,66.91680,21.82239
80.40000,66.99999,21.69318
80.50001,67.08324,21.79378
80.60001,67.16674,21.92691
80.70001,67.24992,21.99468
80.80000,67.33330,21.82494
80.90000,67.41680,21.77937
81.00001,67.49999,22.07778
81.10001,67.58330,21.76746
81.20001,67.66674,21.96773
81.30000,67.74993,21.99100
81.40000,67.83324,22.01986
81.50001,67.91674,21.90986
81.60001,67.99999,22.14991
81.70001,68.08330,22.11718
81.80000,68.16680,22.10463
81.90000,68.24999,22.03265
82.00001,68.33324,21.95219
82.10001,68.41674,22.31347
82.20001,68.49999,22.25697
82.30000,68.58324,22.00844
82.40000,68.66674,22.06249
82.50001,68.74999,22.16632
82.60001,68.83324,22.02863
82.70001,68.91680,22.22738
82.80000,68.99999,22.20616
82.90000,69.08331,22.24252
83.00001,69.16674,22.18626
83.10001,69.24999,22.18563
83.20001,69.33324,22.29254
83.30000,69.41674,22.22468
83.40000,69.49992,22.32072
83.50001,69.58318,22.32302
83.60001,69.66668,22.36168
83.70001,69.74999,22.45665
83.80000,69.83330,22.48017
83.90000,69.91674,22.22208
84.00001,69.99999,22.32881
84.10001,70.08330,22.04103
84.20001,70.16681,22.44763
84.30000,70.24992,22.44106
84.40000,70.33318,22.47615
84.50001,70.41674,22.36992
84.60001,70.49993,22.63888
84.70001,70.58324,22.59301
84.80000,70.66680,22.81464
84.90000,70.74999,22.64623
85.00001,70.83330,22.67754
85.10001,70.91674,22.58885
85.20001,70.99999,22.53166
85.30000,71.08324,22.80631
85.40000,71.16674,22.62996
85.50001,71.24993,22.78519
85.60001,71.33324,22.71698
85.70001,71.41673,22.46718
85.80000,71.49993,22.75706
85.90000,71.58324,22.87599
86.00001,71.66680,22.94297
86.10001,71.74999,22.78886
86.20001,71.83324,22.71350
86.30000,71.91674,22.71757
86.40000,71.99999,22.68641
86.50001,72.08318,22.78210
86.60001,72.16674,22.84365
86.70001,72.24999,22.76485
86.80000,72.33324,22.85918
86.90000,72.41681,22.94718
87.00001,72.49999,23.08610
87.10001,72.58330,22.97217
87.20001,72.66680,22.65108
87.30000,72.74993,22.93758
87.40000,72.83330,22.91425
87.50001,72.91668,22.99324
87.60001,72.99993,23.03092
87.70001,73.08324,22.95409
87.80000,73.16674,23.18067
87.90000,73.24993,23.22918
88.00001,73.33330,23.11442
88.10001,73.41674,23.08948
88.20001,73.49999,23.17023
88.30000,73.58330,23.11143
88.40000,73.66681,23.41841
88.50001,73.74999,23.31488
88.60001,73.83324,22.96218
88.70001,73.91667,23.25284
88.80000,73.99993,23.25324
88.90000,74.08318,23.18890
89.00001,74.16674,23.20281
89.10001,74.24999,23.13348
89.20001,74.33324,23.30655
89.30000,74.41680,23.25142
89.40000,74.49999,23.03514
89.50001,74.58330,23.38813
89.60001,74.66674,23.37505
89.70001,74.74992,23.26833
89.80000,74.83324,23.15391
89.90000,74.91674,23.36437
90.00001,74.99993,23.38563
90.10001,75.08317,23.31233
90.20001,75.16680,23.39940
90.30000,75.24999,23.51504
90.40000,75.33330,23.38549
90.50001,75.41680,23.45242
90.60001,75.49999,23.60765
90.70001,75.58330,23.41665
90.80000,75.66668,23.46800
90.90000,75.74993,23.58991
91.00001,75.83324,23.54733
91.10001,75.91668,23.64514
91.20001,75.99992,23.64328
91.30000,76.08330,23.57232
91.40000,76.16680,23.62564
91.50001,76.24999,23.61853
91.60001,76.33324,23.64773
91.70001,76.41674,23.57918
91.80000,76.49993,23.72265
91.90000,76.58324,23.76058
92.00001,76.66674,23.73780
92.10001,76.75005,23.70678
92.20001,76.83330,23.72682
92.30000,76.91680,23.68336
92.40000,76.99999,23.73211
92.50001,77.08324,23.64347
92.60001,77.16680,23.86696
92.70001,77.24993,23.92542
92.80000,77.33324,23.92551
92.90000,77.41680,23.67650
93.00001,77.49993,23.64489
93.10001,77.58324,23.81590
93.20001,77.66674,23.81213
93.30000,77.74999,23.63994
93.40000,77.83324,23.95629
93.50001,77.91680,24.18737
93.60001,77.99999,23.89646
93.70001,78.08330,23.98201
93.80000,78.16673,24.07511
93.90000,78.24999,23.98240
94.00001,78.33323,24.04262
94.10001,78.41674,23.85108
94.20001,78.49992,23.91718
94.30000,78.58324,24.05634
94.40000,78.66674,23.99946
94.50001,78.74999,24.26974
94.60001,78.83323,24.10250
94.70001,78.91680,24.06688
94.80000,78.99993,24.09265
94.90000,79.08317,24.24671
95.00001,79.16674,24.24725
95.10001,79.24993,24.33109
95.20001,79.33323,24.29537
95.30000,79.41674,24.21755
95.40000,79.49992,24.15723
95.50001,79.58324,24.18512
95.60001,79.66680,24.34147
95.70001,79.74993,24.36142
95.80000,79.83324,24.10329
95.90000,79.91680,24.21363
96.00001,79.99999,24.44506
96.10001,80.08324,24.36872
96.20001,80.16674,24.38729
96.30000,80.24992,24.48215
96.40000,80.33324,24.39547
96.50001,80.41673,24.32687
96.60001,80.49999,24.18330
96.70001,80.58330,24.40782
96.80000,80.66680,24.36053
96.90000,80.74992,24.44565
97.00001,80.83324,24.55355
97.10001,80.91674,24.68874
97.20001,80.99993,24.48583
97.30000,81.08323,24.44535
97.40000,81.16674,24.64218
97.50001,81.24999,24.40640
97.60001,81.33323,24.85347
97.70001,81.41674,24.47118
97.80000,81.49998,24.57383
97.90000,81.58323,24.69050
98.00001,81.66674,24.72896
98.10001,81.74999,24.95765
98.20001,81.83324,24.74033
98.30000,81.91674,24.74053
98.40000,81.99993,24.78188
98.50001,82.08324,24.53331
98.60001,82.16674,24.97347
98.70001,82.24999,24.69814
98.80000,82.33330,24.71774
98.90000,82.41680,24.87268
99.00001,82.49999,24.82593
99.10001,82.58330,24.86768
99.20001,82.66667,24.99322
99.30000,82.74992,24.83691
99.40000,82.83324,24.87136
99.50001,82.91667,25.03271
99.60001,82.99992,24.75998
99.70001,83.08330,25.03355
99.80000,83.16685,24.91379
99.90000,83.24998,24.88557
100.00001,83.33330,25.04325
100.10001,83.41674,24.78585
100.20001,83.49999,24.86969
100.30000,83.58323,25.19765
100.40000,83.66674,24.97450
100.50001,83.74998,24.93942
100.60001,83.83323,24.99543
100.70001,83.91674,25.14145
100.80000,83.99992,25.13287
100.90000,84.08330,25.20407
101.00001,84.16673,25.11690
101.10001,84.24993,25.23939
101.20001,84.33330,25.17511
101.30000,84.41680,25.16977
101.40000,84.49992,25.24831
101.50001,84.58317,25.37571
101.60001,84.66673,25.25655
101.70001,84.74993,25.34112
101.80000,84.83324,25.05873
101.90000,84.91674,25.26747
102.00001,84.99992,25.49111
102.10001,85.08329,25.25062
102.20001,85.16680,25.26488
102.30000,85.24999,25.27859
102.40000,85.33323,25.45789
102.50001,85.41674,25.39306
102.60001,85.49993,25.21328
102.70001,85.58324,25.18079
102.80000,85.66674,25.67995
102.90000,85.74992,25.59347
103.00001,85.83323,25.32956
103.10001,85.91673,25.31515
103.20001,85.99998,25.63556
103.30000,86.08324,25.42231
103.40000,86.16674,25.40320
103.50001,86.24999,25.68392
103.60001,86.33324,25.46083
103.70001,86.41668,25.53055
103.80000,86.49993,25.61116
103.90000,86.58317,25.63267
104.00001,86.66674,25.58181
104.10001,86.74999,25.41771
104.20001,86.83329,25.53036
104.30000,86.91681,25.80162
104.40000,86.99999,25.63830
104.50001,87.08323,25.66222
104.60001,87.16674,25.51272
104.70001,87.24992,25.82916
104.80000,87.33324,25.80583
104.90000,87.41674,25.74983
105.00001,87.49993,25.88923
105.10001,87.58330,25.79407
105.20001,87.66680,25.82499
105.30000,87.74993,25.88806
105.40000,87.83324,25.83847
105.50001,87.91680,25.73356
105.60001,87.99993,25.89746
105.70001,88.08331,25.76698
105.80000,88.16673,25.97253
105.90000,88.24993,25.89246
106.00001,88.33324,25.95671
106.10001,88.41667,26.00075
106.20001,88.49998,25.88595
106.30000,88.58330,26.13531
106.40000,88.66680,26.16294
106.50001,88.74998,26.05637
106.60001,88.83330,26.05583
106.70001,88.91674,25.98444
106.80000,88.99992,26.16035
106.90000,89.08317,26.11811
107.00001,89.16680,25.97919
107.10001,89.24992,26.09376
107.20001,89.33323,26.22704
107.30000,89.41680,26.19293
107.40000,89.49999,26.22395
107.50001,89.58329,26.10385
107.60001,89.66674,26.15598
107.70001,89.74993,26.23282
107.80000,89.83323,26.31573
107.90000,89.91674,26.22552
108.00001,89.99986,26.26462
108.10001,90.08324,26.21738
108.20001,90.16674,26.38031
108.30000,90.24998,26.32783
108.40000,90.33323,26.14643
108.50001,90.41680,26.25364
108.60001,90.49999,26.26080
108.70001,90.58324,26.40981
108.80000,90.66674,26.45606
108.90000,90.74998,26.32577
109.00001,90.83324,26.47400
109.10001,90.91668,26.49585
109.20001,90.99992,26.50379
109.30000,91.08324,26.52084
109.40000,91.16674,26.47346
109.50001,91.24999,26.41765
109.60001,91.33330,26.52094
109.70001,91.41673,26.54975
109.80000,91.49999,26.57008
109.90000,91.58324,26.66965
110.00001,91.66680,26.56925
110.10001,91.74999,26.62604
110.20001,91.83324,26.73972
110.30000,91.91674,26.72801
110.40000,91.99993,26.75359
110.50001,92.08323,26.66808
110.60001,92.16674,26.70625
110.70001,92.24999,26.71341
110.80000,92.33330,26.61722
110.90000,92.41686,26.82283
111.00001,92.49998,26.74732
111.10001,92.58323,26.71218
111.20001,92.66668,26.84277
111.30000,92.74992,26.67024
111.40000,92.83324,26.70616
111.50001,92.91674,26.74296
111.60001,93.00006,26.92808
111.70001,93.08336,26.97977
111.80000,93.16680,26.73051
111.90000,93.24999,26.97801
112.00001,93.33324,26.89280
112.10001,93.41667,26.88261
112.20001,93.49992,26.81572
112.30000,93.58324,27.07322
112.40000,93.66673,27.10751
112.50001,93.74999,26.84899
112.60001,93.83324,26.88491
112.70001,93.91680,26.95179
112.80000,93.99999,26.99952
112.90001,94.08324,27.23648
113.00001,94.16673,27.22781
113.10001,94.24998,27.01182
113.20001,94.33329,27.19003
113.30000,94.41674,27.32257
113.40001,94.49992,27.02578
113.50001,94.58323,27.02451
113.60001,94.66674,27.17494
113.70001,94.74993,27.04754
113.80000,94.83330,27.13353
113.90001,94.91679,27.18425
114.00001,94.99999,27.22355
114.10001,95.08323,27.17910
114.20001,95.16673,27.45791
114.30000,95.24993,27.20057
114.40001,95.33323,27.40445
114.50001,95.41674,27.25236
114.60001,95.49998,27.34560
114.70001,95.58330,27.35545
114.80000,95.66673,27.36315
114.90001,95.74998,27.32943
115.00001,95.83324,27.15999
115.10001,95.91674,27.25074
115.20001,95.99992,27.46987
115.30000,96.08324,27.60653
115.40001,96.16673,27.45997
115.50001,96.24999,27.48153
115.60001,96.33318,27.26833
115.70001,96.41673,27.52818
115.80000,96.49992,27.51941
115.90001,96.58324,27.76181
116.00001,96.66674,27.73285
116.10001,96.74999,27.68757
116.20001,96.83330,27.59815
116.30000,96.91673,27.70389
116.40001,96.99993,27.71281
116.50001,97.08324,27.74780
116.60001,97.16674,27.57453
116.70001,97.24992,27.75676
116.80000,97.33323,27.90131
116.90001,97.41686,27.71526
117.00001,97.49998,27.72011
117.10001,97.58323,27.86937
117.20001,97.66679,27.61378
117.30000,97.74992,27.70296
117.40001,97.83324,28.07369
117.50001,97.91673,27.81130
117.60001,97.99998,27.87912
117.70001,98.08330,28.01940
117.80000,98.16674,28.04351
117.90001,98.24999,27.69914
118.00001,98.33324,28.07315
118.10001,98.41680,27.92777
118.20001,98.49992,27.96119
118.30000,98.58330,27.99495
118.40001,98.66673,28.06355
118.50001,98.74999,27.95855
118.60001,98.83317,27.93302
118.70001,98.91674,27.85457
118.80000,98.99999,27.82428
118.90001,99.08323,28.02107
119.00001,99.16673,28.00749
119.10001,99.24999,28.07859
119.20001,99.33324,27.88514
119.30000,99.41679,28.10667
119.40001,99.49992,27.92895
119.50001,99.58318,28.07791
119.60001,99.66673,28.10540
119.70001,99.74992,27.91572
119.80000,99.83324,28.20241
119.90001,99.91674,28.15714
120.00001,99.99998,28.24632
120.10001,100.08324,28.34687
120.20001,100.16680,28.21966
120.30000,100.24998,28.14562
120.40001,100.33330,28.27219
120.50001,100.41674,28.27415
120.60001,100.49986,28.38303
120.70001,100.58324,28.22618
120.80000,100.66673,28.21633
120.90001,100.74992,28.45957
121.00001,100.83323,28.21506
121.10001,100.91674,28.11030
121.20001,100.99999,28.16777
121.30000,101.08324,28.20585
121.40001,101.16674,28.33986
121.50001,101.24998,28.45810
121.60001,101.33323,28.49348
121.70001,101.41667,28.40023
121.80000,101.49992,28.55913
121.90001,101.58330,28.44389
122.00001,101.66674,28.44403
122.10001,101.74992,28.68712
122.20001,101.83323,28.49725
122.30000,101.91679,28.52753
122.40001,101.99992,28.44864
122.50001,102.08324,28.53743
122.60001,102.16679,28.50906
122.70001,102.24998,28.45712
122.80000,102.33324,28.74367
122.90001,102.41673,28.66061
123.00001,102.49992,28.62269
123.10001,102.58324,28.75146
123.20001,102.66673,28.54189
123.30000,102.74992,28.84461
123.40001,102.83330,28.67526
123.50001,102.91680,28.75896
123.60001,102.99998,28.63641
123.70001,103.08329,28.64258
123.80000,103.16680,28.95314
123.90001,103.24992,28.85651
124.00001,103.33317,28.76812
124.10001,103.41674,28.89571
124.20001,103.49998,28.83157
124.30000,103.58323,28.82217
124.40001,103.66674,28.95667
124.50001,103.74999,28.90081
124.60001,103.83330,28.77601
124.70001,103.91674,29.09118
124.80000,103.99998,28.67722
124.90001,104.08323,29.05403
125.00001,104.16673,28.92605
125.10001,104.24992,29.03419
125.20001,104.33324,28.96926
125.30000,104.41673,28.96035
125.40001,104.49992,29.10073
125.50001,104.58324,29.12214
125.60001,104.66673,29.00655
125.70001,104.74992,28.97078
125.80000,104.83324,29.16257
125.90001,104.91673,29.23768
126.00001,104.99999,29.17722
126.10001,105.08330,29.11469
126.20001,105.16667,29.36190
126.30000,105.24986,29.10519
126.40001,105.33324,29.12033
126.50001,105.41674,29.18668
126.60001,105.49999,29.27296
126.70001,105.58330,29.34838
126.80000,105.66674,29.47597
126.90001,105.74993,29.09759
127.00001,105.83323,29.30810
127.10001,105.91674,29.34122
127.20001,105.99992,29.42947
127.30000,106.08323,29.36440
127.40001,106.16673,29.38851
127.50001,106.24993,29.46387
127.60001,106.33330,29.40340
127.70001,106.41674,29.45912
127.80000,106.49998,29.41085
127.90001,106.58330,29.57804
128.00000,106.66673,29.37684
128.10001,106.74998,29.50135
128.20002,106.83317,29.46544
128.30000,106.91673,29.46333
128.40001,106.99999,29.56035
128.50000,107.08317,29.54016
128.60001,107.16673,29.44907
128.70002,107.24999,29.48376
128.80000,107.33330,29.65002
128.90001,107.41680,29.65693
129.00000,107.49999,29.42829
129.10001,107.58329,29.63062
129.20002,107.66679,29.55143
129.30000,107.74992,29.75419
129.40001,107.83323,29.64458
129.50000,107.91673,29.51243
129.60001,107.99993,29.60499
129.70002,108.08324,29.76566
129.80000,108.16674,29.53276
129.90001,108.24999,29.65237
130.00000,108.33330,29.56260
130.10001,108.41673,29.76194
130.20002,108.49998,29.73435
130.30000,108.58330,29.90207
130.40001,108.66679,29.77374
130.50000,108.74998,29.89027
130.60001,108.83324,29.90462
130.70002,108.91673,29.71710
130.80000,108.99986,29.66844
130.90001,109.08323,29.66820
131.00000,109.16680,29.79310
131.10000,109.25005,29.97940
131.20002,109.33329,29.66369
131.30000,109.41680,29.89286
131.40002,109.49999,29.91638
131.50000,109.58323,29.82759
131.60000,109.66667,29.90521
131.70002,109.74992,29.84259
131.80000,109.83324,29.73342
131.90002,109.91674,29.72930
132.00000,109.99999,29.91075
132.10000,110.08330,29.81240
132.20002,110.16680,29.82108
132.30000,110.24993,29.62895
132.40002,110.33317,29.97489
132.50000,110.41667,29.87566
132.60000,110.49998,29.85944
132.70002,110.58323,29.93211
132.80000,110.66673,29.64291
132.90002,110.74998,29.89267
133.00000,110.83324,30.11566
133.10000,110.91674,29.74493
133.20002,110.99998,29.88693
133.30000,111.08330,29.91006
133.40002,111.16673,29.81402
133.50000,111.24998,29.89575
133.60000,111.33323,29.76884
133.70002,111.41674,29.75400
133.80000,111.49992,29.78080
133.90002,111.58324,29.74131
134.00000,111.66673,29.61484
134.10000,111.74999,29.46563
134.20002,111.83336,29.56167
134.30000,111.91680,29.61361
134.40002,111.99992,29.35734
134.50000,112.08324,29.33255
134.60000,112.16674,-0.99512
134.70002,112.24993,0.06406
134.80000,112.33323,0.06523
134.90002,112.41680,0.06332
135.00000,112.49999,0.18239
135.10000,112.58323,0.12114
135.20002,112.66680,-0.11538
135.30000,112.74998,0.02197
135.40002,112.83330,0.13192
135.50000,112.91673,0.09478
135.60000,112.99998,0.02192
135.70002,113.08330,0.10198
135.80000,113.16667,-0.05423
135.90002,113.24992,-0.04634
136.00000,113.33324,0.06298
136.10000,113.41673,-0.00067
136.20002,113.49998,0.17573
136.30000,113.58330,0.14844
136.40002,113.66680,0.09983
136.50000,113.74999,0.29436
136.60000,113.83324,0.13633
136.70002,113.91673,-0.05124
136.80000,113.99992,0.04211
136.90002,114.08323,-0.03311
137.00000,114.16674,0.38060
137.10000,114.24992,0.20753
137.20002,114.33329,-0.00484
137.30000,114.41674,-0.01802
137.40002,114.49993,0.09875
137.50000,114.58330,0.00639
137.60000,114.66674,0.11174
137.70002,114.74992,0.00492
137.80000,114.83323,0.02731
137.90002,114.91674,-0.05511
138.00000,114.99998,-0.07025
138.10000,115.08323,0.08140
138.17002,115.14167,0.10860