File: V_8/NR/RDSO NR Tensile 50.is_tens_RawData/Specimen_RawData_8.csv
Time,Extension,Load,Tensile strain,Tensile stress,Corrected Position
(sec),(mm),(N),(mm/mm),(MPa),(mm)
0.00000,0.00000,0.02964,0.00000,0.00329,0.00000
0.20000,0.16469,0.37078,0.00143,0.04120,0.16469
0.40000,0.33312,0.71082,0.00290,0.07898,0.33312
0.60000,0.49994,1.23407,0.00435,0.13712,0.49994
0.80000,0.66650,1.53063,0.00580,0.17007,0.66650
1.00000,0.83331,1.72644,0.00725,0.19183,0.83331
1.20000,1.00000,1.97407,0.00870,0.21934,1.00000
1.40000,1.16669,2.29703,0.01015,0.25523,1.16669
1.60000,1.33337,2.53759,0.01159,0.28195,1.33337
1.80000,1.49994,2.84946,0.01304,0.31661,1.49994
2.00000,1.66662,3.14188,0.01449,0.34910,1.66662
2.20000,1.83337,3.23296,0.01594,0.35922,1.83337
2.40000,2.00000,3.30352,0.01739,0.36706,2.00000
2.60000,2.16662,3.65786,0.01884,0.40643,2.16662
2.80000,2.33331,3.77189,0.02029,0.41910,2.33331
3.00000,2.50000,4.06583,0.02174,0.45176,2.50000
3.20000,2.66662,4.13593,0.02319,0.45955,2.66662
3.40000,2.83331,4.54816,0.02464,0.50535,2.83331
3.60000,3.00000,4.55747,0.02609,0.50639,3.00000
3.80000,3.16669,4.88565,0.02754,0.54285,3.16669
4.00000,3.33331,4.97872,0.02899,0.55319,3.33331
4.20000,3.50006,5.09671,0.03044,0.56630,3.50006
4.40000,3.66662,5.35074,0.03188,0.59453,3.66662
4.60000,3.83331,5.54493,0.03333,0.61610,3.83331
4.80000,3.99994,5.71965,0.03478,0.63552,3.99994
5.00000,4.16662,5.99968,0.03623,0.66663,4.16662
5.20000,4.33337,5.95885,0.03768,0.66209,4.33337
5.40000,4.50006,6.20254,0.03913,0.68917,4.50006
5.60000,4.66662,6.58766,0.04058,0.73196,4.66662
5.80000,4.83331,6.72008,0.04203,0.74668,4.83331
6.00000,5.00000,6.81202,0.04348,0.75689,5.00000
6.20000,5.16662,6.97349,0.04493,0.77483,5.16662
6.40000,5.33337,6.99884,0.04638,0.77765,5.33337
6.60000,5.50000,6.88011,0.04783,0.76446,5.50000
6.80000,5.66662,7.35046,0.04927,0.81672,5.66662
7.00000,5.83331,7.36376,0.05072,0.81820,5.83331
7.20000,6.00000,7.41700,0.05217,0.82411,6.00000
7.40000,6.16662,7.93445,0.05362,0.88161,6.16662
7.60000,6.33344,7.97952,0.05507,0.88661,6.33344
7.80000,6.50006,7.87205,0.05652,0.87467,6.50006
8.00000,6.66656,7.93732,0.05797,0.88192,6.66656
8.20000,6.83331,8.42408,0.05942,0.93601,6.83331
8.40000,7.00000,8.42844,0.06087,0.93649,7.00000
8.60000,7.16662,8.47380,0.06232,0.94153,7.16662
8.80000,7.33337,8.56175,0.06377,0.95131,7.33337
9.00000,7.50000,8.68518,0.06522,0.96502,7.50000
9.20000,7.66656,8.85735,0.06667,0.98415,7.66656
9.40000,7.83331,9.06994,0.06812,1.00777,7.83331
9.60000,8.00000,9.03802,0.06957,1.00422,8.00000
9.80000,8.16675,9.02122,0.07102,1.00236,8.16675
10.00000,8.33331,9.22861,0.07246,1.02540,8.33331
10.20000,8.50000,9.54849,0.07391,1.06094,8.50000
10.40000,8.66662,9.49824,0.07536,1.05536,8.66662
10.60000,8.83337,9.55388,0.07681,1.06154,8.83337
10.80000,9.00000,9.59449,0.07826,1.06605,9.00000
11.00000,9.16662,9.60071,0.07971,1.06675,9.16662
11.20000,9.33337,9.80244,0.08116,1.08916,9.33337
11.40000,9.50006,9.89017,0.08261,1.09891,9.50006
11.60000,9.66662,10.06501,0.08406,1.11833,9.66662
11.80000,9.83337,10.41565,0.08551,1.15729,9.83337
12.00000,10.00006,10.15007,0.08696,1.12779,10.00006
12.20000,10.16662,10.27497,0.08841,1.14166,10.16662
12.40000,10.33337,10.45285,0.08986,1.16143,10.33337
12.60000,10.50000,10.56225,0.09130,1.17358,10.50000
12.80000,10.66662,10.32440,0.09275,1.14716,10.66662
13.00000,10.83337,10.57955,0.09420,1.17551,10.83337
13.20000,11.00000,10.73962,0.09565,1.19329,11.00000
13.40000,11.16662,10.63605,0.09710,1.18178,11.16662
13.60000,11.33331,10.78757,0.09855,1.19862,11.33331
13.80000,11.49994,10.85470,0.10000,1.20608,11.49994
14.00000,11.66675,11.07184,0.10145,1.23020,11.66675
14.20000,11.83337,11.02308,0.10290,1.22479,11.83337
14.40000,12.00000,11.07672,0.10435,1.23075,12.00000
14.60000,12.16662,11.24708,0.10580,1.24968,12.16662
14.80000,12.33337,11.13388,0.10725,1.23710,12.33337
15.00000,12.50000,11.34220,0.10870,1.26024,12.50000
15.20000,12.66669,11.22944,0.11015,1.24772,12.66669
15.40000,12.83331,11.42652,0.11159,1.26961,12.83331
15.60000,12.99994,11.38773,0.11304,1.26530,12.99994
15.80000,13.16662,11.34938,0.11449,1.26104,13.16662
16.00000,13.33331,11.61927,0.11594,1.29103,13.33331
16.20000,13.50006,11.49955,0.11739,1.27773,13.50006
16.40000,13.66662,11.51844,0.11884,1.27983,13.66662
16.60000,13.83331,11.48856,0.12029,1.27651,13.83331
16.80000,14.00000,11.94926,0.12174,1.32770,14.00000
17.00000,14.16662,11.73881,0.12319,1.30431,14.16662
17.20000,14.33337,11.87040,0.12464,1.31893,14.33337
17.40000,14.50000,11.90861,0.12609,1.32318,14.50000
17.60000,14.66662,11.93959,0.12754,1.32662,14.66662
17.80000,14.83337,12.11908,0.12899,1.34656,14.83337
18.00000,15.00000,11.90579,0.13043,1.32287,15.00000
18.20000,15.16662,12.13672,0.13188,1.34852,15.16662
18.40000,15.33337,12.01174,0.13333,1.33464,15.33337
18.60000,15.50006,12.32402,0.13478,1.36934,15.50006
18.80000,15.66662,12.40411,0.13623,1.37823,15.66662
19.00000,15.83331,12.50134,0.13768,1.38904,15.83331
19.20000,16.00000,12.15567,0.13913,1.35063,16.00000
19.40000,16.16669,12.46928,0.14058,1.38548,16.16669
19.60000,16.33337,12.43392,0.14203,1.38155,16.33337
19.80000,16.50000,12.23196,0.14348,1.35911,16.50000
20.00000,16.66668,12.33551,0.14493,1.37061,16.66668
20.20000,16.83331,12.48932,0.14638,1.38770,16.83331
20.40000,17.00000,12.59930,0.14783,1.39992,17.00000
20.60000,17.16669,12.52916,0.14928,1.39213,17.16669
20.80000,17.33337,12.62625,0.15072,1.40292,17.33337
21.00000,17.50000,12.68669,0.15217,1.40963,17.50000
21.20000,17.66662,12.77542,0.15362,1.41949,17.66662
21.40000,17.83337,12.76354,0.15507,1.41817,17.83337
21.60000,18.00006,12.66918,0.15652,1.40769,18.00006
21.80000,18.16662,12.59524,0.15797,1.39947,18.16662
22.00000,18.33325,12.83986,0.15942,1.42665,18.33325
22.20000,18.50000,12.70342,0.16087,1.41149,18.50000
22.40000,18.66668,12.91681,0.16232,1.43520,18.66668
22.60000,18.83337,13.07536,0.16377,1.45282,18.83337
22.80000,19.00000,12.81172,0.16522,1.42352,19.00000
23.00000,19.16662,12.83785,0.16667,1.42643,19.16662
23.20000,19.33331,13.15408,0.16812,1.46156,19.33331
23.40000,19.50000,12.99680,0.16957,1.44409,19.50000
23.60000,19.66669,12.88257,0.17101,1.43140,19.66669
23.80000,19.83337,13.04355,0.17246,1.44928,19.83337
24.00000,20.00000,13.19995,0.17391,1.46666,20.00000
24.20000,20.16662,13.08269,0.17536,1.45363,20.16662
24.40000,20.33331,13.15337,0.17681,1.46149,20.33331
24.60000,20.50006,13.06451,0.17826,1.45161,20.50006
24.80000,20.66668,13.39218,0.17971,1.48802,20.66668
25.00000,20.83337,13.15533,0.18116,1.46170,20.83337
25.20000,21.00000,13.27051,0.18261,1.47450,21.00000
25.40000,21.16662,13.20419,0.18406,1.46713,21.16662
25.60000,21.33331,13.30328,0.18551,1.47814,21.33331
25.80000,21.50000,13.55759,0.18696,1.50640,21.50000
26.00000,21.66668,13.39025,0.18841,1.48781,21.66668
26.20000,21.83337,13.24810,0.18986,1.47201,21.83337
26.40000,22.00000,13.39005,0.19130,1.48778,22.00000
26.60000,22.16662,13.48716,0.19275,1.49857,22.16662
26.80000,22.33331,13.63672,0.19420,1.51519,22.33331
27.00000,22.50000,13.81142,0.19565,1.53460,22.50000
27.20000,22.66662,13.50824,0.19710,1.50092,22.66662
27.40000,22.83337,13.60516,0.19855,1.51168,22.83337
27.60000,23.00000,13.72293,0.20000,1.52477,23.00000
27.80000,23.16668,13.62125,0.20145,1.51347,23.16668
28.00000,23.33337,13.86209,0.20290,1.54023,23.33337
28.20000,23.50006,13.70648,0.20435,1.52294,23.50006
28.40000,23.66656,13.81370,0.20580,1.53486,23.66656
28.60000,23.83337,13.83265,0.20725,1.53696,23.83337
28.80000,24.00000,13.83214,0.20870,1.53690,24.00000
29.00000,24.16668,13.83099,0.21015,1.53678,24.16668
29.20000,24.33337,13.90684,0.21159,1.54520,24.33337
29.40000,24.49993,13.88276,0.21304,1.54253,24.49993
29.60000,24.66662,13.90483,0.21449,1.54498,24.66662
29.80000,24.83337,13.97108,0.21594,1.55234,24.83337
30.00000,25.00006,13.95318,0.21739,1.55035,25.00006
30.20000,25.16668,14.11149,0.21884,1.56794,25.16668
30.40000,25.33331,14.10602,0.22029,1.56734,25.33331
30.60000,25.49993,13.89917,0.22174,1.54435,25.49993
30.80000,25.66662,14.05082,0.22319,1.56120,25.66662
31.00000,25.83337,14.13130,0.22464,1.57014,25.83337
31.20000,26.00000,14.30178,0.22609,1.58909,26.00000
31.40000,26.16668,14.09243,0.22754,1.56583,26.16668
31.60000,26.33331,14.13037,0.22899,1.57004,26.33331
31.80000,26.50000,14.21876,0.23043,1.57986,26.50000
32.00000,26.66662,14.28246,0.23188,1.58694,26.66662
32.20000,26.83331,14.39277,0.23333,1.59920,26.83331
32.40000,27.00006,14.22331,0.23478,1.58037,27.00006
32.60000,27.16662,14.32872,0.23623,1.59208,27.16662
32.80000,27.33331,14.47966,0.23768,1.60885,27.33331
33.00000,27.50000,14.44728,0.23913,1.60525,27.50000
33.20000,27.66662,14.28513,0.24058,1.58724,27.66662
33.40000,27.83343,14.21957,0.24203,1.57995,27.83343
33.60000,28.00006,14.49041,0.24348,1.61005,28.00006
33.80000,28.16662,14.40783,0.24493,1.60087,28.16662
34.00000,28.33337,14.46479,0.24638,1.60720,28.33337
34.20000,28.50000,14.43852,0.24783,1.60428,28.50000
34.40000,28.66668,14.66036,0.24928,1.62893,28.66668
34.60000,28.83337,14.55066,0.25072,1.61674,28.83337
34.80000,29.00000,14.56310,0.25217,1.61812,29.00000
35.00000,29.16669,14.59502,0.25362,1.62167,29.16669
35.20000,29.33331,14.80076,0.25507,1.64453,29.33331
35.40000,29.50000,14.74404,0.25652,1.63823,29.50000
35.60000,29.66668,14.74201,0.25797,1.63800,29.66668
35.80000,29.83337,14.59232,0.25942,1.62137,29.83337
36.00000,30.00000,14.81798,0.26087,1.64644,30.00000
36.20000,30.16668,14.82758,0.26232,1.64751,30.16668
36.40000,30.33331,14.81558,0.26377,1.64618,30.33331
36.60000,30.50006,14.97717,0.26522,1.66413,30.50006
36.80000,30.66662,14.89870,0.26667,1.65541,30.66662
37.00000,30.83331,14.88232,0.26812,1.65359,30.83331
37.20000,31.00000,15.01678,0.26957,1.66853,31.00000
37.40000,31.16668,14.98998,0.27101,1.66555,31.16668
37.60000,31.33337,15.13076,0.27246,1.68120,31.33337
37.80000,31.50006,14.82893,0.27391,1.64766,31.50006
38.00000,31.66662,15.16274,0.27536,1.68475,31.66662
38.20000,31.83331,15.16639,0.27681,1.68515,31.83331
38.40000,31.99999,14.99645,0.27826,1.66627,31.99999
38.60000,32.16662,15.34851,0.27971,1.70539,32.16662
38.80000,32.33343,15.31951,0.28116,1.70217,32.33343
39.00000,32.50000,15.43704,0.28261,1.71523,32.50000
39.20000,32.66656,15.26989,0.28406,1.69665,32.66656
39.40000,32.83331,15.21805,0.28551,1.69089,32.83331
39.60000,33.00006,15.18346,0.28696,1.68705,33.00006
39.80000,33.16668,15.25907,0.28841,1.69545,33.16668
40.00000,33.33337,15.32583,0.28986,1.70287,33.33337
40.20000,33.49999,15.47128,0.29130,1.71903,33.49999
40.40000,33.66662,15.39541,0.29275,1.71060,33.66662
40.60000,33.83337,15.44956,0.29420,1.71662,33.83337
40.80000,34.00000,15.43557,0.29565,1.71506,34.00000
41.00000,34.16668,15.46251,0.29710,1.71806,34.16668
41.20000,34.33337,15.50126,0.29855,1.72236,34.33337
41.40000,34.49993,15.57486,0.30000,1.73054,34.49993
41.60000,34.66668,15.47584,0.30145,1.71954,34.66668
41.80000,34.83331,15.76799,0.30290,1.75200,34.83331
42.00000,35.00006,16.11856,0.30435,1.79095,35.00006
42.20000,35.16662,15.75969,0.30580,1.75108,35.16662
42.40000,35.33331,15.64642,0.30725,1.73849,35.33331
42.60000,35.50006,15.62648,0.30870,1.73628,35.50006
42.80000,35.66668,15.64022,0.31015,1.73780,35.66668
43.00000,35.83337,15.90350,0.31159,1.76706,35.83337
43.20000,35.99999,15.93299,0.31304,1.77033,35.99999
43.40000,36.16668,15.86356,0.31449,1.76262,36.16668
43.60000,36.33331,15.91068,0.31594,1.76785,36.33331
43.80000,36.50000,15.99084,0.31739,1.77676,36.50000
44.00000,36.66662,15.91678,0.31884,1.76853,36.66662
44.20000,36.83337,16.00815,0.32029,1.77868,36.83337
44.40000,36.99999,16.00732,0.32174,1.77859,36.99999
44.60000,37.16662,16.09982,0.32319,1.78887,37.16662
44.80000,37.33337,16.22370,0.32464,1.80263,37.33337
45.00000,37.50006,16.08312,0.32609,1.78701,37.50006
45.20000,37.66662,16.19284,0.32754,1.79920,37.66662
45.40000,37.83337,16.14391,0.32899,1.79377,37.83337
45.60000,37.99993,16.28534,0.33043,1.80948,37.99993
45.80000,38.16662,16.20722,0.33188,1.80080,38.16662
46.00000,38.33337,16.11396,0.33333,1.79044,38.33337
46.20000,38.50006,16.25199,0.33478,1.80578,38.50006
46.40000,38.66668,16.36741,0.33623,1.81860,38.66668
46.60000,38.83331,16.21481,0.33768,1.80165,38.83331
46.80000,38.99993,16.25546,0.33913,1.80616,38.99993
47.00000,39.16662,16.26810,0.34058,1.80757,39.16662
47.20000,39.33337,16.56817,0.34203,1.84091,39.33337
47.40000,39.49999,16.53089,0.34348,1.83677,39.49999
47.60000,39.66662,16.52864,0.34493,1.83652,39.66662
47.80000,39.83330,16.76270,0.34638,1.86252,39.83330
48.00000,39.99999,16.45764,0.34783,1.82863,39.99999
48.20000,40.16668,16.56163,0.34928,1.84018,40.16668
48.40000,40.33337,16.72109,0.35072,1.85790,40.33337
48.60000,40.50006,16.71124,0.35217,1.85680,40.50006
48.80000,40.66656,16.76640,0.35362,1.86293,40.66656
49.00000,40.83330,16.68330,0.35507,1.85370,40.83330
49.20000,40.99999,16.71259,0.35652,1.85695,40.99999
49.40000,41.16668,16.60495,0.35797,1.84499,41.16668
49.60000,41.33343,16.76111,0.35942,1.86235,41.33343
49.80000,41.49999,16.80708,0.36087,1.86745,41.49999
50.00000,41.66662,16.96671,0.36232,1.88519,41.66662
50.20000,41.83337,16.98831,0.36377,1.88759,41.83337
50.40000,41.99999,16.96679,0.36522,1.88520,41.99999
50.60000,42.16668,17.03541,0.36667,1.89282,42.16668
50.80000,42.33337,17.07854,0.36812,1.89762,42.33337
51.00000,42.49993,17.03717,0.36956,1.89302,42.49993
51.20000,42.66662,17.04721,0.37101,1.89413,42.66662
51.40000,42.83337,17.24545,0.37246,1.91616,42.83337
51.60000,42.99999,17.15091,0.37391,1.90566,42.99999
51.80000,43.16668,17.28402,0.37536,1.92045,43.16668
52.00000,43.33331,17.17609,0.37681,1.90845,43.33331
52.20000,43.50000,17.18645,0.37826,1.90961,43.50000
52.40000,43.66668,17.05630,0.37971,1.89514,43.66668
52.60000,43.83331,17.31796,0.38116,1.92422,43.83331
52.80000,44.00000,17.46890,0.38261,1.94099,44.00000
53.00000,44.16662,17.34341,0.38406,1.92705,44.16662
53.20000,44.33331,17.43366,0.38551,1.93707,44.33331
53.40000,44.50005,17.22600,0.38696,1.91400,44.50005
53.60000,44.66668,17.50571,0.38841,1.94508,44.66668
53.80000,44.83337,17.60892,0.38986,1.95655,44.83337
54.00000,44.99999,17.55056,0.39130,1.95006,44.99999
54.20000,45.16656,17.50451,0.39275,1.94495,45.16656
54.40000,45.33330,17.35323,0.39420,1.92814,45.33330
54.60000,45.50005,17.51970,0.39565,1.94663,45.50005
54.80000,45.66668,17.53444,0.39710,1.94827,45.66668
55.00000,45.83337,17.58372,0.39855,1.95375,45.83337
55.20000,45.99999,17.58399,0.40000,1.95378,45.99999
55.40000,46.16662,17.73081,0.40145,1.97009,46.16662
55.60000,46.33337,17.65628,0.40290,1.96181,46.33337
55.80000,46.50006,17.88719,0.40435,1.98747,46.50006
56.00000,46.66668,17.86252,0.40580,1.98472,46.66668
56.20000,46.83337,17.67938,0.40725,1.96438,46.83337
56.40000,46.99993,17.67260,0.40870,1.96362,46.99993
56.60000,47.16662,17.69207,0.41014,1.96579,47.16662
56.80000,47.33337,18.02610,0.41159,2.00290,47.33337
57.00000,47.49999,17.87369,0.41304,1.98597,47.49999
57.20000,47.66662,18.00332,0.41449,2.00037,47.66662
57.40000,47.83337,17.96622,0.41594,1.99625,47.83337
57.60000,47.99999,17.96815,0.41739,1.99646,47.99999
57.80000,48.16668,18.04393,0.41884,2.00488,48.16668
58.00000,48.33337,17.95630,0.42029,1.99514,48.33337
58.20000,48.50006,18.09247,0.42174,2.01027,48.50006
58.40000,48.66662,18.12664,0.42319,2.01407,48.66662
58.60000,48.83330,17.93512,0.42464,1.99279,48.83330
58.80000,49.00006,18.24760,0.42609,2.02751,49.00006
59.00000,49.16668,18.28625,0.42754,2.03181,49.16668
59.20000,49.33337,18.24184,0.42899,2.02687,49.33337
59.40000,49.49993,18.40598,0.43043,2.04511,49.49993
59.60000,49.66656,18.40202,0.43188,2.04467,49.66656
59.80000,49.83337,18.34439,0.43333,2.03827,49.83337
60.00000,50.00005,18.37375,0.43478,2.04153,50.00005
60.20000,50.16668,18.54539,0.43623,2.06060,50.16668
60.40000,50.33331,18.41375,0.43768,2.04597,50.33331
60.60000,50.49999,18.46195,0.43913,2.05133,50.49999
60.80000,50.66662,18.46236,0.44058,2.05137,50.66662
61.00000,50.83337,18.62082,0.44203,2.06898,50.83337
61.20000,50.99999,18.82939,0.44348,2.09215,50.99999
61.40000,51.16662,18.62393,0.44493,2.06933,51.16662
61.60000,51.33336,18.61658,0.44638,2.06851,51.33336
61.80000,51.49999,18.55232,0.44783,2.06137,51.49999
62.00000,51.66662,18.68445,0.44927,2.07605,51.66662
62.20000,51.83343,18.65283,0.45073,2.07254,51.83343
62.40000,52.00006,18.88158,0.45217,2.09795,52.00006
62.60000,52.16668,18.99671,0.45362,2.11075,52.16668
62.80000,52.33331,18.92404,0.45507,2.10267,52.33331
63.00000,52.49999,18.94915,0.45652,2.10546,52.49999
63.20000,52.66662,18.82799,0.45797,2.09200,52.66662
63.40000,52.83337,18.79233,0.45942,2.08804,52.83337
63.60000,53.00005,19.00504,0.46087,2.11167,53.00005
63.80000,53.16662,19.02304,0.46232,2.11367,53.16662
64.00000,53.33330,19.18024,0.46377,2.13114,53.33330
64.20000,53.50005,19.18921,0.46522,2.13213,53.50005
64.40000,53.66668,19.13273,0.46667,2.12586,53.66668
64.60001,53.83337,19.00636,0.46812,2.11182,53.83337
64.80000,53.99999,19.08451,0.46957,2.12050,53.99999
65.00000,54.16662,19.11125,0.47101,2.12347,54.16662
65.20000,54.33330,19.02411,0.47246,2.11379,54.33330
65.40000,54.50006,19.24111,0.47391,2.13790,54.50006
65.60001,54.66668,19.42991,0.47536,2.15888,54.66668
65.80000,54.83337,19.40889,0.47681,2.15654,54.83337
66.00000,55.00000,19.47605,0.47826,2.16401,55.00000
66.20001,55.16662,19.31561,0.47971,2.14618,55.16662
66.40000,55.33337,19.44737,0.48116,2.16082,55.33337
66.60001,55.49999,19.52555,0.48261,2.16951,55.49999
66.80000,55.66668,19.42041,0.48406,2.15782,55.66668
67.00000,55.83331,19.45917,0.48551,2.16213,55.83331
67.20001,55.99999,19.61166,0.48696,2.17907,55.99999
67.40000,56.16662,19.57967,0.48841,2.17552,56.16662
67.60001,56.33337,19.52949,0.48986,2.16994,56.33337
67.80000,56.49999,19.67705,0.49130,2.18634,56.49999
68.00000,56.66662,19.50931,0.49275,2.16770,56.66662
68.20001,56.83336,19.67867,0.49420,2.18652,56.83336
68.40000,56.99999,19.69777,0.49565,2.18864,56.99999
68.60001,57.16668,19.70225,0.49710,2.18914,57.16668
68.80000,57.33330,19.70705,0.49855,2.18967,57.33330
69.00000,57.49999,19.89455,0.50000,2.21051,57.49999
69.20001,57.66662,20.04456,0.50145,2.22717,57.66662
69.40000,57.83337,19.81400,0.50290,2.20156,57.83337
69.60001,58.00006,19.81317,0.50435,2.20146,58.00006
69.80000,58.16668,19.95698,0.50580,2.21744,58.16668
70.00000,58.33337,19.98155,0.50725,2.22017,58.33337
70.20001,58.49999,19.86428,0.50870,2.20714,58.49999
70.40000,58.66656,20.20787,0.51014,2.24532,58.66656
70.60001,58.83337,19.80450,0.51159,2.20050,58.83337
70.80000,59.00005,19.93249,0.51304,2.21472,59.00005
71.00000,59.16662,20.06068,0.51449,2.22896,59.16662
71.20001,59.33337,20.07434,0.51594,2.23048,59.33337
71.40000,59.49993,20.05891,0.51739,2.22877,59.49993
71.60001,59.66661,20.11054,0.51884,2.23450,59.66661
71.80000,59.83337,20.24211,0.52029,2.24912,59.83337
72.00000,60.00006,20.18529,0.52174,2.24281,60.00006
72.20001,60.16662,20.46814,0.52319,2.27424,60.16662
72.40000,60.33331,20.50463,0.52464,2.27829,60.33331
72.60001,60.49993,20.30331,0.52609,2.25592,60.49993
72.80000,60.66662,20.44237,0.52754,2.27137,60.66662
73.00000,60.83337,20.45927,0.52899,2.27325,60.83337
73.20001,61.00005,20.40083,0.53044,2.26676,61.00005
73.40000,61.16662,20.53098,0.53188,2.28122,61.16662
73.60001,61.33331,20.40155,0.53333,2.26684,61.33331
73.80000,61.49999,20.57443,0.53478,2.28605,61.49999
74.00000,61.66668,20.59297,0.53623,2.28811,61.66668
74.20001,61.83337,20.67692,0.53768,2.29744,61.83337
74.40000,62.00006,20.46831,0.53913,2.27426,62.00006
74.60001,62.16655,20.67425,0.54058,2.29714,62.16655
74.80000,62.33331,20.76161,0.54203,2.30685,62.33331
75.00000,62.49999,20.55724,0.54348,2.28414,62.49999
75.20001,62.66662,20.71351,0.54493,2.30150,62.66662
75.40000,62.83336,20.72436,0.54638,2.30271,62.83336
75.60001,62.99999,20.73798,0.54783,2.30422,62.99999
75.80000,63.16668,20.67639,0.54928,2.29738,63.16668
76.00000,63.33330,20.99198,0.55072,2.33244,63.33330
76.20001,63.50006,21.04074,0.55217,2.33786,63.50006
76.40000,63.66668,21.02972,0.55362,2.33664,63.66668
76.60001,63.83331,21.02303,0.55507,2.33589,63.83331
76.80000,63.99999,21.02925,0.55652,2.33658,63.99999
77.00000,64.16661,21.15857,0.55797,2.35095,64.16661
77.20001,64.33337,21.12007,0.55942,2.34667,64.33337
77.40000,64.49999,20.98243,0.56087,2.33138,64.49999
77.60001,64.66662,21.23601,0.56232,2.35956,64.66662
77.80000,64.83336,21.12979,0.56377,2.34775,64.83336
78.00000,64.99992,21.10505,0.56522,2.34501,64.99992
78.20001,65.16668,21.24463,0.56667,2.36051,65.16668
78.40000,65.33343,21.29878,0.56812,2.36653,65.33343
78.60001,65.49999,21.34005,0.56957,2.37112,65.49999
78.80000,65.66655,21.24294,0.57101,2.36033,65.66655
79.00000,65.83330,21.36160,0.57246,2.37351,65.83330
79.20001,66.00005,21.49414,0.57391,2.38824,66.00005
79.40000,66.16668,21.30662,0.57536,2.36740,66.16668
79.60001,66.33336,21.47014,0.57681,2.38557,66.33336
79.80000,66.49998,21.45239,0.57826,2.38360,66.49998
80.00000,66.66661,21.57585,0.57971,2.39732,66.66661
80.20001,66.83331,21.58383,0.58116,2.39820,66.83331
80.40000,66.99999,21.70810,0.58261,2.41201,66.99999
80.60001,67.16661,21.71569,0.58406,2.41285,67.16661
80.80000,67.33343,21.72032,0.58551,2.41337,67.33343
81.00001,67.49999,21.82742,0.58696,2.42527,67.49999
81.20001,67.66655,21.59030,0.58840,2.39892,67.66655
81.40000,67.83336,21.84907,0.58986,2.42767,67.83336
81.60001,68.00005,21.91640,0.59130,2.43515,68.00005
81.80000,68.16661,21.93310,0.59275,2.43701,68.16661
82.00001,68.33337,21.85595,0.59420,2.42844,68.33337
82.20001,68.49999,21.86034,0.59565,2.42893,68.49999
82.40000,68.66667,21.88159,0.59710,2.43129,68.66667
82.60001,68.83337,21.94451,0.59855,2.43828,68.83337
82.80000,68.99999,21.84273,0.60000,2.42697,68.99999
83.00001,69.16662,22.01764,0.60145,2.44640,69.16662
83.20001,69.33330,22.01267,0.60290,2.44585,69.33330
83.40000,69.49999,21.80594,0.60435,2.42288,69.49999
83.60001,69.66668,22.11254,0.60580,2.45695,69.66668
83.80000,69.83336,22.12746,0.60725,2.45861,69.83336
84.00001,69.99999,22.15127,0.60870,2.46125,69.99999
84.20001,70.16661,22.14691,0.61014,2.46077,70.16661
84.40000,70.33330,22.25479,0.61159,2.47275,70.33330
84.60001,70.50005,22.09195,0.61304,2.45466,70.50005
84.80000,70.66655,22.19119,0.61449,2.46569,70.66655
85.00001,70.83330,22.29429,0.61594,2.47714,70.83330
85.20001,70.99999,22.34014,0.61739,2.48224,70.99999
85.40000,71.16668,22.50754,0.61884,2.50084,71.16668
85.60001,71.33331,22.45858,0.62029,2.49540,71.33331
85.80000,71.50005,22.56752,0.62174,2.50750,71.50005
86.00001,71.66667,22.27980,0.62319,2.47553,71.66667
86.20001,71.83330,22.69245,0.62464,2.52138,71.83330
86.40000,71.99999,22.53213,0.62609,2.50357,71.99999
86.60001,72.16656,22.52654,0.62754,2.50295,72.16656
86.80000,72.33337,22.60063,0.62899,2.51118,72.33337
87.00001,72.49999,22.66169,0.63043,2.51797,72.49999
87.20001,72.66668,22.74510,0.63188,2.52723,72.66668
87.40000,72.83337,22.65194,0.63333,2.51688,72.83337
87.60001,72.99993,22.75561,0.63478,2.52840,72.99993
87.80000,73.16668,22.81167,0.63623,2.53463,73.16668
88.00001,73.33330,22.89033,0.63768,2.54337,73.33330
88.20001,73.49999,22.87530,0.63913,2.54170,73.49999
88.40000,73.66668,22.93939,0.64058,2.54882,73.66668
88.60001,73.83330,23.09283,0.64203,2.56587,73.83330
88.80000,73.99999,23.00334,0.64348,2.55593,73.99999
89.00001,74.16668,22.69502,0.64493,2.52167,74.16668
89.20001,74.33336,22.82137,0.64638,2.53571,74.33336
89.40000,74.49999,22.99327,0.64783,2.55481,74.49999
89.60001,74.66668,22.93589,0.64928,2.54843,74.66668
89.80000,74.83331,23.01269,0.65072,2.55697,74.83331
90.00001,75.00005,23.18744,0.65217,2.57638,75.00005
90.20001,75.16667,23.02891,0.65362,2.55877,75.16667
90.40000,75.33337,23.19767,0.65507,2.57752,75.33337
90.60001,75.49999,23.06589,0.65652,2.56288,75.49999
90.80000,75.66662,23.24004,0.65797,2.58223,75.66662
91.00001,75.83336,23.38768,0.65942,2.59863,75.83336
91.20001,76.00005,23.40227,0.66087,2.60025,76.00005
91.40000,76.16661,23.29858,0.66232,2.58873,76.16661
91.60001,76.33330,23.21668,0.66377,2.57963,76.33330
91.80000,76.49999,23.37548,0.66522,2.59728,76.49999
92.00001,76.66662,23.41824,0.66667,2.60203,76.66662
92.20001,76.83343,23.46928,0.66812,2.60770,76.83343
92.40000,76.99999,23.43149,0.66957,2.60350,76.99999
92.60001,77.16662,23.56575,0.67101,2.61842,77.16662
92.80000,77.33330,23.63673,0.67246,2.62630,77.33330
93.00001,77.49998,23.76499,0.67391,2.64055,77.49998
93.20001,77.66661,23.59967,0.67536,2.62219,77.66661
93.40000,77.83343,23.41239,0.67681,2.60138,77.83343
93.60001,77.99999,23.51596,0.67826,2.61288,77.99999
93.80000,78.16661,23.59825,0.67971,2.62203,78.16661
94.00001,78.33336,23.76881,0.68116,2.64098,78.33336
94.20001,78.50005,23.77001,0.68261,2.64111,78.50005
94.40000,78.66668,23.93704,0.68406,2.65967,78.66668
94.60001,78.83336,23.74845,0.68551,2.63872,78.83336
94.80000,78.99999,23.84828,0.68696,2.64981,78.99999
95.00001,79.16655,23.99449,0.68840,2.66605,79.16655
95.20001,79.33330,23.87980,0.68985,2.65331,79.33330
95.40000,79.50005,23.78642,0.69130,2.64294,79.50005
95.60001,79.66667,24.00975,0.69275,2.66775,79.66667
95.80000,79.83336,24.01783,0.69420,2.66865,79.83336
96.00001,80.00005,24.04215,0.69565,2.67135,80.00005
96.20001,80.16654,23.95112,0.69710,2.66124,80.16654
96.40000,80.33330,24.08104,0.69855,2.67567,80.33330
96.60001,80.50005,24.19204,0.70000,2.68800,80.50005
96.80000,80.66667,24.07196,0.70145,2.67466,80.66667
97.00001,80.83330,24.22870,0.70290,2.69208,80.83330
97.20001,80.99998,24.18540,0.70435,2.68727,80.99998
97.40000,81.16661,24.29044,0.70580,2.69894,81.16661
97.60001,81.33330,24.21646,0.70725,2.69072,81.33330
97.80000,81.49998,24.39404,0.70870,2.71045,81.49998
98.00001,81.66661,24.47685,0.71014,2.71965,81.66661
98.20001,81.83330,24.45595,0.71159,2.71733,81.83330
98.40000,81.99998,24.42407,0.71304,2.71379,81.99998
98.60001,82.16661,24.39914,0.71449,2.71102,82.16661
98.80000,82.33336,24.54451,0.71594,2.72717,82.33336
99.00001,82.49993,24.63521,0.71739,2.73725,82.49993
99.20001,82.66661,24.63107,0.71884,2.73679,82.66661
99.40000,82.83337,24.83988,0.72029,2.75999,82.83337
99.60001,83.00005,24.65867,0.72174,2.73985,83.00005
99.80000,83.16667,24.59073,0.72319,2.73230,83.16667
100.00001,83.33330,24.67584,0.72464,2.74176,83.33330
100.20001,83.49999,24.64821,0.72609,2.73869,83.49999
100.40000,83.66661,24.93806,0.72754,2.77090,83.66661
100.60001,83.83336,24.69305,0.72899,2.74367,83.83336
100.80000,83.99999,24.81331,0.73043,2.75703,83.99999
101.00001,84.16668,24.83045,0.73188,2.75894,84.16668
101.20001,84.33330,24.94311,0.73333,2.77146,84.33330
101.40000,84.49992,24.98871,0.73478,2.77652,84.49992
101.60001,84.66667,25.06691,0.73623,2.78521,84.66667
101.80000,84.83336,24.94414,0.73768,2.77157,84.83336
102.00001,85.00005,25.19045,0.73913,2.79894,85.00005
102.20001,85.16661,25.13698,0.74058,2.79300,85.16661
102.40000,85.33330,25.06596,0.74203,2.78511,85.33330
102.60001,85.49993,25.19025,0.74348,2.79892,85.49993
102.80000,85.66661,25.03025,0.74493,2.78114,85.66661
103.00001,85.83342,25.28513,0.74638,2.80946,85.83342
103.20001,85.99998,25.28385,0.74783,2.80932,85.99998
103.40000,86.16661,25.30817,0.74927,2.81202,86.16661
103.60001,86.33330,25.39377,0.75072,2.82153,86.33330
103.80000,86.49998,25.52203,0.75217,2.83578,86.49998
104.00001,86.66667,25.36179,0.75362,2.81798,86.66667
104.20001,86.83342,25.33952,0.75507,2.81550,86.83342
104.40000,86.99999,25.26913,0.75652,2.80768,86.99999
104.60001,87.16661,25.51245,0.75797,2.83472,87.16661
104.80000,87.33329,25.56805,0.75942,2.84089,87.33329
105.00001,87.50005,25.35027,0.76087,2.81670,87.50005
105.20001,87.66655,25.62950,0.76232,2.84772,87.66655
105.40000,87.83330,25.66368,0.76377,2.85152,87.83330
105.60001,88.00011,25.67238,0.76522,2.85249,88.00011
105.80000,88.16668,25.76187,0.76667,2.86243,88.16668
106.00001,88.33330,25.67140,0.76812,2.85238,88.33330
106.20001,88.50005,25.72021,0.76957,2.85780,88.50005
106.40000,88.66668,25.91178,0.77101,2.87909,88.66668
106.60001,88.83330,25.93199,0.77246,2.88133,88.83330
106.80000,89.00005,25.84441,0.77391,2.87160,89.00005
107.00001,89.16668,25.88732,0.77536,2.87637,89.16668
107.20001,89.33336,26.08956,0.77681,2.89884,89.33336
107.40000,89.49999,25.80490,0.77826,2.86721,89.49999
107.60001,89.66661,26.10957,0.77971,2.90106,89.66661
107.80000,89.83330,26.06632,0.78116,2.89626,89.83330
108.00001,89.99999,26.08151,0.78261,2.89794,89.99999
108.20001,90.16667,26.21915,0.78406,2.91324,90.16667
108.40000,90.33336,25.97252,0.78551,2.88584,90.33336
108.60001,90.49999,26.23604,0.78696,2.91512,90.49999
108.80000,90.66661,26.15064,0.78841,2.90563,90.66661
109.00001,90.83324,26.09292,0.78985,2.89921,90.83324
109.20001,90.99999,26.23940,0.79130,2.91549,90.99999
109.40000,91.16667,26.28912,0.79275,2.92101,91.16667
109.60001,91.33336,26.29455,0.79420,2.92162,91.33336
109.80000,91.49999,26.40403,0.79565,2.93378,91.49999
110.00001,91.66662,26.45828,0.79710,2.93981,91.66662
110.20001,91.83336,26.44841,0.79855,2.93871,91.83336
110.40000,91.99998,26.41285,0.80000,2.93476,91.99998
110.60001,92.16667,26.37648,0.80145,2.93072,92.16667
110.80000,92.33336,26.45250,0.80290,2.93917,92.33336
111.00001,92.49998,26.48975,0.80435,2.94331,92.49998
111.20001,92.66661,26.75239,0.80580,2.97249,92.66661
111.40000,92.83330,26.72518,0.80725,2.96946,92.83330
111.60001,93.00006,26.36955,0.80870,2.92995,93.00006
111.80000,93.16661,26.63251,0.81014,2.95917,93.16661
112.00001,93.33330,26.58279,0.81159,2.95364,93.33330
112.20001,93.50005,26.71551,0.81304,2.96839,93.50005
112.40000,93.66661,26.85413,0.81449,2.98379,93.66661
112.60001,93.83336,26.66733,0.81594,2.96304,93.83336
112.80000,93.99999,26.94683,0.81739,2.99409,93.99999
113.00001,94.16661,26.75269,0.81884,2.97252,94.16661
113.20001,94.33329,26.88898,0.82029,2.98766,94.33329
113.40001,94.49999,26.87556,0.82174,2.98617,94.49999
113.60001,94.66661,27.00820,0.82319,3.00091,94.66661
113.80000,94.83336,27.04001,0.82464,3.00445,94.83336
114.00001,94.99999,27.05204,0.82609,3.00578,94.99999
114.20001,95.16661,27.07144,0.82754,3.00794,95.16661
114.40001,95.33330,27.08762,0.82899,3.00974,95.33330
114.60001,95.50005,27.19859,0.83044,3.02207,95.50005
114.80000,95.66667,27.19570,0.83188,3.02174,95.66667
115.00001,95.83335,27.08381,0.83333,3.00931,95.83335
115.20001,95.99999,27.36254,0.83478,3.04028,95.99999
115.40001,96.16661,27.26296,0.83623,3.02922,96.16661
115.60001,96.33330,27.25389,0.83768,3.02821,96.33330
115.80000,96.50005,27.34388,0.83913,3.03821,96.50005
116.00001,96.66667,27.36599,0.84058,3.04067,96.66667
116.20001,96.83330,27.40738,0.84203,3.04526,96.83330
116.40001,96.99998,27.39962,0.84348,3.04440,96.99998
116.60001,97.16661,27.56432,0.84493,3.06270,97.16661
116.80000,97.33336,27.31561,0.84638,3.03507,97.33336
117.00001,97.49998,27.50652,0.84783,3.05628,97.49998
117.20001,97.66661,27.63929,0.84927,3.07103,97.66661
117.40001,97.83329,27.47165,0.85072,3.05241,97.83329
117.60001,97.99998,27.54544,0.85217,3.06060,97.99998
117.80000,98.16667,27.45477,0.85362,3.05053,98.16667
118.00001,98.33329,27.67958,0.85507,3.07551,98.33329
118.20001,98.50005,27.75741,0.85652,3.08416,98.50005
118.40001,98.66661,27.62082,0.85797,3.06898,98.66661
118.60001,98.83329,27.90982,0.85942,3.10109,98.83329
118.80000,98.99999,28.09377,0.86087,3.12153,98.99999
119.00001,99.16667,27.81722,0.86232,3.09080,99.16667
119.20001,99.33336,27.80931,0.86377,3.08992,99.33336
119.40001,99.49998,27.80502,0.86522,3.08945,99.49998
119.60001,99.66655,28.08422,0.86667,3.12047,99.66655
119.80000,99.83336,27.97876,0.86812,3.10875,99.83336
120.00001,99.99998,27.93522,0.86957,3.10391,99.99998
120.20001,100.16668,27.94604,0.87101,3.10512,100.16668
120.40001,100.33336,28.04932,0.87246,3.11659,100.33336
120.60001,100.49999,28.22100,0.87391,3.13567,100.49999
120.80000,100.66661,28.15715,0.87536,3.12857,100.66661
121.00001,100.83330,28.07785,0.87681,3.11976,100.83330
121.20001,101.00004,28.29430,0.87826,3.14381,101.00004
121.40001,101.16667,28.35587,0.87971,3.15065,101.16667
121.60001,101.33330,28.35997,0.88116,3.15111,101.33330
121.80000,101.49999,28.46782,0.88261,3.16309,101.49999
122.00001,101.66667,28.34907,0.88406,3.14990,101.66667
122.20001,101.83330,28.61538,0.88551,3.17949,101.83330
122.40001,101.99999,28.44987,0.88696,3.16110,101.99999
122.60001,102.16661,28.37863,0.88841,3.15318,102.16661
122.80000,102.33330,28.47762,0.88985,3.16418,102.33330
123.00001,102.49998,28.48289,0.89130,3.16477,102.49998
123.20001,102.66667,28.55705,0.89275,3.17301,102.66667
123.40001,102.83336,28.68800,0.89420,3.18756,102.83336
123.60001,103.00005,28.59290,0.89565,3.17699,103.00005
123.80000,103.16655,28.67783,0.89710,3.18643,103.16655
124.00001,103.33336,28.93279,0.89855,3.21475,103.33336
124.20001,103.50005,28.64570,0.90000,3.18286,103.50005
124.40001,103.66667,28.63409,0.90145,3.18157,103.66667
124.60001,103.83336,29.00675,0.90290,3.22297,103.83336
124.80000,103.99993,28.95265,0.90435,3.21696,103.99993
125.00001,104.16660,28.70950,0.90580,3.18994,104.16660
125.20001,104.33330,28.88679,0.90725,3.20964,104.33330
125.40001,104.50005,28.93271,0.90870,3.21475,104.50005
125.60001,104.66661,28.95968,0.91014,3.21774,104.66661
125.80000,104.83336,28.90783,0.91159,3.21198,104.83336
126.00001,104.99999,28.99424,0.91304,3.22158,104.99999
126.20001,105.16655,29.07614,0.91449,3.23068,105.16655
126.40001,105.33337,28.90521,0.91594,3.21169,105.33337
126.60001,105.50004,29.11544,0.91739,3.23505,105.50004
126.80000,105.66667,29.10146,0.91884,3.23350,105.66667
127.00001,105.83330,29.18441,0.92029,3.24271,105.83330
127.20001,105.99999,29.23761,0.92174,3.24862,105.99999
127.40001,106.16661,29.12225,0.92319,3.23581,106.16661
127.60001,106.33330,29.12764,0.92464,3.23640,106.33330
127.80000,106.50005,29.32751,0.92609,3.25861,106.50005
128.00000,106.66661,29.37831,0.92754,3.26426,106.66661
128.20002,106.83330,29.39045,0.92899,3.26561,106.83330
128.40001,106.99999,29.41027,0.93043,3.26781,106.99999
128.60001,107.16661,29.49021,0.93188,3.27669,107.16661
128.80000,107.33336,29.37880,0.93333,3.26431,107.33336
129.00000,107.49999,29.45817,0.93478,3.27313,107.49999
129.20002,107.66661,29.74109,0.93623,3.30457,107.66661
129.40001,107.83330,29.44566,0.93768,3.27174,107.83330
129.60001,108.00004,29.59743,0.93913,3.28860,108.00004
129.80000,108.16661,29.42653,0.94058,3.26961,108.16661
130.00000,108.33336,29.67423,0.94203,3.29714,108.33336
130.20002,108.49998,29.74898,0.94348,3.30544,108.49998
130.40001,108.66661,29.90261,0.94493,3.32251,108.66661
130.60001,108.83336,29.79174,0.94638,3.31019,108.83336
130.80000,108.99998,29.80465,0.94783,3.31163,108.99998
131.00000,109.16667,29.97711,0.94928,3.33079,109.16667
131.20002,109.33329,29.91518,0.95072,3.32391,109.33329
131.40002,109.49999,29.95865,0.95217,3.32874,109.49999
131.60000,109.66667,29.89441,0.95362,3.32160,109.66667
131.80000,109.83337,29.93568,0.95507,3.32619,109.83337
132.00000,110.00005,30.04057,0.95652,3.33784,110.00005
132.20002,110.16661,29.92358,0.95797,3.32484,110.16661
132.40002,110.33324,30.02708,0.95942,3.33634,110.33324
132.60000,110.49998,29.96585,0.96087,3.32954,110.49998
132.80000,110.66668,29.99688,0.96232,3.33299,110.66668
133.00000,110.83336,30.20990,0.96377,3.35666,110.83336
133.20002,111.00005,30.28085,0.96522,3.36454,111.00005
133.40002,111.16661,30.31835,0.96667,3.36871,111.16661
133.60000,111.33330,30.52491,0.96812,3.39166,111.33330
133.80000,111.49999,30.34250,0.96957,3.37139,111.49999
134.00000,111.66661,30.32376,0.97101,3.36931,111.66661
134.20002,111.83336,30.36410,0.97246,3.37379,111.83336
134.40002,111.99999,30.51386,0.97391,3.39043,111.99999
134.60000,112.16655,30.47384,0.97536,3.38598,112.16655
134.80000,112.33330,30.37309,0.97681,3.37479,112.33330
135.00000,112.49999,30.52851,0.97826,3.39206,112.49999
135.20002,112.66667,30.64256,0.97971,3.40473,112.66667
135.40002,112.83336,30.60803,0.98116,3.40089,112.83336
135.60000,112.99998,30.74214,0.98261,3.41579,112.99998
135.80000,113.16661,30.79262,0.98406,3.42140,113.16661
136.00000,113.33336,30.70587,0.98551,3.41176,113.33336
136.20002,113.49998,30.62003,0.98696,3.40223,113.49998
136.40002,113.66667,30.77739,0.98841,3.41971,113.66667
136.60000,113.83330,30.76318,0.98985,3.41813,113.83330
136.80000,113.99998,30.89771,0.99130,3.43308,113.99998
137.00000,114.16667,30.98240,0.99275,3.44249,114.16667
137.20002,114.33329,30.99220,0.99420,3.44358,114.33329
137.40002,114.49998,31.09805,0.99565,3.45534,114.49998
137.60000,114.66661,30.97701,0.99710,3.44189,114.66661
137.80000,114.83330,30.94260,0.99855,3.43807,114.83330
138.00000,115.00005,31.06095,1.00000,3.45122,115.00005
138.20002,115.16660,30.94082,1.00145,3.43787,115.16660
138.40002,115.33336,31.09031,1.00290,3.45448,115.33336
138.60000,115.50005,31.13956,1.00435,3.45995,115.50005
138.80000,115.66661,31.12577,1.00580,3.45842,115.66661
139.00000,115.83324,31.03594,1.00725,3.44844,115.83324
139.20002,116.00005,31.15791,1.00870,3.46199,116.00005
139.40002,116.16673,31.17236,1.01015,3.46360,116.16673
139.60000,116.33337,31.23417,1.01159,3.47046,116.33337
139.80000,116.49999,31.25729,1.01304,3.47303,116.49999
140.00000,116.66655,31.46821,1.01449,3.49647,116.66655
140.20002,116.83336,31.31661,1.01594,3.47962,116.83336
140.40002,116.99999,31.33860,1.01739,3.48207,116.99999
140.60000,117.16668,31.34502,1.01884,3.48278,117.16668
140.80000,117.33335,31.61418,1.02029,3.51269,117.33335
141.00000,117.49987,31.36055,1.02174,3.48451,117.49987
141.20002,117.66661,31.62579,1.02319,3.51398,117.66661
141.40002,117.83330,31.52836,1.02464,3.50315,117.83330
141.60000,118.00005,31.71616,1.02609,3.52402,118.00005
141.80000,118.16667,31.65581,1.02754,3.51731,118.16667
142.00000,118.33330,31.90077,1.02899,3.54453,118.33330
142.20002,118.49998,31.65782,1.03043,3.51754,118.49998
142.40002,118.66667,31.82784,1.03188,3.53643,118.66667
142.60000,118.83330,31.86526,1.03333,3.54058,118.83330
142.80000,119.00004,31.88520,1.03478,3.54280,119.00004
143.00000,119.16661,31.80834,1.03623,3.53426,119.16661
143.20002,119.33330,31.92438,1.03768,3.54715,119.33330
143.40002,119.49998,32.00265,1.03913,3.55585,119.49998
143.60000,119.66667,32.18330,1.04058,3.57592,119.66667
143.80000,119.83336,31.89509,1.04203,3.54390,119.83336
144.00000,119.99998,32.21690,1.04348,3.57966,119.99998
144.20002,120.16661,31.96146,1.04493,3.55127,120.16661
144.40002,120.33324,32.31237,1.04638,3.59026,120.33324
144.60000,120.50005,31.98042,1.04783,3.55338,120.50005
144.80000,120.66661,32.06290,1.04927,3.56254,120.66661
145.00000,120.83337,32.15406,1.05072,3.57267,120.83337
145.20002,120.99999,32.26667,1.05217,3.58519,120.99999
145.40002,121.16661,32.38913,1.05362,3.59879,121.16661
145.60000,121.33336,32.30399,1.05507,3.58933,121.33336
145.80000,121.50005,32.46921,1.05652,3.60769,121.50005
146.00000,121.66668,32.41038,1.05797,3.60115,121.66668
146.20002,121.83336,32.26931,1.05942,3.58548,121.83336
146.40002,121.99992,32.49022,1.06087,3.61002,121.99992
146.60000,122.16661,32.47543,1.06232,3.60838,122.16661
146.80000,122.33336,32.51516,1.06377,3.61280,122.33336
147.00000,122.49999,32.52353,1.06522,3.61373,122.49999
147.20002,122.66661,32.45001,1.06667,3.60556,122.66661
147.40002,122.83330,32.63624,1.06812,3.62625,122.83330
147.60000,123.00004,32.64070,1.06957,3.62674,123.00004
147.80000,123.16667,32.73122,1.07101,3.63680,123.16667
148.00000,123.33336,32.85823,1.07246,3.65091,123.33336
148.20002,123.49999,32.75497,1.07391,3.63944,123.49999
148.40002,123.66661,32.87351,1.07536,3.65261,123.66661
148.60000,123.83323,32.87292,1.07681,3.65255,123.83323
148.80000,124.00005,33.00351,1.07826,3.66706,124.00005
149.00000,124.16667,32.94527,1.07971,3.66059,124.16667
149.20002,124.33336,33.00439,1.08116,3.66715,124.33336
149.40002,124.49998,33.10397,1.08261,3.67822,124.49998
149.60000,124.66662,32.94101,1.08406,3.66011,124.66662
149.80000,124.83336,33.01566,1.08551,3.66841,124.83336
150.00000,124.99998,33.19846,1.08696,3.68872,124.99998
150.20002,125.16667,33.06621,1.08841,3.67402,125.16667
150.40002,125.33336,33.20537,1.08986,3.68949,125.33336
150.60000,125.49998,33.01066,1.09130,3.66785,125.49998
150.80000,125.66661,33.32400,1.09275,3.70267,125.66661
151.00000,125.83329,33.27943,1.09420,3.69771,125.83329
151.20002,126.00005,33.28834,1.09565,3.69870,126.00005
151.40002,126.16667,33.49745,1.09710,3.72194,126.16667
151.60000,126.33330,33.38327,1.09855,3.70925,126.33330
151.80000,126.49992,33.51895,1.10000,3.72433,126.49992
152.00000,126.66660,33.32684,1.10145,3.70298,126.66660
152.20002,126.83335,33.65591,1.10290,3.73955,126.83335
152.40002,126.99998,33.56489,1.10435,3.72943,126.99998
152.60000,127.16666,33.59570,1.10580,3.73286,127.16666
152.80000,127.33328,33.59291,1.10725,3.73255,127.33328
153.00000,127.49999,33.74956,1.10870,3.74995,127.49999
153.20002,127.66667,33.52796,1.11014,3.72533,127.66667
153.40002,127.83336,33.64988,1.11159,3.73888,127.83336
153.60000,127.99998,33.82950,1.11304,3.75883,127.99998
153.80000,128.16667,33.92271,1.11449,3.76919,128.16667
154.00000,128.33329,33.65365,1.11594,3.73929,128.33329
154.20002,128.50004,34.13598,1.11739,3.79289,128.50004
154.40002,128.66667,33.92448,1.11884,3.76939,128.66667
154.60000,128.83330,34.13980,1.12029,3.79331,128.83330
154.80000,128.99998,33.86555,1.12174,3.76284,128.99998
155.00000,129.16661,34.04781,1.12319,3.78309,129.16661
155.20002,129.33335,33.89881,1.12464,3.76653,129.33335
155.40002,129.50005,34.07054,1.12609,3.78562,129.50005
155.60000,129.66667,34.01107,1.12754,3.77901,129.66667
155.80000,129.83330,34.19476,1.12899,3.79942,129.83330
156.00000,129.99998,34.00745,1.13043,3.77861,129.99998
156.20002,130.16661,34.17325,1.13188,3.79703,130.16661
156.40002,130.33335,34.08896,1.13333,3.78766,130.33335
156.60000,130.50004,34.08284,1.13478,3.78698,130.50004
156.80000,130.66660,34.32882,1.13623,3.81431,130.66660
157.00000,130.83328,34.24982,1.13768,3.80554,130.83328
157.20002,130.99998,34.33862,1.13913,3.81540,130.99998
157.40002,131.16661,34.33994,1.14058,3.81555,131.16661
157.60000,131.33329,34.32936,1.14203,3.81437,131.33329
157.80000,131.50004,34.43487,1.14348,3.82610,131.50004
158.00000,131.66666,34.40440,1.14493,3.82271,131.66666
158.20002,131.83328,34.64084,1.14638,3.84898,131.83328
158.40002,131.99999,34.43722,1.14783,3.82636,131.99999
158.60000,132.16661,34.62321,1.14927,3.84702,132.16661
158.80000,132.33336,34.50550,1.15072,3.83394,132.33336
159.00000,132.49998,34.51721,1.15217,3.83525,132.49998
159.20002,132.66660,34.54954,1.15362,3.83884,132.66660
159.40002,132.83329,34.76810,1.15507,3.86312,132.83329
159.60000,132.99997,34.84054,1.15652,3.87117,132.99997
159.80000,133.16668,34.94330,1.15797,3.88259,133.16668
160.00000,133.33330,34.97466,1.15942,3.88607,133.33330
160.20002,133.50004,34.75850,1.16087,3.86206,133.50004
160.40002,133.66667,34.96652,1.16232,3.88517,133.66667
160.60000,133.83329,34.96775,1.16377,3.88531,133.83329
160.80000,134.00003,35.00360,1.16522,3.88929,134.00003
161.00002,134.16666,35.02310,1.16667,3.89146,134.16666
161.20002,134.33329,34.97206,1.16812,3.88578,134.33329
161.40002,134.49999,35.14913,1.16957,3.90546,134.49999
161.60000,134.66666,35.31317,1.17101,3.92369,134.66666
161.80000,134.83335,35.16309,1.17246,3.90701,134.83335
162.00002,135.00004,35.01786,1.17391,3.89087,135.00004
162.20002,135.16660,35.09378,1.17536,3.89931,135.16660
162.40002,135.33329,35.34217,1.17681,3.92691,135.33329
162.60000,135.49998,35.51429,1.17826,3.94603,135.49998
162.80000,135.66667,35.48632,1.17971,3.94292,135.66667
163.00002,135.83335,35.51895,1.18116,3.94655,135.83335
163.20002,136.00004,35.40937,1.18261,3.93437,136.00004
163.40002,136.16661,35.40462,1.18406,3.93385,136.16661
163.60000,136.33328,35.64591,1.18551,3.96066,136.33328
163.80000,136.49992,35.54471,1.18696,3.94941,136.49992
164.00002,136.66674,35.55607,1.18841,3.95067,136.66674
164.20002,136.83336,35.68348,1.18986,3.96483,136.83336
164.40002,136.99998,35.63440,1.19130,3.95938,136.99998
164.60000,137.16660,35.70302,1.19275,3.96700,137.16660
164.80000,137.33329,35.58767,1.19420,3.95419,137.33329
165.00002,137.50004,35.68754,1.19565,3.96528,137.50004
165.20002,137.66673,35.83880,1.19710,3.98209,137.66673
165.40002,137.83336,35.89689,1.19855,3.98854,137.83336
165.60000,138.00004,36.00872,1.20000,4.00097,138.00004
165.80000,138.16661,35.95797,1.20145,3.99533,138.16661
166.00002,138.33329,35.94289,1.20290,3.99365,138.33329
166.20002,138.49998,35.83454,1.20435,3.98162,138.49998
166.40002,138.66666,36.08293,1.20580,4.00921,138.66666
166.60000,138.83329,35.96757,1.20725,3.99640,138.83329
166.80000,138.99991,36.05824,1.20869,4.00647,138.99991
167.00002,139.16661,36.06103,1.21014,4.00678,139.16661
167.20002,139.33335,36.09449,1.21159,4.01050,139.33335
167.40002,139.50004,36.00318,1.21304,4.00035,139.50004
167.60000,139.66660,36.21435,1.21449,4.02382,139.66660
167.80000,139.83334,36.27425,1.21594,4.03047,139.83334
168.00002,139.99998,36.46572,1.21739,4.05175,139.99998
168.20002,140.16660,36.40513,1.21884,4.04501,140.16660
168.40002,140.33335,36.28924,1.22029,4.03214,140.33335
168.60000,140.49998,36.28165,1.22174,4.03129,140.49998
168.80000,140.66661,36.51828,1.22319,4.05759,140.66661
169.00002,140.83329,36.50378,1.22464,4.05598,140.83329
169.20002,141.00003,36.44114,1.22609,4.04902,141.00003
169.40002,141.16667,36.72851,1.22754,4.08095,141.16667
169.60000,141.33336,36.70731,1.22899,4.07859,141.33336
169.80000,141.49998,36.67032,1.23043,4.07448,141.49998
170.00002,141.66661,36.65617,1.23188,4.07291,141.66661
170.20002,141.83329,36.71240,1.23333,4.07916,141.83329
170.40002,142.00004,36.65646,1.23478,4.07294,142.00004
170.60000,142.16661,36.60787,1.23623,4.06754,142.16661
170.80000,142.33328,36.57936,1.23768,4.06437,142.33328
171.00002,142.49998,36.70936,1.23913,4.07882,142.49998
171.20002,142.66667,36.80135,1.24058,4.08904,142.66667
171.40002,142.83336,36.69550,1.24203,4.07728,142.83336
171.60000,143.00004,36.85268,1.24348,4.09474,143.00004
171.80000,143.16660,36.76496,1.24493,4.08500,143.16660
172.00002,143.33323,37.01574,1.24638,4.11286,143.33323
172.20002,143.49997,37.04244,1.24783,4.11583,143.49997
172.40002,143.66667,37.02437,1.24928,4.11382,143.66667
172.60000,143.83336,36.83324,1.25072,4.09258,143.83336
172.80000,144.00004,36.96706,1.25217,4.10745,144.00004
173.00002,144.16667,37.08839,1.25362,4.12093,144.16667
173.20002,144.33329,37.09284,1.25507,4.12143,144.33329
173.40002,144.49991,37.24366,1.25652,4.13818,144.49991
173.60000,144.66668,36.99459,1.25797,4.11051,144.66668
173.80000,144.83335,37.16382,1.25942,4.12931,144.83335
174.00002,144.99999,37.09779,1.26087,4.12198,144.99999
174.20002,145.16667,36.97259,1.26232,4.10807,145.16667
174.40002,145.33329,37.05366,1.26377,4.11707,145.33329
174.60000,145.49998,37.14031,1.26522,4.12670,145.49998
174.80000,145.66660,36.87938,1.26667,4.09771,145.66660
175.00002,145.83336,36.92660,1.26812,4.10296,145.83336
175.20002,145.99998,37.01521,1.26957,4.11280,145.99998
175.40002,146.16667,37.19296,1.27101,4.13255,146.16667
175.60000,146.33330,36.88139,1.27246,4.09793,146.33330
175.80000,146.49997,36.48537,1.27391,4.05393,146.49997
176.00002,146.66666,0.13562,1.27536,0.01507,146.66666
176.20002,146.83335,-0.06457,1.27681,-0.00717,146.83335
176.40002,146.99991,-0.03555,1.27826,-0.00395,146.99991
176.60000,147.16660,0.03638,1.27971,0.00404,147.16660
176.80000,147.33329,-0.00232,1.28116,-0.00026,147.33329
177.00002,147.50004,-0.02857,1.28261,-0.00317,147.50004
177.20002,147.66661,0.19584,1.28406,0.02176,147.66661
177.40002,147.83335,0.04733,1.28551,0.00526,147.83335
177.60000,147.99997,0.19780,1.28696,0.02198,147.99997
177.80000,148.16660,0.02597,1.28841,0.00289,148.16660
178.00002,148.33336,0.07130,1.28986,0.00792,148.33336
178.20002,148.50005,0.00746,1.29130,0.00083,148.50005
178.40002,148.66660,0.05200,1.29275,0.00578,148.66660
178.60000,148.83329,0.17179,1.29420,0.01909,148.83329
178.80000,148.99998,0.20361,1.29565,0.02262,148.99998
179.00002,149.16666,0.10353,1.29710,0.01150,149.16666
179.20002,149.33336,0.26018,1.29855,0.02891,149.33336
179.40002,149.49999,-0.02798,1.30000,-0.00311,149.49999
179.60000,149.66654,0.17982,1.30145,0.01998,149.66654
179.80000,149.83329,0.13319,1.30290,0.01480,149.83329
180.00002,150.00003,0.12658,1.30435,0.01406,150.00003
180.20002,150.16667,0.13065,1.30580,0.01452,150.16667
180.24000,150.20004,0.32038,1.30609,0.03560,150.20004