File: V_8/NR/RDSO NR Tensile 50.is_tens_RawData/Specimen_RawData_7.csv
Time,Extension,Load
(sec),(mm),(N)
0.00000,0.00000,0.01761
0.10000,0.07575,0.26084
0.20000,0.16469,0.41970
0.30000,0.24931,0.55151
0.40000,0.33294,0.50452
0.50000,0.41675,0.80401
0.60000,0.50000,1.03117
0.70000,0.58331,1.09016
0.80000,0.66675,1.30429
0.90000,0.74994,1.52950
1.00000,0.83325,1.45556
1.10000,0.91675,1.64710
1.20000,0.99994,1.85735
1.30000,1.08331,1.81801
1.40000,1.16681,2.10495
1.50000,1.25000,2.09809
1.60000,1.33331,2.52875
1.70000,1.41675,2.48294
1.80000,1.49994,2.45035
1.90000,1.58325,2.66188
2.00000,1.66669,2.92183
2.10000,1.75000,2.80050
2.20000,1.83331,3.03693
2.30000,1.91675,2.93153
2.40000,2.00000,3.27066
2.50000,2.08331,3.34700
2.60000,2.16675,3.28497
2.70000,2.25000,3.63252
2.80000,2.33331,3.54168
2.90000,2.41675,3.67246
3.00000,2.49994,3.83518
3.10000,2.58325,3.80343
3.20000,2.66675,3.89565
3.30000,2.75000,4.11561
3.40000,2.83325,4.13663
3.50000,2.91675,4.10209
3.60000,3.00000,4.27912
3.70000,3.08331,4.13889
3.80000,3.16681,4.25413
3.90000,3.24994,4.47752
4.00000,3.33325,4.55210
4.10000,3.41675,4.72051
4.20000,3.49987,4.88510
4.30000,3.58325,4.81597
4.40000,3.66681,4.92244
4.50000,3.75000,5.04259
4.60000,3.83331,5.01657
4.70000,3.91681,5.14284
4.80000,3.99994,5.47114
4.90000,4.08325,5.19258
5.00000,4.16669,5.46276
5.10000,4.24994,5.43248
5.20000,4.33331,5.44978
5.30000,4.41675,5.53122
5.40000,4.49994,5.41053
5.50000,4.58325,5.67337
5.60000,4.66681,5.80552
5.70000,4.74994,5.90038
5.80000,4.83325,5.98079
5.90000,4.91681,5.72055
6.00000,5.00000,6.13514
6.10000,5.08319,6.09427
6.20000,5.16669,6.14063
6.30000,5.25000,6.33148
6.40000,5.33325,6.04767
6.50000,5.41675,6.37980
6.60000,5.50000,6.40425
6.70000,5.58331,6.31173
6.80000,5.66681,6.64239
6.90000,5.74994,6.49460
7.00000,5.83325,6.62832
7.10000,5.91675,6.50901
7.20000,5.99994,6.69599
7.30000,6.08325,6.74475
7.40000,6.16675,6.83554
7.50000,6.25000,6.94324
7.60000,6.33325,6.98921
7.70000,6.41669,7.07128
7.80000,6.50000,7.19687
7.90000,6.58331,7.29286
8.00000,6.66675,7.16276
8.10000,6.75000,7.28879
8.20000,6.83331,7.14919
8.30000,6.91681,7.44182
8.40000,6.99994,7.28928
8.50000,7.08319,7.45461
8.60000,7.16675,7.62385
8.70000,7.24994,7.55471
8.80000,7.33325,7.44005
8.90000,7.41681,7.70068
9.00000,7.50006,7.72994
9.10000,7.58331,7.81554
9.20000,7.66675,7.63439
9.30000,7.75000,7.97278
9.40000,7.83319,7.80280
9.50000,7.91669,8.03192
9.60000,7.99994,8.15060
9.70000,8.08331,8.04829
9.80000,8.16681,8.13722
9.90000,8.25000,8.22268
10.00000,8.33325,8.30676
10.10000,8.41681,8.25830
10.20000,8.49994,8.16025
10.30000,8.58319,8.44264
10.40000,8.66675,8.42358
10.50000,8.75000,8.57587
10.60000,8.83325,8.51590
10.70000,8.91675,8.67127
10.80000,9.00000,8.71498
10.90000,9.08331,8.63394
11.00000,9.16675,8.72179
11.10000,9.25000,8.76643
11.20000,9.33331,8.80249
11.30000,9.41681,8.90451
11.40000,9.49994,8.97022
11.50000,9.58319,8.96630
11.60000,9.66669,9.07636
11.70000,9.74994,9.18553
11.80000,9.83325,9.23585
11.90000,9.91675,9.22203
12.00000,10.00000,9.40044
12.10000,10.08331,9.33032
12.20000,10.16675,9.34174
12.30000,10.24994,9.36869
12.40000,10.33325,9.49957
12.50000,10.41675,9.40201
12.60000,10.49994,9.41984
12.70000,10.58325,9.72663
12.80000,10.66675,9.57488
12.90000,10.74994,9.78293
13.00000,10.83325,9.63422
13.10000,10.91675,9.81924
13.20000,10.99994,9.79146
13.30000,11.08331,9.85619
13.40000,11.16669,9.89627
13.50000,11.25000,9.88132
13.60000,11.33325,9.97428
13.70000,11.41669,10.08472
13.80000,11.49994,10.04263
13.90000,11.58325,10.20507
14.00000,11.66675,10.17689
14.10000,11.75000,10.15313
14.20000,11.83331,10.30174
14.30000,11.91675,10.18018
14.40000,12.00000,10.43684
14.50000,12.08325,10.33604
14.60000,12.16675,10.43164
14.70000,12.24994,10.53939
14.80000,12.33325,10.49995
14.90000,12.41675,10.83226
15.00000,12.49994,10.44781
15.10000,12.58331,10.56090
15.20000,12.66675,10.64136
15.30000,12.74994,10.73044
15.40000,12.83325,10.75367
15.50000,12.91681,10.71942
15.60000,12.99994,10.89846
15.70000,13.08325,10.73431
15.80000,13.16681,10.85103
15.90000,13.25000,10.94354
16.00000,13.33319,10.90763
16.10000,13.41675,10.99588
16.20000,13.49994,10.96089
16.30000,13.58325,11.07810
16.40000,13.66675,11.09549
16.50000,13.75000,11.11387
16.60000,13.83331,11.04399
16.70000,13.91675,11.08604
16.80000,13.99994,11.31452
16.90000,14.08325,11.29365
17.00000,14.16675,11.23313
17.10000,14.25000,11.37009
17.20000,14.33325,11.45241
17.30000,14.41675,11.42203
17.40000,14.50000,11.53595
17.50000,14.58325,11.39145
17.60000,14.66675,11.20265
17.70000,14.75000,11.34598
17.80000,14.83325,11.68932
17.90000,14.91669,11.54850
18.00000,15.00000,11.82677
18.10000,15.08319,11.52728
18.20000,15.16675,11.52003
18.30000,15.24994,11.66218
18.40000,15.33331,11.73705
18.50000,15.41681,11.77145
18.60000,15.50000,11.67251
18.70000,15.58331,11.69309
18.80000,15.66668,11.69118
18.90000,15.74993,11.87459
19.00000,15.83318,11.89767
19.10000,15.91668,12.05966
19.20000,15.99994,11.84950
19.30000,16.08331,12.01492
19.40000,16.16681,11.79815
19.50000,16.25000,11.82917
19.60000,16.33325,11.94971
19.70000,16.41675,12.15399
19.80000,16.49993,11.98210
19.90000,16.58325,12.11493
20.00000,16.66675,11.98229
20.10000,16.75000,12.10327
20.20000,16.83325,12.10077
20.30000,16.91675,12.11591
20.40000,16.99993,12.14693
20.50000,17.08325,12.27012
20.60000,17.16675,12.02610
20.70000,17.25000,12.09916
20.80000,17.33337,12.35121
20.90000,17.41681,12.36993
21.00000,17.50000,12.19049
21.10000,17.58325,12.31725
21.20000,17.66675,12.12503
21.30000,17.74994,12.38541
21.40000,17.83318,12.44823
21.50000,17.91675,12.54564
21.60000,18.00000,12.29422
21.70000,18.08331,12.53182
21.80000,18.16681,12.51928
21.90000,18.24994,12.42064
22.00000,18.33325,12.65133
22.10000,18.41675,12.72062
22.20000,18.49993,12.60170
22.30000,18.58325,12.68725
22.40000,18.66675,12.57029
22.50000,18.75000,12.62468
22.60000,18.83331,12.63262
22.70000,18.91681,12.67285
22.80000,19.00000,12.50757
22.90000,19.08325,12.71043
23.00000,19.16675,12.78525
23.10000,19.25000,12.81823
23.20000,19.33325,12.83925
23.30000,19.41668,12.76673
23.40000,19.49994,12.90084
23.50000,19.58325,12.85723
23.60000,19.66669,12.67907
23.70000,19.75000,12.63776
23.80000,19.83325,13.12585
23.90000,19.91681,12.80319
24.00000,20.00000,13.00364
24.10000,20.08325,13.02716
24.20000,20.16675,13.11977
24.30000,20.24994,12.95915
24.40000,20.33318,13.01379
24.50000,20.41668,13.07087
24.60000,20.50000,13.14981
24.70000,20.58331,13.24213
24.80000,20.66675,13.05941
24.90000,20.74993,13.03084
25.00000,20.83331,13.22243
25.10000,20.91675,13.13315
25.20000,20.99993,12.93465
25.30000,21.08331,13.14986
25.40000,21.16675,13.11850
25.50000,21.25000,13.12894
25.60000,21.33325,13.17407
25.70000,21.41668,13.03848
25.80000,21.49994,13.25756
25.90000,21.58331,13.27843
26.00000,21.66675,13.23468
26.10000,21.75000,13.33135
26.20000,21.83331,13.24575
26.30000,21.91675,13.44499
26.40000,21.99993,13.29578
26.50000,22.08325,13.50408
26.60000,22.16675,13.26271
26.70000,22.24993,13.37937
26.80000,22.33325,13.34106
26.90000,22.41687,13.57253
27.00000,22.49993,13.43896
27.10000,22.58325,13.51848
27.20000,22.66681,13.28652
27.30000,22.75000,13.52525
27.40000,22.83331,13.41735
27.50000,22.91675,13.55058
27.60000,22.99994,13.40471
27.70000,23.08325,13.61075
27.80000,23.16675,13.57694
27.90000,23.24993,13.54847
28.00000,23.33325,13.68435
28.10000,23.41675,13.53970
28.20000,23.50000,13.61996
28.30000,23.58331,13.72742
28.40000,23.66681,13.64015
28.50000,23.75000,13.56974
28.60000,23.83325,13.84649
28.70000,23.91675,13.71012
28.80000,24.00000,13.57689
28.90000,24.08325,13.71199
29.00000,24.16662,13.76598
29.10000,24.24994,13.67034
29.20000,24.33331,13.63486
29.30000,24.41681,13.85325
29.40000,24.50000,13.98197
29.50000,24.58331,13.92852
29.60000,24.66675,13.88510
29.70000,24.74993,13.85840
29.80000,24.83318,13.93302
29.90000,24.91681,14.02877
30.00000,24.99999,14.15024
30.10000,25.08325,13.91142
30.20000,25.16681,14.04371
30.30000,25.25000,13.80043
30.40000,25.33331,13.96527
30.50000,25.41675,14.20135
30.60000,25.49987,14.05180
30.70000,25.58324,14.12569
30.80000,25.66675,13.93734
30.90000,25.74993,14.04749
31.00000,25.83325,14.00358
31.10000,25.91675,14.08835
31.20000,26.00000,14.01755
31.30000,26.08331,14.29028
31.40000,26.16675,13.88255
31.50000,26.25006,14.19346
31.60000,26.33331,14.07733
31.70000,26.41669,14.26436
31.80000,26.49993,14.16827
31.90000,26.58325,14.23922
32.00000,26.66668,14.29518
32.10000,26.74993,14.17797
32.20000,26.83325,14.22928
32.30000,26.91681,14.15813
32.40000,27.00000,14.15813
32.50000,27.08325,14.30596
32.60000,27.16674,14.26176
32.70000,27.25000,14.22291
32.80000,27.33325,14.38755
32.90000,27.41675,14.27578
33.00000,27.49993,14.41964
33.10000,27.58325,14.28641
33.20000,27.66675,14.49152
33.30000,27.74999,14.34996
33.40000,27.83325,14.36800
33.50000,27.91675,14.39544
33.60000,28.00000,14.21531
33.70000,28.08325,14.41244
33.80000,28.16675,14.57806
33.90000,28.24993,14.47633
34.00000,28.33324,14.49603
34.10000,28.41675,14.58359
34.20000,28.50000,14.48344
34.30000,28.58325,14.47810
34.40000,28.66675,14.67439
34.50000,28.75000,14.54146
34.60000,28.83331,14.55081
34.70000,28.91675,14.62622
34.80000,29.00000,14.60099
34.90000,29.08325,14.46350
35.00000,29.16675,14.78871
35.10000,29.24993,14.56968
35.20000,29.33325,14.73182
35.30000,29.41675,14.68493
35.40000,29.49993,14.69257
35.50000,29.58325,14.86770
35.60000,29.66675,14.72471
35.70000,29.75000,14.85937
35.80000,29.83331,14.67630
35.90000,29.91674,14.85109
36.00000,30.00000,14.95982
36.10000,30.08325,14.78969
36.20000,30.16668,14.87946
36.30000,30.24993,15.00205
36.40000,30.33325,14.81149
36.50000,30.41681,14.91420
36.60000,30.49993,14.92478
36.70000,30.58325,14.81282
36.80000,30.66681,14.90680
36.90000,30.75000,15.12406
37.00000,30.83325,15.03106
37.10000,30.91675,15.14009
37.20000,30.99993,15.05409
37.30000,31.08324,15.06404
37.40000,31.16668,14.98319
37.50000,31.25000,15.10623
37.60000,31.33331,15.24431
37.70000,31.41674,15.18095
37.80000,31.49993,14.96153
37.90000,31.58331,15.00749
38.00000,31.66674,15.13984
38.10000,31.74993,15.12318
38.20000,31.83324,14.91694
38.30000,31.91675,15.22628
38.40000,31.99999,15.18620
38.50000,32.08318,15.10735
38.60000,32.16675,15.17086
38.70000,32.24999,15.05434
38.80000,32.33337,15.39087
38.90000,32.41681,15.34495
39.00000,32.50000,15.30977
39.10000,32.58331,15.27253
39.20000,32.66662,15.23093
39.30000,32.74987,15.15880
39.40000,32.83318,15.27390
39.50000,32.91681,15.14861
39.60000,32.99993,15.42669
39.70000,33.08325,15.47696
39.80000,33.16681,15.32947
39.90000,33.24999,15.30928
40.00000,33.33318,15.51302
40.10000,33.41675,15.43624
40.20000,33.49999,15.43771
40.30000,33.58331,15.41997
40.40000,33.66675,15.39244
40.50000,33.74999,15.48142
40.60000,33.83324,15.35088
40.70000,33.91674,15.43315
40.80000,33.99987,15.48882
40.90000,34.08324,15.54095
41.00000,34.16675,15.45417
41.10000,34.25000,15.42821
41.20000,34.33331,15.50602
41.30000,34.41674,15.58530
41.40000,34.49999,15.68119
41.50000,34.58325,15.65787
41.60000,34.66674,15.58123
41.70000,34.74993,15.58745
41.80000,34.83325,15.62043
41.90000,34.91674,15.68756
42.00000,34.99999,15.70961
42.10000,35.08331,15.74764
42.20000,35.16675,15.66424
42.30000,35.24993,15.77953
42.40000,35.33318,15.49769
42.50000,35.41674,15.74803
42.60000,35.49999,15.98965
42.70000,35.58324,16.02355
42.80000,35.66675,15.95794
42.90000,35.74993,15.74200
43.00000,35.83324,15.76939
43.10000,35.91675,15.67570
43.20000,35.99999,15.92075
43.30000,36.08331,16.15443
43.40000,36.16675,15.80918
43.50000,36.25000,15.76777
43.60000,36.33325,15.92222
43.70000,36.41674,16.05869
43.80000,36.49993,15.93496
43.90000,36.58318,15.92369
44.00000,36.66674,16.08333
44.10000,36.74999,15.94790
44.20000,36.83325,15.91159
44.30000,36.91674,15.93222
44.40000,36.99999,16.02644
44.50000,37.08331,16.36033
44.60000,37.16668,15.93462
44.70000,37.24999,16.14674
44.80000,37.33324,16.10994
44.90000,37.41675,16.21931
45.00000,37.49993,16.23548
45.10000,37.58324,16.21549
45.20000,37.66675,16.30045
45.30000,37.74999,16.24224
45.40000,37.83325,16.12567
45.50000,37.91675,16.23621
45.60000,38.00000,16.26238
45.70000,38.08324,16.06217
45.80000,38.16668,16.20500
45.90000,38.24993,16.21088
46.00000,38.33324,16.33921
46.10000,38.41668,16.22950
46.20000,38.50000,16.22558
46.30000,38.58331,16.32569
46.40000,38.66687,16.42682
46.50000,38.74999,16.40605
46.60000,38.83331,16.30942
46.70000,38.91675,16.56030
46.80000,38.99993,16.41673
46.90000,39.08318,16.61126
47.00000,39.16674,16.43648
47.10000,39.24999,16.59328
47.20000,39.33331,16.45137
47.30000,39.41681,16.44358
47.40000,39.49999,16.49625
47.50000,39.58330,16.47131
47.60000,39.66675,16.36768
47.70000,39.74993,16.52360
47.80000,39.83324,16.56471
47.90000,39.91681,16.62909
48.00000,39.99993,16.67079
48.10000,40.08318,16.73885
48.20000,40.16674,16.64321
48.30000,40.24993,16.69671
48.40000,40.33324,16.55981
48.50000,40.41681,16.76840
48.60000,40.49993,16.61003
48.70000,40.58330,16.75850
48.80000,40.66675,16.88531
48.90000,40.74999,16.80123
49.00000,40.83325,16.77438
49.10000,40.91668,16.75213
49.20000,40.99993,16.79741
49.30000,41.08324,16.76879
49.40000,41.16674,16.87674
49.50000,41.25000,16.80647
49.60000,41.33331,16.93931
49.70000,41.41680,16.73557
49.80000,41.49999,16.78423
49.90000,41.58324,16.87767
50.00000,41.66674,16.97836
50.10000,41.74993,16.79692
50.20000,41.83325,16.83063
50.30000,41.91674,16.82548
50.40000,41.99999,16.88757
50.50000,42.08324,17.03491
50.60000,42.16681,16.96651
50.70000,42.24999,16.99826
50.80000,42.33324,16.86253
50.90000,42.41674,16.97204
51.00000,42.49993,16.91207
51.10000,42.58318,17.04961
51.20000,42.66674,16.97738
51.30000,42.74993,16.86145
51.40000,42.83324,17.16750
51.50000,42.91675,16.96489
51.60000,42.99999,17.04829
51.70000,43.08337,17.08969
51.80000,43.16681,17.04594
51.90000,43.24999,17.20881
52.00000,43.33324,17.10733
52.10000,43.41675,17.39717
52.20000,43.50000,17.34229
52.30000,43.58324,17.22797
52.40000,43.66674,17.05294
52.50000,43.75000,17.19906
52.60000,43.83331,17.35650
52.70000,43.91668,17.21400
52.80000,44.00000,17.33141
52.90000,44.08325,17.23527
53.00000,44.16674,17.39496
53.10000,44.24999,17.32964
53.20000,44.33331,17.57151
53.30000,44.41674,17.58322
53.40000,44.49993,17.36213
53.50000,44.58318,17.53260
53.60000,44.66674,17.47704
53.70000,44.74999,17.43058
53.80000,44.83324,17.65358
53.90000,44.91674,17.21680
54.00000,44.99999,17.42730
54.10000,45.08324,17.62261
54.20000,45.16675,17.58253
54.30000,45.24993,17.60360
54.40000,45.33324,17.73355
54.50000,45.41674,17.56475
54.60000,45.49993,17.53280
54.70000,45.58324,17.75952
54.80000,45.66681,17.64305
54.90000,45.75000,17.61281
55.00000,45.83324,17.65628
55.10000,45.91674,17.65936
55.20000,45.99999,17.58910
55.30000,46.08324,17.54137
55.40000,46.16668,17.82155
55.50000,46.24999,17.77231
55.60000,46.33325,17.68426
55.70000,46.41668,17.84233
55.80000,46.49999,17.81675
55.90000,46.58331,17.77574
56.00000,46.66674,17.84409
56.10000,46.75000,17.92215
56.20000,46.83331,17.92690
56.30000,46.91680,17.82557
56.40000,46.99999,17.89133
56.50000,47.08324,17.96914
56.60000,47.16674,17.85551
56.70000,47.24999,17.83375
56.80000,47.33324,17.99001
56.90000,47.41680,17.96062
57.00000,47.49999,18.06988
57.10000,47.58324,18.07023
57.20000,47.66674,18.18763
57.30000,47.74993,18.03710
57.40000,47.83330,17.99795
57.50000,47.91674,18.06724
57.60000,47.99993,17.93386
57.70000,48.08324,17.96919
57.80000,48.16674,18.28235
57.90000,48.24999,18.19003
58.00000,48.33324,18.13290
58.10000,48.41681,17.90696
58.20000,48.49999,18.20277
58.30000,48.58330,18.08351
58.40000,48.66675,17.97953
58.50000,48.74999,17.95023
58.60000,48.83324,18.06234
58.70000,48.91668,18.12692
58.80000,48.99993,18.26946
58.90000,49.08324,18.25550
59.00000,49.16674,18.17827
59.10000,49.25000,18.31920
59.20000,49.33331,18.37070
59.30000,49.41680,18.21017
59.40000,49.50000,18.32522
59.50000,49.58324,18.11178
59.60000,49.66668,18.28044
59.70000,49.74993,18.23109
59.80000,49.83330,18.29720
59.90000,49.91674,18.46855
60.00000,49.99999,18.38520
60.10000,50.08331,18.34051
60.20000,50.16681,18.44914
60.30000,50.24987,18.38329
60.40000,50.33324,18.36550
60.50000,50.41681,18.40887
60.60000,50.49993,18.72589
60.70000,50.58330,18.36290
60.80000,50.66674,18.47516
60.90000,50.74993,18.58154
61.00000,50.83318,18.56557
61.10000,50.91668,18.57360
61.20000,50.99993,18.53916
61.30000,51.08330,18.63397
61.40000,51.16674,18.64955
61.50000,51.24999,18.68954
61.60000,51.33331,18.47595
61.70000,51.41674,18.66484
61.80000,51.49993,18.58703
61.90000,51.58324,18.64215
62.00000,51.66674,18.64054
62.10000,51.74999,18.80900
62.20000,51.83324,18.83796
62.30000,51.91674,18.67944
62.40000,51.99999,18.91126
62.50000,52.08324,18.67023
62.60000,52.16674,18.95913
62.70000,52.24993,18.72344
62.80000,52.33324,18.86951
62.90000,52.41668,18.85805
63.00000,52.49993,18.85599
63.10000,52.58324,19.03450
63.20000,52.66674,18.87755
63.30000,52.74993,18.86241
63.40000,52.83324,18.99843
63.50000,52.91680,18.99074
63.60000,52.99999,18.99667
63.70000,53.08331,19.05312
63.80000,53.16680,18.89686
63.90000,53.24999,19.17601
64.00000,53.33324,18.85403
64.10001,53.41668,19.20639
64.20000,53.49999,18.88554
64.30000,53.58324,19.01739
64.40000,53.66674,18.92395
64.50000,53.74999,18.94899
64.60001,53.83324,19.21800
64.70000,53.91681,19.20825
64.80000,53.99993,19.01676
64.90000,54.08324,19.10731
65.00000,54.16675,19.37843
65.10001,54.24999,19.14965
65.20000,54.33324,19.20629
65.30000,54.41674,19.43247
65.40000,54.49999,19.12975
65.50000,54.58324,19.20178
65.60001,54.66674,19.21320
65.70001,54.75000,19.38764
65.80000,54.83324,19.49353
65.90000,54.91674,19.20825
66.00000,55.00000,19.29709
66.10001,55.08318,19.54723
66.20001,55.16668,19.61911
66.30000,55.24993,19.38666
66.40000,55.33325,19.32805
66.50000,55.41674,19.37823
66.60001,55.50005,19.49593
66.70001,55.58331,19.28312
66.80000,55.66681,19.50323
66.90000,55.74993,19.59118
67.00000,55.83324,19.45080
67.10001,55.91668,19.35829
67.20001,55.99987,19.54988
67.30000,56.08324,19.67032
67.40000,56.16674,19.55385
67.50000,56.24993,19.61294
67.60001,56.33330,19.57830
67.70001,56.41674,19.51543
67.80000,56.49999,19.38710
67.90000,56.58324,19.63974
68.00000,56.66674,19.63127
68.10001,56.74999,19.65493
68.20001,56.83324,19.59765
68.30000,56.91674,19.73167
68.40000,56.99993,19.81413
68.50000,57.08324,19.69026
68.60001,57.16668,19.63729
68.70001,57.24993,19.95261
68.80000,57.33324,19.72731
68.90000,57.41681,19.85789
69.00000,57.49993,19.62592
69.10001,57.58324,19.82658
69.20001,57.66674,19.72343
69.30000,57.74999,19.99308
69.40000,57.83324,20.12690
69.50000,57.91674,19.99896
69.60001,57.99993,19.91987
69.70001,58.08318,19.85622
69.80000,58.16674,19.71319
69.90000,58.24999,20.06006
70.00000,58.33331,19.98279
70.10001,58.41674,19.72182
70.20001,58.49999,20.14664
70.30000,58.58331,20.21059
70.40000,58.66674,20.31094
70.50000,58.74987,20.17541
70.60001,58.83318,19.91439
70.70001,58.91668,20.02370
70.80000,58.99999,20.14768
70.90000,59.08324,20.23979
71.00000,59.16681,20.13155
71.10001,59.24999,20.16561
71.20001,59.33330,20.17668
71.30000,59.41668,20.13052
71.40000,59.49993,20.26273
71.50000,59.58318,20.09598
71.60001,59.66668,20.23097
71.70001,59.74993,20.20809
71.80000,59.83324,20.22230
71.90000,59.91681,20.22911
72.00000,59.99999,20.27566
72.10001,60.08324,20.24773
72.20001,60.16674,20.25822
72.30000,60.25000,20.42193
72.40000,60.33324,20.23666
72.50000,60.41668,20.43501
72.60001,60.49993,20.47676
72.70001,60.58324,20.35293
72.80000,60.66668,20.47803
72.90000,60.74993,20.52051
73.00000,60.83325,20.55006
73.10001,60.91674,20.50111
73.20001,60.99993,20.67148
73.30000,61.08331,20.61067
73.40000,61.16674,20.51904
73.50000,61.24999,20.68231
73.60001,61.33324,20.66840
73.70001,61.41668,20.45172
73.80000,61.49993,20.41845
73.90000,61.58324,20.54893
74.00000,61.66674,20.81883
74.10001,61.74999,20.64840
74.20001,61.83330,20.61023
74.30000,61.91680,20.55124
74.40000,61.99993,20.77046
74.50000,62.08324,20.63189
74.60001,62.16674,20.55707
74.70001,62.24987,20.84543
74.80000,62.33318,20.82554
74.90000,62.41681,20.69442
75.00000,62.49999,20.65987
75.10001,62.58324,20.81118
75.20001,62.66681,20.96284
75.30000,62.74993,20.84602
75.40000,62.83324,20.95656
75.50000,62.91680,20.94823
75.60001,62.99999,20.82490
75.70001,63.08324,21.02928
75.80000,63.16674,20.81936
75.90000,63.24993,20.93432
76.00000,63.33318,20.98567
76.10001,63.41674,21.00875
76.20001,63.49999,20.96602
76.30000,63.58324,20.95661
76.40000,63.66680,20.95617
76.50000,63.75005,21.07122
76.60001,63.83324,20.87645
76.70001,63.91668,20.74885
76.80000,63.99999,21.04192
76.90000,64.08324,21.13532
77.00000,64.16674,21.23807
77.10001,64.24999,21.15982
77.20001,64.33330,21.06333
77.30000,64.41674,21.18402
77.40000,64.49999,21.34107
77.50000,64.58324,21.23140
77.60001,64.66674,21.07103
77.70001,64.74999,21.33626
77.80000,64.83324,21.18466
77.90000,64.91668,21.13385
78.00000,64.99999,21.30177
78.10001,65.08324,21.21455
78.20001,65.16674,21.18211
78.30000,65.24993,21.34087
78.40000,65.33330,21.18530
78.50000,65.41674,21.40295
78.60001,65.49993,21.14516
78.70001,65.58330,21.15805
78.80000,65.66667,21.27438
78.90000,65.74999,21.42334
79.00000,65.83318,21.48385
79.10001,65.91668,21.38237
79.20001,65.99993,21.29417
79.30000,66.08331,21.54584
79.40000,66.16674,21.54030
79.50000,66.25005,21.46665
79.60001,66.33330,21.58141
79.70001,66.41680,21.53961
79.80000,66.49993,21.51541
79.90000,66.58318,21.52712
80.00000,66.66674,21.70371
80.10001,66.74992,21.54682
80.20001,66.83324,21.42936
80.30000,66.91680,21.42696
80.40000,66.99993,21.48062
80.50001,67.08324,21.76776
80.60001,67.16674,21.67079
80.70001,67.24999,21.95327
80.80000,67.33330,21.72214
80.90000,67.41674,21.76472
81.00001,67.49999,21.64580
81.10001,67.58330,21.83881
81.20001,67.66674,21.72557
81.30000,67.74993,21.77868
81.40000,67.83324,21.71209
81.50001,67.91674,21.89677
81.60001,67.99993,21.79980
81.70001,68.08330,21.85850
81.80000,68.16680,21.71910
81.90000,68.25005,21.84665
82.00001,68.33324,21.95660
82.10001,68.41674,21.69014
82.20001,68.49999,21.92960
82.30000,68.58324,22.02584
82.40000,68.66674,21.98360
82.50001,68.74999,21.84503
82.60001,68.83324,21.97904
82.70001,68.91680,21.99031
82.80000,68.99999,21.90496
82.90000,69.08324,21.90138
83.00001,69.16680,22.13364
83.10001,69.24999,22.07832
83.20001,69.33318,21.84101
83.30000,69.41674,22.18367
83.40000,69.49992,22.06764
83.50001,69.58318,22.32234
83.60001,69.66674,22.17936
83.70001,69.74999,22.23448
83.80000,69.83330,22.20371
83.90000,69.91680,22.26466
84.00001,69.99999,22.16593
84.10001,70.08330,22.12727
84.20001,70.16674,22.19822
84.30000,70.24992,22.27098
84.40000,70.33318,22.29931
84.50001,70.41674,22.37261
84.60001,70.49993,22.45851
84.70001,70.58330,22.34267
84.80000,70.66680,22.20856
84.90000,70.74999,22.55171
85.00001,70.83324,22.34448
85.10001,70.91674,22.39613
85.20001,70.99999,22.65901
85.30000,71.08330,22.57228
85.40000,71.16674,22.38991
85.50001,71.24993,22.51858
85.60001,71.33324,22.52098
85.70001,71.41673,22.54847
85.80000,71.49993,22.54137
85.90000,71.58324,22.35198
86.00001,71.66680,22.51932
86.10001,71.74999,22.62182
86.20001,71.83324,22.40490
86.30000,71.91674,22.71419
86.40000,71.99999,22.68636
86.50001,72.08318,22.60193
86.60001,72.16674,22.75114
86.70001,72.24993,22.78083
86.80000,72.33324,22.73560
86.90000,72.41681,22.69478
87.00001,72.49999,22.54720
87.10001,72.58330,22.73232
87.20001,72.66680,22.87216
87.30000,72.74993,22.82645
87.40000,72.83324,22.70708
87.50001,72.91668,22.84267
87.60001,72.99993,22.73570
87.70001,73.08324,22.85947
87.80000,73.16668,22.71399
87.90000,73.24999,22.70767
88.00001,73.33330,22.82302
88.10001,73.41674,22.88691
88.20001,73.49999,22.90406
88.30000,73.58330,23.00505
88.40000,73.66681,23.03014
88.50001,73.74999,22.96816
88.60001,73.83324,22.98320
88.70001,73.91674,22.90426
88.80000,73.99993,23.03347
88.90000,74.08318,23.09947
89.00001,74.16674,23.00231
89.10001,74.24999,22.95061
89.20001,74.33324,22.97158
89.30000,74.41680,23.01510
89.40000,74.49999,23.16469
89.50001,74.58330,23.23104
89.60001,74.66668,23.23883
89.70001,74.74992,23.18968
89.80000,74.83324,23.26357
89.90000,74.91674,22.99800
90.00001,74.99993,23.04347
90.10001,75.08317,23.16651
90.20001,75.16674,23.23143
90.30000,75.24999,23.13343
90.40000,75.33330,23.24873
90.50001,75.41680,23.16038
90.60001,75.49999,23.11251
90.70001,75.58330,23.35623
90.80000,75.66668,23.26926
90.90000,75.74987,23.32247
91.00001,75.83324,23.38353
91.10001,75.91674,23.39813
91.20001,75.99992,23.61162
91.30000,76.08330,23.49280
91.40000,76.16680,23.34119
91.50001,76.24999,23.48726
91.60001,76.33324,23.44992
91.70001,76.41674,23.55855
91.80000,76.49993,23.49672
91.90000,76.58318,23.44929
92.00001,76.66674,23.37133
92.10001,76.74999,23.46286
92.20001,76.83330,23.46923
92.30000,76.91680,23.52548
92.40000,76.99999,23.62853
92.50001,77.08324,23.54934
92.60001,77.16674,23.49696
92.70001,77.24993,23.72182
92.80000,77.33324,23.57590
92.90000,77.41674,23.55351
93.00001,77.49993,23.70786
93.10001,77.58318,23.84275
93.20001,77.66674,23.70639
93.30000,77.74999,23.86353
93.40000,77.83324,23.84231
93.50001,77.91680,23.75171
93.60001,77.99999,23.72883
93.70001,78.08330,23.79272
93.80000,78.16673,23.53650
93.90000,78.24992,23.71766
94.00001,78.33323,23.85559
94.10001,78.41674,23.96844
94.20001,78.49992,23.90832
94.30000,78.58324,23.80061
94.40000,78.66674,24.01391
94.50001,78.74999,24.05370
94.60001,78.83323,23.63759
94.70001,78.91674,23.78469
94.80000,78.99993,23.98279
94.90000,79.08324,23.92297
95.00001,79.16674,23.86946
95.10001,79.24993,24.00313
95.20001,79.33330,23.98613
95.30000,79.41674,24.09050
95.40000,79.49992,23.91444
95.50001,79.58324,24.06835
95.60001,79.66680,24.02616
95.70001,79.74993,23.97319
95.80000,79.83324,24.23382
95.90000,79.91680,24.07398
96.00001,79.99999,23.91924
96.10001,80.08324,24.07550
96.20001,80.16674,24.18110
96.30000,80.24992,24.11862
96.40000,80.33318,24.33035
96.50001,80.41673,24.51150
96.60001,80.49999,24.11666
96.70001,80.58324,24.27096
96.80000,80.66680,24.25239
96.90000,80.74999,24.16532
97.00001,80.83324,24.26969
97.10001,80.91674,24.42443
97.20001,80.99993,24.14572
97.30000,81.08323,24.45025
97.40000,81.16674,24.37690
97.50001,81.24999,24.31109
97.60001,81.33323,24.29742
97.70001,81.41668,24.58603
97.80000,81.49998,24.49533
97.90000,81.58323,24.30414
98.00001,81.66674,24.50866
98.10001,81.74999,24.41737
98.20001,81.83324,24.46549
98.30000,81.91674,24.63082
98.40000,81.99993,24.63542
98.50001,82.08317,24.55056
98.60001,82.16674,24.36911
98.70001,82.24999,24.75998
98.80000,82.33324,24.52008
98.90000,82.41673,24.83338
99.00001,82.49999,24.83995
99.10001,82.58324,24.66007
99.20001,82.66667,24.40488
99.30000,82.74992,24.57775
99.40000,82.83324,24.94672
99.50001,82.91667,24.67982
99.60001,82.99992,24.53468
99.70001,83.08330,24.75866
99.80000,83.16680,24.98146
99.90000,83.24998,24.79119
100.00001,83.33330,24.77400
100.10001,83.41674,24.76542
100.20001,83.49999,24.83084
100.30000,83.58317,24.75248
100.40000,83.66674,24.92937
100.50001,83.74998,24.81844
100.60001,83.83323,24.74107
100.70001,83.91674,24.91531
100.80000,83.99992,24.94476
100.90000,84.08330,25.00797
101.00001,84.16673,24.75533
101.10001,84.24998,24.99288
101.20001,84.33330,25.10043
101.30000,84.41680,24.98891
101.40000,84.49992,24.78825
101.50001,84.58317,25.10406
101.60001,84.66673,25.06912
101.70001,84.74999,25.07980
101.80000,84.83318,25.10940
101.90000,84.91674,25.10425
102.00001,84.99999,25.02037
102.10001,85.08329,25.11464
102.20001,85.16680,25.14894
102.30000,85.24993,25.15448
102.40000,85.33323,25.16506
102.50001,85.41674,25.13821
102.60001,85.49993,25.14688
102.70001,85.58324,25.32946
102.80000,85.66674,25.25757
102.90000,85.74992,25.15374
103.00001,85.83323,25.37444
103.10001,85.91673,25.22367
103.20001,85.99998,25.10136
103.30000,86.08324,25.40590
103.40000,86.16674,25.27267
103.50001,86.24999,25.30741
103.60001,86.33324,25.44103
103.70001,86.41668,25.19245
103.80000,86.49993,25.42266
103.90000,86.58317,25.33122
104.00001,86.66680,25.44064
104.10001,86.74999,25.57313
104.20001,86.83329,25.51379
104.30000,86.91681,25.54829
104.40000,86.99992,25.37042
104.50001,87.08323,25.43466
104.60001,87.16674,25.61130
104.70001,87.24992,25.67711
104.80000,87.33324,25.46323
104.90000,87.41674,25.56784
105.00001,87.49993,25.53687
105.10001,87.58330,25.56294
105.20001,87.66674,25.55486
105.30000,87.74993,25.59116
105.40000,87.83324,25.75835
105.50001,87.91680,25.76320
105.60001,87.99999,25.78344
105.70001,88.08331,25.83798
105.80000,88.16673,25.71651
105.90000,88.24993,25.86174
106.00001,88.33324,25.74924
106.10001,88.41667,25.76266
106.20001,88.49998,25.75894
106.30000,88.58330,25.89246
106.40000,88.66680,25.70867
106.50001,88.74998,25.79060
106.60001,88.83324,25.90506
106.70001,88.91674,25.69005
106.80000,88.99986,25.84557
106.90000,89.08317,26.04118
107.00001,89.16673,25.74022
107.10001,89.24992,25.93612
107.20001,89.33323,26.10797
107.30000,89.41680,26.06495
107.40000,89.49999,25.98841
107.50001,89.58329,25.86846
107.60001,89.66674,25.99801
107.70001,89.74999,26.00806
107.80000,89.83330,26.15741
107.90000,89.91674,26.00845
108.00001,89.99993,25.93563
108.10001,90.08324,26.09023
108.20001,90.16674,26.18245
108.30000,90.24993,26.09782
108.40000,90.33323,26.04931
108.50001,90.41680,26.24909
108.60001,90.49999,26.19979
108.70001,90.58330,26.20827
108.80000,90.66674,26.22258
108.90000,90.74998,26.17319
109.00001,90.83324,26.44812
109.10001,90.91668,26.45959
109.20001,90.99992,26.33729
109.30000,91.08324,26.36296
109.40000,91.16674,26.26526
109.50001,91.24999,26.42803
109.60001,91.33330,26.29970
109.70001,91.41673,26.26393
109.80000,91.49999,26.47620
109.90000,91.58324,26.55999
110.00001,91.66680,26.40172
110.10001,91.74999,26.49771
110.20001,91.83324,26.44886
110.30000,91.91674,26.41559
110.40000,91.99993,26.48664
110.50001,92.08323,26.38036
110.60001,92.16674,26.65265
110.70001,92.24992,26.48840
110.80000,92.33336,26.60713
110.90000,92.41680,26.56303
111.00001,92.49998,26.72326
111.10001,92.58323,26.67142
111.20001,92.66661,26.74957
111.30000,92.74992,26.58821
111.40000,92.83324,26.70630
111.50001,92.91674,26.78701
111.60001,93.00006,26.54220
111.70001,93.08336,26.64829
111.80000,93.16674,26.80607
111.90000,93.24999,26.72982
112.00001,93.33324,26.79377
112.10001,93.41667,26.68670
112.20001,93.49992,26.71659
112.30000,93.58324,26.82831
112.40000,93.66673,26.70145
112.50001,93.74992,26.78103
112.60001,93.83324,26.74144
112.70001,93.91680,26.85776
112.80000,93.99992,26.95174
112.90001,94.08324,26.81959
113.00001,94.16680,27.01500
113.10001,94.24998,26.88844
113.20001,94.33324,27.09164
113.30000,94.41674,26.91789
113.40001,94.49992,26.95527
113.50001,94.58323,27.11085
113.60001,94.66674,26.95023
113.70001,94.74993,27.07248
113.80000,94.83330,27.06787
113.90001,94.91679,26.97708
114.00001,94.99999,27.04675
114.10001,95.08323,27.15686
114.20001,95.16673,27.06410
114.30000,95.24993,27.12942
114.40001,95.33317,27.17097
114.50001,95.41674,27.10266
114.60001,95.49998,27.15764
114.70001,95.58330,27.49824
114.80000,95.66673,27.27250
114.90001,95.74998,27.28147
115.00001,95.83324,27.26833
115.10001,95.91680,27.14755
115.20001,95.99992,27.20203
115.30000,96.08329,27.04749
115.40001,96.16673,27.28019
115.50001,96.24992,27.24393
115.60001,96.33318,27.39568
115.70001,96.41673,27.20997
115.80000,96.49999,27.51999
115.90001,96.58324,27.52930
116.00001,96.66679,27.41553
116.10001,96.74999,27.47781
116.20001,96.83330,27.30479
116.30000,96.91673,27.47820
116.40001,96.99993,27.50701
116.50001,97.08324,27.69703
116.60001,97.16674,27.47114
116.70001,97.24992,27.35996
116.80000,97.33323,27.61079
116.90001,97.41686,27.57002
117.00001,97.49998,27.49873
117.10001,97.58330,27.54209
117.20001,97.66679,27.72545
117.30000,97.74992,27.52852
117.40001,97.83324,27.55047
117.50001,97.91673,27.67861
117.60001,97.99998,27.57885
117.70001,98.08330,27.66660
117.80000,98.16674,27.84423
117.90001,98.24999,27.67807
118.00001,98.33324,27.83703
118.10001,98.41673,27.84080
118.20001,98.49992,27.93566
118.30000,98.58330,27.81659
118.40001,98.66673,27.77803
118.50001,98.74999,27.90136
118.60001,98.83317,27.74897
118.70001,98.91674,27.86324
118.80000,98.99999,27.83168
118.90001,99.08323,27.85702
119.00001,99.16673,27.75711
119.10001,99.24999,27.97016
119.20001,99.33330,27.93292
119.30000,99.41679,27.86834
119.40001,99.49992,27.92522
119.50001,99.58323,28.01215
119.60001,99.66668,28.03930
119.70001,99.74992,27.91391
119.80000,99.83324,27.98520
119.90001,99.91674,28.21481
120.00001,99.99998,27.93787
120.10001,100.08324,27.92449
120.20001,100.16680,28.05409
120.30000,100.24992,28.26582
120.40001,100.33330,28.09942
120.50001,100.41674,28.15420
120.60001,100.49986,27.99314
120.70001,100.58329,28.13847
120.80000,100.66673,28.13470
120.90001,100.74992,28.29272
121.00001,100.83323,28.21481
121.10001,100.91674,28.57006
121.20001,100.99999,28.23182
121.30000,101.08324,28.23294
121.40001,101.16674,28.20952
121.50001,101.24998,28.45628
121.60001,101.33323,28.26661
121.70001,101.41673,28.38768
121.80000,101.49992,28.19105
121.90001,101.58330,28.28934
122.00001,101.66674,28.33491
122.10001,101.74992,28.41302
122.20001,101.83323,28.31242
122.30000,101.91679,28.22574
122.40001,101.99992,28.36725
122.50001,102.08324,28.50773
122.60001,102.16679,28.35045
122.70001,102.24998,28.49401
122.80000,102.33324,28.47270
122.90001,102.41673,28.33393
123.00001,102.49992,28.54644
123.10001,102.58324,28.55703
123.20001,102.66673,28.59226
123.30000,102.74992,28.56874
123.40001,102.83324,28.44683
123.50001,102.91680,28.59897
123.60001,102.99998,28.58187
123.70001,103.08329,28.66777
123.80000,103.16680,28.69075
123.90001,103.24992,28.56325
124.00001,103.33317,28.51959
124.10001,103.41667,28.82971
124.20001,103.49993,28.75293
124.30000,103.58323,28.49284
124.40001,103.66674,28.69496
124.50001,103.74999,28.94952
124.60001,103.83330,28.88562
124.70001,103.91674,28.85852
124.80000,103.99998,28.56506
124.90001,104.08323,28.85289
125.00001,104.16673,28.63386
125.10001,104.24992,29.02615
125.20001,104.33324,28.97838
125.30000,104.41673,28.89214
125.40001,104.49992,28.89459
125.50001,104.58324,28.90302
125.60001,104.66673,29.08554
125.70001,104.74992,28.99695
125.80000,104.83329,28.83206
125.90001,104.91673,28.99670
126.00001,104.99999,29.07608
126.10001,105.08330,29.22137
126.20001,105.16661,29.08838
126.30000,105.24986,29.13096
126.40001,105.33324,28.84108
126.50001,105.41674,29.01219
126.60001,105.49992,28.92967
126.70001,105.58323,29.06217
126.80000,105.66674,29.12048
126.90001,105.74993,28.97470
127.00001,105.83323,29.12704
127.10001,105.91674,29.21892
127.20001,105.99992,29.23803
127.30000,106.08323,28.93178
127.40001,106.16673,28.94569
127.50001,106.24993,29.17442
127.60001,106.33330,29.20505
127.70001,106.41679,29.08167
127.80000,106.49998,29.30065
127.90001,106.58324,29.11283
128.00000,106.66680,29.19236
128.10001,106.74993,29.32481
128.20002,106.83317,29.00494
128.30000,106.91673,29.32583
128.40001,106.99992,29.26699
128.50000,107.08317,29.40071
128.60001,107.16673,29.18874
128.70002,107.24992,29.37743
128.80000,107.33330,29.52850
128.90001,107.41680,29.21030
129.00000,107.49999,29.26424
129.10001,107.58329,29.15522
129.20002,107.66674,29.37797
129.30000,107.74992,29.45412
129.40001,107.83323,29.45348
129.50000,107.91673,29.40482
129.60001,107.99998,29.34847
129.70002,108.08324,29.49748
129.80000,108.16674,29.43956
129.90001,108.24999,29.47960
130.00000,108.33323,29.53144
130.10001,108.41668,29.58725
130.20002,108.49998,29.38885
130.30000,108.58330,29.58147
130.40001,108.66674,29.66168
130.50000,108.74998,29.47122
130.60001,108.83324,29.55775
130.70002,108.91673,29.64527
130.80000,108.99986,29.59484
130.90001,109.08323,29.69750
131.00000,109.16680,29.59852
131.10000,109.24999,29.63610
131.20002,109.33329,29.66153
131.30000,109.41680,29.66947
131.40002,109.49999,29.54041
131.50000,109.58323,29.70529
131.60000,109.66667,29.61944
131.70002,109.74992,29.83377
131.80000,109.83329,29.67721
131.90002,109.91674,29.63791
132.00000,109.99999,29.67829
132.10000,110.08330,29.81863
132.20002,110.16680,29.74822
132.30000,110.24999,29.73116
132.40002,110.33324,29.64546
132.50000,110.41667,29.71416
132.60000,110.49998,29.59607
132.70002,110.58323,29.75973
132.80000,110.66673,29.69672
132.90002,110.74998,29.85562
133.00000,110.83324,29.64727
133.10000,110.91674,29.86038
133.20002,110.99992,29.67829
133.30000,111.08330,29.74405
133.40002,111.16680,29.52458
133.50000,111.24992,29.72891
133.60000,111.33323,29.33211
133.70002,111.41674,29.36847
133.80000,111.49986,29.26522
133.90002,111.58324,-0.84484
134.00000,111.66673,-0.02150
134.10000,111.74999,-0.35171
134.20002,111.83336,-0.15144
134.30000,111.91680,-0.30991
134.40002,111.99992,-0.19618
134.50000,112.08324,-0.17844
134.60000,112.16674,-0.18486
134.70002,112.24986,-0.34083
134.80000,112.33323,-0.11259
134.90002,112.41673,-0.17212
135.00000,112.49999,-0.17011
135.10000,112.58323,-0.25165
135.20002,112.66680,-0.06824
135.30000,112.74998,-0.20167
135.40002,112.83323,-0.25812
135.50000,112.91673,-0.22097
135.60000,112.99998,-0.27517
135.70002,113.08330,-0.27262
135.80000,113.16667,-0.19050
135.90002,113.24992,-0.10568
135.97200,113.30992,-0.30373