File: V_8/NR/RDSO NR Tensile 50.is_tens_RawData/Specimen_RawData_6.csv
Time,Extension,Load
(sec),(mm),(N)
0.00000,-0.00006,0.10017
0.10000,0.07562,0.36002
0.20000,0.16469,0.58507
0.30000,0.24931,0.64819
0.40000,0.33294,0.96321
0.50000,0.41675,1.21374
0.60000,0.50000,1.34114
0.70000,0.58331,1.40935
0.80000,0.66675,1.60564
0.90000,0.74994,1.68110
1.00000,0.83325,1.83320
1.10000,0.91675,1.94766
1.20000,0.99994,2.20981
1.30000,1.08331,2.32878
1.40000,1.16681,2.31369
1.50000,1.25000,2.54796
1.60000,1.33331,2.63312
1.70000,1.41675,2.62626
1.80000,1.49994,2.79614
1.90000,1.58325,3.01978
2.00000,1.66669,2.97999
2.10000,1.75000,3.54648
2.20000,1.83331,3.35543
2.30000,1.91675,3.38306
2.40000,2.00000,3.70421
2.50000,2.08331,3.75825
2.60000,2.16681,3.76482
2.70000,2.24994,3.87674
2.80000,2.33325,4.05372
2.90000,2.41675,4.11551
3.00000,2.49994,4.38903
3.10000,2.58325,4.53147
3.20000,2.66675,4.42549
3.30000,2.75000,4.68136
3.40000,2.83325,4.60541
3.50000,2.91675,4.68195
3.60000,3.00000,4.72306
3.70000,3.08331,5.05817
3.80000,3.16675,5.02662
3.90000,3.24994,5.13760
4.00000,3.33331,5.21536
4.10000,3.41675,5.22654
4.20000,3.49994,5.28176
4.30000,3.58325,5.56757
4.40000,3.66681,5.78876
4.50000,3.75000,5.62544
4.60000,3.83325,5.91508
4.70000,3.91681,5.94277
4.80000,4.00000,5.97222
4.90000,4.08325,5.89970
5.00000,4.16669,6.04228
5.10000,4.24994,6.14950
5.20000,4.33331,6.30213
5.30000,4.41669,6.40577
5.40000,4.49994,6.52018
5.50000,4.58325,6.62690
5.60000,4.66681,6.58653
5.70000,4.74994,6.92972
5.80000,4.83325,6.73416
5.90000,4.91675,6.89488
6.00000,5.00000,6.84490
6.10000,5.08319,7.10725
6.20000,5.16675,7.11249
6.30000,5.24994,7.10088
6.40000,5.33325,7.31780
6.50000,5.41681,7.30619
6.60000,5.50000,7.35955
6.70000,5.58331,7.37224
6.80000,5.66681,7.51439
6.90000,5.74994,7.59068
7.00000,5.83325,7.70460
7.10000,5.91675,7.86812
7.20000,5.99994,7.70362
7.30000,6.08325,8.00978
7.40000,6.16675,7.86160
7.50000,6.25000,7.87248
7.60000,6.33325,8.05618
7.70000,6.41669,8.23493
7.80000,6.50000,8.20259
7.90000,6.58331,8.32181
8.00000,6.66675,8.51124
8.10000,6.75000,8.30157
8.20000,6.83331,8.29255
8.30000,6.91681,8.56377
8.40000,6.99994,8.62536
8.50000,7.08325,8.68666
8.60000,7.16675,8.70038
8.70000,7.24994,8.86472
8.80000,7.33325,8.68872
8.90000,7.41681,8.81146
9.00000,7.50006,8.84542
9.10000,7.58331,9.09022
9.20000,7.66675,8.97987
9.30000,7.75000,9.30646
9.40000,7.83319,9.22144
9.50000,7.91669,9.21811
9.60000,7.99994,9.20934
9.70000,8.08331,9.33772
9.80000,8.16681,9.33218
9.90000,8.25000,9.44616
10.00000,8.33331,9.52573
10.10000,8.41675,9.61893
10.20000,8.49994,9.49217
10.30000,8.58319,9.61526
10.40000,8.66675,9.70752
10.50000,8.74994,9.89451
10.60000,8.83325,9.44964
10.70000,8.91675,9.81669
10.80000,8.99994,9.69566
10.90000,9.08331,9.84237
11.00000,9.16675,10.00975
11.10000,9.25000,9.96286
11.20000,9.33331,9.95443
11.30000,9.41681,10.14387
11.40000,9.49994,10.21501
11.50000,9.58319,10.27690
11.60000,9.66675,10.05405
11.70000,9.74994,10.23422
11.80000,9.83325,10.26490
11.90000,9.91681,10.11981
12.00000,10.00000,10.43081
12.10000,10.08331,10.49554
12.20000,10.16675,10.29268
12.30000,10.25000,10.53861
12.40000,10.33325,10.43267
12.50000,10.41675,10.41283
12.60000,10.49994,10.54542
12.70000,10.58325,10.66307
12.80000,10.66675,10.66140
12.90000,10.74994,10.82732
13.00000,10.83325,10.68056
13.10000,10.91675,10.65876
13.20000,10.99994,10.92777
13.30000,11.08331,10.92943
13.40000,11.16675,11.04968
13.50000,11.25000,10.95996
13.60000,11.33325,11.13690
13.70000,11.41669,11.10216
13.80000,11.49994,11.20128
13.90000,11.58325,11.26234
14.00000,11.66675,11.31447
14.10000,11.75000,11.25670
14.20000,11.83337,11.14626
14.30000,11.91681,11.39253
14.40000,11.99994,11.46010
14.50000,12.08325,11.31482
14.60000,12.16669,11.26038
14.70000,12.24994,11.39361
14.80000,12.33325,11.37352
14.90000,12.41675,11.33108
15.00000,12.50000,11.45545
15.10000,12.58331,11.46000
15.20000,12.66675,11.53659
15.30000,12.74994,11.51155
15.40000,12.83325,11.51312
15.50000,12.91675,11.51385
15.60000,12.99994,11.70255
15.70000,13.08325,11.74636
15.80000,13.16675,11.47705
15.90000,13.25000,11.89311
16.00000,13.33319,11.63508
16.10000,13.41675,11.54213
16.20000,13.49994,11.78737
16.30000,13.58325,11.78100
16.40000,13.66675,11.94446
16.50000,13.75000,11.75954
16.60000,13.83331,11.88547
16.70000,13.91675,11.75155
16.80000,13.99994,11.92070
16.90000,14.08325,11.90615
17.00000,14.16675,12.00174
17.10000,14.25000,12.00121
17.20000,14.33325,12.06368
17.30000,14.41675,12.02546
17.40000,14.50000,12.21200
17.50000,14.58325,11.92080
17.60000,14.66675,12.00851
17.70000,14.75000,12.23278
17.80000,14.83325,12.23611
17.90000,14.91669,12.30608
18.00000,15.00000,12.18211
18.10000,15.08319,12.20005
18.20000,15.16675,11.96294
18.30000,15.24994,12.10200
18.40000,15.33331,12.25355
18.50000,15.41681,12.23606
18.60000,15.49994,12.42554
18.70000,15.58325,12.27335
18.80000,15.66668,12.47195
18.90000,15.74993,12.33274
19.00000,15.83318,12.69989
19.10000,15.91668,12.42491
19.20000,15.99994,12.40232
19.30000,16.08331,12.60753
19.40000,16.16675,12.47596
19.50000,16.25000,12.42574
19.60000,16.33325,12.61885
19.70000,16.41675,12.60474
19.80000,16.49993,12.54554
19.90000,16.58325,12.54760
20.00000,16.66675,12.83998
20.10000,16.75000,12.46509
20.20000,16.83325,12.44132
20.30000,16.91675,12.78638
20.40000,16.99993,12.91270
20.50000,17.08325,12.89192
20.60000,17.16675,12.67971
20.70000,17.25000,12.71391
20.80000,17.33331,12.84160
20.90000,17.41681,12.70200
21.00000,17.50000,12.80843
21.10000,17.58325,12.81088
21.20000,17.66675,12.91128
21.30000,17.74994,12.75330
21.40000,17.83318,12.89080
21.50000,17.91675,12.87536
21.60000,18.00000,12.78589
21.70000,18.08331,12.97870
21.80000,18.16681,12.85258
21.90000,18.24994,12.93602
22.00000,18.33325,12.93220
22.10000,18.41675,13.03162
22.20000,18.49993,12.84479
22.30000,18.58325,13.23100
22.40000,18.66675,13.16368
22.50000,18.74994,13.13864
22.60000,18.83325,13.16436
22.70000,18.91675,13.13731
22.80000,19.00000,13.08479
22.90000,19.08325,13.06778
23.00000,19.16675,13.04828
23.10000,19.25006,13.04975
23.20000,19.33325,13.20876
23.30000,19.41668,13.07332
23.40000,19.49994,13.28456
23.50000,19.58325,13.15094
23.60000,19.66669,13.30151
23.70000,19.75000,13.19249
23.80000,19.83325,13.14550
23.90000,19.91681,13.21758
24.00000,20.00000,13.26452
24.10000,20.08325,13.43401
24.20000,20.16675,13.23174
24.30000,20.24994,13.25315
24.40000,20.33318,13.39653
24.50000,20.41675,13.15638
24.60000,20.50000,13.34218
24.70000,20.58331,13.29936
24.80000,20.66675,13.39138
24.90000,20.74993,13.39795
25.00000,20.83331,13.52010
25.10000,20.91675,13.50805
25.20000,20.99993,13.44513
25.30000,21.08331,13.38339
25.40000,21.16668,13.48271
25.50000,21.25000,13.45557
25.60000,21.33325,13.62163
25.70000,21.41668,13.57033
25.80000,21.50000,13.59448
25.90000,21.58331,13.53568
26.00000,21.66681,13.49786
26.10000,21.75000,13.56293
26.20000,21.83331,13.74531
26.30000,21.91675,13.59002
26.40000,21.99993,13.68714
26.50000,22.08318,13.66740
26.60000,22.16675,13.69567
26.70000,22.24993,13.73575
26.80000,22.33318,13.67627
26.90000,22.41687,13.69234
27.00000,22.49993,13.64373
27.10000,22.58325,13.76887
27.20000,22.66675,13.85835
27.30000,22.75000,13.64157
27.40000,22.83331,13.69949
27.50000,22.91675,13.66029
27.60000,22.99994,13.93915
27.70000,23.08325,13.84492
27.80000,23.16675,13.82459
27.90000,23.24993,13.89250
28.00000,23.33325,13.68126
28.10000,23.41675,13.96821
28.20000,23.50000,13.91166
28.30000,23.58325,14.01182
28.40000,23.66681,13.80700
28.50000,23.75000,13.86482
28.60000,23.83325,14.15186
28.70000,23.91668,13.98482
28.80000,24.00000,13.87770
28.90000,24.08325,14.01902
29.00000,24.16662,14.01946
29.10000,24.24994,14.05028
29.20000,24.33331,14.15450
29.30000,24.41681,14.03818
29.40000,24.50000,14.06469
29.50000,24.58331,14.13701
29.60000,24.66675,14.14671
29.70000,24.74993,14.13201
29.80000,24.83318,13.77240
29.90000,24.91675,14.14470
30.00000,24.99999,14.15343
30.10000,25.08325,14.36545
30.20000,25.16681,14.05827
30.30000,25.25000,14.04685
30.40000,25.33331,13.98942
30.50000,25.41675,14.15715
30.60000,25.49987,14.15254
30.70000,25.58331,14.31552
30.80000,25.66675,14.20228
30.90000,25.74993,14.33575
31.00000,25.83325,14.27744
31.10000,25.91675,14.22707
31.20000,26.00000,14.38289
31.30000,26.08331,14.21237
31.40000,26.16681,14.42817
31.50000,26.25006,14.24971
31.60000,26.33331,14.54719
31.70000,26.41675,14.35648
31.80000,26.49993,14.48952
31.90000,26.58325,14.34212
32.00000,26.66675,14.31841
32.10000,26.75000,14.51259
32.20000,26.83325,14.45311
32.30000,26.91681,14.36736
32.40000,26.99994,14.34158
32.50000,27.08325,14.42998
32.60000,27.16674,14.52259
32.70000,27.25000,14.59584
32.80000,27.33325,14.58962
32.90000,27.41675,14.47937
33.00000,27.50000,14.65386
33.10000,27.58331,14.43125
33.20000,27.66675,14.60677
33.30000,27.74999,14.53420
33.40000,27.83325,14.54778
33.50000,27.91681,14.68855
33.60000,28.00000,14.70923
33.70000,28.08325,14.81086
33.80000,28.16675,14.47815
33.90000,28.24993,14.59217
34.00000,28.33318,14.71384
34.10000,28.41675,14.86559
34.20000,28.49993,14.72045
34.30000,28.58325,14.78954
34.40000,28.66675,14.57188
34.50000,28.75006,14.69551
34.60000,28.83331,14.66577
34.70000,28.91675,14.86657
34.80000,29.00000,14.85706
34.90000,29.08325,14.63299
35.00000,29.16675,14.76284
35.10000,29.24993,14.69502
35.20000,29.33325,14.80429
35.30000,29.41675,14.81429
35.40000,29.49993,14.71972
35.50000,29.58325,14.89151
35.60000,29.66675,14.90440
35.70000,29.75000,14.92282
35.80000,29.83325,14.99127
35.90000,29.91674,14.94012
36.00000,30.00000,15.11872
36.10000,30.08325,15.03640
36.20000,30.16675,14.88284
36.30000,30.24993,14.92429
36.40000,30.33325,14.95276
36.50000,30.41681,14.91753
36.60000,30.49993,14.97569
36.70000,30.58331,15.05992
36.80000,30.66681,15.03121
36.90000,30.75000,14.97873
37.00000,30.83325,15.16365
37.10000,30.91675,15.31296
37.20000,30.99993,15.11897
37.30000,31.08324,15.07002
37.40000,31.16668,15.06340
37.50000,31.24993,15.14680
37.60000,31.33331,15.35010
37.70000,31.41674,15.14454
37.80000,31.49999,15.20305
37.90000,31.58331,15.24803
38.00000,31.66674,15.20442
38.10000,31.74993,15.13519
38.20000,31.83324,15.27043
38.30000,31.91675,15.23020
38.40000,31.99999,15.29003
38.50000,32.08318,15.21466
38.60000,32.16675,15.35250
38.70000,32.24999,15.09182
38.80000,32.33331,15.38371
38.90000,32.41681,15.37891
39.00000,32.50006,15.53507
39.10000,32.58331,15.47529
39.20000,32.66662,15.42693
39.30000,32.74993,15.41282
39.40000,32.83324,15.44124
39.50000,32.91681,15.42835
39.60000,33.00000,15.51332
39.70000,33.08331,15.37636
39.80000,33.16681,15.53022
39.90000,33.24999,15.50984
40.00000,33.33325,15.59706
40.10000,33.41675,15.68090
40.20000,33.49999,15.70741
40.30000,33.58331,15.67815
40.40000,33.66675,15.41743
40.50000,33.74999,15.46564
40.60000,33.83324,15.62685
40.70000,33.91674,15.37421
40.80000,33.99993,15.60284
40.90000,34.08324,15.60617
41.00000,34.16675,15.72941
41.10000,34.25000,15.47510
41.20000,34.33331,15.66948
41.30000,34.41674,15.73935
41.40000,34.49999,15.77997
41.50000,34.58325,15.60338
41.60000,34.66668,15.78478
41.70000,34.74993,15.64861
41.80000,34.83325,15.62205
41.90000,34.91674,15.72485
42.00000,34.99999,15.74195
42.10000,35.08331,15.85749
42.20000,35.16675,15.67762
42.30000,35.24993,15.75832
42.40000,35.33318,15.79561
42.50000,35.41674,15.99631
42.60000,35.49999,15.72039
42.70000,35.58324,15.92933
42.80000,35.66675,15.96872
42.90000,35.74993,15.97691
43.00000,35.83324,16.12606
43.10000,35.91675,16.01096
43.20000,35.99999,15.88528
43.30000,36.08331,15.99043
43.40000,36.16675,15.85823
43.50000,36.25000,16.01870
43.60000,36.33325,16.12376
43.70000,36.41674,16.04771
43.80000,36.49993,15.90071
43.90000,36.58318,16.09348
44.00000,36.66674,16.18819
44.10000,36.74999,16.32172
44.20000,36.83325,16.13268
44.30000,36.91674,15.93325
44.40000,36.99999,15.92256
44.50000,37.08331,16.27154
44.60000,37.16668,15.98259
44.70000,37.24999,16.09896
44.80000,37.33324,16.22651
44.90000,37.41675,16.09548
45.00000,37.49999,16.14752
45.10000,37.58324,16.29722
45.20000,37.66681,16.02649
45.30000,37.74999,16.21926
45.40000,37.83325,16.16658
45.50000,37.91675,16.11744
45.60000,38.00000,16.30462
45.70000,38.08331,16.29634
45.80000,38.16668,16.50831
45.90000,38.24993,16.46362
46.00000,38.33324,16.39282
46.10000,38.41668,16.40482
46.20000,38.49993,16.45456
46.30000,38.58331,16.42908
46.40000,38.66687,16.16487
46.50000,38.74999,16.33122
46.60000,38.83331,16.37557
46.70000,38.91675,16.17834
46.80000,38.99993,16.58980
46.90000,39.08318,16.53408
47.00000,39.16668,16.55295
47.10000,39.24999,16.38718
47.20000,39.33331,16.64811
47.30000,39.41681,16.48616
47.40000,39.49999,16.47920
47.50000,39.58330,16.50057
47.60000,39.66675,16.60523
47.70000,39.74993,16.65310
47.80000,39.83324,16.63081
47.90000,39.91674,16.71695
48.00000,39.99993,16.74189
48.10000,40.08318,16.62792
48.20000,40.16674,16.58818
48.30000,40.24993,16.78864
48.40000,40.33324,16.66119
48.50000,40.41681,16.82073
48.60000,40.49993,16.71048
48.70000,40.58330,16.60641
48.80000,40.66675,16.87625
48.90000,40.74993,16.69588
49.00000,40.83325,16.68564
49.10000,40.91668,16.84278
49.20000,40.99993,16.81157
49.30000,41.08324,16.88438
49.40000,41.16674,16.94784
49.50000,41.25000,16.90114
49.60000,41.33324,16.93681
49.70000,41.41680,16.78285
49.80000,41.50006,16.76164
49.90000,41.58324,16.98434
50.00000,41.66668,16.74429
50.10000,41.74993,16.96827
50.20000,41.83325,16.91569
50.30000,41.91674,16.99728
50.40000,41.99993,17.05863
50.50000,42.08324,16.94338
50.60000,42.16681,16.98273
50.70000,42.24999,17.17770
50.80000,42.33324,17.11870
50.90000,42.41674,17.11728
51.00000,42.49999,17.09895
51.10000,42.58324,16.85856
51.20000,42.66674,17.04378
51.30000,42.74993,17.11307
51.40000,42.83324,17.19083
51.50000,42.91675,17.11831
51.60000,42.99999,17.13712
51.70000,43.08337,17.32146
51.80000,43.16681,17.10498
51.90000,43.24993,17.17970
52.00000,43.33324,17.29833
52.10000,43.41675,17.13590
52.20000,43.49993,17.35743
52.30000,43.58324,17.15991
52.40000,43.66674,17.19137
52.50000,43.75000,17.27339
52.60000,43.83331,17.25041
52.70000,43.91668,17.31210
52.80000,44.00000,17.40202
52.90000,44.08325,17.33518
53.00000,44.16674,17.49909
53.10000,44.24999,17.30980
53.20000,44.33331,17.40878
53.30000,44.41674,17.39942
53.40000,44.49993,17.59758
53.50000,44.58318,17.52099
53.60000,44.66674,17.57391
53.70000,44.74999,17.40491
53.80000,44.83324,17.57033
53.90000,44.91674,17.30921
54.00000,44.99999,17.49394
54.10000,45.08324,17.54456
54.20000,45.16675,17.47282
54.30000,45.24993,17.55901
54.40000,45.33318,17.75634
54.50000,45.41674,17.68935
54.60000,45.49993,17.58880
54.70000,45.58331,17.60958
54.80000,45.66674,17.70895
54.90000,45.75000,17.57308
55.00000,45.83324,17.75139
55.10000,45.91674,17.50815
55.20000,45.99999,17.72414
55.30000,46.08324,17.64452
55.40000,46.16668,17.61286
55.50000,46.24999,17.64045
55.60000,46.33325,17.78774
55.70000,46.41668,17.78652
55.80000,46.49993,17.73414
55.90000,46.58324,17.85468
56.00000,46.66674,17.79647
56.10000,46.75000,17.79196
56.20000,46.83331,17.81234
56.30000,46.91674,18.09737
56.40000,46.99999,17.88138
56.50000,47.08324,17.77020
56.60000,47.16674,17.87629
56.70000,47.24999,18.04705
56.80000,47.33324,17.93866
56.90000,47.41680,17.98634
57.00000,47.49999,17.98815
57.10000,47.58324,17.88981
57.20000,47.66674,18.01035
57.30000,47.74999,17.87805
57.40000,47.83330,18.04931
57.50000,47.91674,18.03318
57.60000,47.99993,18.08875
57.70000,48.08324,17.88550
57.80000,48.16674,17.95973
57.90000,48.24999,18.06866
58.00000,48.33324,18.14897
58.10000,48.41681,18.19239
58.20000,48.49999,18.17127
58.30000,48.58330,18.06116
58.40000,48.66675,18.36080
58.50000,48.74999,18.22909
58.60000,48.83324,18.13648
58.70000,48.91674,18.11153
58.80000,48.99993,18.30915
58.90000,49.08324,18.24315
59.00000,49.16674,18.33277
59.10000,49.25000,18.25873
59.20000,49.33331,18.45233
59.30000,49.41680,18.45468
59.40000,49.50000,18.04053
59.50000,49.58318,18.45855
59.60000,49.66668,18.52049
59.70000,49.74993,18.03279
59.80000,49.83330,18.34321
59.90000,49.91674,18.53612
60.00000,49.99999,18.56983
60.10000,50.08325,18.48339
60.20000,50.16681,18.36104
60.30000,50.24987,18.45880
60.40000,50.33324,18.59168
60.50000,50.41681,18.62574
60.60000,50.49999,18.46933
60.70000,50.58324,18.58732
60.80000,50.66674,18.71311
60.90000,50.74993,18.43493
61.00000,50.83318,18.45840
61.10000,50.91668,18.70762
61.20000,50.99993,18.52622
61.30000,51.08330,18.53112
61.40000,51.16674,18.54156
61.50000,51.24999,18.67239
61.60000,51.33331,18.55376
61.70000,51.41674,18.64362
61.80000,51.49993,18.55312
61.90000,51.58324,18.81468
62.00000,51.66674,18.77568
62.10000,51.74999,18.73496
62.20000,51.83324,18.81454
62.30000,51.91681,18.85457
62.40000,51.99999,18.84849
62.50000,52.08324,18.87094
62.60000,52.16674,18.74922
62.70000,52.24999,18.83492
62.80000,52.33331,18.86991
62.90000,52.41668,18.87686
63.00000,52.49993,18.75044
63.10000,52.58324,19.04572
63.20000,52.66674,18.96693
63.30000,52.74993,18.83105
63.40000,52.83324,18.94801
63.50000,52.91680,18.98236
63.60000,53.00005,19.08732
63.70000,53.08331,18.89548
63.80000,53.16674,18.72986
63.90000,53.24999,18.98888
64.00000,53.33324,19.13681
64.10001,53.41668,19.08051
64.20000,53.49993,18.87422
64.30000,53.58324,19.13196
64.40000,53.66674,19.06414
64.50000,53.74999,19.21452
64.60001,53.83324,19.13813
64.70000,53.91681,19.00760
64.80000,53.99993,19.10388
64.90000,54.08324,19.04910
65.00000,54.16675,19.10819
65.10001,54.24999,19.29116
65.20000,54.33324,19.05135
65.30000,54.41674,19.15572
65.40000,54.49999,19.26803
65.50000,54.58324,19.13000
65.60001,54.66674,19.26842
65.70001,54.75000,19.22300
65.80000,54.83324,19.41964
65.90000,54.91674,19.21271
66.00000,55.00000,19.40900
66.10001,55.08318,19.15283
66.20001,55.16668,19.41836
66.30000,55.24993,19.32884
66.40000,55.33318,19.42233
66.50000,55.41674,19.45119
66.60001,55.49999,19.31448
66.70001,55.58331,19.59829
66.80000,55.66674,19.46511
66.90000,55.74993,19.39229
67.00000,55.83331,19.58565
67.10001,55.91668,19.49196
67.20001,55.99993,19.47324
67.30000,56.08324,19.47104
67.40000,56.16674,19.69727
67.50000,56.24993,19.38372
67.60001,56.33330,19.54610
67.70001,56.41674,19.41792
67.80000,56.49999,19.66419
67.90000,56.58324,19.53425
68.00000,56.66674,19.64528
68.10001,56.74999,19.83349
68.20001,56.83331,19.73926
68.30000,56.91674,19.64601
68.40000,56.99993,19.55831
68.50000,57.08324,19.75097
68.60001,57.16668,19.76170
68.70001,57.24993,19.79096
68.80000,57.33324,19.88312
68.90000,57.41681,19.62735
69.00000,57.49993,19.77665
69.10001,57.58324,19.68438
69.20001,57.66674,19.68306
69.30000,57.74999,19.84221
69.40000,57.83318,19.98132
69.50000,57.91674,19.86588
69.60001,57.99993,19.93864
69.70001,58.08318,19.91360
69.80000,58.16674,20.00822
69.90000,58.24999,20.04781
70.00000,58.33331,20.08618
70.10001,58.41680,20.01444
70.20001,58.49999,19.92247
70.30000,58.58324,19.91297
70.40000,58.66674,19.87425
70.50000,58.74987,20.15203
70.60001,58.83324,19.80301
70.70001,58.91674,19.98318
70.80000,58.99999,19.96486
70.90000,59.08324,20.11146
71.00000,59.16681,19.90944
71.10001,59.24999,20.07148
71.20001,59.33330,20.14772
71.30000,59.41668,20.18629
71.40000,59.49993,20.15355
71.50000,59.58318,20.20770
71.60001,59.66668,20.28835
71.70001,59.74993,20.29423
71.80000,59.83324,20.22260
71.90000,59.91681,20.25082
72.00000,59.99999,20.30864
72.10001,60.08324,20.28659
72.20001,60.16674,20.41776
72.30000,60.25000,20.21015
72.40000,60.33324,20.27238
72.50000,60.41668,20.37459
72.60001,60.50000,20.30692
72.70001,60.58324,20.32790
72.80000,60.66668,20.49548
72.90000,60.74993,20.47833
73.00000,60.83325,20.39718
73.10001,60.91674,20.51503
73.20001,60.99993,20.27463
73.30000,61.08331,20.47852
73.40000,61.16674,20.62763
73.50000,61.24999,20.41722
73.60001,61.33324,20.64997
73.70001,61.41668,20.55775
73.80000,61.49993,20.52781
73.90000,61.58324,20.62096
74.00000,61.66674,20.46510
74.10001,61.74999,20.51405
74.20001,61.83330,20.55521
74.30000,61.91680,20.69246
74.40000,61.99993,20.81589
74.50000,62.08324,20.67878
74.60001,62.16674,20.60367
74.70001,62.24987,20.94696
74.80000,62.33318,20.78252
74.90000,62.41681,20.73288
75.00000,62.49999,20.60058
75.10001,62.58324,20.70946
75.20001,62.66681,20.80359
75.30000,62.74993,20.74498
75.40000,62.83324,20.87434
75.50000,62.91680,20.86204
75.60001,62.99999,20.75660
75.70001,63.08324,20.78551
75.80000,63.16674,20.89477
75.90000,63.24993,20.65531
76.00000,63.33324,20.94637
76.10001,63.41674,20.86881
76.20001,63.49999,20.79442
76.30000,63.58324,21.07980
76.40000,63.66680,21.04937
76.50000,63.74999,20.94500
76.60001,63.83324,21.11341
76.70001,63.91668,20.91095
76.80000,63.99999,21.03148
76.90000,64.08324,21.12625
77.00000,64.16674,21.05883
77.10001,64.24999,20.93505
77.20001,64.33330,21.24248
77.30000,64.41674,21.10386
77.40000,64.49999,21.23033
77.50000,64.58324,21.07926
77.60001,64.66674,21.01580
77.70001,64.74993,21.11302
77.80000,64.83330,21.12253
77.90000,64.91674,21.33533
78.00000,64.99999,21.08377
78.10001,65.08324,21.20117
78.20001,65.16674,21.27766
78.30000,65.24999,21.06681
78.40000,65.33330,21.10680
78.50000,65.41680,21.45778
78.60001,65.49993,21.30716
78.70001,65.58324,21.37037
78.80000,65.66674,21.16633
78.90000,65.74999,21.27301
79.00000,65.83318,21.49860
79.10001,65.91668,21.38384
79.20001,65.99993,21.25590
79.30000,66.08331,21.43162
79.40000,66.16674,21.21083
79.50000,66.25005,21.49708
79.60001,66.33336,21.48248
79.70001,66.41674,21.51947
79.80000,66.49993,21.39158
79.90000,66.58318,21.47464
80.00000,66.66674,21.52290
80.10001,66.74992,21.62624
80.20001,66.83331,21.55965
80.30000,66.91680,21.62865
80.40000,66.99993,21.58077
80.50001,67.08324,21.51051
80.60001,67.16680,21.55030
80.70001,67.24992,21.52825
80.80000,67.33330,21.73743
80.90000,67.41680,21.58259
81.00001,67.49999,21.59831
81.10001,67.58330,21.74527
81.20001,67.66674,21.68686
81.30000,67.74993,21.66319
81.40000,67.83324,21.82425
81.50001,67.91674,21.76678
81.60001,67.99993,21.56681
81.70001,68.08330,21.66319
81.80000,68.16680,21.86874
81.90000,68.24999,21.71175
82.00001,68.33324,21.85821
82.10001,68.41674,21.84131
82.20001,68.49999,21.68490
82.30000,68.58324,21.84243
82.40000,68.66674,21.70009
82.50001,68.74999,21.70401
82.60001,68.83324,21.82146
82.70001,68.91680,21.60890
82.80000,68.99999,21.74551
82.90000,69.08331,22.05107
83.00001,69.16674,21.98875
83.10001,69.24999,22.16073
83.20001,69.33324,22.06484
83.30000,69.41674,22.18690
83.40000,69.49992,22.06181
83.50001,69.58318,21.94205
83.60001,69.66668,22.00580
83.70001,69.74999,22.03686
83.80000,69.83330,22.05524
83.90000,69.91680,22.16093
84.00001,69.99999,22.10826
84.10001,70.08330,22.05323
84.20001,70.16681,22.22027
84.30000,70.24992,22.20773
84.40000,70.33318,22.19376
84.50001,70.41674,22.10096
84.60001,70.49999,22.03971
84.70001,70.58324,22.38496
84.80000,70.66674,22.36301
84.90000,70.74999,22.38560
85.00001,70.83330,22.27535
85.10001,70.91674,22.22017
85.20001,70.99999,22.27765
85.30000,71.08330,22.38212
85.40000,71.16674,22.35997
85.50001,71.24993,22.43352
85.60001,71.33324,22.46694
85.70001,71.41673,22.53313
85.80000,71.49993,22.32900
85.90000,71.58324,22.48590
86.00001,71.66680,22.51799
86.10001,71.74999,22.35894
86.20001,71.83324,22.46596
86.30000,71.91674,22.40235
86.40000,71.99999,22.35046
86.50001,72.08318,22.46449
86.60001,72.16674,22.64647
86.70001,72.24993,22.53475
86.80000,72.33324,22.72811
86.90000,72.41681,22.71806
87.00001,72.49999,22.47164
87.10001,72.58330,22.51554
87.20001,72.66680,22.75407
87.30000,72.74993,22.83076
87.40000,72.83324,22.73835
87.50001,72.91668,22.69851
87.60001,72.99993,22.63270
87.70001,73.08324,22.69214
87.80000,73.16674,22.57199
87.90000,73.24999,22.77617
88.00001,73.33330,22.84389
88.10001,73.41674,22.61737
88.20001,73.49999,22.91029
88.30000,73.58330,22.83419
88.40000,73.66681,22.58924
88.50001,73.74999,22.76427
88.60001,73.83330,22.70218
88.70001,73.91667,22.75393
88.80000,73.99993,22.87368
88.90000,74.08318,22.70566
89.00001,74.16674,22.83644
89.10001,74.24999,23.02480
89.20001,74.33324,22.91038
89.30000,74.41680,22.96247
89.40000,74.49999,23.01662
89.50001,74.58330,22.79612
89.60001,74.66674,22.91024
89.70001,74.74999,22.95395
89.80000,74.83324,22.99207
89.90000,74.91674,23.09756
90.00001,74.99993,22.94258
90.10001,75.08317,22.94757
90.20001,75.16680,23.09820
90.30000,75.24999,23.04004
90.40000,75.33330,22.89784
90.50001,75.41680,23.00397
90.60001,75.49999,23.06302
90.70001,75.58330,22.90798
90.80000,75.66668,23.23261
90.90000,75.74987,23.11898
91.00001,75.83324,23.14073
91.10001,75.91668,23.50671
91.20001,75.99992,23.20997
91.30000,76.08330,23.26397
91.40000,76.16686,23.13030
91.50001,76.24999,23.34031
91.60001,76.33324,23.22452
91.70001,76.41668,23.38519
91.80000,76.49993,23.28504
91.90000,76.58318,23.29518
92.00001,76.66674,23.22800
92.10001,76.74999,23.16317
92.20001,76.83330,23.42400
92.30000,76.91680,23.68345
92.40000,76.99999,23.61726
92.50001,77.08324,23.41087
92.60001,77.16674,23.60447
92.70001,77.24993,23.28822
92.80000,77.33324,23.53386
92.90000,77.41674,23.63210
93.00001,77.49993,23.44860
93.10001,77.58318,23.46394
93.20001,77.66674,23.53699
93.30000,77.74999,23.32228
93.40000,77.83324,23.65964
93.50001,77.91680,23.59643
93.60001,77.99999,23.70546
93.70001,78.08330,23.76945
93.80000,78.16673,23.75720
93.90000,78.24999,23.54013
94.00001,78.33323,23.58207
94.10001,78.41674,23.78454
94.20001,78.49992,23.68277
94.30000,78.58324,23.65788
94.40000,78.66674,23.83927
94.50001,78.74999,23.72530
94.60001,78.83323,23.66474
94.70001,78.91674,23.70075
94.80000,78.99993,23.89822
94.90000,79.08324,23.88014
95.00001,79.16674,23.97941
95.10001,79.24993,23.88661
95.20001,79.33323,23.93943
95.30000,79.41674,23.93551
95.40000,79.49992,23.91380
95.50001,79.58324,23.76234
95.60001,79.66680,24.06105
95.70001,79.74993,24.14998
95.80000,79.83324,23.82095
95.90000,79.91680,23.93335
96.00001,79.99999,23.95384
96.10001,80.08317,24.03336
96.20001,80.16674,24.12926
96.30000,80.24992,24.08540
96.40000,80.33318,23.96682
96.50001,80.41673,23.87730
96.60001,80.49999,24.09559
96.70001,80.58324,23.93531
96.80000,80.66680,23.93502
96.90000,80.74999,24.13455
97.00001,80.83324,24.16013
97.10001,80.91674,24.25920
97.20001,80.99993,24.11421
97.30000,81.08323,24.15336
97.40000,81.16674,24.08427
97.50001,81.24999,24.05311
97.60001,81.33323,24.23260
97.70001,81.41668,24.15508
97.80000,81.49993,24.30820
97.90000,81.58323,24.45094
98.00001,81.66674,24.25700
98.10001,81.75005,24.29556
98.20001,81.83324,24.58804
98.30000,81.91674,24.47421
98.40000,81.99993,24.46235
98.50001,82.08317,24.52557
98.60001,82.16674,24.19996
98.70001,82.24999,24.56775
98.80000,82.33324,24.30708
98.90000,82.41680,24.27126
99.00001,82.49999,24.47216
99.10001,82.58324,24.44344
99.20001,82.66667,24.68506
99.30000,82.74992,24.58510
99.40000,82.83324,24.63346
99.50001,82.91667,24.56472
99.60001,82.99992,24.44917
99.70001,83.08330,24.37822
99.80000,83.16685,24.78389
99.90000,83.24998,24.67923
100.00001,83.33330,24.62312
100.10001,83.41674,24.71583
100.20001,83.49999,24.64130
100.30000,83.58317,24.60661
100.40000,83.66674,24.79007
100.50001,83.74998,24.76473
100.60001,83.83323,24.63631
100.70001,83.91674,24.72450
100.80000,83.99992,24.83529
100.90000,84.08330,24.85352
101.00001,84.16673,24.84176
101.10001,84.24998,24.83059
101.20001,84.33330,25.00679
101.30000,84.41680,24.78213
101.40000,84.49992,24.85445
101.50001,84.58324,25.02125
101.60001,84.66673,24.79796
101.70001,84.74993,24.85014
101.80000,84.83324,24.88714
101.90000,84.91674,25.06927
102.00001,84.99992,25.00954
102.10001,85.08329,25.17182
102.20001,85.16674,24.85769
102.30000,85.24999,25.10994
102.40000,85.33323,25.06780
102.50001,85.41674,25.09328
102.60001,85.49993,24.99033
102.70001,85.58324,24.94697
102.80000,85.66674,24.85132
102.90000,85.74992,25.00924
103.00001,85.83323,25.27144
103.10001,85.91673,24.99484
103.20001,85.99998,25.12312
103.30000,86.08324,25.11376
103.40000,86.16674,25.11160
103.50001,86.24999,25.22636
103.60001,86.33324,25.12822
103.70001,86.41673,25.16472
103.80000,86.49993,25.12444
103.90000,86.58317,25.11974
104.00001,86.66680,25.30858
104.10001,86.74999,25.30300
104.20001,86.83329,25.27997
104.30000,86.91681,25.09455
104.40000,86.99999,25.32206
104.50001,87.08323,25.29668
104.60001,87.16674,25.23533
104.70001,87.24992,25.31098
104.80000,87.33324,25.27164
104.90000,87.41674,25.35420
105.00001,87.49993,25.49420
105.10001,87.58330,25.43123
105.20001,87.66674,25.51409
105.30000,87.74993,25.63634
105.40000,87.83324,25.58205
105.50001,87.91680,25.52835
105.60001,87.99993,25.41310
105.70001,88.08323,25.57063
105.80000,88.16680,25.63365
105.90000,88.24993,25.66084
106.00001,88.33324,25.79339
106.10001,88.41667,25.67050
106.20001,88.49998,25.75468
106.30000,88.58330,25.50140
106.40000,88.66680,25.70538
106.50001,88.74998,25.54466
106.60001,88.83324,25.78035
106.70001,88.91674,25.70837
106.80000,88.99992,25.58597
106.90000,89.08317,25.66079
107.00001,89.16680,25.65781
107.10001,89.24992,25.76776
107.20001,89.33323,25.87174
107.30000,89.41680,25.98380
107.40000,89.49999,25.81069
107.50001,89.58329,25.84332
107.60001,89.66674,25.85640
107.70001,89.74993,25.74963
107.80000,89.83323,25.80177
107.90000,89.91674,25.80573
108.00001,89.99993,25.76653
108.10001,90.08324,26.01869
108.20001,90.16674,26.10522
108.30000,90.24998,25.98326
108.40000,90.33323,25.95038
108.50001,90.41680,25.83665
108.60001,90.49999,26.12032
108.70001,90.58330,25.93887
108.80000,90.66674,26.18117
108.90000,90.74998,25.95430
109.00001,90.83324,26.34655
109.10001,90.91668,26.02192
109.20001,90.99992,26.18455
109.30000,91.08324,26.30019
109.40000,91.16680,26.04030
109.50001,91.24999,26.08974
109.60001,91.33330,26.08347
109.70001,91.41673,26.23934
109.80000,91.49999,26.07920
109.90000,91.58324,26.14281
110.00001,91.66680,26.12090
110.10001,91.74992,26.11002
110.20001,91.83324,26.41137
110.30000,91.91674,26.23409
110.40000,91.99993,26.31053
110.50001,92.08323,26.20057
110.60001,92.16674,26.24536
110.70001,92.24999,26.23782
110.80000,92.33336,26.40089
110.90000,92.41686,26.30896
111.00001,92.49998,26.26971
111.10001,92.58323,26.43685
111.20001,92.66668,26.50482
111.30000,92.74992,26.27241
111.40000,92.83324,26.39275
111.50001,92.91674,26.53882
111.60001,93.00006,26.39030
111.70001,93.08336,26.53167
111.80000,93.16674,26.56675
111.90000,93.24999,26.49428
112.00001,93.33324,26.62183
112.10001,93.41667,26.60889
112.20001,93.49992,26.52486
112.30000,93.58324,26.68616
112.40000,93.66673,26.22596
112.50001,93.74992,26.66661
112.60001,93.83324,26.62001
112.70001,93.91680,26.87447
112.80000,93.99992,26.63775
112.90001,94.08324,26.80146
113.00001,94.16680,26.67009
113.10001,94.24998,26.67078
113.20001,94.33329,26.91284
113.30000,94.41674,26.81381
113.40001,94.49992,26.69680
113.50001,94.58323,26.76265
113.60001,94.66674,26.68935
113.70001,94.74993,26.61281
113.80000,94.83330,26.92523
113.90001,94.91679,27.05783
114.00001,94.99999,26.86614
114.10001,95.08323,26.85796
114.20001,95.16673,26.66039
114.30000,95.24993,26.97198
114.40001,95.33317,26.91534
114.50001,95.41674,26.80705
114.60001,95.49998,26.92690
114.70001,95.58330,26.88486
114.80000,95.66673,26.94920
114.90001,95.74998,27.10384
115.00001,95.83324,26.99266
115.10001,95.91680,27.19356
115.20001,95.99992,27.06528
115.30000,96.08324,27.05445
115.40001,96.16673,27.12329
115.50001,96.24992,27.13358
115.60001,96.33323,27.01638
115.70001,96.41673,27.09370
115.80000,96.49999,27.20086
115.90001,96.58324,27.29685
116.00001,96.66674,27.06817
116.10001,96.74999,27.22413
116.20001,96.83330,27.13001
116.30000,96.91673,27.16396
116.40001,96.99993,27.25201
116.50001,97.08324,27.10207
116.60001,97.16674,27.30165
116.70001,97.24992,27.30503
116.80000,97.33323,27.31988
116.90001,97.41686,27.42263
117.00001,97.49998,27.31155
117.10001,97.58330,27.30307
117.20001,97.66679,27.31121
117.30000,97.74992,27.39573
117.40001,97.83324,27.27740
117.50001,97.91673,27.66562
117.60001,97.99998,27.49873
117.70001,98.08323,27.53989
117.80000,98.16674,27.39945
117.90001,98.24999,27.53308
118.00001,98.33324,27.37941
118.10001,98.41673,27.62544
118.20001,98.49992,27.56121
118.30000,98.58330,27.52504
118.40001,98.66673,27.35060
118.50001,98.74999,27.54616
118.60001,98.83324,27.50833
118.70001,98.91674,27.60580
118.80000,98.99999,27.69713
118.90001,99.08323,27.51402
119.00001,99.16673,27.55003
119.10001,99.24999,27.65176
119.20001,99.33330,27.55542
119.30000,99.41679,27.59492
119.40001,99.49992,27.73883
119.50001,99.58323,27.52651
119.60001,99.66673,27.74294
119.70001,99.74992,27.76402
119.80000,99.83324,27.73501
119.90001,99.91674,27.88181
120.00001,99.99998,27.84575
120.10001,100.08324,27.79439
120.20001,100.16680,27.90460
120.30000,100.24998,27.86922
120.40001,100.33330,27.97780
120.50001,100.41674,28.00010
120.60001,100.49986,27.91248
120.70001,100.58329,27.98089
120.80000,100.66673,27.71173
120.90001,100.74992,28.05497
121.00001,100.83323,27.86157
121.10001,100.91674,27.77377
121.20001,100.99999,27.96805
121.30000,101.08324,28.00764
121.40001,101.16674,28.20776
121.50001,101.24998,28.08658
121.60001,101.33323,28.10804
121.70001,101.41673,28.20398
121.80000,101.49999,28.15298
121.90001,101.58330,28.07134
122.00001,101.66674,28.07580
122.10001,101.74992,28.20496
122.20001,101.83323,28.25406
122.30000,101.91679,28.28944
122.40001,101.99992,28.16777
122.50001,102.08324,28.06708
122.60001,102.16679,27.89788
122.70001,102.24998,28.27753
122.80000,102.33324,28.40910
122.90001,102.41680,28.21241
123.00001,102.49992,28.28228
123.10001,102.58324,28.48735
123.20001,102.66673,28.22662
123.30000,102.74992,28.27146
123.40001,102.83330,28.10486
123.50001,102.91680,28.38254
123.60001,102.99998,28.34407
123.70001,103.08329,28.24250
123.80000,103.16680,28.41821
123.90001,103.24992,28.31992
124.00001,103.33324,28.56698
124.10001,103.41667,28.53150
124.20001,103.49993,28.48906
124.30000,103.58323,28.63807
124.40001,103.66674,28.55237
124.50001,103.74999,28.49073
124.60001,103.83330,28.50264
124.70001,103.91674,28.58192
124.80000,103.99998,28.41615
124.90001,104.08323,28.61504
125.00001,104.16673,28.53919
125.10001,104.24992,28.53904
125.20001,104.33324,28.65664
125.30000,104.41673,28.61431
125.40001,104.49992,28.69540
125.50001,104.58324,28.53601
125.60001,104.66673,28.86960
125.70001,104.74992,28.72132
125.80000,104.83329,28.65366
125.90001,104.91673,28.81683
126.00001,104.99999,28.71839
126.10001,105.08324,28.69766
126.20001,105.16667,28.65067
126.30000,105.24986,28.60206
126.40001,105.33324,28.82016
126.50001,105.41674,28.85573
126.60001,105.49992,28.82422
126.70001,105.58330,28.91365
126.80000,105.66674,28.95290
126.90001,105.74998,28.72765
127.00001,105.83323,28.85480
127.10001,105.91674,28.79027
127.20001,105.99992,29.08196
127.30000,106.08323,28.91311
127.40001,106.16673,28.81099
127.50001,106.24993,28.98514
127.60001,106.33330,28.90880
127.70001,106.41679,29.11371
127.80000,106.49998,28.97720
127.90001,106.58324,28.93722
128.00000,106.66680,28.99068
128.10001,106.74998,29.09167
128.20002,106.83317,28.94006
128.30000,106.91673,28.97279
128.40001,106.99999,29.15296
128.50000,107.08317,29.01003
128.60001,107.16673,29.02997
128.70002,107.24992,29.26454
128.80000,107.33330,29.03424
128.90001,107.41680,29.13704
129.00000,107.49999,29.28737
129.10001,107.58329,29.17815
129.20002,107.66674,29.25013
129.30000,107.74992,29.08147
129.40001,107.83323,29.39345
129.50000,107.91673,29.10289
129.60001,107.99998,29.25542
129.70002,108.08324,29.10979
129.80000,108.16674,29.35107
129.90001,108.24999,29.26669
130.00000,108.33323,29.32246
130.10001,108.41668,29.30143
130.20002,108.49998,29.36430
130.30000,108.58323,29.24758
130.40001,108.66679,29.45235
130.50000,108.74998,29.52105
130.60001,108.83324,29.27708
130.70002,108.91673,29.38228
130.80000,108.99986,29.34058
130.90001,109.08323,29.39777
131.00000,109.16680,29.36121
131.10000,109.25005,29.48288
131.20002,109.33329,29.46681
131.30000,109.41680,29.45818
131.40002,109.49999,29.42506
131.50000,109.58323,29.35450
131.60000,109.66667,29.29551
131.70002,109.74992,29.41977
131.80000,109.83324,29.45872
131.90002,109.91674,29.42560
132.00000,109.99999,29.43476
132.10000,110.08330,29.69461
132.20002,110.16680,29.46132
132.30000,110.24993,29.58588
132.40002,110.33324,29.45392
132.50000,110.41667,29.47450
132.60000,110.49992,29.71127
132.70002,110.58323,29.78207
132.80000,110.66673,29.70137
132.90002,110.74998,29.63409
133.00000,110.83324,29.65492
133.10000,110.91674,29.58789
133.20002,110.99998,29.58980
133.30000,111.08330,29.77913
133.40002,111.16680,29.76007
133.50000,111.24998,29.67815
133.60000,111.33323,29.79217
133.70002,111.41674,29.74371
133.80000,111.49986,29.55785
133.90002,111.58324,29.74292
134.00000,111.66673,29.71254
134.10000,111.74999,29.89198
134.20002,111.83336,29.70936
134.30000,111.91680,29.73170
134.40002,111.99992,29.60337
134.50000,112.08324,29.71215
134.60000,112.16674,29.77590
134.70002,112.24993,29.85846
134.80000,112.33323,29.88654
134.90002,112.41680,29.73028
135.00000,112.49992,29.91197
135.10000,112.58330,29.67922
135.20002,112.66680,29.60077
135.30000,112.74998,29.69966
135.40002,112.83323,29.68932
135.50000,112.91673,29.91849
135.60000,112.99998,29.73631
135.70002,113.08330,29.82358
135.80000,113.16667,29.55011
135.90002,113.24992,29.53286
136.00000,113.33324,29.55520
136.10000,113.41673,29.65467
136.20002,113.49998,29.55369
136.30000,113.58330,29.43873
136.40002,113.66680,29.41795
136.50000,113.74999,29.12993
136.60000,113.83324,18.31263
136.70002,113.91673,-0.39522
136.80000,113.99992,0.01560
136.90002,114.08323,-0.17722
137.00000,114.16674,-0.13885
137.10000,114.24999,-0.27953
137.20002,114.33329,-0.24278
137.30000,114.41674,-0.19226
137.40002,114.49993,0.09267
137.50000,114.58330,-0.08137
137.60000,114.66674,-0.09529
137.70002,114.74992,-0.11288
137.80000,114.83330,-0.00586
137.90002,114.91674,-0.00626
138.00000,114.99998,-0.03943
138.10000,115.08323,-0.14346
138.20002,115.16668,0.03201
138.30000,115.24999,-0.11592
138.40002,115.33324,-0.00126
138.50000,115.41673,-0.18285
138.60000,115.49998,-0.03379
138.70002,115.58330,-0.26189
138.80000,115.66673,-0.23342
138.90002,115.74992,0.02515
139.00000,115.83317,-0.31981
139.10000,115.91673,-0.36219
139.20002,115.99992,-0.26605
139.30000,116.08324,-0.15982
139.40002,116.16680,-0.19319
139.50000,116.24998,-0.10244
139.60000,116.33324,-0.11587
139.70002,116.41674,0.06043
139.80000,116.49999,-0.24087
139.90002,116.58323,-0.18187
140.00000,116.66667,-0.05349
140.10000,116.74993,-0.24572
140.20002,116.83323,-0.14395
140.30000,116.91674,0.08949
140.40002,116.99992,-0.30383
140.50000,117.08323,-0.22960
140.60000,117.16680,-0.04198
140.69200,117.24330,-0.13978