File: V_8/NR/RDSO NR Tensile 50.is_tens_RawData/Specimen_RawData_2.csv
Time,Extension,Load
(sec),(mm),(N)
0.00000,0.00000,0.18666
0.20000,0.16469,0.42181
0.40000,0.33294,0.92969
0.60000,0.50000,1.05910
0.80000,0.66669,1.58771
1.00000,0.83325,1.78072
1.20000,0.99994,2.27175
1.40000,1.16681,2.27008
1.60000,1.33331,2.54771
1.80000,1.49994,2.90154
2.00000,1.66669,2.92060
2.20000,1.83331,3.19010
2.40000,2.00000,3.53712
2.60000,2.16681,3.62762
2.80000,2.33331,3.94548
3.00000,2.50000,4.17931
3.20000,2.66669,4.38433
3.40000,2.83325,4.81239
3.60000,3.00000,4.74139
3.80000,3.16681,5.14436
4.00000,3.33331,5.33389
4.20000,3.49987,5.52945
4.40000,3.66681,5.57831
4.60000,3.83331,5.78504
4.80000,3.99994,5.95590
5.00000,4.16669,6.22883
5.20000,4.33331,6.19703
5.40000,4.50000,6.76033
5.60000,4.66681,6.81594
5.80000,4.83325,6.75793
6.00000,5.00000,6.95520
6.20000,5.16669,7.20510
6.40000,5.33325,7.16668
6.60000,5.50000,7.41869
6.80000,5.66681,7.45461
7.00000,5.83325,7.87463
7.20000,5.99994,7.88135
7.40000,6.16675,7.98807
7.60000,6.33325,8.24262
7.80000,6.50000,8.36625
8.00000,6.66675,8.38453
8.20000,6.83331,8.39188
8.40000,6.99994,8.86732
8.60000,7.16669,8.90735
8.80000,7.33325,8.73213
9.00000,7.50006,8.83194
9.20000,7.66675,9.01354
9.40000,7.83319,9.18043
9.60000,7.99994,9.26074
9.80000,8.16681,9.52309
10.00000,8.33325,9.76554
10.20000,8.49994,9.52338
10.40000,8.66675,9.80342
10.60000,8.83325,9.82625
10.80000,8.99994,9.98697
11.00000,9.16675,10.04788
11.20000,9.33331,10.14142
11.40000,9.49994,10.14563
11.60000,9.66669,10.04832
11.80000,9.83325,10.26470
12.00000,10.00000,10.44551
12.20000,10.16675,10.59805
12.40000,10.33325,10.70447
12.60000,10.49994,10.72304
12.80000,10.66675,10.69203
13.00000,10.83325,10.88097
13.20000,11.00000,10.80737
13.40000,11.16675,11.31731
13.60000,11.33325,11.14846
13.80000,11.49987,11.03988
14.00000,11.66675,11.04571
14.20000,11.83337,11.21667
14.40000,11.99994,11.37068
14.60000,12.16669,11.34961
14.80000,12.33325,11.48421
15.00000,12.50000,11.47691
15.20000,12.66675,11.43109
15.40000,12.83325,11.69902
15.60000,12.99994,11.57726
15.80000,13.16675,11.80427
16.00000,13.33319,11.86871
16.20000,13.49994,11.89262
16.40000,13.66675,11.63434
16.60000,13.83331,11.85666
16.80000,13.99994,12.03065
17.00000,14.16675,12.13306
17.20000,14.33325,12.20906
17.40000,14.50000,12.21166
17.60000,14.66675,12.15178
17.80000,14.83325,12.18005
18.00000,15.00000,12.21475
18.20000,15.16675,12.41584
18.40000,15.33331,12.48003
18.60000,15.50000,12.60312
18.80000,15.66668,12.44279
19.00000,15.83318,12.55598
19.20000,15.99994,12.73645
19.40000,16.16681,12.71832
19.60000,16.33325,12.75007
19.80000,16.49993,12.74331
20.00000,16.66675,12.78408
20.20000,16.83325,12.79691
20.40000,16.99993,12.85150
20.60000,17.16675,12.84194
20.80000,17.33331,13.11007
21.00000,17.50000,12.70768
21.20000,17.66675,13.06739
21.40000,17.83318,12.98052
21.60000,18.00000,13.14026
21.80000,18.16681,12.93103
22.00000,18.33325,12.81842
22.20000,18.49993,13.00732
22.40000,18.66675,13.08704
22.60000,18.83325,13.23051
22.80000,19.00000,12.99218
23.00000,19.16675,13.28044
23.20000,19.33325,13.24487
23.40000,19.49994,13.22948
23.60000,19.66669,13.36683
23.80000,19.83325,13.40642
24.00000,20.00000,13.27995
24.20000,20.16675,13.27790
24.40000,20.33318,13.36874
24.60000,20.50000,13.57508
24.80000,20.66675,13.60835
25.00000,20.83331,13.76451
25.20000,20.99993,13.33944
25.40000,21.16668,13.61609
25.60000,21.33325,13.57606
25.80000,21.50000,13.65113
26.00000,21.66675,13.59189
26.20000,21.83331,13.82914
26.40000,21.99993,13.78749
26.60000,22.16675,13.61707
26.80000,22.33325,13.80837
27.00000,22.50000,13.84463
27.20000,22.66675,13.84262
27.40000,22.83325,13.75153
27.60000,23.00000,13.92425
27.80000,23.16675,13.82758
28.00000,23.33325,14.02382
28.20000,23.50000,14.16925
28.40000,23.66681,13.99334
28.60000,23.83331,14.10712
28.80000,24.00000,14.09257
29.00000,24.16662,13.88108
29.20000,24.33331,14.10325
29.40000,24.50000,14.20135
29.60000,24.66675,14.30106
29.80000,24.83318,14.26539
30.00000,24.99999,14.14852
30.20000,25.16681,14.30185
30.40000,25.33331,14.34766
30.60000,25.49987,14.35751
30.80000,25.66675,14.37402
31.00000,25.83325,14.17846
31.20000,26.00000,14.50167
31.40000,26.16681,14.39250
31.60000,26.33331,14.56953
31.80000,26.49993,14.41136
32.00000,26.66668,14.45301
32.20000,26.83325,14.32336
32.40000,27.00000,14.50799
32.60000,27.16674,14.45869
32.80000,27.33325,14.54660
33.00000,27.50000,14.54993
33.20000,27.66675,14.68904
33.40000,27.83331,14.77175
33.60000,28.00000,14.54400
33.80000,28.16675,14.88196
34.00000,28.33318,14.89969
34.20000,28.49993,14.97437
34.40000,28.66675,14.78038
34.60000,28.83331,14.94869
34.80000,28.99993,14.91170
35.00000,29.16675,15.08325
35.20000,29.33331,14.94869
35.40000,29.49993,15.03155
35.60000,29.66675,14.95692
35.80000,29.83331,15.08761
36.00000,30.00000,14.84702
36.20000,30.16675,15.13548
36.40000,30.33325,15.18497
36.60000,30.49993,14.87799
36.80000,30.66681,15.10853
37.00000,30.83325,15.06120
37.20000,30.99993,15.19546
37.40000,31.16668,15.22559
37.60000,31.33331,15.35951
37.80000,31.49999,15.37999
38.00000,31.66674,15.25053
38.20000,31.83324,15.30531
38.40000,31.99993,15.62239
38.60000,32.16675,15.41801
38.80000,32.33337,15.46883
39.00000,32.50006,15.46216
39.20000,32.66668,15.53282
39.40000,32.83324,15.57080
39.60000,32.99993,15.60093
39.80000,33.16681,15.71152
40.00000,33.33325,15.69021
40.20000,33.49993,15.63910
40.40000,33.66675,15.60294
40.60000,33.83331,15.56134
40.80000,33.99987,15.85436
41.00000,34.16675,15.88317
41.20000,34.33331,15.80487
41.40000,34.49999,15.88297
41.60000,34.66668,15.90311
41.80000,34.83331,15.71740
42.00000,34.99999,15.92296
42.20000,35.16681,15.93315
42.40000,35.33318,15.87592
42.60000,35.49999,15.99494
42.80000,35.66675,16.21353
43.00000,35.83324,16.16232
43.20000,35.99999,15.81437
43.40000,36.16675,16.24008
43.60000,36.33325,16.14287
43.80000,36.49993,16.26321
44.00000,36.66674,16.14404
44.20000,36.83325,16.29178
44.40000,36.99999,16.26272
44.60000,37.16668,16.39468
44.80000,37.33318,16.48925
45.00000,37.49993,16.50615
45.20000,37.66681,16.38948
45.40000,37.83331,16.66663
45.60000,38.00000,16.50267
45.80000,38.16668,16.50963
46.00000,38.33324,16.68177
46.20000,38.49993,16.33142
46.40000,38.66687,16.58117
46.60000,38.83325,16.61532
46.80000,38.99993,16.59857
47.00000,39.16674,16.54256
47.20000,39.33331,16.74836
47.40000,39.49999,16.79035
47.60000,39.66675,16.83132
47.80000,39.83324,16.88674
48.00000,39.99993,16.94877
48.20000,40.16674,16.83602
48.40000,40.33324,16.80799
48.60000,40.49993,17.02109
48.80000,40.66675,16.82269
49.00000,40.83325,16.98106
49.20000,40.99993,17.00791
49.40000,41.16674,16.94681
49.60000,41.33324,17.12071
49.80000,41.50006,17.08523
50.00000,41.66668,17.07607
50.20000,41.83325,17.20964
50.40000,41.99999,17.13967
50.60000,42.16681,17.34204
50.80000,42.33324,17.23052
51.00000,42.49993,17.16892
51.20000,42.66668,17.28447
51.40000,42.83324,17.44259
51.60000,42.99999,17.44729
51.80000,43.16681,17.48679
52.00000,43.33324,17.42167
52.20000,43.50000,17.51521
52.40000,43.66668,17.45876
52.60000,43.83324,17.48566
52.80000,44.00000,17.58327
53.00000,44.16674,17.57513
53.20000,44.33331,17.53118
53.40000,44.49993,17.75246
53.60000,44.66674,17.78520
53.80000,44.83324,17.69954
54.00000,44.99999,17.85414
54.20000,45.16675,17.78265
54.40000,45.33318,17.79505
54.60000,45.49993,17.88942
54.80000,45.66674,17.86717
55.00000,45.83324,17.81327
55.20000,45.99999,18.01888
55.40000,46.16668,17.88486
55.60000,46.33325,17.94214
55.80000,46.49993,17.88819
56.00000,46.66674,17.95317
56.20000,46.83331,18.07219
56.40000,46.99999,18.28421
56.60000,47.16674,18.14917
56.80000,47.33324,18.18200
57.00000,47.49999,18.20860
57.20000,47.66674,18.24795
57.40000,47.83330,18.23619
57.60000,47.99993,18.23203
57.80000,48.16674,18.21370
58.00000,48.33324,18.39289
58.20000,48.49999,18.43802
58.40000,48.66675,18.42415
58.60000,48.83324,18.41744
58.80000,48.99993,18.57625
59.00000,49.16681,18.52647
59.20000,49.33331,18.66543
59.40000,49.49993,18.56518
59.60000,49.66668,18.63559
59.80000,49.83325,18.79067
60.00000,49.99999,18.80699
60.20000,50.16681,18.76245
60.40000,50.33324,18.80336
60.60000,50.49999,18.82527
60.80000,50.66674,18.69321
61.00000,50.83318,18.73663
61.20000,50.99993,18.98133
61.40000,51.16674,18.87025
61.60000,51.33331,18.97952
61.80000,51.49993,18.93468
62.00000,51.66674,18.92410
62.20000,51.83324,19.03484
62.40000,51.99999,19.02225
62.60000,52.16674,18.91989
62.80000,52.33324,18.92949
63.00000,52.49993,19.00578
63.20000,52.66674,19.03969
63.40000,52.83324,19.29292
63.60000,52.99999,19.09971
63.80000,53.16680,19.18468
64.00000,53.33324,19.28949
64.20000,53.49999,19.28023
64.40000,53.66674,19.27504
64.60001,53.83330,19.32771
64.80000,53.99999,19.57741
65.00000,54.16675,19.46854
65.20000,54.33324,19.35603
65.40000,54.49999,19.35187
65.60001,54.66674,19.52694
65.80000,54.83324,19.57232
66.00000,55.00000,19.73456
66.20001,55.16674,19.48510
66.40000,55.33318,19.49039
66.60001,55.49999,19.72000
66.80000,55.66674,19.79576
67.00000,55.83331,19.77841
67.20001,55.99993,19.81046
67.40000,56.16674,19.93600
67.60001,56.33330,19.93864
67.80000,56.49999,19.87984
68.00000,56.66674,19.85373
68.20001,56.83324,20.08741
68.40000,56.99993,19.93237
68.60001,57.16668,19.90096
68.80000,57.33324,19.67042
69.00000,57.49993,20.25974
69.20001,57.66674,20.06937
69.40000,57.83324,20.16007
69.60001,57.99993,20.17903
69.80000,58.16674,20.31055
70.00000,58.33331,20.29732
70.20001,58.49999,20.14586
70.40000,58.66680,20.26714
70.60001,58.83318,20.33392
70.80000,58.99999,20.23029
71.00000,59.16681,20.35073
71.20001,59.33330,20.35573
71.40000,59.49993,20.33294
71.60001,59.66668,20.41007
71.80000,59.83324,20.45579
72.00000,59.99999,20.59495
72.20001,60.16674,20.66217
72.40000,60.33324,20.54644
72.60001,60.49993,20.63630
72.80000,60.66668,20.59000
73.00000,60.83325,20.69334
73.20001,60.99993,20.68275
73.40000,61.16674,20.69270
73.60001,61.33324,20.76924
73.80000,61.49993,20.70137
74.00000,61.66674,20.96720
74.20001,61.83330,21.06373
74.40000,61.99993,21.00777
74.60001,62.16674,20.87199
74.80000,62.33318,20.88703
75.00000,62.49999,21.08994
75.20001,62.66681,21.04810
75.40000,62.83324,20.99816
75.60001,62.99999,21.09759
75.80000,63.16674,21.08171
76.00000,63.33318,21.11199
76.20001,63.49999,21.13693
76.40000,63.66680,21.28903
76.60001,63.83324,21.20053
76.80000,63.99999,21.40491
77.00000,64.16674,21.20083
77.20001,64.33330,21.33582
77.40000,64.49999,21.35096
77.60001,64.66674,21.50703
77.80000,64.83330,21.68705
78.00000,64.99999,21.55559
78.20001,65.16674,21.56696
78.40000,65.33330,21.61997
78.60001,65.49993,21.74483
78.80000,65.66674,21.56764
79.00000,65.83318,21.56455
79.20001,65.99993,21.52413
79.40000,66.16674,21.87129
79.60001,66.33330,21.80975
79.80000,66.49993,21.80338
80.00000,66.66674,21.91838
80.20001,66.83324,21.87022
80.40000,66.99999,21.83582
80.60001,67.16674,21.98556
80.80000,67.33330,21.94871
81.00001,67.49993,22.08748
81.20001,67.66674,21.78060
81.40000,67.83324,21.94234
81.60001,67.99993,21.88447
81.80000,68.16680,22.09772
82.00001,68.33324,21.98194
82.20001,68.49999,22.22007
82.40000,68.66667,22.09155
82.60001,68.83324,22.18734
82.80000,68.99999,22.39515
83.00001,69.16680,22.25927
83.20001,69.33324,22.29480
83.40000,69.49992,22.26035
83.60001,69.66668,22.33998
83.80000,69.83330,22.28882
84.00001,69.99999,22.42563
84.20001,70.16681,22.56018
84.40000,70.33318,22.45459
84.60001,70.49999,22.49188
84.80000,70.66674,22.55362
85.00001,70.83330,22.47203
85.20001,70.99999,22.77186
85.40000,71.16674,22.61344
85.60001,71.33324,22.68925
85.80000,71.49993,22.62908
86.00001,71.66680,22.65299
86.20001,71.83324,22.83115
86.40000,71.99999,22.79014
86.60001,72.16674,22.96120
86.80000,72.33324,22.68856
87.00001,72.49999,22.93586
87.20001,72.66680,23.10967
87.40000,72.83330,22.94062
87.60001,72.99993,22.74535
87.80000,73.16674,23.00853
88.00001,73.33330,22.93929
88.20001,73.49999,23.16974
88.40000,73.66681,23.37848
88.60001,73.83324,23.27627
88.80000,73.99993,23.18439
89.00001,74.16674,23.14696
89.20001,74.33324,23.22736
89.40000,74.49999,23.17508
89.60001,74.66674,23.56438
89.80000,74.83324,23.39926
90.00001,74.99993,23.21134
90.20001,75.16674,23.34795
90.40000,75.33330,23.42503
90.60001,75.49999,23.49755
90.80000,75.66668,23.60736
91.00001,75.83324,23.35663
91.20001,75.99992,23.48520
91.40000,76.16680,23.43253
91.60001,76.33324,23.70849
91.80000,76.49993,23.56228
92.00001,76.66674,23.65920
92.20001,76.83330,23.70056
92.40000,76.99999,23.81855
92.60001,77.16680,23.99019
92.80000,77.33324,23.75367
93.00001,77.49993,23.78493
93.20001,77.66674,24.02885
93.40000,77.83324,23.97525
93.60001,77.99999,23.92914
93.80000,78.16673,23.83486
94.00001,78.33323,23.97736
94.20001,78.49992,24.12680
94.40000,78.66674,24.01322
94.60001,78.83323,24.08231
94.80000,78.99993,24.26503
95.00001,79.16674,24.22863
95.20001,79.33323,24.02601
95.40000,79.49992,24.25043
95.60001,79.66680,24.36411
95.80000,79.83324,24.55653
96.00001,79.99999,24.17551
96.20001,80.16674,24.19825
96.40000,80.33318,24.33246
96.60001,80.49992,24.47465
96.80000,80.66680,24.47999
97.00001,80.83324,24.53845
97.20001,80.99993,24.43756
97.40000,81.16674,24.62807
97.60001,81.33323,24.56041
97.80000,81.49993,24.74308
98.00001,81.66674,24.56917
98.20001,81.83324,24.77106
98.40000,81.99993,24.69016
98.60001,82.16674,24.91428
98.80000,82.33330,24.81094
99.00001,82.49999,24.93251
99.20001,82.66667,24.77262
99.40000,82.83324,24.83603
99.60001,82.99992,24.96456
99.80000,83.16680,24.90625
100.00001,83.33330,25.03766
100.20001,83.49999,25.03110
100.40000,83.66674,25.09063
100.60001,83.83330,25.15610
100.80000,83.99992,25.12728
101.00001,84.16668,25.17702
101.20001,84.33330,25.08098
101.40000,84.49992,25.21695
101.60001,84.66673,25.36199
101.80000,84.83318,25.34107
102.00001,84.99999,25.33377
102.20001,85.16674,25.42339
102.40000,85.33323,25.59562
102.60001,85.49993,25.28237
102.80000,85.66674,25.59474
103.00001,85.83323,25.44774
103.20001,85.99998,25.28276
103.40000,86.16674,25.52541
103.60001,86.33324,25.59744
103.80000,86.49993,25.84851
104.00001,86.66674,25.52301
104.20001,86.83329,25.66898
104.40000,86.99999,25.81656
104.60001,87.16674,25.88948
104.80000,87.33324,25.70690
105.00001,87.49993,25.97469
105.20001,87.66674,25.90741
105.40000,87.83324,25.96856
105.60001,87.99993,25.86890
105.80000,88.16673,25.90741
106.00001,88.33324,25.75517
106.20001,88.49992,25.87242
106.40000,88.66680,26.10121
106.60001,88.83324,25.97180
106.80000,88.99986,26.28520
107.00001,89.16673,26.26653
107.20001,89.33323,26.18323
107.40000,89.49999,26.16388
107.60001,89.66674,26.23311
107.80000,89.83330,26.34635
108.00001,89.99986,26.28270
108.20001,90.16674,26.29240
108.40000,90.33323,26.23576
108.60001,90.49999,26.44626
108.80000,90.66674,26.45440
109.00001,90.83324,26.47032
109.20001,90.99992,26.51227
109.40000,91.16674,26.52290
109.60001,91.33330,26.64035
109.80000,91.49999,26.64951
110.00001,91.66680,26.66539
110.20001,91.83324,26.80514
110.40000,91.99993,26.71787
110.60001,92.16674,26.70532
110.80000,92.33330,26.99648
111.00001,92.49998,26.90961
111.20001,92.66668,26.94572
111.40000,92.83324,26.96287
111.60001,93.00006,26.84512
111.80000,93.16680,27.05817
112.00001,93.33324,26.75266
112.20001,93.49992,26.94640
112.40000,93.66673,26.94826
112.60001,93.83324,27.12349
112.80000,93.99992,27.18371
113.00001,94.16673,27.14657
113.20001,94.33329,27.09801
113.40001,94.49992,27.20297
113.60001,94.66674,27.14784
113.80000,94.83330,27.09360
114.00001,94.99999,27.18523
114.20001,95.16673,27.27117
114.40001,95.33317,27.41783
114.60001,95.49998,27.49309
114.80000,95.66673,27.37549
115.00001,95.83324,27.35011
115.20001,95.99992,27.66856
115.40001,96.16673,27.42498
115.60001,96.33318,27.42013
115.80000,96.49999,27.49990
116.00001,96.66674,27.74402
116.20001,96.83330,27.75769
116.40001,96.99993,27.56895
116.60001,97.16674,27.58624
116.80000,97.33323,27.58781
117.00001,97.49998,27.83012
117.20001,97.66679,27.74353
117.40001,97.83324,27.95840
117.60001,97.99998,27.88715
117.80000,98.16674,27.95761
118.00001,98.33329,27.91944
118.20001,98.49992,27.82752
118.40001,98.66673,27.88882
118.60001,98.83317,27.99088
118.80000,98.99999,28.14126
119.00001,99.16673,28.05008
119.20001,99.33330,28.10922
119.40001,99.49992,28.23632
119.60001,99.66673,28.06296
119.80000,99.83324,28.25102
120.00001,99.99998,28.30100
120.20001,100.16680,28.46432
120.40001,100.33330,28.24044
120.60001,100.49986,28.31296
120.80000,100.66673,28.56820
121.00001,100.83323,28.52092
121.20001,100.99992,28.43864
121.40001,101.16674,28.51758
121.60001,101.33323,28.55610
121.80000,101.49992,28.54899
122.00001,101.66674,28.68501
122.20001,101.83323,28.61921
122.40001,101.99992,28.74073
122.60001,102.16679,28.73279
122.80000,102.33324,28.70501
123.00001,102.49992,28.84902
123.20001,102.66673,28.93702
123.40001,102.83324,29.01518
123.60001,102.99998,28.83574
123.80000,103.16680,28.99974
124.00001,103.33324,28.77606
124.20001,103.49993,29.10068
124.40001,103.66674,28.92276
124.60001,103.83330,28.93737
124.80000,103.99998,28.96696
125.00001,104.16673,28.92467
125.20001,104.33324,29.17947
125.40001,104.49992,29.40076
125.60001,104.66673,29.27546
125.80000,104.83329,29.06545
126.00001,104.99999,29.29648
126.20001,105.16661,29.28027
126.40001,105.33324,29.46661
126.60001,105.49999,29.34245
126.80000,105.66680,29.61787
127.00001,105.83323,29.37763
127.20001,105.99986,29.62508
127.40001,106.16673,29.52835
127.60001,106.33330,29.56055
127.80000,106.49998,29.67021
128.00000,106.66680,29.54962
128.20002,106.83317,29.66261
128.40001,106.99992,29.55153
128.60001,107.16673,29.76674
128.80000,107.33330,29.63601
129.00000,107.49999,29.84185
129.20002,107.66674,29.88880
129.40001,107.83317,29.70852
129.60001,107.99993,29.97900
129.80000,108.16674,29.98562
130.00000,108.33323,30.10758
130.20002,108.49993,29.87066
130.40001,108.66674,30.07754
130.60001,108.83324,30.09116
130.80000,108.99986,29.80829
131.00000,109.16680,30.08435
131.20002,109.33329,30.26982
131.40002,109.49999,30.34356
131.60000,109.66667,30.30799
131.80000,109.83329,30.26384
132.00000,109.99999,30.26320
132.20002,110.16680,30.25115
132.40002,110.33317,30.49742
132.60000,110.49998,30.48120
132.80000,110.66668,30.46523
133.00000,110.83324,30.33621
133.20002,110.99992,30.53544
133.40002,111.16680,30.69249
133.60000,111.33323,30.48228
133.80000,111.49992,30.69303
134.00000,111.66673,30.65471
134.20002,111.83330,30.54667
134.40002,111.99992,30.67255
134.60000,112.16674,30.77599
134.80000,112.33323,30.90373
135.00000,112.49992,30.96351
135.20002,112.66680,30.95376
135.40002,112.83323,30.77177
135.60000,112.99998,31.03525
135.80000,113.16674,31.11668
136.00000,113.33324,31.03696
136.20002,113.49998,30.96606
136.40002,113.66680,30.98492
136.60000,113.83324,31.02961
136.80000,113.99992,31.29641
137.00000,114.16674,30.99399
137.20002,114.33329,31.12653
137.40002,114.49993,31.32400
137.60000,114.66674,31.01814
137.80000,114.83323,31.23149
138.00000,114.99998,31.47286
138.20002,115.16673,31.25261
138.40002,115.33324,31.27882
138.60000,115.49998,31.29455
138.80000,115.66673,31.28049
139.00000,115.83317,31.42220
139.20002,115.99986,31.52848
139.40002,116.16680,31.62604
139.60000,116.33324,31.47306
139.80000,116.49992,31.77607
140.00000,116.66674,31.76568
140.20002,116.83330,31.80381
140.40002,116.99992,31.74814
140.60000,117.16680,31.69233
140.80000,117.33330,31.87407
141.00000,117.49992,31.72237
141.20002,117.66667,31.95140
141.40002,117.83330,31.92988
141.60000,117.99999,32.16317
141.80000,118.16673,32.03881
142.00000,118.33323,32.10413
142.20002,118.49998,31.95267
142.40002,118.66674,32.15097
142.60000,118.83323,32.25985
142.80000,118.99998,32.31032
143.00000,119.16674,32.22026
143.20002,119.33330,32.12838
143.40002,119.49993,32.15303
143.60000,119.66674,32.32835
143.80000,119.83329,32.14083
144.00000,119.99998,32.32129
144.20002,120.16667,32.36583
144.40002,120.33324,32.46085
144.60000,120.49992,32.46565
144.80000,120.66680,32.63651
145.00000,120.83324,32.51391
145.20002,120.99992,32.57482
145.40002,121.16673,32.56840
145.60000,121.33324,32.62686
145.80000,121.49998,32.70408
146.00000,121.66673,32.63391
146.20002,121.83330,32.66704
146.40002,121.99992,32.72907
146.60000,122.16673,32.75994
146.80000,122.33323,32.96657
147.00000,122.49999,32.91909
147.20002,122.66673,33.05502
147.40002,122.83323,32.80576
147.60000,122.99986,33.02057
147.80000,123.16667,33.00744
148.00000,123.33323,32.99921
148.20002,123.49999,32.92747
148.40002,123.66674,33.24837
148.60000,123.83318,33.16938
148.80000,123.99992,33.23210
149.00000,124.16679,33.27988
149.20002,124.33324,33.27571
149.40002,124.49998,33.30795
149.60000,124.66673,33.18129
149.80000,124.83324,33.31329
150.00000,124.99992,33.39958
150.20002,125.16673,33.35593
150.40002,125.33324,33.54663
150.60000,125.49998,33.40351
150.80000,125.66673,33.44261
151.00000,125.83317,33.54031
151.20002,125.99992,33.45324
151.40002,126.16679,33.61396
151.60000,126.33330,33.51836
151.80000,126.49992,33.62734
152.00000,126.66667,33.70005
152.20002,126.83324,33.64253
152.40002,127.00004,33.76101
152.60000,127.16673,33.94951
152.80000,127.33323,33.69211
153.00000,127.49991,33.78330
153.20002,127.66673,33.89992
153.40002,127.83329,33.82441
153.60000,127.99998,33.91599
153.80000,128.16672,33.62327
154.00000,128.33322,33.87297
154.20002,128.49991,33.75660
154.40002,128.66679,33.81981
154.60000,128.83330,33.96656
154.80000,128.99992,33.48695
155.00000,129.16672,33.71588
155.20002,129.33323,33.36151
155.40002,129.49991,-0.10759
155.60000,129.66679,-0.14497
155.80000,129.83330,0.10762
156.00000,129.99992,-0.06280
156.20002,130.16673,0.09806
156.40002,130.33323,0.16858
156.60000,130.49997,0.09988
156.80000,130.66674,0.10130
157.00000,130.83323,0.04529
157.20002,130.99991,0.00129
157.40002,131.16673,-0.05614
157.60000,131.33324,0.00129
157.80000,131.49998,0.18509
158.00000,131.66673,0.02682
158.14802,131.79004,0.10257