File: V_8/NR/RDSO NR Tensile 250.is_tens_RawData/Specimen_RawData_6.csv
Time,Extension,Load,
(sec),(mm),(N),(kgf)
0,0,-0.960463301,-0.09794
0.04,0.06756,-0.403935914,-0.04119
0.08,0.27756,-0.187895414,-0.01916
0.12,0.48294,-0.036676871,-0.00374
0.16,0.65537,0.258111028,0.02632
0.2,0.82406,0.609679431,0.06217
0.24,0.99475,1.036072573,0.10565
0.28,1.16387,1.231322974,0.12556
0.32,1.33169,1.594267091,0.16257
0.36,1.499,2.065378557,0.21061
0.4,1.666,2.029093952,0.20691
0.44,1.83287,2.265826483,0.23105
0.48,1.99981,2.639067582,0.26911
0.52,2.16662,2.900512871,0.29577
0.56,2.33337,3.080955231,0.31417
0.6,2.5,3.309450176,0.33747
0.64,2.66656,3.474299962,0.35428
0.68,2.83331,3.731430325,0.3805
0.72,3.00006,3.914912747,0.39921
0.76,3.16669,4.202541791,0.42854
0.8,3.33331,4.38582808,0.44723
0.84,3.5,4.562740046,0.46527
0.88,3.66656,4.673457124,0.47656
0.92,3.83337,4.928037758,0.50252
0.96,4.00012,5.161632161,0.52634
1,4.16669,5.231553576,0.53347
1.04,4.33325,5.480152153,0.55882
1.08,4.5,5.677363885,0.57893
1.12,4.66662,5.938416908,0.60555
1.16,4.83344,6.189074882,0.63111
1.2,5.00006,6.220652295,0.63433
1.24,5.16662,6.271058476,0.63947
1.28,5.33325,6.467877941,0.65954
1.32,5.5,6.729813563,0.68625
1.36,5.66669,7.056375008,0.71955
1.4,5.83337,7.042057299,0.71809
1.44,6.00006,7.080793566,0.72204
1.48,6.16662,7.29026361,0.7434
1.52,6.33331,7.510815169,0.76589
1.56,6.5,7.469431106,0.76167
1.6,6.66662,7.703025509,0.78549
1.64,6.83337,7.955939012,0.81128
1.68,7.00012,7.983789898,0.81412
1.72,7.16669,7.935148914,0.80916
1.76,7.33325,8.117062272,0.82771
1.8,7.5,8.322805789,0.84869
1.84,7.66675,8.417047695,0.8583
1.88,7.83344,8.741059411,0.89134
1.92,8,9.009467422,0.91871
1.96,8.16656,8.982695267,0.91598
2,8.33344,9.050851485,0.92293
2.04,8.50019,9.216191604,0.93979
2.08,8.66656,9.402419887,0.95878
2.12,8.83319,9.085861225,0.9265
2.16,9,9.320142094,0.95039
2.2,9.16669,9.719076616,0.99107
2.24,9.33337,9.532946399,0.97209
2.28,9.50012,9.488522274,0.96756
2.32,9.66662,9.764775605,0.99573
2.36,9.83331,9.815083719,1.00086
2.4,10,9.969832656,1.01664
2.44,10.16669,10.31492867,1.05183
2.48,10.33337,10.32287206,1.05264
2.52,10.5,10.27756533,1.04802
2.56,10.66656,10.4527121,1.06588
2.6,10.83325,10.56637118,1.07747
2.64,11.00006,10.60157705,1.08106
2.68,11.16675,10.51694566,1.07243
2.72,11.33337,10.46408782,1.06704
2.76,11.5,10.59373173,1.08026
2.8,11.66656,10.6298202,1.08394
2.84,11.83337,10.74710774,1.0959
2.88,12.00012,10.90254314,1.11175
2.92,12.16669,11.01551575,1.12327
2.96,12.33331,11.08131837,1.12998
3,12.5,11.13005742,1.13495
3.04,12.66669,11.27117511,1.14934
3.08,12.83337,11.29912406,1.15219
3.12,13.00006,11.28725802,1.15098
3.16,13.16662,11.3180509,1.15412
3.2,13.33331,11.44553735,1.16712
3.24,13.50006,11.54850717,1.17762
3.28,13.66668,11.43857463,1.16641
3.32,13.83331,11.63264823,1.1862
3.36,14.00006,11.72865533,1.19599
3.4,14.16662,11.57488706,1.18031
3.44,14.33331,11.8256431,1.20588
3.48,14.50006,11.78484744,1.20172
3.52,14.66669,11.83103676,1.20643
3.56,14.83337,11.81985718,1.20529
3.6,15.00006,11.82221077,1.20553
3.64,15.16662,11.92478833,1.21599
3.68,15.33331,12.06227757,1.23001
3.72,15.50012,11.79416376,1.20267
3.76,15.66675,11.98147077,1.22177
3.8,15.83331,12.21496711,1.24558
3.84,15.99994,12.09454145,1.2333
3.88,16.16662,12.12974732,1.23689
3.92,16.33337,12.25703764,1.24987
3.96,16.50006,12.24477932,1.24862
4,16.66668,12.2366398,1.24779
4.04,16.83337,12.33774637,1.2581
4.08,17.00006,12.26615782,1.2508
4.12,17.1665,12.37579617,1.26198
4.16,17.33331,12.55653273,1.28041
4.2,17.50012,12.60497758,1.28535
4.24,17.66669,12.42718301,1.26722
4.28,17.83331,12.57134077,1.28192
4.32,18,12.65479536,1.29043
4.36,18.16669,12.41002138,1.26547
4.4,18.33337,12.63282846,1.28819
4.44,18.50006,12.63724146,1.28864
4.48,18.66662,12.64557711,1.28949
4.52,18.83331,12.79100973,1.30432
4.56,19.00006,12.79414786,1.30464
4.6,19.16675,13.02548673,1.32823
4.64,19.33337,12.84455404,1.30978
4.68,19.5,12.89584282,1.31501
4.72,19.66662,12.89270469,1.31469
4.76,19.83331,13.06314427,1.33207
4.8,20.00006,12.78385087,1.30359
4.84,20.16668,12.94438573,1.31996
4.88,20.33337,12.96478357,1.32204
4.92,20.5,12.88240771,1.31364
4.96,20.66662,13.08873962,1.33468
5,20.83331,13.11266785,1.33712
5.04,21.00006,13.2410369,1.35021
5.08,21.16662,13.14552013,1.34047
5.12,21.33331,13.27634084,1.35381
5.16,21.5,13.13836127,1.33974
5.2,21.66662,13.3004652,1.35627
5.24,21.83337,13.2808519,1.35427
5.28,22.00012,13.43618923,1.37011
5.32,22.16662,13.27133945,1.3533
5.36,22.33325,13.4140262,1.36785
5.4,22.5,13.3367498,1.35997
5.44,22.66668,13.33361167,1.35965
5.48,22.83337,13.38411592,1.3648
5.52,23.00006,13.56700994,1.38345
5.56,23.16662,13.67262756,1.39422
5.6,23.33325,13.43501243,1.36999
5.64,23.5,13.39362837,1.36577
5.68,23.66669,13.63085123,1.38996
5.72,23.83343,13.57348233,1.38411
5.76,24.00006,13.50307058,1.37693
5.8,24.16662,13.66850877,1.3938
5.84,24.33325,13.65732919,1.39266
5.88,24.50006,13.81345106,1.40858
5.92,24.66675,13.80786127,1.40801
5.96,24.83337,13.55269223,1.38199
6,24.99993,13.75412082,1.40253
6.04,25.16662,13.72087628,1.39914
6.08,25.33343,13.8261997,1.40988
6.12,25.50012,13.80874387,1.4081
6.16,25.6665,13.87170256,1.41452
6.2,25.83318,13.94005491,1.42149
6.24,26,14.00026774,1.42763
6.28,26.16668,14.07832867,1.43559
6.32,26.33343,13.98408677,1.42598
6.36,26.50006,14.17021698,1.44496
6.4,26.66662,13.98232157,1.4258
6.44,26.83331,13.9073007,1.41815
6.48,27.00006,14.16492139,1.44442
6.52,27.16668,13.96800386,1.42434
6.56,27.33337,13.93956458,1.42144
6.6,27.5,14.20434413,1.44844
6.64,27.66662,14.28681805,1.45685
6.68,27.83331,14.41773683,1.4702
6.72,28.00006,14.35262067,1.46356
6.76,28.16668,14.44715678,1.4732
6.8,28.33331,14.52207959,1.48084
6.84,28.5,14.48187232,1.47674
6.88,28.66662,14.18522116,1.44649
6.92,28.83337,14.32918278,1.46117
6.96,29.00006,14.51952986,1.48058
7,29.16669,14.48893311,1.47746
7.04,29.33337,14.47157534,1.47569
7.08,29.5,14.61465436,1.49028
7.12,29.66662,14.3979274,1.46818
7.16,29.83337,14.67986858,1.49693
7.2,30.00006,14.51001741,1.47961
7.24,30.16668,14.42911254,1.47136
7.28,30.33331,14.61328143,1.49014
7.32,30.50006,14.68212411,1.49716
7.36,30.66662,14.59425653,1.4882
7.4,30.83337,14.75430106,1.50452
7.44,31.00006,14.81363129,1.51057
7.48,31.16662,14.58337115,1.48709
7.52,31.33325,14.77901382,1.50704
7.56,31.50006,14.97446035,1.52697
7.6,31.66668,14.99260265,1.52882
7.64,31.83337,14.92268124,1.52169
7.68,31.99999,15.01358888,1.53096
7.72,32.16656,15.04693149,1.53436
7.76,32.33337,15.0434011,1.534
7.8,32.50012,15.01535408,1.53114
7.84,32.66668,15.05212902,1.53489
7.88,32.83324,15.13891787,1.54374
7.92,33,15.17333921,1.54725
7.96,33.16668,15.30170826,1.56034
8,33.33337,15.29415714,1.55957
8.04,33.50006,15.1444096,1.5443
8.08,33.66668,15.22403959,1.55242
8.12,33.83337,15.33887546,1.56413
8.16,34.00006,15.17304501,1.54722
8.2,34.16656,15.10233907,1.54001
8.24,34.33331,15.30023726,1.56019
8.28,34.50006,15.4184074,1.57224
8.32,34.66662,15.39683277,1.57004
8.36,34.83331,15.40252062,1.57062
8.4,34.99999,15.571195,1.58782
8.44,35.16662,15.57658866,1.58837
8.48,35.33337,15.50176392,1.58074
8.52,35.49999,15.49941033,1.5805
8.56,35.66662,15.67720489,1.59863
8.6,35.83324,15.6315059,1.59397
8.64,35.99999,15.71182236,1.60216
8.68,36.16668,15.61983599,1.59278
8.72,36.33337,15.79311949,1.61045
8.76,36.50006,15.68534441,1.59946
8.8,36.66662,15.76566087,1.60765
8.84,36.83331,15.63170203,1.59399
8.88,37.00006,15.64121448,1.59496
8.92,37.16668,15.97101212,1.62859
8.96,37.33337,15.95179109,1.62663
9,37.49999,15.88745947,1.62007
9.04,37.66656,16.03799154,1.63542
9.08,37.83337,16.1039903,1.64215
9.12,38.00012,16.09575271,1.64131
9.16,38.16668,16.25167845,1.65721
9.2,38.33324,16.08006207,1.63971
9.24,38.5,16.24295053,1.65632
9.28,38.66668,16.23794914,1.65581
9.32,38.83349,16.32620899,1.66481
9.36,39.00012,16.2992407,1.66206
9.4,39.16656,16.27060528,1.65914
9.44,39.33324,16.34513582,1.66674
9.48,39.50006,16.23108448,1.65511
9.52,39.66668,16.34827395,1.66706
9.56,39.83337,16.4552645,1.67797
9.6,40.00005,16.4178031,1.67415
9.64,40.16655,16.27894093,1.65999
9.68,40.33324,16.2766854,1.65976
9.72,40.50006,16.66689201,1.69955
9.76,40.66668,16.43221887,1.67562
9.8,40.83337,16.44820371,1.67725
9.84,40.99999,16.53234477,1.68583
9.88,41.16655,16.67767932,1.70065
9.92,41.33324,16.68248458,1.70114
9.96,41.50006,16.81507049,1.71466
10,41.66674,16.80447931,1.71358
10.04,41.83331,16.88106924,1.72139
10.08,41.99999,16.8879339,1.72209
10.12,42.16668,16.92755276,1.72613
10.16,42.33343,16.81212849,1.71436
10.2,42.50005,16.9051936,1.72385
10.24,42.66649,16.96913296,1.73037
10.28,42.83324,16.90323227,1.72365
10.32,43.00006,16.96275864,1.72972
10.36,43.16668,16.98247,1.73173
10.4,43.33337,17.23391251,1.75737
10.44,43.50012,17.23646224,1.75763
10.48,43.66668,17.24921088,1.75893
10.52,43.83331,17.18576186,1.75246
10.56,44.00006,17.27578691,1.76164
10.6,44.16668,17.21998707,1.75595
10.64,44.33337,17.39336864,1.77363
10.68,44.50005,17.34708125,1.76891
10.72,44.66656,17.20517903,1.75444
10.76,44.83331,17.24450369,1.75845
10.8,45.00006,17.22940145,1.75691
10.84,45.16668,17.38424846,1.7727
10.88,45.3333,17.46172099,1.7806
10.92,45.49999,17.58430412,1.7931
10.96,45.66655,17.35708403,1.76993
11,45.83337,17.50820451,1.78534
11.04,46.00012,17.82162505,1.8173
11.08,46.16668,17.59822956,1.79452
11.12,46.3333,17.84614167,1.8198
11.16,46.49993,17.69649219,1.80454
11.2,46.66662,17.72699087,1.80765
11.24,46.83337,17.75621469,1.81063
11.28,47.00012,17.62029452,1.79677
11.32,47.16662,17.58577511,1.79325
11.36,47.33331,17.70982924,1.8059
11.4,47.50005,17.93822611,1.82919
11.44,47.66668,17.75513596,1.81052
11.48,47.83337,17.85163339,1.82036
11.52,48.00005,17.99765441,1.83525
11.56,48.16662,17.84525907,1.81971
11.6,48.3333,18.00961853,1.83647
11.64,48.50012,18.09738804,1.84542
11.68,48.66675,18.01913098,1.83744
11.72,48.83337,18.06512416,1.84213
11.76,48.99999,18.3021509,1.8663
11.8,49.16662,18.10621403,1.84632
11.84,49.33337,18.34353496,1.87052
11.88,49.50012,18.18662856,1.85452
11.92,49.66662,18.27439808,1.86347
11.96,49.83325,18.26488563,1.8625
12,49.99999,18.17299731,1.85313
12.04,50.16668,18.202025,1.85609
12.08,50.33331,18.36383472,1.87259
12.12,50.50005,18.21683304,1.8576
12.16,50.66668,18.44954484,1.88133
12.2,50.83337,18.60802031,1.89749
12.24,50.99993,18.54849394,1.89142
12.28,51.16649,18.49691096,1.88616
12.32,51.33331,18.53348977,1.88989
12.36,51.50012,18.79552346,1.91661
12.4,51.66662,18.76777064,1.91378
12.44,51.8333,18.50701181,1.88719
12.48,51.99999,18.65009084,1.90178
12.52,52.16668,18.84308571,1.92146
12.56,52.33337,18.87760512,1.92498
12.6,52.50006,18.95458732,1.93283
12.64,52.66662,18.74894187,1.91186
12.68,52.83331,18.91898918,1.9292
12.72,53.00005,19.09384175,1.94703
12.76,53.16674,18.97792715,1.93521
12.8,53.33337,19.00901423,1.93838
12.84,53.49999,19.10139287,1.9478
12.88,53.66662,18.92840356,1.93016
12.92,53.8333,19.13522581,1.95125
12.96,54.00012,19.19534058,1.95738
13,54.16668,19.16758776,1.95455
13.04,54.3333,19.30635186,1.9687
13.08,54.49993,19.25447468,1.96341
13.12,54.66662,19.21260028,1.95914
13.16,54.83337,19.21260028,1.95914
13.2,55.00012,19.42305099,1.9806
13.24,55.16662,19.4587472,1.98424
13.28,55.33325,19.52356915,1.99085
13.32,55.49999,19.4962086,1.98806
13.36,55.66668,19.54926258,1.99347
13.4,55.83337,19.35312958,1.97347
13.44,56.00005,19.50366165,1.98882
13.48,56.16656,19.49228594,1.98766
13.52,56.33324,19.42775818,1.98108
13.56,56.50006,19.64232768,2.00296
13.6,56.66668,19.57917286,1.99652
13.64,56.83336,19.68930154,2.00775
13.68,57.00005,19.77403099,2.01639
13.72,57.16662,19.70332505,2.00918
13.76,57.3333,19.86895937,2.02607
13.8,57.50006,19.83777422,2.02289
13.84,57.66668,19.74618011,2.01355
13.88,57.83337,19.75647709,2.0146
13.92,58.00006,19.68096589,2.0069
13.96,58.16655,19.92495534,2.03178
14,58.33324,19.81816092,2.02089
14.04,58.50011,19.82492751,2.02158
14.08,58.66674,19.88867073,2.02808
14.12,58.8333,20.12020574,2.05169
14.16,58.99993,19.95084489,2.03442
14.2,59.16668,20.122069,2.05188
14.24,59.33343,20.10696676,2.05034
14.28,59.50006,20.34065923,2.07417
14.32,59.66655,20.46549789,2.0869
14.36,59.83324,20.21631091,2.06149
14.4,60.00006,20.40381406,2.08061
14.44,60.16668,20.58651195,2.09924
14.48,60.33343,20.49462364,2.08987
14.52,60.50006,20.32035947,2.0721
14.56,60.66662,20.40146046,2.08037
14.6,60.83325,20.63946786,2.10464
14.64,60.99999,20.60798851,2.10143
14.68,61.16668,20.6112247,2.10176
14.72,61.33337,20.59886833,2.1005
14.76,61.49999,20.66006182,2.10674
14.8,61.66656,20.77578029,2.11854
14.84,61.8333,20.66516128,2.10726
14.88,62.00012,20.66712261,2.10746
14.92,62.16668,20.8076519,2.12179
14.96,62.33331,20.87325839,2.12848
15,62.49999,20.75714766,2.11664
15.04,62.66668,20.89453882,2.13065
15.08,62.83336,21.04144244,2.14563
15.12,63.00006,20.87982885,2.12915
15.16,63.16661,20.84403458,2.1255
15.2,63.3333,21.11205032,2.15283
15.24,63.49999,21.08174777,2.14974
15.28,63.66668,21.16549656,2.15828
15.32,63.83337,21.27994017,2.16995
15.36,64.00005,21.08596463,2.15017
15.4,64.16667,21.11342325,2.15297
15.44,64.33337,21.30730072,2.17274
15.48,64.50005,21.32446236,2.17449
15.52,64.66662,21.26817219,2.16875
15.56,64.83336,21.11263872,2.15289
15.6,65.00005,21.1422548,2.15591
15.64,65.16661,21.12626996,2.15428
15.68,65.3333,21.31524411,2.17355
15.72,65.50005,21.3574127,2.17785
15.76,65.66667,21.37594727,2.17974
15.8,65.8333,21.52853875,2.1953
15.84,65.99999,21.75418976,2.21831
15.88,66.16655,21.51353457,2.19377
15.92,66.33336,21.55285924,2.19778
15.96,66.50012,21.42252886,2.18449
16,66.66661,21.49450967,2.19183
16.04,66.83324,21.62327098,2.20496
16.08,66.99999,21.61944639,2.20457
16.12,67.16668,21.73134027,2.21598
16.16,67.33336,21.63700029,2.20636
16.2,67.50011,21.84882393,2.22796
16.24,67.66674,21.80900894,2.2239
16.28,67.83336,21.769292,2.21985
16.32,67.99993,21.91090003,2.23429
16.36,68.16655,21.92963073,2.2362
16.4,68.33337,21.97042639,2.24036
16.44,68.50012,22.0046516,2.24385
16.48,68.66661,22.00318061,2.2437
16.52,68.8333,22.03936714,2.24739
16.56,69.00011,21.82401311,2.22543
16.6,69.16668,22.13645298,2.25729
16.64,69.33337,22.09065592,2.25262
16.68,69.49999,22.2233399,2.26615
16.72,69.66655,22.40878365,2.28506
16.76,69.8333,22.2637433,2.27027
16.8,70.00005,22.21814237,2.26562
16.84,70.16668,22.35690647,2.27977
16.88,70.3333,22.37897143,2.28202
16.92,70.49999,22.36739959,2.28084
16.96,70.66661,22.35876973,2.27996
17,70.8333,22.46007243,2.29029
17.04,71.00006,22.38593415,2.28273
17.08,71.16668,22.55402014,2.29987
17.12,71.33331,22.53293584,2.29772
17.16,71.49999,22.61129097,2.30571
17.2,71.66661,22.76035205,2.32091
17.24,71.83337,22.60972191,2.30555
17.28,72.00005,22.61040837,2.30562
17.32,72.16662,22.70239475,2.315
17.36,72.3333,22.68562538,2.31329
17.4,72.50005,22.68797897,2.31353
17.44,72.66674,22.82174168,2.32717
17.48,72.83343,22.80546264,2.32551
17.52,73.00005,22.90323494,2.33548
17.56,73.16662,22.95521019,2.34078
17.6,73.3333,22.93657755,2.33888
17.64,73.50005,22.83586326,2.32861
17.68,73.66668,22.96589944,2.34187
17.72,73.83343,22.9645265,2.34173
17.76,74.00006,23.05798388,2.35126
17.8,74.16661,22.96560524,2.34184
17.84,74.3333,23.29226475,2.37515
17.88,74.50006,23.07573392,2.35307
17.92,74.66668,23.1413404,2.35976
17.96,74.83337,23.22636406,2.36843
18,75.00005,23.3410038,2.38012
18.04,75.16656,23.24793869,2.37063
18.08,75.3333,23.34796652,2.38083
18.12,75.50012,23.36610882,2.38268
18.16,75.66668,23.50869751,2.39722
18.2,75.83324,23.5769518,2.40418
18.24,75.99992,23.3614997,2.38221
18.28,76.16668,23.37160055,2.38324
18.32,76.33343,23.71748109,2.41851
18.36,76.49999,23.65442433,2.41208
18.4,76.66649,23.79436523,2.42635
18.44,76.83324,23.55459264,2.4019
18.48,77.00005,23.67894096,2.41458
18.52,77.16668,23.6556992,2.41221
18.56,77.33336,23.80544674,2.42748
18.6,77.50005,23.91018176,2.43816
18.64,77.66661,23.92979506,2.44016
18.68,77.83331,23.84486948,2.4315
18.72,78.00005,23.77700746,2.42458
18.76,78.16668,23.93891525,2.44109
18.8,78.33336,23.94372051,2.44158
18.84,78.50005,24.11366975,2.45891
18.88,78.66668,23.92528401,2.4397
18.92,78.83336,23.88890133,2.43599
18.96,79.00012,24.08130781,2.45561
19,79.16667,23.85644132,2.43268
19.04,79.3333,24.05041686,2.45246
19.08,79.49999,24.14416843,2.46202
19.12,79.66661,24.26498636,2.47434
19.16,79.83336,24.20938266,2.46867
19.2,80.00005,24.14416843,2.46202
19.24,80.16662,24.32323786,2.48028
19.28,80.3333,24.2815596,2.47603
19.32,80.49999,24.28989525,2.47688
19.36,80.66662,24.45003785,2.49321
19.4,80.83336,24.46759175,2.495
19.44,81.00005,24.53692477,2.50207
19.48,81.16661,24.51848826,2.50019
19.52,81.3333,24.69569443,2.51826
19.56,81.49998,24.81357036,2.53028
19.6,81.66661,24.75777052,2.52459
19.64,81.83336,24.71579806,2.52031
19.68,81.99998,24.58762515,2.50724
19.72,82.16655,24.57203257,2.50565
19.76,82.3333,24.71726906,2.52046
19.8,82.50011,24.95370739,2.54457
19.84,82.66673,24.64195399,2.51278
19.88,82.83329,24.8916313,2.53824
19.92,82.99999,24.92193384,2.54133
19.96,83.16661,25.05353909,2.55475
20,83.33342,25.16033351,2.56564
20.04,83.50012,25.06481674,2.5559
20.08,83.66661,25.0842339,2.55788
20.12,83.83323,25.16366777,2.56598
20.16,83.99999,25.27477711,2.57731
20.2,84.16668,25.17425895,2.56706
20.24,84.3333,25.24418036,2.57419
20.28,84.50005,25.12051851,2.56158
20.32,84.66667,25.30360866,2.58025
20.36,84.8333,25.3591143,2.58591
20.4,84.99992,25.24673009,2.57445
20.44,85.16661,25.51317677,2.60162
20.48,85.33336,25.2256458,2.5723
20.52,85.50005,25.44698189,2.59487
20.56,85.66661,25.46277059,2.59648
20.6,85.83331,25.50238946,2.60052
20.64,86.00005,25.54171412,2.60453
20.68,86.16667,25.59976949,2.61045
20.72,86.3333,25.48110903,2.59835
20.76,86.49998,25.42638792,2.59277
20.8,86.66655,25.50258559,2.60054
20.84,86.83329,25.65076407,2.61565
20.88,87.00011,25.93339173,2.64447
20.92,87.16667,25.95624122,2.6468
20.96,87.33337,25.76363861,2.62716
21,87.50005,25.85562499,2.63654
21.04,87.66661,25.88886953,2.63993
21.08,87.8333,25.9513379,2.6463
21.12,88.00011,25.86415678,2.63741
21.16,88.16668,25.92172181,2.64328
21.2,88.3333,26.09412272,2.66086
21.24,88.49998,25.92113341,2.64322
21.28,88.66668,25.9311362,2.64424
21.32,88.83336,26.17208559,2.66881
21.36,89.00011,26.19640608,2.67129
21.4,89.16655,26.0271433,2.65403
21.44,89.33323,26.20042681,2.6717
21.48,89.49999,26.22406083,2.67411
21.52,89.66668,26.16012147,2.66759
21.56,89.83336,26.29643391,2.68149
21.6,89.99999,26.31545881,2.68343
21.64,90.16655,26.32202927,2.6841
21.68,90.33323,26.38430149,2.69045
21.72,90.50005,26.4785434,2.70006
21.76,90.66674,26.37547551,2.68955
21.8,90.83336,26.59092761,2.71152
21.84,90.99999,26.67771646,2.72037
21.88,91.16654,26.44461239,2.6966
21.92,91.3333,26.67536286,2.72013
21.96,91.50005,26.71429527,2.7241
22,91.66667,26.64545258,2.71708
22.04,91.83336,26.8107927,2.73394
22.08,92.00005,26.68085459,2.72069
22.12,92.16655,26.66212389,2.71878
22.16,92.33336,26.91189926,2.74425
22.2,92.50017,26.71723726,2.7244
22.24,92.66668,26.83315186,2.73622
22.28,92.8333,26.85217676,2.73816
22.32,92.99998,26.88571551,2.74158
22.36,93.16674,26.86718094,2.73969
22.4,93.33342,27.13176436,2.76667
22.44,93.49999,27.12048671,2.76552
22.48,93.66655,27.15059312,2.76859
22.52,93.83329,27.28867076,2.78267
22.56,94.00005,27.2259082,2.77627
22.6,94.16667,27.15137766,2.76867
22.64,94.33337,27.21639575,2.7753
22.68,94.50004,27.31073572,2.78492
22.72,94.66661,27.14980859,2.76851
22.76,94.8333,27.36535876,2.79049
22.8,95.00004,27.30494979,2.78433
22.84,95.16668,27.25944694,2.77969
22.88,95.33335,27.48107723,2.80229
22.92,95.49998,27.27788344,2.78157
22.96,95.66661,27.45450121,2.79958
23,95.8333,27.66632485,2.82118
23.04,96.00011,27.59463824,2.81387
23.08,96.16661,27.55099864,2.80942
23.12,96.33323,27.40703702,2.79474
23.16,96.49992,27.44332163,2.79844
23.2,96.66667,27.70712051,2.82534
23.24,96.83336,27.70123652,2.82474
23.28,97.00004,27.82097572,2.83695
23.32,97.16661,27.89952698,2.84496
23.36,97.3333,27.89785985,2.84479
23.4,97.50005,27.83754896,2.83864
23.44,97.66674,27.72683188,2.82735
23.48,97.83336,27.86088878,2.84102
23.52,98.00005,27.96513347,2.85165
23.56,98.16667,28.10478017,2.86589
23.6,98.33336,28.08585333,2.86396
23.64,98.5001,28.3049339,2.8863
23.68,98.66667,28.07947901,2.86331
23.72,98.83337,27.8514744,2.84006
23.76,98.99999,28.18960769,2.87454
23.8,99.16661,28.0297593,2.85824
23.84,99.33336,28.28463413,2.88423
23.88,99.50011,28.21804698,2.87744
23.92,99.66668,28.49616357,2.9058
23.96,99.8333,28.40937472,2.89695
24,99.99998,28.31679994,2.88751
24.04,100.16661,28.42839962,2.89889
24.08,100.33336,28.34582763,2.89047
24.12,100.50011,28.49469257,2.90565
24.16,100.66655,28.54362776,2.91064
24.2,100.83323,28.56853665,2.91318
24.24,100.99999,28.62237516,2.91867
24.28,101.16661,28.46017316,2.90213
24.32,101.3333,28.66189596,2.9227
24.36,101.50004,28.69376757,2.92595
24.4,101.66667,28.61325497,2.91774
24.44,101.8333,28.75417653,2.93211
24.48,101.99992,28.78457715,2.93521
24.52,102.16661,28.77339757,2.93407
24.56,102.33336,28.83792532,2.94065
24.6,102.50011,28.72877731,2.92952
24.64,102.66662,28.8511643,2.942
24.68,102.8333,29.00365771,2.95755
24.72,103.0001,29.20969542,2.97856
24.76,103.16674,29.02719367,2.95995
24.8,103.33336,29.29432681,2.98719
24.84,103.49998,28.96580404,2.95369
24.88,103.66655,28.88215331,2.94516
24.92,103.8333,29.11005986,2.9684
24.96,104.00011,29.25706154,2.98339
25,104.16668,29.42907018,3.00093
25.04,104.3333,29.31815697,2.98962
25.08,104.49998,29.22607253,2.98023
25.12,104.66661,29.35924684,2.99381
25.16,104.83336,29.37876207,2.9958
25.2,105.00011,29.24146897,2.9818
25.24,105.16667,29.43456191,3.00149
25.28,105.33324,29.53812013,3.01205
25.32,105.49999,29.52086043,3.01029
25.36,105.66667,29.58656498,3.01699
25.4,105.83336,29.71826829,3.03042
25.44,106.00004,29.67335384,3.02584
25.48,106.16655,29.79564276,3.03831
25.52,106.33323,29.53351101,3.01158
25.56,106.50005,29.58666305,3.017
25.6,106.66667,29.63383304,3.02181
25.64,106.83335,29.83467323,3.04229
25.68,106.99999,29.93450493,3.05247
25.72,107.16654,29.82261105,3.04106
25.76,107.3333,29.96245388,3.05532
25.8,107.50011,30.02511837,3.06171
25.84,107.66674,29.97010307,3.0561
25.88,107.83336,30.03463082,3.06268
25.92,107.99998,30.06561984,3.06584
25.96,108.16661,30.19702895,3.07924
26,108.3333,30.06738503,3.06602
26.04,108.50005,30.10945556,3.07031
26.08,108.66667,30.44474493,3.1045
26.12,108.83336,30.35785801,3.09564
26.16,108.99998,30.22625276,3.08222
26.2,109.16654,30.29068245,3.08879
26.24,109.33336,30.25753598,3.08541
26.28,109.5001,30.6386224,3.12427
26.32,109.66667,30.28862306,3.08858
26.36,109.83324,30.45219798,3.10526
26.4,109.99999,30.46249496,3.10631
26.44,110.16673,30.50142736,3.11028
26.48,110.33342,30.72109632,3.13268
26.52,110.49992,30.58821621,3.11913
26.56,110.66649,30.66049123,3.1265
26.6,110.8333,30.69177444,3.12969
26.64,111.00005,30.72148859,3.13272
26.68,111.16668,30.60027839,3.12036
26.72,111.33336,30.66500228,3.12696
26.76,111.49999,30.73021651,3.13361
26.8,111.66655,30.71393747,3.13195
26.84,111.8333,30.95851532,3.15689
26.88,112.00011,30.94174595,3.15518
26.92,112.16667,30.82720428,3.1435
26.96,112.33336,31.09718135,3.17103
27,112.50004,31.10071174,3.17139
27.04,112.66667,30.92605531,3.15358
27.08,112.83342,31.03304586,3.16449
27.12,113.00005,31.20024924,3.18154
27.16,113.16661,31.09041476,3.17034
27.2,113.33324,31.13356402,3.17474
27.24,113.50005,31.20691776,3.18222
27.28,113.66667,31.39167505,3.20106
27.32,113.83336,31.30998565,3.19273
27.36,114.00005,31.27781984,3.18945
27.4,114.16661,31.21868574,3.18342
27.44,114.33329,31.33577714,3.19536
27.48,114.50005,31.41511294,3.20345
27.52,114.66661,31.44580776,3.20658
27.56,114.8333,31.54397232,3.21659
27.6,115.00005,31.60310642,3.22262
27.64,115.16668,31.46551912,3.20859
27.68,115.3333,31.47169731,3.20922
27.72,115.49998,31.70529172,3.23304
27.76,115.66667,31.4802291,3.21009
27.8,115.83329,31.58947518,3.22123
27.84,115.99999,31.78678498,3.24135
27.88,116.16655,31.59486884,3.22178
27.92,116.33329,31.6775389,3.23021
27.96,116.50004,31.81924499,3.24466
28,116.66667,31.73029867,3.23559
28.04,116.8333,31.82836517,3.24559
28.08,116.99999,31.88563601,3.25143
28.12,117.16668,32.01743739,3.26487
28.16,117.33342,31.9875271,3.26182
28.2,117.50011,31.82954197,3.24571
28.24,117.66661,31.94731984,3.25772
28.28,117.83324,31.77727253,3.24038
28.32,118.00005,31.98801744,3.26187
28.36,118.16667,31.97399393,3.26044
28.4,118.33336,31.98399671,3.26146
28.44,118.50011,32.22161184,3.28569
28.48,118.66667,32.19964494,3.28345
28.52,118.8333,32.11717102,3.27504
28.56,118.99993,32.15512275,3.27891
28.6,119.16667,32.15865315,3.27927
28.64,119.33336,32.24563813,3.28814
28.68,119.50005,32.25103179,3.28869
28.72,119.66655,32.26731083,3.29035
28.76,119.83329,32.22857456,3.2864
28.8,120.00011,32.31428468,3.29514
28.84,120.16667,32.00027575,3.26312
28.88,120.33329,31.98733097,3.2618
28.92,120.49999,32.07372756,3.27061
28.96,120.66655,32.28300147,3.29195
29,120.83337,32.03508936,3.26667
29.04,121.00005,32.08010188,3.27126
29.08,121.16667,32.13119453,3.27647
29.12,121.3333,31.99037103,3.26211
29.16,121.49998,32.04460181,3.26764
29.2,121.6666,32.27692134,3.29133
29.24,121.83336,32.05686012,3.26889
29.28,122.00011,32.14423737,3.2778
29.32,122.16668,31.92417614,3.25536
29.36,122.3333,31.90417058,3.25332
29.4,122.50005,31.67322397,3.22977
29.44,122.66673,31.51484657,3.21362
29.48,122.83336,31.07001693,3.16826
29.52,123.00004,30.74061156,3.13467
29.56,123.16661,12.70196535,1.29524
29.6,123.3333,-2.38527148,-0.24323
29.64,123.50012,-1.30261732,-0.13283
29.68,123.66674,-1.163166757,-0.11861
29.72,123.83336,-1.032836378,-0.10532
29.76,123.99998,-1.013223078,-0.10332
29.8,124.16654,-0.836997578,-0.08535
29.84,124.3333,-1.202393357,-0.12261
29.88,124.50005,-1.072259111,-0.10934
29.92,124.66673,-0.944674595,-0.09633
29.96,124.83336,-0.970368018,-0.09895
30,124.99998,-0.997140172,-0.10168
30.04,125.16654,-0.987137389,-0.10066
30.08,125.33329,-1.090597547,-0.11121
30.12,125.50004,-1.098050601,-0.11197
30.16,125.66666,-0.969975752,-0.09891
30.2,125.83335,-1.187879515,-0.12113
30.24,125.99992,-1.161793826,-0.11847
30.28,126.16654,-1.00420096,-0.1024
30.32,126.33336,-1.113839307,-0.11358
30.36,126.50016,-1.261723589,-0.12866
30.4,126.6666,-1.046075356,-0.10667
30.44,126.83324,-1.281140756,-0.13064
30.48,127.00004,-0.929376221,-0.09477
30.52,127.1668,-1.027442721,-0.10477
30.56,127.33336,-1.185427852,-0.12088
30.6,127.49991,-1.064806057,-0.10858
30.64,127.66654,-1.075495306,-0.10967
30.68,127.83336,-1.248386545,-0.1273
30.72,128.0001,-1.234657235,-0.1259
30.76,128.16667,-1.031365381,-0.10517
30.8,128.33335,-1.063825392,-0.10848
30.84,128.49999,-1.05519554,-0.1076
30.88,128.66661,-1.014596009,-0.10346
30.92,128.83335,-1.180034195,-0.12033
30.96,129.00004,-1.052940011,-0.10737
31,129.16661,-1.091970478,-0.11135
31.04,129.33329,-1.033718977,-0.10541
31.08,129.49998,-1.236226299,-0.12606
31.12,129.6666,-1.103934591,-0.11257
31.16,129.83336,-1.062256328,-0.10832
31.2,130.00004,-1.233774637,-0.12581
31.24,130.16661,-1.120900095,-0.1143
31.28,130.3333,-1.055685873,-0.10765
31.32,130.49997,-1.135512004,-0.11579
31.36,130.66666,-1.164147422,-0.11871
31.4,130.83336,-1.194548037,-0.12181
31.44,131.00005,-1.257114464,-0.12819
31.48,131.16661,-1.285063416,-0.13104
31.52,131.33324,-1.190723443,-0.12142
31.56,131.49998,-1.167187483,-0.11902
31.6,131.66666,-1.082261894,-0.11036
31.64,131.83336,-1.191409909,-0.12149
31.68,132.00005,-1.244954218,-0.12695
31.72,132.16661,-1.154144639,-0.11769
31.76,132.33329,-0.944086196,-0.09627
31.8,132.5001,-1.13561007,-0.1158
31.84,132.66667,-1.030875048,-0.10512
31.88,132.83335,-1.19278284,-0.12163
31.92,132.99997,-1.057843336,-0.10787
31.96,133.1666,-1.201510758,-0.12252
31.972,133.21667,-1.193959638,-0.12175