File: V_8/NR/RDSO NR Tensile 250.is_tens_RawData/Specimen_RawData_4.csv
Time,Extension,Load,
(sec),(mm),(N),(kgf)
0,0,-1.131393211,-0.11537
0.04,0.06762,-0.625468137,-0.06378
0.08,0.2775,-0.248598578,-0.02535
0.12,0.48287,-0.0588399,-0.006
0.16,0.65537,0.058741834,0.00599
0.2,0.82406,0.997924704,0.10176
0.24,0.99475,1.06921905,0.10903
0.28,1.16387,1.008613953,0.10285
0.32,1.33169,1.385973845,0.14133
0.36,1.499,1.70861263,0.17423
0.4,1.666,1.95181755,0.19903
0.44,1.83287,2.335453698,0.23815
0.48,1.99981,2.707616065,0.2761
0.52,2.16662,2.722227974,0.27759
0.56,2.33337,3.076444172,0.31371
0.6,2.5,3.329455742,0.33951
0.64,2.66656,3.727213466,0.38007
0.68,2.83331,3.570503199,0.36409
0.72,3.00006,3.933937648,0.40115
0.76,3.16669,3.923248399,0.40006
0.8,3.33331,4.289526777,0.43741
0.84,3.5,4.310316875,0.43953
0.88,3.66656,4.769562294,0.48636
0.92,3.83337,4.83663978,0.4932
0.96,4.00012,5.229592246,0.53327
1,4.16669,5.259796728,0.53635
1.04,4.33331,5.377084262,0.54831
1.08,4.5,5.455831661,0.55634
1.12,4.66669,5.76434887,0.5878
1.16,4.83344,5.763564338,0.58772
1.2,5.00006,6.137982235,0.6259
1.24,5.16662,6.163185326,0.62847
1.28,5.33325,6.162400794,0.62839
1.32,5.5,6.570945833,0.67005
1.36,5.66669,6.496807559,0.66249
1.4,5.83337,6.628314735,0.6759
1.44,6.00006,6.792281923,0.69262
1.48,6.16662,6.880934039,0.70166
1.52,6.33331,7.116195573,0.72565
1.56,6.5,7.258293931,0.74014
1.6,6.66662,7.173466409,0.73149
1.64,6.83337,7.534056929,0.76826
1.68,7.00012,7.459134123,0.76062
1.72,7.16662,7.589758701,0.77394
1.76,7.33325,7.590445167,0.77401
1.8,7.50006,7.799621011,0.79534
1.84,7.66675,8.235330471,0.83977
1.88,7.83337,8.247490717,0.84101
1.92,8,8.249844313,0.84125
1.96,8.16656,8.315156602,0.84791
2,8.33344,8.466865477,0.86338
2.04,8.50019,8.558753788,0.87275
2.08,8.66656,8.524626646,0.86927
2.12,8.83319,8.649269167,0.88198
2.16,9,8.758319115,0.8931
2.2,9.16669,8.949254591,0.91257
2.24,9.33337,8.900221341,0.90757
2.28,9.50012,9.051636017,0.92301
2.32,9.66662,9.144406926,0.93247
2.36,9.83325,9.253947206,0.94364
2.4,10,9.350444642,0.95348
2.44,10.16669,9.33789213,0.9522
2.48,10.33337,9.398791427,0.95841
2.52,10.5,9.525493345,0.97133
2.56,10.66656,9.849701194,1.00439
2.6,10.83331,9.696913587,0.98881
2.64,11.00006,9.644938342,0.98351
2.68,11.16669,9.972284319,1.01689
2.72,11.33337,9.799589212,0.99928
2.76,11.5,10.02631896,1.0224
2.8,11.66656,10.21352791,1.04149
2.84,11.83337,10.29531537,1.04983
2.88,12.00012,10.37651443,1.05811
2.92,12.16669,10.039656,1.02376
2.96,12.33331,10.44496485,1.06509
3,12.5,10.64649151,1.08564
3.04,12.66669,10.70425267,1.09153
3.08,12.83331,10.72857317,1.09401
3.12,13.00006,10.80653603,1.10196
3.16,13.16662,10.7870208,1.09997
3.2,13.33331,11.02679339,1.12442
3.24,13.50006,11.00119804,1.12181
3.28,13.66668,11.01983067,1.12371
3.32,13.83337,11.14231573,1.1362
3.36,14.00012,11.12593862,1.13453
3.4,14.16662,11.16035997,1.13804
3.44,14.33331,11.34845151,1.15722
3.48,14.50006,11.46985784,1.1696
3.52,14.66669,11.53958312,1.17671
3.56,14.83337,11.73944265,1.19709
3.6,15.00006,11.62127252,1.18504
3.64,15.16662,11.91311842,1.2148
3.68,15.33331,11.90752863,1.21423
3.72,15.50012,11.66246045,1.18924
3.76,15.66675,11.87438215,1.21085
3.8,15.83331,12.04786179,1.22854
3.84,15.99994,12.03785901,1.22752
3.88,16.16662,11.99873047,1.22353
3.92,16.33337,12.21075025,1.24515
3.96,16.50006,12.2556647,1.24973
4,16.66668,12.23614947,1.24774
4.04,16.83337,12.4749414,1.27209
4.08,17.00006,12.37913043,1.26232
4.12,17.16656,12.22418536,1.24652
4.16,17.33331,12.35451574,1.25981
4.2,17.50012,12.38099369,1.26251
4.24,17.66669,12.47327427,1.27192
4.28,17.83331,12.63351493,1.28826
4.32,18,12.58987534,1.28381
4.36,18.16669,12.55643466,1.2804
4.4,18.33337,12.64979397,1.28992
4.44,18.50006,12.52623018,1.27732
4.48,18.66662,12.6886283,1.29388
4.52,18.83325,12.78081081,1.30328
4.56,19.00006,12.87632758,1.31302
4.6,19.16668,12.70883,1.29594
4.64,19.33337,12.87848505,1.31324
4.68,19.5,12.98645626,1.32425
4.72,19.66662,13.00763863,1.32641
4.76,19.83331,12.92830283,1.31832
4.8,20.00006,12.93918821,1.31943
4.84,20.16668,13.04058897,1.32977
4.88,20.33337,12.93565782,1.31907
4.92,20.5,13.14257813,1.34017
4.96,20.66662,13.04323677,1.33004
5,20.83331,12.99645905,1.32527
5.04,21.00006,13.17052708,1.34302
5.08,21.16662,13.31164478,1.35741
5.12,21.33325,13.23466257,1.34956
5.16,21.5,13.23554517,1.34965
5.2,21.66662,13.25339328,1.35147
5.24,21.83337,13.39205931,1.36561
5.28,22.00012,13.37548607,1.36392
5.32,22.16662,13.47914236,1.37449
5.36,22.33325,13.54151265,1.38085
5.4,22.5,13.42059666,1.36852
5.44,22.66668,13.42324445,1.36879
5.48,22.83337,13.51640763,1.37829
5.52,23.00006,13.53758999,1.38045
5.56,23.16662,13.51071977,1.37771
5.6,23.33325,13.58681938,1.38547
5.64,23.5,13.83296629,1.41057
5.68,23.66669,13.68361101,1.39534
5.72,23.83337,13.71626716,1.39867
5.76,24.00006,13.75549376,1.40267
5.8,24.16662,13.54141459,1.38084
5.84,24.33325,13.77589159,1.40475
5.88,24.50006,13.79236676,1.40643
5.92,24.66675,13.70038038,1.39705
5.96,24.83337,13.74617744,1.40172
6,24.99993,13.83414309,1.41069
6.04,25.16662,13.98447903,1.42602
6.08,25.33343,13.87837108,1.4152
6.12,25.50012,13.99467795,1.42706
6.16,25.6665,13.89533658,1.41693
6.2,25.83318,14.05263525,1.43297
6.24,26,14.13177492,1.44104
6.28,26.16668,14.21444498,1.44947
6.32,26.33343,14.05047779,1.43275
6.36,26.50006,14.04184794,1.43187
6.4,26.66662,14.2369022,1.45176
6.44,26.83331,14.03027609,1.43069
6.48,27.00006,14.05567531,1.43328
6.52,27.16668,14.25288704,1.45339
6.56,27.33337,14.24425719,1.45251
6.6,27.50006,14.23278341,1.45134
6.64,27.66662,14.17904297,1.44586
6.68,27.83331,14.47059467,1.47559
6.72,28.00006,14.1605084,1.44397
6.76,28.16668,14.40773405,1.46918
6.8,28.33331,14.35340521,1.46364
6.84,28.5,14.42038463,1.47047
6.88,28.66662,14.65162543,1.49405
6.92,28.83337,14.34399082,1.46268
6.96,29.00006,14.42538602,1.47098
7,29.16669,14.66849287,1.49577
7.04,29.33337,14.50962514,1.47957
7.08,29.5,14.51050774,1.47966
7.12,29.66662,14.8493275,1.51421
7.16,29.83331,14.71330926,1.50034
7.2,30.00006,14.48795244,1.47736
7.24,30.16668,14.80058845,1.50924
7.28,30.33331,14.72497917,1.50153
7.32,30.50006,14.94052934,1.52351
7.36,30.66662,14.86384134,1.51569
7.4,30.83337,14.61230077,1.49004
7.44,31.00006,14.97838301,1.52737
7.48,31.16662,14.75557592,1.50465
7.52,31.33325,14.93062463,1.5225
7.56,31.50006,15.02712206,1.53234
7.6,31.66668,14.84599324,1.51387
7.64,31.83337,15.0820393,1.53794
7.68,31.99999,15.16912235,1.54682
7.72,32.16656,15.15117618,1.54499
7.76,32.33331,15.13685847,1.54353
7.8,32.50012,15.15402011,1.54528
7.84,32.66668,15.34789758,1.56505
7.88,32.83324,15.28072203,1.5582
7.92,33,15.13989854,1.54384
7.96,33.16668,15.06203374,1.5359
8,33.33337,15.13185708,1.54302
8.04,33.50006,15.24983108,1.55505
8.08,33.66668,15.48254289,1.57878
8.12,33.83337,15.33799287,1.56404
8.16,34.00006,15.53187034,1.58381
8.2,34.16656,15.41732866,1.57213
8.24,34.33331,15.48332742,1.57886
8.28,34.50006,15.65337473,1.5962
8.32,34.66662,15.51696423,1.58229
8.36,34.83331,15.48705395,1.57924
8.4,34.99999,15.28062396,1.55819
8.44,35.16668,15.67720489,1.59863
8.48,35.33337,15.72388454,1.60339
8.52,35.49999,15.6888748,1.59982
8.56,35.66656,15.63621309,1.59445
8.6,35.83324,15.44184529,1.57463
8.64,35.99999,15.8109676,1.61227
8.68,36.16668,15.72506134,1.60351
8.72,36.33337,15.90442497,1.6218
8.76,36.50006,15.84823287,1.61607
8.8,36.66662,15.79086396,1.61022
8.84,36.83331,15.9866047,1.63018
8.88,37.00006,16.06819603,1.6385
8.92,37.16668,15.99091962,1.63062
8.96,37.33337,15.97140439,1.62863
9,37.49999,15.93296232,1.62471
9.04,37.66662,16.01690725,1.63327
9.08,37.83337,16.07103995,1.63879
9.12,38.00012,16.02955782,1.63456
9.16,38.16668,16.02867523,1.63447
9.2,38.33324,16.20774465,1.65273
9.24,38.5,16.2383414,1.65585
9.28,38.66668,16.38191076,1.67049
9.32,38.83349,16.28276553,1.66038
9.36,39.00012,16.32728772,1.66492
9.4,39.16656,16.3569038,1.66794
9.44,39.33324,16.20558719,1.65251
9.48,39.49999,16.38240109,1.67054
9.52,39.66668,16.42280449,1.67466
9.56,39.83337,16.54460308,1.68708
9.6,40.00005,16.52126326,1.6847
9.64,40.16655,16.61383803,1.69414
9.68,40.33324,16.70062688,1.70299
9.72,40.50006,16.68013099,1.7009
9.76,40.66668,16.6508091,1.69791
9.8,40.83337,16.52165552,1.68474
9.84,40.99999,16.72887004,1.70587
9.88,41.16655,16.7322043,1.70621
9.92,41.33324,16.81203043,1.71435
9.96,41.50006,16.76152618,1.7092
10,41.66674,16.80359671,1.71349
10.04,41.83331,16.70258821,1.70319
10.08,41.99999,17.03483752,1.73707
10.12,42.16668,16.8844035,1.72173
10.16,42.33343,17.08740116,1.74243
10.2,42.50012,17.16585436,1.75043
10.24,42.66656,16.80340058,1.71347
10.28,42.83324,17.09044122,1.74274
10.32,42.99999,17.12074377,1.74583
10.36,43.16668,17.28578969,1.76266
10.4,43.33337,17.14329906,1.74813
10.44,43.50012,17.26382279,1.76042
10.48,43.66668,17.20517903,1.75444
10.52,43.83331,17.1788972,1.75176
10.56,44.00006,17.24283656,1.75828
10.6,44.16668,17.42847645,1.77721
10.64,44.33337,17.26097886,1.76013
10.68,44.50005,17.38454265,1.77273
10.72,44.66656,17.28873168,1.76296
10.76,44.83331,17.27912117,1.76198
10.8,45.00006,17.58724611,1.7934
10.84,45.16668,17.41710073,1.77605
10.88,45.3333,17.4728025,1.78173
10.92,45.49999,17.53389793,1.78796
10.96,45.66655,17.5732226,1.79197
11,45.83331,17.73944532,1.80892
11.04,46.00006,17.75248816,1.81025
11.08,46.16662,17.53870319,1.78845
11.12,46.3333,17.75543016,1.81055
11.16,46.49993,17.71179057,1.8061
11.2,46.66662,17.78563464,1.81363
11.24,46.83337,17.68619521,1.80349
11.28,47.00012,17.86045938,1.82126
11.32,47.16668,17.81642752,1.81677
11.36,47.33331,17.86526464,1.82175
11.4,47.50005,18.04403987,1.83998
11.44,47.66668,17.90615837,1.82592
11.48,47.83337,17.81024933,1.81614
11.52,48.00005,18.11768781,1.84749
11.56,48.16662,18.11121542,1.84683
11.6,48.3333,18.09983971,1.84567
11.64,48.50012,18.27253481,1.86328
11.68,48.66675,18.28292986,1.86434
11.72,48.83337,18.23566181,1.85952
11.76,48.99999,18.09993777,1.84568
11.8,49.16662,18.15877767,1.85168
11.84,49.33337,18.27106381,1.86313
11.88,49.50012,18.33971036,1.87013
11.92,49.66662,18.4730808,1.88373
11.96,49.83325,18.26380689,1.86239
12,49.99999,18.44179759,1.88054
12.04,50.16668,18.42836248,1.87917
12.08,50.33331,18.58115009,1.89475
12.12,50.50005,18.73884102,1.91083
12.16,50.66668,18.50514855,1.887
12.2,50.83337,18.55741799,1.89233
12.24,50.99999,18.48259326,1.8847
12.28,51.16655,18.66695828,1.9035
12.32,51.33331,18.8492639,1.92209
12.36,51.50005,18.81935362,1.91904
12.4,51.66662,18.85534402,1.92271
12.44,51.83324,18.76600544,1.9136
12.48,51.99999,18.72354265,1.90927
12.52,52.16668,18.87642832,1.92486
12.56,52.33343,19.18818172,1.95665
12.6,52.50006,19.22093593,1.95999
12.64,52.66662,18.86475841,1.92367
12.68,52.83331,18.86985786,1.92419
12.72,53.00005,19.03539412,1.94107
12.76,53.16674,19.05510548,1.94308
12.8,53.33337,19.06608893,1.9442
12.84,53.49999,19.01176009,1.93866
12.88,53.66662,19.21201188,1.95908
12.92,53.8333,19.24025503,1.96196
12.96,54.00012,19.12973409,1.95069
13,54.16668,19.21809201,1.9597
13.04,54.3333,19.08246604,1.94587
13.08,54.49999,19.33508534,1.97163
13.12,54.66662,19.32282703,1.97038
13.16,54.83337,19.52582468,1.99108
13.2,55.00012,19.31311844,1.96939
13.24,55.16662,19.48179282,1.98659
13.28,55.33325,19.35244311,1.9734
13.32,55.49999,19.61016187,1.99968
13.36,55.66668,19.39892663,1.97814
13.4,55.83337,19.59054857,1.99768
13.44,56.00005,19.82796757,2.02189
13.48,56.16656,19.69802946,2.00864
13.52,56.33324,19.67341476,2.00613
13.56,56.50006,19.69950045,2.00879
13.6,56.66668,19.85415132,2.02456
13.64,56.83336,19.84522727,2.02365
13.68,57.00005,19.76177268,2.01514
13.72,57.16662,19.72372288,2.01126
13.76,57.3333,19.85748559,2.0249
13.8,57.50006,19.95584628,2.03493
13.84,57.66668,20.02890583,2.04238
13.88,57.83337,19.95614048,2.03496
13.92,58.00006,20.02831743,2.04232
13.96,58.16655,20.15629421,2.05537
14,58.33324,20.13422925,2.05312
14.04,58.50011,20.0649943,2.04606
14.08,58.66674,20.00232981,2.03967
14.12,58.8333,20.281329,2.06812
14.16,58.99993,20.19679568,2.0595
14.2,59.16668,20.1048093,2.05012
14.24,59.33343,20.38184716,2.07837
14.28,59.50006,20.39557647,2.07977
14.32,59.66655,20.27721021,2.0677
14.36,59.83324,20.35360401,2.07549
14.4,60.00006,20.47559873,2.08793
14.44,60.16668,20.39283061,2.07949
14.48,60.33343,20.48736671,2.08913
14.52,60.50006,20.30868955,2.07091
14.56,60.66662,20.45412217,2.08574
14.6,60.83325,20.6132841,2.10197
14.64,61.00005,20.7538134,2.1163
14.68,61.16668,20.66574968,2.10732
14.72,61.33337,20.71331193,2.11217
14.76,61.49999,21.00211777,2.14162
14.8,61.66662,20.64682284,2.10539
14.84,61.8333,20.72292245,2.11315
14.88,62.00012,21.01594515,2.14303
14.92,62.16668,20.84207325,2.1253
14.96,62.33331,20.89228329,2.13042
15,62.49999,20.94445467,2.13574
15.04,62.66668,21.12136664,2.15378
15.08,62.83336,20.96083178,2.13741
15.12,63.00006,21.05634855,2.14715
15.16,63.16661,21.01859295,2.1433
15.2,63.3333,20.96122404,2.13745
15.24,63.49999,21.1252893,2.15418
15.28,63.66668,21.05683888,2.1472
15.32,63.83337,21.14480453,2.15617
15.36,64.00005,21.16353523,2.15808
15.4,64.16667,21.36280636,2.1784
15.44,64.33337,21.37006328,2.17914
15.48,64.50005,21.16824242,2.15856
15.52,64.66662,21.36672902,2.1788
15.56,64.83336,21.54109126,2.19658
15.6,65.00005,21.40536722,2.18274
15.64,65.16661,21.48823341,2.19119
15.68,65.3333,21.32485462,2.17453
15.72,65.50005,21.62013286,2.20464
15.76,65.66667,21.64288428,2.20696
15.8,65.8333,21.55178051,2.19767
15.84,65.99999,21.61052234,2.20366
15.88,66.16655,21.64896441,2.20758
15.92,66.33336,21.65357353,2.20805
15.96,66.50012,21.71751289,2.21457
16,66.66661,21.8714773,2.23027
16.04,66.83324,21.78576717,2.22153
16.08,66.99999,21.96768053,2.24008
16.12,67.16668,21.81469679,2.22448
16.16,67.33336,22.06594317,2.2501
16.2,67.50011,21.96493467,2.2398
16.24,67.66674,21.87716515,2.23085
16.28,67.83336,22.06849289,2.25036
16.32,67.99993,22.14037564,2.25769
16.36,68.16655,22.083399,2.25188
16.4,68.33337,22.26276263,2.27017
16.44,68.50012,22.22196697,2.26601
16.48,68.66661,22.29865497,2.27383
16.52,68.8333,22.26658722,2.27056
16.56,69.00005,22.1639116,2.26009
16.6,69.16674,22.09801091,2.25337
16.64,69.33337,22.05721525,2.24921
16.68,69.49999,22.15449721,2.25913
16.72,69.66655,22.42143423,2.28635
16.76,69.8333,22.31611081,2.27561
16.8,70.00005,22.37063578,2.28117
16.84,70.16668,22.40652812,2.28483
16.88,70.3333,22.52401179,2.29681
16.92,70.49999,22.57686963,2.3022
16.96,70.66661,22.38514962,2.28265
17,70.8333,22.56019833,2.3005
17.04,71.00006,22.69062677,2.3138
17.08,71.16668,22.68209498,2.31293
17.12,71.33331,22.7136724,2.31615
17.16,71.49999,22.7127898,2.31606
17.2,71.66661,22.86341994,2.33142
17.24,71.83337,22.75760619,2.32063
17.28,72.00005,22.97845195,2.34315
17.32,72.16667,22.88430811,2.33355
17.36,72.3333,22.81556349,2.32654
17.4,72.50005,22.99953625,2.3453
17.44,72.66674,22.94834553,2.34008
17.48,72.83343,22.94422674,2.33966
17.52,73.00005,23.16615123,2.36229
17.56,73.16662,23.15212772,2.36086
17.6,73.3333,23.03081946,2.34849
17.64,73.50005,23.05141342,2.35059
17.68,73.66668,23.06053361,2.35152
17.72,73.83343,23.21773421,2.36755
17.76,74.00006,23.23469971,2.36928
17.8,74.16661,23.39415584,2.38554
17.84,74.3333,23.24833096,2.37067
17.88,74.50006,23.36287263,2.38235
17.92,74.66668,23.50163673,2.3965
17.96,74.83337,23.47300131,2.39358
18,74.99999,23.39356744,2.38548
18.04,75.16649,23.63745883,2.41035
18.08,75.3333,23.7151275,2.41827
18.12,75.50012,23.60646981,2.40719
18.16,75.66668,23.43838383,2.39005
18.2,75.83324,23.75415796,2.42225
18.24,75.99992,23.75268697,2.4221
18.28,76.16668,23.63216324,2.40981
18.32,76.33343,23.51046271,2.3974
18.36,76.49999,23.80211248,2.42714
18.4,76.66649,23.8081926,2.42776
18.44,76.83324,23.7894619,2.42585
18.48,77.00005,23.77063313,2.42393
18.52,77.16668,23.86801317,2.43386
18.56,77.33336,23.84810567,2.43183
18.6,77.50005,23.93391386,2.44058
18.64,77.66661,24.09709651,2.45722
18.68,77.83331,24.04600387,2.45201
18.72,78.00005,24.0637539,2.45382
18.76,78.16668,24.08944733,2.45644
18.8,78.33336,24.10994322,2.45853
18.84,78.50005,24.31549061,2.47949
18.88,78.66668,24.11955374,2.45951
18.92,78.83336,24.27969634,2.47584
18.96,79.00012,24.33784977,2.48177
19,79.16667,24.34088983,2.48208
19.04,79.3333,24.19575141,2.46728
19.08,79.49999,24.34255696,2.48225
19.12,79.66661,24.38345069,2.48642
19.16,79.83336,24.41473391,2.48961
19.2,80.00005,24.31500028,2.47944
19.24,80.16662,24.46190389,2.49442
19.28,80.3333,24.49593297,2.49789
19.32,80.49999,24.46053096,2.49428
19.36,80.66662,24.60311965,2.50882
19.4,80.8333,24.55859746,2.50428
19.44,81.00005,24.63538353,2.51211
19.48,81.16661,24.83592952,2.53256
19.52,81.3333,24.77659929,2.52651
19.56,81.49998,24.68422065,2.51709
19.6,81.66661,24.95900298,2.54511
19.64,81.83336,24.94046841,2.54322
19.68,81.99998,24.95704165,2.54491
19.72,82.16655,24.83563532,2.53253
19.76,82.33336,24.90251668,2.53935
19.8,82.50011,24.88182465,2.53724
19.84,82.66673,24.8881009,2.53788
19.88,82.83329,24.99773925,2.54906
19.92,82.99999,25.20387503,2.57008
19.96,83.16661,25.26840279,2.57666
20,83.33342,25.13630721,2.56319
20.04,83.50012,25.13669948,2.56323
20.08,83.66661,25.07177946,2.55661
20.12,83.83323,25.22868586,2.57261
20.16,83.99999,25.35126898,2.58511
20.2,84.16668,25.24996629,2.57478
20.24,84.3333,25.2836031,2.57821
20.28,84.50005,25.42334786,2.59246
20.32,84.66662,25.49277894,2.59954
20.36,84.8333,25.46963525,2.59718
20.4,84.99992,25.51199998,2.6015
20.44,85.16655,25.48816982,2.59907
20.48,85.33336,25.42324979,2.59245
20.52,85.50012,25.30949265,2.58085
20.56,85.66661,25.68381248,2.61902
20.6,85.83331,25.61899053,2.61241
20.64,86.00005,25.72853081,2.62358
20.68,86.16667,25.77540659,2.62836
20.72,86.3333,25.71342857,2.62204
20.76,86.49998,25.74324078,2.62508
20.8,86.66655,25.87602282,2.63862
20.84,86.83329,25.76471735,2.62727
20.88,87.00011,25.91132676,2.64222
20.92,87.16667,25.91495522,2.64259
20.96,87.33337,25.89975492,2.64104
21,87.50005,26.10334097,2.6618
21.04,87.66661,26.08529673,2.65996
21.08,87.83337,26.04724693,2.65608
21.12,88.00011,26.04097068,2.65544
21.16,88.16668,26.05832845,2.65721
21.2,88.3333,26.05528839,2.6569
21.24,88.49998,26.35978487,2.68795
21.28,88.66668,26.32712872,2.68462
21.32,88.83336,26.39538301,2.69158
21.36,89.00011,26.34075997,2.68601
21.4,89.16661,26.37155285,2.68915
21.44,89.33323,26.47805307,2.70001
21.48,89.49999,26.61073704,2.71354
21.52,89.66668,26.52502692,2.7048
21.56,89.83342,26.35184148,2.68714
21.6,89.99999,26.59896906,2.71234
21.64,90.16655,26.43794387,2.69592
21.68,90.33323,26.48481966,2.7007
21.72,90.50005,26.61044284,2.71351
21.76,90.66674,26.82658141,2.73555
21.8,90.83336,26.65065011,2.71761
21.84,90.99999,26.72135605,2.72482
21.88,91.16654,26.78862967,2.73168
21.92,91.3333,26.94082888,2.7472
21.96,91.50005,26.793533,2.73218
22,91.66667,26.9489684,2.74803
22.04,91.83336,27.02614674,2.7559
22.08,92.00005,26.88993237,2.74201
22.12,92.16661,26.94259408,2.74738
22.16,92.33336,27.04889816,2.75822
22.2,92.50011,27.12244804,2.76572
22.24,92.66668,27.22247587,2.77592
22.28,92.8333,27.05997968,2.75935
22.32,92.99998,27.14794533,2.76832
22.36,93.16674,27.01271162,2.75453
22.4,93.33342,27.2826887,2.78206
22.44,93.49999,27.2434621,2.77806
22.48,93.66655,27.35398304,2.78933
22.52,93.83329,27.31259898,2.78511
22.56,94.00005,27.20609876,2.77425
22.6,94.16667,27.43969317,2.79807
22.64,94.33337,27.19609598,2.77323
22.68,94.50004,27.22247587,2.77592
22.72,94.66661,27.34702032,2.78862
22.76,94.83323,27.58012439,2.81239
22.8,95.00004,27.48382309,2.80257
22.84,95.16668,27.60160096,2.81458
22.88,95.33335,27.41233261,2.79528
22.92,95.49998,27.49686594,2.8039
22.96,95.66661,27.56149176,2.81049
23,95.8333,27.82019119,2.83687
23.04,96.00011,27.80155855,2.83497
23.08,96.16661,27.9109027,2.84612
23.12,96.33323,27.77988585,2.83276
23.16,96.49992,27.85490673,2.84041
23.2,96.66661,27.98513904,2.85369
23.24,96.83336,28.04535187,2.85983
23.28,97.00011,27.88462088,2.84344
23.32,97.16661,27.83058623,2.83793
23.36,97.3333,28.19519748,2.87511
23.4,97.50005,28.04711707,2.86001
23.44,97.66674,28.07908675,2.86327
23.48,97.83342,27.9691542,2.85206
23.52,98.00005,28.18901929,2.87448
23.56,98.16667,28.27394488,2.88314
23.6,98.33336,28.24717273,2.88041
23.64,98.5001,28.39084015,2.89506
23.68,98.66667,28.46144803,2.90226
23.72,98.83337,28.16175681,2.8717
23.76,98.99999,28.41319931,2.89734
23.8,99.16661,28.55353247,2.91165
23.84,99.33336,28.63061274,2.91951
23.88,99.50011,28.45546597,2.90165
23.92,99.66668,28.35955694,2.89187
23.96,99.8333,28.53352691,2.90961
24,99.99998,28.59432814,2.91581
24.04,100.16661,28.85106623,2.94199
24.08,100.33336,28.44507092,2.90059
24.12,100.50011,28.49449644,2.90563
24.16,100.66655,28.69327724,2.9259
24.2,100.8333,28.92363544,2.94939
24.24,100.99999,28.69651343,2.92623
24.28,101.16667,28.70494715,2.92709
24.32,101.33336,28.81595843,2.93841
24.36,101.50004,28.84204412,2.94107
24.4,101.66667,29.07171586,2.96449
24.44,101.8333,29.14379474,2.97184
24.48,101.99992,29.12104331,2.96952
24.52,102.16661,28.95423219,2.95251
24.56,102.33336,29.10427394,2.96781
24.6,102.50011,29.11113859,2.96851
24.64,102.66662,29.06230147,2.96353
24.68,102.8333,29.03778485,2.96103
24.72,103.0001,29.12271044,2.96969
24.76,103.16674,29.19263185,2.97682
24.8,103.33336,29.29756301,2.98752
24.84,103.49998,29.27912651,2.98564
24.88,103.66655,29.33826061,2.99167
24.92,103.8333,29.48663522,3.0068
24.96,104.00011,29.58097519,3.01642
25,104.16668,29.63138137,3.02156
25.04,104.3333,29.60176529,3.01854
25.08,104.49998,29.63196977,3.02162
25.12,104.66655,29.65050434,3.02351
25.16,104.83336,29.74768824,3.03342
25.2,105.00005,29.70306799,3.02887
25.24,105.16667,29.77426426,3.03613
25.28,105.33324,29.73631253,3.03226
25.32,105.49999,29.75004184,3.03366
25.36,105.66667,29.86360285,3.04524
25.4,105.83336,29.77906952,3.03662
25.44,106.00004,29.8921402,3.04815
25.48,106.16655,29.89910292,3.04886
25.52,106.33323,29.91695102,3.05068
25.56,106.50005,29.98177298,3.05729
25.6,106.66667,30.03247336,3.06246
25.64,106.83335,30.13416832,3.07283
25.68,106.99999,30.12926499,3.07233
25.72,107.16654,30.0267855,3.06188
25.76,107.3333,30.17741565,3.07724
25.8,107.50011,30.21644611,3.08122
25.84,107.66674,30.23164642,3.08277
25.88,107.83336,29.99981721,3.05913
25.92,108.00004,30.21723065,3.0813
25.96,108.16661,30.0856254,3.06788
26,108.3333,30.22036877,3.08162
26.04,108.50005,30.27028462,3.08671
26.08,108.66667,30.31627781,3.0914
26.12,108.83336,30.32206373,3.09199
26.16,108.99998,30.34520743,3.09435
26.2,109.16654,30.43689961,3.1037
26.24,109.33336,30.58507809,3.11881
26.28,109.5001,30.63440554,3.12384
26.32,109.66667,30.62077429,3.12245
26.36,109.83324,30.75002594,3.13563
26.4,109.99999,30.56624932,3.11689
26.44,110.16667,30.8315192,3.14394
26.48,110.33342,30.91477766,3.15243
26.52,110.49998,30.6954029,3.13006
26.56,110.66655,30.78454535,3.13915
26.6,110.8333,30.98538554,3.15963
26.64,111.00005,30.89565469,3.15048
26.68,111.16668,30.8303424,3.14382
26.72,111.33336,31.19769951,3.18128
26.76,111.49999,31.02471021,3.16364
26.8,111.66655,31.09482775,3.17079
26.84,111.8333,31.15984584,3.17742
26.88,112.00011,31.11699078,3.17305
26.92,112.16667,31.18416634,3.1799
26.96,112.3333,31.25683361,3.18731
27,112.50004,31.22280454,3.18384
27.04,112.66667,31.29753121,3.19146
27.08,112.83342,31.24202557,3.1858
27.12,113.00005,31.31635998,3.19338
27.16,113.16661,31.3792206,3.19979
27.2,113.33324,31.35205618,3.19702
27.24,113.49998,31.43482431,3.20546
27.28,113.66667,31.54701239,3.2169
27.32,113.83336,31.52524162,3.21468
27.36,114.00005,31.48866282,3.21095
27.4,114.16661,31.72009976,3.23455
27.44,114.33329,31.73814399,3.23639
27.48,114.50005,31.73716333,3.23629
27.52,114.66661,31.67047811,3.22949
27.56,114.8333,31.81257647,3.24398
27.6,115.00005,31.89563879,3.25245
27.64,115.16668,31.91701729,3.25463
27.68,115.3333,31.90593578,3.2535
27.72,115.49998,31.83895636,3.24667
27.76,115.66667,31.89867885,3.25276
27.8,115.83329,31.94339718,3.25732
27.84,115.99999,32.00812107,3.26392
27.88,116.16655,32.40538846,3.30443
27.92,116.33329,31.97536686,3.26058
27.96,116.50004,32.06372477,3.26959
28,116.66667,32.14511997,3.27789
28.04,116.8333,32.33713418,3.29747
28.08,116.99999,32.29427912,3.2931
28.12,117.16668,32.400289,3.30391
28.16,117.33342,32.38734422,3.30259
28.2,117.50011,32.46540516,3.31055
28.24,117.66661,32.58808635,3.32306
28.28,117.8333,32.48286099,3.31233
28.32,118.00005,32.64182679,3.32854
28.36,118.16667,32.54444676,3.31861
28.4,118.33336,32.53424784,3.31757
28.44,118.50011,32.58298689,3.32254
28.48,118.66667,32.60446345,3.32473
28.52,118.8333,32.51335968,3.31544
28.56,118.99998,32.6534967,3.32973
28.6,119.16667,32.77196104,3.34181
28.64,119.33336,32.71214047,3.33571
28.68,119.50005,32.88650271,3.35349
28.72,119.66655,33.02987593,3.36811
28.76,119.83329,32.81461996,3.34616
28.8,120.00011,32.97682196,3.3627
28.84,120.16667,32.90729281,3.35561
28.88,120.33329,32.90150688,3.35502
28.92,120.49999,32.83374293,3.34811
28.96,120.66661,32.90131075,3.355
29,120.83329,33.2442493,3.38997
29.04,121.00005,33.04017291,3.36916
29.08,121.16667,33.00938003,3.36602
29.12,121.3333,33.07959565,3.37318
29.16,121.49998,33.44714889,3.41066
29.2,121.6666,33.16079471,3.38146
29.24,121.83336,33.39144712,3.40498
29.28,122.00011,33.35163212,3.40092
29.32,122.16668,33.47735337,3.41374
29.36,122.3333,33.42920272,3.40883
29.4,122.50005,33.52746535,3.41885
29.44,122.66673,33.52462142,3.41856
29.48,122.83336,33.43390991,3.40931
29.52,123.00004,33.42145547,3.40804
29.56,123.16661,33.50853852,3.41692
29.6,123.3333,33.67270184,3.43366
29.64,123.50004,33.46568346,3.41255
29.68,123.66674,33.56169056,3.42234
29.72,123.83336,33.73585667,3.4401
29.76,123.99998,33.83941489,3.45066
29.8,124.16654,33.61523487,3.4278
29.84,124.3333,33.83156957,3.44986
29.88,124.50005,33.92434048,3.45932
29.92,124.66673,33.77998659,3.4446
29.96,124.83336,33.93228386,3.46013
30,124.99998,33.82499911,3.44919
30.04,125.1666,34.16332854,3.48369
30.08,125.33329,34.05986838,3.47314
30.12,125.50004,34.08713087,3.47592
30.16,125.66666,34.11821795,3.47909
30.2,125.83335,33.85235967,3.45198
30.24,125.99992,33.87864149,3.45466
30.28,126.16654,34.07016536,3.47419
30.32,126.33336,34.24560633,3.49208
30.36,126.50016,34.06790983,3.47396
30.4,126.6666,34.12635747,3.47992
30.44,126.83324,34.31748908,3.49941
30.48,127.00004,34.09585879,3.47681
30.52,127.16673,34.18460897,3.48586
30.56,127.33336,34.25266712,3.4928
30.6,127.49991,34.49440104,3.51745
30.64,127.66654,34.26806356,3.49437
30.68,127.83336,34.16891833,3.48426
30.72,128.0001,34.15685615,3.48303
30.76,128.16672,34.2044184,3.48788
30.8,128.33335,34.42467576,3.51034
30.84,128.49999,34.28787299,3.49639
30.88,128.66661,34.26855389,3.49442
30.92,128.83335,34.43585534,3.51148
30.96,129.00004,34.32866866,3.50055
31,129.16661,34.19225816,3.48664
31.04,129.33329,34.21138112,3.48859
31.08,129.49998,34.01505199,3.46857
31.12,129.6666,33.75223377,3.44177
31.16,129.8333,33.8305889,3.44976
31.2,130.00004,32.76686158,3.34129
31.24,130.16661,2.030172683,0.20702
31.28,130.3333,-2.203456189,-0.22469
31.32,130.50004,-1.297125596,-0.13227
31.36,130.66666,-1.025677524,-0.10459
31.4,130.83336,-1.140317262,-0.11628
31.44,131.00005,-1.036759038,-0.10572
31.48,131.16661,-1.080594764,-0.11019
31.52,131.33324,-1.074710774,-0.10959
31.56,131.49998,-1.191115709,-0.12146
31.6,131.66666,-1.125411154,-0.11476
31.64,131.83336,-1.086086488,-0.11075
31.68,132.00005,-1.173267606,-0.11964
31.72,132.16661,-1.086184554,-0.11076
31.76,132.33329,-1.059216267,-0.10801
31.8,132.50004,-1.056372338,-0.10772
31.84,132.66672,-1.109132115,-0.1131
31.88,132.83335,-1.163657089,-0.11866
31.92,132.99997,-1.290064808,-0.13155
31.96,133.1666,-1.435399361,-0.14637
32,133.33336,-1.297419795,-0.1323
32.04,133.50016,-1.160813161,-0.11837
32.08,133.66667,-1.184545254,-0.12079
32.12,133.83329,-1.23956056,-0.1264
32.16,133.99998,-1.25132854,-0.1276
32.2,134.16666,-1.222987322,-0.12471
32.24,134.33342,-1.14933938,-0.1172
32.28,134.50004,-1.119723297,-0.11418
32.32,134.66655,-1.205531485,-0.12293
32.36,134.8333,-1.314189167,-0.13401
32.4,135.00004,-1.227302248,-0.12515
32.44,135.16666,-1.099325465,-0.1121
32.48,135.33329,-0.934573745,-0.0953
32.52,135.50005,-1.161891892,-0.11848
32.56,135.66661,-1.272805104,-0.12979
32.6,135.83324,-0.999984101,-0.10197
32.64,135.99992,-1.239952826,-0.12644
32.68,136.16661,-1.136884935,-0.11593
32.72,136.33335,-0.996061441,-0.10157
32.76,136.49997,-1.222300856,-0.12464
32.8,136.6666,-1.081379296,-0.11027
32.84,136.83336,-1.196117101,-0.12197
32.88,137.0001,-1.105797854,-0.11276
32.92,137.16667,-1.132766142,-0.11551
32.96,137.33335,-1.28104269,-0.13063
33,137.49997,-1.222791189,-0.12469
33.04,137.66666,-1.090107214,-0.11116
33.08,137.83336,-1.037249371,-0.10577
33.12,138.0001,-1.038230036,-0.10587
33.16,138.16667,-1.174346338,-0.11975
33.2,138.33329,-1.276139365,-0.13013
33.24,138.49998,-1.167187483,-0.11902
33.28,138.6666,-1.05548974,-0.10763
33.32,138.83336,-1.10815145,-0.113
33.36,139.00011,-1.1770922,-0.12003
33.4,139.16661,-1.181897458,-0.12052
33.44,139.33323,-1.121292361,-0.11434
33.48,139.49998,-1.049115417,-0.10698
33.52,139.66667,-1.025187191,-0.10454
33.56,139.83334,-1.003122229,-0.10229
33.6,139.99998,-1.245150351,-0.12697
33.64,140.1666,-1.430888302,-0.14591
33.68,140.3333,-1.135119738,-0.11575
33.72,140.5001,-1.221712457,-0.12458
33.76,140.66673,-1.145122521,-0.11677
33.772,140.7168,-1.195822901,-0.12194