File: V_8/FR/RDSO FR Tensile 250.is_tens_RawData/Specimen_RawData_6.csv
Time,Extension,Load,
(sec),(mm),(N),(kgf)
0,0,0.208391313,0.02125
0.04,0.06794,0.902407933,0.09202
0.08,0.27775,1.550823631,0.15814
0.12,0.48256,2.438913855,0.2487
0.16,0.65519,3.223151656,0.32867
0.2,0.82412,4.067210021,0.41474
0.24,0.99487,4.544303544,0.46339
0.28,1.164,4.823891135,0.4919
0.32,1.33162,5.270191777,0.53741
0.36,1.49894,5.891443054,0.60076
0.4,1.666,6.303518487,0.64278
0.44,1.83294,6.604680709,0.67349
0.48,1.99987,6.840628708,0.69755
0.52,2.16669,7.131592013,0.72722
0.56,2.33312,7.809133462,0.79631
0.6,2.49987,7.781576775,0.7935
0.64,2.66669,7.895039716,0.80507
0.68,2.83337,8.303682821,0.84674
0.72,3.00012,8.639462517,0.88098
0.76,3.16675,8.996718777,0.91741
0.8,3.33325,8.960826438,0.91375
0.84,3.49994,9.206581087,0.93881
0.88,3.66669,9.449197608,0.96355
0.92,3.83331,9.761343277,0.99538
0.96,4.00006,9.911777288,1.01072
1,4.16669,10.07594061,1.02746
1.04,4.33325,10.47075634,1.06772
1.08,4.5,10.76691717,1.09792
1.12,4.66675,10.73416296,1.09458
1.16,4.83337,11.07151172,1.12898
1.2,5,11.16781302,1.1388
1.24,5.16662,11.24861982,1.14704
1.28,5.33331,11.52389248,1.17511
1.32,5.5,11.66265658,1.18926
1.36,5.66675,11.80995246,1.20428
1.4,5.83337,12.18338969,1.24236
1.44,6,12.10748622,1.23462
1.48,6.16669,12.19633447,1.24368
1.52,6.33331,12.33088171,1.2574
1.56,6.5,12.39550753,1.26399
1.6,6.66669,12.72393224,1.29748
1.64,6.83331,13.01597428,1.32726
1.68,7,13.0443155,1.33015
1.72,7.16662,13.00999222,1.32665
1.76,7.33337,13.15091378,1.34102
1.8,7.50006,13.24486149,1.3506
1.84,7.66675,13.40382729,1.36681
1.88,7.83331,13.70685277,1.39771
1.92,7.99994,13.66164412,1.3931
1.96,8.16669,13.76265261,1.4034
2,8.33344,13.90092638,1.4175
2.04,8.50019,13.88866806,1.41625
2.08,8.66656,14.05430238,1.43314
2.12,8.83306,13.97545692,1.4251
2.16,9,14.44323412,1.4728
2.2,9.16675,14.4187175,1.4703
2.24,9.33337,14.35673947,1.46398
2.28,9.50006,14.38684588,1.46705
2.32,9.66662,14.43636947,1.4721
2.36,9.83319,14.83363686,1.51261
2.4,10,14.91375719,1.52078
2.44,10.16675,14.82510507,1.51174
2.48,10.33331,14.86119354,1.51542
2.52,10.50006,14.96994929,1.52651
2.56,10.66669,15.11332251,1.54113
2.6,10.83325,15.11597031,1.5414
2.64,11.00006,15.03271185,1.53291
2.68,11.16681,14.89316322,1.51868
2.72,11.33331,15.19609064,1.54957
2.76,11.49994,15.58168812,1.58889
2.8,11.66669,15.62473931,1.59328
2.84,11.83337,15.70289831,1.60125
2.88,12.00006,15.65190373,1.59605
2.92,12.16669,15.82440271,1.61364
2.96,12.33325,15.77752692,1.60886
3,12.5,15.76615121,1.6077
3.04,12.66675,15.72967047,1.60398
3.08,12.83337,15.99239062,1.63077
3.12,13.00006,15.98856603,1.63038
3.16,13.16669,16.05436865,1.63709
3.2,13.33325,16.06515596,1.63819
3.24,13.5,16.10899169,1.64266
3.28,13.66668,16.03848188,1.63547
3.32,13.83331,15.9827801,1.62979
3.36,14,16.5319525,1.68579
3.4,14.16662,16.19833027,1.65177
3.44,14.33325,16.31022415,1.66318
3.48,14.5,16.56862937,1.68953
3.52,14.66675,16.48007533,1.6805
3.56,14.83331,16.72180925,1.70515
3.6,14.99994,16.79231906,1.71234
3.64,15.16662,16.82340614,1.71551
3.68,15.33337,16.66218482,1.69907
3.72,15.50006,16.74230515,1.70724
3.76,15.66675,16.78555247,1.71165
3.8,15.83331,16.69140863,1.70205
3.84,16,16.79810498,1.71293
3.88,16.16669,16.6531627,1.69815
3.92,16.33331,16.79084806,1.71219
3.96,16.50006,16.89067976,1.72237
4,16.66668,17.08308623,1.74199
4.04,16.83337,17.16624663,1.75047
4.08,17.00006,17.03013032,1.73659
4.12,17.16669,16.99610125,1.73312
4.16,17.33325,17.20919975,1.75485
4.2,17.50006,17.22959758,1.75693
4.24,17.66669,17.2181238,1.75576
4.28,17.83331,17.22596912,1.75656
4.32,18.00006,17.26578412,1.76062
4.36,18.16675,17.42592672,1.77695
4.4,18.33331,17.42337699,1.77669
4.44,18.49993,17.52977914,1.78754
4.48,18.66662,17.36571389,1.77081
4.52,18.83331,17.58508865,1.79318
4.56,19.00006,17.68511648,1.80338
4.6,19.16668,17.59734696,1.79443
4.64,19.33318,17.51918796,1.78646
4.68,19.49994,17.49398487,1.78389
4.72,19.66669,17.69913999,1.80481
4.76,19.83331,17.90684483,1.82599
4.8,20.00006,17.78847857,1.81392
4.84,20.16668,17.74179891,1.80916
4.88,20.33331,17.62490365,1.79724
4.92,20.5,17.67687889,1.80254
4.96,20.66668,17.53321147,1.78789
5,20.83331,17.94430624,1.82981
5.04,21.00006,17.97382425,1.83282
5.08,21.16675,17.86408784,1.82163
5.12,21.33331,17.85545799,1.82075
5.16,21.5,18.10150684,1.84584
5.2,21.66675,18.09385765,1.84506
5.24,21.83337,17.95264189,1.83066
5.28,22,17.93763771,1.82913
5.32,22.16668,18.12288533,1.84802
5.36,22.33325,18.14298897,1.85007
5.4,22.5,18.03138929,1.83869
5.44,22.66675,18.31058461,1.86716
5.48,22.83337,18.202025,1.85609
5.52,23,18.24566459,1.86054
5.56,23.16668,18.1411257,1.84988
5.6,23.33331,18.35039961,1.87122
5.64,23.50006,18.45336944,1.88172
5.68,23.66675,18.30823102,1.86692
5.72,23.83331,18.31980287,1.8681
5.76,23.99993,18.29675724,1.86575
5.8,24.16662,18.318528,1.86797
5.84,24.33337,18.10356623,1.84605
5.88,24.50006,18.05463105,1.84106
5.92,24.66668,18.40659172,1.87695
5.96,24.83325,18.4974013,1.88621
6,24.99993,18.40767045,1.87706
6.04,25.16675,18.4154177,1.87785
6.08,25.3335,18.60625511,1.89731
6.12,25.50006,18.80660497,1.91774
6.16,25.6665,18.66205495,1.903
6.2,25.83312,18.67843206,1.90467
6.24,26.00006,18.66009362,1.9028
6.28,26.16681,18.77188943,1.9142
6.32,26.33337,18.79738672,1.9168
6.36,26.50006,18.81141023,1.91823
6.4,26.66668,18.81356769,1.91845
6.44,26.83325,18.75355099,1.91233
6.48,27,18.84190891,1.92134
6.52,27.16674,18.82004008,1.91911
6.56,27.33337,19.08050471,1.94567
6.6,27.50006,18.7705165,1.91406
6.64,27.66668,19.06363727,1.94395
6.68,27.83325,19.21769974,1.95966
6.72,28.00006,18.92055824,1.92936
6.76,28.16675,18.93840635,1.93118
6.8,28.33331,19.02803913,1.94032
6.84,28.5,19.14356147,1.9521
6.88,28.66668,18.95105693,1.93247
6.92,28.83331,18.9297765,1.9303
6.96,29.00006,19.1829842,1.95612
7,29.16669,18.99724625,1.93718
7.04,29.33325,19.07118839,1.94472
7.08,29.5,19.19004499,1.95684
7.12,29.66668,18.90094494,1.92736
7.16,29.83337,19.30595959,1.96866
7.2,30.00006,19.17180462,1.95498
7.24,30.16668,19.26271226,1.96425
7.28,30.33325,19.26310453,1.96429
7.32,30.49999,19.28065843,1.96608
7.36,30.66675,19.54494765,1.99303
7.4,30.83337,19.40216283,1.97847
7.44,31,19.40196669,1.97845
7.48,31.16668,19.42746398,1.98105
7.52,31.33331,19.5172929,1.99021
7.56,31.50006,19.40765455,1.97903
7.6,31.66674,19.68959574,2.00778
7.64,31.83331,19.60898507,1.99956
7.68,31.99999,19.51974456,1.99046
7.72,32.16668,19.5933925,1.99797
7.76,32.33337,19.56671841,1.99525
7.8,32.50006,19.58966597,1.99759
7.84,32.66668,19.8287521,2.02197
7.88,32.83331,19.69224353,2.00805
7.92,33,19.68949767,2.00777
7.96,33.16668,19.86601737,2.02577
8,33.33331,19.89327986,2.02855
8.04,33.49999,19.7116607,2.01003
8.08,33.66668,19.81080593,2.02014
8.12,33.83337,19.93083933,2.03238
8.16,34.00006,19.82679077,2.02177
8.2,34.16662,19.95339462,2.03468
8.24,34.33324,20.06224844,2.04578
8.28,34.49999,19.95780761,2.03513
8.32,34.66668,20.03979121,2.04349
8.36,34.83331,19.94652997,2.03398
8.4,35.00006,20.07107442,2.04668
8.44,35.16675,20.24779026,2.0647
8.48,35.33331,20.26397123,2.06635
8.52,35.49999,19.96496647,2.03586
8.56,35.66662,19.90014451,2.02925
8.6,35.83337,20.28260386,2.06825
8.64,36.00012,20.0248851,2.04197
8.68,36.16668,20.11853861,2.05152
8.72,36.33318,20.24622119,2.06454
8.76,36.5,20.33850177,2.07395
8.8,36.66668,20.22866729,2.06275
8.84,36.83337,20.12108834,2.05178
8.88,37.00006,20.57974536,2.09855
8.92,37.16674,20.50658775,2.09109
8.96,37.33331,20.39734167,2.07995
9,37.49999,20.3369327,2.07379
9.04,37.66668,20.33448104,2.07354
9.08,37.83337,20.34938715,2.07506
9.12,38.00006,20.37017725,2.07718
9.16,38.16668,20.72154952,2.11301
9.2,38.33324,20.68820691,2.10961
9.24,38.5,20.63397613,2.10408
9.28,38.66674,20.78725407,2.11971
9.32,38.83331,20.73920149,2.11481
9.36,38.99999,20.70330915,2.11115
9.4,39.16662,20.74989074,2.1159
9.44,39.33324,20.93602095,2.13488
9.48,39.50006,20.86698214,2.12784
9.52,39.66675,20.87384679,2.12854
9.56,39.8333,20.93180409,2.13445
9.6,39.99999,20.94112041,2.1354
9.64,40.16662,20.84099451,2.12519
9.68,40.33331,20.93043116,2.13431
9.72,40.50006,21.08478783,2.15005
9.76,40.66675,20.77332863,2.11829
9.8,40.8333,20.78244881,2.11922
9.84,40.99999,21.07645218,2.1492
9.88,41.16668,21.07439278,2.14899
9.92,41.33337,21.02643827,2.1441
9.96,41.50006,21.28896229,2.17087
10,41.66668,21.30533939,2.17254
10.04,41.83325,21.1059702,2.15221
10.08,41.99999,21.20913615,2.16273
10.12,42.16681,21.27621364,2.16957
10.16,42.3335,21.23581024,2.16545
10.2,42.50005,21.23659477,2.16553
10.24,42.66656,21.29327721,2.17131
10.28,42.83318,21.40870148,2.18308
10.32,43.00006,21.52265476,2.1947
10.36,43.16675,21.35751077,2.17786
10.4,43.33337,21.76291768,2.2192
10.44,43.50006,21.46420712,2.18874
10.48,43.66662,21.3606489,2.17818
10.52,43.83324,21.71535543,2.21435
10.56,44,21.67701143,2.21044
10.6,44.16674,21.64298235,2.20697
10.64,44.33337,21.7930241,2.22227
10.68,44.49999,21.73398806,2.21625
10.72,44.66662,21.56864794,2.19939
10.76,44.83324,21.68289542,2.21104
10.8,45.00006,21.85235433,2.22832
10.84,45.16675,21.82626864,2.22566
10.88,45.33324,21.73438033,2.21629
10.92,45.49999,21.86569137,2.22968
10.96,45.66674,21.78174645,2.22112
11,45.83337,21.78370778,2.22132
11.04,46.00006,22.05319452,2.2488
11.08,46.16662,22.03112956,2.24655
11.12,46.33325,22.13704138,2.25735
11.16,46.49999,22.03720968,2.24717
11.2,46.66674,22.28669086,2.27261
11.24,46.83337,22.26060517,2.26995
11.28,47.00006,22.0427014,2.24773
11.32,47.16668,22.27884554,2.27181
11.36,47.33331,22.2004904,2.26382
11.4,47.50005,22.41643284,2.28584
11.44,47.66674,22.37544104,2.28166
11.48,47.8333,22.33699897,2.27774
11.52,47.99999,22.30610802,2.27459
11.56,48.16662,22.32415226,2.27643
11.6,48.3333,22.41437344,2.28563
11.64,48.50006,22.49076724,2.29342
11.68,48.66675,22.64973304,2.30963
11.72,48.83324,22.65934356,2.31061
11.76,48.99993,22.6170769,2.3063
11.8,49.16668,22.46497575,2.29079
11.84,49.33331,22.44555859,2.28881
11.88,49.5,22.55402014,2.29987
11.92,49.66668,22.49920096,2.29428
11.96,49.83325,22.66277588,2.31096
12,49.99993,22.81428863,2.32641
12.04,50.16668,22.78182862,2.3231
12.08,50.33331,22.95766185,2.34103
12.12,50.50005,22.89450702,2.33459
12.16,50.66674,22.85027903,2.33008
12.2,50.83337,23.09770081,2.35531
12.24,51.00005,23.10995912,2.35656
12.28,51.16662,22.93647949,2.33887
12.32,51.33331,23.12368843,2.35796
12.36,51.49999,23.25548981,2.3714
12.4,51.66662,23.24852709,2.37069
12.44,51.8333,23.1217271,2.35776
12.48,52.00006,23.26490419,2.37236
12.52,52.16674,23.26902299,2.37278
12.56,52.33331,23.22940412,2.36874
12.6,52.49999,23.19606151,2.36534
12.64,52.66662,23.37297348,2.38338
12.68,52.83337,23.57675566,2.40416
12.72,53.00011,23.52281909,2.39866
12.76,53.16662,23.44201229,2.39042
12.8,53.33318,23.58656231,2.40516
12.84,53.49999,23.6337323,2.40997
12.88,53.66674,23.55988823,2.40244
12.92,53.83337,23.79456136,2.42637
12.96,54.00006,23.78573538,2.42547
13,54.16668,23.48241569,2.39454
13.04,54.33324,23.78691217,2.42559
13.08,54.49993,23.82368711,2.42934
13.12,54.66668,23.8518322,2.43221
13.16,54.83331,23.68717854,2.41542
13.2,55.00006,23.73954605,2.42076
13.24,55.16662,24.13338112,2.46092
13.28,55.33325,24.12504547,2.46007
13.32,55.50005,24.00148168,2.44747
13.36,55.66674,24.0672843,2.45418
13.4,55.83331,24.10249017,2.45777
13.44,55.99999,24.11984794,2.45954
13.48,56.16668,24.11190455,2.45873
13.52,56.3333,24.12563386,2.46013
13.56,56.50006,23.99530349,2.44684
13.6,56.66674,24.20761746,2.46849
13.64,56.83331,24.40747699,2.48887
13.68,56.99999,24.44042733,2.49223
13.72,57.16668,24.33647684,2.48163
13.76,57.3333,24.46729755,2.49497
13.8,57.50006,24.28999332,2.47689
13.84,57.66674,24.62508655,2.51106
13.88,57.83331,24.55222314,2.50363
13.92,57.99993,24.4987769,2.49818
13.96,58.16668,24.53113884,2.50148
14,58.33337,24.4803404,2.4963
14.04,58.50005,24.6152799,2.51006
14.08,58.66668,24.70912954,2.51963
14.12,58.83324,24.75698599,2.52451
14.16,58.99993,24.91173493,2.54029
14.2,59.16681,24.80778444,2.52969
14.24,59.33343,24.94027228,2.5432
14.28,59.49999,24.98450027,2.54771
14.32,59.66649,25.0660916,2.55603
14.36,59.83318,25.08138997,2.55759
14.4,60.00006,24.99293399,2.54857
14.44,60.16681,25.04049624,2.55342
14.48,60.33337,25.17514155,2.56715
14.52,60.5,25.19112639,2.56878
14.56,60.66662,25.41079535,2.59118
14.6,60.83325,25.41285474,2.59139
14.64,61.00005,25.38098313,2.58814
14.68,61.16674,25.18749793,2.56841
14.72,61.33337,25.42785892,2.59292
14.76,61.49999,25.49885906,2.60016
14.8,61.66662,25.48356069,2.5986
14.84,61.8333,25.48816982,2.59907
14.88,62.00012,25.62183446,2.6127
14.92,62.16674,25.59574877,2.61004
14.96,62.33331,25.56534815,2.60694
15,62.49999,25.52514089,2.60284
15.04,62.66674,25.63419083,2.61396
15.08,62.83336,25.70705424,2.62139
15.12,63.00006,25.89181153,2.64023
15.16,63.16668,26.01066813,2.65235
15.2,63.33324,26.06882156,2.65828
15.24,63.50006,26.0084126,2.65212
15.28,63.66674,26.03106596,2.65443
15.32,63.83337,26.05244446,2.65661
15.36,64.00005,26.07343069,2.65875
15.4,64.16667,26.17434112,2.66904
15.44,64.33324,26.14139077,2.66568
15.48,64.49999,26.32722679,2.68463
15.52,64.66674,26.23886887,2.67562
15.56,64.8333,26.39675594,2.69172
15.6,64.99992,26.24563546,2.67631
15.64,65.16661,26.34438843,2.68638
15.68,65.3333,26.41107365,2.69318
15.72,65.50005,26.64172606,2.7167
15.76,65.66674,26.58043449,2.71045
15.8,65.83324,26.65457277,2.71801
15.84,65.99999,26.61083511,2.71355
15.88,66.16674,26.67045954,2.71963
15.92,66.33336,26.54277696,2.70661
15.96,66.50005,26.70801901,2.72346
16,66.66668,26.85855109,2.73881
16.04,66.83324,26.87679146,2.74067
16.08,66.99999,26.8104985,2.73391
16.12,67.16674,26.8918937,2.74221
16.16,67.33336,26.92504017,2.74559
16.2,67.49999,27.13156822,2.76665
16.24,67.66674,26.96750297,2.74992
16.28,67.83336,26.87247653,2.74023
16.32,67.99999,27.13284309,2.76678
16.36,68.16661,27.2636638,2.78012
16.4,68.3333,27.35447338,2.78938
16.44,68.49999,27.31740424,2.7856
16.48,68.66661,27.30828406,2.78467
16.52,68.8333,27.24032397,2.77774
16.56,69.00005,27.21129629,2.77478
16.6,69.16668,27.42704259,2.79678
16.64,69.33324,27.46538659,2.80069
16.68,69.49992,27.62435239,2.8169
16.72,69.66662,27.55894203,2.81023
16.76,69.83336,27.69947132,2.82456
16.8,70.00005,27.91972868,2.84702
16.84,70.16661,27.57237714,2.8116
16.88,70.33318,27.85078793,2.83999
16.92,70.49999,28.01151893,2.85638
16.96,70.66674,27.85775066,2.8407
17,70.83336,27.95022736,2.85013
17.04,71.00006,27.86794957,2.84174
17.08,71.16674,27.90492064,2.84551
17.12,71.33331,28.15253855,2.87076
17.16,71.49999,28.0669265,2.86203
17.2,71.66667,27.97258653,2.85241
17.24,71.83337,28.10144591,2.86555
17.28,72.00005,28.20716159,2.87633
17.32,72.16667,28.21000552,2.87662
17.36,72.3333,28.39142855,2.89512
17.4,72.50005,28.50753928,2.90696
17.44,72.66674,28.47468701,2.90361
17.48,72.8333,28.49979203,2.90617
17.52,72.99999,28.53489984,2.90975
17.56,73.16662,28.60501739,2.9169
17.6,73.33324,28.63080887,2.91953
17.64,73.50005,28.62335582,2.91877
17.68,73.66674,28.62767075,2.91921
17.72,73.8333,28.81066284,2.93787
17.76,73.99993,28.81811589,2.93863
17.8,74.16661,28.7756531,2.9343
17.84,74.3333,28.92441998,2.94947
17.88,74.50006,29.02140774,2.95936
17.92,74.66668,28.88274171,2.94522
17.96,74.83324,28.87764226,2.9447
18,74.99993,29.14212761,2.97167
18.04,75.16667,29.22901452,2.98053
18.08,75.33337,29.13859721,2.97131
18.12,75.50005,29.27736131,2.98546
18.16,75.66668,29.23450625,2.98109
18.2,75.83324,29.22028661,2.97964
18.24,76.00005,29.19753518,2.97732
18.28,76.16686,29.30119147,2.98789
18.32,76.33343,29.28569696,2.98631
18.36,76.49993,29.61049321,3.01943
18.4,76.66655,29.70679451,3.02925
18.44,76.8333,29.5949987,3.01785
18.48,77.00011,29.68992707,3.02753
18.52,77.1668,29.70865778,3.02944
18.56,77.33336,29.93175906,3.05219
18.6,77.49998,29.99883655,3.05903
18.64,77.66668,30.05316539,3.06457
18.68,77.83331,30.20310907,3.07986
18.72,77.99999,30.04002448,3.06323
18.76,78.16668,29.91861815,3.05085
18.8,78.3333,30.12210614,3.0716
18.84,78.49999,30.07503422,3.0668
18.88,78.66655,30.19261595,3.07879
18.92,78.8333,30.25057326,3.0847
18.96,79.00004,30.3610942,3.09597
19,79.16674,30.43797834,3.10381
19.04,79.33323,30.57134878,3.11741
19.08,79.49999,30.37580418,3.09747
19.12,79.66667,30.48044113,3.10814
19.16,79.8333,30.52800338,3.11299
19.2,79.99999,30.43552667,3.10356
19.24,80.16662,30.40316473,3.10026
19.28,80.33324,30.70364049,3.1309
19.32,80.50005,30.7565964,3.1363
19.36,80.66674,30.47681267,3.10777
19.4,80.83336,30.82004542,3.14277
19.44,80.99998,30.87800272,3.14868
19.48,81.16661,30.94635507,3.15565
19.52,81.33323,31.04118538,3.16532
19.56,81.50005,31.1441552,3.17582
19.6,81.66674,31.11032226,3.17237
19.64,81.83324,31.20809456,3.18234
19.68,81.99998,31.00754857,3.16189
19.72,82.16668,31.11012613,3.17235
19.76,82.33336,31.36921782,3.19877
19.8,82.50005,31.26340407,3.18798
19.84,82.66667,31.4003049,3.20194
19.88,82.83324,31.53230241,3.2154
19.92,82.99999,31.4029527,3.20221
19.96,83.16674,31.41324968,3.20326
20,83.3333,31.54612979,3.21681
20.04,83.49999,31.74873518,3.23747
20.08,83.66668,31.66959551,3.2294
20.12,83.83323,31.73902659,3.23648
20.16,83.99999,32.15982994,3.27939
20.2,84.16668,32.04332694,3.26751
20.24,84.3333,31.68803201,3.23128
20.28,84.49999,31.91995928,3.25493
20.32,84.66667,31.98350638,3.26141
20.36,84.8333,31.98017212,3.26107
20.4,84.99992,32.13953018,3.27732
20.44,85.16661,32.05999825,3.26921
20.48,85.3333,32.27241029,3.29087
20.52,85.49999,32.39891607,3.30377
20.56,85.66667,32.35243255,3.29903
20.6,85.83336,32.25828871,3.28943
20.64,86.00011,32.46491483,3.3105
20.68,86.16674,32.49149085,3.31321
20.72,86.3333,32.40548653,3.30444
20.76,86.49993,32.59024381,3.32328
20.8,86.66667,32.74744441,3.33931
20.84,86.83342,32.75725106,3.34031
20.88,87.00005,32.82256335,3.34697
20.92,87.16661,32.74911154,3.33948
20.96,87.33324,32.70674681,3.33516
21,87.49999,32.90111462,3.35498
21.04,87.66667,32.95132467,3.3601
21.08,87.8333,32.82324982,3.34704
21.12,88.00005,33.09489402,3.37474
21.16,88.16661,33.26876593,3.39247
21.2,88.33324,33.04488011,3.36964
21.24,88.49998,33.3253503,3.39824
21.28,88.66673,33.15549912,3.38092
21.32,88.83336,33.45224835,3.41118
21.36,88.99999,33.18952819,3.38439
21.4,89.16661,33.09106943,3.37435
21.44,89.33323,33.40331316,3.40619
21.48,89.50005,33.5595331,3.42212
21.52,89.66674,33.46891965,3.41288
21.56,89.83323,33.66515072,3.43289
21.6,89.99993,33.79332363,3.44596
21.64,90.16661,33.77635813,3.44423
21.68,90.3333,33.83823809,3.45054
21.72,90.50005,33.80803361,3.44746
21.76,90.66674,33.91727969,3.4586
21.8,90.8333,33.94581704,3.46151
21.84,90.99999,33.99426189,3.46645
21.88,91.16674,34.03613629,3.47072
21.92,91.3333,33.87050197,3.45383
21.96,91.50005,34.08144301,3.47534
22,91.66674,34.10046791,3.47728
22.04,91.83324,34.12174834,3.47945
22.08,91.99998,34.21971678,3.48944
22.12,92.16674,34.4239893,3.51027
22.16,92.33336,34.23638808,3.49114
22.2,92.50005,34.39976687,3.5078
22.24,92.66661,34.43703214,3.5116
22.28,92.83324,34.38535109,3.50633
22.32,92.99998,34.63198834,3.53148
22.36,93.1668,34.61306151,3.52955
22.4,93.33336,34.6578779,3.53412
22.44,93.49992,34.70700921,3.53913
22.48,93.66655,35.16223391,3.58555
22.52,93.83329,34.93766162,3.56265
22.56,94.00005,35.02621567,3.57168
22.6,94.16673,35.12359571,3.58161
22.64,94.33337,35.09182216,3.57837
22.68,94.49992,34.950018,3.56391
22.72,94.66661,35.13791342,3.58307
22.76,94.8333,35.05995055,3.57512
22.8,95.00004,35.15899771,3.58522
22.84,95.16673,35.54067253,3.62414
22.88,95.3333,35.45751214,3.61566
22.92,95.49998,35.32257264,3.6019
22.96,95.66661,35.42142367,3.61198
23,95.83335,35.50350533,3.62035
23.04,96.00011,35.67973083,3.63832
23.08,96.16667,35.65384127,3.63568
23.12,96.3333,35.60157183,3.63035
23.16,96.49999,35.54488939,3.62457
23.2,96.66674,35.52135343,3.62217
23.24,96.83336,35.66276532,3.63659
23.28,96.99998,35.96569274,3.66748
23.32,97.16667,35.95255183,3.66614
23.36,97.3333,36.09847478,3.68102
23.4,97.50005,35.77818959,3.64836
23.44,97.66674,36.29127352,3.70068
23.48,97.83329,36.31010229,3.7026
23.52,97.99998,36.20330787,3.69171
23.56,98.16661,36.20291561,3.69167
23.6,98.33324,36.39081102,3.71083
23.64,98.50005,36.49995903,3.72196
23.68,98.66673,36.42729176,3.71455
23.72,98.83324,36.68020526,3.74034
23.76,98.99999,36.53369391,3.7254
23.8,99.16667,36.79347207,3.75189
23.84,99.3333,36.65764997,3.73804
23.88,99.50005,36.68059753,3.74038
23.92,99.66668,36.82701081,3.75531
23.96,99.83317,36.89212697,3.76195
24,99.99998,36.77993889,3.75051
24.04,100.16668,37.01078743,3.77405
24.08,100.3333,36.93341296,3.76616
24.12,100.50005,36.89448056,3.76219
24.16,100.66673,37.18524774,3.79184
24.2,100.83323,37.17043969,3.79033
24.24,101.00004,37.31518585,3.80509
24.28,101.16674,37.37098569,3.81078
24.32,101.33336,37.3062618,3.80418
24.36,101.50004,37.42433386,3.81622
24.4,101.66674,37.64841582,3.83907
24.44,101.83336,37.56937422,3.83101
24.48,101.99999,37.59487151,3.83361
24.52,102.16667,37.58163253,3.83226
24.56,102.3333,37.6584186,3.84009
24.6,102.49998,37.71392424,3.84575
24.64,102.66667,37.71510104,3.84587
24.68,102.83336,37.55780237,3.82983
24.72,103.00005,38.08471367,3.88356
24.76,103.16667,37.98213612,3.8731
24.8,103.33324,37.90466358,3.8652
24.84,103.49993,37.89593566,3.86431
24.88,103.66674,38.25211319,3.90063
24.92,103.83342,38.26868643,3.90232
24.96,104.00005,38.13237399,3.88842
25,104.16655,38.27966988,3.90344
25.04,104.33324,38.36028054,3.91166
25.08,104.49998,38.46089677,3.92192
25.12,104.66673,38.39695741,3.9154
25.16,104.83336,38.56161106,3.93219
25.2,104.99999,38.79844166,3.95634
25.24,105.16661,38.5820089,3.93427
25.28,105.33324,38.5811263,3.93418
25.32,105.49999,38.75490014,3.9519
25.36,105.66674,38.97505943,3.97435
25.4,105.83336,38.91916152,3.96865
25.44,106.00004,38.71439867,3.94777
25.48,106.16668,38.90660901,3.96737
25.52,106.33335,38.93083144,3.96984
25.56,106.50005,39.00114512,3.97701
25.6,106.66673,39.21895081,3.99922
25.64,106.8333,39.01301116,3.97822
25.68,106.99999,39.26249234,4.00366
25.72,107.16667,39.37281715,4.01491
25.76,107.3333,39.48696656,4.02655
25.8,107.50005,39.33996487,4.01156
25.84,107.66674,39.37664175,4.0153
25.88,107.8333,39.40439456,4.01813
25.92,107.99998,39.5825814,4.0363
25.96,108.16667,39.75753203,4.05414
26,108.3333,39.72938695,4.05127
26.04,108.50005,39.5424722,4.03221
26.08,108.66674,39.67064511,4.04528
26.12,108.83324,39.84510542,4.06307
26.16,108.99998,39.70310512,4.04859
26.2,109.16674,39.89472706,4.06813
26.24,109.33336,40.09331173,4.08838
26.28,109.49999,40.09605759,4.08866
26.32,109.66661,40.24207861,4.10355
26.36,109.83324,40.16480221,4.09567
26.4,110.00005,40.40173087,4.11983
26.44,110.16686,40.27797095,4.10721
26.48,110.33336,40.33524178,4.11305
26.52,110.49986,40.35701255,4.11527
26.56,110.66655,40.36779986,4.11637
26.6,110.8333,40.48744099,4.12857
26.64,111.00011,40.5790351,4.13791
26.68,111.1668,40.50391616,4.13025
26.72,111.3333,40.55314555,4.13527
26.76,111.49992,40.74349262,4.15468
26.8,111.66661,40.65356564,4.14551
26.84,111.83336,40.64895652,4.14504
26.88,112.00004,40.64964298,4.14511
26.92,112.16674,40.78105209,4.15851
26.96,112.3333,41.01847109,4.18272
27,112.49992,41.02249181,4.18313
27.04,112.66661,41.13840642,4.19495
27.08,112.83336,41.21833062,4.2031
27.12,113.00005,41.25893015,4.20724
27.16,113.16667,41.4434913,4.22606
27.2,113.33324,41.36660716,4.21822
27.24,113.49998,41.2479467,4.20612
27.28,113.66673,41.32296757,4.21377
27.32,113.8333,41.40730476,4.22237
27.36,113.99998,41.44927722,4.22665
27.4,114.16661,41.44506036,4.22622
27.44,114.33324,41.78525305,4.26091
27.48,114.49998,41.58735485,4.24073
27.52,114.66674,41.72533442,4.2548
27.56,114.8333,42.00060709,4.28287
27.6,114.99998,42.06709617,4.28965
27.64,115.1666,41.89783339,4.27239
27.68,115.3333,41.86037199,4.26857
27.72,115.50005,41.97648273,4.28041
27.76,115.66673,42.06837104,4.28978
27.8,115.83329,42.07248983,4.2902
27.84,115.99999,42.22390451,4.30564
27.88,116.16673,42.19801495,4.303
27.92,116.33337,42.31520442,4.31495
27.96,116.50004,42.38532197,4.3221
28,116.66667,42.38855816,4.32243
28.04,116.83323,42.59704754,4.34369
28.08,117.00004,42.45730278,4.32944
28.12,117.16673,42.43337455,4.327
28.16,117.33335,42.66471342,4.35059
28.2,117.50005,42.64529626,4.34861
28.24,117.66667,42.71080468,4.35529
28.28,117.83324,42.83927179,4.36839
28.32,117.99999,42.82583668,4.36702
28.36,118.16673,42.83123034,4.36757
28.4,118.3333,43.05903882,4.3908
28.44,118.49998,43.04501531,4.38937
28.48,118.66674,43.14906387,4.39998
28.52,118.8333,43.19937198,4.40511
28.56,118.99998,43.32744683,4.41817
28.6,119.16667,43.21064963,4.40626
28.64,119.33323,43.21025736,4.40622
28.68,119.49998,43.40001604,4.42557
28.72,119.66667,43.43169152,4.4288
28.76,119.83329,43.61860627,4.44786
28.8,120.00005,43.50671239,4.43645
28.84,120.16667,43.44924542,4.43059
28.88,120.33324,43.68578182,4.45471
28.92,120.49999,43.61615461,4.44761
28.96,120.6668,43.65194888,4.45126
29,120.83342,43.81424894,4.46781
29.04,120.99999,43.81071854,4.46745
29.08,121.16661,43.78463285,4.46479
29.12,121.3333,43.88740655,4.47527
29.16,121.50005,44.05686546,4.49255
29.2,121.66673,44.00449795,4.48721
29.24,121.83336,43.96840947,4.48353
29.28,122.00005,43.92251435,4.47885
29.32,122.16668,44.00998967,4.48777
29.36,122.33323,43.90280299,4.47684
29.4,122.49999,43.85690786,4.47216
29.44,122.66673,14.79774452,1.50895
29.48,122.83336,-2.120884196,-0.21627
29.52,122.99999,-0.499648818,-0.05095
29.56,123.16661,-0.179755895,-0.01833
29.6,123.3333,-0.115228138,-0.01175
29.64,123.50004,-0.165732385,-0.0169
29.68,123.66674,-0.347939942,-0.03548
29.72,123.8333,-0.283019919,-0.02886
29.76,123.99992,-0.097968434,-0.00999
29.8,124.16661,-0.25889556,-0.0264
29.84,124.3333,-0.251638639,-0.02566
29.88,124.50005,-0.222709022,-0.02271
29.92,124.66667,-0.181717225,-0.01853
29.96,124.83324,-0.197407865,-0.02013
30,124.99998,-0.329013108,-0.03355
30.04,125.16673,-0.131016844,-0.01336
30.08,125.33336,-0.141902226,-0.01447
30.12,125.50004,-0.189464478,-0.01932
30.16,125.66666,-0.212902372,-0.02171
30.2,125.83323,-0.270467407,-0.02758
30.24,126.00005,-0.405406911,-0.04134
30.28,126.16679,-0.170439577,-0.01738
30.32,126.33336,-0.190150944,-0.01939
30.36,126.50005,-0.162594257,-0.01658
30.4,126.6666,-0.120327596,-0.01227
30.44,126.83329,-0.063449026,-0.00647
30.48,127.00011,-0.173577705,-0.0177
30.52,127.16685,-0.218688295,-0.0223
30.56,127.33328,-0.199761461,-0.02037
30.6,127.49985,-0.238105462,-0.02428
30.64,127.66661,-0.285961914,-0.02916
30.68,127.83329,-0.234575068,-0.02392
30.72,128.00003,-0.31802966,-0.03243
30.76,128.16672,-0.194662003,-0.01985
30.8,128.33329,-0.043247327,-0.00441
30.84,128.49991,-0.326169179,-0.03326
30.88,128.66661,-0.473661195,-0.0483
30.92,128.8333,-0.15523927,-0.01583
30.96,128.99998,-0.238693861,-0.02434
31,129.16672,-0.184463087,-0.01881
31.04,129.33329,-0.339702356,-0.03464
31.08,129.49985,-0.061193496,-0.00624
31.12,129.6666,-0.159456129,-0.01626
31.16,129.83336,-0.282823786,-0.02884
31.2,130.00011,-0.165340119,-0.01686
31.24,130.16666,-0.446594841,-0.04554
31.28,130.33323,-0.222610955,-0.0227
31.32,130.49997,-0.320089056,-0.03264
31.36,130.66679,-0.196034934,-0.01999
31.4,130.83336,-0.30430035,-0.03103
31.44,130.99998,-0.325090448,-0.03315
31.48,131.16667,-0.290865239,-0.02966
31.52,131.33329,-0.360786654,-0.03679
31.56,131.50004,-0.244283652,-0.02491
31.6,131.66673,-0.198486596,-0.02024
31.64,131.83328,-0.501806281,-0.05117
31.654,131.89173,-0.466208141,-0.04754