File: V_8/FR/RDSO FR Tensile 250.is_tens_RawData/Specimen_RawData_7.csv
Time,Extension,Load,
(sec),(mm),(N),(kgf)
0,0,-0.363630582,-0.03708
0.04,0.068,0.10002783,0.0102
0.08,0.27775,1.11432964,0.11363
0.12,0.48262,2.259648293,0.23042
0.16,0.65525,2.990832117,0.30498
0.2,0.82406,3.603453543,0.36745
0.24,0.99487,4.314337601,0.43994
0.28,1.164,4.558915452,0.46488
0.32,1.33162,5.073666511,0.51737
0.36,1.49887,5.330012342,0.54351
0.4,1.666,5.939985972,0.60571
0.44,1.83294,6.306852748,0.64312
0.48,1.99987,6.699805214,0.68319
0.52,2.16669,6.92937889,0.7066
0.56,2.33312,7.161011963,0.73022
0.6,2.49987,7.595152359,0.77449
0.64,2.66669,7.902885036,0.80587
0.68,2.83337,8.224641222,0.83868
0.72,3.00006,8.379586292,0.85448
0.76,3.16675,8.550222002,0.87188
0.8,3.33325,9.091745215,0.9271
0.84,3.49994,9.26924558,0.9452
0.88,3.66669,9.332204273,0.95162
0.92,3.83337,9.837442881,1.00314
0.96,4.00006,9.920112941,1.01157
1,4.16675,10.01670844,1.02142
1.04,4.33325,10.45339857,1.06595
1.08,4.5,10.69474022,1.09056
1.12,4.66675,10.82340347,1.10368
1.16,4.83337,10.93843548,1.11541
1.2,5,10.91225172,1.11274
1.24,5.16662,11.43877076,1.16643
1.28,5.33331,11.6491234,1.18788
1.32,5.5,11.62960817,1.18589
1.36,5.66675,11.87261696,1.21067
1.4,5.83337,11.93243752,1.21677
1.44,6.00006,12.16573772,1.24056
1.48,6.16669,12.02952336,1.22667
1.52,6.33331,12.37873816,1.26228
1.56,6.5,12.57369436,1.28216
1.6,6.66675,12.6921587,1.29424
1.64,6.83331,12.9231053,1.31779
1.68,7,13.00057784,1.32569
1.72,7.16669,13.26771098,1.35293
1.76,7.33337,13.30732985,1.35697
1.8,7.50006,13.5343538,1.38012
1.84,7.66675,13.58289672,1.38507
1.88,7.83325,13.66968557,1.39392
1.92,7.99994,13.75843575,1.40297
1.96,8.16669,13.926914,1.42015
2,8.3335,13.92671786,1.42013
2.04,8.50019,14.03674848,1.43135
2.08,8.66656,14.24092293,1.45217
2.12,8.83306,14.24435526,1.45252
2.16,9,14.35271874,1.46357
2.2,9.16681,14.23592154,1.45166
2.24,9.33337,14.53688763,1.48235
2.28,9.50006,14.65486163,1.49438
2.32,9.66662,14.74812287,1.50389
2.36,9.83319,14.93131109,1.52257
2.4,10,15.02212067,1.53183
2.44,10.16675,15.0659564,1.5363
2.48,10.33331,15.02280714,1.5319
2.52,10.50006,15.07674371,1.5374
2.56,10.66669,15.21129095,1.55112
2.6,10.83325,15.38947778,1.56929
2.64,11.00006,15.02427813,1.53205
2.68,11.16681,15.17010302,1.54692
2.72,11.33331,15.28954802,1.5591
2.76,11.49994,15.40036316,1.5704
2.8,11.66669,15.50696145,1.58127
2.84,11.83331,15.55972122,1.58665
2.88,12.00006,15.73143566,1.60416
2.92,12.16669,15.62552384,1.59336
2.96,12.33325,15.69819112,1.60077
3,12.5,15.98474143,1.62999
3.04,12.66675,15.90020811,1.62137
3.08,12.83337,15.98189751,1.6297
3.12,13.00006,16.03083269,1.63469
3.16,13.16669,16.11007042,1.64277
3.2,13.33325,16.05887971,1.63755
3.24,13.5,16.25099198,1.65714
3.28,13.66675,15.99552875,1.63109
3.32,13.83331,16.22588696,1.65458
3.36,14,16.19450568,1.65138
3.4,14.16662,16.42751168,1.67514
3.44,14.33325,16.30600729,1.66275
3.48,14.5,16.63129387,1.69592
3.52,14.66675,16.4356512,1.67597
3.56,14.83331,16.59510733,1.69223
3.6,14.99994,16.60452171,1.69319
3.64,15.16662,16.50106156,1.68264
3.68,15.33331,16.70611861,1.70355
3.72,15.50006,17.01532228,1.73508
3.76,15.66675,17.00453497,1.73398
3.8,15.83331,16.82517134,1.71569
3.84,16,16.98354874,1.73184
3.88,16.16669,17.09897301,1.74361
3.92,16.33331,17.06955306,1.74061
3.96,16.50006,16.95452105,1.72888
4,16.66668,17.01228222,1.73477
4.04,16.83337,17.26499959,1.76054
4.08,17.00006,17.30795272,1.76492
4.12,17.16662,17.11162359,1.7449
4.16,17.33325,17.09387355,1.74309
4.2,17.50006,17.11927277,1.74568
4.24,17.66669,16.95216746,1.72864
4.28,17.83331,16.97874348,1.73135
4.32,18.00006,17.24881862,1.75889
4.36,18.16675,17.40621535,1.77494
4.4,18.33331,17.60381935,1.79509
4.44,18.5,17.5553745,1.79015
4.48,18.66662,17.33129255,1.7673
4.52,18.83331,17.55223637,1.78983
4.56,19.00006,17.44632455,1.77903
4.6,19.16668,17.43847923,1.77823
4.64,19.33318,17.4944752,1.78394
4.68,19.49994,17.43514497,1.77789
4.72,19.66675,17.6139202,1.79612
4.76,19.83331,17.49467133,1.78396
4.8,20.00006,17.73032513,1.80799
4.84,20.16668,17.86722597,1.82195
4.88,20.33331,17.94626757,1.83001
4.92,20.5,17.78612497,1.81368
4.96,20.66668,17.82799937,1.81795
5,20.83331,17.87497322,1.82274
5.04,21.00006,17.84153254,1.81933
5.08,21.16675,17.78308491,1.81337
5.12,21.33325,17.9090023,1.82621
5.16,21.5,17.97941404,1.83339
5.2,21.66675,17.94018744,1.82939
5.24,21.83337,18.04766833,1.84035
5.28,22,18.09366152,1.84504
5.32,22.16668,18.07414628,1.84305
5.36,22.33325,18.09268085,1.84494
5.4,22.5,18.03001636,1.83855
5.44,22.66675,18.02079811,1.83761
5.48,22.83337,18.09650544,1.84533
5.52,23,18.08483553,1.84414
5.56,23.16668,18.23507341,1.85946
5.6,23.33331,18.31480147,1.86759
5.64,23.50006,18.40266906,1.87655
5.68,23.66675,18.3758969,1.87382
5.72,23.83331,18.19545454,1.85542
5.76,23.99993,18.23419081,1.85937
5.8,24.16662,18.28145886,1.86419
5.84,24.33337,18.36922838,1.87314
5.88,24.50006,18.55545666,1.89213
5.92,24.66668,18.58517081,1.89516
5.96,24.83325,18.48573138,1.88502
6,24.99993,18.62596648,1.89932
6.04,25.16675,18.46072443,1.88247
6.08,25.3335,18.57212797,1.89383
6.12,25.50006,18.58997607,1.89565
6.16,25.6665,18.49367477,1.88583
6.2,25.83312,18.60370538,1.89705
6.24,26.00006,18.61341397,1.89804
6.28,26.16681,18.67382293,1.9042
6.32,26.33337,18.70039895,1.90691
6.36,26.50006,18.61694436,1.8984
6.4,26.66668,18.59948852,1.89662
6.44,26.83325,18.73079957,1.91001
6.48,27,18.82082461,1.91919
6.52,27.16674,18.69216137,1.90607
6.56,27.33337,18.80758564,1.91784
6.6,27.50006,18.74864767,1.91183
6.64,27.66668,18.82033428,1.91914
6.68,27.83325,18.92026404,1.92933
6.72,28.00006,18.79091433,1.91614
6.76,28.16675,18.88986343,1.92623
6.8,28.33331,19.08158344,1.94578
6.84,28.5,19.07040386,1.94464
6.88,28.66668,19.28938635,1.96697
6.92,28.83331,19.14836672,1.95259
6.96,29.00006,18.98400727,1.93583
7,29.16669,18.92938423,1.93026
7.04,29.33318,19.22750639,1.96066
7.08,29.5,19.25408241,1.96337
7.12,29.66675,19.32773035,1.97088
7.16,29.83337,19.26918465,1.96491
7.2,30.00006,19.20132263,1.95799
7.24,30.16668,19.19082952,1.95692
7.28,30.33325,19.21819007,1.95971
7.32,30.49999,19.24761002,1.96271
7.36,30.66675,19.144346,1.95218
7.4,30.83337,19.44580242,1.98292
7.44,31,19.08874229,1.94651
7.48,31.16668,19.48914781,1.98734
7.52,31.33331,19.38107853,1.97632
7.56,31.50006,19.53710233,1.99223
7.6,31.66674,19.47855663,1.98626
7.64,31.83331,19.38921805,1.97715
7.68,31.99993,19.33439887,1.97156
7.72,32.16668,19.62604865,2.0013
7.76,32.33337,19.59525576,1.99816
7.8,32.50006,19.46825965,1.98521
7.84,32.66668,19.67115924,2.0059
7.88,32.83331,19.70165792,2.00901
7.92,33,19.53651393,1.99217
7.96,33.16668,19.53945593,1.99247
8,33.33331,19.60153202,1.9988
8.04,33.49999,19.80894267,2.01995
8.08,33.66675,19.81688605,2.02076
8.12,33.83337,19.69646039,2.00848
8.16,34.00006,20.05567798,2.04511
8.2,34.16656,19.82502557,2.02159
8.24,34.33324,19.93427165,2.03273
8.28,34.49999,19.92407274,2.03169
8.32,34.66668,19.92319014,2.0316
8.36,34.83331,19.83257669,2.02236
8.4,35.00006,19.83002697,2.0221
8.44,35.16675,19.98516817,2.03792
8.48,35.33325,20.0825482,2.04785
8.52,35.49999,19.98212811,2.03761
8.56,35.66662,20.1844393,2.05824
8.6,35.83331,20.14648756,2.05437
8.64,36.00012,20.2382778,2.06373
8.68,36.16668,20.23729714,2.06363
8.72,36.33318,20.14099584,2.05381
8.76,36.5,20.18698903,2.0585
8.8,36.66668,20.12834526,2.05252
8.84,36.83337,20.28819365,2.06882
8.88,37.00006,20.32898932,2.07298
8.92,37.16674,20.35291754,2.07542
8.96,37.33331,20.19875701,2.0597
9,37.49999,20.46000616,2.08634
9.04,37.66668,20.30104036,2.07013
9.08,37.83337,20.28417293,2.06841
9.12,38.00006,20.41067871,2.08131
9.16,38.16668,20.30613982,2.07065
9.2,38.33324,20.39587067,2.0798
9.24,38.5,20.3413457,2.07424
9.28,38.66674,20.34007083,2.07411
9.32,38.83331,20.54277429,2.09478
9.36,38.99993,20.56425085,2.09697
9.4,39.16662,20.54640275,2.09515
9.44,39.33324,20.53639996,2.09413
9.48,39.49999,20.68771657,2.10956
9.52,39.66675,20.67104527,2.10786
9.56,39.8333,20.60377165,2.101
9.6,39.99999,20.69016824,2.10981
9.64,40.16662,20.74420288,2.11532
9.68,40.33331,20.59729926,2.10034
9.72,40.50006,20.75783412,2.11671
9.76,40.66675,20.72831611,2.1137
9.8,40.8333,20.86472661,2.12761
9.84,40.99999,20.82589227,2.12365
9.88,41.16668,21.01712195,2.14315
9.92,41.33337,20.97995474,2.13936
9.96,41.50006,21.06546873,2.14808
10,41.66668,20.75763799,2.11669
10.04,41.83325,20.95141739,2.13645
10.08,41.99999,21.07351019,2.1489
10.12,42.16681,20.87423906,2.12858
10.16,42.3335,20.92180131,2.13343
10.2,42.50005,21.03222419,2.14469
10.24,42.66656,20.86864927,2.12801
10.28,42.83318,21.08929889,2.15051
10.32,43.00006,21.49225414,2.1916
10.36,43.16675,21.19011125,2.16079
10.4,43.33337,21.11764011,2.1534
10.44,43.50006,21.35201905,2.1773
10.48,43.66662,21.30553552,2.17256
10.52,43.83324,21.42292112,2.18453
10.56,44,21.32132423,2.17417
10.6,44.16674,21.34427179,2.17651
10.64,44.33337,21.49519614,2.1919
10.68,44.49999,21.42458826,2.1847
10.72,44.66656,21.57070734,2.1996
10.76,44.83324,21.56560788,2.19908
10.8,45.00006,21.6738733,2.21012
10.84,45.16675,21.62631105,2.20527
10.88,45.33324,21.58433858,2.20099
10.92,45.49999,21.6112088,2.20373
10.96,45.66668,21.60316735,2.20291
11,45.83337,21.55403604,2.1979
11.04,46.00006,21.68721034,2.21148
11.08,46.16662,21.7520323,2.21809
11.12,46.33325,21.84088055,2.22715
11.16,46.49999,21.98337117,2.24168
11.2,46.66674,22.02799143,2.24623
11.24,46.83337,21.88530467,2.23168
11.28,47.00006,21.84509741,2.22758
11.32,47.16668,22.07153296,2.25067
11.36,47.33331,21.76507514,2.21942
11.4,47.50005,22.07172909,2.25069
11.44,47.66674,22.11036729,2.25463
11.48,47.8333,21.90736963,2.23393
11.52,47.99999,21.96758247,2.24007
11.56,48.16662,22.19450835,2.26321
11.6,48.3333,22.19931361,2.2637
11.64,48.50006,22.27394221,2.27131
11.68,48.66675,22.11644741,2.25525
11.72,48.83324,22.36475179,2.28057
11.76,48.99993,22.12095847,2.25571
11.8,49.16668,22.36916478,2.28102
11.84,49.33331,22.45399231,2.28967
11.88,49.5,22.58089036,2.30261
11.92,49.66668,22.4783128,2.29215
11.96,49.83325,22.51057668,2.29544
12,49.99993,22.48311806,2.29264
12.04,50.16668,22.69592236,2.31434
12.08,50.33331,22.56255192,2.30074
12.12,50.50005,22.62080342,2.30668
12.16,50.66674,22.50635982,2.29501
12.2,50.83337,22.77143357,2.32204
12.24,50.99999,22.73436443,2.31826
12.28,51.16662,22.66012809,2.31069
12.32,51.33331,22.75672359,2.32054
12.36,51.50005,22.88881917,2.33401
12.4,51.66668,22.89068243,2.3342
12.44,51.8333,22.80408971,2.32537
12.48,52.00006,22.82066295,2.32706
12.52,52.16674,23.07230159,2.35272
12.56,52.33331,23.05778775,2.35124
12.6,52.49999,22.98002101,2.34331
12.64,52.66662,22.97207763,2.3425
12.68,52.83337,23.08406957,2.35392
12.72,53.00011,22.99198512,2.34453
12.76,53.16662,23.17644821,2.36334
12.8,53.33318,23.18988332,2.36471
12.84,53.49993,23.17801728,2.3635
12.88,53.66674,23.23666104,2.36948
12.92,53.83337,23.23175772,2.36898
12.96,54.00006,23.24990002,2.37083
13,54.16668,23.52742821,2.39913
13.04,54.33324,23.57204847,2.40368
13.08,54.49993,23.55076804,2.40151
13.12,54.66668,23.5576327,2.40221
13.16,54.83331,23.73523113,2.42032
13.2,55.00006,23.34345546,2.38037
13.24,55.16662,23.5192887,2.3983
13.28,55.33325,23.72248248,2.41902
13.32,55.50005,23.58175706,2.40467
13.36,55.66674,23.55361197,2.4018
13.4,55.83331,23.80623127,2.42756
13.44,55.99999,23.64040082,2.41065
13.48,56.16668,23.74886237,2.42171
13.52,56.3333,23.82241225,2.42921
13.56,56.50006,23.969512,2.44421
13.6,56.66674,23.96303961,2.44355
13.64,56.83331,23.84124101,2.43113
13.68,56.99999,23.79720916,2.42664
13.72,57.16668,23.99265569,2.44657
13.76,57.3333,24.03962954,2.45136
13.8,57.50006,24.1454433,2.46215
13.84,57.66674,24.35559981,2.48358
13.88,57.83331,24.37982223,2.48605
13.92,57.99993,24.24537306,2.47234
13.96,58.16668,24.22075837,2.46983
14,58.33337,24.22252357,2.47001
14.04,58.50005,24.22016997,2.46977
14.08,58.66668,24.36452386,2.48449
14.12,58.83324,24.36020893,2.48405
14.16,58.99999,24.39100181,2.48719
14.2,59.16681,24.33275031,2.48125
14.24,59.33343,24.54153389,2.50254
14.28,59.49999,24.83681212,2.53265
14.32,59.66649,24.62832274,2.51139
14.36,59.83318,24.65195677,2.5138
14.4,60.00006,24.60007959,2.50851
14.44,60.16681,24.68274965,2.51694
14.48,60.33337,24.62900921,2.51146
14.52,60.5,24.66578415,2.51521
14.56,60.66662,24.92085511,2.54122
14.6,60.83325,25.00882076,2.55019
14.64,61.00005,24.68029799,2.51669
14.68,61.16674,24.93899742,2.54307
14.72,61.33337,25.19593165,2.56927
14.76,61.49999,24.81435489,2.53036
14.8,61.66662,24.93860515,2.54303
14.84,61.8333,25.00028898,2.54932
14.88,62.00006,25.21574108,2.57129
14.92,62.16674,25.27350225,2.57718
14.96,62.33331,25.2051499,2.57021
15,62.49999,25.38461159,2.58851
15.04,62.66674,25.30154927,2.58004
15.08,62.83336,25.50611599,2.6009
15.12,63.00006,25.45335621,2.59552
15.16,63.16661,25.41383541,2.59149
15.2,63.33324,25.60477088,2.61096
15.24,63.49999,25.74843831,2.62561
15.28,63.66674,25.49248474,2.59951
15.32,63.83337,25.65831519,2.61642
15.36,63.99999,25.78639004,2.62948
15.4,64.16667,25.79551023,2.63041
15.44,64.33324,25.56181776,2.60658
15.48,64.49999,25.77442593,2.62826
15.52,64.66674,25.77972152,2.6288
15.56,64.8333,25.80355168,2.63123
15.6,64.99999,25.84160148,2.63511
15.64,65.16661,25.99399682,2.65065
15.68,65.3333,25.93711825,2.64485
15.72,65.50005,25.99497749,2.65075
15.76,65.66674,25.97428546,2.64864
15.8,65.83324,25.96134068,2.64732
15.84,65.99999,25.7742298,2.62824
15.88,66.16674,26.11079402,2.66256
15.92,66.33336,26.15413942,2.66698
15.96,66.50005,26.17836184,2.66945
16,66.66668,26.21209672,2.67289
16.04,66.83324,26.3579216,2.68776
16.08,66.99999,26.48580032,2.7008
16.12,67.16674,26.54846481,2.70719
16.16,67.33336,26.37321998,2.68932
16.2,67.50006,26.58671075,2.71109
16.24,67.66674,26.4556939,2.69773
16.28,67.83336,26.61622877,2.7141
16.32,67.99999,26.55297587,2.70765
16.36,68.16661,26.52286946,2.70458
16.4,68.3333,26.53757943,2.70608
16.44,68.49999,26.59004501,2.71143
16.48,68.66661,26.69821236,2.72246
16.52,68.8333,26.86472928,2.73944
16.56,69.00005,26.77999982,2.7308
16.6,69.16668,26.97652509,2.75084
16.64,69.33324,26.99368672,2.75259
16.68,69.49992,26.85835495,2.73879
16.72,69.66662,26.99378479,2.7526
16.76,69.83336,26.88689231,2.7417
16.8,70.00005,27.09646042,2.76307
16.84,70.16661,26.99819778,2.75305
16.88,70.33318,26.9489684,2.74803
16.92,70.50005,27.21110015,2.77476
16.96,70.66674,27.18011114,2.7716
17,70.83336,27.36074963,2.79002
17.04,71.00006,27.36781042,2.79074
17.08,71.16674,27.22796759,2.77648
17.12,71.33331,27.38752179,2.79275
17.16,71.49999,27.693097,2.82391
17.2,71.66667,27.71849623,2.8265
17.24,71.83337,27.7335004,2.82803
17.28,72.00005,27.62592145,2.81706
17.32,72.16667,27.77645353,2.83241
17.36,72.3333,27.71918269,2.82657
17.4,72.50005,27.56217822,2.81056
17.44,72.66674,27.88530734,2.84351
17.48,72.8333,27.96513347,2.85165
17.52,72.99999,27.99592635,2.85479
17.56,73.16662,27.82480031,2.83734
17.6,73.33324,27.95120803,2.85023
17.64,73.50005,28.07947901,2.86331
17.68,73.66674,28.11703848,2.86714
17.72,73.8333,28.05476625,2.86079
17.76,73.99999,28.23177629,2.87884
17.8,74.16661,28.10095558,2.8655
17.84,74.3333,28.33033312,2.88889
17.88,74.50006,28.36534286,2.89246
17.92,74.66674,28.35985114,2.8919
17.96,74.83324,28.29689244,2.88548
18,74.99993,28.40829599,2.89684
18.04,75.16674,28.59423007,2.9158
18.08,75.33337,28.72004939,2.92863
18.12,75.50005,28.45213171,2.90131
18.16,75.66668,28.78859787,2.93562
18.2,75.83324,28.59942759,2.91633
18.24,76.00005,28.68356865,2.92491
18.28,76.16686,28.6529719,2.92179
18.32,76.33343,28.76202185,2.93291
18.36,76.49993,28.64277299,2.92075
18.4,76.66655,28.79036307,2.9358
18.44,76.8333,29.00012731,2.95719
18.48,77.00011,28.96286204,2.95339
18.52,77.1668,28.76986717,2.93371
18.56,77.33336,29.11918004,2.96933
18.6,77.49998,29.20783216,2.97837
18.64,77.66668,29.19223959,2.97678
18.68,77.83331,29.5566547,3.01394
18.72,77.99999,29.2255822,2.98018
18.76,78.16673,29.25823834,2.98351
18.8,78.3333,29.41200661,2.99919
18.84,78.49999,29.44623182,3.00268
18.88,78.66655,29.37199548,2.99511
18.92,78.8333,29.68286629,3.02681
18.96,79.00004,29.6342253,3.02185
19,79.16667,29.53360907,3.01159
19.04,79.33323,29.76543828,3.03523
19.08,79.49999,29.61863273,3.02026
19.12,79.66667,29.90037778,3.04899
19.16,79.8333,29.75180704,3.03384
19.2,79.99999,29.88968854,3.0479
19.24,80.16662,30.07885881,3.06719
19.28,80.33324,29.85928792,3.0448
19.32,80.50005,29.98559757,3.05768
19.36,80.6668,29.98598984,3.05772
19.4,80.83336,30.10739617,3.0701
19.44,80.99998,30.21203312,3.08077
19.48,81.16661,30.23449035,3.08306
19.52,81.3333,30.29695871,3.08943
19.56,81.50005,30.31971014,3.09175
19.6,81.66674,30.23164642,3.08277
19.64,81.8333,30.24920032,3.08456
19.68,81.99998,30.43003495,3.103
19.72,82.16668,30.39963434,3.0999
19.76,82.33336,30.57487917,3.11777
19.8,82.50011,30.58645102,3.11895
19.84,82.66667,30.55909046,3.11616
19.88,82.83324,30.81690729,3.14245
19.92,82.99992,30.77464063,3.13814
19.96,83.16674,30.74933947,3.13556
20,83.3333,30.86495988,3.14735
20.04,83.49999,31.05648375,3.16688
20.08,83.66668,31.05599342,3.16683
20.12,83.83323,30.95165066,3.15619
20.16,83.99999,31.11247972,3.17259
20.2,84.16668,31.19622851,3.18113
20.24,84.3333,31.22064707,3.18362
20.28,84.49999,31.2823309,3.18991
20.32,84.66667,31.32695116,3.19446
20.36,84.8333,31.39863777,3.20177
20.4,84.99992,31.45149561,3.20716
20.44,85.16661,31.40511016,3.20243
20.48,85.3333,31.14062481,3.17546
20.52,85.49999,31.47463931,3.20952
20.56,85.66667,31.42668479,3.20463
20.6,85.83336,31.53799027,3.21598
20.64,86.00005,31.66763418,3.2292
20.68,86.16674,31.59957603,3.22226
20.72,86.3333,31.53406761,3.21558
20.76,86.49993,31.68665908,3.23114
20.8,86.66667,31.90466091,3.25337
20.84,86.83342,31.80169109,3.24287
20.88,87.00005,31.75030424,3.23763
20.92,87.16661,32.12187821,3.27552
20.96,87.33324,31.99086136,3.26216
21,87.49999,32.16679267,3.2801
21.04,87.66667,32.02861697,3.26601
21.08,87.8333,31.95742069,3.25875
21.12,88.00005,32.27044896,3.29067
21.16,88.16661,32.07294302,3.27053
21.2,88.33324,32.16806753,3.28023
21.24,88.49998,32.31938414,3.29566
21.28,88.66668,32.29722111,3.2934
21.32,88.83336,32.33478058,3.29723
21.36,88.99999,32.47246595,3.31127
21.4,89.16661,32.4620709,3.31021
21.44,89.33323,32.60818998,3.32511
21.48,89.50005,32.78833814,3.34348
21.52,89.66674,32.83903852,3.34865
21.56,89.83323,32.70282415,3.33476
21.6,89.99993,32.67046221,3.33146
21.64,90.16661,32.59622587,3.32389
21.68,90.3333,33.01418529,3.36651
21.72,90.50005,32.97956782,3.36298
21.76,90.66674,33.10126834,3.37539
21.8,90.8333,32.8106973,3.34576
21.84,90.99999,33.0888139,3.37412
21.88,91.16674,33.0492931,3.37009
21.92,91.3333,33.3452578,3.40027
21.96,91.50005,33.45273868,3.41123
22,91.66674,33.31024806,3.3967
22.04,91.8333,33.23875758,3.38941
22.08,91.99998,33.26307807,3.39189
22.12,92.16674,33.49196528,3.41523
22.16,92.33336,33.26641233,3.39223
22.2,92.50005,33.42606459,3.40851
22.24,92.66661,33.67495737,3.43389
22.28,92.83324,33.6739767,3.43379
22.32,92.99998,33.61788267,3.42807
22.36,93.1668,33.84078782,3.4508
22.4,93.33336,33.82176292,3.44886
22.44,93.49986,33.69309967,3.43574
22.48,93.66655,33.82235132,3.44892
22.52,93.83329,33.99092763,3.46611
22.56,94.00005,34.0112274,3.46818
22.6,94.16673,33.99789035,3.46682
22.64,94.33337,34.05996645,3.47315
22.68,94.49992,34.16313241,3.48367
22.72,94.66661,34.07251896,3.47443
22.76,94.8333,34.34298637,3.50201
22.8,95.00004,34.23962428,3.49147
22.84,95.16673,34.2433508,3.49185
22.88,95.3333,34.52372293,3.52044
22.92,95.49992,34.48351566,3.51634
22.96,95.66661,34.61580737,3.52983
23,95.83335,34.59236948,3.52744
23.04,96.00011,34.53323538,3.52141
23.08,96.16667,34.58756422,3.52695
23.12,96.3333,34.81978569,3.55063
23.16,96.49999,35.08181938,3.57735
23.2,96.66674,34.76879111,3.54543
23.24,96.83336,34.91559666,3.5604
23.28,96.99998,34.78252042,3.54683
23.32,97.16667,34.8326324,3.55194
23.36,97.3333,35.00297391,3.56931
23.4,97.50005,35.17351156,3.5867
23.44,97.66674,35.17243282,3.58659
23.48,97.83329,34.96727771,3.56567
23.52,97.99998,35.19263452,3.58865
23.56,98.16661,34.94844894,3.56375
23.6,98.33329,35.0662268,3.57576
23.64,98.50005,35.24068711,3.59355
23.68,98.66667,35.2439233,3.59388
23.72,98.83324,35.40367363,3.61017
23.76,98.99992,35.49683681,3.61967
23.8,99.16667,35.51919597,3.62195
23.84,99.3333,35.66335372,3.63665
23.88,99.50005,35.68767421,3.63913
23.92,99.66668,35.64795728,3.63508
23.96,99.83324,35.84918974,3.6556
24,99.99998,35.66158853,3.63647
24.04,100.16673,35.80309849,3.6509
24.08,100.3333,35.86752818,3.65747
24.12,100.50005,36.10357424,3.68154
24.16,100.66673,36.1657484,3.68788
24.2,100.8333,35.96431981,3.66734
24.24,101.00004,35.97991238,3.66893
24.28,101.16674,35.97177287,3.6681
24.32,101.33336,36.17418212,3.68874
24.36,101.50004,36.37678751,3.7094
24.4,101.66674,36.29372518,3.70093
24.44,101.83336,36.48554326,3.72049
24.48,101.99999,36.45141612,3.71701
24.52,102.16667,36.36786346,3.70849
24.56,102.3333,36.8126931,3.75385
24.6,102.49998,36.68069559,3.74039
24.64,102.66667,36.69491524,3.74184
24.68,102.83336,36.61028385,3.73321
24.72,103.00005,36.77719303,3.75023
24.76,103.16667,36.73826063,3.74626
24.8,103.33324,36.8311296,3.75573
24.84,103.49993,36.97518929,3.77042
24.88,103.66674,36.99342966,3.77228
24.92,103.83342,36.91752619,3.76454
24.96,104.00005,36.98352495,3.77127
25,104.16655,37.18387481,3.7917
25.04,104.33324,37.14082361,3.78731
25.08,104.49998,37.24634317,3.79807
25.12,104.66673,37.01667142,3.77465
25.16,104.83329,37.36372877,3.81004
25.2,104.99999,37.3823614,3.81194
25.24,105.16661,37.34215414,3.80784
25.28,105.33324,37.49503981,3.82343
25.32,105.49999,37.58516292,3.83262
25.36,105.66674,37.44865436,3.8187
25.4,105.83336,37.57623887,3.83171
25.44,106.00004,37.73677373,3.84808
25.48,106.16668,37.73530273,3.84793
25.52,106.33335,37.81954186,3.85652
25.56,106.50011,37.9883143,3.87373
25.6,106.66673,37.71323777,3.84568
25.64,106.8333,38.05195946,3.88022
25.68,106.99999,38.07049403,3.88211
25.72,107.16667,37.79051417,3.85356
25.76,107.3333,37.80973521,3.85552
25.8,107.50005,38.07274956,3.88234
25.84,107.66674,38.22132031,3.89749
25.88,107.83323,38.28270994,3.90375
25.92,107.99993,38.39009276,3.9147
25.96,108.16667,38.48168687,3.92404
26,108.3333,38.27878728,3.90335
26.04,108.50005,38.598386,3.93594
26.08,108.66674,38.35027776,3.91064
26.12,108.83324,38.41421711,3.91716
26.16,108.99998,38.46580009,3.92242
26.2,109.16674,38.76323579,3.95275
26.24,109.33336,38.88071945,3.96473
26.28,109.49999,38.90651094,3.96736
26.32,109.66661,38.92533971,3.96928
26.36,109.83324,38.94544334,3.97133
26.4,110.00005,38.98751387,3.97562
26.44,110.16686,38.9716271,3.974
26.48,110.3333,39.04115625,3.98109
26.52,110.49986,39.16874077,3.9941
26.56,110.66655,39.25248956,4.00264
26.6,110.83336,38.99143653,3.97602
26.64,111.00011,39.07577372,3.98462
26.68,111.1668,39.36938482,4.01456
26.72,111.3333,39.3630105,4.01391
26.76,111.49992,39.38978266,4.01664
26.8,111.66661,39.48480909,4.02633
26.84,111.83336,39.31191786,4.0087
26.88,112.00004,39.52060337,4.02998
26.92,112.16674,39.49363508,4.02723
26.96,112.3333,39.66780118,4.04499
27,112.49992,39.74252786,4.05261
27.04,112.66661,39.83304324,4.06184
27.08,112.83336,39.83529877,4.06207
27.12,113.00005,39.9719054,4.076
27.16,113.16667,39.84726288,4.06329
27.2,113.33324,39.86599358,4.0652
27.24,113.49998,40.10429518,4.0895
27.28,113.66673,39.98994964,4.07784
27.32,113.8333,40.1285176,4.09197
27.36,113.99992,40.34857883,4.11441
27.4,114.16661,40.35691448,4.11526
27.44,114.33324,40.15715302,4.09489
27.48,114.49998,40.39368942,4.11901
27.52,114.66667,40.4253649,4.12224
27.56,114.8333,40.2488452,4.10424
27.6,114.99998,40.34504843,4.11405
27.64,115.1666,40.4601785,4.12579
27.68,115.3333,40.59168568,4.1392
27.72,115.50005,40.6785726,4.14806
27.76,115.66673,40.70406989,4.15066
27.8,115.83329,40.86372215,4.16694
27.84,115.99999,40.74790561,4.15513
27.88,116.16673,40.71024808,4.15129
27.92,116.33337,40.72584065,4.15288
27.96,116.50004,40.97061464,4.17784
28,116.66667,40.96129832,4.17689
28.04,116.83323,41.14909567,4.19604
28.08,117.00004,41.30776726,4.21222
28.12,117.16673,41.18067308,4.19926
28.16,117.33335,41.35885991,4.21743
28.2,117.50005,41.32394824,4.21387
28.24,117.66667,41.48399276,4.23019
28.28,117.83324,41.49497621,4.23131
28.32,117.99999,41.38131714,4.21972
28.36,118.16673,41.63511324,4.2456
28.4,118.3333,41.51733537,4.23359
28.44,118.50005,41.51498178,4.23335
28.48,118.66674,41.73965213,4.25626
28.52,118.8333,41.67129978,4.24929
28.56,118.99998,41.7543621,4.25776
28.6,119.16667,41.90067732,4.27268
28.64,119.33323,41.74220186,4.25652
28.68,119.49998,41.66943652,4.2491
28.72,119.66667,41.94431691,4.27713
28.76,119.83329,41.88783061,4.27137
28.8,120.00005,42.01070794,4.2839
28.84,120.16667,42.02885024,4.28575
28.88,120.33324,42.28343087,4.31171
28.92,120.49999,42.34295724,4.31778
28.96,120.6668,42.37345592,4.32089
29,120.83342,42.05532819,4.28845
29.04,120.99999,42.50094237,4.33389
29.08,121.16661,42.40062034,4.32366
29.12,121.33324,42.45651824,4.32936
29.16,121.50005,42.39532475,4.32312
29.2,121.66673,42.55429054,4.33933
29.24,121.83336,42.79269021,4.36364
29.28,122.00005,42.56125327,4.34004
29.32,122.16668,42.65608357,4.34971
29.36,122.3333,42.67187228,4.35132
29.4,122.49999,42.86310195,4.37082
29.44,122.66668,42.92537418,4.37717
29.48,122.8333,42.78151063,4.3625
29.52,122.99999,43.01098624,4.3859
29.56,123.16661,42.91801919,4.37642
29.6,123.3333,42.8538837,4.36988
29.64,123.50004,43.05442969,4.39033
29.68,123.66674,43.02030255,4.38685
29.72,123.8333,43.1085624,4.39585
29.76,123.99992,43.23536239,4.40878
29.8,124.16661,43.26399781,4.4117
29.84,124.3333,43.10640494,4.39563
29.88,124.50005,43.37579362,4.4231
29.92,124.66667,43.24487484,4.40975
29.96,124.83324,43.41305889,4.4269
30,124.99992,43.51563644,4.43736
30.04,125.16673,43.33637088,4.41908
30.08,125.33336,43.4018793,4.42576
30.12,125.50004,43.6223328,4.44824
30.16,125.66666,43.63282591,4.44931
30.2,125.83323,43.50906599,4.43669
30.24,126.00005,43.39815278,4.42538
30.28,126.16679,43.53083675,4.43891
30.32,126.33336,43.4211984,4.42773
30.36,126.50005,43.11444639,4.39645
30.4,126.6666,42.597734,4.34376
30.44,126.83329,27.52089223,2.80635
30.48,127.00011,-0.82768126,-0.0844
30.52,127.16685,-0.822974068,-0.08392
30.56,127.33328,-0.19024901,-0.0194
30.6,127.49985,0.000686466,0.00007
30.64,127.66661,-0.101694961,-0.01037
30.68,127.83329,0.005295591,0.00054
30.72,128.00003,0.008531786,0.00087
30.76,128.16672,-0.014513842,-0.00148
30.8,128.33329,0.074334407,0.00758
30.84,128.49991,-0.166614984,-0.01699
30.88,128.66661,-0.066096821,-0.00674
30.92,128.8333,-0.048444851,-0.00494
30.96,128.99998,-0.022947561,-0.00234
31,129.16672,-0.245656583,-0.02505
31.04,129.33329,-0.048248718,-0.00492
31.08,129.49985,0.020201699,0.00206
31.12,129.6666,-0.11012868,-0.01123
31.16,129.83336,-0.077668668,-0.00792
31.2,130.00011,-0.017357771,-0.00177
31.24,130.16666,-0.123956056,-0.01264
31.28,130.33323,0.026183756,0.00267
31.32,130.49997,-0.189562545,-0.01933
31.36,130.66679,-0.171616375,-0.0175
31.4,130.83336,-0.00784532,-0.0008
31.44,130.99998,-0.121798593,-0.01242
31.48,131.16667,-0.152199208,-0.01552
31.52,131.33329,-0.218786362,-0.02231
31.56,131.50004,-0.292826569,-0.02986
31.6,131.6668,-0.134645305,-0.01373
31.64,131.83328,-0.197702064,-0.02016
31.68,131.99999,-0.167791782,-0.01711
31.72,132.16667,-0.018730702,-0.00191
31.76,132.33329,-0.415017428,-0.04232
31.8,132.50004,-0.340781088,-0.03475
31.84,132.66667,-0.128565182,-0.01311
31.88,132.83323,-0.053936575,-0.0055
31.92,132.99991,-0.150237878,-0.01532
31.96,133.16668,-0.158475464,-0.01616
32,133.33336,-0.232025339,-0.02366
32.04,133.50004,-0.06080123,-0.0062
32.08,133.66667,-0.099733631,-0.01017
32.12,133.83323,-0.24938311,-0.02543
32.16,133.99998,-0.258111028,-0.02632
32.2,134.16673,-0.204370586,-0.02084
32.24,134.33336,0.101302695,0.01033
32.28,134.50004,0.000392266,0.00004
32.32,134.66661,0.167497582,0.01708
32.36,134.83323,-0.273311336,-0.02787
32.4,134.99998,-0.086886919,-0.00886
32.44,135.16674,0.046189322,0.00471
32.476,135.31673,0.158083198,0.01612