File: V_8/FR/RDSO FR Tensile 250.is_tens_RawData/Specimen_RawData_3.csv
Time,Extension,Load,
(sec),(mm),(N),(kgf)
0,0,0.059036033,0.00602
0.04,0.06806,0.659987545,0.0673
0.08,0.27781,1.511793164,0.15416
0.12,0.4825,2.104016758,0.21455
0.16,0.65512,2.71477492,0.27683
0.2,0.82412,3.181375327,0.32441
0.24,0.99487,3.829300692,0.39048
0.28,1.164,4.090549848,0.41712
0.32,1.33162,4.514099062,0.46031
0.36,1.49894,5.018357005,0.51173
0.4,1.666,5.321676689,0.54266
0.44,1.83294,5.736203785,0.58493
0.48,1.99987,6.052174048,0.61715
0.52,2.16669,6.348334878,0.64735
0.56,2.33312,7.011362484,0.71496
0.6,2.49987,7.172289611,0.73137
0.64,2.66669,7.07285018,0.72123
0.68,2.83337,7.542196449,0.76909
0.72,3.00006,7.902688903,0.80585
0.76,3.16675,7.977121376,0.81344
0.8,3.33325,8.431071205,0.85973
0.84,3.49994,8.691045496,0.88624
0.88,3.66669,8.904242067,0.90798
0.92,3.83337,9.025158062,0.92031
0.96,4.00006,9.213543808,0.93952
1,4.16669,9.332204273,0.95162
1.04,4.33325,9.65984445,0.98503
1.08,4.5,9.990230488,1.01872
1.12,4.66675,10.07721547,1.02759
1.16,4.83337,10.43731566,1.06431
1.2,5,10.40524792,1.06104
1.24,5.16662,10.59863505,1.08076
1.28,5.33325,10.81751948,1.10308
1.32,5.5,11.20674542,1.14277
1.36,5.66675,11.24146096,1.14631
1.4,5.83337,11.46770038,1.16938
1.44,6,11.98235337,1.22186
1.48,6.16669,11.76474381,1.19967
1.52,6.33331,11.91851208,1.21535
1.56,6.5,12.22222403,1.24632
1.6,6.66675,12.37226577,1.26162
1.64,6.83331,12.54309762,1.27904
1.68,7,12.56839877,1.28162
1.72,7.16662,12.62194308,1.28708
1.76,7.33337,12.86652093,1.31202
1.8,7.50006,13.02254473,1.32793
1.84,7.66675,13.21642221,1.3477
1.88,7.83331,13.49287167,1.37589
1.92,7.99994,13.6725295,1.39421
1.96,8.16669,13.257414,1.35188
2,8.33344,13.64134435,1.39103
2.04,8.50019,13.83316242,1.41059
2.08,8.66656,13.82139444,1.40939
2.12,8.83306,13.84630333,1.41193
2.16,9,14.06587423,1.43432
2.2,9.16675,14.19355681,1.44734
2.24,9.33337,14.2618111,1.4543
2.28,9.50006,14.23592154,1.45166
2.32,9.66662,14.3554646,1.46385
2.36,9.83319,14.39694673,1.46808
2.4,10,14.52139312,1.48077
2.44,10.16675,14.69673602,1.49865
2.48,10.33331,14.74086595,1.50315
2.52,10.50006,14.73331483,1.50238
2.56,10.66669,15.11420511,1.54122
2.6,10.83325,14.99623111,1.52919
2.64,11.00006,15.18942212,1.54889
2.68,11.16681,15.0044687,1.53003
2.72,11.33331,15.19609064,1.54957
2.76,11.49994,15.23600371,1.55364
2.8,11.66669,15.26375653,1.55647
2.84,11.83331,15.52667281,1.58328
2.88,12.00006,15.39045844,1.56939
2.92,12.16669,15.61777659,1.59257
2.96,12.33325,15.6710267,1.598
3,12.5,15.43115604,1.57354
3.04,12.66675,15.62905424,1.59372
3.08,12.83337,15.75869815,1.60694
3.12,13.00006,15.84744833,1.61599
3.16,13.16669,15.88745947,1.62007
3.2,13.33325,15.92443054,1.62384
3.24,13.49994,15.97640578,1.62914
3.28,13.66668,15.97846518,1.62935
3.32,13.83331,16.18587583,1.6505
3.36,14,16.02681196,1.63428
3.4,14.16662,16.23883174,1.6559
3.44,14.33325,16.30561502,1.66271
3.48,14.5,16.24373506,1.6564
3.52,14.66675,16.42868848,1.67526
3.56,14.83331,16.36386652,1.66865
3.6,14.99994,16.23569361,1.65558
3.64,15.16662,16.36661238,1.66893
3.68,15.33337,16.51812513,1.68438
3.72,15.50006,16.54460308,1.68708
3.76,15.66675,16.50812234,1.68336
3.8,15.83331,16.68670144,1.70157
3.84,16,16.98756946,1.73225
3.88,16.16669,16.87695045,1.72097
3.92,16.33331,16.80261604,1.71339
3.96,16.50006,16.9865888,1.73215
4,16.66668,17.0436635,1.73797
4.04,16.83337,16.94804866,1.72822
4.08,17.00006,17.05023396,1.73864
4.12,17.16669,16.87263552,1.72053
4.16,17.33325,16.68660337,1.70156
4.2,17.50006,17.01090929,1.73463
4.24,17.66669,17.09201029,1.7429
4.28,17.83331,17.21037655,1.75497
4.32,18.00006,17.23499124,1.75748
4.36,18.16675,17.16663889,1.75051
4.4,18.33331,17.33315581,1.76749
4.44,18.5,17.28784909,1.76287
4.48,18.66662,17.14526039,1.74833
4.52,18.83331,17.27255071,1.76131
4.56,19.00012,17.57792979,1.79245
4.6,19.16668,17.46799725,1.78124
4.64,19.33318,17.51036197,1.78556
4.68,19.49994,17.45103174,1.77951
4.72,19.66675,17.48457048,1.78293
4.76,19.83331,17.45917126,1.78034
4.8,20.00006,17.53105401,1.78767
4.84,20.16668,17.52683715,1.78724
4.88,20.33331,17.64706668,1.7995
4.92,20.5,17.79436256,1.81452
4.96,20.66668,17.73915112,1.80889
5,20.83331,17.70580851,1.80549
5.04,21.00006,17.77367053,1.81241
5.08,21.16675,17.74660417,1.80965
5.12,21.33331,17.68894107,1.80377
5.16,21.5,17.68158608,1.80302
5.2,21.66675,17.56802508,1.79144
5.24,21.83337,17.90890423,1.8262
5.28,22,18.05737691,1.84134
5.32,22.16668,17.89184066,1.82446
5.36,22.33325,17.91165009,1.82648
5.4,22.5,18.20006367,1.85589
5.44,22.66675,18.15750281,1.85155
5.48,22.83337,18.20506506,1.8564
5.52,23,18.06875263,1.8425
5.56,23.16668,18.04835479,1.84042
5.6,23.33331,18.17123212,1.85295
5.64,23.50006,18.32558879,1.86869
5.68,23.66675,18.33627804,1.86978
5.72,23.83331,18.36452119,1.87266
5.76,23.99993,18.30401416,1.86649
5.8,24.16662,18.20447666,1.85634
5.84,24.33337,18.64528558,1.90129
5.88,24.50006,18.43228514,1.87957
5.92,24.66668,18.20781092,1.85668
5.96,24.83325,18.31146721,1.86725
6,24.99993,18.34461369,1.87063
6.04,25.16675,18.39413727,1.87568
6.08,25.33343,18.34451562,1.87062
6.12,25.50006,18.5737951,1.894
6.16,25.66656,18.57399123,1.89402
6.2,25.83312,18.2626301,1.86227
6.24,26.00006,18.51534747,1.88804
6.28,26.16675,18.74894187,1.91186
6.32,26.33337,18.47160981,1.88358
6.36,26.50006,18.50652148,1.88714
6.4,26.66668,18.72148325,1.90906
6.44,26.83325,18.93595468,1.93093
6.48,27,18.93958315,1.9313
6.52,27.16674,18.67754946,1.90458
6.56,27.33337,18.76031758,1.91302
6.6,27.50006,18.76953583,1.91396
6.64,27.66668,18.88652917,1.92589
6.68,27.83325,19.00107084,1.93757
6.72,28.00006,18.98498793,1.93593
6.76,28.16675,19.05069249,1.94263
6.8,28.33331,18.86897527,1.9241
6.84,28.5,19.21642487,1.95953
6.88,28.66662,19.09080169,1.94672
6.92,28.83331,19.20661822,1.95853
6.96,29.00006,19.23044838,1.96096
7,29.16669,19.27281311,1.96528
7.04,29.33318,19.09040942,1.94668
7.08,29.5,19.19739997,1.95759
7.12,29.66675,19.2397647,1.96191
7.16,29.83337,19.11590671,1.94928
7.2,30.00006,19.21279641,1.95916
7.24,30.16668,19.27045952,1.96504
7.28,30.33325,19.36980088,1.97517
7.32,30.49999,19.26938078,1.96493
7.36,30.66675,19.29968333,1.96802
7.4,30.83337,19.415696,1.97985
7.44,31,19.41167528,1.97944
7.48,31.16668,19.46816158,1.9852
7.52,31.33331,19.3018408,1.96824
7.56,31.50006,19.47767403,1.98617
7.6,31.66674,19.69371453,2.0082
7.64,31.83331,19.45658973,1.98402
7.68,31.99993,19.5963345,1.99827
7.72,32.16668,19.65419373,2.00417
7.76,32.33337,19.58682205,1.9973
7.8,32.50006,19.73637346,2.01255
7.84,32.66668,19.71215103,2.01008
7.88,32.83331,19.69430293,2.00826
7.92,33,19.80756974,2.01981
7.96,33.16668,19.66488298,2.00526
8,33.33331,19.93544845,2.03285
8.04,33.49999,20.05155919,2.04469
8.08,33.66668,19.82129905,2.02121
8.12,33.83337,19.83924522,2.02304
8.16,34.00006,19.81855318,2.02093
8.2,34.16662,19.84189301,2.02331
8.24,34.33324,20.11343915,2.051
8.28,34.49999,19.89092626,2.02831
8.32,34.66668,20.04606746,2.04413
8.36,34.83331,20.07146669,2.04672
8.4,35.00006,20.02910196,2.0424
8.44,35.16675,20.17090612,2.05686
8.48,35.33325,19.9060285,2.02985
8.52,35.49999,20.07637001,2.04722
8.56,35.66662,19.93172193,2.03247
8.6,35.83331,20.15972654,2.05572
8.64,36.00012,20.33575591,2.07367
8.68,36.16668,20.35634987,2.07577
8.72,36.33318,20.32192853,2.07226
8.76,36.5,20.3006481,2.07009
8.8,36.66668,20.34095343,2.0742
8.84,36.83337,20.11167395,2.05082
8.88,37.00006,20.27024748,2.06699
8.92,37.16674,20.41146324,2.08139
8.96,37.33324,20.53855743,2.09435
9,37.49999,20.65476623,2.1062
9.04,37.66668,20.70066135,2.11088
9.08,37.83337,20.593965,2.1
9.12,38.00006,20.67761572,2.10853
9.16,38.16668,20.72939484,2.11381
9.2,38.33324,20.63485873,2.10417
9.24,38.5,20.69899422,2.11071
9.28,38.66674,20.70036715,2.11085
9.32,38.83331,20.78313528,2.11929
9.36,38.99999,20.7716615,2.11812
9.4,39.16662,20.78813667,2.1198
9.44,39.33324,20.79235353,2.12023
9.48,39.49999,20.84844757,2.12595
9.52,39.66675,20.84148485,2.12524
9.56,39.8333,20.92415491,2.13367
9.6,39.99999,20.9276853,2.13403
9.64,40.16662,20.97358042,2.13871
9.68,40.33331,20.91513279,2.13275
9.72,40.50006,20.97289396,2.13864
9.76,40.66675,21.32014743,2.17405
9.8,40.8333,21.07478505,2.14903
9.84,40.99999,20.94249334,2.13554
9.88,41.16668,20.87884818,2.12905
9.92,41.33337,21.12372023,2.15402
9.96,41.50006,21.33456321,2.17552
10,41.66668,21.35192098,2.17729
10.04,41.83325,21.26944705,2.16888
10.08,41.99999,21.28298023,2.17026
10.12,42.16681,21.41154541,2.18337
10.16,42.3335,21.35270551,2.17737
10.2,42.50005,21.35172485,2.17727
10.24,42.66656,21.43057031,2.18531
10.28,42.83318,21.33309221,2.17537
10.32,43.00006,21.24218457,2.1661
10.36,43.16675,21.51186744,2.1936
10.4,43.33337,21.52530255,2.19497
10.44,43.50006,21.52902908,2.19535
10.48,43.66662,21.60552095,2.20315
10.52,43.83324,21.70486231,2.21328
10.56,44,21.52412575,2.19485
10.6,44.16674,21.62817431,2.20546
10.64,44.33331,21.66995064,2.20972
10.68,44.49999,21.70466618,2.21326
10.72,44.66656,21.76066215,2.21897
10.76,44.83324,21.82411118,2.22544
10.8,45.00006,21.99661015,2.24303
10.84,45.16675,21.81106833,2.22411
10.88,45.33324,22.09310759,2.25287
10.92,45.49999,21.95767775,2.23906
10.96,45.66674,22.07869181,2.2514
11,45.83337,22.1044833,2.25403
11.04,46.00006,22.05535198,2.24902
11.08,46.16662,21.88383367,2.23153
11.12,46.33325,22.03171796,2.24661
11.16,46.49999,22.32071993,2.27608
11.2,46.66681,22.1062485,2.25421
11.24,46.83337,22.12733279,2.25636
11.28,47.00006,22.21235645,2.26503
11.32,47.16668,22.07780921,2.25131
11.36,47.33331,22.09448052,2.25301
11.4,47.50005,22.33601831,2.27764
11.44,47.66674,22.41633477,2.28583
11.48,47.8333,22.53185711,2.29761
11.52,47.99999,22.40829332,2.28501
11.56,48.16662,22.42878922,2.2871
11.6,48.3333,22.46409316,2.2907
11.64,48.49999,22.44801025,2.28906
11.68,48.66675,22.58569562,2.3031
11.72,48.83324,22.56961271,2.30146
11.76,48.99993,22.48890398,2.29323
11.8,49.16668,22.5954042,2.30409
11.84,49.33331,22.8114447,2.32612
11.88,49.5,22.71151493,2.31593
11.92,49.66662,22.69788369,2.31454
11.96,49.83325,22.8714614,2.33224
12,49.99993,22.74191555,2.31903
12.04,50.16668,22.82968507,2.32798
12.08,50.33331,22.67483806,2.31219
12.12,50.50005,22.96236904,2.34151
12.16,50.66674,22.96678203,2.34196
12.2,50.83337,22.86410641,2.33149
12.24,50.99999,22.9680569,2.34209
12.28,51.16662,23.07396872,2.35289
12.32,51.33331,23.16428797,2.3621
12.36,51.49999,22.9657033,2.34185
12.4,51.66662,23.18743166,2.36446
12.44,51.83337,23.17242748,2.36293
12.48,52.00006,22.9487378,2.34012
12.52,52.16674,23.01679595,2.34706
12.56,52.33331,23.42436032,2.38862
12.6,52.49993,23.24990002,2.37083
12.64,52.66662,23.23960304,2.36978
12.68,52.83337,23.3202137,2.378
12.72,53.00011,23.32796095,2.37879
12.76,53.16662,23.50663812,2.39701
12.8,53.33318,23.53958846,2.40037
12.84,53.49993,23.40151083,2.38629
12.88,53.66674,23.49202621,2.39552
12.92,53.83337,23.66315225,2.41297
12.96,54.00006,23.71787336,2.41855
13,54.16668,23.85673552,2.43271
13.04,54.33324,23.88007535,2.43509
13.08,54.49993,23.81103653,2.42805
13.12,54.66668,24.04580773,2.45199
13.16,54.83331,24.03354942,2.45074
13.2,55.00006,23.76729887,2.42359
13.24,55.16662,23.97922058,2.4452
13.28,55.33325,23.95637109,2.44287
13.32,55.50005,24.11033549,2.45857
13.36,55.66674,23.9498987,2.44221
13.4,55.83331,23.888411,2.43594
13.44,55.99999,24.01628972,2.44898
13.48,56.16668,24.1624088,2.46388
13.52,56.3333,24.17084252,2.46474
13.56,56.50006,24.17486325,2.46515
13.6,56.66674,24.23644901,2.47143
13.64,56.83331,24.44591905,2.49279
13.68,56.99999,24.25625844,2.47345
13.72,57.16668,24.46455169,2.49469
13.76,57.3333,24.61008237,2.50953
13.8,57.50006,24.61871223,2.51041
13.84,57.66674,24.33686911,2.48167
13.88,57.83331,24.44542872,2.49274
13.92,57.99993,24.56624665,2.50506
13.96,58.16668,24.518096,2.50015
14,58.33337,24.81592396,2.53052
14.04,58.50005,24.73982435,2.52276
14.08,58.66668,24.71138507,2.51986
14.12,58.83318,24.80033138,2.52893
14.16,58.99993,24.62341942,2.51089
14.2,59.16681,24.64901478,2.5135
14.24,59.33343,24.90791034,2.5399
14.28,59.49999,24.99626825,2.54891
14.32,59.66649,24.91859958,2.54099
14.36,59.83318,25.21858501,2.57158
14.4,60.00006,25.1823004,2.56788
14.44,60.16681,24.95243253,2.54444
14.48,60.33337,24.92477777,2.54162
14.52,60.5,25.30831585,2.58073
14.56,60.66662,25.09835548,2.55932
14.6,60.83325,25.221527,2.57188
14.64,61.00005,25.31704377,2.58162
14.68,61.16674,25.30870812,2.58077
14.72,61.33331,25.40834368,2.59093
14.76,61.49999,25.32979242,2.58292
14.8,61.66662,25.48512975,2.59876
14.84,61.8333,25.50435079,2.60072
14.88,62.00006,25.48856208,2.59911
14.92,62.16674,25.69940506,2.62061
14.96,62.33331,25.67900722,2.61853
15,62.50005,25.6738097,2.618
15.04,62.66674,25.82944124,2.63387
15.08,62.83336,25.67125997,2.61774
15.12,63.00006,25.83650202,2.63459
15.16,63.16668,25.92839033,2.64396
15.2,63.33324,25.92270248,2.64338
15.24,63.50006,26.08529673,2.65996
15.28,63.66674,25.96585174,2.64778
15.32,63.83337,26.00851066,2.65213
15.36,63.99999,25.93652985,2.64479
15.4,64.16667,26.13060346,2.66458
15.44,64.33324,26.25769764,2.67754
15.48,64.50005,26.05744585,2.65712
15.52,64.66674,26.13648745,2.66518
15.56,64.8333,26.1228562,2.66379
15.6,64.99999,26.34262323,2.6862
15.64,65.16661,26.23729981,2.67546
15.68,65.3333,26.3412503,2.68606
15.72,65.50005,26.44225879,2.69636
15.76,65.66674,26.70595961,2.72325
15.8,65.83324,26.66035869,2.7186
15.84,65.99999,26.56513612,2.70889
15.88,66.16674,26.73743896,2.72646
15.92,66.33336,26.4571649,2.69788
15.96,66.50005,26.50835562,2.7031
16,66.66668,26.74665721,2.7274
16.04,66.83331,26.92445177,2.74553
16.08,67.00005,26.82736594,2.73563
16.12,67.16674,26.77411583,2.7302
16.16,67.33336,27.1085226,2.7643
16.2,67.49999,27.2015877,2.77379
16.24,67.66674,27.04105284,2.75742
16.28,67.8333,26.78833547,2.73165
16.32,67.99999,26.81579409,2.73445
16.36,68.16661,27.05733188,2.75908
16.4,68.3333,27.23532258,2.77723
16.44,68.49999,27.2244372,2.77612
16.48,68.66661,27.15794811,2.76934
16.52,68.8333,27.19678245,2.7733
16.56,69.00005,27.29298568,2.78311
16.6,69.16668,27.47950816,2.80213
16.64,69.33324,27.3608477,2.79003
16.68,69.49992,27.58296832,2.81268
16.72,69.66662,27.30936279,2.78478
16.76,69.83336,27.51079138,2.80532
16.8,70.00005,27.64798641,2.81931
16.84,70.16661,27.72898934,2.82757
16.88,70.33318,27.69231247,2.82383
16.92,70.49999,27.79067317,2.83386
16.96,70.66674,27.65671433,2.8202
17,70.83336,27.73477526,2.82816
17.04,71.00006,28.00436007,2.85565
17.08,71.16668,27.89236813,2.84423
17.12,71.33331,28.01132279,2.85636
17.16,71.49999,27.96081855,2.85121
17.2,71.66667,27.91325629,2.84636
17.24,71.83337,28.04947066,2.86025
17.28,72.00005,28.03878141,2.85916
17.32,72.16667,27.99847608,2.85505
17.36,72.3333,28.39564541,2.89555
17.4,72.50005,28.30208997,2.88601
17.44,72.66674,28.27776947,2.88353
17.48,72.8333,28.37495338,2.89344
17.52,72.99999,28.52411252,2.90865
17.56,73.16662,28.51499234,2.90772
17.6,73.33324,28.59834886,2.91622
17.64,73.50005,28.53097718,2.90935
17.68,73.66674,28.68955071,2.92552
17.72,73.8333,28.77310337,2.93404
17.76,73.99999,28.52372026,2.90861
17.8,74.16661,28.63120114,2.91957
17.84,74.3333,28.68817778,2.92538
17.88,74.50006,28.97404162,2.95453
17.92,74.66668,28.87950552,2.94489
17.96,74.83324,28.96237171,2.95334
18,74.99999,28.96256784,2.95336
18.04,75.16674,28.84783004,2.94166
18.08,75.33337,29.15585692,2.97307
18.12,75.50005,28.89696136,2.94667
18.16,75.66668,29.02552654,2.95978
18.2,75.83324,29.18968986,2.97652
18.24,76.00005,29.31894151,2.9897
18.28,76.16686,29.32982689,2.99081
18.32,76.33343,29.26520106,2.98422
18.36,76.49993,29.29972047,2.98774
18.4,76.66655,29.50595432,3.00877
18.44,76.8333,29.5399834,3.01224
18.48,77.00011,29.74023519,3.03266
18.52,77.1668,29.5774448,3.01606
18.56,77.33336,29.66805825,3.0253
18.6,77.50005,29.78495351,3.03722
18.64,77.66668,29.84467601,3.04331
18.68,77.83324,29.83741909,3.04257
18.72,77.99999,29.92273695,3.05127
18.76,78.16673,29.76337888,3.03502
18.8,78.3333,29.97873292,3.05698
18.84,78.49999,30.07003283,3.06629
18.88,78.66655,30.07856461,3.06716
18.92,78.8333,30.11357435,3.07073
18.96,79.00004,30.33961764,3.09378
19,79.16674,30.25684951,3.08534
19.04,79.33323,30.08640993,3.06796
19.08,79.49992,30.42660262,3.10265
19.12,79.66667,30.1043561,3.06979
19.16,79.8333,30.41542304,3.10151
19.2,79.99999,30.55320647,3.11556
19.24,80.16662,30.50299643,3.11044
19.28,80.33324,30.64303539,3.12472
19.32,80.50005,30.46053363,3.10611
19.36,80.6668,30.42218963,3.1022
19.4,80.83336,30.59174661,3.11949
19.44,80.99998,30.68236005,3.12873
19.48,81.16661,30.53977136,3.11419
19.52,81.3333,30.6725534,3.12773
19.56,81.50005,30.9328219,3.15427
19.6,81.66674,30.99529026,3.16064
19.64,81.8333,31.04952103,3.16617
19.68,81.99998,31.02000301,3.16316
19.72,82.16668,31.14337067,3.17574
19.76,82.33336,31.07492025,3.16876
19.8,82.50005,31.13925188,3.17532
19.84,82.66667,31.21358629,3.1829
19.88,82.83324,31.24643856,3.18625
19.92,82.99999,31.42217373,3.20417
19.96,83.16674,31.25261675,3.18688
20,83.3333,31.42854805,3.20482
20.04,83.49999,31.51808277,3.21395
20.08,83.66668,31.56603729,3.21884
20.12,83.83323,31.47150118,3.2092
20.16,83.99999,31.50533412,3.21265
20.2,84.16668,31.63056504,3.22542
20.24,84.3333,31.59025971,3.22131
20.28,84.49999,31.69136627,3.23162
20.32,84.66667,31.89250066,3.25213
20.36,84.8333,31.7753112,3.24018
20.4,84.99992,31.74559705,3.23715
20.44,85.16661,31.91711536,3.25464
20.48,85.3333,31.97105193,3.26014
20.52,85.49999,31.83895636,3.24667
20.56,85.66667,32.09206599,3.27248
20.6,85.83336,31.94584884,3.25757
20.64,86.00005,32.14266831,3.27764
20.68,86.16674,32.23583148,3.28714
20.72,86.3333,32.16336034,3.27975
20.76,86.49993,32.36174887,3.29998
20.8,86.66667,32.285257,3.29218
20.84,86.83342,32.23730248,3.28729
20.88,87.00011,32.42186363,3.30611
20.92,87.16661,32.52336246,3.31646
20.96,87.33324,32.43990787,3.30795
21,87.49999,32.56857112,3.32107
21.04,87.66674,32.52542186,3.31667
21.08,87.8333,32.60583639,3.32487
21.12,88.00005,32.82423048,3.34714
21.16,88.16661,32.86512421,3.35131
21.2,88.33324,32.74803281,3.33937
21.24,88.49998,32.80442105,3.34512
21.28,88.66673,32.71449407,3.33595
21.32,88.83336,33.11548799,3.37684
21.36,89.00005,32.91043093,3.35593
21.4,89.16661,32.93847795,3.35879
21.44,89.33323,33.04742984,3.3699
21.48,89.50005,33.03036626,3.36816
21.52,89.66674,33.17236656,3.38264
21.56,89.83323,33.32338897,3.39804
21.6,89.99993,33.30416793,3.39608
21.64,90.16661,33.37457968,3.40326
21.68,90.3333,33.43037952,3.40895
21.72,90.50005,33.47607851,3.41361
21.76,90.66674,33.57934253,3.42414
21.8,90.8333,33.58238259,3.42445
21.84,90.99999,33.68015489,3.43442
21.88,91.16674,33.61062574,3.42733
21.92,91.3333,33.80548388,3.4472
21.96,91.50005,33.86255858,3.45302
22,91.66674,33.93924659,3.46084
22.04,91.8333,33.64024183,3.43035
22.08,91.99998,33.88766361,3.45558
22.12,92.16674,33.96366514,3.46333
22.16,92.33336,34.32670733,3.50035
22.2,92.50005,34.20883139,3.48833
22.24,92.66661,34.2445276,3.49197
22.28,92.83324,34.22079551,3.48955
22.32,92.99998,34.44654459,3.51257
22.36,93.1668,34.47851427,3.51583
22.4,93.33336,34.38338976,3.50613
22.44,93.49992,34.25933564,3.49348
22.48,93.66655,34.49126291,3.51713
22.52,93.83324,34.38907762,3.50671
22.56,94.00005,34.41261358,3.50911
22.6,94.16673,34.57520784,3.52569
22.64,94.33337,34.6581721,3.53415
22.68,94.49992,34.73623303,3.54211
22.72,94.66661,34.84528298,3.55323
22.76,94.8333,34.58530869,3.52672
22.8,95.00004,34.68876885,3.53727
22.84,95.16673,34.81703983,3.55035
22.88,95.3333,34.86499435,3.55524
22.92,95.49992,34.98875427,3.56786
22.96,95.66661,34.92707044,3.56157
23,95.83335,35.06004861,3.57513
23.04,96.00011,35.15085819,3.58439
23.08,96.16667,35.33179089,3.60284
23.12,96.3333,35.33541935,3.60321
23.16,96.49999,35.28118857,3.59768
23.2,96.66674,35.37052715,3.60679
23.24,96.83336,35.19371325,3.58876
23.28,96.99998,35.49840587,3.61983
23.32,97.16667,35.62824592,3.63307
23.36,97.3333,35.58195853,3.62835
23.4,97.50005,35.49840587,3.61983
23.44,97.66674,35.71336764,3.64175
23.48,97.83329,35.67698497,3.63804
23.52,97.99998,35.79623383,3.6502
23.56,98.16661,35.79819516,3.6504
23.6,98.33329,35.86380165,3.65709
23.64,98.50005,36.08690294,3.67984
23.68,98.66667,36.03463349,3.67451
23.72,98.83324,35.87792322,3.65853
23.76,98.99999,36.05444292,3.67653
23.8,99.16667,35.94686397,3.66556
23.84,99.3333,36.03404509,3.67445
23.88,99.50005,36.33412858,3.70505
23.92,99.66668,36.31059262,3.70265
23.96,99.83324,36.46691062,3.71859
24,99.99998,36.42209423,3.71402
24.04,100.16668,36.46867582,3.71877
24.08,100.33336,36.51398254,3.72339
24.12,100.50005,36.62695515,3.73491
24.16,100.66673,36.46485123,3.71838
24.2,100.83323,36.76297339,3.74878
24.24,101.00004,36.7966102,3.75221
24.28,101.16674,36.66971215,3.73927
24.32,101.33336,37.01500429,3.77448
24.36,101.50004,36.94753454,3.7676
24.4,101.66674,36.96459811,3.76934
24.44,101.83336,36.96322518,3.7692
24.48,101.99999,37.11611085,3.78479
24.52,102.16667,37.07796299,3.7809
24.56,102.3333,37.17701015,3.791
24.6,102.49998,37.29057116,3.80258
24.64,102.66667,37.23800751,3.79722
24.68,102.83336,37.28468717,3.80198
24.72,103.00005,37.27635151,3.80113
24.76,103.16667,37.34892072,3.80853
24.8,103.33324,37.56505929,3.83057
24.84,103.49993,37.51857577,3.82583
24.88,103.66674,37.46944445,3.82082
24.92,103.83342,37.50200253,3.82414
24.96,104.00005,37.813854,3.85594
25,104.16655,37.72745741,3.84713
25.04,104.33324,37.82885818,3.85747
25.08,104.49998,37.75079724,3.84951
25.12,104.66673,37.91270503,3.86602
25.16,104.83329,37.96487641,3.87134
25.2,104.99999,37.88161795,3.86285
25.24,105.16667,37.96114988,3.87096
25.28,105.33324,38.00282815,3.87521
25.32,105.49999,38.0500962,3.88003
25.36,105.66667,38.31821001,3.90737
25.4,105.83336,38.32134814,3.90769
25.44,106.00004,38.23063663,3.89844
25.48,106.16668,38.33380258,3.90896
25.52,106.33335,38.35214102,3.91083
25.56,106.50005,38.54062483,3.93005
25.6,106.66673,38.39450575,3.91515
25.64,106.8333,38.58838322,3.93492
25.68,106.99999,38.675074,3.94376
25.72,107.16667,38.64506566,3.9407
25.76,107.3333,38.67301461,3.94355
25.8,107.50005,38.71096634,3.94742
25.84,107.66674,38.83855086,3.96043
25.88,107.8333,38.86806888,3.96344
25.92,107.99998,39.07459693,3.9845
25.96,108.16661,39.22552127,3.99989
26,108.3333,39.2081635,3.99812
26.04,108.50005,39.23630858,4.00099
26.08,108.66674,39.1677601,3.994
26.12,108.83324,39.11411772,3.98853
26.16,108.99998,39.24876303,4.00226
26.2,109.16674,39.37879921,4.01552
26.24,109.33336,39.45146648,4.02293
26.28,109.49999,39.47088365,4.02491
26.32,109.66661,39.51756331,4.02967
26.36,109.83324,39.49961714,4.02784
26.4,110.00005,39.83127804,4.06166
26.44,110.16686,39.83186644,4.06172
26.48,110.33336,39.63328178,4.04147
26.52,110.49986,39.67437164,4.04566
26.56,110.66655,39.73811486,4.05216
26.6,110.83336,39.62102346,4.04022
26.64,111.00011,39.7787144,4.0563
26.68,111.1668,39.98396758,4.07723
26.72,111.3333,40.00603254,4.07948
26.76,111.49999,40.12332008,4.09144
26.8,111.66661,39.99014577,4.07786
26.84,111.83336,40.1493077,4.09409
26.88,112.00004,40.22099431,4.1014
26.92,112.16674,40.02682264,4.0816
26.96,112.3333,40.43948647,4.12368
27,112.49999,40.46665089,4.12645
27.04,112.66661,40.36770179,4.11636
27.08,112.83336,40.59099921,4.13913
27.12,113.00005,40.75477027,4.15583
27.16,113.16667,40.65935157,4.1461
27.2,113.33324,40.56373673,4.13635
27.24,113.49998,40.92187559,4.17287
27.28,113.66667,40.67190408,4.14738
27.32,113.8333,40.92864217,4.17356
27.36,113.99992,40.78850515,4.15927
27.4,114.16661,40.75986973,4.15635
27.44,114.33329,40.77830623,4.15823
27.48,114.49998,41.01719622,4.18259
27.52,114.66674,40.78046369,4.15845
27.56,114.8333,40.88578711,4.16919
27.6,114.99998,40.93913529,4.17463
27.64,115.1666,41.04269351,4.18519
27.68,115.3333,41.23137346,4.20443
27.72,115.50005,41.40151884,4.22178
27.76,115.66673,41.23637485,4.20494
27.8,115.83329,41.4402551,4.22573
27.84,115.99999,41.5383216,4.23573
27.88,116.16673,41.37111822,4.21868
27.92,116.33337,41.55116832,4.23704
27.96,116.50004,41.58676646,4.24067
28,116.66667,41.60716429,4.24275
28.04,116.83323,41.54204813,4.23611
28.08,117.00004,41.58980652,4.24098
28.12,117.16673,41.77221021,4.25958
28.16,117.33335,41.74102506,4.2564
28.2,117.50005,41.83193271,4.26567
28.24,117.66667,41.93931552,4.27662
28.28,117.83324,42.04061822,4.28695
28.32,117.99999,42.00766787,4.28359
28.36,118.16667,41.97001034,4.27975
28.4,118.33323,42.04718867,4.28762
28.44,118.49998,42.10436144,4.29345
28.48,118.66674,41.96530315,4.27927
28.52,118.8333,42.04169695,4.28706
28.56,118.99998,42.22145284,4.30539
28.6,119.16667,42.05915279,4.28884
28.64,119.33323,42.12603414,4.29566
28.68,119.49998,41.72857061,4.25513
28.72,119.66667,41.70689792,4.25292
28.76,119.83336,39.12000171,3.98913
28.8,120.00005,2.364677515,0.24113
28.84,120.16667,-1.432947698,-0.14612
28.88,120.33324,-0.168870513,-0.01722
28.92,120.49999,-0.089240515,-0.0091
28.96,120.6668,-0.034127142,-0.00348
29,120.83342,0.062566427,0.00638
29.04,120.99999,-0.112286143,-0.01145
29.08,121.16661,-0.181128826,-0.01847
29.12,121.3333,-0.246735314,-0.02516
29.16,121.50005,-0.082964259,-0.00846
29.2,121.66673,-0.103656291,-0.01057
29.24,121.83336,-0.103460158,-0.01055
29.28,122.00005,-0.065704555,-0.0067
29.32,122.16668,-0.168184048,-0.01715
29.356,122.31661,-0.009218251,-0.00094