File: V_8/FR/RDSO FR Tensile 250.is_tens_RawData/Specimen_RawData_2.csv
Time,Extension,Load,
(sec),(mm),(N),(kgf)
0,0,2.412141701,0.24597
0.04,0.06806,2.713794255,0.27673
0.08,0.27781,3.66209731,0.37343
0.12,0.4825,3.971497117,0.40498
0.16,0.65519,4.828500261,0.49237
0.2,0.82412,5.295198734,0.53996
0.24,0.99487,5.790630692,0.59048
0.28,1.164,5.92517793,0.6042
0.32,1.33162,6.253308439,0.63766
0.36,1.49887,6.806305433,0.69405
0.4,1.666,7.050687151,0.71897
0.44,1.83294,7.458545724,0.76056
0.48,1.99994,7.644970141,0.77957
0.52,2.16669,8.227289018,0.83895
0.56,2.33312,8.363699519,0.85286
0.6,2.49987,8.58081875,0.875
0.64,2.66669,8.574052162,0.87431
0.68,2.83337,9.102630597,0.92821
0.72,3.00012,9.182456728,0.93635
0.76,3.16675,9.396339764,0.95816
0.8,3.33325,9.651116531,0.98414
0.84,3.49994,9.828911096,1.00227
0.88,3.66662,10.15900293,1.03593
0.92,3.83331,10.24588985,1.04479
0.96,4.00006,10.40828798,1.06135
1,4.16675,10.59039747,1.07992
1.04,4.33325,10.75004973,1.0962
1.08,4.5,10.76603457,1.09783
1.12,4.66675,11.00384583,1.12208
1.16,4.83337,11.17605061,1.13964
1.2,5,11.24361842,1.14653
1.24,5.16662,11.42092266,1.16461
1.28,5.33325,11.53654306,1.1764
1.32,5.5,11.67001157,1.19001
1.36,5.66675,11.68962487,1.19201
1.4,5.83337,11.99569041,1.22322
1.44,6,12.28312332,1.25253
1.48,6.16669,12.28547692,1.25277
1.52,6.33331,12.43041921,1.26755
1.56,6.5,12.54878547,1.27962
1.6,6.66669,12.36481272,1.26086
1.64,6.83331,12.60978284,1.28584
1.68,7,12.81621282,1.30689
1.72,7.16662,12.87495465,1.31288
1.76,7.33337,13.14346073,1.34026
1.8,7.50006,13.1198267,1.33785
1.84,7.66675,12.96752943,1.32232
1.88,7.83325,13.24956868,1.35108
1.92,7.99994,13.48620315,1.37521
1.96,8.16669,13.41451654,1.3679
2,8.3335,13.36548329,1.3629
2.04,8.50019,13.58819231,1.38561
2.08,8.66656,13.73793985,1.40088
2.12,8.83312,13.81492205,1.40873
2.16,9,13.76314294,1.40345
2.2,9.16675,13.8853338,1.41591
2.24,9.33337,13.89994571,1.4174
2.28,9.50006,14.01125119,1.42875
2.32,9.66662,14.13187298,1.44105
2.36,9.83319,14.24464946,1.45255
2.4,10,13.97594725,1.42515
2.44,10.16675,14.2020886,1.44821
2.48,10.33331,14.33045765,1.4613
2.52,10.50006,14.55463766,1.48416
2.56,10.66669,14.5328669,1.48194
2.6,10.83325,14.57915429,1.48666
2.64,11.00006,14.70360068,1.49935
2.68,11.16681,14.53727989,1.48239
2.72,11.33331,14.66074562,1.49498
2.76,11.49994,14.91591465,1.521
2.8,11.66669,14.84795457,1.51407
2.84,11.83331,14.8068647,1.50988
2.88,12.00006,14.85060236,1.51434
2.92,12.16669,14.87845325,1.51718
2.96,12.33325,15.09841641,1.53961
3,12.5,15.17284888,1.5472
3.04,12.66675,15.25963773,1.55605
3.08,12.83337,15.15892344,1.54578
3.12,13.00006,15.12342336,1.54216
3.16,13.16669,15.06144534,1.53584
3.2,13.33331,15.24963495,1.55503
3.24,13.5,15.4728343,1.57779
3.28,13.66668,15.29964886,1.56013
3.32,13.83331,15.39428304,1.56978
3.36,14,15.3785924,1.56818
3.4,14.16662,15.39369464,1.56972
3.44,14.33325,15.42988118,1.57341
3.48,14.5,15.52373082,1.58298
3.52,14.66675,15.72172708,1.60317
3.56,14.83331,15.79360983,1.6105
3.6,14.99994,15.65817999,1.59669
3.64,15.16662,15.48362162,1.57889
3.68,15.33331,15.78576451,1.6097
3.72,15.50006,15.77380039,1.60848
3.76,15.66675,15.74457658,1.6055
3.8,15.83331,15.7667396,1.60776
3.84,16,15.70181958,1.60114
3.88,16.16669,15.86304091,1.61758
3.92,16.33331,16.01926084,1.63351
3.96,16.50006,16.06809796,1.63849
4,16.66668,16.02112411,1.6337
4.04,16.83337,15.97405219,1.6289
4.08,17.00006,16.07937561,1.63964
4.12,17.16662,16.15057189,1.6469
4.16,17.33325,16.03857994,1.63548
4.2,17.50006,16.06858829,1.63854
4.24,17.66669,16.05770291,1.63743
4.28,17.83331,16.22294496,1.65428
4.32,18.00006,16.33591757,1.6658
4.36,18.16675,16.3551386,1.66776
4.4,18.33331,16.04524846,1.63616
4.44,18.49993,16.37641903,1.66993
4.48,18.66662,16.43192467,1.67559
4.52,18.83331,16.27766607,1.65986
4.56,19.00012,16.34180156,1.6664
4.6,19.16668,16.34189963,1.66641
4.64,19.33318,16.52714725,1.6853
4.68,19.49994,16.60256038,1.69299
4.72,19.66675,16.43496474,1.6759
4.76,19.83331,16.53842489,1.68645
4.8,20.00006,16.40838871,1.67319
4.84,20.16668,16.60530625,1.69327
4.88,20.33331,16.77505936,1.71058
4.92,20.5,16.81291303,1.71444
4.96,20.66668,16.7491698,1.70794
5,20.83331,16.83988131,1.71719
5.04,21.00006,16.74044188,1.70705
5.08,21.16675,16.72818357,1.7058
5.12,21.33331,16.91303892,1.72465
5.16,21.5,16.83527219,1.71672
5.2,21.66675,16.87636205,1.72091
5.24,21.83337,16.79790885,1.71291
5.28,22.00006,16.81928735,1.71509
5.32,22.16668,17.02689413,1.73626
5.36,22.33331,16.91951131,1.72531
5.4,22.5,16.87077226,1.72034
5.44,22.66675,17.09348128,1.74305
5.48,22.83337,16.84243104,1.71745
5.52,23,16.96207217,1.72965
5.56,23.16662,17.0609232,1.73973
5.6,23.33325,17.11888051,1.74564
5.64,23.50006,17.13810154,1.7476
5.68,23.66675,17.20076603,1.75399
5.72,23.83331,17.02875739,1.73645
5.76,23.99993,17.16614856,1.75046
5.8,24.16662,17.11691918,1.74544
5.84,24.33337,17.17821074,1.75169
5.88,24.50006,17.3969971,1.774
5.92,24.66668,17.31981876,1.76613
5.96,24.83325,17.20488483,1.75441
6,24.99993,17.27068745,1.76112
6.04,25.16675,17.48731635,1.78321
6.08,25.3335,17.35767243,1.76999
6.12,25.50006,17.59028617,1.79371
6.16,25.6665,17.52222802,1.78677
6.2,25.83312,17.48378595,1.78285
6.24,26.00006,17.60009282,1.79471
6.28,26.16675,17.36796942,1.77104
6.32,26.33337,17.30883532,1.76501
6.36,26.50006,17.59058037,1.79374
6.4,26.66668,17.62833597,1.79759
6.44,26.83325,17.45622927,1.78004
6.48,27,17.49153321,1.78364
6.52,27.16668,17.53948772,1.78853
6.56,27.33337,17.49673073,1.78417
6.6,27.50006,17.5904823,1.79373
6.64,27.66668,17.67109297,1.80195
6.68,27.83325,17.75631276,1.81064
6.72,28.00006,17.59009004,1.79369
6.76,28.16675,17.84025768,1.8192
6.8,28.33331,17.80426727,1.81553
6.84,28.5,17.7690614,1.81194
6.88,28.66668,17.68168415,1.80303
6.92,28.83331,17.73728786,1.8087
6.96,29.00006,17.95323029,1.83072
7,29.16669,17.89184066,1.82446
7.04,29.33318,17.85467346,1.82067
7.08,29.5,17.85614445,1.82082
7.12,29.66675,17.89880338,1.82517
7.16,29.83337,17.66471865,1.8013
7.2,30.00006,17.89978405,1.82527
7.24,30.16668,17.97549138,1.83299
7.28,30.33325,17.88948706,1.82422
7.32,30.49999,17.81319133,1.81644
7.36,30.66675,18.07395015,1.84303
7.4,30.83337,18.02305364,1.83784
7.44,31,18.13259392,1.84901
7.48,31.16668,18.24076127,1.86004
7.52,31.33331,18.19378741,1.85525
7.56,31.50006,18.07699021,1.84334
7.6,31.66674,18.12435633,1.84817
7.64,31.83331,18.04413793,1.83999
7.68,31.99999,18.03276222,1.83883
7.72,32.16668,18.23958447,1.85992
7.76,32.33337,18.19329708,1.8552
7.8,32.50006,18.36775738,1.87299
7.84,32.66668,18.18398076,1.85425
7.88,32.83331,18.21447944,1.85736
7.92,33,18.34863442,1.87104
7.96,33.16668,18.17721417,1.85356
8,33.33331,18.25625577,1.86162
8.04,33.49999,18.21222391,1.85713
8.08,33.66668,18.25252925,1.86124
8.12,33.83337,18.34951701,1.87113
8.16,34.00006,18.33372831,1.86952
8.2,34.16662,18.40090386,1.87637
8.24,34.33324,18.49455737,1.88592
8.28,34.49999,18.43022574,1.87936
8.32,34.66668,18.56869564,1.89348
8.36,34.83331,18.5173088,1.88824
8.4,35.00006,18.54692488,1.89126
8.44,35.16675,18.54515968,1.89108
8.48,35.33325,18.69902602,1.90677
8.52,35.49999,18.61204104,1.8979
8.56,35.66662,18.53025357,1.88956
8.6,35.83337,18.55222047,1.8918
8.64,36.00012,18.74815734,1.91178
8.68,36.16668,18.85740342,1.92292
8.72,36.33318,18.91349746,1.92864
8.76,36.49993,18.6745094,1.90427
8.8,36.66668,18.73972362,1.91092
8.84,36.83337,18.67921659,1.90475
8.88,37.00006,18.83877078,1.92102
8.92,37.16674,18.98900866,1.93634
8.96,37.33324,18.89349189,1.9266
9,37.49999,19.06716766,1.94431
9.04,37.66668,18.8659352,1.92379
9.08,37.83337,18.95184146,1.93255
9.12,38.00006,18.98577247,1.93601
9.16,38.16668,18.91487039,1.92878
9.2,38.33324,19.00666063,1.93814
9.24,38.5,19.0445143,1.942
9.28,38.66674,19.19475218,1.95732
9.32,38.83331,19.01019103,1.9385
9.36,38.99999,19.1229675,1.95
9.4,39.16662,19.04049357,1.94159
9.44,39.33324,19.20514723,1.95838
9.48,39.49999,19.02872559,1.94039
9.52,39.66675,19.17778667,1.95559
9.56,39.8333,19.15140679,1.9529
9.6,39.99999,19.21730747,1.95962
9.64,40.16662,19.15307392,1.95307
9.68,40.33331,19.07432652,1.94504
9.72,40.50006,19.35970003,1.97414
9.76,40.66675,19.32929942,1.97104
9.8,40.8333,19.3416558,1.9723
9.84,40.99993,19.16876456,1.95467
9.88,41.16668,19.44884248,1.98323
9.92,41.33337,19.46904418,1.98529
9.96,41.50006,19.53700426,1.99222
10,41.66668,19.41108688,1.97938
10.04,41.83325,19.50062159,1.98851
10.08,41.99999,19.34449972,1.97259
10.12,42.16681,19.27232278,1.96523
10.16,42.3335,19.54965484,1.99351
10.2,42.50005,19.56760101,1.99534
10.24,42.66656,19.59564803,1.9982
10.28,42.83318,19.74176712,2.0131
10.32,43.00006,19.68145622,2.00695
10.36,43.16675,19.46669058,1.98505
10.4,43.33337,19.71303363,2.01017
10.44,43.50006,19.70577671,2.00943
10.48,43.66662,19.76049782,2.01501
10.52,43.83324,19.48699035,1.98712
10.56,44,19.66792304,2.00557
10.6,44.16674,19.79972442,2.01901
10.64,44.33331,19.8100214,2.02006
10.68,44.49999,19.57809413,1.99641
10.72,44.66656,19.67459156,2.00625
10.76,44.83324,19.96104381,2.03546
10.8,45.00006,19.91877715,2.03115
10.84,45.16675,19.99683808,2.03911
10.88,45.33324,19.8088446,2.01994
10.92,45.49999,19.86788063,2.02596
10.96,45.66674,20.03753568,2.04326
11,45.83337,20.20542553,2.06038
11.04,46.00006,19.97212532,2.03659
11.08,46.16662,19.91573709,2.03084
11.12,46.33325,20.14413396,2.05413
11.16,46.49999,20.20513133,2.06035
11.2,46.66674,20.08902059,2.04851
11.24,46.83331,20.17012159,2.05678
11.28,47.00006,20.3381095,2.07391
11.32,47.16668,20.33075451,2.07316
11.36,47.33331,20.23729714,2.06363
11.4,47.50005,20.30888568,2.07093
11.44,47.66674,20.14923342,2.05465
11.48,47.8333,20.2403372,2.06394
11.52,47.99999,20.45304344,2.08563
11.56,48.16668,20.29623511,2.06964
11.6,48.3333,20.44490392,2.0848
11.64,48.49999,20.56876191,2.09743
11.68,48.66675,20.25632204,2.06557
11.72,48.83324,20.35723247,2.07586
11.76,48.99999,20.66486708,2.10723
11.8,49.16668,20.63907559,2.1046
11.84,49.33331,20.55954366,2.09649
11.88,49.5,20.70370141,2.11119
11.92,49.66668,20.60288905,2.10091
11.96,49.83325,20.76116838,2.11705
12,49.99993,20.65388363,2.10611
12.04,50.16668,20.64152725,2.10485
12.08,50.33331,20.57513623,2.09808
12.12,50.50005,20.80990743,2.12202
12.16,50.66674,20.67614473,2.10838
12.2,50.83337,20.74135895,2.11503
12.24,50.99999,20.92189938,2.13344
12.28,51.16662,21.027517,2.14421
12.32,51.33331,20.84128871,2.12522
12.36,51.50005,20.90463967,2.13168
12.4,51.66662,20.75214626,2.11613
12.44,51.83337,20.97534562,2.13889
12.48,52.00006,21.08155164,2.14972
12.52,52.16674,21.02898799,2.14436
12.56,52.33331,20.98279867,2.13965
12.6,52.49999,21.13293848,2.15496
12.64,52.66662,21.03065512,2.14453
12.68,52.83337,21.11685558,2.15332
12.72,53.00011,21.07449085,2.149
12.76,53.16662,21.32916955,2.17497
12.8,53.33318,21.43184518,2.18544
12.84,53.49999,21.4194888,2.18418
12.88,53.66674,21.33024828,2.17508
12.92,53.83337,21.48999861,2.19137
12.96,54.00006,21.43576784,2.18584
13,54.16668,21.21335301,2.16316
13.04,54.33324,21.50921964,2.19333
13.08,54.49993,21.31024272,2.17304
13.12,54.66668,21.45018361,2.18731
13.16,54.83331,21.4554792,2.18785
13.2,55.00006,21.43125678,2.18538
13.24,55.16668,21.5368744,2.19615
13.28,55.33325,21.57364934,2.1999
13.32,55.50005,21.49725553,2.19211
13.36,55.66674,21.59983309,2.20257
13.4,55.83331,21.52069343,2.1945
13.44,55.99999,21.56492142,2.19901
13.48,56.16668,21.50039366,2.19243
13.52,56.3333,21.74752124,2.21763
13.56,56.50006,21.77497986,2.22043
13.6,56.66674,21.81597166,2.22461
13.64,56.83331,21.70868691,2.21367
13.68,56.99999,21.73653779,2.21651
13.72,57.16668,21.88569694,2.23172
13.76,57.3333,21.84029215,2.22709
13.8,57.50006,22.03613095,2.24706
13.84,57.66674,21.91550915,2.23476
13.88,57.83331,22.01386985,2.24479
13.92,57.99993,21.9074677,2.23394
13.96,58.16668,22.06251084,2.24975
14,58.33337,22.11968361,2.25558
14.04,58.50005,22.20382466,2.26416
14.08,58.66668,22.13282452,2.25692
14.12,58.83324,22.14272923,2.25793
14.16,58.99999,22.36730152,2.28083
14.2,59.16681,22.22706642,2.26653
14.24,59.33343,22.4182961,2.28603
14.28,59.49999,22.35553354,2.27963
14.32,59.66649,22.39466207,2.28362
14.36,59.83318,22.55392207,2.29986
14.4,60.00006,22.39299494,2.28345
14.44,60.16681,22.23844214,2.26769
14.48,60.33337,22.4191787,2.28612
14.52,60.5,22.51165541,2.29555
14.56,60.66662,22.50586948,2.29496
14.6,60.83325,22.5365643,2.29809
14.64,61.00005,22.39201428,2.28335
14.68,61.16674,22.53185711,2.29761
14.72,61.33337,22.5927564,2.30382
14.76,61.49999,22.78428028,2.32335
14.8,61.66662,22.66101069,2.31078
14.84,61.8333,22.5918738,2.30373
14.88,62.00006,22.71837959,2.31663
14.92,62.16674,22.67219027,2.31192
14.96,62.33331,22.95687732,2.34095
15,62.49999,22.97825581,2.34313
15.04,62.66674,23.10515387,2.35607
15.08,62.83336,23.00963709,2.34633
15.12,63.00006,23.02287607,2.34768
15.16,63.16668,23.26088347,2.37195
15.2,63.33324,23.05886648,2.35135
15.24,63.50006,23.14869539,2.36051
15.28,63.66674,23.32060597,2.37804
15.32,63.83337,23.27529924,2.37342
15.36,63.99999,23.27000365,2.37288
15.4,64.16667,23.10995912,2.35656
15.44,64.33324,23.18615679,2.36433
15.48,64.49999,23.21381155,2.36715
15.52,64.66668,23.18909879,2.36463
15.56,64.8333,23.28667496,2.37458
15.6,64.99999,23.41514207,2.38768
15.64,65.16661,23.37267928,2.38335
15.68,65.3333,23.40200116,2.38634
15.72,65.50005,23.25882407,2.37174
15.76,65.66674,23.53615613,2.40002
15.8,65.83324,23.39297904,2.38542
15.84,65.99999,23.57234267,2.40371
15.88,66.16674,23.4774143,2.39403
15.92,66.33336,23.68884567,2.41559
15.96,66.50005,23.78034172,2.42492
16,66.66668,23.62363145,2.40894
16.04,66.83324,23.61343254,2.4079
16.08,66.99999,23.74974497,2.4218
16.12,67.16674,23.66785944,2.41345
16.16,67.33336,23.87968308,2.43505
16.2,67.50006,23.65834699,2.41248
16.24,67.66674,23.73719246,2.42052
16.28,67.8333,23.73434853,2.42023
16.32,67.99999,24.01991818,2.44935
16.36,68.16661,24.04119861,2.45152
16.4,68.3333,24.16289913,2.46393
16.44,68.49999,23.95166389,2.44239
16.48,68.66661,24.15750548,2.46338
16.52,68.8333,24.22321003,2.47008
16.56,69.00005,24.43532787,2.49171
16.6,69.16668,24.19614368,2.46732
16.64,69.33324,24.3787435,2.48594
16.68,69.49992,24.35962053,2.48399
16.72,69.66662,24.21811057,2.46956
16.76,69.83336,24.30548783,2.47847
16.8,70.00005,24.42159856,2.49031
16.84,70.16661,24.37129045,2.48518
16.88,70.33318,24.44837072,2.49304
16.92,70.49999,24.43277814,2.49145
16.96,70.66674,24.35363848,2.48338
17,70.83336,24.68402452,2.51707
17.04,71.00006,24.50230729,2.49854
17.08,71.16668,24.71236573,2.51996
17.12,71.33324,24.711287,2.51985
17.16,71.49999,24.75894732,2.52471
17.2,71.66667,24.84779557,2.53377
17.24,71.83337,24.79317253,2.5282
17.28,72.00005,24.91222526,2.54034
17.32,72.16667,24.97940081,2.54719
17.36,72.33324,24.84877624,2.53387
17.4,72.50005,24.88633571,2.5377
17.44,72.66674,25.13640528,2.5632
17.48,72.8333,25.03716198,2.55308
17.52,72.99999,25.01058596,2.55037
17.56,73.16662,25.11414418,2.56093
17.6,73.33324,25.21289715,2.571
17.64,73.50005,25.18690953,2.56835
17.68,73.66674,25.18749793,2.56841
17.72,73.8333,25.29340975,2.57921
17.76,73.99993,25.31390565,2.5813
17.8,74.16661,25.09639415,2.55912
17.84,74.3333,25.28938902,2.5788
17.88,74.50006,25.51817816,2.60213
17.92,74.66668,25.38363093,2.58841
17.96,74.83324,25.42913378,2.59305
18,74.99993,25.56417135,2.60682
18.04,75.16674,25.45217941,2.5954
18.08,75.33337,25.5537763,2.60576
18.12,75.50005,25.58986478,2.60944
18.16,75.66668,25.65615773,2.6162
18.2,75.83324,25.64380135,2.61494
18.24,76.00005,25.79247017,2.6301
18.28,76.16686,25.62997397,2.61353
18.32,76.33343,25.80590528,2.63147
18.36,76.49993,25.69714953,2.62038
18.4,76.66655,25.66665085,2.61727
18.44,76.8333,25.77785826,2.62861
18.48,77.00011,25.76628641,2.62743
18.52,77.1668,25.89181153,2.64023
18.56,77.33336,25.95594702,2.64677
18.6,77.50005,25.92682127,2.6438
18.64,77.66661,25.93603952,2.64474
18.68,77.83324,26.02273031,2.65358
18.72,77.99999,26.21101799,2.67278
18.76,78.16673,25.96006581,2.64719
18.8,78.3333,26.24857746,2.67661
18.84,78.49999,26.17365465,2.66897
18.88,78.66655,26.12570013,2.66408
18.92,78.8333,26.46726575,2.69891
18.96,79.00004,26.42215516,2.69431
19,79.16674,26.54365956,2.7067
19.04,79.33323,26.5572908,2.70809
19.08,79.49999,26.38969515,2.691
19.12,79.66667,26.45549777,2.69771
19.16,79.8333,26.62770255,2.71527
19.2,79.99999,26.57876736,2.71028
19.24,80.16662,26.83442673,2.73635
19.28,80.33324,26.66330069,2.7189
19.32,80.50005,26.72625938,2.72532
19.36,80.6668,26.56748971,2.70913
19.4,80.83336,26.82393361,2.73528
19.44,80.99998,26.8509019,2.73803
19.48,81.16661,26.77892109,2.73069
19.52,81.3333,26.74400941,2.72713
19.56,81.50005,26.92533437,2.74562
19.6,81.66674,27.00015911,2.75325
19.64,81.83324,26.96877783,2.75005
19.68,81.99998,27.23600905,2.7773
19.72,82.16668,27.15637905,2.76918
19.76,82.33336,27.09508748,2.76293
19.8,82.50005,27.24061817,2.77777
19.84,82.66667,27.13166629,2.76666
19.88,82.83324,27.07478772,2.76086
19.92,82.99992,27.23120379,2.77681
19.96,83.16674,27.27994284,2.78178
20,83.3333,27.31397191,2.78525
20.04,83.49999,27.32809349,2.78669
20.08,83.66668,27.54138813,2.80844
20.12,83.83323,27.37379248,2.79135
20.16,83.99999,27.44861722,2.79898
20.2,84.16668,27.50765325,2.805
20.24,84.3333,27.74144379,2.82884
20.28,84.49999,27.78851571,2.83364
20.32,84.66667,27.61807613,2.81626
20.36,84.8333,27.58806778,2.8132
20.4,84.99992,27.61984133,2.81644
20.44,85.16661,27.73428493,2.82811
20.48,85.3333,27.95866108,2.85099
20.52,85.49999,27.84794401,2.8397
20.56,85.66667,27.88314988,2.84329
20.6,85.83336,27.96346634,2.85148
20.64,86.00005,28.03456455,2.85873
20.68,86.16674,28.07094723,2.86244
20.72,86.3333,28.13282719,2.86875
20.76,86.49993,28.08585333,2.86396
20.8,86.66667,28.07938095,2.8633
20.84,86.83342,28.19657041,2.87525
20.88,87.00005,28.10419177,2.86583
20.92,87.16661,28.42938028,2.89899
20.96,87.33324,28.57530324,2.91387
21,87.49999,28.60540965,2.91694
21.04,87.66667,28.39064402,2.89504
21.08,87.8333,28.35190775,2.89109
21.12,88.00005,28.31160242,2.88698
21.16,88.16661,28.3599492,2.89191
21.2,88.33324,28.63610447,2.92007
21.24,88.49998,28.59540687,2.91592
21.28,88.66673,28.43408748,2.89947
21.32,88.83336,28.56539852,2.91286
21.36,88.99999,28.72338365,2.92897
21.4,89.16661,28.74005496,2.93067
21.44,89.33323,28.6746446,2.924
21.48,89.50005,28.73868202,2.93053
21.52,89.66674,28.79899292,2.93668
21.56,89.83323,29.05376969,2.96266
21.6,89.99993,29.01317016,2.95852
21.64,90.16661,28.97688555,2.95482
21.68,90.3333,28.97502229,2.95463
21.72,90.50012,29.04749343,2.96202
21.76,90.66674,29.01895608,2.95911
21.8,90.8333,29.04455144,2.96172
21.84,90.99999,29.09476149,2.96684
21.88,91.16667,29.15546465,2.97303
21.92,91.3333,29.36964189,2.99487
21.96,91.50011,29.26775079,2.98448
22,91.66674,29.36885735,2.99479
22.04,91.8333,29.37268195,2.99518
22.08,91.99998,29.35797197,2.99368
22.12,92.16674,29.49487281,3.00764
22.16,92.33336,29.45446941,3.00352
22.2,92.50005,29.77191067,3.03589
22.24,92.66661,29.52448889,3.01066
22.28,92.83324,29.30266247,2.98804
22.32,92.99998,29.55802763,3.01408
22.36,93.1668,29.77651979,3.03636
22.4,93.33336,29.60941448,3.01932
22.44,93.49992,29.657369,3.02421
22.48,93.66655,29.72856528,3.03147
22.52,93.83329,29.84820641,3.04367
22.56,94.00005,29.79505436,3.03825
22.6,94.16673,29.77583333,3.03629
22.64,94.33337,29.72415228,3.03102
22.68,94.49992,29.94019278,3.05305
22.72,94.66661,30.13760065,3.07318
22.76,94.83323,30.0660121,3.06588
22.8,95.00004,30.16574573,3.07605
22.84,95.16673,30.30068524,3.08981
22.88,95.3333,30.20722786,3.08028
22.92,95.49998,30.2639103,3.08606
22.96,95.66661,30.24763126,3.0844
23,95.83335,30.32775159,3.09257
23.04,96.00011,30.46631956,3.1067
23.08,96.16667,30.36580139,3.09645
23.12,96.3333,30.36393813,3.09626
23.16,96.49999,30.62352015,3.12273
23.2,96.66674,30.42572002,3.10256
23.24,96.83336,30.24302213,3.08393
23.28,96.99998,30.56409186,3.11667
23.32,97.16661,30.59919966,3.12025
23.36,97.3333,30.71727173,3.13229
23.4,97.50005,30.50152543,3.11029
23.44,97.66674,30.79807852,3.14053
23.48,97.83329,30.71874273,3.13244
23.52,97.99998,30.74090576,3.1347
23.56,98.16661,30.82151642,3.14292
23.6,98.33329,30.95645592,3.15668
23.64,98.50005,30.80357025,3.14109
23.68,98.66667,30.92791857,3.15377
23.72,98.83324,31.02480827,3.16365
23.76,98.99999,31.11963858,3.17332
23.8,99.16667,31.04491191,3.1657
23.84,99.3333,31.30155194,3.19187
23.88,99.50005,31.06472134,3.16772
23.92,99.66668,31.23123826,3.1847
23.96,99.83324,31.39324411,3.20122
24,99.99998,31.36333383,3.19817
24.04,100.16668,31.53975546,3.21616
24.08,100.33336,31.34950645,3.19676
24.12,100.50005,31.47032438,3.20908
24.16,100.66673,31.40452176,3.20237
24.2,100.83323,31.53338114,3.21551
24.24,101.00004,31.62575978,3.22493
24.28,101.16674,31.72088429,3.23463
24.32,101.33336,31.84984174,3.24778
24.36,101.50004,31.85945225,3.24876
24.4,101.66674,31.65282614,3.22769
24.44,101.83336,31.64605955,3.227
24.48,101.99999,31.88553794,3.25142
24.52,102.16667,31.67851956,3.23031
24.56,102.3333,31.82473671,3.24522
24.6,102.49998,32.12678153,3.27602
24.64,102.66667,31.96036268,3.25905
24.68,102.83336,31.77030981,3.23967
24.72,103.0001,31.96546214,3.25957
24.76,103.16667,31.92456841,3.2554
24.8,103.33324,32.15767248,3.27917
24.84,103.49993,32.02694984,3.26584
24.88,103.66674,32.04126755,3.2673
24.92,103.83342,32.11795555,3.27512
24.96,104.00005,32.24053867,3.28762
25,104.16655,32.47325048,3.31135
25.04,104.33324,32.33674191,3.29743
25.08,104.49998,32.18885763,3.28235
25.12,104.66673,32.53532657,3.31768
25.16,104.83329,32.46609162,3.31062
25.2,104.99999,32.66045943,3.33044
25.24,105.16661,32.66967768,3.33138
25.28,105.33324,32.44147693,3.30811
25.32,105.49999,32.84374571,3.34913
25.36,105.66674,32.83874432,3.34862
25.4,105.83336,32.78804394,3.34345
25.44,106.00004,32.77009777,3.34162
25.48,106.16668,32.73126344,3.33766
25.52,106.3333,32.78637681,3.34328
25.56,106.50005,32.8543369,3.35021
25.6,106.66673,33.02958173,3.36808
25.64,106.8333,33.00908583,3.36599
25.68,106.99999,33.11107499,3.37639
25.72,107.16667,32.99064933,3.36411
25.76,107.3333,33.18315387,3.38374
25.8,107.50005,33.38772059,3.4046
25.84,107.66674,33.29230189,3.39487
25.88,107.8333,33.16079471,3.38146
25.92,107.99998,33.30828673,3.3965
25.96,108.16661,33.32682129,3.39839
26,108.3333,33.27033499,3.39263
26.04,108.50005,33.34810172,3.40056
26.08,108.66674,33.4983396,3.41588
26.12,108.83324,33.35682964,3.40145
26.16,108.99998,33.34819979,3.40057
26.2,109.16674,33.35545671,3.40131
26.24,109.33336,33.3259387,3.3983
26.28,109.49999,33.69241321,3.43567
26.32,109.66661,33.86530445,3.4533
26.36,109.83324,33.80460128,3.44711
26.4,110.00005,33.85755719,3.45251
26.44,110.16686,33.81117174,3.44778
26.48,110.33336,33.92689021,3.45958
26.52,110.49986,33.97876739,3.46487
26.56,110.6666,33.80744521,3.4474
26.6,110.83336,34.12380774,3.47966
26.64,111.00011,33.88717327,3.45553
26.68,111.1668,33.90100065,3.45694
26.72,111.3333,33.94326731,3.46125
26.76,111.49999,33.99887102,3.46692
26.8,111.66661,34.26884809,3.49445
26.84,111.83336,34.34671289,3.50239
26.88,112.00004,34.41212325,3.50906
26.92,112.16674,34.3411231,3.50182
26.96,112.3333,34.47076702,3.51504
27,112.49992,34.53382378,3.52147
27.04,112.66661,34.55853653,3.52399
27.08,112.83336,34.58883908,3.52708
27.12,113.00005,34.57265811,3.52543
27.16,113.16667,34.68857271,3.53725
27.2,113.33324,34.53078371,3.52116
27.24,113.49998,34.52068286,3.52013
27.28,113.66673,34.83567246,3.55225
27.32,113.8333,34.85155924,3.55387
27.36,113.99998,34.78820828,3.54741
27.4,114.16661,34.90951654,3.55978
27.44,114.33324,34.93324863,3.5622
27.48,114.49998,34.86381755,3.55512
27.52,114.66667,35.17978781,3.58734
27.56,114.8333,34.9901272,3.568
27.6,114.99998,35.16282231,3.58561
27.64,115.1666,35.14409161,3.5837
27.68,115.3333,35.00925017,3.56995
27.72,115.50005,35.1262435,3.58188
27.76,115.66673,35.15605572,3.58492
27.8,115.83329,35.25951588,3.59547
27.84,115.99999,35.20126437,3.58953
27.88,116.16667,35.16292037,3.58562
27.92,116.33337,35.47222211,3.61716
27.96,116.50004,35.63481637,3.63374
28,116.66667,35.44319443,3.6142
28.04,116.83323,35.45555081,3.61546
28.08,117.00004,35.53302334,3.62336
28.12,117.16673,35.60304283,3.6305
28.16,117.33335,35.56469882,3.62659
28.2,117.50005,35.72160522,3.64259
28.24,117.66667,35.80780568,3.65138
28.28,117.83324,35.80760954,3.65136
28.32,117.99999,35.57921267,3.62807
28.36,118.16673,35.70503199,3.6409
28.4,118.3333,35.7538691,3.64588
28.44,118.49998,35.90018432,3.6608
28.48,118.66674,36.12446241,3.68367
28.52,118.8333,35.93509599,3.66436
28.56,118.99998,35.90940257,3.66174
28.6,119.16667,36.26930663,3.69844
28.64,119.33323,36.13740718,3.68499
28.68,119.49998,36.18349844,3.68969
28.72,119.66667,36.10288778,3.68147
28.76,119.83336,36.40718813,3.7125
28.8,120.00005,36.42091744,3.7139
28.84,120.16667,36.19899295,3.69127
28.88,120.33324,36.21997918,3.69341
28.92,120.49999,36.22174437,3.69359
28.96,120.6668,36.48936785,3.72088
29,120.83342,36.52212206,3.72422
29.04,120.99999,36.74532142,3.74698
29.08,121.16661,36.63215268,3.73544
29.12,121.3333,36.59253381,3.7314
29.16,121.50005,36.76326759,3.74881
29.2,121.66673,36.5211414,3.72412
29.24,121.83336,36.70540835,3.74291
29.28,122.00005,36.57174371,3.72928
29.32,122.16668,36.68873705,3.74121
29.36,122.33323,37.02520321,3.77552
29.4,122.49999,36.93174583,3.76599
29.44,122.66668,37.0717848,3.78027
29.48,122.8333,37.04148225,3.77718
29.52,122.99999,36.91330933,3.76411
29.56,123.16661,37.18269801,3.79158
29.6,123.3333,37.18583614,3.7919
29.64,123.50004,37.03697119,3.77672
29.68,123.66674,37.20074224,3.79342
29.72,123.8333,37.25605175,3.79906
29.76,123.99992,37.25703241,3.79916
29.8,124.16661,37.28302004,3.80181
29.84,124.3333,37.25428655,3.79888
29.88,124.50005,37.29155182,3.80268
29.92,124.66667,37.35166659,3.80881
29.96,124.83324,37.52043903,3.82602
30,124.99992,37.43374825,3.81718
30.04,125.16673,37.4400245,3.81782
30.08,125.33336,37.39324678,3.81305
30.12,125.50004,37.70058719,3.84439
30.16,125.66666,37.71166871,3.84552
30.2,125.83323,37.74373645,3.84879
30.24,126.00005,37.86367178,3.86102
30.28,126.16679,37.81836506,3.8564
30.32,126.33336,37.71470877,3.84583
30.36,126.49998,37.69205541,3.84352
30.4,126.6666,38.12129248,3.88729
30.44,126.83329,37.87975469,3.86266
30.48,127.00011,38.00390688,3.87532
30.52,127.1668,37.94879351,3.8697
30.56,127.33328,37.93496613,3.86829
30.6,127.49985,38.13776765,3.88897
30.64,127.66661,37.90701718,3.86544
30.68,127.83329,38.18778157,3.89407
30.72,128.00003,38.11246649,3.88639
30.76,128.1668,38.17493485,3.89276
30.8,128.33329,38.2661367,3.90206
30.84,128.49991,38.29320305,3.90482
30.88,128.66661,38.12227314,3.88739
30.92,128.8333,38.31752355,3.9073
30.96,129.00004,38.3829339,3.91397
31,129.16672,38.62515816,3.93867
31.04,129.33329,38.55729614,3.93175
31.08,129.49985,38.46217163,3.92205
31.12,129.66667,38.60809458,3.93693
31.16,129.83336,38.53317178,3.92929
31.2,130.00011,38.55386381,3.9314
31.24,130.16666,38.64692892,3.94089
31.28,130.33323,38.66487509,3.94272
31.32,130.50004,38.67026875,3.94327
31.36,130.66679,38.5006137,3.92597
31.4,130.83336,38.06470811,3.88152
31.44,130.99998,37.7772752,3.85221
31.48,131.16667,37.04050158,3.77708
31.52,131.33335,3.706521434,0.37796
31.56,131.50009,-1.297517862,-0.13231
31.6,131.66673,-0.050013915,-0.0051
31.64,131.83328,0.18044236,0.0184
31.68,131.99999,-0.029223817,-0.00298
31.72,132.16667,-0.020692032,-0.00211
31.76,132.33329,-0.245558516,-0.02504
31.8,132.50004,-0.056584371,-0.00577
31.84,132.66667,-0.055309506,-0.00564
31.88,132.83323,0.06080123,0.0062
31.92,132.99991,0.141608026,0.01444
31.96,133.16668,-0.098654899,-0.01006
32,133.33336,-0.133468507,-0.01361
32.04,133.50004,-0.039716933,-0.00405
32.08,133.66667,0.084533323,0.00862
32.12,133.83323,0.041384063,0.00422
32.16,133.99998,0.015788707,0.00161
32.2,134.16673,-0.227023948,-0.02315
32.24,134.33336,-0.100420096,-0.01024
32.28,134.50004,0.044816391,0.00457
32.32,134.66661,-0.100223963,-0.01022
32.36,134.83323,0.124348322,0.01268
32.4,135.00004,-0.025693423,-0.00262
32.44,135.16674,0.1176798,0.012
32.48,135.33329,0.030890948,0.00315
32.52,135.50005,-0.097085835,-0.0099
32.56,135.66673,0.104833089,0.01069
32.6,135.8333,0.203586054,0.02076
32.64,135.99998,-0.08825985,-0.009
32.68,136.16666,-0.018338436,-0.00187
32.72,136.33328,0.060408964,0.00616
32.76,136.50005,-0.177010033,-0.01805
32.8,136.66674,0.11993533,0.01223
32.84,136.83336,-0.11571847,-0.0118
32.88,137.00004,-0.159848395,-0.0163
32.92,137.16667,0.072176944,0.00736
32.938,137.24166,0.102969825,0.0105