File: V_7/NatR/RDSO NatR Tensile 500.is_tens_RawData/Specimen_RawData_1.csv
Time,Extension,Load,Tensile strain,Tensile stress,Corrected Position
(sec),(mm),(N),(mm/mm),(MPa),(mm)
0.00000,0.00006,0.07244,0.00000,0.00805,0.00006
0.01000,0.00325,-0.00297,0.00003,-0.00033,0.00325
0.02000,0.02031,0.12637,0.00018,0.01404,0.02031
0.03000,0.05225,0.43895,0.00045,0.04877,0.05225
0.04000,0.09894,0.66454,0.00086,0.07384,0.09894
0.05000,0.16025,0.88118,0.00139,0.09791,0.16025
0.06000,0.23606,1.02943,0.00205,0.11438,0.23606
0.07000,0.32462,1.27231,0.00282,0.14137,0.32462
0.08000,0.42087,1.60086,0.00366,0.17787,0.42087
0.09000,0.52162,1.74770,0.00454,0.19419,0.52162
0.10000,0.62550,1.93305,0.00544,0.21478,0.62550
0.11000,0.73169,2.13853,0.00636,0.23761,0.73169
0.12000,0.83975,2.43767,0.00730,0.27085,0.83975
0.13000,0.94944,2.85262,0.00826,0.31696,0.94944
0.14000,1.06056,3.11181,0.00922,0.34576,1.06056
0.15000,1.17106,3.38976,0.01018,0.37664,1.17106
0.16000,1.27756,3.54717,0.01111,0.39413,1.27756
0.17000,1.37825,3.57046,0.01198,0.39672,1.37825
0.18000,1.47325,3.66108,0.01281,0.40679,1.47325
0.19000,1.56325,3.79685,0.01359,0.42187,1.56325
0.20000,1.64975,3.96538,0.01435,0.44060,1.64975
0.21000,1.73406,4.09315,0.01508,0.45479,1.73406
0.22000,1.81725,4.33463,0.01580,0.48163,1.81725
0.23000,1.90031,4.71721,0.01652,0.52413,1.90031
0.24000,1.98369,4.96589,0.01725,0.55177,1.98369
0.25000,2.06750,5.23380,0.01798,0.58153,2.06750
0.26000,2.15187,5.43338,0.01871,0.60371,2.15187
0.27000,2.23662,5.45417,0.01945,0.60602,2.23662
0.28000,2.32156,5.66815,0.02019,0.62979,2.32156
0.29000,2.40662,5.89244,0.02093,0.65472,2.40662
0.30000,2.49156,5.95489,0.02167,0.66165,2.49156
0.31000,2.57625,6.13830,0.02240,0.68203,2.57625
0.32000,2.66075,6.35368,0.02314,0.70596,2.66075
0.33000,2.74506,6.52428,0.02387,0.72492,2.74506
0.34000,2.82912,6.75776,0.02460,0.75086,2.82912
0.35000,2.91306,6.93275,0.02533,0.77031,2.91306
0.36000,2.99687,6.96297,0.02606,0.77366,2.99687
0.37000,3.08050,7.13749,0.02679,0.79305,3.08050
0.38000,3.16412,7.22485,0.02751,0.80276,3.16412
0.39000,3.24769,7.24589,0.02824,0.80510,3.24769
0.40000,3.33125,7.39423,0.02897,0.82158,3.33125
0.41000,3.41475,7.62786,0.02969,0.84754,3.41475
0.42000,3.49831,7.76547,0.03042,0.86283,3.49831
0.43000,3.58187,8.11048,0.03115,0.90116,3.58187
0.44000,3.66537,8.30362,0.03187,0.92262,3.66537
0.45000,3.74894,8.38358,0.03260,0.93151,3.74894
0.46000,3.83244,8.62479,0.03333,0.95831,3.83244
0.47000,3.91587,8.81328,0.03405,0.97925,3.91587
0.48000,3.99937,8.82586,0.03478,0.98065,3.99937
0.49000,4.08275,9.03593,0.03550,1.00399,4.08275
0.50000,4.16619,9.25857,0.03623,1.02873,4.16619
0.51000,4.24956,9.34664,0.03695,1.03852,4.24956
0.52000,4.33287,9.53927,0.03768,1.05992,4.33287
0.53000,4.41625,9.63682,0.03840,1.07076,4.41625
0.54000,4.49969,9.67086,0.03913,1.07454,4.49969
0.55000,4.58306,9.82767,0.03985,1.09196,4.58306
0.56000,4.66644,9.95775,0.04058,1.10642,4.66644
0.57000,4.74987,10.02777,0.04130,1.11420,4.74987
0.58000,4.83325,10.23915,0.04203,1.13768,4.83325
0.59000,4.91656,10.43390,0.04275,1.15932,4.91656
0.60000,4.99994,10.51975,0.04348,1.16886,4.99994
0.61000,5.08325,10.64969,0.04420,1.18330,5.08325
0.62000,5.16656,10.80377,0.04493,1.20042,5.16656
0.63000,5.24994,10.93786,0.04565,1.21532,5.24994
0.64000,5.33319,11.13144,0.04638,1.23683,5.33319
0.65000,5.41656,11.19646,0.04710,1.24405,5.41656
0.66000,5.49994,11.23964,0.04783,1.24885,5.49994
0.67000,5.58325,11.49474,0.04855,1.27719,5.58325
0.68000,5.66662,11.67847,0.04927,1.29761,5.66662
0.69000,5.75000,11.77717,0.05000,1.30857,5.75000
0.70000,5.83331,11.98610,0.05072,1.33179,5.83331
0.71000,5.91662,12.09024,0.05145,1.34336,5.91662
0.72000,6.00000,12.08551,0.05217,1.34283,6.00000
0.73000,6.08331,12.24412,0.05290,1.36046,6.08331
0.74000,6.16662,12.36802,0.05362,1.37422,6.16662
0.75000,6.25000,12.41147,0.05435,1.37905,6.25000
0.76000,6.33337,12.58557,0.05507,1.39840,6.33337
0.77000,6.41675,12.65542,0.05580,1.40616,6.41675
0.78000,6.50006,12.66164,0.05652,1.40685,6.50006
0.79000,6.58337,12.85581,0.05725,1.42842,6.58337
0.80000,6.66669,13.01858,0.05797,1.44651,6.66669
0.81000,6.75006,13.07451,0.05870,1.45272,6.75006
0.82000,6.83337,13.27911,0.05942,1.47546,6.83337
0.83000,6.91669,13.44462,0.06015,1.49385,6.91669
0.84000,7.00000,13.51462,0.06087,1.50162,7.00000
0.85000,7.08331,13.74087,0.06159,1.52676,7.08331
0.86000,7.16669,13.85174,0.06232,1.53908,7.16669
0.87000,7.25006,13.78588,0.06304,1.53176,7.25006
0.88000,7.33344,13.90560,0.06377,1.54507,7.33344
0.89000,7.41675,14.05200,0.06449,1.56133,7.41675
0.90000,7.50012,14.16476,0.06522,1.57386,7.50012
0.91000,7.58344,14.40166,0.06594,1.60018,7.58344
0.92000,7.66675,14.53850,0.06667,1.61539,7.66675
0.93000,7.75006,14.60029,0.06739,1.62225,7.75006
0.94000,7.83337,14.74545,0.06812,1.63838,7.83337
0.95000,7.91669,14.85372,0.06884,1.65041,7.91669
0.96000,8.00006,14.87113,0.06957,1.65235,8.00006
0.97000,8.08337,15.16417,0.07029,1.68491,8.08337
0.98000,8.16669,15.35569,0.07101,1.70619,8.16669
0.99000,8.25012,15.39385,0.07174,1.71043,8.25012
1.00000,8.33344,15.55341,0.07246,1.72816,8.33344
1.01000,8.41675,15.54925,0.07319,1.72769,8.41675
1.02000,8.50012,15.48065,0.07391,1.72007,8.50012
1.03000,8.58337,15.61226,0.07464,1.73470,8.58337
1.04000,8.66669,15.80606,0.07536,1.75623,8.66669
1.05000,8.75000,15.90366,0.07609,1.76707,8.75000
1.06000,8.83331,16.06273,0.07681,1.78475,8.83331
1.07000,8.91669,16.16321,0.07754,1.79591,8.91669
1.08000,9.00000,16.12638,0.07826,1.79182,9.00000
1.09000,9.08337,16.22366,0.07899,1.80263,9.08337
1.10000,9.16675,16.28770,0.07971,1.80974,9.16675
1.11000,9.25012,16.28197,0.08044,1.80911,9.25012
1.12000,9.33344,16.48843,0.08116,1.83205,9.33344
1.13000,9.41675,16.62504,0.08188,1.84723,9.41675
1.14000,9.50012,16.64571,0.08261,1.84952,9.50012
1.15000,9.58337,16.77179,0.08333,1.86353,9.58337
1.16000,9.66669,16.89868,0.08406,1.87763,9.66669
1.17000,9.75006,17.01342,0.08478,1.89038,9.75006
1.18000,9.83337,17.26982,0.08551,1.91887,9.83337
1.19000,9.91675,17.36610,0.08623,1.92957,9.91675
1.20000,10.00012,17.32282,0.08696,1.92476,10.00012
1.21000,10.08344,17.43036,0.08768,1.93671,10.08344
1.22000,10.16675,17.51214,0.08841,1.94579,10.16675
1.23000,10.25012,17.52825,0.08913,1.94758,10.25012
1.24000,10.33344,17.68066,0.08986,1.96452,10.33344
1.25000,10.41669,17.84154,0.09058,1.98239,10.41669
1.26000,10.50000,17.83780,0.09130,1.98198,10.50000
1.27000,10.58331,18.10531,0.09203,2.01170,10.58331
1.28000,10.66662,18.33896,0.09275,2.03766,10.66662
1.29000,10.74994,18.42308,0.09348,2.04701,10.74994
1.30000,10.83331,18.58162,0.09420,2.06462,10.83331
1.31000,10.91668,18.50760,0.09493,2.05640,10.91668
1.32000,11.00006,18.32145,0.09565,2.03572,11.00006
1.33000,11.08337,18.36717,0.09638,2.04080,11.08337
1.34000,11.16669,18.35201,0.09710,2.03911,11.16669
1.35000,11.25006,18.35409,0.09783,2.03934,11.25006
1.36000,11.33337,18.62536,0.09855,2.06948,11.33337
1.37000,11.41669,18.78972,0.09928,2.08775,11.41669
1.38000,11.50000,18.78668,0.10000,2.08741,11.50000
1.39000,11.58337,18.90198,0.10072,2.10022,11.58337
1.40000,11.66669,18.98271,0.10145,2.10919,11.66669
1.41000,11.75006,18.96032,0.10217,2.10670,11.75006
1.42000,11.83344,19.10235,0.10290,2.12248,11.83344
1.43000,11.91669,19.22894,0.10362,2.13655,11.91669
1.44000,12.00006,19.23379,0.10435,2.13709,12.00006
1.45000,12.08344,19.38764,0.10507,2.15418,12.08344
1.46000,12.16669,19.47792,0.10580,2.16421,12.16669
1.47000,12.25006,19.48774,0.10652,2.16530,12.25006
1.48000,12.33337,19.62908,0.10725,2.18101,12.33337
1.49000,12.41675,19.73765,0.10797,2.19307,12.41675
1.50000,12.50012,19.78675,0.10870,2.19853,12.50012
1.51000,12.58344,20.04141,0.10942,2.22682,12.58344
1.52000,12.66681,20.13266,0.11015,2.23696,12.66681
1.53000,12.75019,20.04609,0.11087,2.22734,12.75019
1.54000,12.83350,20.11557,0.11160,2.23506,12.83350
1.55000,12.91675,20.17636,0.11232,2.24182,12.91675
1.56000,13.00012,20.12627,0.11304,2.23625,13.00012
1.57000,13.08344,20.31853,0.11377,2.25761,13.08344
1.58000,13.16675,20.39707,0.11449,2.26634,13.16675
1.59000,13.25006,20.35796,0.11522,2.26200,13.25006
1.60000,13.33337,20.57422,0.11594,2.28602,13.33337
1.61000,13.41669,20.68820,0.11667,2.29869,13.41669
1.62000,13.50000,20.65494,0.11739,2.29499,13.50000
1.63000,13.58337,20.81753,0.11812,2.31306,13.58337
1.64000,13.66668,20.84492,0.11884,2.31610,13.66668
1.65000,13.75006,20.79444,0.11957,2.31049,13.75006
1.66000,13.83337,20.95642,0.12029,2.32849,13.83337
1.67000,13.91669,20.98498,0.12101,2.33166,13.91669
1.68000,14.00006,21.02439,0.12174,2.33604,14.00006
1.69000,14.08337,21.24566,0.12246,2.36063,14.08337
1.70000,14.16669,21.34302,0.12319,2.37145,14.16669
1.71000,14.25000,21.31355,0.12391,2.36817,14.25000
1.72000,14.33337,21.43655,0.12464,2.38184,14.33337
1.73000,14.41669,21.48308,0.12536,2.38701,14.41669
1.74000,14.50006,21.50566,0.12609,2.38952,14.50006
1.75000,14.58344,21.64813,0.12681,2.40535,14.58344
1.76000,14.66675,21.75297,0.12754,2.41700,14.66675
1.77000,14.75012,21.79040,0.12826,2.42115,14.75012
1.78000,14.83337,22.00477,0.12899,2.44497,14.83337
1.79000,14.91669,22.06991,0.12971,2.45221,14.91669
1.80000,15.00000,22.05221,0.13043,2.45025,15.00000
1.81000,15.08331,22.12301,0.13116,2.45811,15.08331
1.82000,15.16662,22.12543,0.13188,2.45838,15.16662
1.83000,15.25000,22.10114,0.13261,2.45568,15.25000
1.84000,15.33337,22.18566,0.13333,2.46507,15.33337
1.85000,15.41669,22.18233,0.13406,2.46470,15.41669
1.86000,15.50006,22.08275,0.13478,2.45364,15.50006
1.87000,15.58344,22.15762,0.13551,2.46196,15.58344
1.88000,15.66668,22.25933,0.13623,2.47326,15.66668
1.89000,15.75006,22.35450,0.13696,2.48383,15.75006
1.90000,15.83337,22.60274,0.13768,2.51142,15.83337
1.91000,15.91668,22.71344,0.13841,2.52372,15.91668
1.92000,16.00000,22.67168,0.13913,2.51908,16.00000
1.93000,16.08331,22.72559,0.13985,2.52507,16.08331
1.94000,16.16662,22.78390,0.14058,2.53154,16.16662
1.95000,16.25006,22.81290,0.14130,2.53477,16.25006
1.96000,16.33344,22.94437,0.14203,2.54937,16.33344
1.97000,16.41675,23.08426,0.14275,2.56492,16.41675
1.98000,16.50012,23.12190,0.14348,2.56910,16.50012
1.99000,16.58337,23.23434,0.14420,2.58159,16.58337
2.00000,16.66668,23.25575,0.14493,2.58397,16.66668
2.01000,16.75006,23.19033,0.14565,2.57670,16.75006
2.02000,16.83337,23.25955,0.14638,2.58439,16.83337
2.03000,16.91675,23.28656,0.14710,2.58740,16.91675
2.04000,17.00012,23.21005,0.14783,2.57889,17.00012
2.05000,17.08344,23.37127,0.14855,2.59681,17.08344
2.06000,17.16675,23.48795,0.14928,2.60977,17.16675
2.07000,17.25012,23.46948,0.15000,2.60772,17.25012
2.08000,17.33343,23.63715,0.15073,2.62635,17.33343
2.09000,17.41675,23.82150,0.15145,2.64683,17.41675
2.10000,17.50012,23.82583,0.15217,2.64731,17.50012
2.11000,17.58337,23.97133,0.15290,2.66348,17.58337
2.12000,17.66675,24.08754,0.15362,2.67639,17.66675
2.13000,17.75006,24.09820,0.15435,2.67758,17.75006
2.14000,17.83337,24.17155,0.15507,2.68573,17.83337
2.15000,17.91675,24.15582,0.15580,2.68398,17.91675
2.16000,18.00012,24.19606,0.15652,2.68845,18.00012
2.17000,18.08343,24.38462,0.15725,2.70940,18.08343
2.18000,18.16675,24.50566,0.15797,2.72285,18.16675
2.19000,18.25012,24.45846,0.15870,2.71761,18.25012
2.20000,18.33337,24.57141,0.15942,2.73016,18.33337
2.21000,18.41668,24.57878,0.16015,2.73098,18.41668
2.22000,18.50006,24.51104,0.16087,2.72345,18.50006
2.23000,18.58337,24.65368,0.16159,2.73930,18.58337
2.24000,18.66675,24.65677,0.16232,2.73964,18.66675
2.25000,18.75012,24.48596,0.16304,2.72066,18.75012
2.26000,18.83350,24.58300,0.16377,2.73144,18.83350
2.27000,18.91675,24.59191,0.16449,2.73243,18.91675
2.28000,19.00012,24.54300,0.16522,2.72700,19.00012
2.29000,19.08337,24.74165,0.16594,2.74907,19.08337
2.30000,19.16668,24.84329,0.16667,2.76037,19.16668
2.31000,19.25000,24.88034,0.16739,2.76448,19.25000
2.32000,19.33331,25.01279,0.16812,2.77920,19.33331
2.33000,19.41662,25.06667,0.16884,2.78519,19.41662
2.34000,19.50000,25.09237,0.16957,2.78804,19.50000
2.35000,19.58331,25.27100,0.17029,2.80789,19.58331
2.36000,19.66662,25.36108,0.17101,2.81790,19.66662
2.37000,19.75000,25.24891,0.17174,2.80543,19.75000
2.38000,19.83337,25.34411,0.17246,2.81601,19.83337
2.39000,19.91675,25.40460,0.17319,2.82273,19.91675
2.40000,20.00012,25.41224,0.17391,2.82358,20.00012
2.41000,20.08343,25.55664,0.17464,2.83963,20.08343
2.42000,20.16675,25.61420,0.17536,2.84602,20.16675
2.43000,20.25006,25.53350,0.17609,2.83706,20.25006
2.44000,20.33337,25.66866,0.17681,2.85207,20.33337
2.45000,20.41668,25.71128,0.17754,2.85681,20.41668
2.46000,20.50000,25.63038,0.17826,2.84782,20.50000
2.47000,20.58331,25.72806,0.17899,2.85867,20.58331
2.48000,20.66668,25.75840,0.17971,2.86204,20.66668
2.49000,20.75006,25.71770,0.18044,2.85752,20.75006
2.50000,20.83337,25.83121,0.18116,2.87013,20.83337
2.51000,20.91675,25.78745,0.18188,2.86527,20.91675
2.52000,21.00006,25.73413,0.18261,2.85935,21.00006
2.53000,21.08337,25.93733,0.18333,2.88193,21.08337
2.54000,21.16668,26.08046,0.18406,2.89783,21.16668
2.55000,21.25000,26.13000,0.18478,2.90333,21.25000
2.56000,21.33331,26.24237,0.18551,2.91582,21.33331
2.57000,21.41662,26.27685,0.18623,2.91965,21.41662
2.58000,21.50000,26.23980,0.18696,2.91553,21.50000
2.59000,21.58337,26.27793,0.18768,2.91977,21.58337
2.60000,21.66675,26.21477,0.18841,2.91275,21.66675
2.61000,21.75012,26.09165,0.18913,2.89907,21.75012
2.62000,21.83344,26.17193,0.18986,2.90799,21.83344
2.63000,21.91681,26.26973,0.19058,2.91886,21.91681
2.64000,22.00012,26.28922,0.19131,2.92102,22.00012
2.65000,22.08343,26.44178,0.19203,2.93798,22.08343
2.66000,22.16668,26.52904,0.19275,2.94767,22.16668
2.67000,22.25006,26.46681,0.19348,2.94076,22.25006
2.68000,22.33337,26.56612,0.19420,2.95179,22.33337
2.69000,22.41675,26.65370,0.19493,2.96152,22.41675
2.70000,22.50012,26.57315,0.19565,2.95257,22.50012
2.71000,22.58343,26.73200,0.19638,2.97022,22.58343
2.72000,22.66681,26.88490,0.19710,2.98721,22.66681
2.73000,22.75012,26.91041,0.19783,2.99005,22.75012
2.74000,22.83343,26.96135,0.19855,2.99571,22.83343
2.75000,22.91668,26.94380,0.19928,2.99376,22.91668
2.76000,23.00000,26.84520,0.20000,2.98280,23.00000
2.77000,23.08337,26.95688,0.20072,2.99521,23.08337
2.78000,23.16668,27.02658,0.20145,3.00295,23.16668
2.79000,23.25006,26.95935,0.20217,2.99548,23.25006
2.80000,23.33337,27.10091,0.20290,3.01121,23.33337
2.81000,23.41675,27.22229,0.20362,3.02470,23.41675
2.82000,23.50012,27.22601,0.20435,3.02511,23.50012
2.83000,23.58343,27.30938,0.20507,3.03437,23.58343
2.84000,23.66675,27.27918,0.20580,3.03102,23.66675
2.85000,23.75006,27.22608,0.20652,3.02512,23.75006
2.86000,23.83337,27.36286,0.20725,3.04032,23.83337
2.87000,23.91668,27.41807,0.20797,3.04645,23.91668
2.88000,24.00006,27.41287,0.20870,3.04588,24.00006
2.89000,24.08337,27.46583,0.20942,3.05176,24.08337
2.90000,24.16668,27.52407,0.21015,3.05823,24.16668
2.91000,24.25012,27.44807,0.21087,3.04979,24.25012
2.92000,24.33343,27.56754,0.21160,3.06306,24.33343
2.93000,24.41674,27.64767,0.21232,3.07196,24.41674
2.94000,24.50006,27.60513,0.21304,3.06724,24.50006
2.95000,24.58337,27.70128,0.21377,3.07792,24.58337
2.96000,24.66662,27.70645,0.21449,3.07849,24.66662
2.97000,24.75000,27.61725,0.21522,3.06858,24.75000
2.98000,24.83331,27.83704,0.21594,3.09300,24.83331
2.99000,24.91668,27.96623,0.21667,3.10736,24.91668
3.00000,24.99999,27.99745,0.21739,3.11083,24.99999
3.01000,25.08337,28.07928,0.21812,3.11992,25.08337
3.02000,25.16675,28.05844,0.21884,3.11760,25.16675
3.03000,25.25012,27.92873,0.21957,3.10319,25.25012
3.04000,25.33343,28.05374,0.22029,3.11708,25.33343
3.05000,25.41675,28.15432,0.22102,3.12826,25.41675
3.06000,25.50012,28.16475,0.22174,3.12942,25.50012
3.07000,25.58337,28.24731,0.22246,3.13859,25.58337
3.08000,25.66668,28.24910,0.22319,3.13879,25.66668
3.09000,25.75000,28.19194,0.22391,3.13244,25.75000
3.10000,25.83331,28.32914,0.22464,3.14768,25.83331
3.11000,25.91662,28.48755,0.22536,3.16528,25.91662
3.12000,26.00000,28.44640,0.22609,3.16071,26.00000
3.13000,26.08331,28.49710,0.22681,3.16634,26.08331
3.14000,26.16668,28.55710,0.22754,3.17301,26.16668
3.15000,26.25006,28.56538,0.22826,3.17393,26.25006
3.16000,26.33337,28.73961,0.22899,3.19329,26.33337
3.17000,26.41675,28.82425,0.22971,3.20269,26.41675
3.18000,26.50006,28.77409,0.23044,3.19712,26.50006
3.19000,26.58337,28.79351,0.23116,3.19928,26.58337
3.20000,26.66668,28.79447,0.23188,3.19939,26.66668
3.21000,26.75006,28.72239,0.23261,3.19138,26.75006
3.22000,26.83337,28.86860,0.23333,3.20762,26.83337
3.23000,26.91675,28.94436,0.23406,3.21604,26.91675
3.24000,27.00012,28.83302,0.23478,3.20367,27.00012
3.25000,27.08343,28.96260,0.23551,3.21807,27.08343
3.26000,27.16681,29.05432,0.23623,3.22826,27.16681
3.27000,27.25018,28.96804,0.23696,3.21867,27.25018
3.28000,27.33350,29.05643,0.23768,3.22849,27.33350
3.29000,27.41681,29.12287,0.23841,3.23587,27.41681
3.30000,27.50012,29.04739,0.23913,3.22749,27.50012
3.31000,27.58331,29.08910,0.23985,3.23212,27.58331
3.32000,27.66662,29.14246,0.24058,3.23805,27.66662
3.33000,27.74999,29.13237,0.24130,3.23693,27.74999
3.34000,27.83331,29.25681,0.24203,3.25076,27.83331
3.35000,27.91668,29.40503,0.24275,3.26723,27.91668
3.36000,28.00006,29.35448,0.24348,3.26161,28.00006
3.37000,28.08337,29.49641,0.24420,3.27738,28.08337
3.38000,28.16668,29.56822,0.24493,3.28536,28.16668
3.39000,28.25006,29.51669,0.24565,3.27963,28.25006
3.40000,28.33337,29.62288,0.24638,3.29143,28.33337
3.41000,28.41668,29.62100,0.24710,3.29122,28.41668
3.42000,28.50006,29.50459,0.24783,3.27829,28.50006
3.43000,28.58337,29.52502,0.24855,3.28056,28.58337
3.44000,28.66675,29.51221,0.24928,3.27913,28.66675
3.45000,28.75012,29.45691,0.25000,3.27299,28.75012
3.46000,28.83343,29.61975,0.25073,3.29108,28.83343
3.47000,28.91675,29.70924,0.25145,3.30103,28.91675
3.48000,29.00012,29.65854,0.25217,3.29539,29.00012
3.49000,29.08343,29.84803,0.25290,3.31645,29.08343
3.50000,29.16669,29.93201,0.25362,3.32578,29.16669
3.51000,29.25000,29.86422,0.25435,3.31825,29.25000
3.52000,29.33331,30.00298,0.25507,3.33366,29.33331
3.53000,29.41662,30.07724,0.25580,3.34192,29.41662
3.54000,29.50000,30.10119,0.25652,3.34458,29.50000
3.55000,29.58337,30.22639,0.25725,3.35849,29.58337
3.56000,29.66668,30.28174,0.25797,3.36464,29.66668
3.57000,29.75006,30.17317,0.25870,3.35257,29.75006
3.58000,29.83343,30.27452,0.25942,3.36384,29.83343
3.59000,29.91674,30.35007,0.26015,3.37223,29.91674
3.60000,30.00012,30.27902,0.26087,3.36434,30.00012
3.61000,30.08337,30.43682,0.26159,3.38187,30.08337
3.62000,30.16668,30.48487,0.26232,3.38721,30.16668
3.63000,30.25006,30.43173,0.26304,3.38130,30.25006
3.64000,30.33337,30.57319,0.26377,3.39702,30.33337
3.65000,30.41668,30.66537,0.26449,3.40726,30.41668
3.66000,30.50006,30.65901,0.26522,3.40656,30.50006
3.67000,30.58337,30.83167,0.26594,3.42574,30.58337
3.68000,30.66675,30.85234,0.26667,3.42804,30.66675
3.69000,30.75006,30.75021,0.26739,3.41669,30.75006
3.70000,30.83337,30.79870,0.26812,3.42208,30.83337
3.71000,30.91662,30.79542,0.26884,3.42171,30.91662
3.72000,31.00000,30.67105,0.26957,3.40789,31.00000
3.73000,31.08331,30.77470,0.27029,3.41941,31.08331
3.74000,31.16662,30.88344,0.27101,3.43149,31.16662
3.75000,31.25000,30.85743,0.27174,3.42860,31.25000
3.76000,31.33331,31.04900,0.27246,3.44989,31.33331
3.77000,31.41668,31.17239,0.27319,3.46360,31.41668
3.78000,31.50012,31.14770,0.27391,3.46086,31.50012
3.79000,31.58343,31.22612,0.27464,3.46957,31.58343
3.80000,31.66674,31.23969,0.27536,3.47108,31.66674
3.81000,31.75012,31.11087,0.27609,3.45676,31.75012
3.82000,31.83343,31.23577,0.27681,3.47064,31.83343
3.83000,31.91668,31.42053,0.27754,3.49117,31.91668
3.84000,32.00006,31.40339,0.27826,3.48927,32.00006
3.85000,32.08337,31.52271,0.27899,3.50252,32.08337
3.86000,32.16675,31.60975,0.27971,3.51219,32.16675
3.87000,32.25012,31.54186,0.28044,3.50465,32.25012
3.88000,32.33343,31.67362,0.28116,3.51929,32.33343
3.89000,32.41675,31.72123,0.28188,3.52458,32.41675
3.90000,32.50012,31.57385,0.28261,3.50821,32.50012
3.91000,32.58343,31.64565,0.28333,3.51618,32.58343
3.92000,32.66674,31.77247,0.28406,3.53027,32.66674
3.93000,32.75006,31.74710,0.28478,3.52746,32.75006
3.94000,32.83337,31.97961,0.28551,3.55329,32.83337
3.95000,32.91668,32.11167,0.28623,3.56796,32.91668
3.96000,33.00000,32.08728,0.28696,3.56525,33.00000
3.97000,33.08337,32.22217,0.28768,3.58024,33.08337
3.98000,33.16668,32.24789,0.28841,3.58310,33.16668
3.99000,33.25012,32.24157,0.28913,3.58240,33.25012
4.00000,33.33343,32.41331,0.28986,3.60148,33.33343
4.01000,33.41675,32.36104,0.29058,3.59567,33.41675
4.02000,33.50012,32.13876,0.29131,3.57097,33.50012
4.03000,33.58343,32.15443,0.29203,3.57271,33.58343
4.04000,33.66675,32.13376,0.29275,3.57042,33.66675
4.05000,33.75012,32.03301,0.29348,3.55922,33.75012
4.06000,33.83343,32.24775,0.29420,3.58308,33.83343
4.07000,33.91674,32.34943,0.29493,3.59438,33.91674
4.08000,34.00006,32.35908,0.29565,3.59545,34.00006
4.09000,34.08337,32.55614,0.29638,3.61735,34.08337
4.10000,34.16668,32.65278,0.29710,3.62809,34.16668
4.11000,34.25006,32.58719,0.29783,3.62080,34.25006
4.12000,34.33337,32.72209,0.29855,3.63579,34.33337
4.13000,34.41668,32.76274,0.29928,3.64030,34.41668
4.14000,34.50006,32.66169,0.30000,3.62908,34.50006
4.15000,34.58337,32.76186,0.30072,3.64021,34.58337
4.16000,34.66668,32.88427,0.30145,3.65381,34.66668
4.17000,34.75006,32.83039,0.30217,3.64782,34.75006
4.18000,34.83337,32.96911,0.30290,3.66323,34.83337
4.19000,34.91668,33.03161,0.30362,3.67018,34.91668
4.20000,35.00012,32.83088,0.30435,3.64788,35.00012
4.21000,35.08343,32.89583,0.30507,3.65509,35.08343
4.22000,35.16675,33.02196,0.30580,3.66911,35.16675
4.23000,35.25012,32.89730,0.30652,3.65526,35.25012
4.24000,35.33337,33.07363,0.30725,3.67485,35.33337
4.25000,35.41668,33.20128,0.30797,3.68903,35.41668
4.26000,35.50006,33.09602,0.30870,3.67734,35.50006
4.27000,35.58337,33.16508,0.30942,3.68501,35.58337
4.28000,35.66668,33.14618,0.31015,3.68291,35.66668
4.29000,35.75006,33.02304,0.31087,3.66923,35.75006
4.30000,35.83337,33.20447,0.31159,3.68939,35.83337
4.31000,35.91668,33.34970,0.31232,3.70552,35.91668
4.32000,36.00006,33.25536,0.31304,3.69504,36.00006
4.33000,36.08331,33.42998,0.31377,3.71444,36.08331
4.34000,36.16662,33.56057,0.31449,3.72895,36.16662
4.35000,36.24993,33.50292,0.31522,3.72255,36.24993
4.36000,36.33331,33.61900,0.31594,3.73545,36.33331
4.37000,36.41662,33.65158,0.31667,3.73906,36.41662
4.38000,36.50000,33.53666,0.31739,3.72630,36.50000
4.39000,36.58331,33.64046,0.31812,3.73783,36.58331
4.40000,36.66668,33.79921,0.31884,3.75547,36.66668
4.41000,36.75006,33.74141,0.31957,3.74905,36.75006
4.42000,36.83343,33.79260,0.32029,3.75473,36.83343
4.43000,36.91674,33.82483,0.32102,3.75831,36.91674
4.44000,37.00012,33.74670,0.32174,3.74963,37.00012
4.45000,37.08343,33.95125,0.32246,3.77236,37.08343
4.46000,37.16674,34.08341,0.32319,3.78705,37.16674
4.47000,37.25006,34.04814,0.32391,3.78313,37.25006
4.48000,37.33337,34.14454,0.32464,3.79384,37.33337
4.49000,37.41668,34.15041,0.32536,3.79449,37.41668
4.50000,37.50006,33.95409,0.32609,3.77268,37.50006
4.51000,37.58343,34.03001,0.32681,3.78111,37.58343
4.52000,37.66675,34.12646,0.32754,3.79183,37.66675
4.53000,37.75012,34.10706,0.32826,3.78967,37.75012
4.54000,37.83349,34.26493,0.32899,3.80721,37.83349
4.55000,37.91681,34.35668,0.32971,3.81741,37.91681
4.56000,38.00012,34.28947,0.33044,3.80994,38.00012
4.57000,38.08343,34.36711,0.33116,3.81857,38.08343
4.58000,38.16668,34.36564,0.33188,3.81840,38.16668
4.59000,38.25006,34.23275,0.33261,3.80364,38.25006
4.60000,38.33337,34.36672,0.33333,3.81852,38.33337
4.61000,38.41668,34.47178,0.33406,3.83020,38.41668
4.62000,38.50006,34.47761,0.33478,3.83085,38.50006
4.63000,38.58343,34.67790,0.33551,3.85310,38.58343
4.64000,38.66674,34.75529,0.33623,3.86170,38.66674
4.65000,38.75012,34.60203,0.33696,3.84467,38.75012
4.66000,38.83343,34.69872,0.33768,3.85541,38.83343
4.67000,38.91675,34.82578,0.33841,3.86953,38.91675
4.68000,39.00006,34.87662,0.33913,3.87518,39.00006
4.69000,39.08331,35.06006,0.33985,3.89556,39.08331
4.70000,39.16662,35.12869,0.34058,3.90319,39.16662
4.71000,39.24999,35.06785,0.34130,3.89643,39.24999
4.72000,39.33331,35.13848,0.34203,3.90428,39.33331
4.73000,39.41668,35.16616,0.34275,3.90735,39.41668
4.74000,39.50006,35.01177,0.34348,3.89020,39.50006
4.75000,39.58337,35.05948,0.34420,3.89550,39.58337
4.76000,39.66668,35.02401,0.34493,3.89156,39.66668
4.77000,39.75006,34.80922,0.34565,3.86769,39.75006
4.78000,39.83337,34.97184,0.34638,3.88576,39.83337
4.79000,39.91668,35.22646,0.34710,3.91405,39.91668
4.80000,39.99999,35.27754,0.34783,3.91973,39.99999
4.81000,40.08337,35.37850,0.34855,3.93094,40.08337
4.82000,40.16668,35.40303,0.34928,3.93367,40.16668
4.83000,40.25005,35.30987,0.35000,3.92332,40.25005
4.84000,40.33337,35.34421,0.35072,3.92713,40.33337
4.85000,40.41668,35.37840,0.35145,3.93093,40.41668
4.86000,40.50006,35.29508,0.35217,3.92168,40.50006
4.87000,40.58337,35.36263,0.35290,3.92918,40.58337
4.88000,40.66668,35.42214,0.35362,3.93579,40.66668
4.89000,40.74999,35.33794,0.35435,3.92644,40.74999
4.90000,40.83330,35.51001,0.35507,3.94556,40.83330
4.91000,40.91662,35.66793,0.35580,3.96310,40.91662
4.92000,40.99999,35.62703,0.35652,3.95856,40.99999
4.93000,41.08331,35.78794,0.35725,3.97644,41.08331
4.94000,41.16662,35.83006,0.35797,3.98112,41.16662
4.95000,41.25006,35.66676,0.35870,3.96297,41.25006
4.96000,41.33337,35.68184,0.35942,3.96465,41.33337
4.97000,41.41668,35.74454,0.36015,3.97162,41.41668
4.98000,41.50006,35.70815,0.36087,3.96757,41.50006
4.99000,41.58337,35.88708,0.36159,3.98745,41.58337
5.00000,41.66668,36.00875,0.36232,4.00097,41.66668
5.01000,41.75006,35.91103,0.36304,3.99011,41.75006
5.02000,41.83337,36.01424,0.36377,4.00158,41.83337
5.03000,41.91668,36.06009,0.36449,4.00668,41.91668
5.04000,41.99999,35.91015,0.36522,3.99002,41.99999
5.05000,42.08337,35.99371,0.36594,3.99930,42.08337
5.06000,42.16674,36.07640,0.36667,4.00849,42.16674
5.07000,42.25012,36.08301,0.36739,4.00922,42.25012
5.08000,42.33350,36.28927,0.36812,4.03214,42.33350
5.09000,42.41681,36.38910,0.36884,4.04323,42.41681
5.10000,42.50012,36.28109,0.36957,4.03123,42.50012
5.11000,42.58343,36.40467,0.37029,4.04496,42.58343
5.12000,42.66668,36.52478,0.37101,4.05831,42.66668
5.13000,42.74999,36.43583,0.37174,4.04843,42.74999
5.14000,42.83330,36.48990,0.37246,4.05443,42.83330
5.15000,42.91662,36.57611,0.37319,4.06401,42.91662
5.16000,42.99999,36.48138,0.37391,4.05349,42.99999
5.17000,43.08337,36.55456,0.37464,4.06162,43.08337
5.18000,43.16675,36.61397,0.37536,4.06822,43.16675
5.19000,43.25012,36.57518,0.37609,4.06391,43.25012
5.20000,43.33343,36.72046,0.37681,4.08005,43.33343
5.21000,43.41675,36.83278,0.37754,4.09253,43.41675
5.22000,43.50000,36.65786,0.37826,4.07310,43.50000
5.23000,43.58337,36.68299,0.37899,4.07589,43.58337
5.24000,43.66668,36.75485,0.37971,4.08387,43.66668
5.25000,43.75000,36.75793,0.38043,4.08421,43.75000
5.26000,43.83337,36.92545,0.38116,4.10283,43.83337
5.27000,43.91668,37.00853,0.38188,4.11206,43.91668
5.28000,44.00006,36.88372,0.38261,4.09819,44.00006
5.29000,44.08343,36.96636,0.38333,4.10737,44.08343
5.30000,44.16680,37.08264,0.38406,4.12029,44.16680
5.31000,44.25018,36.99099,0.38478,4.11011,44.25018
5.32000,44.33343,37.08391,0.38551,4.12043,44.33343
5.33000,44.41668,37.21127,0.38623,4.13459,44.41668
5.34000,44.49999,37.11516,0.38696,4.12391,44.49999
5.35000,44.58331,37.25119,0.38768,4.13902,44.58331
5.36000,44.66662,37.36247,0.38841,4.15139,44.66662
5.37000,44.74999,37.31300,0.38913,4.14589,44.74999
5.38000,44.83337,37.43320,0.38986,4.15925,44.83337
5.39000,44.91668,37.52941,0.39058,4.16993,44.91668
5.40000,45.00012,37.42576,0.39131,4.15842,45.00012
5.41000,45.08337,37.48194,0.39203,4.16466,45.08337
5.42000,45.16668,37.59210,0.39275,4.17690,45.16668
5.43000,45.25006,37.48699,0.39348,4.16522,45.25006
5.44000,45.33330,37.61797,0.39420,4.17977,45.33330
5.45000,45.41662,37.70148,0.39493,4.18905,45.41662
5.46000,45.49999,37.60611,0.39565,4.17846,45.49999
5.47000,45.58331,37.71784,0.39638,4.19087,45.58331
5.48000,45.66668,37.86885,0.39710,4.20765,45.66668
5.49000,45.75005,37.81605,0.39783,4.20178,45.75005
5.50000,45.83343,38.01472,0.39855,4.22386,45.83343
5.51000,45.91668,38.16549,0.39928,4.24061,45.91668
5.52000,46.00006,38.11112,0.40000,4.23457,46.00006
5.53000,46.08337,38.18484,0.40072,4.24276,46.08337
5.54000,46.16662,38.25136,0.40145,4.25015,46.16662
5.55000,46.24999,38.16427,0.40217,4.24047,46.24999
5.56000,46.33330,38.19424,0.40290,4.24380,46.33330
5.57000,46.41668,38.18606,0.40362,4.24290,46.41668
5.58000,46.50006,38.03108,0.40435,4.22568,46.50006
5.59000,46.58337,38.18831,0.40507,4.24315,46.58337
5.60000,46.66674,38.33521,0.40580,4.25947,46.66674
5.61000,46.75006,38.29309,0.40652,4.25479,46.75006
5.62000,46.83343,38.40653,0.40725,4.26739,46.83343
5.63000,46.91668,38.46100,0.40797,4.27344,46.91668
5.64000,47.00006,38.35770,0.40870,4.26197,47.00006
5.65000,47.08337,38.55921,0.40942,4.28436,47.08337
5.66000,47.16674,38.71595,0.41015,4.30177,47.16674
5.67000,47.25012,38.63293,0.41087,4.29255,47.25012
5.68000,47.33343,38.71238,0.41160,4.30137,47.33343
5.69000,47.41674,38.75289,0.41232,4.30588,47.41674
5.70000,47.50011,38.65972,0.41304,4.29552,47.50011
5.71000,47.58343,38.77150,0.41377,4.30794,47.58343
5.72000,47.66680,38.87676,0.41449,4.31964,47.66680
5.73000,47.75012,38.77267,0.41522,4.30807,47.75012
5.74000,47.83343,38.91923,0.41594,4.32436,47.83343
5.75000,47.91668,39.01151,0.41667,4.33461,47.91668
5.76000,48.00005,38.82778,0.41739,4.31420,48.00005
5.77000,48.08336,38.80828,0.41812,4.31203,48.08336
5.78000,48.16668,38.87142,0.41884,4.31905,48.16668
5.79000,48.24999,38.75945,0.41957,4.30661,48.24999
5.80000,48.33337,38.81274,0.42029,4.31253,48.33337
5.81000,48.41668,38.93084,0.42101,4.32565,48.41668
5.82000,48.50006,38.88999,0.42174,4.32111,48.50006
5.83000,48.58343,39.04311,0.42246,4.33812,48.58343
5.84000,48.66675,39.18711,0.42319,4.35412,48.66675
5.85000,48.75006,39.18040,0.42391,4.35338,48.75006
5.86000,48.83337,39.31843,0.42464,4.36871,48.83337
5.87000,48.91668,39.39960,0.42536,4.37773,48.91668
5.88000,48.99999,39.30648,0.42609,4.36739,48.99999
5.89000,49.08337,39.32671,0.42681,4.36963,49.08337
5.90000,49.16668,39.37516,0.42754,4.37502,49.16668
5.91000,49.25005,39.34023,0.42826,4.37114,49.25005
5.92000,49.33337,39.41439,0.42899,4.37938,49.33337
5.93000,49.41668,39.43379,0.42971,4.38153,49.41668
5.94000,49.50006,39.28008,0.43044,4.36445,49.50006
5.95000,49.58337,39.44765,0.43116,4.38307,49.58337
5.96000,49.66668,39.56628,0.43188,4.39625,49.66668
5.97000,49.75006,39.50520,0.43261,4.38947,49.75006
5.98000,49.83337,39.59533,0.43333,4.39948,49.83337
5.99000,49.91662,39.64652,0.43406,4.40517,49.91662
6.00000,49.99999,39.58882,0.43478,4.39876,49.99999
6.01000,50.08331,39.74561,0.43551,4.41618,50.08331
6.02000,50.16668,39.86091,0.43623,4.42899,50.16668
6.03000,50.25005,39.81105,0.43696,4.42345,50.25005
6.04000,50.33337,39.95501,0.43768,4.43945,50.33337
6.05000,50.41674,40.02383,0.43841,4.44709,50.41674
6.06000,50.50005,39.89383,0.43913,4.43265,50.50005
6.07000,50.58337,39.93659,0.43986,4.43740,50.58337
6.08000,50.66668,40.00120,0.44058,4.44458,50.66668
6.09000,50.75006,39.90583,0.44130,4.43398,50.75006
6.10000,50.83337,40.05831,0.44203,4.45092,50.83337
6.11000,50.91668,40.12164,0.44275,4.45796,50.91668
6.12000,51.00005,39.99317,0.44348,4.44369,51.00005
6.13000,51.08337,40.15089,0.44420,4.46121,51.08337
6.14000,51.16668,40.26271,0.44493,4.47363,51.16668
6.15000,51.25005,40.18816,0.44565,4.46535,51.25005
6.16000,51.33336,40.25400,0.44638,4.47267,51.33336
6.17000,51.41668,40.25899,0.44710,4.47322,51.41668
6.18000,51.49999,40.13193,0.44783,4.45910,51.49999
6.19000,51.58330,40.34657,0.44855,4.48295,51.58330
6.20000,51.66662,40.51527,0.44927,4.50170,51.66662
6.21000,51.74999,40.42519,0.45000,4.49169,51.74999
6.22000,51.83337,40.53398,0.45072,4.50378,51.83337
6.23000,51.91668,40.52673,0.45145,4.50297,51.91668
6.24000,52.00012,40.34300,0.45217,4.48256,52.00012
6.25000,52.08343,40.44228,0.45290,4.49359,52.08343
6.26000,52.16680,40.58374,0.45362,4.50931,52.16680
6.27000,52.25012,40.50116,0.45435,4.50013,52.25012
6.28000,52.33343,40.65237,0.45507,4.51693,52.33343
6.29000,52.41674,40.79383,0.45580,4.53265,52.41674
6.30000,52.50012,40.70919,0.45652,4.52324,52.50012
6.31000,52.58343,40.78202,0.45725,4.53134,52.58343
6.32000,52.66680,40.83336,0.45797,4.53704,52.66680
6.33000,52.75012,40.64492,0.45870,4.51610,52.75012
6.34000,52.83343,40.66667,0.45942,4.51852,52.83343
6.35000,52.91674,40.67260,0.46015,4.51918,52.91674
6.36000,53.00005,40.64066,0.46087,4.51563,53.00005
6.37000,53.08331,40.82817,0.46159,4.53646,53.08331
6.38000,53.16662,40.93931,0.46232,4.54881,53.16662
6.39000,53.24993,40.87230,0.46304,4.54137,53.24993
6.40000,53.33324,40.98770,0.46377,4.55419,53.33324
6.41000,53.41662,41.11275,0.46449,4.56808,53.41662
6.42000,53.49999,41.08748,0.46522,4.56528,53.49999
6.43000,53.58336,41.24780,0.46594,4.58309,53.58336
6.44000,53.66668,41.31569,0.46667,4.59063,53.66668
6.45000,53.75012,41.15243,0.46739,4.57249,53.75012
6.46000,53.83349,41.19563,0.46812,4.57729,53.83349
6.47000,53.91681,41.28620,0.46884,4.58736,53.91681
6.48000,54.00012,41.19779,0.46957,4.57753,54.00012
6.49000,54.08343,41.28223,0.47029,4.58691,54.08343
6.50000,54.16668,41.35203,0.47101,4.59467,54.16668
6.51000,54.24999,41.18069,0.47174,4.57563,54.24999
6.52000,54.33330,41.23668,0.47246,4.58185,54.33330
6.53000,54.41662,41.24907,0.47319,4.58323,54.41662
6.54000,54.49999,41.07763,0.47391,4.56418,54.49999
6.55000,54.58337,40.59854,0.47464,4.51095,54.58337
6.56000,54.66668,32.79826,0.47536,3.64425,54.66668
6.57000,54.75005,21.03920,0.47609,2.33769,54.75005
6.58000,54.83337,10.98395,0.47681,1.22044,54.83337
6.59000,54.91674,4.09249,0.47754,0.45472,54.91674
6.60000,55.00006,0.14860,0.47826,0.01651,55.00006
6.61000,55.08337,-1.34768,0.47899,-0.14974,55.08337
6.62000,55.16668,-1.64248,0.47971,-0.18250,55.16668
6.63000,55.25006,-1.49688,0.48044,-0.16632,55.25006
6.64000,55.33337,-0.89068,0.48116,-0.09896,55.33337
6.65000,55.41668,-0.42165,0.48188,-0.04685,55.41668
6.66000,55.50005,-0.19689,0.48261,-0.02188,55.50005
6.67000,55.58343,0.05307,0.48333,0.00590,55.58343
6.68000,55.66674,0.07631,0.48406,0.00848,55.66674
6.69000,55.75012,-0.10228,0.48478,-0.01136,55.75012
6.70000,55.83337,-0.01776,0.48551,-0.00197,55.83337
6.71000,55.91668,0.04050,0.48623,0.00450,55.91668
6.72000,56.00005,-0.09589,0.48696,-0.01065,56.00005
6.73000,56.08337,-0.01490,0.48768,-0.00166,56.08337
6.74000,56.16662,0.10129,0.48841,0.01125,56.16662
6.75000,56.24999,0.00109,0.48913,0.00012,56.24999
6.76000,56.33330,0.10702,0.48985,0.01189,56.33330
6.77000,56.41662,0.11611,0.49058,0.01290,56.41662
6.78000,56.50006,-0.09866,0.49130,-0.01096,56.50006
6.79000,56.58337,-0.11587,0.49203,-0.01287,56.58337
6.80000,56.66674,-0.07182,0.49275,-0.00798,56.66674
6.81000,56.75005,-0.19070,0.49348,-0.02119,56.75005
6.82000,56.83343,-0.10390,0.49420,-0.01154,56.83343
6.83000,56.91674,0.02142,0.49493,0.00238,56.91674
6.84000,57.00005,-0.02756,0.49565,-0.00306,57.00005
6.85000,57.08337,0.02860,0.49638,0.00318,57.08337
6.86000,57.16674,0.01439,0.49710,0.00160,57.16674
6.87000,57.25012,-0.17771,0.49783,-0.01975,57.25012
6.88000,57.33343,-0.13821,0.49855,-0.01536,57.33343
6.89000,57.41674,-0.08218,0.49928,-0.00913,57.41674
6.90000,57.50012,-0.20240,0.50000,-0.02249,57.50012
6.91000,57.58343,-0.06481,0.50073,-0.00720,57.58343
6.92000,57.66674,0.04711,0.50145,0.00523,57.66674
6.93000,57.75006,-0.11296,0.50217,-0.01255,57.75006
6.94000,57.83337,-0.04850,0.50290,-0.00539,57.83337
6.95000,57.91668,-0.01620,0.50362,-0.00180,57.91668
6.96000,57.99999,-0.22748,0.50435,-0.02528,57.99999
6.97000,58.08337,-0.22285,0.50507,-0.02476,58.08337
6.98000,58.16668,-0.17664,0.50580,-0.01963,58.16668
6.99000,58.25012,-0.23806,0.50652,-0.02645,58.25012
7.00000,58.33343,-0.07757,0.50725,-0.00862,58.33343
7.01000,58.41674,0.04868,0.50797,0.00541,58.41674
7.02000,58.50011,0.04956,0.50870,0.00551,58.50011
7.03000,58.58337,0.16658,0.50942,0.01851,58.58337
7.04000,58.66668,0.20104,0.51015,0.02234,58.66668
7.05000,58.75005,-0.00045,0.51087,-0.00005,58.75005
7.06000,58.83337,0.04971,0.51159,0.00552,58.83337
7.07000,58.91668,0.13687,0.51232,0.01521,58.91668
7.08000,59.00012,0.04831,0.51304,0.00537,59.00012
7.09000,59.08343,0.09257,0.51377,0.01029,59.08343
7.10000,59.16674,0.06316,0.51449,0.00702,59.16674
7.11000,59.25012,-0.05964,0.51522,-0.00663,59.25012
7.12000,59.33343,0.04417,0.51594,0.00491,59.33343
7.13000,59.41674,0.09154,0.51667,0.01017,59.41674
7.14000,59.49999,-0.04933,0.51739,-0.00548,59.49999
7.15000,59.58330,-0.00211,0.51812,-0.00023,59.58330
7.16000,59.66661,0.02684,0.51884,0.00298,59.66661
7.17000,59.74993,-0.04568,0.51956,-0.00508,59.74993
7.18000,59.83324,0.10949,0.52029,0.01217,59.83324
7.19000,59.91668,0.18468,0.52101,0.02052,59.91668
7.20000,60.00006,0.03915,0.52174,0.00435,60.00006
7.21000,60.08343,0.00038,0.52246,0.00004,60.08343
7.22000,60.16674,-0.00520,0.52319,-0.00058,60.16674
7.23000,60.25012,-0.12819,0.52391,-0.01424,60.25012
7.24000,60.33343,-0.09253,0.52464,-0.01028,60.33343
7.25000,60.41674,-0.03224,0.52536,-0.00358,60.41674
7.26000,60.50006,-0.13395,0.52609,-0.01488,60.50006
7.27000,60.58337,-0.03062,0.52681,-0.00340,60.58337
7.28000,60.66668,0.02370,0.52754,0.00263,60.66668
7.29000,60.75006,-0.10047,0.52826,-0.01116,60.75006
7.30000,60.83337,-0.05607,0.52899,-0.00623,60.83337
7.31000,60.91674,-0.01088,0.52971,-0.00121,60.91674
7.32000,61.00005,-0.15269,0.53044,-0.01697,61.00005
7.33000,61.08343,-0.04500,0.53116,-0.00500,61.08343
7.34000,61.16674,0.15198,0.53188,0.01689,61.16674
7.35000,61.25005,0.13078,0.53261,0.01453,61.25005
7.36000,61.33337,0.21603,0.53333,0.02400,61.33337
7.37000,61.41668,0.22984,0.53406,0.02554,61.41668
7.38000,61.49999,0.00609,0.53478,0.00068,61.49999
7.39000,61.58324,-0.01830,0.53551,-0.00203,61.58324
7.40000,61.66662,0.01998,0.53623,0.00222,61.66662
7.41000,61.75006,-0.03873,0.53696,-0.00430,61.75006
7.42000,61.83337,0.12923,0.53768,0.01436,61.83337
7.43000,61.91674,0.22142,0.53841,0.02460,61.91674
7.44000,62.00012,-0.03008,0.53913,-0.00334,62.00012
7.45000,62.08343,-0.02751,0.53986,-0.00306,62.08343
7.46000,62.16674,-0.01901,0.54058,-0.00211,62.16674
7.47000,62.25012,-0.15491,0.54131,-0.01721,62.25012
7.48000,62.33343,-0.00074,0.54203,-0.00008,62.33343
7.49000,62.41674,0.14047,0.54275,0.01561,62.41674
7.50000,62.50011,0.03636,0.54348,0.00404,62.50011
7.51000,62.58342,0.09014,0.54420,0.01002,62.58342
7.52000,62.66674,0.14515,0.54493,0.01613,62.66674
7.53000,62.75012,0.02272,0.54565,0.00252,62.75012
7.54000,62.83343,0.08625,0.54638,0.00958,62.83343
7.55000,62.91674,0.13619,0.54710,0.01513,62.91674
7.56000,63.00011,-0.04916,0.54783,-0.00546,63.00011
7.57000,63.08343,0.03330,0.54855,0.00370,63.08343
7.58000,63.16668,0.12012,0.54928,0.01335,63.16668
7.59000,63.25005,-0.05511,0.55000,-0.00612,63.25005
7.60000,63.33336,0.06022,0.55072,0.00669,63.33336
7.61000,63.41674,0.10768,0.55145,0.01196,63.41674
7.62000,63.50006,-0.07546,0.55217,-0.00838,63.50006
7.63000,63.58343,-0.06065,0.55290,-0.00674,63.58343
7.64000,63.66674,-0.06030,0.55362,-0.00670,63.66674
7.65000,63.75011,-0.21597,0.55435,-0.02400,63.75011
7.66000,63.83342,-0.17196,0.55507,-0.01911,63.83342
7.67000,63.91674,-0.09077,0.55580,-0.01009,63.91674
7.68000,64.00011,-0.08386,0.55652,-0.00932,64.00011
7.69000,64.08336,0.05245,0.55725,0.00583,64.08336
7.70000,64.16667,-0.00880,0.55797,-0.00098,64.16667
7.71000,64.24999,-0.12344,0.55870,-0.01372,64.24999
7.72000,64.33337,0.00051,0.55942,0.00006,64.33337
7.73000,64.41662,0.02718,0.56014,0.00302,64.41662
7.74000,64.49999,-0.05065,0.56087,-0.00563,64.49999
7.75000,64.58336,0.05302,0.56159,0.00589,64.58336
7.76000,64.66668,0.14758,0.56232,0.01640,64.66668
7.77000,64.75005,0.00149,0.56304,0.00017,64.75005
7.78000,64.83336,0.06747,0.56377,0.00750,64.83336
7.79000,64.91668,0.13102,0.56449,0.01456,64.91668
7.80000,64.99999,0.02147,0.56522,0.00239,64.99999
7.81000,65.08330,0.09002,0.56594,0.01000,65.08330
7.82000,65.16661,0.03249,0.56667,0.00361,65.16661
7.83000,65.25006,-0.15474,0.56739,-0.01719,65.25006
7.84000,65.33337,-0.11472,0.56812,-0.01275,65.33337
7.85000,65.41674,-0.03785,0.56884,-0.00421,65.41674
7.86000,65.50011,-0.09868,0.56957,-0.01096,65.50011
7.87000,65.58342,-0.02923,0.57029,-0.00325,65.58342
7.88000,65.66674,0.02786,0.57102,0.00310,65.66674
7.89000,65.75005,-0.13733,0.57174,-0.01526,65.75005
7.90000,65.83336,-0.05923,0.57246,-0.00658,65.83336
7.91000,65.91661,-0.02332,0.57319,-0.00259,65.91661
7.92000,65.99999,-0.16133,0.57391,-0.01793,65.99999
7.93000,66.08331,-0.08034,0.57464,-0.00893,66.08331
7.94000,66.16668,0.04307,0.57536,0.00479,66.16668
7.94600,66.21681,-0.08957,0.57580,-0.00995,66.21681