File: FR/FR/RDSO FR Tensile 500.is_tens_RawData/Specimen_RawData_3.csv
Time,Extension,Load,Tensile strain,Tensile stress,Corrected Position
(sec),(mm),(N),(mm/mm),(MPa),(mm)
0.00000,0.00000,-0.01453,0.00000,-0.00161,0.00000
0.02000,0.01994,0.23570,0.00017,0.02619,0.01994
0.04000,0.09775,0.83676,0.00085,0.09297,0.09775
0.06000,0.23406,1.65459,0.00204,0.18384,0.23406
0.08000,0.41781,2.26746,0.00363,0.25194,0.41781
0.10000,0.62137,2.64707,0.00540,0.29412,0.62137
0.12000,0.83475,3.05458,0.00726,0.33940,0.83475
0.14000,1.05462,3.69595,0.00917,0.41066,1.05462
0.16000,1.27394,4.23691,0.01108,0.47077,1.27394
0.18000,1.47350,4.44971,0.01281,0.49441,1.47350
0.20000,1.65200,4.85193,0.01437,0.53910,1.65200
0.22000,1.81944,5.51038,0.01582,0.61226,1.81944
0.24000,1.98481,6.09138,0.01726,0.67682,1.98481
0.26000,2.15225,6.56778,0.01872,0.72975,2.15225
0.28000,2.32169,6.88119,0.02019,0.76458,2.32169
0.30000,2.49150,7.15322,0.02167,0.79480,2.49150
0.32000,2.66075,7.40785,0.02314,0.82309,2.66075
0.34000,2.82919,7.71566,0.02460,0.85730,2.82919
0.36000,2.99687,8.10061,0.02606,0.90007,2.99687
0.38000,3.16419,8.44806,0.02751,0.93867,3.16419
0.40000,3.33131,8.53031,0.02897,0.94781,3.33131
0.42000,3.49831,8.65768,0.03042,0.96196,3.49831
0.44000,3.66531,9.01352,0.03187,1.00150,3.66531
0.46000,3.83237,9.43258,0.03332,1.04806,3.83237
0.48000,3.99937,9.66770,0.03478,1.07419,3.99937
0.50000,4.16619,9.74027,0.03623,1.08225,4.16619
0.52000,4.33294,9.92608,0.03768,1.10290,4.33294
0.54000,4.49962,10.06882,0.03913,1.11876,4.49962
0.56000,4.66637,10.32360,0.04058,1.14707,4.66637
0.58000,4.83319,10.44620,0.04203,1.16069,4.83319
0.60000,4.99987,10.73777,0.04348,1.19309,4.99987
0.62000,5.16650,11.14929,0.04493,1.23881,5.16650
0.64000,5.33319,11.23352,0.04638,1.24817,5.33319
0.66000,5.49994,11.41561,0.04783,1.26840,5.49994
0.68000,5.66662,11.58445,0.04927,1.28716,5.66662
0.70000,5.83331,11.61244,0.05072,1.29027,5.83331
0.72000,6.00000,11.91258,0.05217,1.32362,6.00000
0.74000,6.16656,12.15673,0.05362,1.35075,6.16656
0.76000,6.33331,12.20319,0.05507,1.35591,6.33331
0.78000,6.50000,12.30373,0.05652,1.36708,6.50000
0.80000,6.66669,12.45895,0.05797,1.38433,6.66669
0.82000,6.83331,12.65265,0.05942,1.40585,6.83331
0.84000,7.00000,12.89761,0.06087,1.43307,7.00000
0.86000,7.16656,13.07931,0.06232,1.45326,7.16656
0.88000,7.33331,13.13067,0.06377,1.45896,7.33331
0.90000,7.50000,13.27076,0.06522,1.47453,7.50000
0.92000,7.66662,13.29907,0.06667,1.47767,7.66662
0.94000,7.83331,13.43608,0.06812,1.49290,7.83331
0.96000,7.99994,13.54092,0.06956,1.50455,7.99994
0.98000,8.16662,13.62005,0.07101,1.51334,8.16662
1.00000,8.33337,13.67266,0.07246,1.51918,8.33337
1.02000,8.50006,13.83315,0.07391,1.53702,8.50006
1.04000,8.66669,13.93976,0.07536,1.54886,8.66669
1.06000,8.83331,14.03929,0.07681,1.55992,8.83331
1.08000,9.00000,14.20968,0.07826,1.57885,9.00000
1.10000,9.16669,14.24791,0.07971,1.58310,9.16669
1.12000,9.33344,14.27331,0.08116,1.58592,9.33344
1.14000,9.50006,14.54930,0.08261,1.61659,9.50006
1.16000,9.66669,14.65380,0.08406,1.62820,9.66669
1.18000,9.83331,14.59779,0.08551,1.62198,9.83331
1.20000,10.00000,14.71895,0.08696,1.63544,10.00000
1.22000,10.16669,14.89496,0.08841,1.65500,10.16669
1.24000,10.33337,14.84571,0.08986,1.64952,10.33337
1.26000,10.50000,14.77398,0.09130,1.64155,10.50000
1.28000,10.66662,14.78032,0.09275,1.64226,10.66662
1.30000,10.83325,15.02119,0.09420,1.66902,10.83325
1.32000,11.00000,15.12971,0.09565,1.68108,11.00000
1.34000,11.16669,15.28440,0.09710,1.69827,11.16669
1.36000,11.33337,15.25425,0.09855,1.69492,11.33337
1.38000,11.49994,15.31489,0.10000,1.70165,11.49994
1.40000,11.66656,15.43987,0.10145,1.71554,11.66656
1.42000,11.83331,15.67873,0.10290,1.74208,11.83331
1.44000,12.00000,15.67288,0.10435,1.74143,12.00000
1.46000,12.16669,15.60011,0.10580,1.73335,12.16669
1.48000,12.33331,15.52669,0.10725,1.72519,12.33331
1.50000,12.49994,15.64726,0.10870,1.73858,12.49994
1.52000,12.66662,15.90870,0.11014,1.76763,12.66662
1.54000,12.83337,15.83983,0.11159,1.75998,12.83337
1.56000,13.00006,15.91769,0.11304,1.76863,13.00006
1.58000,13.16662,16.02330,0.11449,1.78037,13.16662
1.60000,13.33331,15.97789,0.11594,1.77532,13.33331
1.62000,13.50000,16.16052,0.11739,1.79561,13.50000
1.64000,13.66668,16.28927,0.11884,1.80992,13.66668
1.66000,13.83337,16.22197,0.12029,1.80244,13.83337
1.68000,14.00006,16.33076,0.12174,1.81453,14.00006
1.70000,14.16669,16.37002,0.12319,1.81889,14.16669
1.72000,14.33331,16.31011,0.12464,1.81223,14.33331
1.74000,14.50006,16.29334,0.12609,1.81037,14.50006
1.76000,14.66669,16.38986,0.12754,1.82110,14.66669
1.78000,14.83331,16.33933,0.12899,1.81548,14.83331
1.80000,15.00000,16.42740,0.13043,1.82527,15.00000
1.82000,15.16662,16.68919,0.13188,1.85435,15.16662
1.84000,15.33337,16.69717,0.13333,1.85524,15.33337
1.86000,15.50006,16.85257,0.13478,1.87251,15.50006
1.88000,15.66668,16.87867,0.13623,1.87541,15.66668
1.90000,15.83337,16.66582,0.13768,1.85176,15.83337
1.92000,16.00000,16.78414,0.13913,1.86490,16.00000
1.94000,16.16656,16.89934,0.14058,1.87770,16.16656
1.96000,16.33331,16.77246,0.14203,1.86361,16.33331
1.98000,16.50006,16.88463,0.14348,1.87607,16.50006
2.00000,16.66675,16.93990,0.14493,1.88221,16.66675
2.02000,16.83337,16.84539,0.14638,1.87171,16.83337
2.04000,17.00000,17.02545,0.14783,1.89172,17.00000
2.06000,17.16662,16.91850,0.14927,1.87983,17.16662
2.08000,17.33331,16.86413,0.15072,1.87379,17.33331
2.10000,17.50000,16.99623,0.15217,1.88847,17.50000
2.12000,17.66662,17.09018,0.15362,1.89891,17.66662
2.14000,17.83325,17.00759,0.15507,1.88973,17.83325
2.16000,17.99993,17.12366,0.15652,1.90263,17.99993
2.18000,18.16662,17.15126,0.15797,1.90570,18.16662
2.20000,18.33337,17.12868,0.15942,1.90319,18.33337
2.22000,18.50006,17.23649,0.16087,1.91517,18.50006
2.24000,18.66662,17.32804,0.16232,1.92534,18.66662
2.26000,18.83337,17.19556,0.16377,1.91062,18.83337
2.28000,19.00006,17.15523,0.16522,1.90614,19.00006
2.30000,19.16675,17.20715,0.16667,1.91191,19.16675
2.32000,19.33337,17.18077,0.16812,1.90897,19.33337
2.34000,19.50000,17.27680,0.16957,1.91964,19.50000
2.36000,19.66662,17.41831,0.17101,1.93537,19.66662
2.38000,19.83337,17.33181,0.17246,1.92576,19.83337
2.40000,20.00006,17.51001,0.17391,1.94556,20.00006
2.42000,20.16668,17.50670,0.17536,1.94519,20.16668
2.44000,20.33337,17.39999,0.17681,1.93333,20.33337
2.46000,20.50000,17.44199,0.17826,1.93800,20.50000
2.48000,20.66662,17.49032,0.17971,1.94337,20.66662
2.50000,20.83337,17.47276,0.18116,1.94142,20.83337
2.52000,21.00006,17.69572,0.18261,1.96619,21.00006
2.54000,21.16662,17.91950,0.18406,1.99106,21.16662
2.56000,21.33331,17.80312,0.18551,1.97812,21.33331
2.58000,21.49994,17.76844,0.18696,1.97427,21.49994
2.60000,21.66662,17.76109,0.18841,1.97345,21.66662
2.62000,21.83337,17.80196,0.18986,1.97800,21.83337
2.64000,22.00000,17.75607,0.19130,1.97290,22.00000
2.66000,22.16662,17.81113,0.19275,1.97901,22.16662
2.68000,22.33331,17.65632,0.19420,1.96181,22.33331
2.70000,22.49993,17.66153,0.19565,1.96239,22.49993
2.72000,22.66662,17.75935,0.19710,1.97326,22.66662
2.74000,22.83331,17.76231,0.19855,1.97359,22.83331
2.76000,23.00000,17.91805,0.20000,1.99089,23.00000
2.78000,23.16662,17.94269,0.20145,1.99363,23.16662
2.80000,23.33331,17.77921,0.20290,1.97547,23.33331
2.82000,23.50006,17.83116,0.20435,1.98124,23.50006
2.84000,23.66675,18.04019,0.20580,2.00447,23.66675
2.86000,23.83337,17.97847,0.20725,1.99761,23.83337
2.88000,24.00006,18.11158,0.20870,2.01240,24.00006
2.90000,24.16668,18.11893,0.21015,2.01321,24.16668
2.92000,24.33337,17.86084,0.21159,1.98454,24.33337
2.94000,24.50006,17.84492,0.21304,1.98277,24.50006
2.96000,24.66668,18.00666,0.21449,2.00074,24.66668
2.98000,24.83331,17.88744,0.21594,1.98749,24.83331
3.00000,24.99999,18.11721,0.21739,2.01302,24.99999
3.02000,25.16662,18.27700,0.21884,2.03078,25.16662
3.04000,25.33343,18.15873,0.22029,2.01764,25.33343
3.06000,25.50012,18.26176,0.22174,2.02908,25.50012
3.08000,25.66668,18.37966,0.22319,2.04218,25.66668
3.10000,25.83325,18.17883,0.22464,2.01987,25.83325
3.12000,25.99987,18.24352,0.22609,2.02706,25.99987
3.14000,26.16662,18.31956,0.22754,2.03551,26.16662
3.16000,26.33337,18.19265,0.22899,2.02141,26.33337
3.18000,26.50006,18.16674,0.23044,2.01853,26.50006
3.20000,26.66662,18.15731,0.23188,2.01748,26.66662
3.22000,26.83331,18.20955,0.23333,2.02328,26.83331
3.24000,27.00000,18.38272,0.23478,2.04252,27.00000
3.26000,27.16668,18.44552,0.23623,2.04950,27.16668
3.28000,27.33331,18.38601,0.23768,2.04289,27.33331
3.30000,27.49993,18.47618,0.23913,2.05291,27.49993
3.32000,27.66656,18.39272,0.24058,2.04364,27.66656
3.34000,27.83331,18.20759,0.24203,2.02307,27.83331
3.36000,28.00006,18.40197,0.24348,2.04466,28.00006
3.38000,28.16675,18.39673,0.24493,2.04408,28.16675
3.40000,28.33337,18.20362,0.24638,2.02262,28.33337
3.42000,28.50000,18.27251,0.24783,2.03028,28.50000
3.44000,28.66662,18.52355,0.24927,2.05817,28.66662
3.46000,28.83337,18.48490,0.25072,2.05388,28.83337
3.48000,29.00006,18.60728,0.25217,2.06748,29.00006
3.50000,29.16669,18.60863,0.25362,2.06763,29.16669
3.52000,29.33337,18.66011,0.25507,2.07335,29.33337
3.54000,29.50000,18.71563,0.25652,2.07951,29.50000
3.56000,29.66662,18.60792,0.25797,2.06755,29.66662
3.58000,29.83337,18.55879,0.25942,2.06209,29.83337
3.60000,30.00006,18.59638,0.26087,2.06626,30.00006
3.62000,30.16668,18.59898,0.26232,2.06655,30.16668
3.64000,30.33337,18.44280,0.26377,2.04920,30.33337
3.66000,30.49999,18.61728,0.26522,2.06859,30.49999
3.68000,30.66662,18.64698,0.26667,2.07189,30.66662
3.70000,30.83337,18.65972,0.26812,2.07330,30.83337
3.72000,31.00000,18.84450,0.26957,2.09383,31.00000
3.74000,31.16662,18.83275,0.27101,2.09253,31.16662
3.76000,31.33331,18.60329,0.27246,2.06703,31.33331
3.78000,31.49999,18.84333,0.27391,2.09370,31.49999
3.80000,31.66668,18.90985,0.27536,2.10109,31.66668
3.82000,31.83337,18.81656,0.27681,2.09073,31.83337
3.84000,31.99999,18.76366,0.27826,2.08485,31.99999
3.86000,32.16656,18.77578,0.27971,2.08620,32.16656
3.88000,32.33331,18.62710,0.28116,2.06968,32.33331
3.90000,32.50000,18.69094,0.28261,2.07677,32.50000
3.92000,32.66668,18.86890,0.28406,2.09654,32.66668
3.94000,32.83331,18.85366,0.28551,2.09485,32.83331
3.96000,32.99993,18.91663,0.28696,2.10185,32.99993
3.98000,33.16662,18.90243,0.28841,2.10027,33.16662
4.00000,33.33337,18.80769,0.28986,2.08974,33.33337
4.02000,33.50006,18.74108,0.29130,2.08234,33.50006
4.04000,33.66675,18.91435,0.29275,2.10159,33.66675
4.06000,33.83331,18.89616,0.29420,2.09957,33.83331
4.08000,34.00006,19.00157,0.29565,2.11129,34.00006
4.10000,34.16668,19.04139,0.29710,2.11571,34.16668
4.12000,34.33337,18.90409,0.29855,2.10045,34.33337
4.14000,34.50006,19.13977,0.30000,2.12664,34.50006
4.16000,34.66668,19.09843,0.30145,2.12205,34.66668
4.18000,34.83331,18.92623,0.30290,2.10291,34.83331
4.20000,34.99999,19.12826,0.30435,2.12536,34.99999
4.22000,35.16675,19.26788,0.30580,2.14088,35.16675
4.24000,35.33343,19.32938,0.30725,2.14771,35.33343
4.26000,35.49999,19.47447,0.30870,2.16383,35.49999
4.28000,35.66662,19.41985,0.31014,2.15776,35.66662
4.30000,35.83331,19.21946,0.31159,2.13550,35.83331
4.32000,35.99999,19.14379,0.31304,2.12709,35.99999
4.34000,36.16662,19.12958,0.31449,2.12551,36.16662
4.36000,36.33331,18.92910,0.31594,2.10323,36.33331
4.38000,36.50000,19.11146,0.31739,2.12350,36.50000
4.40000,36.66662,19.30660,0.31884,2.14518,36.66662
4.42000,36.83337,19.16705,0.32029,2.12967,36.83337
4.44000,36.99999,19.30339,0.32174,2.14482,36.99999
4.46000,37.16662,19.36879,0.32319,2.15209,37.16662
4.48000,37.33324,19.18496,0.32464,2.13166,37.33324
4.50000,37.49993,19.40993,0.32609,2.15666,37.49993
4.52000,37.66656,19.43952,0.32754,2.15995,37.66656
4.54000,37.83337,19.32039,0.32899,2.14671,37.83337
4.56000,38.00006,19.39524,0.33044,2.15503,38.00006
4.58000,38.16668,19.47518,0.33188,2.16391,38.16668
4.60000,38.33331,19.43984,0.33333,2.15998,38.33331
4.62000,38.50000,19.47309,0.33478,2.16368,38.50000
4.64000,38.66668,19.59895,0.33623,2.17766,38.66668
4.66000,38.83337,19.60356,0.33768,2.17817,38.83337
4.68000,39.00006,19.68533,0.33913,2.18726,39.00006
4.70000,39.16662,19.67505,0.34058,2.18612,39.16662
4.72000,39.33331,19.43396,0.34203,2.15933,39.33331
4.74000,39.49999,19.51140,0.34348,2.16793,39.49999
4.76000,39.66668,19.67674,0.34493,2.18630,39.66668
4.78000,39.83337,19.58406,0.34638,2.17601,39.83337
4.80000,39.99999,19.63091,0.34783,2.18121,39.99999
4.82000,40.16662,19.75139,0.34927,2.19460,40.16662
4.84000,40.33331,19.57030,0.35072,2.17448,40.33331
4.86000,40.50006,19.69966,0.35217,2.18885,40.50006
4.88000,40.66668,19.72680,0.35362,2.19187,40.66668
4.90000,40.83330,19.59219,0.35507,2.17691,40.83330
4.92000,40.99999,19.73439,0.35652,2.19271,40.99999
4.94000,41.16655,19.84511,0.35797,2.20501,41.16655
4.96000,41.33331,19.80172,0.35942,2.20019,41.33331
4.98000,41.50006,19.88525,0.36087,2.20947,41.50006
5.00000,41.66668,19.74328,0.36232,2.19370,41.66668
5.02000,41.83325,19.66559,0.36377,2.18507,41.83325
5.04000,41.99993,19.85454,0.36522,2.20606,41.99993
5.06000,42.16662,19.89133,0.36667,2.21015,42.16662
5.08000,42.33337,19.78031,0.36812,2.19781,42.33337
5.10000,42.50005,19.96061,0.36957,2.21785,42.50005
5.12000,42.66662,20.05304,0.37101,2.22812,42.66662
5.14000,42.83324,20.01503,0.37246,2.22389,42.83324
5.16000,42.99993,20.12272,0.37391,2.23586,42.99993
5.18000,43.16668,20.01293,0.37536,2.22366,43.16668
5.20000,43.33337,19.92167,0.37681,2.21352,43.33337
5.22000,43.50006,20.01663,0.37826,2.22407,43.50006
5.24000,43.66668,20.09583,0.37971,2.23287,43.66668
5.26000,43.83337,20.11873,0.38116,2.23541,43.83337
5.28000,44.00006,20.11028,0.38261,2.23448,44.00006
5.30000,44.16674,20.20349,0.38406,2.24483,44.16674
5.32000,44.33337,20.18258,0.38551,2.24251,44.33337
5.34000,44.49999,20.15025,0.38696,2.23892,44.49999
5.36000,44.66662,20.18623,0.38841,2.24291,44.66662
5.38000,44.83331,20.17741,0.38985,2.24193,44.83331
5.40000,45.00006,20.31667,0.39130,2.25741,45.00006
5.42000,45.16675,20.41926,0.39275,2.26881,45.16675
5.44000,45.33337,20.18691,0.39420,2.24299,45.33337
5.46000,45.49999,20.37275,0.39565,2.26364,45.49999
5.48000,45.66662,20.43560,0.39710,2.27062,45.66662
5.50000,45.83331,20.30726,0.39855,2.25636,45.83331
5.52000,45.99999,20.18069,0.40000,2.24230,45.99999
5.54000,46.16668,20.27995,0.40145,2.25333,46.16668
5.56000,46.33330,20.44826,0.40290,2.27203,46.33330
5.58000,46.49993,20.55590,0.40435,2.28399,46.49993
5.60000,46.66662,20.48468,0.40580,2.27608,46.66662
5.62000,46.83343,20.40491,0.40725,2.26721,46.83343
5.64000,47.00006,20.52070,0.40870,2.28008,47.00006
5.66000,47.16662,20.48379,0.41014,2.27598,47.16662
5.68000,47.33324,20.57725,0.41159,2.28636,47.33324
5.70000,47.49993,20.69714,0.41304,2.29968,47.49993
5.72000,47.66662,20.60312,0.41449,2.28924,47.66662
5.74000,47.83337,20.46841,0.41594,2.27427,47.83337
5.76000,47.99999,20.74480,0.41739,2.30498,47.99999
5.78000,48.16662,20.82307,0.41884,2.31367,48.16662
5.80000,48.33330,20.63613,0.42029,2.29290,48.33330
5.82000,48.50006,20.61176,0.42174,2.29020,48.50006
5.84000,48.66675,20.67429,0.42319,2.29714,48.66675
5.86000,48.83343,20.57152,0.42464,2.28572,48.83343
5.88000,49.00006,20.69429,0.42609,2.29937,49.00006
5.90000,49.16662,20.81785,0.42754,2.31309,49.16662
5.92000,49.33337,20.67972,0.42899,2.29775,49.33337
5.94000,49.50006,20.81942,0.43044,2.31327,49.50006
5.96000,49.66668,20.86894,0.43188,2.31877,49.66668
5.98000,49.83330,20.79995,0.43333,2.31111,49.83330
6.00000,49.99993,20.79885,0.43478,2.31098,49.99993
6.02000,50.16662,20.92145,0.43623,2.32461,50.16662
6.04000,50.33337,20.89946,0.43768,2.32216,50.33337
6.06000,50.50005,20.95794,0.43913,2.32866,50.50005
6.08000,50.66662,21.13205,0.44058,2.34801,50.66662
6.10000,50.83330,21.05485,0.44203,2.33943,50.83330
6.12000,50.99999,21.08517,0.44348,2.34280,50.99999
6.14000,51.16662,21.09463,0.44493,2.34385,51.16662
6.16000,51.33331,20.99840,0.44638,2.33316,51.33331
6.18000,51.49999,21.00957,0.44783,2.33440,51.49999
6.20000,51.66662,21.07486,0.44927,2.34165,51.66662
6.22000,51.83330,21.14897,0.45072,2.34989,51.83330
6.24000,51.99999,21.20339,0.45217,2.35593,51.99999
6.26000,52.16668,21.27674,0.45362,2.36408,52.16668
6.28000,52.33337,21.03413,0.45507,2.33713,52.33337
6.30000,52.49999,21.22957,0.45652,2.35884,52.49999
6.32000,52.66655,21.37961,0.45797,2.37551,52.66655
6.34000,52.83324,21.24828,0.45942,2.36092,52.83324
6.36000,52.99993,21.45181,0.46087,2.38353,52.99993
6.38000,53.16668,21.43221,0.46232,2.38136,53.16668
6.40000,53.33337,21.31933,0.46377,2.36881,53.33337
6.42000,53.50005,21.37899,0.46522,2.37544,53.50005
6.44000,53.66668,21.20232,0.46667,2.35581,53.66668
6.46000,53.83343,21.08995,0.46812,2.34333,53.83343
6.48000,54.00012,21.24008,0.46957,2.36001,54.00012
6.50000,54.16675,21.54490,0.47102,2.39388,54.16675
6.52000,54.33330,21.49861,0.47246,2.38873,54.33330
6.54000,54.49993,21.39107,0.47391,2.37679,54.49993
6.56000,54.66662,21.56990,0.47536,2.39666,54.66662
6.58000,54.83337,21.62114,0.47681,2.40235,54.83337
6.60000,55.00006,21.60103,0.47826,2.40011,55.00006
6.62000,55.16668,21.68315,0.47971,2.40924,55.16668
6.64000,55.33330,21.64191,0.48116,2.40466,55.33330
6.66000,55.49999,21.72763,0.48261,2.41418,55.49999
6.68000,55.66668,21.84077,0.48406,2.42675,55.66668
6.70000,55.83337,21.71570,0.48551,2.41286,55.83337
6.72000,55.99999,21.83541,0.48696,2.42616,55.99999
6.74000,56.16656,21.74401,0.48840,2.41600,56.16656
6.76000,56.33330,21.58932,0.48985,2.39881,56.33330
6.78000,56.49999,21.71695,0.49130,2.41299,56.49999
6.80000,56.66668,21.81856,0.49275,2.42428,56.66668
6.82000,56.83336,21.73953,0.49420,2.41550,56.83336
6.84000,56.99999,21.97207,0.49565,2.44134,56.99999
6.86000,57.16662,22.09240,0.49710,2.45471,57.16662
6.88000,57.33330,21.93301,0.49855,2.43700,57.33330
6.90000,57.49999,21.91376,0.50000,2.43486,57.49999
6.92000,57.66662,21.84895,0.50145,2.42766,57.66662
6.94000,57.83331,21.83605,0.50290,2.42623,57.83331
6.96000,57.99993,21.97023,0.50435,2.44114,57.99993
6.98000,58.16662,22.10222,0.50580,2.45580,58.16662
7.00000,58.33337,22.12196,0.50725,2.45800,58.33337
7.02000,58.50011,22.26805,0.50870,2.47423,58.50011
7.04000,58.66668,22.24307,0.51015,2.47145,58.66668
7.06000,58.83337,22.07927,0.51159,2.45325,58.83337
7.08000,58.99999,22.18382,0.51304,2.46487,58.99999
7.10000,59.16668,22.24657,0.51449,2.47184,59.16668
7.12000,59.33343,22.38943,0.51594,2.48771,59.33343
7.14000,59.50006,22.53309,0.51739,2.50368,59.50006
7.16000,59.66661,22.33163,0.51884,2.48129,59.66661
7.18000,59.83324,22.14231,0.52029,2.46026,59.83324
7.20000,59.99999,22.41027,0.52174,2.49003,59.99999
7.22000,60.16674,22.56797,0.52319,2.50755,60.16674
7.24000,60.33343,22.59493,0.52464,2.51055,60.33343
7.26000,60.50006,22.60553,0.52609,2.51173,60.50006
7.28000,60.66662,22.50485,0.52754,2.50054,60.66662
7.30000,60.83325,22.42979,0.52898,2.49220,60.83325
7.32000,60.99993,22.51893,0.53043,2.50210,60.99993
7.34000,61.16662,22.64284,0.53188,2.51587,61.16662
7.36000,61.33331,22.62574,0.53333,2.51397,61.33331
7.38000,61.49993,22.68129,0.53478,2.52014,61.49993
7.40000,61.66662,22.66392,0.53623,2.51821,61.66662
7.42000,61.83337,22.65653,0.53768,2.51739,61.83337
7.44000,62.00006,22.75180,0.53913,2.52798,62.00006
7.46000,62.16674,22.73713,0.54058,2.52635,62.16674
7.48000,62.33331,22.67122,0.54203,2.51902,62.33331
7.50000,62.49987,22.67107,0.54348,2.51901,62.49987
7.52000,62.66662,22.71391,0.54493,2.52377,62.66662
7.54000,62.83336,22.68902,0.54638,2.52100,62.83336
7.56000,63.00006,22.79635,0.54783,2.53293,63.00006
7.58000,63.16668,22.90820,0.54928,2.54536,63.16668
7.60000,63.33336,23.06533,0.55072,2.56281,63.33336
7.62000,63.50006,23.25967,0.55217,2.58441,63.50006
7.64000,63.66674,23.25871,0.55362,2.58430,63.66674
7.66000,63.83349,22.96156,0.55507,2.55128,63.83349
7.68000,64.00005,22.98150,0.55652,2.55350,64.00005
7.70000,64.16661,23.09756,0.55797,2.56640,64.16661
7.72000,64.33330,23.02605,0.55942,2.55845,64.33330
7.74000,64.49999,23.08255,0.56087,2.56473,64.49999
7.76000,64.66668,23.23623,0.56232,2.58180,64.66668
7.78000,64.83336,23.02957,0.56377,2.55884,64.83336
7.80000,64.99999,23.01890,0.56522,2.55766,64.99999
7.82000,65.16661,23.08211,0.56667,2.56468,65.16661
7.84000,65.33330,23.11103,0.56812,2.56789,65.33330
7.86000,65.49999,23.20897,0.56957,2.57877,65.49999
7.88000,65.66667,23.24630,0.57101,2.58292,65.66667
7.90000,65.83330,23.33584,0.57246,2.59287,65.83330
7.92000,65.99993,23.43721,0.57391,2.60413,65.99993
7.94000,66.16655,23.38577,0.57536,2.59842,66.16655
7.96000,66.33330,23.18651,0.57681,2.57628,66.33330
7.98000,66.50005,23.31326,0.57826,2.59036,66.50005
8.00000,66.66668,23.59446,0.57971,2.62161,66.66668
8.02000,66.83331,23.44431,0.58116,2.60492,66.83331
8.04000,66.99999,23.46858,0.58261,2.60762,66.99999
8.06000,67.16661,23.58222,0.58406,2.62025,67.16661
8.08000,67.33330,23.62197,0.58551,2.62466,67.33330
8.10000,67.49999,23.82034,0.58696,2.64670,67.49999
8.12000,67.66662,23.89423,0.58841,2.65491,67.66662
8.14000,67.83330,23.76416,0.58985,2.64046,67.83330
8.16000,67.99993,23.61983,0.59130,2.62443,67.99993
8.18000,68.16661,23.63617,0.59275,2.62624,68.16661
8.20000,68.33337,23.74621,0.59420,2.63847,68.33337
8.22000,68.50005,23.90587,0.59565,2.65621,68.50005
8.24000,68.66661,23.88608,0.59710,2.65401,68.66661
8.26000,68.83330,23.77384,0.59855,2.64154,68.83330
8.28000,69.00005,24.01745,0.60000,2.66861,69.00005
8.30000,69.16674,23.96357,0.60145,2.66262,69.16674
8.32000,69.33343,23.84082,0.60290,2.64898,69.33343
8.34000,69.49999,24.06653,0.60435,2.67406,69.49999
8.36000,69.66662,24.25009,0.60580,2.69445,69.66662
8.38000,69.83330,23.98157,0.60725,2.66462,69.83330
8.40000,69.99999,24.01693,0.60870,2.66855,69.99999
8.42000,70.16668,24.16347,0.61015,2.68483,70.16668
8.44000,70.33336,23.99337,0.61159,2.66593,70.33336
8.46000,70.49999,24.17652,0.61304,2.68628,70.49999
8.48000,70.66668,24.29212,0.61449,2.69912,70.66668
8.50000,70.83336,24.30059,0.61594,2.70007,70.83336
8.52000,70.99999,24.34899,0.61739,2.70544,70.99999
8.54000,71.16661,24.33387,0.61884,2.70376,71.16661
8.56000,71.33324,24.24487,0.62029,2.69387,71.33324
8.58000,71.49993,24.20806,0.62174,2.68979,71.49993
8.60000,71.66667,24.23645,0.62319,2.69294,71.66667
8.62000,71.83337,24.31455,0.62464,2.70162,71.83337
8.64000,72.00005,24.34708,0.62609,2.70523,72.00005
8.66000,72.16662,24.41163,0.62754,2.71240,72.16662
8.68000,72.33330,24.44600,0.62899,2.71622,72.33330
8.70000,72.49999,24.67839,0.63043,2.74204,72.49999
8.72000,72.66662,24.81219,0.63188,2.75691,72.66662
8.74000,72.83330,24.66438,0.63333,2.74049,72.83330
8.76000,72.99999,24.64844,0.63478,2.73872,72.99999
8.78000,73.16655,24.65419,0.63623,2.73935,73.16655
8.80000,73.33330,24.67680,0.63768,2.74187,73.33330
8.82000,73.50005,24.81322,0.63913,2.75702,73.50005
8.84000,73.66668,24.93599,0.64058,2.77067,73.66668
8.86000,73.83343,25.04419,0.64203,2.78269,73.83343
8.88000,74.00006,25.09668,0.64348,2.78852,74.00006
8.90000,74.16668,25.18173,0.64493,2.79797,74.16668
8.92000,74.33336,25.19995,0.64638,2.79999,74.33336
8.94000,74.50006,25.17042,0.64783,2.79671,74.50006
8.96000,74.66668,25.07214,0.64928,2.78579,74.66668
8.98000,74.83337,24.94762,0.65072,2.77196,74.83337
9.00000,74.99999,25.02303,0.65217,2.78034,74.99999
9.02000,75.16661,25.06445,0.65362,2.78494,75.16661
9.04000,75.33337,24.89969,0.65507,2.76663,75.33337
9.06000,75.50005,25.04306,0.65652,2.78256,75.50005
9.08000,75.66662,25.17277,0.65797,2.79697,75.66662
9.10000,75.83330,25.01181,0.65942,2.77909,75.83330
9.12000,75.99999,25.23539,0.66087,2.80393,75.99999
9.14000,76.16668,25.28352,0.66232,2.80928,76.16668
9.16000,76.33343,25.36706,0.66377,2.81856,76.33343
9.18000,76.50005,25.44381,0.66522,2.82709,76.50005
9.20000,76.66655,25.51253,0.66667,2.83473,76.66655
9.22000,76.83324,25.43651,0.66812,2.82628,76.83324
9.24000,76.99999,25.38347,0.66957,2.82039,76.99999
9.26000,77.16668,25.34237,0.67101,2.81582,77.16668
9.28000,77.33336,25.40519,0.67246,2.82280,77.33336
9.30000,77.49998,25.53683,0.67391,2.83743,77.49998
9.32000,77.66661,25.50445,0.67536,2.83383,77.66661
9.34000,77.83331,25.43399,0.67681,2.82600,77.83331
9.36000,77.99999,25.65179,0.67826,2.85020,77.99999
9.38000,78.16668,25.85323,0.67971,2.87258,78.16668
9.40000,78.33330,25.74275,0.68116,2.86031,78.33330
9.42000,78.49999,25.78919,0.68261,2.86547,78.49999
9.44000,78.66661,25.68128,0.68406,2.85348,78.66661
9.46000,78.83336,25.77055,0.68551,2.86339,78.83336
9.48000,79.00012,25.79119,0.68696,2.86569,79.00012
9.50000,79.16674,25.67359,0.68841,2.85262,79.16674
9.52000,79.33336,25.68995,0.68986,2.85444,79.33336
9.54000,79.49992,25.90875,0.69130,2.87875,79.49992
9.56000,79.66661,25.99917,0.69275,2.88880,79.66661
9.58000,79.83336,25.86746,0.69420,2.87416,79.83336
9.60000,79.99999,26.00659,0.69565,2.88962,79.99999
9.62000,80.16667,26.10191,0.69710,2.90021,80.16667
9.64000,80.33330,26.17152,0.69855,2.90795,80.33330
9.66000,80.49999,26.26870,0.70000,2.91874,80.49999
9.68000,80.66667,26.21305,0.70145,2.91256,80.66667
9.70000,80.83336,26.25873,0.70290,2.91764,80.83336
9.72000,80.99998,26.37516,0.70435,2.93057,80.99998
9.74000,81.16661,26.19591,0.70580,2.91066,81.16661
9.76000,81.33323,26.24712,0.70725,2.91635,81.33323
9.78000,81.49993,26.55375,0.70869,2.95042,81.49993
9.80000,81.66668,26.74987,0.71015,2.97221,81.66668
9.82000,81.83330,26.46619,0.71159,2.94069,81.83330
9.84000,81.99993,26.48679,0.71304,2.94298,81.99993
9.86000,82.16655,26.54557,0.71449,2.94951,82.16655
9.88000,82.33330,26.48327,0.71594,2.94259,82.33330
9.90000,82.49999,26.69156,0.71739,2.96573,82.49999
9.92000,82.66667,26.63570,0.71884,2.95952,82.66667
9.94000,82.83329,26.41092,0.72029,2.93455,82.83329
9.96000,82.99992,26.62264,0.72174,2.95807,82.99992
9.98000,83.16656,26.70797,0.72319,2.96755,83.16656
10.00000,83.33337,26.51484,0.72464,2.94609,83.33337
10.02000,83.50004,26.68167,0.72609,2.96463,83.50004
10.04000,83.66674,26.72125,0.72754,2.96903,83.66674
10.06000,83.83336,26.61074,0.72899,2.95675,83.83336
10.08000,83.99999,26.81767,0.73043,2.97974,83.99999
10.10000,84.16668,26.85778,0.73188,2.98420,84.16668
10.12000,84.33343,26.79384,0.73333,2.97709,84.33343
10.14000,84.50005,26.96628,0.73478,2.99625,84.50005
10.16000,84.66662,26.93317,0.73623,2.99257,84.66662
10.18000,84.83330,26.78923,0.73768,2.97658,84.83330
10.20000,84.99999,26.93682,0.73913,2.99298,84.99999
10.22000,85.16667,27.10936,0.74058,3.01215,85.16667
10.24000,85.33343,27.14240,0.74203,3.01582,85.33343
10.26000,85.50005,27.38525,0.74348,3.04281,85.50005
10.28000,85.66661,27.29142,0.74493,3.03238,85.66661
10.30000,85.83331,27.16326,0.74638,3.01814,85.83331
10.32000,86.00005,27.34139,0.74783,3.03793,86.00005
10.34000,86.16667,27.36198,0.74928,3.04022,86.16667
10.36000,86.33330,27.30595,0.75072,3.03399,86.33330
10.38000,86.49998,27.35008,0.75217,3.03890,86.49998
10.40000,86.66655,27.23776,0.75362,3.02642,86.66655
10.42000,86.83329,27.28219,0.75507,3.03135,86.83329
10.44000,87.00005,27.60543,0.75652,3.06727,87.00005
10.46000,87.16667,27.68007,0.75797,3.07556,87.16667
10.48000,87.33329,27.52899,0.75942,3.05878,87.33329
10.50000,87.49999,27.53406,0.76087,3.05934,87.49999
10.52000,87.66667,27.69940,0.76232,3.07771,87.66667
10.54000,87.83330,27.55799,0.76377,3.06200,87.83330
10.56000,87.99999,27.76469,0.76522,3.08497,87.99999
10.58000,88.16655,27.79455,0.76667,3.08828,88.16655
10.60000,88.33330,27.61853,0.76812,3.06873,88.33330
10.62000,88.49998,27.66188,0.76957,3.07354,88.49998
10.64000,88.66668,27.75460,0.77101,3.08384,88.66668
10.66000,88.83343,27.73594,0.77246,3.08177,88.83343
10.68000,89.00005,27.88663,0.77391,3.09851,89.00005
10.70000,89.16668,27.96564,0.77536,3.10729,89.16668
10.72000,89.33330,27.78220,0.77681,3.08691,89.33330
10.74000,89.49999,27.94154,0.77826,3.10462,89.49999
10.76000,89.66668,28.08251,0.77971,3.12028,89.66668
10.78000,89.83336,28.01678,0.78116,3.11298,89.83336
10.80000,89.99999,28.15461,0.78261,3.12829,89.99999
10.82000,90.16661,28.22586,0.78406,3.13621,90.16661
10.84000,90.33330,28.10960,0.78551,3.12329,90.33330
10.86000,90.50005,28.23357,0.78696,3.13706,90.50005
10.88000,90.66674,28.40239,0.78841,3.15582,90.66674
10.90000,90.83336,28.23955,0.78986,3.13773,90.83336
10.92000,90.99992,28.32468,0.79130,3.14719,90.99992
10.94000,91.16654,28.28361,0.79275,3.14262,91.16654
10.96000,91.33330,28.27584,0.79420,3.14176,91.33330
10.98000,91.50005,28.40557,0.79565,3.15617,91.50005
11.00000,91.66667,28.59504,0.79710,3.17723,91.66667
11.02000,91.83330,28.46582,0.79855,3.16287,91.83330
11.04000,91.99998,28.39855,0.80000,3.15539,91.99998
11.06000,92.16661,28.53966,0.80145,3.17107,92.16661
11.08000,92.33336,28.45296,0.80290,3.16144,92.33336
11.10000,92.49998,28.54922,0.80435,3.17214,92.49998
11.12000,92.66655,28.51201,0.80580,3.16800,92.66655
11.14000,92.83324,28.53538,0.80725,3.17060,92.83324
11.16000,92.99998,28.65955,0.80870,3.18439,92.99998
11.18000,93.16668,28.70995,0.81015,3.18999,93.16668
11.20000,93.33342,28.66920,0.81159,3.18547,93.33342
11.22000,93.50005,28.76011,0.81304,3.19557,93.50005
11.24000,93.66661,29.02652,0.81449,3.22517,93.66661
11.26000,93.83336,28.88668,0.81594,3.20963,93.83336
11.28000,94.00005,28.96909,0.81739,3.21879,94.00005
11.30000,94.16673,29.16490,0.81884,3.24054,94.16673
11.32000,94.33342,29.07181,0.82029,3.23020,94.33342
11.34000,94.50004,28.99081,0.82174,3.22120,94.50004
11.36000,94.66661,29.19938,0.82319,3.24438,94.66661
11.38000,94.83336,29.19240,0.82464,3.24360,94.83336
11.40000,95.00004,29.25135,0.82609,3.25015,95.00004
11.42000,95.16673,29.21635,0.82754,3.24626,95.16673
11.44000,95.33335,29.12775,0.82899,3.23642,95.33335
11.46000,95.49998,29.15503,0.83043,3.23945,95.49998
11.48000,95.66661,29.26485,0.83188,3.25165,95.66661
11.50000,95.83330,29.31760,0.83333,3.25751,95.83330
11.52000,96.00005,29.56281,0.83478,3.28476,96.00005
11.54000,96.16667,29.60630,0.83623,3.28959,96.16667
11.56000,96.33330,29.45796,0.83768,3.27311,96.33330
11.58000,96.49992,29.60836,0.83913,3.28982,96.49992
11.60000,96.66661,29.61887,0.84058,3.29099,96.66661
11.62000,96.83336,29.48289,0.84203,3.27588,96.83336
11.64000,97.00004,29.72442,0.84348,3.30271,97.00004
11.66000,97.16661,29.76148,0.84493,3.30683,97.16661
11.68000,97.33330,29.65959,0.84638,3.29551,97.33330
11.70000,97.49993,29.73780,0.84783,3.30420,97.49993
11.72000,97.66667,29.74739,0.84928,3.30527,97.66667
11.74000,97.83336,29.79741,0.85072,3.31082,97.83336
11.76000,97.99998,29.82327,0.85217,3.31370,97.99998
11.78000,98.16654,29.85898,0.85362,3.31766,98.16654
11.80000,98.33329,29.73664,0.85507,3.30407,98.33329
11.82000,98.49999,29.79246,0.85652,3.31027,98.49999
11.84000,98.66673,29.92442,0.85797,3.32494,98.66673
11.86000,98.83337,29.87208,0.85942,3.31912,98.83337
11.88000,98.99999,30.00526,0.86087,3.33392,98.99999
11.90000,99.16661,30.17954,0.86232,3.35328,99.16661
11.92000,99.33336,30.20513,0.86377,3.35613,99.33336
11.94000,99.50005,30.33832,0.86522,3.37092,99.50005
11.96000,99.66673,30.30099,0.86667,3.36678,99.66673
11.98000,99.83336,30.05684,0.86812,3.33965,99.83336
12.00000,99.99998,30.16553,0.86957,3.35173,99.99998
12.02000,100.16668,30.29700,0.87101,3.36633,100.16668
12.04000,100.33342,30.19250,0.87246,3.35472,100.33342
12.06000,100.50005,30.31013,0.87391,3.36779,100.50005
12.08000,100.66661,30.35066,0.87536,3.37230,100.66661
12.10000,100.83330,30.36200,0.87681,3.37356,100.83330
12.12000,100.99999,30.49080,0.87826,3.38787,100.99999
12.14000,101.16667,30.38255,0.87971,3.37584,101.16667
12.16000,101.33336,30.27601,0.88116,3.36400,101.33336
12.18000,101.50004,30.45411,0.88261,3.38379,101.50004
12.20000,101.66667,30.56900,0.88406,3.39656,101.66667
12.22000,101.83336,30.65168,0.88551,3.40574,101.83336
12.24000,101.99999,30.80860,0.88696,3.42318,101.99999
12.26000,102.16667,30.93869,0.88841,3.43763,102.16667
12.28000,102.33330,30.82797,0.88985,3.42533,102.33330
12.30000,102.49998,30.92030,0.89130,3.43559,102.49998
12.32000,102.66654,30.90776,0.89275,3.43420,102.66654
12.34000,102.83330,30.78464,0.89420,3.42052,102.83330
12.36000,102.99998,30.78178,0.89565,3.42020,102.99998
12.38000,103.16667,30.97146,0.89710,3.44127,103.16667
12.40000,103.33336,30.89698,0.89855,3.43300,103.33336
12.42000,103.49998,30.97724,0.90000,3.44192,103.49998
12.44000,103.66655,31.02745,0.90145,3.44749,103.66655
12.46000,103.83330,30.89079,0.90290,3.43231,103.83330
12.48000,104.00005,31.02216,0.90435,3.44691,104.00005
12.50000,104.16673,31.26097,0.90580,3.47344,104.16673
12.52000,104.33336,31.22478,0.90725,3.46942,104.33336
12.54000,104.49998,31.38715,0.90870,3.48746,104.49998
12.56000,104.66667,31.33219,0.91014,3.48135,104.66667
12.58000,104.83336,31.23384,0.91159,3.47043,104.83336
12.60000,105.00005,31.40018,0.91304,3.48891,105.00005
12.62000,105.16667,31.41571,0.91449,3.49063,105.16667
12.64000,105.33329,31.32671,0.91594,3.48075,105.33329
12.66000,105.49999,31.48218,0.91739,3.49802,105.49999
12.68000,105.66667,31.61497,0.91884,3.51277,105.66667
12.70000,105.83342,31.53713,0.92029,3.50413,105.83342
12.72000,106.00004,31.65954,0.92174,3.51773,106.00004
12.74000,106.16661,31.66561,0.92319,3.51840,106.16661
12.76000,106.33330,31.59528,0.92464,3.51059,106.33330
12.78000,106.50005,31.63250,0.92609,3.51472,106.50005
12.80000,106.66673,31.74957,0.92754,3.52773,106.66673
12.82000,106.83335,31.57475,0.92899,3.50831,106.83335
12.84000,106.99992,31.79297,0.93043,3.53255,106.99992
12.86000,107.16654,32.00349,0.93188,3.55594,107.16654
12.88000,107.33330,31.76985,0.93333,3.52998,107.33330
12.90000,107.50005,31.79400,0.93478,3.53267,107.50005
12.92000,107.66667,32.04053,0.93623,3.56006,107.66667
12.94000,107.83330,31.92806,0.93768,3.54756,107.83330
12.96000,107.99998,32.02583,0.93913,3.55843,107.99998
12.98000,108.16661,31.90190,0.94058,3.54466,108.16661
13.00000,108.33330,31.86492,0.94203,3.54055,108.33330
13.02000,108.50005,32.07844,0.94348,3.56427,108.50005
13.04000,108.66667,32.23273,0.94493,3.58141,108.66667
13.06000,108.83336,32.20716,0.94638,3.57857,108.83336
13.08000,108.99998,32.33760,0.94783,3.59307,108.99998
13.10000,109.16667,32.32105,0.94928,3.59123,109.16667
13.12000,109.33336,32.40525,0.95072,3.60058,109.33336
13.14000,109.50005,32.37106,0.95217,3.59678,109.50005
13.16000,109.66667,32.35362,0.95362,3.59485,109.66667
13.18000,109.83329,32.35989,0.95507,3.59554,109.83329
13.20000,109.99999,32.44688,0.95652,3.60521,109.99999
13.22000,110.16667,32.37292,0.95797,3.59699,110.16667
13.24000,110.33342,32.31042,0.95942,3.59005,110.33342
13.26000,110.50005,32.45668,0.96087,3.60630,110.50005
13.28000,110.66660,32.56811,0.96232,3.61868,110.66660
13.30000,110.83330,32.62665,0.96377,3.62518,110.83330
13.32000,111.00005,32.73676,0.96522,3.63742,111.00005
13.34000,111.16668,32.73392,0.96667,3.63710,111.16668
13.36000,111.33336,32.49768,0.96812,3.61085,111.33336
13.38000,111.49999,32.55651,0.96957,3.61739,111.49999
13.40000,111.66661,32.80215,0.97101,3.64468,111.66661
13.42000,111.83330,32.74832,0.97246,3.63870,111.83330
13.44000,112.00004,32.94577,0.97391,3.66064,112.00004
13.46000,112.16667,32.90790,0.97536,3.65643,112.16667
13.48000,112.33330,32.72520,0.97681,3.63613,112.33330
13.50000,112.49992,32.76791,0.97826,3.64088,112.49992
13.52000,112.66661,33.00651,0.97971,3.66739,112.66661
13.54000,112.83336,33.12357,0.98116,3.68040,112.83336
13.56000,113.00005,33.24573,0.98261,3.69397,113.00005
13.58000,113.16667,33.21796,0.98406,3.69088,113.16667
13.60000,113.33330,33.07484,0.98551,3.67498,113.33330
13.62000,113.49998,33.28208,0.98696,3.69801,113.49998
13.64000,113.66667,33.18465,0.98841,3.68718,113.66667
13.66000,113.83343,33.10506,0.98986,3.67834,113.83343
13.68000,114.00005,33.40101,0.99130,3.71122,114.00005
13.70000,114.16667,33.51009,0.99275,3.72334,114.16667
13.72000,114.33336,33.54849,0.99420,3.72761,114.33336
13.74000,114.50005,33.53453,0.99565,3.72606,114.50005
13.76000,114.66674,33.41164,0.99710,3.71240,114.66674
13.78000,114.83336,33.29751,0.99855,3.69972,114.83336
13.80000,114.99998,33.60913,1.00000,3.73435,114.99998
13.82000,115.16660,33.66355,1.00145,3.74039,115.16660
13.84000,115.33336,33.55085,1.00290,3.72787,115.33336
13.86000,115.50005,33.69275,1.00435,3.74364,115.50005
13.88000,115.66673,33.71067,1.00580,3.74563,115.66673
13.90000,115.83336,33.57396,1.00725,3.73044,115.83336
13.92000,115.99992,33.65611,1.00870,3.73957,115.99992
13.94000,116.16661,33.82657,1.01014,3.75851,116.16661
13.96000,116.33329,33.77773,1.01159,3.75308,116.33329
13.98000,116.50004,33.94457,1.01304,3.77162,116.50004
14.00000,116.66667,34.12178,1.01449,3.79131,116.66667
14.02000,116.83336,34.03817,1.01594,3.78202,116.83336
14.04000,116.99999,34.12526,1.01739,3.79170,116.99999
14.06000,117.16661,34.08852,1.01884,3.78761,117.16661
14.08000,117.33330,33.87868,1.02029,3.76430,117.33330
14.10000,117.49999,34.09572,1.02174,3.78841,117.49999
14.12000,117.66661,34.19829,1.02319,3.79981,117.66661
14.14000,117.83330,34.07922,1.02464,3.78658,117.83330
14.16000,117.99992,34.14706,1.02609,3.79412,117.99992
14.18000,118.16661,34.36282,1.02754,3.81809,118.16661
14.20000,118.33336,34.42851,1.02899,3.82539,118.33336
14.22000,118.50005,34.36684,1.03044,3.81854,118.50005
14.24000,118.66667,34.47313,1.03188,3.83035,118.66667
14.26000,118.83336,34.40123,1.03333,3.82236,118.83336
14.28000,119.00004,34.48273,1.03478,3.83141,119.00004
14.30000,119.16674,34.62718,1.03623,3.84746,119.16674
14.32000,119.33336,34.44203,1.03768,3.82689,119.33336
14.34000,119.49998,34.57462,1.03913,3.84162,119.49998
14.36000,119.66661,34.67680,1.04058,3.85298,119.66661
14.38000,119.83336,34.68126,1.04203,3.85347,119.83336
14.40000,120.00005,34.84354,1.04348,3.87150,120.00005
14.42000,120.16674,34.88532,1.04493,3.87615,120.16674
14.44000,120.33342,34.71285,1.04638,3.85698,120.33342
14.46000,120.49999,34.74836,1.04783,3.86093,120.49999
14.48000,120.66661,34.75169,1.04927,3.86130,120.66661
14.50000,120.83329,34.62317,1.05072,3.84702,120.83329
14.52000,121.00005,34.84966,1.05217,3.87218,121.00005
14.54000,121.16661,35.01135,1.05362,3.89015,121.16661
14.56000,121.33330,35.10638,1.05507,3.90071,121.33330
14.58000,121.49998,35.20390,1.05652,3.91154,121.49998
14.60000,121.66668,35.27208,1.05797,3.91912,121.66668
14.62000,121.83336,35.10564,1.05942,3.90063,121.83336
14.64000,121.99998,35.29897,1.06087,3.92211,121.99998
14.66000,122.16661,35.34546,1.06232,3.92727,122.16661
14.68000,122.33323,35.26513,1.06377,3.91835,122.33323
14.70000,122.49999,35.12587,1.06522,3.90287,122.49999
14.72000,122.66668,35.09428,1.06667,3.89936,122.66668
14.74000,122.83330,35.23103,1.06812,3.91456,122.83330
14.76000,122.99999,35.45993,1.06957,3.93999,122.99999
14.78000,123.16661,35.36917,1.07101,3.92991,123.16661
14.80000,123.33330,35.17015,1.07246,3.90779,123.33330
14.82000,123.50004,35.35853,1.07391,3.92873,123.50004
14.84000,123.66667,35.52023,1.07536,3.94669,123.66667
14.86000,123.83336,35.49348,1.07681,3.94372,123.83336
14.88000,123.99998,35.59595,1.07826,3.95511,123.99998
14.90000,124.16661,35.54403,1.07971,3.94934,124.16661
14.92000,124.33330,35.57024,1.08116,3.95225,124.33330
14.94000,124.49998,35.59816,1.08261,3.95535,124.49998
14.96000,124.66667,35.69358,1.08406,3.96595,124.66667
14.98000,124.83336,35.65057,1.08551,3.96117,124.83336
15.00000,124.99998,35.85228,1.08696,3.98359,124.99998
15.02000,125.16667,35.97939,1.08841,3.99771,125.16667
15.04000,125.33336,35.78684,1.08986,3.97632,125.33336
15.06000,125.50004,36.04919,1.09130,4.00547,125.50004
15.08000,125.66666,36.06021,1.09275,4.00669,125.66666
15.10000,125.83329,35.97738,1.09420,3.99749,125.83329
15.12000,125.99992,36.21058,1.09565,4.02340,125.99992
15.14000,126.16660,36.18883,1.09710,4.02098,126.16660
15.16000,126.33336,36.11262,1.09855,4.01251,126.33336
15.18000,126.50005,36.09503,1.10000,4.01056,126.50005
15.20000,126.66660,36.00011,1.10145,4.00001,126.66660
15.22000,126.83329,35.92580,1.10290,3.99176,126.83329
15.24000,126.99998,36.19540,1.10435,4.02171,126.99998
15.26000,127.16666,36.28528,1.10580,4.03170,127.16666
15.28000,127.33336,36.29395,1.10725,4.03266,127.33336
15.30000,127.49991,36.49953,1.10869,4.05550,127.49991
15.32000,127.66647,36.34083,1.11014,4.03787,127.66647
15.34000,127.83329,36.31281,1.11159,4.03476,127.83329
15.36000,128.00003,36.49933,1.11304,4.05548,128.00003
15.38000,128.16672,36.63815,1.11449,4.07091,128.16672
15.40000,128.33335,36.46235,1.11594,4.05137,128.33335
15.42000,128.50004,36.43384,1.11739,4.04820,128.50004
15.44000,128.66667,36.54165,1.11884,4.06018,128.66667
15.46000,128.83342,36.66646,1.12029,4.07405,128.83342
15.48000,129.00010,36.86180,1.12174,4.09576,129.00010
15.50000,129.16672,36.81346,1.12319,4.09038,129.16672
15.52000,129.33329,36.72710,1.12464,4.08079,129.33329
15.54000,129.49998,36.71471,1.12609,4.07941,129.49998
15.56000,129.66667,36.79969,1.12754,4.08885,129.66667
15.58000,129.83342,36.78201,1.12899,4.08689,129.83342
15.60000,130.00011,36.95002,1.13044,4.10556,130.00011
15.62000,130.16666,36.79862,1.13188,4.08874,130.16666
15.64000,130.33330,36.76188,1.13333,4.08465,130.33330
15.66000,130.49997,37.10333,1.13478,4.12259,130.49997
15.68000,130.66660,37.13449,1.13623,4.12605,130.66660
15.70000,130.83328,37.09119,1.13768,4.12124,130.83328
15.72000,130.99998,37.12596,1.13913,4.12511,130.99998
15.74000,131.16661,37.16025,1.14058,4.12892,131.16661
15.76000,131.33329,37.10715,1.14203,4.12302,131.33329
15.78000,131.49998,37.22520,1.14348,4.13613,131.49998
15.80000,131.66666,37.24313,1.14493,4.13813,131.66666
15.82000,131.83336,37.06689,1.14638,4.11854,131.83336
15.84000,131.99999,37.24406,1.14783,4.13823,131.99999
15.86000,132.16661,37.37083,1.14927,4.15231,132.16661
15.88000,132.33324,37.38743,1.15072,4.15416,132.33324
15.90000,132.49998,37.39360,1.15217,4.15484,132.49998
15.92000,132.66660,37.41751,1.15362,4.15750,132.66660
15.94000,132.83329,37.36750,1.15507,4.15194,132.83329
15.96000,132.99991,37.42583,1.15652,4.15843,132.99991
15.98000,133.16660,37.46551,1.15797,4.16283,133.16660
16.00000,133.33342,37.47663,1.15942,4.16407,133.33342
16.02000,133.50010,37.56935,1.16087,4.17437,133.50010
16.04000,133.66672,37.65101,1.16232,4.18344,133.66672
16.06000,133.83329,37.54329,1.16377,4.17148,133.83329
16.08000,133.99998,37.72051,1.16522,4.19117,133.99998
16.10000,134.16666,37.61691,1.16667,4.17966,134.16666
16.12000,134.33342,37.64322,1.16812,4.18258,134.33342
16.14000,134.50004,37.83743,1.16957,4.20416,134.50004
16.16000,134.66661,37.99608,1.17101,4.22179,134.66661
16.18000,134.83330,37.92536,1.17246,4.21393,134.83330
16.20000,134.99998,37.98227,1.17391,4.22025,134.99998
16.22000,135.16666,37.92820,1.17536,4.21424,135.16666
16.24000,135.33342,37.89983,1.17681,4.21109,135.33342
16.26000,135.50005,37.96934,1.17826,4.21882,135.50005
16.28000,135.66661,38.22052,1.17971,4.24672,135.66661
16.30000,135.83330,38.20347,1.18116,4.24483,135.83330
16.32000,135.99998,38.46401,1.18261,4.27378,135.99998
16.34000,136.16666,38.34293,1.18406,4.26033,136.16666
16.36000,136.33335,38.21719,1.18551,4.24635,136.33335
16.38000,136.49997,38.21959,1.18696,4.24662,136.49997
16.40000,136.66660,38.22508,1.18841,4.24723,136.66660
16.42000,136.83329,38.12329,1.18985,4.23592,136.83329
16.44000,137.00004,38.42301,1.19130,4.26922,137.00004
16.46000,137.16660,38.70716,1.19275,4.30080,137.16660
16.48000,137.33329,38.60758,1.19420,4.28973,137.33329
16.50000,137.49992,38.63452,1.19565,4.29272,137.49992
16.52000,137.66654,38.65558,1.19710,4.29506,137.66654
16.54000,137.83336,38.51206,1.19855,4.27912,137.83336
16.56000,138.00004,38.54395,1.20000,4.28266,138.00004
16.58000,138.16667,38.57726,1.20145,4.28636,138.16667
16.60000,138.33336,38.62130,1.20290,4.29125,138.33336
16.62000,138.50003,38.71201,1.20435,4.30133,138.50003
16.64000,138.66673,38.77098,1.20580,4.30789,138.66673
16.66000,138.83342,38.70212,1.20725,4.30024,138.83342
16.68000,139.00004,38.65088,1.20870,4.29454,139.00004
16.70000,139.16667,38.66763,1.21014,4.29640,139.16667
16.72000,139.33335,38.77373,1.21159,4.30819,139.33335
16.74000,139.50004,38.89408,1.21304,4.32156,139.50004
16.76000,139.66672,39.04288,1.21449,4.33810,139.66672
16.78000,139.83342,38.91352,1.21594,4.32372,139.83342
16.80000,140.00005,38.92097,1.21739,4.32455,140.00005
16.82000,140.16667,38.93042,1.21884,4.32560,140.16667
16.84000,140.33335,38.84372,1.22029,4.31597,140.33335
16.86000,140.50004,38.92606,1.22174,4.32512,140.50004
16.88000,140.66673,39.01937,1.22319,4.33549,140.66673
16.90000,140.83335,38.93885,1.22464,4.32654,140.83335
16.92000,140.99997,39.05528,1.22609,4.33948,140.99997
16.94000,141.16654,39.21775,1.22754,4.35753,141.16654
16.96000,141.33330,39.17137,1.22899,4.35237,141.33330
16.98000,141.50004,39.26610,1.23044,4.36290,141.50004
17.00000,141.66667,39.27913,1.23188,4.36435,141.66667
17.02000,141.83329,39.14374,1.23333,4.34930,141.83329
17.04000,141.99992,39.17822,1.23478,4.35314,141.99992
17.06000,142.16661,39.14869,1.23623,4.34985,142.16661
17.08000,142.33336,39.14810,1.23768,4.34979,142.33336
17.10000,142.50005,39.11234,1.23913,4.34582,142.50005
17.12000,142.66661,30.12574,1.24058,3.34730,142.66661
17.14000,142.83329,9.65825,1.24203,1.07314,142.83329
17.16000,142.99998,0.02926,1.24348,0.00325,142.99998
17.18000,143.16666,-1.65174,1.24493,-0.18353,143.16666
17.20000,143.33342,-0.82350,1.24638,-0.09150,143.33342
17.22000,143.50004,-0.03297,1.24783,-0.00366,143.50004
17.24000,143.66667,0.20148,1.24928,0.02239,143.66667
17.26000,143.83336,0.02204,1.25072,0.00245,143.83336
17.28000,144.00004,0.09509,1.25217,0.01057,144.00004
17.30000,144.16672,0.11106,1.25362,0.01234,144.16672
17.32000,144.33342,0.05321,1.25507,0.00591,144.33342
17.34000,144.49998,0.15468,1.25652,0.01719,144.49998
17.36000,144.66654,0.06715,1.25797,0.00746,144.66654
17.38000,144.83330,-0.05450,1.25942,-0.00606,144.83330
17.40000,145.00004,-0.01264,1.26087,-0.00140,145.00004
17.42000,145.16667,0.00523,1.26232,0.00058,145.16667
17.44000,145.33335,-0.15790,1.26377,-0.01754,145.33335
17.46000,145.49998,-0.03456,1.26522,-0.00384,145.49998
17.48000,145.66660,0.05909,1.26667,0.00657,145.66660
17.50000,145.83336,0.02515,1.26812,0.00279,145.83336
17.52000,146.00004,-0.19628,1.26957,-0.02181,146.00004
17.54000,146.16661,-0.08085,1.27101,-0.00898,146.16661
17.56000,146.33330,-0.12442,1.27246,-0.01382,146.33330
17.58000,146.49997,-0.06679,1.27391,-0.00742,146.49997
17.60000,146.66661,-0.05494,1.27536,-0.00610,146.66661
17.62000,146.83335,-0.04392,1.27681,-0.00488,146.83335
17.64000,147.00005,0.00058,1.27826,0.00006,147.00005
17.66000,147.16660,-0.02234,1.27971,-0.00248,147.16660
17.68000,147.33329,-0.09160,1.28116,-0.01018,147.33329
17.70000,147.49992,0.08772,1.28261,0.00975,147.49992
17.72000,147.66673,0.19191,1.28406,0.02132,147.66673