File: NR/NR/RDSO NR Tensile 250.is_tens_RawData/Specimen_RawData_2.csv
Time,Extension,Load,
(sec),(mm),(N),(kgf)
0,0,-1.038328102,-0.10588
0.04,0.06769,-0.555448656,-0.05664
0.08,0.27756,-0.226827815,-0.02313
0.12,0.48294,-0.141313827,-0.01441
0.16,0.65537,0.211235241,0.02154
0.2,0.82406,0.789631458,0.08052
0.24,0.99475,0.819247541,0.08354
0.28,1.16394,1.285946015,0.13113
0.32,1.33169,1.501300049,0.15309
0.36,1.499,1.833745484,0.18699
0.4,1.666,2.136084503,0.21782
0.44,1.83287,2.350163673,0.23965
0.48,1.99981,2.613374159,0.26649
0.52,2.16662,2.772339955,0.2827
0.56,2.33337,3.14008933,0.3202
0.6,2.5,3.203636422,0.32668
0.64,2.66656,3.405751479,0.34729
0.68,2.83331,3.670629095,0.3743
0.72,3.00006,3.650917729,0.37229
0.76,3.16669,4.041516598,0.41212
0.8,3.33331,4.237845731,0.43214
0.84,3.5,4.547147472,0.46368
0.88,3.66656,4.757696248,0.48515
0.92,3.83337,4.939805738,0.50372
0.96,4.00012,5.318342428,0.54232
1,4.16669,5.259208329,0.53629
1.04,4.33331,5.217628133,0.53205
1.08,4.5,5.623623443,0.57345
1.12,4.66669,5.8251501,0.594
1.16,4.83344,5.897915443,0.60142
1.2,5.00006,6.050506917,0.61698
1.24,5.16662,6.28606265,0.641
1.28,5.33325,6.606151706,0.67364
1.32,5.5,6.562806313,0.66922
1.36,5.66669,6.898684076,0.70347
1.4,5.83337,7.002830699,0.71409
1.44,6.00006,7.096288073,0.72362
1.48,6.16662,7.136985671,0.72777
1.52,6.33331,7.355870099,0.75009
1.56,6.5,7.668113835,0.78193
1.6,6.66662,7.727836333,0.78802
1.64,6.83337,7.932403052,0.80888
1.68,7.00012,8.135498774,0.82959
1.72,7.16669,8.037628407,0.81961
1.76,7.33325,8.204733723,0.83665
1.8,7.50006,8.268575014,0.84316
1.84,7.66675,8.523155648,0.86912
1.88,7.83337,8.587879538,0.87572
1.92,8,8.473337866,0.86404
1.96,8.16656,8.667215337,0.88381
2,8.33344,8.929052892,0.91051
2.04,8.50012,9.119596101,0.92994
2.08,8.66656,9.109593318,0.92892
2.12,8.83319,9.255908536,0.94384
2.16,9,9.363585553,0.95482
2.2,9.16669,9.416247264,0.96019
2.24,9.33337,9.722410877,0.99141
2.28,9.50012,9.746633302,0.99388
2.32,9.66662,9.8851032,1.008
2.36,9.83325,9.914228951,1.01097
2.4,10,9.954436216,1.01507
2.44,10.16669,10.13046558,1.03302
2.48,10.33337,10.06554556,1.0264
2.52,10.50006,10.0420096,1.024
2.56,10.66656,10.26746448,1.04699
2.6,10.83331,10.39259734,1.05975
2.64,11.00006,10.19058035,1.03915
2.68,11.16669,10.36572712,1.05701
2.72,11.33337,10.74857873,1.09605
2.76,11.5,10.62472074,1.08342
2.8,11.66656,10.6523755,1.08624
2.84,11.83337,10.82693387,1.10404
2.88,12.00012,10.97658335,1.1193
2.92,12.16669,11.08798689,1.13066
2.96,12.33331,11.1222121,1.13415
3,12.5,10.96030431,1.11764
3.04,12.66669,11.27607844,1.14984
3.08,12.83337,11.4374959,1.1663
3.12,13.00006,11.40454555,1.16294
3.16,13.16662,11.52859967,1.17559
3.2,13.33331,11.47074044,1.16969
3.24,13.50006,11.35080511,1.15746
3.28,13.66668,11.53007067,1.17574
3.32,13.83337,11.55380276,1.17816
3.36,14.00012,11.4919228,1.17185
3.4,14.16662,11.77553112,1.20077
3.44,14.33331,11.72894953,1.19602
3.48,14.50006,11.76239021,1.19943
3.52,14.66669,11.90978416,1.21446
3.56,14.83337,11.94548037,1.2181
3.6,15.00006,12.02736589,1.22645
3.64,15.16662,11.83878401,1.20722
3.68,15.33331,11.8253489,1.20585
3.72,15.50012,12.1421037,1.23815
3.76,15.66675,11.99549428,1.2232
3.8,15.83331,11.99470975,1.22312
3.84,15.99994,12.21987043,1.24608
3.88,16.16662,12.21496711,1.24558
3.92,16.33337,12.19662867,1.24371
3.96,16.50006,12.18427229,1.24245
4,16.66668,12.37432517,1.26183
4.04,16.83337,12.24615225,1.24876
4.08,17,12.51916939,1.2766
4.12,17.1665,12.42149516,1.26664
4.16,17.33331,12.52171912,1.27686
4.2,17.50012,12.67352606,1.29234
4.24,17.66669,12.64479258,1.28941
4.28,17.83331,12.42865401,1.26737
4.32,18,12.24203346,1.24834
4.36,18.16669,12.48876878,1.2735
4.4,18.33337,12.52662244,1.27736
4.44,18.50006,12.56378965,1.28115
4.48,18.66662,12.60105492,1.28495
4.52,18.83331,12.66116968,1.29108
4.56,19.00006,12.86436347,1.3118
4.6,19.16668,12.83798358,1.30911
4.64,19.33337,12.8291576,1.30821
4.68,19.5,12.78130114,1.30333
4.72,19.66662,12.84769217,1.3101
4.76,19.83331,12.7319737,1.2983
4.8,20.00006,12.91104312,1.31656
4.84,20.16668,12.84190624,1.30951
4.88,20.33337,13.0835421,1.33415
4.92,20.5,13.01156129,1.32681
4.96,20.66662,12.94320894,1.31984
5,20.83331,13.10472446,1.33631
5.04,21.00006,13.15052152,1.34098
5.08,21.16662,13.13414441,1.33931
5.12,21.33331,13.19514177,1.34553
5.16,21.5,13.27241818,1.35341
5.2,21.66662,13.09050482,1.33486
5.24,21.83344,13.38107586,1.36449
5.28,22.00012,13.29948453,1.35617
5.32,22.16662,13.27712537,1.35389
5.36,22.33325,13.4769849,1.37427
5.4,22.5,13.35616697,1.36195
5.44,22.66668,13.44668235,1.37118
5.48,22.83337,13.55602649,1.38233
5.52,23.00006,13.60319648,1.38714
5.56,23.16662,13.49532333,1.37614
5.6,23.33325,13.55828202,1.38256
5.64,23.5,13.47384677,1.37395
5.68,23.66669,13.59917575,1.38673
5.72,23.83337,13.40343502,1.36677
5.76,24.00006,13.36411035,1.36276
5.8,24.16662,13.58348511,1.38513
5.84,24.33325,13.70753924,1.39778
5.88,24.50006,13.82933783,1.4102
5.92,24.66675,13.65438719,1.39236
5.96,24.83337,13.72264148,1.39932
6,24.99993,13.65889825,1.39282
6.04,25.16662,13.79011123,1.4062
6.08,25.33343,13.89131586,1.41652
6.12,25.50012,13.92063774,1.41951
6.16,25.6665,13.99595281,1.42719
6.2,25.83318,14.04292667,1.43198
6.24,26,14.06999302,1.43474
6.28,26.16668,13.91593055,1.41903
6.32,26.33343,14.00203294,1.42781
6.36,26.50006,13.8666031,1.414
6.4,26.66662,13.93024826,1.42049
6.44,26.83331,13.99399148,1.42699
6.48,27.00006,14.23180275,1.45124
6.52,27.16668,14.25249478,1.45335
6.56,27.33337,14.2594575,1.45406
6.6,27.5,14.07313115,1.43506
6.64,27.66662,14.24867018,1.45296
6.68,27.83331,14.21601404,1.44963
6.72,28.00006,14.21434691,1.44946
6.76,28.16668,14.30907915,1.45912
6.8,28.33331,14.55738353,1.48444
6.84,28.5,14.23062595,1.45112
6.88,28.66662,14.29417304,1.4576
6.92,28.83337,14.52531578,1.48117
6.96,29.00006,14.33898943,1.46217
7,29.16669,14.37272431,1.46561
7.04,29.33337,14.65162543,1.49405
7.08,29.5,14.57228963,1.48596
7.12,29.66662,14.56464045,1.48518
7.16,29.83331,14.71007307,1.50001
7.2,30.00006,14.65692102,1.49459
7.24,30.16668,14.56689598,1.48541
7.28,30.33331,14.59484493,1.48826
7.32,30.50006,14.69859929,1.49884
7.36,30.66662,14.93611635,1.52306
7.4,30.83337,14.8258896,1.51182
7.44,31.00006,14.65574423,1.49447
7.48,31.16662,14.54993047,1.48368
7.52,31.33325,14.70870014,1.49987
7.56,31.50006,14.79843098,1.50902
7.6,31.66668,15.0650738,1.53621
7.64,31.83337,14.93101689,1.52254
7.68,31.99999,15.00643003,1.53023
7.72,32.16656,14.83295039,1.51254
7.76,32.33331,15.05467875,1.53515
7.8,32.50018,14.91581658,1.52099
7.84,32.66668,14.87551125,1.51688
7.88,32.83324,15.29131321,1.55928
7.92,33,15.14725352,1.54459
7.96,33.16668,15.17902707,1.54783
8,33.33337,15.19697324,1.54966
8.04,33.50006,15.39241977,1.56959
8.08,33.66668,15.29386294,1.55954
8.12,33.83337,15.28278143,1.55841
8.16,34.00006,15.37133548,1.56744
8.2,34.16656,15.37663107,1.56798
8.24,34.33331,15.51990622,1.58259
8.28,34.50006,15.60649894,1.59142
8.32,34.66662,15.46312572,1.5768
8.36,34.83331,15.41987839,1.57239
8.4,34.99999,15.59414256,1.59016
8.44,35.16668,15.64356808,1.5952
8.48,35.33337,15.54118665,1.58476
8.52,35.49999,15.5161797,1.58221
8.56,35.66656,15.59541743,1.59029
8.6,35.83324,15.57099887,1.5878
8.64,35.99999,15.6689673,1.59779
8.68,36.16668,15.72466908,1.60347
8.72,36.33337,15.79488469,1.61063
8.76,36.50006,15.62346445,1.59315
8.8,36.66662,15.76164015,1.60724
8.84,36.83331,15.99091962,1.63062
8.88,37.00006,15.91707555,1.62309
8.92,37.16668,15.85137099,1.61639
8.96,37.33337,15.83568035,1.61479
9,37.49999,15.83205189,1.61442
9.04,37.66662,16.33797697,1.66601
9.08,37.83337,16.01955504,1.63354
9.12,38.00012,16.07339355,1.63903
9.16,38.16668,16.16096693,1.64796
9.2,38.33324,16.24716739,1.65675
9.24,38.5,16.08251373,1.63996
9.28,38.66668,16.26678069,1.65875
9.32,38.83343,16.11752347,1.64353
9.36,39.00012,16.23873367,1.65589
9.4,39.16656,16.27207628,1.65929
9.44,39.33324,16.43996613,1.67641
9.48,39.49999,16.40005306,1.67234
9.52,39.66668,16.56421638,1.68908
9.56,39.83337,16.54077849,1.68669
9.6,40.00005,16.41201717,1.67356
9.64,40.16655,16.51753673,1.68432
9.68,40.33331,16.5167522,1.68424
9.72,40.50006,16.49978669,1.68251
9.76,40.66668,16.44879211,1.67731
9.8,40.83337,16.48674385,1.68118
9.84,40.99999,16.85145316,1.71837
9.88,41.16655,16.38946188,1.67126
9.92,41.33324,16.73759795,1.70676
9.96,41.50006,16.78280661,1.71137
10,41.66674,16.74103028,1.70711
10.04,41.83331,16.60138359,1.69287
10.08,41.99999,16.77976655,1.71106
10.12,42.16668,16.8311534,1.7163
10.16,42.33343,16.97913574,1.73139
10.2,42.50012,16.83713545,1.71691
10.24,42.66656,16.93225996,1.72661
10.28,42.83324,17.15859744,1.74969
10.32,42.99999,17.09465808,1.74317
10.36,43.16668,16.99325732,1.73283
10.4,43.33337,17.19949117,1.75386
10.44,43.50012,17.17870107,1.75174
10.48,43.66668,17.14035707,1.74783
10.52,43.83331,17.15938197,1.74977
10.56,44.00006,17.21204368,1.75514
10.6,44.16668,17.06347293,1.73999
10.64,44.33337,17.14133773,1.74793
10.68,44.50005,17.21096495,1.75503
10.72,44.66662,17.27568884,1.76163
10.76,44.83331,17.38042386,1.77231
10.8,45.00006,17.40219462,1.77453
10.84,45.16668,17.56831928,1.79147
10.88,45.3333,17.60332902,1.79504
10.92,45.49999,17.48260915,1.78273
10.96,45.66655,17.64079042,1.79886
11,45.83331,17.62147132,1.79689
11.04,46.00006,17.52311062,1.78686
11.08,46.16668,17.81642752,1.81677
11.12,46.3333,17.78641917,1.81371
11.16,46.49993,17.62882631,1.79764
11.2,46.66662,17.57420327,1.79207
11.24,46.83337,17.62176552,1.79692
11.28,47.00012,17.79740262,1.81483
11.32,47.16662,17.8486914,1.82006
11.36,47.33337,18.07159655,1.84279
11.4,47.50005,17.96166401,1.83158
11.44,47.66668,17.97392232,1.83283
11.48,47.83337,17.93508799,1.82887
11.52,48.00005,17.91547469,1.82687
11.56,48.16662,17.93832418,1.8292
11.6,48.3333,18.15034395,1.85082
11.64,48.50012,18.0222691,1.83776
11.68,48.66668,18.29312878,1.86538
11.72,48.83337,18.25949197,1.86195
11.76,48.99999,18.2029076,1.85618
11.8,49.16662,18.39139141,1.8754
11.84,49.33337,18.26596436,1.86261
11.88,49.50012,18.35726427,1.87192
11.92,49.66662,18.44719125,1.88109
11.96,49.83325,18.50818861,1.88731
12,49.99999,18.38884168,1.87514
12.04,50.16668,18.52407538,1.88893
12.08,50.33331,18.4198307,1.8783
12.12,50.50005,18.66009362,1.9028
12.16,50.66668,18.56693045,1.8933
12.2,50.83337,18.49426317,1.88589
12.24,50.99999,18.76600544,1.9136
12.28,51.16655,18.6349886,1.90024
12.32,51.33331,18.71422633,1.90832
12.36,51.50012,18.69578983,1.90644
12.4,51.66662,18.69451496,1.90631
12.44,51.8333,18.85838408,1.92302
12.48,51.99999,18.92899196,1.93022
12.52,52.16668,18.95321439,1.93269
12.56,52.33337,18.68284505,1.90512
12.6,52.50006,18.84269344,1.92142
12.64,52.66662,19.09197849,1.94684
12.68,52.83331,18.87976258,1.9252
12.72,53.00005,18.90163141,1.92743
12.76,53.16674,18.95831385,1.93321
12.8,53.33337,18.99136226,1.93658
12.84,53.49999,19.09256689,1.9469
12.88,53.66662,19.24604096,1.96255
12.92,53.8333,19.12110424,1.94981
12.96,54.00012,19.23996083,1.96193
13,54.16668,19.12394817,1.9501
13.04,54.3333,19.17258915,1.95506
13.08,54.49993,19.05628228,1.9432
13.12,54.66662,19.20308783,1.95817
13.16,54.83337,19.27565704,1.96557
13.2,55.00006,19.42256066,1.98055
13.24,55.16662,19.65890092,2.00465
13.28,55.33325,19.39912276,1.97816
13.32,55.49999,19.5140567,1.98988
13.36,55.66668,19.52896281,1.9914
13.4,55.83337,19.56103056,1.99467
13.44,56.00005,19.65850866,2.00461
13.48,56.16656,19.5521065,1.99376
13.52,56.33324,19.65154594,2.0039
13.56,56.50006,19.59692289,1.99833
13.6,56.66668,19.76706827,2.01568
13.64,56.83336,19.86062371,2.02522
13.68,57.00005,19.76510694,2.01548
13.72,57.16662,19.71960409,2.01084
13.76,57.3333,19.86101598,2.02526
13.8,57.50006,19.97663638,2.03705
13.84,57.66668,20.01174419,2.04063
13.88,57.83337,19.79776309,2.01881
13.92,58.00006,20.11491015,2.05115
13.96,58.16655,20.17129839,2.0569
14,58.33324,19.85189579,2.02433
14.04,58.50011,19.93731172,2.03304
14.08,58.66674,20.03851634,2.04336
14.12,58.8333,20.15962847,2.05571
14.16,58.99993,20.01076352,2.04053
14.2,59.16668,20.01017513,2.04047
14.24,59.33343,20.15364642,2.0551
14.28,59.50006,20.3586054,2.076
14.32,59.66655,20.19542274,2.05936
14.36,59.83324,20.24582893,2.0645
14.4,60.00006,20.35468274,2.0756
14.44,60.16668,20.34938715,2.07506
14.48,60.33343,20.44784592,2.0851
14.52,60.50006,20.41028645,2.08127
14.56,60.66662,20.58386415,2.09897
14.6,60.83325,20.5368903,2.09418
14.64,60.99999,20.57798016,2.09837
14.68,61.16668,20.60759624,2.10139
14.72,61.33337,20.55110994,2.09563
14.76,61.49999,20.66172895,2.10691
14.8,61.66656,20.80196405,2.12121
14.84,61.8333,20.8477611,2.12588
14.88,62.00012,20.83236466,2.12431
14.92,62.16668,20.80774997,2.1218
14.96,62.33331,20.92729303,2.13399
15,62.49999,21.08920083,2.1505
15.04,62.66668,20.92866596,2.13413
15.08,62.83336,20.80990743,2.12202
15.12,63.00011,20.95298646,2.13661
15.16,63.16661,21.26934899,2.16887
15.2,63.3333,20.92248778,2.1335
15.24,63.49999,21.0087863,2.1423
15.28,63.66668,21.14980592,2.15668
15.32,63.83337,21.28690289,2.17066
15.36,64.00005,21.0468361,2.14618
15.4,64.16667,21.16628109,2.15836
15.44,64.3333,21.09685001,2.15128
15.48,64.50005,21.06850879,2.14839
15.52,64.66662,21.27758657,2.16971
15.56,64.83336,21.26777992,2.16871
15.6,65.00005,21.31455764,2.17348
15.64,65.16661,21.3395646,2.17603
15.68,65.3333,21.34829252,2.17692
15.72,65.50005,21.50853318,2.19326
15.76,65.66667,21.48744888,2.19111
15.8,65.8333,21.54991724,2.19748
15.84,65.99999,21.61915219,2.20454
15.88,66.16655,21.64945474,2.20763
15.92,66.33336,21.60512868,2.20311
15.96,66.50012,21.70348938,2.21314
16,66.66661,21.83460429,2.22651
16.04,66.83324,21.66083045,2.20879
16.08,66.99999,21.73114413,2.21596
16.12,67.16668,21.61552373,2.20417
16.16,67.33336,21.890208,2.23218
16.2,67.50011,22.0239707,2.24582
16.24,67.66674,22.03858261,2.24731
16.28,67.83336,22.01485052,2.24489
16.32,67.99993,21.92462934,2.23569
16.36,68.16655,21.91766662,2.23498
16.4,68.33337,22.03917101,2.24737
16.44,68.50012,22.02348037,2.24577
16.48,68.66661,22.05250805,2.24873
16.52,68.8333,22.11428995,2.25503
16.56,69.00005,22.06427603,2.24993
16.6,69.16668,22.24805266,2.26867
16.64,69.33337,22.28472953,2.27241
16.68,69.49999,22.17293372,2.26101
16.72,69.66655,22.15263395,2.25894
16.76,69.8333,22.34386363,2.27844
16.8,70.00005,22.360633,2.28015
16.84,70.16668,22.438792,2.28812
16.88,70.3333,22.54892068,2.29935
16.92,70.49999,22.49998549,2.29436
16.96,70.66661,22.4405572,2.2883
17,70.8333,22.56284612,2.30077
17.04,71.00006,22.62217635,2.30682
17.08,71.16668,22.6557151,2.31024
17.12,71.33331,22.71602599,2.31639
17.16,71.49999,22.57029917,2.30153
17.2,71.66661,22.72789204,2.3176
17.24,71.83337,22.83517679,2.32854
17.28,72.00005,22.82448754,2.32745
17.32,72.16662,22.85302489,2.33036
17.36,72.3333,22.64620265,2.30927
17.4,72.50005,22.89862582,2.33501
17.44,72.66674,22.90274461,2.33543
17.48,72.83343,22.81850549,2.32684
17.52,73.00005,22.98835666,2.34416
17.56,73.16662,23.17889987,2.36359
17.6,73.33324,23.02317027,2.34771
17.64,73.50005,23.10397707,2.35595
17.68,73.66668,23.13496608,2.35911
17.72,73.83343,23.16497443,2.36217
17.76,74.00006,23.0459217,2.35003
17.8,74.16661,23.14820506,2.36046
17.84,74.3333,23.34522066,2.38055
17.88,74.50006,23.43240178,2.38944
17.92,74.66668,23.28598849,2.37451
17.96,74.83337,23.27235725,2.37312
18,74.99999,23.38258399,2.38436
18.04,75.16649,23.5977419,2.4063
18.08,75.3333,23.43838383,2.39005
18.12,75.50012,23.33521787,2.37953
18.16,75.66668,23.74503778,2.42132
18.2,75.83324,23.68786501,2.41549
18.24,75.99992,23.71993275,2.41876
18.28,76.16668,23.75572703,2.42241
18.32,76.33343,23.74180158,2.42099
18.36,76.49999,23.63912596,2.41052
18.4,76.66649,23.76523948,2.42338
18.44,76.83324,23.66991884,2.41366
18.48,77.00011,23.81584179,2.42854
18.52,77.16668,23.69884846,2.41661
18.56,77.33336,23.98608524,2.4459
18.6,77.50005,23.9861833,2.44591
18.64,77.66661,23.89655052,2.43677
18.68,77.83331,23.8491844,2.43194
18.72,78.00005,24.19339782,2.46704
18.76,78.16668,23.95725368,2.44296
18.8,78.33336,24.03090163,2.45047
18.84,78.50005,24.19506495,2.46721
18.88,78.66668,24.1413245,2.46173
18.92,78.83336,24.06512683,2.45396
18.96,79.00012,24.14838529,2.46245
19,79.16667,24.25723911,2.47355
19.04,79.3333,24.01266126,2.44861
19.08,79.49999,24.2218371,2.46994
19.12,79.66661,24.35079455,2.48309
19.16,79.8333,24.31186215,2.47912
19.2,80.00005,24.36648519,2.48469
19.24,80.16662,24.45915803,2.49414
19.28,80.3333,24.52947171,2.50131
19.32,80.49999,24.53996483,2.50238
19.36,80.66662,24.44425192,2.49262
19.4,80.83336,24.67696373,2.51635
19.44,81.00005,24.67863086,2.51652
19.48,81.16661,24.64313079,2.5129
19.52,81.3333,24.6123379,2.50976
19.56,81.49998,24.66823581,2.51546
19.6,81.66661,24.80768637,2.52968
19.64,81.83336,24.63842359,2.51242
19.68,82.00006,24.69706736,2.5184
19.72,82.16655,24.89006223,2.53808
19.76,82.33336,24.93517282,2.54268
19.8,82.50011,24.91379433,2.5405
19.84,82.66667,24.87927492,2.53698
19.88,82.83329,25.07736925,2.55718
19.92,82.99999,25.04108464,2.55348
19.96,83.16661,24.98312734,2.54757
20,83.33342,25.16023544,2.56563
20.04,83.50012,25.16876723,2.5665
20.08,83.66661,25.26957959,2.57678
20.12,83.83323,25.22054634,2.57178
20.16,83.99999,25.37029388,2.58705
20.2,84.16668,25.24849529,2.57463
20.24,84.3333,25.12444117,2.56198
20.28,84.50005,25.23447178,2.5732
20.32,84.66667,25.22554773,2.57229
20.36,84.8333,25.52759255,2.60309
20.4,84.99992,25.43442937,2.59359
20.44,85.16661,25.42638792,2.59277
20.48,85.33336,25.58368659,2.60881
20.52,85.50005,25.54191026,2.60455
20.56,85.66661,25.42011166,2.59213
20.6,85.83331,25.53602627,2.60395
20.64,86.00005,25.53514367,2.60386
20.68,86.16667,25.65223507,2.6158
20.72,86.3333,25.59810236,2.61028
20.76,86.49998,25.809926,2.63188
20.8,86.66655,25.7145073,2.62215
20.84,86.83329,25.79158757,2.63001
20.88,87.00005,25.7941373,2.63027
20.92,87.16667,26.01351206,2.65264
20.96,87.33337,26.10726363,2.6622
21,87.49999,25.96389041,2.64758
21.04,87.66661,25.76746321,2.62755
21.08,87.83337,26.02214191,2.65352
21.12,88.00011,25.89691099,2.64075
21.16,88.16668,26.15198195,2.66676
21.2,88.3333,26.21484258,2.67317
21.24,88.49998,26.06970416,2.65837
21.28,88.66668,26.1249156,2.664
21.32,88.83336,26.30829996,2.6827
21.36,89.00011,26.41862477,2.69395
21.4,89.16655,26.20503593,2.67217
21.44,89.33323,26.28868666,2.6807
21.48,89.49999,26.38606669,2.69063
21.52,89.66674,26.63162521,2.71567
21.56,89.83342,26.33056105,2.68497
21.6,89.99999,26.45618424,2.69778
21.64,90.16655,26.59896906,2.71234
21.68,90.33323,26.47481687,2.69968
21.72,90.50005,26.43715934,2.69584
21.76,90.66667,26.53071478,2.70538
21.8,90.83336,26.56847038,2.70923
21.84,90.99999,26.66692915,2.71927
21.88,91.16654,26.62829094,2.71533
21.92,91.3333,26.7709777,2.72988
21.96,91.50005,26.82667947,2.73556
22,91.66667,26.83540739,2.73645
22.04,91.83336,26.79431753,2.73226
22.08,91.99998,26.76009232,2.72877
22.12,92.16661,26.84325271,2.73725
22.16,92.33336,26.84393918,2.73732
22.2,92.50017,26.9302377,2.74612
22.24,92.66668,27.09547975,2.76297
22.28,92.8333,27.09528362,2.76295
22.32,92.99998,26.98780273,2.75199
22.36,93.16674,26.98397814,2.7516
22.4,93.33342,27.12823396,2.76631
22.44,93.49999,27.11793698,2.76526
22.48,93.66655,27.08057364,2.76145
22.52,93.83329,27.20776589,2.77442
22.56,94.00005,27.23228252,2.77692
22.6,94.16667,27.27229365,2.781
22.64,94.33337,27.42821939,2.7969
22.68,94.50004,27.30151747,2.78398
22.72,94.66661,27.40174143,2.7942
22.76,94.8333,27.42596386,2.79667
22.8,95.00004,27.48549022,2.80274
22.84,95.16668,27.42929812,2.79701
22.88,95.33335,27.86186945,2.84112
22.92,95.49998,27.68858594,2.82345
22.96,95.66661,27.66867844,2.82142
23,95.8333,27.57021968,2.81138
23.04,96.00011,27.52550135,2.80682
23.08,96.16661,27.62464658,2.81693
23.12,96.33323,27.65220327,2.81974
23.16,96.49992,27.65004581,2.81952
23.2,96.66661,27.87726589,2.84269
23.24,96.83336,27.94208785,2.8493
23.28,97.00011,27.73301007,2.82798
23.32,97.16661,27.87187223,2.84214
23.36,97.3333,27.89050487,2.84404
23.4,97.50005,27.9266914,2.84773
23.44,97.66674,27.96464314,2.8516
23.48,97.83336,27.89864439,2.84487
23.52,98.00005,28.10252464,2.86566
23.56,98.16667,28.19480522,2.87507
23.6,98.33336,28.1831353,2.87388
23.64,98.5001,28.23844481,2.87952
23.68,98.66667,28.12498187,2.86795
23.72,98.83337,28.31699607,2.88753
23.76,98.99999,28.37613017,2.89356
23.8,99.16661,28.45899637,2.90201
23.84,99.33336,28.23207049,2.87887
23.88,99.50011,28.4404618,2.90012
23.92,99.66668,28.26551116,2.88228
23.96,99.8333,28.27659268,2.88341
24,99.99998,28.70602588,2.9272
24.04,100.16661,28.50145916,2.90634
24.08,100.33336,28.5385283,2.91012
24.12,100.50011,28.52205313,2.90844
24.16,100.66655,28.44261926,2.90034
24.2,100.83323,28.64679371,2.92116
24.24,100.99999,28.80781891,2.93758
24.28,101.16661,28.94599461,2.95167
24.32,101.3333,28.92687164,2.94972
24.36,101.50004,29.05092576,2.96237
24.4,101.66667,28.94972113,2.95205
24.44,101.8333,28.81831202,2.93865
24.48,101.99999,28.79310893,2.93608
24.52,102.16661,28.88793924,2.94575
24.56,102.33336,28.80389625,2.93718
24.6,102.50011,29.08338577,2.96568
24.64,102.66662,29.17851028,2.97538
24.68,102.8333,29.0110127,2.9583
24.72,103.0001,29.2241112,2.98003
24.76,103.16667,29.30942905,2.98873
24.8,103.33336,29.25058915,2.98273
24.84,103.49998,29.14036241,2.97149
24.88,103.66655,29.20587083,2.97817
24.92,103.8333,29.18321747,2.97586
24.96,104.00011,29.29295388,2.98705
25,104.16668,29.40376903,2.99835
25.04,104.3333,29.38091953,2.99602
25.08,104.49998,29.40474969,2.99845
25.12,104.66655,29.51311318,3.0095
25.16,104.83336,29.60725702,3.0191
25.2,105.00005,29.51321124,3.00951
25.24,105.16667,29.7123843,3.02982
25.28,105.33324,29.60617828,3.01899
25.32,105.49999,29.76945901,3.03564
25.36,105.66667,29.65217147,3.02368
25.4,105.83336,29.68835801,3.02737
25.44,106.00004,29.77946179,3.03666
25.48,106.16655,29.83192737,3.04201
25.52,106.33323,29.96363068,3.05544
25.56,106.50005,29.8321235,3.04203
25.6,106.66673,29.87321336,3.04622
25.64,106.83335,30.00638767,3.0598
25.68,106.99999,30.08327181,3.06764
25.72,107.16661,30.04443747,3.06368
25.76,107.3333,30.10396384,3.06975
25.8,107.50011,29.95500082,3.05456
25.84,107.66674,30.24929839,3.08457
25.88,107.83336,30.17123746,3.07661
25.92,107.99998,30.05816678,3.06508
25.96,108.16661,30.17113939,3.0766
26,108.33336,30.09474559,3.06881
26.04,108.50005,30.34481516,3.09431
26.08,108.66667,30.46533889,3.1066
26.12,108.83336,30.39306388,3.09923
26.16,108.99998,30.2844062,3.08815
26.2,109.16654,30.39394648,3.09932
26.24,109.33336,30.60890825,3.12124
26.28,109.5001,30.59831706,3.12016
26.32,109.66667,30.40728352,3.10068
26.36,109.83324,30.63793593,3.1242
26.4,109.99999,30.78307435,3.139
26.44,110.16667,30.72943197,3.13353
26.48,110.33342,30.83259793,3.14405
26.52,110.49998,30.50113316,3.11025
26.56,110.66655,30.76728564,3.13739
26.6,110.8333,30.76012679,3.13666
26.64,111.00005,30.74767234,3.13539
26.68,111.16668,30.74757428,3.13538
26.72,111.33336,30.86692121,3.14755
26.76,111.49999,30.8543687,3.14627
26.8,111.66655,30.94213821,3.15522
26.84,111.8333,30.92301525,3.15327
26.88,112.00011,30.96743937,3.1578
26.92,112.16667,31.15170632,3.17659
26.96,112.3333,31.13699635,3.17509
27,112.50004,31.21633215,3.18318
27.04,112.66667,31.12012891,3.17337
27.08,112.83342,31.01882622,3.16304
27.12,113.00012,31.2047603,3.182
27.16,113.16661,31.31714451,3.19346
27.2,113.33324,31.08511917,3.1698
27.24,113.49998,31.42099693,3.20405
27.28,113.66667,31.56515469,3.21875
27.32,113.83336,31.47885617,3.20995
27.36,114.00005,31.44433676,3.20643
27.4,114.16661,31.35313491,3.19713
27.44,114.33329,31.47552191,3.20961
27.48,114.50005,31.4998424,3.21209
27.52,114.66667,31.47983683,3.21005
27.56,114.8333,31.60036056,3.22234
27.6,115.00005,31.83885829,3.24666
27.64,115.1666,31.83542596,3.24631
27.68,115.3333,31.85415666,3.24822
27.72,115.49998,31.8514108,3.24794
27.76,115.66667,31.84376161,3.24716
27.8,115.83336,31.86484591,3.24931
27.84,115.99999,31.9530077,3.2583
27.88,116.16655,31.89102967,3.25198
27.92,116.33329,31.98232958,3.26129
27.96,116.50004,31.91848829,3.25478
28,116.66667,32.10589337,3.27389
28.04,116.8333,32.18120844,3.28157
28.08,116.99999,32.08657427,3.27192
28.12,117.16668,31.94271071,3.25725
28.16,117.33342,31.95506709,3.25851
28.2,117.50011,31.91358496,3.25428
28.24,117.66661,32.12609507,3.27595
28.28,117.8333,32.26927216,3.29055
28.32,118.00005,32.32144354,3.29587
28.36,118.16667,32.35645328,3.29944
28.4,118.33336,32.34017424,3.29778
28.44,118.50011,32.43049348,3.30699
28.48,118.66667,32.33762451,3.29752
28.52,118.8333,32.29790758,3.29347
28.56,118.99993,32.26525143,3.29014
28.6,119.16667,32.39793541,3.30367
28.64,119.33336,32.676052,3.33203
28.68,119.50005,32.50610276,3.3147
28.72,119.66655,32.59985433,3.32426
28.76,119.83329,32.65604643,3.32999
28.8,120.00011,32.67242354,3.33166
28.84,120.16674,32.59455874,3.32372
28.88,120.33329,32.70223576,3.3347
28.92,120.49992,32.85727889,3.35051
28.96,120.66661,33.0317392,3.3683
29,120.83329,32.85276783,3.35005
29.04,121.00005,32.78765168,3.34341
29.08,121.16667,32.79363373,3.34402
29.12,121.3333,32.89483836,3.35434
29.16,121.49998,32.83452746,3.34819
29.2,121.6666,32.94269481,3.35922
29.24,121.83336,33.23356005,3.38888
29.28,122.00011,33.09106943,3.37435
29.32,122.16668,33.22767606,3.38828
29.36,122.3333,33.27955324,3.39357
29.4,122.50005,32.85678856,3.35046
29.44,122.66668,33.03654445,3.36879
29.48,122.83336,33.22944126,3.38846
29.52,123.00004,33.13833748,3.37917
29.56,123.16661,33.25180042,3.39074
29.6,123.3333,33.32809616,3.39852
29.64,123.50004,33.24415123,3.38996
29.68,123.66674,33.14726153,3.38008
29.72,123.83336,33.14078914,3.37942
29.76,123.99998,33.31269972,3.39695
29.8,124.16654,33.29593035,3.39524
29.84,124.3333,33.41969027,3.40786
29.88,124.50005,33.35565284,3.40133
29.92,124.66667,33.41311981,3.40719
29.96,124.83336,33.41537534,3.40742
30,124.99998,33.61396001,3.42767
30.04,125.16654,33.43910744,3.40984
30.08,125.33329,33.54923612,3.42107
30.12,125.50004,33.31887791,3.39758
30.16,125.66666,33.42969305,3.40888
30.2,125.83335,33.49196528,3.41523
30.24,125.99992,33.62141306,3.42843
30.28,126.16654,33.656717,3.43203
30.32,126.33336,33.55247231,3.4214
30.36,126.50016,33.50589072,3.41665
30.4,126.6666,33.52854408,3.41896
30.44,126.83324,33.50853852,3.41692
30.48,127.00004,33.4992222,3.41597
30.52,127.16673,33.51628577,3.41771
30.56,127.33336,33.45058122,3.41101
30.6,127.49999,33.60621275,3.42688
30.64,127.66654,33.4228284,3.40818
30.68,127.83336,33.39536978,3.40538
30.72,128.0001,33.31230745,3.39691
30.76,128.16672,33.11892031,3.37719
30.8,128.33335,3.675924686,0.37484
30.84,128.50004,-2.58336581,-0.26343
30.88,128.66661,-1.223771854,-0.12479
30.92,128.83335,-1.135413937,-0.11578
30.96,129.00004,-1.051861279,-0.10726
31,129.16661,-1.068630651,-0.10897
31.04,129.33329,-1.005083559,-0.10249
31.08,129.49998,-1.215632334,-0.12396
31.12,129.6666,-1.036857105,-0.10573
31.16,129.83336,-1.178955463,-0.12022
31.2,130.00004,-1.11040698,-0.11323
31.24,130.16661,-1.056176205,-0.1077
31.28,130.3333,-1.180034195,-0.12033
31.32,130.49997,-1.243189021,-0.12677
31.36,130.66666,-1.299184992,-0.13248
31.4,130.83336,-1.143063124,-0.11656
31.44,131.00005,-1.089126549,-0.11106
31.48,131.16661,-1.159636363,-0.11825
31.52,131.33324,-1.259566126,-0.12844
31.56,131.49998,-1.258879661,-0.12837
31.6,131.66666,-1.290947406,-0.13164
31.64,131.83342,-1.110897312,-0.11328
31.68,132.00005,-1.072161045,-0.10933
31.72,132.16661,-1.227204181,-0.12514
31.76,132.33329,-1.134433272,-0.11568
31.8,132.5001,-1.333802467,-0.13601
31.84,132.66667,-1.101286795,-0.1123
31.88,132.83335,-1.111387645,-0.11333
31.92,132.99997,-1.217299465,-0.12413
31.96,133.1666,-1.04931155,-0.107
32,133.33336,-1.16699135,-0.119
32.04,133.5001,-0.929474287,-0.09478
32.08,133.66667,-1.2748645,-0.13
32.12,133.83329,-1.200137827,-0.12238
32.16,133.99998,-0.992138781,-0.10117
32.2,134.16666,-0.991746515,-0.10113
32.24,134.33342,-1.126980218,-0.11492
32.28,134.50004,-1.059216267,-0.10801
32.32,134.66655,-1.091284012,-0.11128
32.36,134.8333,-1.140905661,-0.11634
32.4,135.00004,-1.041956563,-0.10625
32.44,135.16666,-1.251034341,-0.12757
32.48,135.33336,-1.267117247,-0.12921
32.52,135.50005,-1.13982693,-0.11623
32.56,135.66661,-1.34939504,-0.1376
32.6,135.83324,-1.176601867,-0.11998
32.64,135.99992,-1.047056021,-0.10677
32.68,136.16666,-1.235441767,-0.12598
32.72,136.33335,-1.243581287,-0.12681
32.76,136.49997,-1.189056313,-0.12125
32.8,136.6666,-0.977428806,-0.09967
32.84,136.83336,-1.196901633,-0.12205
32.88,137.0001,-1.299086926,-0.13247
32.92,137.16667,-1.233284304,-0.12576
32.96,137.33335,-1.115898704,-0.11379
33,137.50004,-1.242404489,-0.12669
33.04,137.66666,-0.965464693,-0.09845
33.08,137.83336,-1.15914603,-0.1182
33.12,138.0001,-1.077162436,-0.10984
33.16,138.16667,-1.066277055,-0.10873
33.2,138.33329,-1.214749736,-0.12387
33.24,138.49998,-1.144239922,-0.11668
33.28,138.66666,-1.269666976,-0.12947
33.32,138.83336,-0.960953634,-0.09799
33.36,139.00011,-1.105405588,-0.11272
33.4,139.16661,-0.990373584,-0.10099
33.44,139.33323,-1.065100257,-0.10861
33.48,139.49998,-1.22220279,-0.12463
33.52,139.66667,-1.241718023,-0.12662
33.548,139.78342,-1.186212384,-0.12096