File: NR/NR/RDSO NR Tensile 250.is_tens_RawData/Specimen_RawData_3.csv
Time,Extension,Load,
(sec),(mm),(N),(kgf)
0,0,-1.052351612,-0.10731
0.04,0.06762,-0.410408303,-0.04185
0.08,0.27756,-0.17485257,-0.01783
0.12,0.48294,-0.324305916,-0.03307
0.16,0.65537,0.288119377,0.02938
0.2,0.82406,0.623899073,0.06362
0.24,0.99475,0.891032219,0.09086
0.28,1.16387,1.103248125,0.1125
0.32,1.33169,1.391465569,0.14189
0.36,1.49906,1.728029797,0.17621
0.4,1.666,2.24601705,0.22903
0.44,1.83287,2.406453844,0.24539
0.48,1.99981,2.530704099,0.25806
0.52,2.16662,2.84226137,0.28983
0.56,2.33337,3.135970537,0.31978
0.6,2.5,3.452529199,0.35206
0.64,2.66656,3.460276453,0.35285
0.68,2.83331,3.85793611,0.3934
0.72,3.00006,4.104965624,0.41859
0.76,3.16669,4.273443871,0.43577
0.8,3.33331,4.583039811,0.46734
0.84,3.5,4.648940499,0.47406
0.88,3.66656,4.873708917,0.49698
0.92,3.83337,5.128583751,0.52297
0.96,4.00012,5.363158819,0.54689
1,4.16669,5.427490443,0.55345
1.04,4.33331,5.663438442,0.57751
1.08,4.5,5.81534345,0.593
1.12,4.66669,6.039621536,0.61587
1.16,4.83344,6.112975278,0.62335
1.2,5.00012,6.412764568,0.65392
1.24,5.16662,6.587617138,0.67175
1.28,5.33325,6.727459967,0.68601
1.32,5.5,6.901331871,0.70374
1.36,5.66669,6.920552905,0.7057
1.4,5.83337,7.232306309,0.73749
1.44,6.00006,7.237013501,0.73797
1.48,6.16662,7.377935061,0.75234
1.52,6.33331,7.627122038,0.77775
1.56,6.5,7.867483029,0.80226
1.6,6.66669,7.937208311,0.80937
1.64,6.83337,8.29838723,0.8462
1.68,7.00012,8.334966035,0.84993
1.72,7.16669,8.241900926,0.84044
1.76,7.33325,8.259062564,0.84219
1.8,7.50006,8.568658504,0.87376
1.84,7.66675,8.643483244,0.88139
1.88,7.83337,9.007506092,0.91851
1.92,8,8.863446403,0.90382
1.96,8.16656,9.057520007,0.92361
2,8.33344,9.179220533,0.93602
2.04,8.50012,9.19108658,0.93723
2.08,8.66656,9.299842328,0.94832
2.12,8.83319,9.407127079,0.95926
2.16,9,9.615812591,0.98054
2.2,9.16669,9.532161867,0.97201
2.24,9.33337,9.576291792,0.97651
2.28,9.50012,9.684164942,0.98751
2.32,9.66662,9.961497004,1.01579
2.36,9.83325,9.944531499,1.01406
2.4,10,10.15978747,1.03601
2.44,10.16669,10.11938407,1.03189
2.48,10.33337,10.28972558,1.04926
2.52,10.50006,10.3733763,1.05779
2.56,10.66656,10.30198389,1.05051
2.6,10.83325,10.50184342,1.07089
2.64,11.00006,10.41093577,1.06162
2.68,11.16669,10.67404819,1.08845
2.72,11.33337,10.58206182,1.07907
2.76,11.5,10.62119035,1.08306
2.8,11.66656,10.87135799,1.10857
2.84,11.83337,11.00011931,1.1217
2.88,12.00012,10.80879156,1.10219
2.92,12.16669,11.11328805,1.13324
2.96,12.33331,11.01953647,1.12368
3,12.5,11.30137959,1.15242
3.04,12.66662,11.19183931,1.14125
3.08,12.83337,11.37787146,1.16022
3.12,13.00006,11.42415885,1.16494
3.16,13.16662,11.36708415,1.15912
3.2,13.33331,11.56282488,1.17908
3.24,13.50006,11.48201809,1.17084
3.28,13.66668,11.55115497,1.17789
3.32,13.83337,11.59832496,1.1827
3.36,14.00006,11.65745905,1.18873
3.4,14.16662,11.58851831,1.1817
3.44,14.33331,11.68638867,1.19168
3.48,14.50006,11.8871308,1.21215
3.52,14.66669,11.75523136,1.1987
3.56,14.83337,11.92076761,1.21558
3.6,15.00006,11.99696528,1.22335
3.64,15.16662,11.96744726,1.22034
3.68,15.33331,12.18721429,1.24275
3.72,15.50012,12.09032459,1.23287
3.76,15.66668,11.93979251,1.21752
3.8,15.83331,12.19221568,1.24326
3.84,15.99994,12.11817547,1.23571
3.88,16.16662,12.13788684,1.23772
3.92,16.33337,12.3938404,1.26382
3.96,16.50006,12.1002293,1.23388
4,16.66668,12.35275054,1.25963
4.04,16.83337,12.42698688,1.2672
4.08,17,12.35382927,1.25974
4.12,17.16656,12.34637622,1.25898
4.16,17.33331,12.55604239,1.28036
4.2,17.50012,12.66215035,1.29118
4.24,17.66669,12.45689716,1.27025
4.28,17.83331,12.6517553,1.29012
4.32,18,12.78090888,1.30329
4.36,18.16669,12.73413116,1.29852
4.4,18.33337,12.85318389,1.31066
4.44,18.50006,12.65911029,1.29087
4.48,18.66662,12.63145553,1.28805
4.52,18.83325,13.06373266,1.33213
4.56,19.00006,12.87132619,1.31251
4.6,19.16668,12.79257879,1.30448
4.64,19.33337,12.80199318,1.30544
4.68,19.5,12.89711768,1.31514
4.72,19.66662,12.9842988,1.32403
4.76,19.83331,12.90741466,1.31619
4.8,20.00006,13.02303507,1.32798
4.84,20.16668,13.25515847,1.35165
4.88,20.33337,13.01165935,1.32682
4.92,20.5,13.02862486,1.32855
4.96,20.66662,13.12767202,1.33865
5,20.83331,13.12267063,1.33814
5.04,21.00006,13.10854906,1.3367
5.08,21.16662,13.19720117,1.34574
5.12,21.33331,13.257414,1.35188
5.16,21.49994,13.30576079,1.35681
5.2,21.66662,13.18121633,1.34411
5.24,21.83337,13.46394205,1.37294
5.28,22.00012,13.34940038,1.36126
5.32,22.16662,13.40892674,1.36733
5.36,22.33325,13.45482187,1.37201
5.4,22.5,13.44736881,1.37125
5.44,22.66668,13.51395597,1.37804
5.48,22.83337,13.36548329,1.3629
5.52,23.00006,13.59280143,1.38608
5.56,23.16662,13.54867151,1.38158
5.6,23.33325,13.49865759,1.37648
5.64,23.5,13.76451587,1.40359
5.68,23.66669,13.63467583,1.39035
5.72,23.83343,13.54474885,1.38118
5.76,24.00006,13.64713027,1.39162
5.8,24.16662,13.8101168,1.40824
5.84,24.33325,13.91034076,1.41846
5.88,24.50006,13.87131029,1.41448
5.92,24.66675,13.81600079,1.40884
5.96,24.83337,13.81188199,1.40842
6,24.99993,14.02733409,1.43039
6.04,25.16662,13.7866789,1.40585
6.08,25.33343,13.92593333,1.42005
6.12,25.50012,13.99997354,1.4276
6.16,25.6665,14.14795589,1.44269
6.2,25.83318,13.86581857,1.41392
6.24,26,13.94888089,1.42239
6.28,26.16668,14.06665876,1.4344
6.32,26.33337,14.11422101,1.43925
6.36,26.50006,14.29025038,1.4572
6.4,26.66662,14.03988661,1.43167
6.44,26.83331,14.09833424,1.43763
6.48,27.00006,14.20924745,1.44894
6.52,27.16668,14.35007095,1.4633
6.56,27.33337,14.27573654,1.45572
6.6,27.50006,14.48765824,1.47733
6.64,27.66662,14.42548408,1.47099
6.68,27.83331,14.44696065,1.47318
6.72,28.00006,14.2576923,1.45388
6.76,28.16668,14.29397691,1.45758
6.8,28.33331,14.53267077,1.48192
6.84,28.5,14.46863334,1.47539
6.88,28.66662,14.62249968,1.49108
6.92,28.83337,14.3387933,1.46215
6.96,29.00012,14.58562668,1.48732
7,29.16669,14.5144304,1.48006
7.04,29.33337,14.47275214,1.47581
7.08,29.5,14.55522606,1.48422
7.12,29.66662,14.39116081,1.46749
7.16,29.83337,14.53629923,1.48229
7.2,30.00006,14.8074531,1.50994
7.24,30.16668,14.69899155,1.49888
7.28,30.33331,14.75891018,1.50499
7.32,30.50006,14.98926839,1.52848
7.36,30.66662,14.94180421,1.52364
7.4,30.83337,14.7863688,1.50779
7.44,31.00006,14.87933585,1.51727
7.48,31.16662,15.00554743,1.53014
7.52,31.33325,14.98446313,1.52799
7.56,31.50006,14.90924613,1.52032
7.6,31.66668,14.94347134,1.52381
7.64,31.83337,15.13528941,1.54337
7.68,31.99999,15.16490549,1.54639
7.72,32.16656,15.16676876,1.54658
7.76,32.33331,15.28454662,1.55859
7.8,32.50012,15.336718,1.56391
7.84,32.66668,15.22717772,1.55274
7.88,32.83324,15.24894848,1.55496
7.92,33,15.35966556,1.56625
7.96,33.16668,15.25993193,1.55608
8,33.33337,15.26944438,1.55705
8.04,33.50006,15.48715201,1.57925
8.08,33.66668,15.52275015,1.58288
8.12,33.83337,15.2802317,1.55815
8.16,34.00006,15.09782801,1.53955
8.2,34.16656,15.68495214,1.59942
8.24,34.33331,15.42988118,1.57341
8.28,34.50006,15.5349104,1.58412
8.32,34.66662,15.58610111,1.58934
8.36,34.83331,15.61522686,1.59231
8.4,34.99999,15.59884976,1.59064
8.44,35.16668,15.44272789,1.57472
8.48,35.33337,15.6724977,1.59815
8.52,35.49999,15.73859452,1.60489
8.56,35.66656,15.63827249,1.59466
8.6,35.83324,15.77762499,1.60887
8.64,35.99999,15.76487634,1.60757
8.68,36.16668,15.78674517,1.6098
8.72,36.33337,15.82626597,1.61383
8.76,36.50006,15.85941245,1.61721
8.8,36.66662,16.01386718,1.63296
8.84,36.83331,16.03799154,1.63542
8.88,37.00006,15.88628267,1.61995
8.92,37.16668,15.96542233,1.62802
8.96,37.33337,16.22833862,1.65483
9,37.49999,16.08270987,1.63998
9.04,37.66662,15.93521785,1.62494
9.08,37.83337,16.03406888,1.63502
9.12,38.00012,16.23245741,1.65525
9.16,38.16668,16.21333445,1.6533
9.2,38.33324,16.26962462,1.65904
9.24,38.5,16.2573663,1.65779
9.28,38.66668,16.3580806,1.66806
9.32,38.83343,16.34552809,1.66678
9.36,39.00012,16.37092731,1.66937
9.4,39.16662,16.45977556,1.67843
9.44,39.33324,16.50292482,1.68283
9.48,39.49999,16.45124377,1.67756
9.52,39.66668,16.39750333,1.67208
9.56,39.83337,16.46154076,1.67861
9.6,40.00005,16.42192189,1.67457
9.64,40.16655,16.5714733,1.68982
9.68,40.33331,16.62756734,1.69554
9.72,40.50006,16.85478742,1.71871
9.76,40.66668,16.65384916,1.69822
9.8,40.83337,16.76564497,1.70962
9.84,41.00006,16.63707979,1.69651
9.88,41.16655,16.96138571,1.72958
9.92,41.33324,16.74367808,1.70738
9.96,41.50006,16.79888952,1.71301
10,41.66674,16.85380676,1.71861
10.04,41.83331,16.92578757,1.72595
10.08,41.99999,16.89725022,1.72304
10.12,42.16668,16.94785253,1.7282
10.16,42.33343,17.04827263,1.73844
10.2,42.50005,17.03120906,1.7367
10.24,42.66656,17.08671469,1.74236
10.28,42.83324,17.09867881,1.74358
10.32,43.00006,17.15575351,1.7494
10.36,43.16668,17.19194005,1.75309
10.4,43.33337,17.21586827,1.75553
10.44,43.50006,17.30275519,1.76439
10.48,43.66668,17.25470261,1.75949
10.52,43.83331,17.36571389,1.77081
10.56,44.00006,17.46113259,1.78054
10.6,44.16668,17.39601644,1.7739
10.64,44.33337,17.34364892,1.76856
10.68,44.50005,17.4353411,1.77791
10.72,44.66662,17.42690738,1.77705
10.76,44.83331,17.4950636,1.784
10.8,45.00006,17.45926933,1.78035
10.84,45.16668,17.66275732,1.8011
10.88,45.3333,17.72571601,1.80752
10.92,45.49999,17.44965881,1.77937
10.96,45.66655,17.68354741,1.80322
11,45.83337,17.82770517,1.81792
11.04,46.00006,17.70982924,1.8059
11.08,46.16662,17.75866635,1.81088
11.12,46.3333,17.92204514,1.82754
11.16,46.49993,17.9242026,1.82776
11.2,46.66662,17.8279013,1.81794
11.24,46.83337,17.82652837,1.8178
11.28,47.00006,17.94107004,1.82948
11.32,47.16668,18.10013391,1.8457
11.36,47.33331,18.12710219,1.84845
11.4,47.50005,18.08414907,1.84407
11.44,47.66668,18.12602346,1.84834
11.48,47.83337,18.02972216,1.83852
11.52,48.00005,18.04806059,1.84039
11.56,48.16662,18.06747776,1.84237
11.6,48.3333,18.05188519,1.84078
11.64,48.50012,18.00491133,1.83599
11.68,48.66675,18.03197769,1.83875
11.72,48.83337,18.41728097,1.87804
11.76,48.99999,18.14573483,1.85035
11.8,49.16662,18.32137193,1.86826
11.84,49.33337,18.42502822,1.87883
11.88,49.50012,18.60988357,1.89768
11.92,49.66662,18.45062358,1.88144
11.96,49.83325,18.42689148,1.87902
12,49.99999,18.48945791,1.8854
12.04,50.16668,18.63165434,1.8999
12.08,50.33331,18.72138518,1.90905
12.12,50.50005,18.63302727,1.90004
12.16,50.66668,18.42404755,1.87873
12.2,50.83337,18.75276646,1.91225
12.24,50.99993,18.83916305,1.92106
12.28,51.16655,18.78149995,1.91518
12.32,51.33331,18.76198471,1.91319
12.36,51.50012,18.79081626,1.91613
12.4,51.66662,18.83063126,1.92019
12.44,51.83324,19.06030301,1.94361
12.48,51.99999,19.01980154,1.93948
12.52,52.16668,18.90025848,1.92729
12.56,52.33337,18.9669437,1.93409
12.6,52.50006,19.06187207,1.94377
12.64,52.66662,19.03843418,1.94138
12.68,52.83331,19.05893008,1.94347
12.72,53.00005,18.93811215,1.93115
12.76,53.16674,19.11914291,1.94961
12.8,53.33337,19.30723445,1.96879
12.84,53.49999,19.20455883,1.95832
12.88,53.66662,19.23182132,1.9611
12.92,53.8333,19.21122735,1.959
12.96,54.00012,19.3791172,1.97612
13,54.16668,19.32066956,1.97016
13.04,54.3333,19.3755868,1.97576
13.08,54.49993,19.26437939,1.96442
13.12,54.66662,19.45090188,1.98344
13.16,54.83337,19.34832432,1.97298
13.2,55.00006,19.38833545,1.97706
13.24,55.16662,19.5324932,1.99176
13.28,55.33325,19.47080938,1.98547
13.32,55.49999,19.5518123,1.99373
13.36,55.66668,19.73813865,2.01273
13.4,55.83337,19.54945871,1.99349
13.44,56.00005,19.64468128,2.0032
13.48,56.16656,19.77667879,2.01666
13.52,56.33324,19.73647152,2.01256
13.56,56.49999,19.71980022,2.01086
13.6,56.66668,19.80482387,2.01953
13.64,56.83336,19.86905743,2.02608
13.68,57.00005,19.80394128,2.01944
13.72,57.16662,19.95515982,2.03486
13.76,57.3333,19.94005758,2.03332
13.8,57.50006,20.1416823,2.05388
13.84,57.66668,20.3214382,2.07221
13.88,57.83337,20.03822214,2.04333
13.92,58.00006,19.98438364,2.03784
13.96,58.16662,20.12736459,2.05242
14,58.33324,20.1431533,2.05403
14.04,58.50011,20.17316165,2.05709
14.08,58.66674,20.22445043,2.06232
14.12,58.8333,20.42842875,2.08312
14.16,58.99993,20.32349759,2.07242
14.2,59.16668,20.39802813,2.08002
14.24,59.33343,20.42185829,2.08245
14.28,59.50006,20.39508614,2.07972
14.32,59.66655,20.48638605,2.08903
14.36,59.83324,20.46814568,2.08717
14.4,59.99999,20.6548643,2.10621
14.44,60.16668,20.66810327,2.10756
14.48,60.33343,20.65829662,2.10656
14.52,60.50006,20.66761294,2.10751
14.56,60.66662,20.52325905,2.09279
14.6,60.83325,20.71174287,2.11201
14.64,60.99999,20.6135783,2.102
14.68,61.16668,20.71743072,2.11259
14.72,61.33337,20.83216853,2.12429
14.76,61.49999,20.58710035,2.0993
14.8,61.66656,20.75959932,2.11689
14.84,61.8333,20.85776389,2.1269
14.88,62.00012,20.92631237,2.13389
14.92,62.16668,20.96789256,2.13813
14.96,62.33331,21.03251839,2.14472
15,62.49999,21.05840794,2.14736
15.04,62.66668,20.96328344,2.13766
15.08,62.83336,21.02987059,2.14445
15.12,63.00011,21.06997979,2.14854
15.16,63.16661,21.00751143,2.14217
15.2,63.3333,21.17481288,2.15923
15.24,63.49999,21.26719152,2.16865
15.28,63.66668,21.00515783,2.14193
15.32,63.83337,21.10440113,2.15205
15.36,64.00005,21.39016691,2.18119
15.4,64.16667,21.32642369,2.17469
15.44,64.33337,21.36074696,2.17819
15.48,64.50005,21.63209697,2.20586
15.52,64.66662,21.50157046,2.19255
15.56,64.83336,21.64651274,2.20733
15.6,65.00005,21.45145848,2.18744
15.64,65.16661,21.55433023,2.19793
15.68,65.3333,21.60473642,2.20307
15.72,65.50005,21.60463835,2.20306
15.76,65.66667,21.66043819,2.20875
15.8,65.8333,21.60856101,2.20346
15.84,65.99999,21.65671166,2.20837
15.88,66.16655,21.62317292,2.20495
15.92,66.33336,21.77399919,2.22033
15.96,66.50012,21.92433514,2.23566
16,66.66661,21.81626586,2.22464
16.04,66.83324,21.98425377,2.24177
16.08,66.99999,22.00474967,2.24386
16.12,67.16668,21.94218324,2.23748
16.16,67.33336,22.11938941,2.25555
16.2,67.50011,21.99317782,2.24268
16.24,67.66674,22.00229801,2.24361
16.28,67.83336,21.99288362,2.24265
16.32,67.99993,21.89628812,2.2328
16.36,68.16655,22.01681185,2.24509
16.4,68.33337,22.42986795,2.28721
16.44,68.50012,22.42300329,2.28651
16.48,68.66661,22.18931082,2.26268
16.52,68.8333,22.37691204,2.28181
16.56,69.00005,22.3969176,2.28385
16.6,69.16668,22.29120192,2.27307
16.64,69.33337,22.40956818,2.28514
16.68,69.49999,22.56608232,2.3011
16.72,69.66655,22.32689812,2.27671
16.76,69.8333,22.53607397,2.29804
16.8,70.00005,22.51322447,2.29571
16.84,70.16668,22.59148154,2.30369
16.88,70.33336,22.59030474,2.30357
16.92,70.49999,22.68827317,2.31356
16.96,70.66661,22.74426915,2.31927
17,70.8333,22.76760897,2.32165
17.04,71.00006,22.89970455,2.33512
17.08,71.16668,22.86391028,2.33147
17.12,71.33331,22.63306173,2.30793
17.16,71.49999,22.93049743,2.33826
17.2,71.66661,23.00708737,2.34607
17.24,71.83337,22.82546821,2.32755
17.28,72.00005,22.87440339,2.33254
17.32,72.16667,23.0459217,2.35003
17.36,72.3333,22.95628892,2.34089
17.4,72.50005,22.98237461,2.34355
17.44,72.66674,23.08799223,2.35432
17.48,72.83343,23.27804511,2.3737
17.52,73.00005,23.08210824,2.35372
17.56,73.16662,23.36444169,2.38251
17.6,73.3333,23.22763892,2.36856
17.64,73.50005,23.15997304,2.36166
17.68,73.66668,23.26421773,2.37229
17.72,73.83343,23.37611161,2.3837
17.76,74.00006,23.37679807,2.38377
17.8,74.16661,23.30873992,2.37683
17.84,74.3333,23.36257843,2.38232
17.88,74.50006,23.27216112,2.3731
17.92,74.66668,23.4785911,2.39415
17.96,74.83337,23.43318631,2.38952
18,74.99999,23.54782605,2.40121
18.04,75.16649,23.5974477,2.40627
18.08,75.3333,23.8322189,2.43021
18.12,75.50012,23.72630708,2.41941
18.16,75.66668,23.66305418,2.41296
18.2,75.83324,23.52840888,2.39923
18.24,75.99992,23.76435688,2.42329
18.28,76.16668,23.80358348,2.42729
18.32,76.33343,23.80985973,2.42793
18.36,76.49999,23.97490565,2.44476
18.4,76.66649,23.73317173,2.42011
18.44,76.83324,23.83692609,2.43069
18.48,77.00011,23.85879492,2.43292
18.52,77.16668,24.07493348,2.45496
18.56,77.33336,23.97284626,2.44455
18.6,77.50005,24.07248182,2.45471
18.64,77.66661,24.11553302,2.4591
18.68,77.83331,24.01373999,2.44872
18.72,78.00005,24.21595311,2.46934
18.76,78.16668,24.28499193,2.47638
18.8,78.33336,24.37521311,2.48558
18.84,78.50005,24.28979719,2.47687
18.88,78.66668,24.48014426,2.49628
18.92,78.83336,24.41414551,2.48955
18.96,79.00004,24.42071596,2.49022
19,79.16667,24.34353763,2.48235
19.04,79.3333,24.49475617,2.49777
19.08,79.49999,24.27018389,2.47487
19.12,79.66661,24.3790377,2.48597
19.16,79.83336,24.5939014,2.50788
19.2,80.00005,24.51652693,2.49999
19.24,80.16662,24.62518462,2.51107
19.28,80.3333,24.63920813,2.5125
19.32,80.49999,24.7698327,2.52582
19.36,80.66662,24.54486815,2.50288
19.4,80.83336,24.80915737,2.52983
19.44,81.00005,24.65460457,2.51407
19.48,81.16661,24.75571113,2.52438
19.52,81.3333,24.89496556,2.53858
19.56,81.49998,24.91624599,2.54075
19.6,81.66661,24.96057205,2.54527
19.64,81.83336,24.9466466,2.54385
19.68,81.99998,25.03039539,2.55239
19.72,82.16655,24.91477499,2.5406
19.76,82.33336,25.07501565,2.55694
19.8,82.50011,25.10453367,2.55995
19.84,82.66673,25.09717868,2.5592
19.88,82.83329,25.25516381,2.57531
19.92,82.99999,25.21534881,2.57125
19.96,83.16661,25.20348277,2.57004
20,83.33342,25.15778378,2.56538
20.04,83.50012,25.13807241,2.56337
20.08,83.66661,25.29272328,2.57914
20.12,83.83323,25.31733797,2.58165
20.16,83.99999,25.5944739,2.60991
20.2,84.16668,25.6372309,2.61427
20.24,84.3333,25.54867685,2.60524
20.28,84.50005,25.61869633,2.61238
20.32,84.66667,25.32547749,2.58248
20.36,84.8333,25.61173361,2.61167
20.4,84.99992,25.58976671,2.60943
20.44,85.16661,25.7150957,2.62221
20.48,85.33336,25.6375251,2.6143
20.52,85.50012,25.67302517,2.61792
20.56,85.66661,25.63713283,2.61426
20.6,85.83331,25.60280955,2.61076
20.64,86.00005,25.77109167,2.62792
20.68,86.16667,25.71499763,2.6222
20.72,86.3333,25.87886675,2.63891
20.76,86.49998,25.86356838,2.63735
20.8,86.66655,25.90112785,2.64118
20.84,86.83329,26.19346408,2.67099
20.88,87.00011,26.04999279,2.65636
20.92,87.16667,25.99487942,2.65074
20.96,87.33337,26.29202092,2.68104
21,87.49999,26.22896416,2.67461
21.04,87.66661,26.15149162,2.66671
21.08,87.83337,26.27525154,2.67933
21.12,88.00011,26.33615084,2.68554
21.16,88.16668,26.29525711,2.68137
21.2,88.3333,26.41548664,2.69363
21.24,88.49998,26.33232625,2.68515
21.28,88.66668,26.27044629,2.67884
21.32,88.83336,26.22543376,2.67425
21.36,89.00011,26.37390644,2.68939
21.4,89.16661,26.63525367,2.71604
21.44,89.33323,26.36645339,2.68863
21.48,89.49999,26.4797202,2.70018
21.52,89.66674,26.60338205,2.71279
21.56,89.83342,26.318695,2.68376
21.6,89.99999,26.60808925,2.71327
21.64,90.16655,26.76901637,2.72968
21.68,90.33323,26.62564315,2.71506
21.72,90.50005,26.85335356,2.73828
21.76,90.66667,26.84923477,2.73786
21.8,90.83336,26.83942812,2.73686
21.84,90.99999,26.83344606,2.73625
21.88,91.16654,27.0054547,2.75379
21.92,91.3333,26.92209818,2.74529
21.96,91.50005,26.8093217,2.73379
22,91.66667,27.01839948,2.75511
22.04,91.83336,27.0476233,2.75809
22.08,91.99998,27.05870481,2.75922
22.12,92.16661,27.17167742,2.77074
22.16,92.33336,27.03673792,2.75698
22.2,92.50017,27.17991501,2.77158
22.24,92.66668,27.22286813,2.77596
22.28,92.8333,27.30004647,2.78383
22.32,92.99998,27.26003534,2.77975
22.36,93.16674,27.21296342,2.77495
22.4,93.33342,27.20688329,2.77433
22.44,93.49999,27.44224289,2.79833
22.48,93.66655,27.31142218,2.78499
22.52,93.83329,27.57855533,2.81223
22.56,94.00005,27.36369163,2.79032
22.6,94.16667,27.55394064,2.80972
22.64,94.33337,27.50608419,2.80484
22.68,94.50004,27.45214761,2.79934
22.72,94.66661,27.60670042,2.8151
22.76,94.83323,27.64367149,2.81887
22.8,95.00004,27.59306917,2.81371
22.84,95.16668,27.39360191,2.79337
22.88,95.33335,27.68691881,2.82328
22.92,95.49998,27.8342147,2.8383
22.96,95.66661,27.81813179,2.83666
23,95.8333,27.77841486,2.83261
23.04,96.00011,27.84666914,2.83957
23.08,96.16661,27.8731471,2.84227
23.12,96.33323,28.00033935,2.85524
23.16,96.49992,27.86608631,2.84155
23.2,96.66667,27.89383913,2.84438
23.24,96.83336,28.10242657,2.86565
23.28,97.00011,27.97327299,2.85248
23.32,97.16661,28.04927453,2.86023
23.36,97.3333,28.27404295,2.88315
23.4,97.50005,28.36730419,2.89266
23.44,97.66674,27.97798018,2.85296
23.48,97.83336,28.29238138,2.88502
23.52,98.00005,28.27227775,2.88297
23.56,98.16667,28.51646334,2.90787
23.6,98.33336,28.25364512,2.88107
23.64,98.5001,28.29355818,2.88514
23.68,98.66667,28.34818122,2.89071
23.72,98.83337,28.58295242,2.91465
23.76,98.99999,28.38260256,2.89422
23.8,99.16661,28.51783627,2.90801
23.84,99.33336,28.70337808,2.92693
23.88,99.50011,28.62992628,2.91944
23.92,99.66668,28.76261025,2.93297
23.96,99.8333,28.71808806,2.92843
24,99.99998,28.71906872,2.92853
24.04,100.16661,28.70161289,2.92675
24.08,100.33336,28.70936014,2.92754
24.12,100.50011,28.70965434,2.92757
24.16,100.66655,28.84930104,2.94181
24.2,100.83323,28.95550706,2.95264
24.24,100.99999,28.9094158,2.94794
24.28,101.16661,28.92510644,2.94954
24.32,101.3333,28.93491309,2.95054
24.36,101.50004,29.02356521,2.95958
24.4,101.66667,29.19871198,2.97744
24.44,101.8333,29.14977679,2.97245
24.48,101.99999,29.03131246,2.96037
24.52,102.16661,29.14114694,2.97157
24.56,102.33343,29.3210009,2.98991
24.6,102.50011,29.32766942,2.99059
24.64,102.66662,29.3204125,2.98985
24.68,102.8333,29.39906184,2.99787
24.72,103.0001,29.40514196,2.99849
24.76,103.16667,29.42563786,3.00058
24.8,103.33336,29.45260614,3.00333
24.84,103.49998,29.43044312,3.00107
24.88,103.66655,29.47133685,3.00524
24.92,103.8333,29.5203701,3.01024
24.96,104.00011,29.66158586,3.02464
25,104.16668,29.69914533,3.02847
25.04,104.3333,29.52998061,3.01122
25.08,104.49998,29.6541328,3.02388
25.12,104.66661,29.82104199,3.0409
25.16,104.83329,29.64815075,3.02327
25.2,105.00005,29.78387478,3.03711
25.24,105.16667,29.60941448,3.01932
25.28,105.33324,29.98138071,3.05725
25.32,105.49999,29.8508542,3.04394
25.36,105.66667,29.88547168,3.04747
25.4,105.83336,29.95706022,3.05477
25.44,105.99999,29.80976434,3.03975
25.48,106.16655,29.94323284,3.05336
25.52,106.33323,30.12563653,3.07196
25.56,106.50005,30.02580484,3.06178
25.6,106.66673,30.00609347,3.05977
25.64,106.83335,29.9489207,3.05394
25.68,106.99999,30.40081113,3.10002
25.72,107.16654,30.30205817,3.08995
25.76,107.3333,30.18947783,3.07847
25.8,107.50011,30.08719447,3.06804
25.84,107.66674,30.4023802,3.10018
25.88,107.83336,30.37747131,3.09764
25.92,107.99998,30.50515389,3.11066
25.96,108.16661,30.43846867,3.10386
26,108.3333,30.51172434,3.11133
26.04,108.50005,30.17143359,3.07663
26.08,108.66667,30.4383706,3.10385
26.12,108.83336,30.67833933,3.12832
26.16,108.99998,30.61390964,3.12175
26.2,109.16654,30.72737258,3.13332
26.24,109.33336,30.74943754,3.13557
26.28,109.5001,30.78130915,3.13882
26.32,109.66667,30.64342765,3.12476
26.36,109.83324,31.00323364,3.16145
26.4,109.99999,30.78140722,3.13883
26.44,110.16667,30.77365997,3.13804
26.48,110.33342,30.9099724,3.15194
26.52,110.49998,30.90340195,3.15127
26.56,110.66655,31.0698208,3.16824
26.6,110.8333,31.11091066,3.17243
26.64,111.00005,31.03255553,3.16444
26.68,111.16668,31.03539945,3.16473
26.72,111.33336,31.05775862,3.16701
26.76,111.49999,31.07805838,3.16908
26.8,111.66655,31.25438195,3.18706
26.84,111.8333,31.22005867,3.18356
26.88,112.00011,31.26065821,3.1877
26.92,112.16674,31.28850909,3.19054
26.96,112.3333,31.20015117,3.18153
27,112.50004,31.17298675,3.17876
27.04,112.66667,31.43374558,3.20535
27.08,112.83342,31.50886452,3.21301
27.12,113.00012,31.4971946,3.21182
27.16,113.16661,31.5387748,3.21606
27.2,113.33324,31.76187609,3.23881
27.24,113.49998,31.55770163,3.21799
27.28,113.66667,31.66998778,3.22944
27.32,113.83336,31.62419072,3.22477
27.36,114.00005,31.73794786,3.23637
27.4,114.16661,31.64017556,3.2264
27.44,114.33329,31.76226835,3.23885
27.48,114.50005,31.77462473,3.24011
27.52,114.66661,31.79502256,3.24219
27.56,114.8333,31.73127934,3.23569
27.6,115.00005,31.87631969,3.25048
27.64,115.16668,31.94359331,3.25734
27.68,115.3333,31.77825319,3.24048
27.72,115.49998,32.15257302,3.27865
27.76,115.66667,32.01802578,3.26493
27.8,115.83329,31.96222595,3.25924
27.84,115.99999,32.10128424,3.27342
27.88,116.16655,32.22779003,3.28632
27.92,116.33329,32.18238524,3.28169
27.96,116.50004,32.33370185,3.29712
28,116.66667,32.27545035,3.29118
28.04,116.8333,32.10628563,3.27393
28.08,116.99999,32.27750974,3.29139
28.12,117.16668,32.18120844,3.28157
28.16,117.33342,32.32575846,3.29631
28.2,117.50011,32.41215505,3.30512
28.24,117.66654,32.31742281,3.29546
28.28,117.83324,32.42892442,3.30683
28.32,118.00005,32.51845913,3.31596
28.36,118.16667,32.33791871,3.29755
28.4,118.33336,32.39666054,3.30354
28.44,118.50011,32.41676417,3.30559
28.48,118.66667,32.48374359,3.31242
28.52,118.8333,32.52434312,3.31656
28.56,118.99993,32.80824564,3.34551
28.6,119.16667,32.45304878,3.30929
28.64,119.33336,32.55346887,3.31953
28.68,119.50005,32.58671342,3.32292
28.72,119.66655,32.4225501,3.30618
28.76,119.83329,32.634766,3.32782
28.8,120.00005,32.61191651,3.32549
28.84,120.16667,32.69723436,3.33419
28.88,120.33329,32.49678644,3.31375
28.92,120.49999,32.66967768,3.33138
28.96,120.66661,32.559549,3.32015
29,120.83329,32.32958306,3.2967
29.04,121.00005,32.0668629,3.26991
29.08,121.16667,26.41264271,2.69334
29.12,121.3333,-0.503277278,-0.05132
29.16,121.49998,-1.85767371,-0.18943
29.2,121.6666,-1.05745107,-0.10783
29.24,121.83336,-1.158361498,-0.11812
29.28,122.00011,-1.09049948,-0.1112
29.32,122.16668,-0.873184116,-0.08904
29.36,122.3333,-0.88093137,-0.08983
29.4,122.50005,-1.347041444,-0.13736
29.44,122.66668,-1.244561952,-0.12691
29.48,122.83336,-1.123351758,-0.11455
29.52,123.00004,-1.098050601,-0.11197
29.56,123.16661,-1.096971869,-0.11186
29.6,123.3333,-1.065198323,-0.10862
29.64,123.50004,-1.157969232,-0.11808
29.68,123.66674,-1.071082313,-0.10922
29.72,123.83336,-1.077260503,-0.10985
29.76,123.99998,-1.15130071,-0.1174
29.8,124.16654,-1.195430635,-0.1219
29.84,124.3333,-1.276923897,-0.13021
29.88,124.50005,-1.068630651,-0.10897
29.92,124.66667,-1.162186092,-0.11851
29.96,124.83336,-1.177386399,-0.12006
30,124.99998,-1.18886018,-0.12123
30.04,125.1666,-1.063825392,-0.10848
30.08,125.33329,-0.826798662,-0.08431
30.12,125.50004,-1.050978681,-0.10717
30.16,125.66666,-1.12217496,-0.11443
30.2,125.83335,-1.059804666,-0.10807
30.24,125.99992,-1.050684481,-0.10714
30.28,126.16654,-1.154929171,-0.11777
30.32,126.33341,-1.22416412,-0.12483
30.36,126.5001,-1.160518961,-0.11834
30.4,126.6666,-1.006946822,-0.10268
30.44,126.83324,-1.226811915,-0.1251
30.48,127.00004,-1.222791189,-0.12469
30.52,127.1668,-1.018910935,-0.1039
30.56,127.33336,-0.982332131,-0.10017
30.6,127.49991,-1.285063416,-0.13104
30.64,127.66654,-1.256329932,-0.12811
30.68,127.83336,-1.139238531,-0.11617
30.72,128.0001,-0.943203597,-0.09618
30.76,128.16672,-1.075691439,-0.10969
30.8,128.33335,-1.199451362,-0.12231
30.84,128.49999,-1.130314479,-0.11526
30.88,128.66661,-1.188664047,-0.12121
30.92,128.83335,-1.296242997,-0.13218
30.96,129.00004,-1.031463447,-0.10518
31,129.16661,-1.160126695,-0.1183
31.04,129.33329,-1.077946968,-0.10992
31.08,129.49998,-0.922217366,-0.09404
31.12,129.6666,-1.090695613,-0.11122
31.16,129.83336,-1.154242705,-0.1177
31.2,130.00004,-1.208081214,-0.12319
31.24,130.16661,-1.052645811,-0.10734
31.28,130.3333,-1.150712311,-0.11734
31.32,130.49997,-1.020087733,-0.10402
31.36,130.66666,-0.882108168,-0.08995
31.4,130.83336,-0.89466068,-0.09123
31.44,131.00005,-1.076868237,-0.10981
31.48,131.16661,-1.037641637,-0.10581
31.52,131.33324,-1.017243805,-0.10373
31.56,131.49998,-0.953990912,-0.09728
31.564,131.51667,-0.936437009,-0.09549