File: NR/NR/RDSO NR Tensile 250.is_tens_RawData/Specimen_RawData_5.csv
Time,Extension,Load,
(sec),(mm),(N),(kgf)
0,0,-0.978507537,-0.09978
0.04,0.06762,-0.587516402,-0.05991
0.08,0.27756,-0.072373077,-0.00738
0.12,0.48287,-0.173969971,-0.01774
0.16,0.65537,0.378144424,0.03856
0.2,0.82406,0.936927341,0.09554
0.24,0.99475,1.104719123,0.11265
0.28,1.16387,1.294673933,0.13202
0.32,1.33169,1.757842013,0.17925
0.36,1.499,1.971528916,0.20104
0.4,1.666,2.196395401,0.22397
0.44,1.83287,2.414887563,0.24625
0.48,1.99981,2.741252875,0.27953
0.52,2.16662,2.978083472,0.30368
0.56,2.33337,3.32082589,0.33863
0.6,2.5,3.561677214,0.36319
0.64,2.66656,3.596392755,0.36673
0.68,2.83331,3.745257702,0.38191
0.72,3.00006,4.147820684,0.42296
0.76,3.16669,4.457318558,0.45452
0.8,3.33331,4.630896263,0.47222
0.84,3.5,4.652765093,0.47445
0.88,3.66656,4.916073645,0.5013
0.92,3.83337,5.12132683,0.52223
0.96,4.00012,5.2370453,0.53403
1,4.16669,5.592340229,0.57026
1.04,4.33325,5.849176393,0.59645
1.08,4.5,5.766800533,0.58805
1.12,4.66662,6.316267132,0.64408
1.16,4.83344,6.360985456,0.64864
1.2,5.00012,6.296359633,0.64205
1.24,5.16662,6.816308216,0.69507
1.28,5.33325,6.723831506,0.68564
1.32,5.5,6.829547193,0.69642
1.36,5.66669,7.04931422,0.71883
1.4,5.83337,7.290852009,0.74346
1.44,6.00006,7.347338313,0.74922
1.48,6.16662,7.449621673,0.75965
1.52,6.33331,7.818253646,0.79724
1.56,6.5,7.848458128,0.80032
1.6,6.66662,7.970943187,0.81281
1.64,6.83337,8.077345339,0.82366
1.68,7.00012,8.164232258,0.83252
1.72,7.16662,8.365856982,0.85308
1.76,7.33325,8.508053407,0.86758
1.8,7.5,8.433719,0.86
1.84,7.66675,8.818531946,0.89924
1.88,7.83337,8.925914764,0.91019
1.92,8,9.089783885,0.9269
1.96,8.16656,9.039377704,0.92176
2,8.33344,9.03976997,0.9218
2.04,8.50012,9.206581087,0.93881
2.08,8.66656,9.266793918,0.94495
2.12,8.83319,9.206188821,0.93877
2.16,9,9.421935121,0.96077
2.2,9.16669,9.652195263,0.98425
2.24,9.33337,9.847445664,1.00416
2.28,9.50012,9.768109866,0.99607
2.32,9.66662,9.960516339,1.01569
2.36,9.83331,10.04995299,1.02481
2.4,10,10.08976799,1.02887
2.44,10.16669,9.941491438,1.01375
2.48,10.33337,10.26981808,1.04723
2.52,10.5,10.42966647,1.06353
2.56,10.66656,10.393578,1.05985
2.6,10.83325,10.3971084,1.06021
2.64,11.00006,10.52743878,1.0735
2.68,11.16669,10.53361696,1.07413
2.72,11.33337,10.69248469,1.09033
2.76,11.5,10.8485085,1.10624
2.8,11.66656,10.80506504,1.10181
2.84,11.83337,11.02826439,1.12457
2.88,12.00012,11.1623213,1.13824
2.92,12.16669,11.11760297,1.13368
2.96,12.33331,11.07984737,1.12983
3,12.5,11.2574458,1.14794
3.04,12.66669,11.33099568,1.15544
3.08,12.83337,11.46828878,1.16944
3.12,13.00006,11.31344177,1.15365
3.16,13.16662,11.4164116,1.16415
3.2,13.33331,11.27607844,1.14984
3.24,13.50006,11.3546297,1.15785
3.28,13.66668,11.48084129,1.17072
3.32,13.83337,11.59283323,1.18214
3.36,14.00012,11.63813995,1.18676
3.4,14.16662,11.72208488,1.19532
3.44,14.33331,11.74169818,1.19732
3.48,14.50006,11.86555617,1.20995
3.52,14.66669,11.83280196,1.20661
3.56,14.83337,11.92233667,1.21574
3.6,15.00006,11.91439328,1.21493
3.64,15.16656,12.18123223,1.24214
3.68,15.33331,12.09601244,1.23345
3.72,15.50012,11.90233111,1.2137
3.76,15.66675,11.96362267,1.21995
3.8,15.83331,12.26929595,1.25112
3.84,16,12.25488017,1.24965
3.88,16.16662,12.1221962,1.23612
3.92,16.33337,12.3745213,1.26185
3.96,16.50006,12.46827288,1.27141
4,16.66668,12.28773245,1.253
4.04,16.83337,12.15328328,1.23929
4.08,17,12.40786391,1.26525
4.12,17.16656,12.30283469,1.25454
4.16,17.33331,12.55604239,1.28036
4.2,17.50012,12.39864566,1.26431
4.24,17.66669,12.26782495,1.25097
4.28,17.83331,12.7691409,1.30209
4.32,18,12.70196535,1.29524
4.36,18.16669,12.68382304,1.29339
4.4,18.33337,12.84416177,1.30974
4.44,18.50006,12.66479814,1.29145
4.48,18.66662,12.85318389,1.31066
4.52,18.83331,12.76531631,1.3017
4.56,19.00006,12.81209403,1.30647
4.6,19.16668,12.87936764,1.31333
4.64,19.33337,12.9822394,1.32382
4.68,19.5,12.89868675,1.3153
4.72,19.66662,12.94673933,1.3202
4.76,19.83331,13.05931967,1.33168
4.8,20.00006,12.97713995,1.3233
4.84,20.16668,12.89819641,1.31525
4.88,20.33337,13.03313592,1.32901
4.92,20.5,13.29007015,1.35521
4.96,20.66662,13.06647853,1.33241
5,20.83331,13.16277983,1.34223
5.04,21.00006,13.15248285,1.34118
5.08,21.16662,13.16984062,1.34295
5.12,21.33325,13.16209336,1.34216
5.16,21.5,13.26859358,1.35302
5.2,21.66662,13.51954576,1.37861
5.24,21.83337,13.5501425,1.38173
5.28,22.00012,13.39392257,1.3658
5.32,22.16662,13.51062171,1.3777
5.36,22.33325,13.42314639,1.36878
5.4,22.5,13.26790712,1.35295
5.44,22.66668,13.51307337,1.37795
5.48,22.83337,13.60751141,1.38758
5.52,23.00006,13.61967165,1.38882
5.56,23.16662,13.373917,1.36376
5.6,23.33325,13.50895457,1.37753
5.64,23.5,13.54259138,1.38096
5.68,23.66669,13.69145633,1.39614
5.72,23.83337,13.66223251,1.39316
5.76,24.00006,13.47512163,1.37408
5.8,24.16662,13.67174496,1.39413
5.84,24.33325,13.92858113,1.42032
5.88,24.50006,13.93603418,1.42108
5.92,24.66675,13.96506187,1.42404
5.96,24.83337,13.77353799,1.40451
6,24.99993,13.82443451,1.4097
6.04,25.16662,14.08038807,1.4358
6.08,25.33343,14.03723881,1.4314
6.12,25.50012,13.93936844,1.42142
6.16,25.66656,14.10686603,1.4385
6.2,25.83318,14.13030392,1.44089
6.24,26,13.87925368,1.41529
6.28,26.16668,14.06852202,1.43459
6.32,26.33337,14.00458267,1.42807
6.36,26.50006,14.05361592,1.43307
6.4,26.66662,14.13167685,1.44103
6.44,26.83331,14.12020307,1.43986
6.48,27.00006,14.27475587,1.45562
6.52,27.16668,14.21209138,1.44923
6.56,27.33337,14.20463833,1.44847
6.6,27.5,14.2811302,1.45627
6.64,27.66662,14.43901726,1.47237
6.68,27.83331,14.33889136,1.46216
6.72,28.00006,14.44980458,1.47347
6.76,28.16668,14.39027821,1.4674
6.8,28.33331,14.63730772,1.49259
6.84,28.5,14.54649814,1.48333
6.88,28.66662,14.3976332,1.46815
6.92,28.83337,14.53796636,1.48246
6.96,29.00012,14.55120534,1.48381
7,29.16669,14.74959387,1.50404
7.04,29.33337,14.87011759,1.51633
7.08,29.5,14.69075397,1.49804
7.12,29.66662,14.60318058,1.48911
7.16,29.83337,14.63593479,1.49245
7.2,30.00006,14.89296709,1.51866
7.24,30.16668,14.87737452,1.51707
7.28,30.33331,14.88345464,1.51769
7.32,30.50006,14.80617824,1.50981
7.36,30.66662,14.83618659,1.51287
7.4,30.83337,14.93160529,1.5226
7.44,31.00006,14.94288294,1.52375
7.48,31.16662,15.0229052,1.53191
7.52,31.33325,14.9432752,1.52379
7.56,31.50006,15.12342336,1.54216
7.6,31.66674,15.05987627,1.53568
7.64,31.83337,15.06664286,1.53637
7.68,31.99999,15.08635423,1.53838
7.72,32.16656,15.09880867,1.53965
7.76,32.33331,15.15745244,1.54563
7.8,32.50012,15.19079505,1.54903
7.84,32.66668,15.28415436,1.55855
7.88,32.83324,15.19530611,1.54949
7.92,33,15.221686,1.55218
7.96,33.16668,15.23619984,1.55366
8,33.33337,15.4731285,1.57782
8.04,33.50006,15.4344903,1.57388
8.08,33.66668,15.3940869,1.56976
8.12,33.83337,15.44361049,1.57481
8.16,34.00006,15.44655248,1.57511
8.2,34.16656,15.45076934,1.57554
8.24,34.33331,15.55138557,1.5858
8.28,34.50006,15.77027,1.60812
8.32,34.66662,15.66563304,1.59745
8.36,34.83331,15.67573389,1.59848
8.4,34.99999,15.60826414,1.5916
8.44,35.16668,15.71005717,1.60198
8.48,35.33337,15.77164293,1.60826
8.52,35.49999,15.6502366,1.59588
8.56,35.66656,15.77291779,1.60839
8.6,35.83324,15.80616234,1.61178
8.64,35.99999,15.82185298,1.61338
8.68,36.16668,16.04269874,1.6359
8.72,36.33337,15.86500224,1.61778
8.76,36.50006,15.86676743,1.61796
8.8,36.66656,16.07741428,1.63944
8.84,36.83331,16.14419756,1.64625
8.88,37.00006,16.09908697,1.64165
8.92,37.16668,15.98709503,1.63023
8.96,37.33337,16.05132859,1.63678
9,37.49999,16.12527073,1.64432
9.04,37.66662,16.20676399,1.65263
9.08,37.83337,16.26697682,1.65877
9.12,38.00012,16.03956061,1.63558
9.16,38.16668,16.1988206,1.65182
9.2,38.33324,16.11968094,1.64375
9.24,38.5,16.14733569,1.64657
9.28,38.66668,16.32709159,1.6649
9.32,38.83343,16.4365338,1.67606
9.36,39.00012,16.43084594,1.67548
9.4,39.16656,16.42947301,1.67534
9.44,39.33324,16.55950919,1.6886
9.48,39.49999,16.48340959,1.68084
9.52,39.66668,16.46330595,1.67879
9.56,39.83337,16.52861824,1.68545
9.6,40.00005,16.56352992,1.68901
9.64,40.16655,16.43663187,1.67607
9.68,40.33331,16.47850626,1.68034
9.72,40.50006,16.74877754,1.7079
9.76,40.66668,16.73436176,1.70643
9.8,40.83337,16.91754998,1.72511
9.84,41.00006,16.7295565,1.70594
9.88,41.16655,16.68385751,1.70128
9.92,41.33324,16.70013655,1.70294
9.96,41.50006,16.69866555,1.70279
10,41.66674,16.81722795,1.71488
10.04,41.83331,17.14329906,1.74813
10.08,41.99999,16.86027915,1.71927
10.12,42.16668,16.9634451,1.72979
10.16,42.33343,16.78270854,1.71136
10.2,42.50005,17.0644536,1.74009
10.24,42.66656,17.11515398,1.74526
10.28,42.83324,17.23450091,1.75743
10.32,42.99999,17.12643163,1.74641
10.36,43.16668,17.26902032,1.76095
10.4,43.33337,17.21763347,1.75571
10.44,43.50012,17.1841928,1.7523
10.48,43.66668,17.32383949,1.76654
10.52,43.83331,17.23479511,1.75746
10.56,44.00006,17.54625431,1.78922
10.6,44.16668,17.46005386,1.78043
10.64,44.33337,17.60627101,1.79534
10.68,44.50005,17.42092533,1.77644
10.72,44.66656,17.47152764,1.7816
10.76,44.83331,17.54713691,1.78931
10.8,45.00006,17.52811201,1.78737
10.84,45.16668,17.6689355,1.80173
10.88,45.3333,17.70335685,1.80524
10.92,45.49999,17.57871432,1.79253
10.96,45.66655,17.69011787,1.80389
11,45.83337,17.65442166,1.80025
11.04,46.00012,17.73179613,1.80814
11.08,46.16662,17.69923805,1.80482
11.12,46.3333,17.75945088,1.81096
11.16,46.49993,17.88164174,1.82342
11.2,46.66662,17.87330609,1.82257
11.24,46.83337,17.95891815,1.8313
11.28,47.00006,17.93557832,1.82892
11.32,47.16668,17.9054719,1.82585
11.36,47.33337,17.99667375,1.83515
11.4,47.50005,17.89968598,1.82526
11.44,47.66668,17.96715573,1.83214
11.48,47.83337,18.12582733,1.84832
11.52,48.00005,18.16034674,1.85184
11.56,48.16662,17.97245132,1.83268
11.6,48.3333,18.14485223,1.85026
11.64,48.50012,18.27910527,1.86395
11.68,48.66675,18.26959282,1.86298
11.72,48.8333,18.3375529,1.86991
11.76,48.99999,18.33941617,1.8701
11.8,49.16662,18.26390496,1.8624
11.84,49.33337,18.68215858,1.90505
11.88,49.50012,18.53594143,1.89014
11.92,49.66668,18.49583223,1.88605
11.96,49.83325,18.47710153,1.88414
12,49.99999,18.4757286,1.884
12.04,50.16668,18.48063193,1.8845
12.08,50.33331,18.41708483,1.87802
12.12,50.50005,18.46886395,1.8833
12.16,50.66668,18.56408652,1.89301
12.2,50.83337,18.59782139,1.89645
12.24,50.99999,18.80503591,1.91758
12.28,51.16655,18.82337434,1.91945
12.32,51.33331,18.78375548,1.91541
12.36,51.50012,18.70314481,1.90719
12.4,51.66662,19.02921593,1.94044
12.44,51.83324,19.09443015,1.94709
12.48,51.99999,19.0840351,1.94603
12.52,52.16668,19.12953796,1.95067
12.56,52.33343,19.11718158,1.94941
12.6,52.50006,19.15748691,1.95352
12.64,52.66662,19.05471322,1.94304
12.68,52.83331,19.11649511,1.94934
12.72,53.00005,19.27006725,1.965
12.76,53.16674,19.20652016,1.95852
12.8,53.33337,19.05314415,1.94288
12.84,53.49999,19.17435435,1.95524
12.88,53.66662,19.12953796,1.95067
12.92,53.8333,19.3413616,1.97227
12.96,54.00012,19.44717535,1.98306
13,54.16668,19.40441836,1.9787
13.04,54.3333,19.48071409,1.98648
13.08,54.49993,19.42785625,1.98109
13.12,54.66662,19.40029956,1.97828
13.16,54.83337,19.495326,1.98797
13.2,55.00006,19.56613001,1.99519
13.24,55.16662,19.55063551,1.99361
13.28,55.33325,19.40245703,1.9785
13.32,55.49999,19.71156263,2.01002
13.36,55.66668,19.66802111,2.00558
13.4,55.83337,19.78266085,2.01727
13.44,56.00005,19.73460826,2.01237
13.48,56.16656,19.62948097,2.00165
13.52,56.33324,19.58427232,1.99704
13.56,56.49999,19.73343146,2.01225
13.6,56.66668,19.847777,2.02391
13.64,56.83336,20.03537822,2.04304
13.68,57.00005,19.92240561,2.03152
13.72,57.16662,19.96830073,2.0362
13.76,57.3333,19.89877158,2.02911
13.8,57.50006,19.76804894,2.01578
13.84,57.66668,19.91818875,2.03109
13.88,57.83337,20.03920281,2.04343
13.92,58.00006,20.23209962,2.0631
13.96,58.16655,20.08823606,2.04843
14,58.33324,20.0831366,2.04791
14.04,58.50011,20.17276938,2.05705
14.08,58.66674,20.15168509,2.0549
14.12,58.8333,20.12108834,2.05178
14.16,58.99993,20.17924177,2.05771
14.2,59.16668,20.40930578,2.08117
14.24,59.33343,20.22297943,2.06217
14.28,59.50006,20.28603619,2.0686
14.32,59.66655,20.47442194,2.08781
14.36,59.83324,20.40685412,2.08092
14.4,60.00006,20.48118853,2.0885
14.44,60.16668,20.43029201,2.08331
14.48,60.33343,20.54914861,2.09543
14.52,60.50006,20.68085192,2.10886
14.56,60.66662,20.74430094,2.11533
14.6,60.83325,20.84609397,2.12571
14.64,60.99999,20.55287514,2.09581
14.68,61.16668,20.89718662,2.13092
14.72,61.33337,20.72154952,2.11301
14.76,61.49999,20.87796558,2.12896
14.8,61.66662,20.65623723,2.10635
14.84,61.8333,21.00084291,2.14149
14.88,62.00012,20.74900814,2.11581
14.92,62.16668,20.79862979,2.12087
14.96,62.33331,21.01761228,2.1432
15,62.49999,21.16078937,2.1578
15.04,62.66668,21.09910554,2.15151
15.08,62.83336,21.04016758,2.1455
15.12,63.00011,21.23443731,2.16531
15.16,63.16661,20.95838011,2.13716
15.2,63.3333,21.19756431,2.16155
15.24,63.49999,21.23512378,2.16538
15.28,63.66668,21.26670119,2.1686
15.32,63.83337,21.11567878,2.1532
15.36,64.00005,21.36604255,2.17873
15.4,64.16667,21.32250103,2.17429
15.44,64.33337,21.37339754,2.17948
15.48,64.50005,21.42262693,2.1845
15.52,64.66662,21.458127,2.18812
15.56,64.83336,21.41693907,2.18392
15.6,65.00005,21.61885799,2.20451
15.64,65.16661,21.5561935,2.19812
15.68,65.3333,21.35084225,2.17718
15.72,65.50005,21.63847129,2.20651
15.76,65.66667,21.68436641,2.21119
15.8,65.8333,21.70515651,2.21331
15.84,65.99993,21.74810964,2.21769
15.88,66.16655,21.65141607,2.20783
15.92,66.33336,21.8679469,2.22991
15.96,66.50012,21.88000908,2.23114
16,66.66661,21.80861667,2.22386
16.04,66.83324,21.83362363,2.22641
16.08,66.99999,21.90099531,2.23328
16.12,67.16668,21.85627699,2.22872
16.16,67.33336,22.00592647,2.24398
16.2,67.50011,21.84009602,2.22707
16.24,67.66674,22.01455632,2.24486
16.28,67.83336,22.05917658,2.24941
16.32,67.99993,22.1018355,2.25376
16.36,68.16655,21.99288362,2.24265
16.4,68.33337,22.31630694,2.27563
16.44,68.50012,22.4572285,2.29
16.48,68.66667,22.29502651,2.27346
16.52,68.8333,22.3957408,2.28373
16.56,69.00005,22.39270074,2.28342
16.6,69.16668,22.25452504,2.26933
16.64,69.33337,22.3618098,2.28027
16.68,69.49999,22.43663454,2.2879
16.72,69.66655,22.50792888,2.29517
16.76,69.8333,22.51763746,2.29616
16.8,70.00005,22.44418566,2.28867
16.84,70.16668,22.48164706,2.29249
16.88,70.3333,22.59726746,2.30428
16.92,70.49999,22.34180423,2.27823
16.96,70.66661,22.48733492,2.29307
17,70.8333,22.74603434,2.31945
17.04,71.00006,22.66189329,2.31087
17.08,71.16661,22.82507594,2.32751
17.12,71.33331,22.85292683,2.33035
17.16,71.49999,22.87450146,2.33255
17.2,71.66661,22.86096828,2.33117
17.24,71.83337,22.74495561,2.31934
17.28,72.00012,22.80389358,2.32535
17.32,72.16662,22.83154833,2.32817
17.36,72.3333,22.9882586,2.34415
17.4,72.50005,22.91264933,2.33644
17.44,72.66674,22.93265489,2.33848
17.48,72.83343,22.8500829,2.33006
17.52,73.00005,22.96178064,2.34145
17.56,73.16662,23.06504467,2.35198
17.6,73.3333,23.10750746,2.35631
17.64,73.50005,23.03405565,2.34882
17.68,73.66668,23.28236003,2.37414
17.72,73.83343,23.28343876,2.37425
17.76,74.00006,23.38356466,2.38446
17.8,74.16661,23.2215588,2.36794
17.84,74.3333,23.50987431,2.39734
17.88,74.50006,23.21518448,2.36729
17.92,74.66668,23.52419202,2.3988
17.96,74.83337,23.52919341,2.39931
18,74.99999,23.55066998,2.4015
18.04,75.16649,23.46643085,2.39291
18.08,75.3333,23.72885681,2.41967
18.12,75.50012,23.60019356,2.40655
18.16,75.66668,23.60117422,2.40665
18.2,75.83324,23.89507952,2.43662
18.24,75.99992,23.52497655,2.39888
18.28,76.16668,23.80642741,2.42758
18.32,76.33343,23.848596,2.43188
18.36,76.49999,23.79514976,2.42643
18.4,76.66649,23.78877544,2.42578
18.44,76.83324,23.93175639,2.44036
18.48,77.00005,24.10131337,2.45765
18.52,77.16668,23.97755345,2.44503
18.56,77.33336,23.84300621,2.43131
18.6,77.50005,23.92126328,2.43929
18.64,77.66661,23.99481315,2.44679
18.68,77.83331,24.15103309,2.46272
18.72,78.00005,23.93675779,2.44087
18.76,78.16668,24.26694769,2.47454
18.8,78.33336,24.25871011,2.4737
18.84,78.50005,24.26488829,2.47433
18.88,78.66668,24.06993209,2.45445
18.92,78.83336,24.35873794,2.4839
18.96,79.00012,24.41139965,2.48927
19,79.16667,24.35373654,2.48339
19.04,79.3333,24.38148936,2.48622
19.08,79.49999,24.39227668,2.48732
19.12,79.66661,24.34442023,2.48244
19.16,79.83336,24.50927001,2.49925
19.2,80.00005,24.59527433,2.50802
19.24,80.16662,24.50564155,2.49888
19.28,80.3333,24.37472277,2.48553
19.32,80.49999,24.67657146,2.51631
19.36,80.66662,24.72462405,2.52121
19.4,80.83336,24.5148598,2.49982
19.44,81.00005,24.54065129,2.50245
19.48,81.16661,24.78012969,2.52687
19.52,81.3333,24.85838675,2.53485
19.56,81.49998,24.89800562,2.53889
19.6,81.66661,24.81876789,2.53081
19.64,81.83336,24.79797779,2.52869
19.68,82.00006,24.85446409,2.53445
19.72,82.16661,24.83269333,2.53223
19.76,82.33336,24.89320036,2.5384
19.8,82.50011,24.81455103,2.53038
19.84,82.66673,25.14268154,2.56384
19.88,82.83329,25.0675626,2.55618
19.92,82.99999,25.19593165,2.56927
19.96,83.16661,25.19504905,2.56918
20,83.33342,25.13611108,2.56317
20.04,83.50012,25.26359753,2.57617
20.08,83.66661,25.25006435,2.57479
20.12,83.83323,25.20760156,2.57046
20.16,83.99999,25.49209248,2.59947
20.2,84.16668,25.23662924,2.57342
20.24,84.33335,25.47689217,2.59792
20.28,84.50005,25.36038917,2.58604
20.32,84.66667,25.41001082,2.5911
20.36,84.8333,25.32057417,2.58198
20.4,84.99992,25.61693113,2.6122
20.44,85.16661,25.61575433,2.61208
20.48,85.33336,25.70980011,2.62167
20.52,85.50005,25.80865114,2.63175
20.56,85.66661,25.56113129,2.60651
20.6,85.83331,25.68842161,2.61949
20.64,86.00005,25.56387715,2.60679
20.68,86.16667,25.77609306,2.62843
20.72,86.3333,25.81384866,2.63228
20.76,86.49998,25.80306135,2.63118
20.8,86.66655,25.99703688,2.65096
20.84,86.83329,26.01459079,2.65275
20.88,87.00011,25.89543999,2.6406
20.92,87.16667,25.90122591,2.64119
20.96,87.33337,25.9082867,2.64191
21,87.49999,26.06009364,2.65739
21.04,87.66661,26.23278875,2.675
21.08,87.8333,26.02469164,2.65378
21.12,88.00011,26.07705915,2.65912
21.16,88.16668,25.99213356,2.65046
21.2,88.3333,26.05391545,2.65676
21.24,88.49998,26.23121969,2.67484
21.28,88.66668,26.29231512,2.68107
21.32,88.83336,26.27897807,2.67971
21.36,89.00005,26.40352253,2.69241
21.4,89.16661,26.46628509,2.69881
21.44,89.33323,26.56131153,2.7085
21.48,89.49999,26.50757108,2.70302
21.52,89.66668,26.47422847,2.69962
21.56,89.83342,26.74047902,2.72677
21.6,89.99999,26.50355036,2.70261
21.64,90.16655,26.82305101,2.73519
21.68,90.33323,26.69242644,2.72187
21.72,90.50005,26.56140959,2.70851
21.76,90.66667,26.69262257,2.72189
21.8,90.83336,26.71870826,2.72455
21.84,90.99999,26.7118436,2.72385
21.88,91.16654,26.6559457,2.71815
21.92,91.3333,26.82913114,2.73581
21.96,91.50005,26.80677197,2.73353
22,91.66667,26.95955958,2.74911
22.04,91.83336,27.00074751,2.75331
22.08,92.00005,26.87100553,2.74008
22.12,92.16661,27.11921184,2.76539
22.16,92.33336,27.16030171,2.76958
22.2,92.50017,27.1269591,2.76618
22.24,92.66668,27.00506244,2.75375
22.28,92.8333,27.24120657,2.77783
22.32,92.99998,27.42292379,2.79636
22.36,93.16674,27.17795368,2.77138
22.4,93.33342,27.00241464,2.75348
22.44,93.49999,27.15686938,2.76923
22.48,93.66655,27.65857759,2.82039
22.52,93.83329,27.39840717,2.79386
22.56,94.00005,27.39575937,2.79359
22.6,94.16667,27.34280346,2.78819
22.64,94.33337,27.55570584,2.8099
22.68,94.50004,27.37006595,2.79097
22.72,94.66661,27.45508961,2.79964
22.76,94.83323,27.61081921,2.81552
22.8,95.00004,27.49225681,2.80343
22.84,95.16668,27.56904288,2.81126
22.88,95.33335,27.86118298,2.84105
22.92,95.49998,27.64563282,2.81907
22.96,95.66661,27.55707877,2.81004
23,95.8333,27.58502772,2.81289
23.04,96.00011,27.88177695,2.84315
23.08,96.16661,27.6158206,2.81603
23.12,96.33323,28.0268173,2.85794
23.16,96.49992,28.10399564,2.86581
23.2,96.66661,28.04103694,2.85939
23.24,96.83336,28.07732155,2.86309
23.28,97.00011,28.20470993,2.87608
23.32,97.16661,28.10056331,2.86546
23.36,97.3333,28.03652588,2.85893
23.4,97.50005,28.0874224,2.86412
23.44,97.66674,28.03044576,2.85831
23.48,97.83336,28.06221931,2.86155
23.52,98.00005,28.3631854,2.89224
23.56,98.16667,28.37642437,2.89359
23.6,98.33336,28.39417441,2.8954
23.64,98.5001,28.30601263,2.88641
23.68,98.66667,28.43212615,2.89927
23.72,98.83337,28.30267837,2.88607
23.76,98.99999,28.35681107,2.89159
23.8,99.16661,28.40809985,2.89682
23.84,99.33336,28.41565097,2.89759
23.88,99.50011,28.57236124,2.91357
23.92,99.66668,28.87332733,2.94426
23.96,99.8333,28.75868759,2.93257
24,99.99998,28.62708235,2.91915
24.04,100.16661,28.82998194,2.93984
24.08,100.33336,28.49979203,2.90617
24.12,100.50011,28.62796495,2.91924
24.16,100.66655,28.81595843,2.93841
24.2,100.83323,28.82184242,2.93901
24.24,100.99999,28.86479554,2.94339
24.28,101.16661,28.91549592,2.94856
24.32,101.3333,28.93765895,2.95082
24.36,101.50004,28.92422384,2.94945
24.4,101.66667,29.01503342,2.95871
24.44,101.8333,28.79997359,2.93678
24.48,101.99999,28.9899284,2.95615
24.52,102.16661,29.08907363,2.96626
24.56,102.33336,29.1831194,2.97585
24.6,102.50011,29.26627979,2.98433
24.64,102.66667,29.03533319,2.96078
24.68,102.8333,29.26265133,2.98396
24.72,103.0001,29.32178543,2.98999
24.76,103.16674,29.14977679,2.97245
24.8,103.33336,29.31295945,2.98909
24.84,103.49998,29.27667484,2.98539
24.88,103.66655,29.42308813,3.00032
24.92,103.8333,29.61598493,3.01999
24.96,104.00011,29.3204125,2.98985
25,104.16668,29.61284681,3.01967
25.04,104.3333,29.65550573,3.02402
25.08,104.49998,29.60009816,3.01837
25.12,104.66655,29.61137581,3.01952
25.16,104.83336,29.67178477,3.02568
25.2,105.00005,29.60215756,3.01858
25.24,105.16667,29.80799914,3.03957
25.28,105.33324,29.86693711,3.04558
25.32,105.49999,30.04855627,3.0641
25.36,105.66667,29.99981721,3.05913
25.4,105.83336,29.8737037,3.04627
25.44,106.00004,29.6936536,3.02791
25.48,106.16655,29.93205326,3.05222
25.52,106.33323,29.94156571,3.05319
25.56,106.50005,30.01462526,3.06064
25.6,106.66673,30.09347072,3.06868
25.64,106.83335,29.96098288,3.05517
25.68,106.99999,30.06934636,3.06622
25.72,107.16654,30.07728975,3.06703
25.76,107.3333,30.34716876,3.09455
25.8,107.50011,30.27891447,3.08759
25.84,107.66674,30.27293242,3.08698
25.88,107.83336,30.51672574,3.11184
25.92,107.99998,30.24498346,3.08413
25.96,108.16661,30.30333303,3.09008
26,108.3333,30.05414606,3.06467
26.04,108.50005,30.29921424,3.08966
26.08,108.66667,30.33353751,3.09316
26.12,108.83336,30.28823079,3.08854
26.16,108.99998,30.36070193,3.09593
26.2,109.16654,30.43856674,3.10387
26.24,109.33336,30.36334973,3.0962
26.28,109.5001,30.68540012,3.12904
26.32,109.66667,30.57223138,3.1175
26.36,109.83324,30.67333794,3.12781
26.4,109.99999,30.61616517,3.12198
26.44,110.16667,30.79719593,3.14044
26.48,110.33342,30.88908424,3.14981
26.52,110.49998,30.80631611,3.14137
26.56,110.66649,30.5355545,3.11376
26.6,110.83324,30.90830527,3.15177
26.64,111.00005,30.82004542,3.14277
26.68,111.16668,30.92213265,3.15318
26.72,111.33336,30.84201232,3.14501
26.76,111.49999,30.93958848,3.15496
26.8,111.66655,30.97322529,3.15839
26.84,111.8333,30.98911207,3.16001
26.88,112.00011,31.02520054,3.16369
26.92,112.16674,30.89732182,3.15065
26.96,112.3333,31.20221057,3.18174
27,112.50004,31.36058797,3.19789
27.04,112.66667,30.99970325,3.16109
27.08,112.83342,31.19701305,3.18121
27.12,113.00012,31.3203807,3.19379
27.16,113.16661,31.37137528,3.19899
27.2,113.33324,31.49974433,3.21208
27.24,113.49998,31.18612767,3.1801
27.28,113.66667,31.18102821,3.17958
27.32,113.83336,31.43904117,3.20589
27.36,114.00005,31.27978117,3.18965
27.4,114.16661,31.40687536,3.20261
27.44,114.33329,31.50249019,3.21236
27.48,114.50005,31.3806916,3.19994
27.52,114.66667,31.48032717,3.2101
27.56,114.8333,31.48013103,3.21008
27.6,115.00005,31.62997664,3.22536
27.64,115.16668,31.64439242,3.22683
27.68,115.3333,31.62085646,3.22443
27.72,115.50005,31.7129409,3.23382
27.76,115.66667,31.70156519,3.23266
27.8,115.83336,31.79865102,3.24256
27.84,115.99999,31.62517139,3.22487
27.88,116.16655,31.43845277,3.20583
27.92,116.33329,31.52759522,3.21492
27.96,116.50004,31.68920881,3.2314
28,116.66667,31.55593644,3.21781
28.04,116.8333,31.49758687,3.21186
28.08,116.99999,31.5378922,3.21597
28.12,117.16668,31.50562832,3.21268
28.16,117.33342,31.46855919,3.2089
28.2,117.50011,31.43639337,3.20562
28.24,117.66661,30.80602191,3.14134
28.28,117.8333,27.76154742,2.83089
28.32,118.00005,0.284294784,0.02899
28.36,118.16667,-2.020366033,-0.20602
28.4,118.33336,-1.00449516,-0.10243
28.44,118.50011,-1.042348829,-0.10629
28.48,118.66667,-0.982528264,-0.10019
28.52,118.8333,-0.999101502,-0.10188
28.56,118.99993,-1.029796317,-0.10501
28.6,119.16667,-1.050096082,-0.10708
28.64,119.33336,-1.004397093,-0.10242
28.68,119.50005,-1.241423824,-0.12659
28.72,119.66655,-1.035091908,-0.10555
28.76,119.83329,-1.056470405,-0.10773
28.8,120.00005,-1.006750689,-0.10266
28.84,120.16667,-1.038328102,-0.10588
28.88,120.33329,-1.007633288,-0.10275
28.92,120.49999,-1.098835133,-0.11205
28.96,120.66661,-1.04372176,-0.10643
29,120.83329,-1.137081068,-0.11595
29.04,121.00005,-1.172581141,-0.11957
29.08,121.16667,-1.203864354,-0.12276
29.12,121.3333,-0.908978389,-0.09269
29.16,121.49998,-1.064217658,-0.10852
29.2,121.6666,-1.063923459,-0.10849
29.24,121.83336,-1.170717877,-0.11938
29.28,122.00011,-1.02803112,-0.10483
29.32,122.16668,-0.728241829,-0.07426
29.36,122.3333,-1.060098865,-0.1081
29.4,122.50005,-0.874655114,-0.08919
29.44,122.66668,-1.009888817,-0.10298
29.48,122.83336,-1.224066053,-0.12482
29.52,123.00004,-1.346551112,-0.13731
29.56,123.16661,-1.250151742,-0.12748
29.6,123.3333,-1.106092054,-0.11279
29.64,123.50012,-1.05715687,-0.1078
29.68,123.66674,-1.068042252,-0.10891
29.72,123.83336,-1.140023063,-0.11625
29.76,123.99998,-1.137375267,-0.11598
29.8,124.16654,-0.917510174,-0.09356
29.84,124.3333,-1.068336451,-0.10894
29.88,124.50005,-1.12021363,-0.11423
29.92,124.66667,-1.113741241,-0.11357
29.96,124.83336,-0.989000653,-0.10085
30,124.99998,-1.035778373,-0.10562
30.04,125.16654,-1.056764604,-0.10776
30.08,125.33329,-1.066277055,-0.10873
30.12,125.50004,-1.150908444,-0.11736
30.16,125.66666,-1.219162728,-0.12432
30.2,125.83335,-1.21014061,-0.1234
30.24,125.99992,-1.013125012,-0.10331
30.28,126.16654,-1.2160246,-0.124
30.32,126.33336,-1.346845311,-0.13734
30.36,126.5001,-1.146495452,-0.11691
30.4,126.6666,-1.052351612,-0.10731
30.44,126.83324,-1.247013614,-0.12716
30.48,127.00004,-1.155713703,-0.11785
30.52,127.1668,-1.015478608,-0.10355
30.56,127.33336,-0.958305838,-0.09772
30.6,127.49991,-1.06137373,-0.10823
30.64,127.66654,-1.036955171,-0.10574
30.68,127.83336,-1.000082167,-0.10198
30.72,128.0001,-1.341647787,-0.13681
30.76,128.16667,-1.201510758,-0.12252
30.8,128.33335,-1.23985476,-0.12643
30.84,128.49999,-1.10619012,-0.1128
30.88,128.66661,-1.070003582,-0.10911
30.92,128.83335,-1.152183309,-0.11749
30.96,129.00004,-1.119723297,-0.11418
31,129.16661,-0.999395702,-0.10191
31.04,129.33329,-1.045094691,-0.10657
31.08,129.49998,-1.068042252,-0.10891
31.12,129.6666,-0.972231281,-0.09914
31.16,129.83336,-1.308403243,-0.13342
31.2,130.00004,-0.897308475,-0.0915
31.24,130.16661,-1.076672104,-0.10979
31.28,130.3333,-1.070788114,-0.10919
31.32,130.49997,-0.832976851,-0.08494
31.36,130.66666,-1.117761967,-0.11398
31.4,130.83336,-1.056176205,-0.1077
31.44,131.00005,-1.234559169,-0.12589
31.48,131.16661,-1.026854322,-0.10471
31.52,131.33324,-0.819247541,-0.08354
31.56,131.49998,-0.999199569,-0.10189
31.6,131.66666,-1.084125158,-0.11055
31.64,131.83336,-0.971054483,-0.09902
31.68,132.00005,-1.10648432,-0.11283
31.72,132.16661,-1.33595993,-0.13623
31.76,132.33329,-1.274276101,-0.12994
31.8,132.50004,-1.064021525,-0.1085
31.84,132.66667,-1.202001091,-0.12257
31.88,132.83335,-1.03558224,-0.1056
31.92,132.99997,-1.070199715,-0.10913
31.96,133.16668,-1.10256166,-0.11243
32,133.33336,-1.047546353,-0.10682
32.04,133.50016,-1.105111389,-0.11269
32.08,133.66667,-1.157380833,-0.11802
32.12,133.83329,-1.050194149,-0.10709
32.16,133.99998,-1.116879369,-0.11389
32.2,134.16666,-1.140219196,-0.11627
32.24,134.33342,-1.06696352,-0.1088
32.266,134.44173,-1.167579749,-0.11906