File: NR/NR/RDSO NR Tensile 250.is_tens_RawData/Specimen_RawData_1.csv
Time,Extension,Load,
(sec),(mm),(N),(kgf)
0,0,0.092868976,0.00947
0.04,0.06756,0.598009517,0.06098
0.08,0.2775,0.729222494,0.07436
0.12,0.48294,0.780511274,0.07959
0.16,0.65537,1.165814552,0.11888
0.2,0.82406,1.657814183,0.16905
0.24,0.99475,1.773728786,0.18087
0.28,1.16387,2.22218689,0.2266
0.32,1.33169,2.481474716,0.25304
0.36,1.499,2.750961458,0.28052
0.4,1.666,2.911005986,0.29684
0.44,1.83287,3.182257925,0.3245
0.48,1.99981,3.366132613,0.34325
0.52,2.16662,3.600609614,0.36716
0.56,2.33337,3.949726354,0.40276
0.6,2.5,3.999838336,0.40787
0.64,2.66656,4.527632239,0.46169
0.68,2.83331,4.650117297,0.47418
0.72,3.00006,4.663846607,0.47558
0.76,3.16669,4.873414718,0.49695
0.8,3.33331,5.195170904,0.52976
0.84,3.5,5.323932219,0.54289
0.88,3.66656,5.338936393,0.54442
0.92,3.83337,5.579003185,0.5689
0.96,4.00012,5.939985972,0.60571
1,4.16669,5.963031599,0.60806
1.04,4.33331,6.300478426,0.64247
1.08,4.5,6.351178806,0.64764
1.12,4.66662,6.513184664,0.66416
1.16,4.83344,6.796989115,0.6931
1.2,5.00006,6.858182611,0.69934
1.24,5.16662,7.03754624,0.71763
1.28,5.33325,6.999202238,0.71372
1.32,5.5,7.246722084,0.73896
1.36,5.66669,7.380680923,0.75262
1.4,5.83337,7.445404813,0.75922
1.44,6.00006,7.681548945,0.7833
1.48,6.16662,8.157956002,0.83188
1.52,6.33331,7.916712412,0.80728
1.56,6.5,8.048415722,0.82071
1.6,6.66662,8.367720246,0.85327
1.64,6.83331,8.267986615,0.8431
1.68,7.00012,8.471768802,0.86388
1.72,7.16669,8.75370999,0.89263
1.76,7.33325,8.636814722,0.88071
1.8,7.50006,8.896494814,0.90719
1.84,7.66675,9.055166411,0.92337
1.88,7.83337,9.11655604,0.92963
1.92,8,9.32641835,0.95103
1.96,8.16656,9.345835517,0.95301
2,8.33344,9.523728148,0.97115
2.04,8.50019,9.802531207,0.99958
2.08,8.66656,9.746633302,0.99388
2.12,8.83319,9.90304937,1.00983
2.16,9,10.02014077,1.02177
2.2,9.16669,10.07564641,1.02743
2.24,9.33337,9.91452315,1.011
2.28,9.50012,10.04534386,1.02434
2.32,9.66662,10.18724609,1.03881
2.36,9.83325,10.2779576,1.04806
2.4,10,10.22480556,1.04264
2.44,10.16669,10.3959316,1.06009
2.48,10.33337,10.6312912,1.08409
2.52,10.5,10.67002747,1.08804
2.56,10.66656,10.81300842,1.10262
2.6,10.83325,10.86596433,1.10802
2.64,11.00006,11.00933756,1.12264
2.68,11.16675,11.10877699,1.13278
2.72,11.33337,11.09171342,1.13104
2.76,11.5,11.13447041,1.1354
2.8,11.66656,10.9462808,1.11621
2.84,11.83337,11.27313644,1.14954
2.88,12.00012,11.42808151,1.16534
2.92,12.16669,11.3745372,1.15988
2.96,12.33331,11.47829156,1.17046
3,12.5,11.47152497,1.16977
3.04,12.66669,11.49682613,1.17235
3.08,12.83331,11.53477786,1.17622
3.12,13.00006,11.56998374,1.17981
3.16,13.16662,11.5109477,1.17379
3.2,13.33331,11.64804467,1.18777
3.24,13.50006,11.74052138,1.1972
3.28,13.66668,11.92272894,1.21578
3.32,13.83337,11.87732415,1.21115
3.36,14.00012,11.93194719,1.21672
3.4,14.16662,12.01628438,1.22532
3.44,14.33331,12.03579961,1.22731
3.48,14.50006,11.84888486,1.20825
3.52,14.66669,12.01746118,1.22544
3.56,14.83337,12.31528914,1.25581
3.6,15.00006,12.47709886,1.27231
3.64,15.16656,12.37197157,1.26159
3.68,15.33331,12.23271714,1.24739
3.72,15.50012,12.20015907,1.24407
3.76,15.66675,12.32470352,1.25677
3.8,15.83331,12.35275054,1.25963
3.84,15.99994,12.33833476,1.25816
3.88,16.16662,12.48788618,1.27341
3.92,16.33337,12.46297729,1.27087
3.96,16.50006,12.46101596,1.27067
4,16.66668,12.55123714,1.27987
4.04,16.83337,12.69794462,1.29483
4.08,17,12.7076532,1.29582
4.12,17.16656,12.76041298,1.3012
4.16,17.33331,12.54486281,1.27922
4.2,17.50012,12.71481206,1.29655
4.24,17.66669,12.72687424,1.29778
4.28,17.83331,12.90888566,1.31634
4.32,18,13.00518696,1.32616
4.36,18.16669,12.90015774,1.31545
4.4,18.33337,12.86446154,1.31181
4.44,18.50006,12.98096454,1.32369
4.48,18.66662,12.91516192,1.31698
4.52,18.83325,12.73619055,1.29873
4.56,19.00006,13.03205719,1.3289
4.6,19.16668,13.12747589,1.33863
4.64,19.33337,13.0039121,1.32603
4.68,19.50006,13.06196747,1.33195
4.72,19.66662,13.13639994,1.33954
4.76,19.83331,13.07657938,1.33344
4.8,20.00006,13.09266228,1.33508
4.84,20.16668,13.36234516,1.36258
4.88,20.33337,13.27330078,1.3535
4.92,20.5,13.33057161,1.35934
4.96,20.66662,13.3756822,1.36394
5,20.83331,13.29056048,1.35526
5.04,21.00006,13.27222204,1.35339
5.08,21.16662,13.41000548,1.36744
5.12,21.33331,13.58093539,1.38487
5.16,21.5,13.52925434,1.3796
5.2,21.66662,13.54837731,1.38155
5.24,21.83337,13.7096967,1.398
5.28,22.00012,13.71518842,1.39856
5.32,22.16662,13.68763174,1.39575
5.36,22.33325,13.62084845,1.38894
5.4,22.5,13.39961043,1.36638
5.44,22.66668,13.49091034,1.37569
5.48,22.83337,13.57691466,1.38446
5.52,23.00006,13.91083109,1.41851
5.56,23.16662,13.8303185,1.4103
5.6,23.33325,13.81590272,1.40883
5.64,23.5,13.75392469,1.40251
5.68,23.66669,13.99487408,1.42708
5.72,23.83337,13.98938236,1.42652
5.76,24.00006,13.77912778,1.40508
5.8,24.16662,13.86670117,1.41401
5.84,24.33325,14.01644871,1.42928
5.88,24.50006,14.05606758,1.43332
5.92,24.66675,13.97506465,1.42506
5.96,24.83337,13.98800943,1.42638
6,24.99993,14.07519055,1.43527
6.04,25.16662,14.21434691,1.44946
6.08,25.33343,14.19747947,1.44774
6.12,25.50012,14.21944637,1.44998
6.16,25.6665,14.15423214,1.44333
6.2,25.83318,14.2416094,1.45224
6.24,26,14.44303799,1.47278
6.28,26.16668,14.26083043,1.4542
6.32,26.33337,14.27534427,1.45568
6.36,26.50006,14.24259006,1.45234
6.4,26.66662,14.46765268,1.47529
6.44,26.83331,14.4166581,1.47009
6.48,27.00006,14.46951594,1.47548
6.52,27.16668,14.46314162,1.47483
6.56,27.33337,14.39018014,1.46739
6.6,27.50006,14.33045765,1.4613
6.64,27.66662,14.51305747,1.47992
6.68,27.83331,14.57738909,1.48648
6.72,28.00006,14.75763532,1.50486
6.76,28.16668,14.49619003,1.4782
6.8,28.33331,14.55689319,1.48439
6.84,28.5,14.64093618,1.49296
6.88,28.66662,14.65652876,1.49455
6.92,28.83337,14.91434559,1.52084
6.96,29.00006,14.89394775,1.51876
7,29.16669,14.91209006,1.52061
7.04,29.33337,14.8674698,1.51606
7.08,29.5,14.85148496,1.51443
7.12,29.66662,14.76391158,1.5055
7.16,29.83331,14.85442695,1.51473
7.2,30.00006,14.92081798,1.5215
7.24,30.16668,15.05791494,1.53548
7.28,30.33331,15.02702399,1.53233
7.32,30.50006,15.01868834,1.53148
7.36,30.66662,14.90355827,1.51974
7.4,30.83337,15.03702678,1.53335
7.44,31.00006,15.26522752,1.55662
7.48,31.16662,15.10920372,1.54071
7.52,31.33325,15.01809994,1.53142
7.56,31.50006,15.18961825,1.54891
7.6,31.66668,15.09194402,1.53895
7.64,31.83337,15.37310067,1.56762
7.68,31.99999,15.261501,1.55624
7.72,32.16656,15.32171383,1.56238
7.76,32.33331,15.3405426,1.5643
7.8,32.50018,15.36751088,1.56705
7.84,32.66668,15.36192109,1.56648
7.88,32.83324,15.40036316,1.5704
7.92,33,15.58943537,1.58968
7.96,33.16668,15.46381219,1.57687
8,33.33337,15.60012462,1.59077
8.04,33.50006,15.49156501,1.5797
8.08,33.66668,15.42233006,1.57264
8.12,33.83337,15.34848598,1.56511
8.16,34.00006,15.59453483,1.5902
8.2,34.16656,15.80371067,1.61153
8.24,34.33331,15.73143566,1.60416
8.28,34.50006,15.64513714,1.59536
8.32,34.66662,15.79410016,1.61055
8.36,34.83331,15.71496049,1.60248
8.4,34.99999,15.92550927,1.62395
8.44,35.16668,15.81243859,1.61242
8.48,35.33337,15.6502366,1.59588
8.52,35.49999,15.90177717,1.62153
8.56,35.66656,15.90471917,1.62183
8.6,35.83324,16.01896664,1.63348
8.64,35.99999,16.10575549,1.64233
8.68,36.16668,16.03504955,1.63512
8.72,36.33337,16.05250539,1.6369
8.76,36.50006,15.98797763,1.63032
8.8,36.66662,16.19362308,1.65129
8.84,36.83331,16.12909532,1.64471
8.88,37.00006,16.17126392,1.64901
8.92,37.16668,16.37357511,1.66964
8.96,37.33337,16.33140651,1.66534
9,37.49999,16.36445492,1.66871
9.04,37.66662,16.42201996,1.67458
9.08,37.83337,16.4178031,1.67415
9.12,38.00012,16.12693786,1.64449
9.16,38.16668,16.38671602,1.67098
9.2,38.33324,16.54999674,1.68763
9.24,38.5,16.50645521,1.68319
9.28,38.66668,16.60511011,1.69325
9.32,38.83349,16.57853409,1.69054
9.36,39.00012,16.73897089,1.7069
9.4,39.16656,16.74662007,1.70768
9.44,39.33324,16.66100802,1.69895
9.48,39.50006,16.74603167,1.70762
9.52,39.66668,16.68954537,1.70186
9.56,39.83337,16.59863772,1.69259
9.6,40.00005,16.70484374,1.70342
9.64,40.16655,16.67081467,1.69995
9.68,40.33324,16.8106575,1.71421
9.72,40.50006,17.03424912,1.73701
9.76,40.66668,16.9277489,1.72615
9.8,40.83337,17.08063457,1.74174
9.84,40.99999,16.96099344,1.72954
9.88,41.16655,17.03542591,1.73713
9.92,41.33324,17.06111934,1.73975
9.96,41.50006,17.10662219,1.74439
10,41.66674,17.1821334,1.75209
10.04,41.83331,17.14065127,1.74786
10.08,41.99999,17.09632521,1.74334
10.12,42.16668,17.10534733,1.74426
10.16,42.33343,17.30393199,1.76451
10.2,42.50005,16.95432492,1.72886
10.24,42.66656,17.10230727,1.74395
10.28,42.83324,17.18948839,1.75284
10.32,43.00006,17.36326222,1.77056
10.36,43.16668,17.64392855,1.79918
10.4,43.33337,17.46358425,1.78079
10.44,43.50006,17.41239354,1.77557
10.48,43.66668,17.37728573,1.77199
10.52,43.83331,17.3946435,1.77376
10.56,44.00006,17.39954683,1.77426
10.6,44.16668,17.42072919,1.77642
10.64,44.33337,17.54792144,1.78939
10.68,44.50005,17.93881451,1.82925
10.72,44.66656,17.91174816,1.82649
10.76,44.83331,17.62676691,1.79743
10.8,45.00006,17.71326156,1.80625
10.84,45.16668,17.79848135,1.81494
10.88,45.3333,17.82799937,1.81795
10.92,45.49999,17.62088292,1.79683
10.96,45.66655,17.99294722,1.83477
11,45.83337,17.80720927,1.81583
11.04,46.00006,17.92636007,1.82798
11.08,46.16662,18.09954551,1.84564
11.12,46.3333,17.92096641,1.82743
11.16,46.49993,17.87134476,1.82237
11.2,46.66662,18.11023475,1.84673
11.24,46.83337,17.93244019,1.8286
11.28,47.00012,18.01118759,1.83663
11.32,47.16668,18.40718012,1.87701
11.36,47.33331,18.09807451,1.84549
11.4,47.50005,18.29969923,1.86605
11.44,47.66668,18.34520209,1.87069
11.48,47.83337,18.2225209,1.85818
11.52,48.00005,18.45385977,1.88177
11.56,48.16656,18.5170146,1.88821
11.6,48.3333,18.436502,1.88
11.64,48.50012,18.4730808,1.88373
11.68,48.66675,18.59821366,1.89649
11.72,48.8333,18.39649087,1.87592
11.76,48.99999,18.42738182,1.87907
11.8,49.16662,18.64852177,1.90162
11.84,49.33337,18.78581487,1.91562
11.88,49.50012,18.43758073,1.88011
11.92,49.66668,18.48651592,1.8851
11.96,49.83325,18.7503148,1.912
12,49.99999,18.67980499,1.90481
12.04,50.16668,18.77993088,1.91502
12.08,50.33337,18.87907611,1.92513
12.12,50.50005,18.8694656,1.92415
12.16,50.66668,19.01205429,1.93869
12.2,50.83337,19.10080447,1.94774
12.24,50.99993,18.94389807,1.93174
12.28,51.16649,19.01627115,1.93912
12.32,51.33331,19.0240184,1.93991
12.36,51.50012,18.9250693,1.92982
12.4,51.66662,19.08697709,1.94633
12.44,51.83324,19.10404067,1.94807
12.48,51.99999,19.20367623,1.95823
12.52,52.16668,19.23172325,1.96109
12.56,52.33337,19.22534893,1.96044
12.6,52.50006,19.29164188,1.9672
12.64,52.66662,19.17572728,1.95538
12.68,52.83331,19.34793205,1.97294
12.72,53.00005,19.22897739,1.96081
12.76,53.16674,19.40078989,1.97833
12.8,53.33337,19.36558402,1.97474
12.84,53.49999,19.29664327,1.96771
12.88,53.66662,19.38264759,1.97648
12.92,53.8333,19.46031626,1.9844
12.96,54.00012,19.61457486,2.00013
13,54.16668,19.5728966,1.99588
13.04,54.3333,19.67076697,2.00586
13.08,54.49993,19.52003876,1.99049
13.12,54.66662,19.52180396,1.99067
13.16,54.83337,19.57946706,1.99655
13.2,55.00012,19.72715521,2.01161
13.24,55.16662,19.71970215,2.01085
13.28,55.33325,19.80178381,2.01922
13.32,55.49999,19.88867073,2.02808
13.36,55.66668,19.67429736,2.00622
13.4,55.83337,19.96065154,2.03542
13.44,56.00005,20.07637001,2.04722
13.48,56.16656,20.01625525,2.04109
13.52,56.3333,19.88680747,2.02789
13.56,56.50006,19.9268186,2.03197
13.6,56.66668,19.95310042,2.03465
13.64,56.83336,19.95545402,2.03489
13.68,57.00005,20.07911588,2.0475
13.72,57.16662,20.23543388,2.06344
13.76,57.3333,20.31555421,2.07161
13.8,57.50006,20.23759134,2.06366
13.84,57.66668,20.22288136,2.06216
13.88,57.83337,20.0638175,2.04594
13.92,58.00006,20.33104871,2.07319
13.96,58.16655,20.36184159,2.07633
14,58.33324,20.22052777,2.06192
14.04,58.50011,20.31682907,2.07174
14.08,58.66674,20.50207669,2.09063
14.12,58.8333,20.54865828,2.09538
14.16,58.99993,20.44372712,2.08468
14.2,59.16668,20.46334042,2.08668
14.24,59.33343,20.65437396,2.10616
14.28,59.50006,20.65584496,2.10631
14.32,59.66655,20.66545548,2.10729
14.36,59.83324,20.69369863,2.11017
14.4,60.00006,20.68006739,2.10878
14.44,60.16668,20.89140069,2.13033
14.48,60.33343,20.77068083,2.11802
14.52,60.50006,20.67251627,2.10801
14.56,60.66662,20.66212122,2.10695
14.6,60.83325,20.69536576,2.11034
14.64,60.99999,20.9642641,2.13776
14.68,61.16668,21.04781676,2.14628
14.72,61.33337,21.21041102,2.16286
14.76,61.49999,21.03281259,2.14475
14.8,61.66656,21.13097715,2.15476
14.84,61.8333,21.05732921,2.14725
14.88,62.00012,21.08233617,2.1498
14.92,62.16668,21.23571218,2.16544
14.96,62.33331,21.2385561,2.16573
15,62.49999,21.24924535,2.16682
15.04,62.66668,21.31338084,2.17336
15.08,62.83336,21.4747983,2.18982
15.12,63.00011,21.2830783,2.17027
15.16,63.16661,21.20384056,2.16219
15.2,63.3333,21.50814091,2.19322
15.24,63.49999,21.55540897,2.19804
15.28,63.66668,21.38742105,2.18091
15.32,63.83337,21.57963139,2.20051
15.36,64.00005,21.29680761,2.17167
15.4,64.16667,21.37192654,2.17933
15.44,64.33337,21.45263527,2.18756
15.48,64.50005,21.66691058,2.20941
15.52,64.66662,21.70770624,2.21357
15.56,64.83336,21.76085828,2.21899
15.6,65.00005,21.85872865,2.22897
15.64,65.16661,21.76330995,2.21924
15.68,65.3333,21.81685426,2.2247
15.72,65.50005,21.83548689,2.2266
15.76,65.66667,21.83185843,2.22623
15.8,65.83336,21.96709213,2.24002
15.84,65.99999,21.68162055,2.21091
15.88,66.16655,21.91443042,2.23465
15.92,66.33336,21.80518434,2.22351
15.96,66.50012,21.87912648,2.23105
16,66.66661,21.99003969,2.24236
16.04,66.83324,22.10340457,2.25392
16.08,66.99999,22.17126659,2.26084
16.12,67.16668,22.05554812,2.24904
16.16,67.33336,22.08330094,2.25187
16.2,67.50011,22.26531236,2.27043
16.24,67.66674,22.1852901,2.26227
16.28,67.83336,22.29414391,2.27337
16.32,67.99993,22.29208451,2.27316
16.36,68.16655,22.31267848,2.27526
16.4,68.33337,22.1065427,2.25424
16.44,68.50012,22.47458627,2.29177
16.48,68.66661,22.47468434,2.29178
16.52,68.8333,22.56500358,2.30099
16.56,69.00005,22.63443467,2.30807
16.6,69.16668,22.39162201,2.28331
16.64,69.33337,22.6533615,2.31
16.68,69.49999,22.6355134,2.30818
16.72,69.66655,22.54990134,2.29945
16.76,69.8333,22.64836011,2.30949
16.8,70.00005,22.72210612,2.31701
16.84,70.16668,22.92196564,2.33739
16.88,70.3333,22.91137446,2.33631
16.92,70.49999,22.79732312,2.32468
16.96,70.66661,22.85567269,2.33063
17,70.8333,22.88126805,2.33324
17.04,71.00006,22.93206649,2.33842
17.08,71.16668,23.09318975,2.35485
17.12,71.33331,22.99384839,2.34472
17.16,71.49999,22.96079998,2.34135
17.2,71.66661,23.04150871,2.34958
17.24,71.83337,22.95060106,2.34031
17.28,72.00005,22.9864934,2.34397
17.32,72.16667,23.1249633,2.35809
17.36,72.3333,23.03866478,2.34929
17.4,72.50005,23.25803954,2.37166
17.44,72.66674,23.40788515,2.38694
17.48,72.83343,23.45436867,2.39168
17.52,73.00005,23.18919686,2.36464
17.56,73.16662,23.46780378,2.39305
17.6,73.3333,23.46221399,2.39248
17.64,73.50005,23.54174592,2.40059
17.68,73.66668,23.41553434,2.38772
17.72,73.83343,23.36385329,2.38245
17.76,74.00006,23.60774468,2.40732
17.8,74.16661,23.75847289,2.42269
17.84,74.3333,23.50026379,2.39636
17.88,74.50006,23.59823223,2.40635
17.92,74.66668,23.55037578,2.40147
17.96,74.83337,23.54880671,2.40131
18,74.99999,23.72336508,2.41911
18.04,75.16649,23.77720359,2.4246
18.08,75.3333,23.82260838,2.42923
18.12,75.50012,23.80113182,2.42704
18.16,75.66668,23.77602679,2.42448
18.2,75.83324,23.79701302,2.42662
18.24,75.99992,23.84045648,2.43105
18.28,76.16668,23.9847123,2.44576
18.32,76.33343,23.92479367,2.43965
18.36,76.49999,24.08552467,2.45604
18.4,76.66649,24.03727595,2.45112
18.44,76.83324,24.21820864,2.46957
18.48,77.00011,24.29018945,2.47691
18.52,77.16668,24.33784977,2.48177
18.56,77.33336,24.18820029,2.46651
18.6,77.50005,24.35628627,2.48365
18.64,77.66661,24.11612141,2.45916
18.68,77.83331,24.2250733,2.47027
18.72,78.00005,24.40541759,2.48866
18.76,78.16668,24.36138573,2.48417
18.8,78.3333,24.40433886,2.48855
18.84,78.50005,24.40865378,2.48899
18.88,78.66668,24.49132384,2.49742
18.92,78.83336,24.4367008,2.49185
18.96,79.00012,24.6940273,2.51809
19,79.16667,24.74060889,2.52284
19.04,79.3333,24.75914345,2.52473
19.08,79.49999,24.66843194,2.51548
19.12,79.66661,24.72295692,2.52104
19.16,79.83336,24.8105303,2.52997
19.2,80.00005,24.82680934,2.53163
19.24,80.16662,24.74943487,2.52374
19.28,80.3333,24.59900086,2.5084
19.32,80.49999,24.7710095,2.52594
19.36,80.66662,24.90565481,2.53967
19.4,80.83336,24.83700826,2.53267
19.44,81.00005,24.94596014,2.54378
19.48,81.16661,24.86986053,2.53602
19.52,81.3333,25.02500174,2.55184
19.56,81.49998,24.84279418,2.53326
19.6,81.66661,24.92350291,2.54149
19.64,81.83336,25.00891883,2.5502
19.68,82.00006,25.31478824,2.58139
19.72,82.16655,25.24820109,2.5746
19.76,82.33336,25.01637188,2.55096
19.8,82.50011,25.29439041,2.57931
19.84,82.66673,25.33185181,2.58313
19.88,82.83329,25.45335621,2.59552
19.92,82.99999,25.41393348,2.5915
19.96,83.16661,25.3989293,2.58997
20,83.33342,25.60329989,2.61081
20.04,83.50012,25.27281578,2.57711
20.08,83.66661,25.55191304,2.60557
20.12,83.83323,25.71499763,2.6222
20.16,83.99999,25.69097134,2.61975
20.2,84.16668,25.72882501,2.62361
20.24,84.3333,25.59349324,2.60981
20.28,84.50005,25.59721976,2.61019
20.32,84.66667,25.51533424,2.60184
20.36,84.8333,25.66488565,2.61709
20.4,84.99992,25.79492183,2.63035
20.44,85.16661,25.77942732,2.62877
20.48,85.33336,25.89210573,2.64026
20.52,85.50005,25.79992322,2.63086
20.56,85.66661,25.97350092,2.64856
20.6,85.83331,26.30467149,2.68233
20.64,86.00005,26.03234082,2.65456
20.68,86.16667,25.97526612,2.64874
20.72,86.3333,26.01586565,2.65288
20.76,86.49998,26.01596372,2.65289
20.8,86.66655,26.19925001,2.67158
20.84,86.83329,26.2417128,2.67591
20.88,87.00005,26.24995039,2.67675
20.92,87.16667,26.25161752,2.67692
20.96,87.33337,26.30241597,2.6821
21,87.50005,26.41980157,2.69407
21.04,87.66661,26.14413663,2.66596
21.08,87.8333,26.50384456,2.70264
21.12,88.00011,26.36125587,2.6881
21.16,88.16668,26.32055827,2.68395
21.2,88.3333,26.44794665,2.69694
21.24,88.49998,26.41617311,2.6937
21.28,88.66668,26.45196738,2.69735
21.32,88.83336,26.57906156,2.71031
21.36,89.00011,26.78549154,2.73136
21.4,89.16655,26.73126077,2.72583
21.44,89.33323,26.76077879,2.72884
21.48,89.49999,26.79912279,2.73275
21.52,89.66668,26.84629277,2.73756
21.56,89.83342,26.86374861,2.73934
21.6,90.00004,26.89562022,2.74259
21.64,90.16655,26.80078992,2.73292
21.68,90.33323,26.83717259,2.73663
21.72,90.50005,26.97221016,2.7504
21.76,90.66667,26.98682207,2.75189
21.8,90.83336,26.84423338,2.73735
21.84,90.99999,26.98535107,2.75174
21.88,91.16654,27.05939128,2.75929
21.92,91.3333,26.98799887,2.75201
21.96,91.50005,27.17354068,2.77093
22,91.66667,27.1448072,2.768
22.04,91.83336,27.29582961,2.7834
22.08,92.00005,27.38997345,2.793
22.12,92.16661,27.23816651,2.77752
22.16,92.33336,27.44763655,2.79888
22.2,92.50011,27.23865684,2.77757
22.24,92.66668,27.39360191,2.79337
22.28,92.8333,27.32809349,2.78669
22.32,92.99998,27.45705094,2.79984
22.36,93.16674,27.36732009,2.79069
22.4,93.33342,27.47019185,2.80118
22.44,93.49999,27.45077468,2.7992
22.48,93.66655,27.60473909,2.8149
22.52,93.83329,27.44989208,2.79911
22.56,94.00005,27.45459927,2.79959
22.6,94.16667,27.7165349,2.8263
22.64,94.33337,27.74762198,2.82947
22.68,94.50004,27.5540387,2.80973
22.72,94.66661,27.68956661,2.82355
22.76,94.8333,27.65141874,2.81966
22.8,95.00004,27.94297044,2.84939
22.84,95.16668,27.80528508,2.83535
22.88,95.33335,27.8532396,2.84024
22.92,95.49998,28.02465984,2.85772
22.96,95.66661,28.12880646,2.86834
23,95.8333,28.13753438,2.86923
23.04,96.00011,28.00671367,2.85589
23.08,96.16661,28.08644173,2.86402
23.12,96.33323,28.17274025,2.87282
23.16,96.49992,28.29806924,2.8856
23.2,96.66661,28.19362842,2.87495
23.24,96.83336,28.19049029,2.87463
23.28,97.00011,28.5388225,2.91015
23.32,97.16661,28.38574069,2.89454
23.36,97.33323,28.31022949,2.88684
23.4,97.50005,28.42977255,2.89903
23.44,97.66674,28.37887604,2.89384
23.48,97.83342,28.49126025,2.9053
23.52,98.00005,28.64816665,2.9213
23.56,98.16667,28.66071916,2.92258
23.6,98.33329,28.52626999,2.90887
23.64,98.5001,28.67101614,2.92363
23.68,98.66667,28.4196717,2.898
23.72,98.83337,28.67876339,2.92442
23.76,98.99999,28.70563361,2.92716
23.8,99.16661,28.60158506,2.91655
23.84,99.33336,28.95295733,2.95238
23.88,99.50011,28.80585758,2.93738
23.92,99.66668,28.60678258,2.91708
23.96,99.8333,28.93040203,2.95008
24,99.99998,28.76074699,2.93278
24.04,100.16661,28.97463002,2.95459
24.08,100.33336,28.8496933,2.94185
24.12,100.50011,28.78359648,2.93511
24.16,100.66655,29.07004873,2.96432
24.2,100.83323,28.92363544,2.94939
24.24,100.99999,29.0458263,2.96185
24.28,101.16667,29.22450347,2.98007
24.32,101.3333,29.1831194,2.97585
24.36,101.50004,29.21989434,2.9796
24.4,101.66667,29.39415851,2.99737
24.44,101.8333,29.32031444,2.98984
24.48,101.99999,29.38945132,2.99689
24.52,102.16661,29.25735574,2.98342
24.56,102.33343,29.31658791,2.98946
24.6,102.50011,29.32963075,2.99079
24.64,102.66662,29.29099255,2.98685
24.68,102.8333,29.41396794,2.99939
24.72,103.0001,29.46584512,3.00468
24.76,103.16667,29.67531517,3.02604
24.8,103.33336,29.71169784,3.02975
24.84,103.49998,29.43505224,3.00154
24.88,103.66655,29.49055788,3.0072
24.92,103.8333,29.55861603,3.01414
24.96,104.00011,29.74709984,3.03336
25,104.16668,29.77877532,3.03659
25.04,104.3333,29.8511484,3.04397
25.08,104.49998,29.94440964,3.05348
25.12,104.66661,29.86242605,3.04512
25.16,104.83336,29.96588621,3.05567
25.2,105.00005,29.86360285,3.04524
25.24,105.16667,29.9902067,3.05815
25.28,105.33324,30.0859196,3.06791
25.32,105.49999,30.03315982,3.06253
25.36,105.66667,30.0844486,3.06776
25.4,105.83336,30.1485841,3.0743
25.44,106.00004,30.10896523,3.07026
25.48,106.16655,30.02256864,3.06145
25.52,106.33323,29.98275364,3.05739
25.56,106.50005,30.30097944,3.08984
25.6,106.66673,30.31372808,3.09114
25.64,106.83335,30.33216458,3.09302
25.68,106.99999,30.38208043,3.09811
25.72,107.16654,30.71315294,3.13187
25.76,107.33336,30.40816612,3.10077
25.8,107.50011,30.37531384,3.09742
25.84,107.66674,30.43660541,3.10367
25.88,107.83336,30.4992699,3.11006
25.92,108.00004,30.72874551,3.13346
25.96,108.16661,30.66323709,3.12678
26,108.3333,30.61793036,3.12216
26.04,108.50005,30.75149694,3.13578
26.08,108.66667,30.5548736,3.11573
26.12,108.83336,30.60429912,3.12077
26.16,108.99998,30.73158944,3.13375
26.2,109.16654,30.85672229,3.14651
26.24,109.33336,31.05687602,3.16692
26.28,109.5001,30.96410511,3.15746
26.32,109.66667,30.85181897,3.14601
26.36,109.83324,31.08188298,3.16947
26.4,109.99999,31.04069505,3.16527
26.44,110.16667,31.06530974,3.16778
26.48,110.33342,31.19524785,3.18103
26.52,110.49998,31.28301737,3.18998
26.56,110.66649,31.04805003,3.16602
26.6,110.8333,31.25889301,3.18752
26.64,111.00005,31.10012334,3.17133
26.68,111.16668,31.28772456,3.19046
26.72,111.33336,31.40187397,3.2021
26.76,111.49999,31.27213199,3.18887
26.8,111.66655,31.19779758,3.18129
26.84,111.8333,31.38794852,3.20068
26.88,112.00011,31.57094061,3.21934
26.92,112.16674,31.41413228,3.20335
26.96,112.3333,31.44649422,3.20665
27,112.50004,31.47915037,3.20998
27.04,112.66667,31.71804036,3.23434
27.08,112.83342,31.68665908,3.23114
27.12,113.00012,31.66302505,3.22873
27.16,113.16661,31.62929018,3.22529
27.2,113.3333,31.72343402,3.23489
27.24,113.49998,31.70646851,3.23316
27.28,113.66667,31.66714385,3.22915
27.32,113.83336,31.80316208,3.24302
27.36,114.00005,31.93545379,3.25651
27.4,114.16661,32.09196793,3.27247
27.44,114.33329,31.95830329,3.25884
27.48,114.50005,32.00508101,3.26361
27.52,114.66661,31.90201312,3.2531
27.56,114.8333,31.9881155,3.26188
27.6,115.00005,32.02626337,3.26577
27.64,115.16668,32.17061726,3.28049
27.68,115.3333,32.14698323,3.27808
27.72,115.49998,32.35468808,3.29926
27.76,115.66667,32.29486751,3.29316
27.8,115.83329,32.12001494,3.27533
27.84,115.99999,32.25230665,3.28882
27.88,116.16655,32.38616743,3.30247
27.92,116.33329,32.18797503,3.28226
27.96,116.50004,32.50374916,3.31446
28,116.66667,32.59024381,3.32328
28.04,116.8333,32.46972008,3.31099
28.08,116.99999,32.61525077,3.32583
28.12,117.16668,32.7123366,3.33573
28.16,117.33342,32.44049627,3.30801
28.2,117.50011,32.7328325,3.33782
28.24,117.66661,32.73979522,3.33853
28.28,117.8333,32.61054358,3.32535
28.32,118.00005,32.47442728,3.31147
28.36,118.16667,32.80628431,3.34531
28.4,118.33336,32.70145122,3.33462
28.44,118.50011,32.75950659,3.34054
28.48,118.66667,32.91758979,3.35666
28.52,118.8333,32.90758701,3.35564
28.56,118.99993,32.75832979,3.34042
28.6,119.16667,32.86178995,3.35097
28.64,119.33336,32.8546311,3.35024
28.68,119.50005,32.94249868,3.3592
28.72,119.66655,33.10421034,3.37569
28.76,119.83329,32.92602351,3.35752
28.8,120.00011,32.80981471,3.34567
28.84,120.16667,32.96407331,3.3614
28.88,120.33329,33.05900168,3.37108
28.92,120.49999,33.02144221,3.36725
28.96,120.66655,32.86512421,3.35131
29,120.83329,33.16138311,3.38152
29.04,121.00005,32.9304365,3.35797
29.08,121.16667,33.25160429,3.39072
29.12,121.3333,33.16824776,3.38222
29.16,121.49998,33.20963183,3.38644
29.2,121.6666,33.25856701,3.39143
29.24,121.83336,33.07302519,3.37251
29.28,122.00011,33.05262736,3.37043
29.32,122.16668,33.18472294,3.3839
29.36,122.3333,32.9684863,3.36185
29.4,122.50005,32.92072792,3.35698
29.44,122.66673,32.90562568,3.35544
29.48,122.83336,32.70900234,3.33539
29.52,123.00004,32.80059645,3.34473
29.56,123.16661,32.25054146,3.28864
29.6,123.3333,4.629425266,0.47207
29.64,123.50012,-2.42057542,-0.24683
29.68,123.66674,-1.411373068,-0.14392
29.72,123.83336,-1.109034049,-0.11309
29.76,123.99998,-1.206021817,-0.12298
29.8,124.16654,-1.173463739,-0.11966
29.84,124.3333,-1.000866699,-0.10206
29.88,124.50005,-1.226811915,-0.1251
29.92,124.66673,-1.286534414,-0.13119
29.96,124.83336,-1.405979411,-0.14337
30,124.99998,-1.021754864,-0.10419
30.04,125.16654,-1.272608971,-0.12977
30.08,125.33329,-1.313698834,-0.13396
30.12,125.50004,-1.21798593,-0.1242
30.16,125.66666,-1.320661556,-0.13467
30.2,125.83335,-1.13982693,-0.11623
30.24,125.99992,-1.147770316,-0.11704
30.28,126.16654,-1.212788406,-0.12367
30.32,126.33336,-1.361849486,-0.13887
30.36,126.50016,-1.237795363,-0.12622
30.4,126.6666,-1.106680453,-0.11285
30.44,126.83324,-1.001258965,-0.1021
30.48,127.00004,-1.279277493,-0.13045
30.52,127.1668,-1.207787014,-0.12316
30.56,127.33336,-1.21014061,-0.1234
30.6,127.49991,-1.128549282,-0.11508
30.64,127.66654,-1.234853368,-0.12592
30.68,127.83336,-1.164833887,-0.11878
30.72,128.0001,-1.023127795,-0.10433
30.76,128.16672,-1.222693122,-0.12468
30.8,128.33335,-1.187879515,-0.12113
30.84,128.49999,-1.134923605,-0.11573
30.88,128.66661,-1.283788552,-0.13091
30.92,128.83335,-1.408136874,-0.14359
30.96,129.00004,-1.237108898,-0.12615
31,129.16661,-1.273981902,-0.12991
31.04,129.33329,-1.060883397,-0.10818
31.08,129.49998,-1.072062978,-0.10932
31.12,129.6666,-1.046173422,-0.10668
31.16,129.83336,-1.127960883,-0.11502
31.2,130.00004,-1.158949897,-0.11818
31.24,130.16661,-1.253976336,-0.12787
31.28,130.3333,-1.151889109,-0.11746
31.32,130.49997,-1.161793826,-0.11847
31.36,130.66666,-1.032346046,-0.10527
31.4,130.83336,-1.192684773,-0.12162
31.44,131.00005,-1.259566126,-0.12844
31.48,131.16661,-1.406077477,-0.14338
31.52,131.33324,-1.161303493,-0.11842
31.56,131.49998,-1.10030613,-0.1122
31.6,131.66666,-1.197097766,-0.12207
31.638,131.82511,-1.281533022,-0.13068