File: NR/NR/RDSO NR Tensile 250.is_tens_RawData/Specimen_RawData_7.csv
Time,Extension,Load,
(sec),(mm),(N),(kgf)
0,0,-1.076672104,-0.10979
0.04,0.06762,-0.547701403,-0.05585
0.08,0.27756,-0.163280723,-0.01665
0.12,0.483,-0.375986961,-0.03834
0.16,0.65537,-0.087279185,-0.0089
0.2,0.82406,0.410800569,0.04189
0.24,0.99475,0.726966965,0.07413
0.28,1.16387,0.966249225,0.09853
0.32,1.33169,1.352533168,0.13792
0.36,1.499,1.665365303,0.16982
0.4,1.666,1.984473694,0.20236
0.44,1.83287,2.152951941,0.21954
0.48,1.99981,2.26533615,0.231
0.52,2.16662,2.497165356,0.25464
0.56,2.33337,2.724777703,0.27785
0.6,2.5,3.036236907,0.30961
0.64,2.66656,3.127144552,0.31888
0.68,2.83331,3.502641181,0.35717
0.72,3.00006,3.640424613,0.37122
0.76,3.16669,3.836459547,0.39121
0.8,3.33331,4.002093865,0.4081
0.84,3.5,4.151645278,0.42335
0.88,3.66662,4.417013227,0.45041
0.92,3.83337,4.630013665,0.47213
0.96,4.00012,4.816143882,0.49111
1,4.16669,5.088572619,0.51889
1.04,4.33331,5.054053211,0.51537
1.08,4.5,5.311870039,0.54166
1.12,4.66669,5.512317965,0.5621
1.16,4.83344,5.770428993,0.58842
1.2,5.00012,5.973524715,0.60913
1.24,5.16662,6.070806683,0.61905
1.28,5.33325,6.100128566,0.62204
1.32,5.5,6.611153098,0.67415
1.36,5.66669,6.803559571,0.69377
1.4,5.83337,6.845532033,0.69805
1.44,6.00006,6.822584472,0.69571
1.48,6.16662,7.144732924,0.72856
1.52,6.33331,7.253194473,0.73962
1.56,6.5,7.443051217,0.75898
1.6,6.66669,7.528859405,0.76773
1.64,6.83337,7.675174623,0.78265
1.68,7.00012,7.957998409,0.81149
1.72,7.16662,7.953095084,0.81099
1.76,7.33325,8.342419089,0.85069
1.8,7.5,8.288482514,0.84519
1.84,7.66675,8.277793265,0.8441
1.88,7.83337,8.33006271,0.84943
1.92,8,8.535119761,0.87034
1.96,8.16656,8.665254007,0.88361
2,8.33344,9.001327902,0.91788
2.04,8.50019,9.154311642,0.93348
2.08,8.66656,9.098217604,0.92776
2.12,8.83319,9.152644512,0.93331
2.16,9,9.350346576,0.95347
2.2,9.16669,9.541282051,0.97294
2.24,9.33337,9.436547029,0.96226
2.28,9.50012,9.478029159,0.96649
2.32,9.66662,9.703974375,0.98953
2.36,9.83325,9.989445956,1.01864
2.4,10,9.844307536,1.00384
2.44,10.16669,10.01886591,1.02164
2.48,10.33337,10.02700543,1.02247
2.52,10.5,10.28943138,1.04923
2.56,10.66656,10.14164516,1.03416
2.6,10.83331,10.31689,1.05203
2.64,11.00006,10.48272045,1.06894
2.68,11.16675,10.47418867,1.06807
2.72,11.33331,10.61824835,1.08276
2.76,11.5,10.63570419,1.08454
2.8,11.66656,10.46555881,1.06719
2.84,11.83337,10.90577933,1.11208
2.88,12.00012,10.91597825,1.11312
2.92,12.16669,10.90362187,1.11186
2.96,12.33331,10.9614811,1.11776
3,12.50006,10.99668698,1.12135
3.04,12.66669,11.28637542,1.15089
3.08,12.83337,11.27146931,1.14937
3.12,13.00006,11.08043577,1.12989
3.16,13.16662,11.30079119,1.15236
3.2,13.33331,11.39287564,1.16175
3.24,13.50006,11.33021114,1.15536
3.28,13.66668,11.50751538,1.17344
3.32,13.83337,11.62244931,1.18516
3.36,14.00012,11.62352805,1.18527
3.4,14.16662,11.6128388,1.18418
3.44,14.33331,11.69992185,1.19306
3.48,14.50006,11.65961652,1.18895
3.52,14.66669,11.50329852,1.17301
3.56,14.83337,11.7870049,1.20194
3.6,15.00006,11.65353639,1.18833
3.64,15.16662,11.85869151,1.20925
3.68,15.33331,11.79955741,1.20322
3.72,15.50012,11.97794038,1.22141
3.76,15.66668,12.04040874,1.22778
3.8,15.83331,11.93439885,1.21697
3.84,15.99994,12.05668778,1.22944
3.88,16.16662,12.17358304,1.24136
3.92,16.33337,12.13543518,1.23747
3.96,16.50006,12.28233879,1.25245
4,16.66668,12.26998241,1.25119
4.04,16.83343,12.33715797,1.25804
4.08,17.00006,12.3765807,1.26206
4.12,17.1665,12.26704042,1.25089
4.16,17.33331,12.38638735,1.26306
4.2,17.50012,12.3754039,1.26194
4.24,17.66669,12.49837929,1.27448
4.28,17.83331,12.36844118,1.26123
4.32,18,12.46758641,1.27134
4.36,18.16669,12.69588522,1.29462
4.4,18.33337,12.65312823,1.29026
4.44,18.50006,12.66881887,1.29186
4.48,18.66662,12.6119403,1.28606
4.52,18.83331,12.54044982,1.27877
4.56,19.00006,12.81915481,1.30719
4.6,19.16668,12.87632758,1.31302
4.64,19.33337,12.67087827,1.29207
4.68,19.5,12.77080803,1.30226
4.72,19.66662,12.81856641,1.30713
4.76,19.83331,12.87750438,1.31314
4.8,20.00006,12.85749882,1.3111
4.84,20.16668,13.05039562,1.33077
4.88,20.33337,12.86122534,1.31148
4.92,20.5,13.06883212,1.33265
4.96,20.66662,13.05853514,1.3316
5,20.83331,12.8288634,1.30818
5.04,21.00006,13.05539701,1.33128
5.08,21.16662,13.33567107,1.35986
5.12,21.33325,13.17356714,1.34333
5.16,21.5,13.12296483,1.33817
5.2,21.66662,13.24662669,1.35078
5.24,21.83337,13.34077053,1.36038
5.28,22.00012,13.11335431,1.33719
5.32,22.16662,13.23623164,1.34972
5.36,22.33325,13.21377441,1.34743
5.4,22.5,13.26682839,1.35284
5.44,22.66668,13.32988515,1.35927
5.48,22.83337,13.3361614,1.35991
5.52,23.00012,13.6288899,1.38976
5.56,23.16662,13.41079001,1.36752
5.6,23.33325,13.54798504,1.38151
5.64,23.5,13.38323332,1.36471
5.68,23.66669,13.49198907,1.3758
5.72,23.83343,13.59044784,1.38584
5.76,24.00006,13.5917227,1.38597
5.8,24.16662,13.39068638,1.36547
5.84,24.33325,13.64585541,1.39149
5.88,24.50006,13.77677419,1.40484
5.92,24.66675,13.82659197,1.40992
5.96,24.83337,13.66762617,1.39371
6,24.99993,13.58907491,1.3857
6.04,25.16662,13.67684442,1.39465
6.08,25.33343,13.81452979,1.40869
6.12,25.50012,13.73352686,1.40043
6.16,25.6665,13.76657527,1.4038
6.2,25.83318,13.98742103,1.42632
6.24,26,14.05940184,1.43366
6.28,26.16668,14.02772636,1.43043
6.32,26.33337,13.81776598,1.40902
6.36,26.50006,13.93044439,1.42051
6.4,26.66662,13.9848713,1.42606
6.44,26.83331,14.16953052,1.44489
6.48,27,14.17541451,1.44549
6.52,27.16668,14.04380927,1.43207
6.56,27.33337,14.16600012,1.44453
6.6,27.50006,14.28681805,1.45685
6.64,27.66662,14.23454861,1.45152
6.68,27.83331,14.23994227,1.45207
6.72,28.00006,14.20610932,1.44862
6.76,28.16668,14.24955278,1.45305
6.8,28.33337,14.35850466,1.46416
6.84,28.5,14.33800877,1.46207
6.88,28.66662,14.54414455,1.48309
6.92,28.83337,14.38360969,1.46672
6.96,29.00006,14.53777023,1.48244
7,29.16669,14.44656838,1.47314
7.04,29.33337,14.49050217,1.47762
7.08,29.5,14.51698013,1.48032
7.12,29.66662,14.43823273,1.47229
7.16,29.83337,14.51815693,1.48044
7.2,30.00006,14.66211855,1.49512
7.24,30.16668,14.60063085,1.48885
7.28,30.33331,14.60308252,1.4891
7.32,30.50006,14.6540771,1.4943
7.36,30.66662,14.74625961,1.5037
7.4,30.83337,14.56787664,1.48551
7.44,31.00006,14.63044307,1.49189
7.48,31.16662,14.74331761,1.5034
7.52,31.33325,14.91797405,1.52121
7.56,31.50006,14.61465436,1.49028
7.6,31.66668,14.97436228,1.52696
7.64,31.83337,14.70232581,1.49922
7.68,31.99999,14.9441578,1.52388
7.72,32.16656,14.80176524,1.50936
7.76,32.33331,14.96906669,1.52642
7.8,32.50012,15.19501191,1.54946
7.84,32.66668,15.13685847,1.54353
7.88,32.83324,14.92444644,1.52187
7.92,33,14.86962726,1.51628
7.96,33.16668,15.1599041,1.54588
8,33.33337,14.93023236,1.52246
8.04,33.50006,15.31210331,1.5614
8.08,33.66668,15.32485196,1.5627
8.12,33.83337,15.07890117,1.53762
8.16,34.00006,15.3349528,1.56373
8.2,34.16656,15.30268893,1.56044
8.24,34.33331,15.44164916,1.57461
8.28,34.50006,15.3001392,1.56018
8.32,34.66662,15.30925938,1.56111
8.36,34.83331,15.35338931,1.56561
8.4,34.99999,15.54157892,1.5848
8.44,35.16668,15.42988118,1.57341
8.48,35.33337,15.52422115,1.58303
8.52,35.49999,15.5729602,1.588
8.56,35.66662,15.76252274,1.60733
8.6,35.83324,15.5729602,1.588
8.64,35.99999,15.45861466,1.57634
8.68,36.16668,15.56717428,1.58741
8.72,36.33337,15.7281014,1.60382
8.76,36.50006,15.92933386,1.62434
8.8,36.66662,15.58884697,1.58962
8.84,36.83331,15.74810697,1.60586
8.88,37.00006,16.081435,1.63985
8.92,37.16668,15.96385327,1.62786
8.96,37.33337,16.01190585,1.63276
9,37.49999,15.93002033,1.62441
9.04,37.66656,16.0454446,1.63618
9.08,37.83337,15.9827801,1.62979
9.12,38.00012,16.02818489,1.63442
9.16,38.16668,16.02455643,1.63405
9.2,38.33324,15.95316402,1.62677
9.24,38.5,16.17910924,1.64981
9.28,38.66668,15.93511978,1.62493
9.32,38.83343,16.08780933,1.6405
9.36,39.00012,16.25099198,1.65714
9.4,39.16656,16.16665479,1.64854
9.44,39.33324,16.0023934,1.63179
9.48,39.50006,16.15125835,1.64697
9.52,39.66668,16.4145669,1.67382
9.56,39.83337,16.37808617,1.6701
9.6,40.00005,16.33395624,1.6656
9.64,40.16655,16.28051,1.66015
9.68,40.33324,16.43045368,1.67544
9.72,40.50006,16.49439303,1.68196
9.76,40.66668,16.69523323,1.70244
9.8,40.83337,16.46026589,1.67848
9.84,41.00006,16.81232463,1.71438
9.88,41.16655,16.48929358,1.68144
9.92,41.33324,16.5922634,1.69194
9.96,41.50006,16.67993485,1.70088
10,41.66674,16.62148722,1.69492
10.04,41.83331,16.68415171,1.70131
10.08,41.99999,16.75544606,1.70858
10.12,42.16668,16.93275029,1.72666
10.16,42.33343,16.94138014,1.72754
10.2,42.50005,16.93304449,1.72669
10.24,42.66656,16.88371704,1.72166
10.28,42.83324,17.04768423,1.73838
10.32,43.00006,16.82693654,1.71587
10.36,43.16668,16.71563106,1.70452
10.4,43.33337,17.20106023,1.75402
10.44,43.50012,17.04886103,1.7385
10.48,43.66668,17.03395492,1.73698
10.52,43.83331,16.98188161,1.73167
10.56,44.00006,17.08838182,1.74253
10.6,44.16668,17.00424077,1.73395
10.64,44.33337,17.40248882,1.77456
10.68,44.50005,17.3981739,1.77412
10.72,44.66656,17.46044613,1.78047
10.76,44.83331,17.28961428,1.76305
10.8,45.00006,17.0615116,1.73979
10.84,45.16668,17.28500516,1.76258
10.88,45.3333,17.46887984,1.78133
10.92,45.49999,17.31393477,1.76553
10.96,45.66655,17.45534667,1.77995
11,45.83337,17.39032858,1.77332
11.04,46.00012,17.76484454,1.81151
11.08,46.16668,17.59185524,1.79387
11.12,46.3333,17.59715083,1.79441
11.16,46.49993,17.56675021,1.79131
11.2,46.66662,17.58714804,1.79339
11.24,46.83337,17.76209868,1.81123
11.28,47.00006,17.99157429,1.83463
11.32,47.16668,17.76190255,1.81121
11.36,47.33337,17.62666884,1.79742
11.4,47.50005,17.67609436,1.80246
11.44,47.66668,17.62500171,1.79725
11.48,47.83337,17.88281854,1.82354
11.52,48.00005,18.06041697,1.84165
11.56,48.16662,17.88164174,1.82342
11.6,48.33337,17.96950933,1.83238
11.64,48.50012,17.89635172,1.82492
11.68,48.66675,17.99196656,1.83467
11.72,48.83337,18.0667913,1.8423
11.76,48.99999,18.07375402,1.84301
11.8,49.16662,18.04198047,1.83977
11.84,49.33337,18.02707436,1.83825
11.88,49.50012,18.29459977,1.86553
11.92,49.66662,18.19143382,1.85501
11.96,49.83325,18.23929027,1.85989
12,49.99999,18.24497813,1.86047
12.04,50.16668,18.18937442,1.8548
12.08,50.33337,18.49857809,1.88633
12.12,50.50005,18.52633091,1.88916
12.16,50.66668,18.43248127,1.87959
12.2,50.83337,18.68529671,1.90537
12.24,50.99999,18.24997952,1.86098
12.28,51.16649,18.32460812,1.86859
12.32,51.33331,18.43316774,1.87966
12.36,51.50012,18.66097622,1.90289
12.4,51.66662,18.63802866,1.90055
12.44,51.83324,18.5363337,1.89018
12.48,51.99999,18.60233245,1.89691
12.52,52.16668,18.57310863,1.89393
12.56,52.33337,18.8706424,1.92427
12.6,52.50006,18.68392378,1.90523
12.64,52.66662,18.78032315,1.91506
12.68,52.83331,18.908398,1.92812
12.72,53.00005,18.8665236,1.92385
12.76,53.16674,18.93154169,1.93048
12.8,53.33337,18.85230396,1.9224
12.84,53.49999,18.92438284,1.92975
12.88,53.66662,18.8879021,1.92603
12.92,53.8333,19.01068136,1.93855
12.96,54.00012,18.98891059,1.93633
13,54.16668,19.03735545,1.94127
13.04,54.3333,19.20220523,1.95808
13.08,54.49993,19.26104513,1.96408
13.12,54.66662,19.15827144,1.9536
13.16,54.83337,19.14414986,1.95216
13.2,55.00006,19.40392802,1.97865
13.24,55.16662,19.29321094,1.96736
13.28,55.33325,19.20426463,1.95829
13.32,55.49999,19.31096098,1.96917
13.36,55.66668,19.28026617,1.96604
13.4,55.83343,19.64997687,2.00374
13.44,56.00005,19.59770743,1.99841
13.48,56.16656,19.41961866,1.98025
13.52,56.33324,19.52925701,1.99143
13.56,56.49999,19.66753077,2.00553
13.6,56.66668,19.69489133,2.00832
13.64,56.83336,19.68596728,2.00741
13.68,57.00005,19.77089287,2.01607
13.72,57.16662,19.54739931,1.99328
13.76,57.3333,19.7517699,2.01412
13.8,57.50006,19.68577114,2.00739
13.84,57.66668,19.90043871,2.02928
13.88,57.83337,19.92456307,2.03174
13.92,58.00006,19.71813309,2.01069
13.96,58.16662,19.82453524,2.02154
14,58.33324,19.83355736,2.02246
14.04,58.50011,19.98938503,2.03835
14.08,58.66674,20.00566407,2.04001
14.12,58.8333,20.04793073,2.04432
14.16,58.99993,20.05960064,2.04551
14.2,59.16668,19.90475364,2.02972
14.24,59.33343,20.10578996,2.05022
14.28,59.50006,20.17600558,2.05738
14.32,59.66655,20.11265462,2.05092
14.36,59.83324,20.15227348,2.05496
14.4,60.00006,20.18277217,2.05807
14.44,60.16668,20.19326528,2.05914
14.48,60.33343,20.45274924,2.0856
14.52,60.50006,20.36497972,2.07665
14.56,60.66662,20.35458467,2.07559
14.6,60.83325,20.31241608,2.07129
14.64,61.00005,20.54679501,2.09519
14.68,61.16668,20.49285844,2.08969
14.72,61.33337,20.25151678,2.06508
14.76,61.49999,20.43411661,2.0837
14.8,61.66662,20.45647577,2.08598
14.84,61.8333,20.8290304,2.12397
14.88,62.00012,20.71380226,2.11222
14.92,62.16668,20.59318047,2.09992
14.96,62.33331,20.72302051,2.11316
15,62.49999,20.81961602,2.12301
15.04,62.66668,20.85952908,2.12708
15.08,62.83336,20.81971408,2.12302
15.12,63.00006,20.74018215,2.11491
15.16,63.16661,21.01722001,2.14316
15.2,63.3333,21.10038041,2.15164
15.24,63.50006,20.92435104,2.13369
15.28,63.66668,20.97005003,2.13835
15.32,63.83337,20.92180131,2.13343
15.36,64.00005,20.98328901,2.1397
15.4,64.16667,21.08625883,2.1502
15.44,64.33337,21.01006116,2.14243
15.48,64.50005,21.05615241,2.14713
15.52,64.66662,21.0079037,2.14221
15.56,64.83336,21.1651043,2.15824
15.6,65.00005,21.2816073,2.17012
15.64,65.16661,21.48136876,2.19049
15.68,65.3333,21.32073583,2.17411
15.72,65.50005,21.34780219,2.17687
15.76,65.66667,21.38693072,2.18086
15.8,65.8333,21.45881346,2.18819
15.84,65.99999,21.38398872,2.18056
15.88,66.16655,21.39183404,2.18136
15.92,66.33336,21.59846016,2.20243
15.96,66.50012,21.655731,2.20827
16,66.66661,21.57041314,2.19957
16.04,66.83317,21.66298792,2.20901
16.08,66.99999,21.48764501,2.19113
16.12,67.16668,21.62748784,2.20539
16.16,67.33336,21.63945196,2.20661
16.2,67.50011,21.66592991,2.20931
16.24,67.66674,21.68838714,2.2116
16.28,67.83336,21.78194258,2.22114
16.32,67.99993,21.62886077,2.20553
16.36,68.16655,21.80381141,2.22337
16.4,68.33337,21.92874813,2.23611
16.44,68.50012,21.97101479,2.24042
16.48,68.66667,21.89697459,2.23287
16.52,68.8333,22.05201772,2.24868
16.56,69.00005,21.93727992,2.23698
16.6,69.16668,22.13762978,2.25741
16.64,69.33337,22.15606628,2.25929
16.68,69.49999,22.1627348,2.25997
16.72,69.66655,22.10193357,2.25377
16.76,69.8333,22.20274593,2.26405
16.8,70.00005,22.11389768,2.25499
16.84,70.16668,22.2212805,2.26594
16.88,70.3333,22.12684246,2.25631
16.92,70.49999,22.19117409,2.26287
16.96,70.66661,22.29012318,2.27296
17,70.8333,22.319347,2.27594
17.04,71.00006,22.50135843,2.2945
17.08,71.16668,22.58628401,2.30316
17.12,71.33331,22.76358825,2.32124
17.16,71.49999,22.58677435,2.30321
17.2,71.66661,22.50753661,2.29513
17.24,71.83337,22.65090984,2.30975
17.28,72.00005,22.74270008,2.31911
17.32,72.16667,22.77574849,2.32248
17.36,72.3333,22.6735632,2.31206
17.4,72.50005,22.65855902,2.31053
17.44,72.66674,22.75623326,2.32049
17.48,72.83343,22.83233286,2.32825
17.52,73.00005,22.76760897,2.32165
17.56,73.16662,22.94324607,2.33956
17.6,73.33324,22.99335806,2.34467
17.64,73.50005,23.07798945,2.3533
17.68,73.66668,22.88685784,2.33381
17.72,73.83343,22.87538406,2.33264
17.76,74.00006,22.94805133,2.34005
17.8,74.16661,23.06857506,2.35234
17.84,74.3333,23.11564698,2.35714
17.88,74.50006,23.19390405,2.36512
17.92,74.66668,23.19664991,2.3654
17.96,74.83337,23.24833096,2.37067
18,74.99999,23.38130913,2.38423
18.04,75.16656,23.12947436,2.35855
18.08,75.3333,23.1413404,2.35976
18.12,75.50012,23.23842624,2.36966
18.16,75.66668,23.33453141,2.37946
18.2,75.83324,23.30834765,2.37679
18.24,75.99992,23.42112413,2.38829
18.28,76.16668,23.48182729,2.39448
18.32,76.33343,23.54321692,2.40074
18.36,76.49999,23.63530136,2.41013
18.4,76.66649,23.71208743,2.41796
18.44,76.83324,23.65815086,2.41246
18.48,77.00011,23.59205404,2.40572
18.52,77.16668,23.6343207,2.41003
18.56,77.33336,23.70179045,2.41691
18.6,77.50005,23.70924351,2.41767
18.64,77.66661,23.95607689,2.44284
18.68,77.83331,23.66717298,2.41338
18.72,78.00005,23.72807227,2.41959
18.76,78.16668,23.87017063,2.43408
18.8,78.33336,23.85761812,2.4328
18.84,78.50005,23.92244008,2.43941
18.88,78.66668,23.94411277,2.44162
18.92,78.83336,23.92812793,2.43999
18.96,79.00012,23.8281001,2.42979
19,79.16667,24.03609915,2.451
19.04,79.3333,24.17672651,2.46534
19.08,79.49999,24.10602056,2.45813
19.12,79.66661,24.1240648,2.45997
19.16,79.83336,24.16809666,2.46446
19.2,80.00005,24.2016354,2.46788
19.24,80.16662,24.08699566,2.45619
19.28,80.3333,24.19143649,2.46684
19.32,80.49999,24.24096007,2.47189
19.36,80.66662,24.47749647,2.49601
19.4,80.83336,24.48092879,2.49636
19.44,81.00005,24.3228456,2.48024
19.48,81.16661,24.61822189,2.51036
19.52,81.3333,24.30970469,2.4789
19.56,81.49998,24.41542037,2.48968
19.6,81.66661,24.59586273,2.50808
19.64,81.83336,24.67519853,2.51617
19.68,81.99998,24.45788317,2.49401
19.72,82.16655,24.52290126,2.50064
19.76,82.33336,24.5558516,2.504
19.8,82.50011,24.77581476,2.52643
19.84,82.66673,24.65636976,2.51425
19.88,82.83329,24.91457886,2.54058
19.92,82.99999,24.94292008,2.54347
19.96,83.16661,24.66450928,2.51508
20,83.33342,24.86201521,2.53522
20.04,83.50012,24.8283784,2.53179
20.08,83.66661,24.83406626,2.53237
20.12,83.83323,24.88702217,2.53777
20.16,83.99999,25.10335687,2.55983
20.2,84.16668,25.08148804,2.5576
20.24,84.3333,25.04226144,2.5536
20.28,84.50005,25.08256677,2.55771
20.32,84.66667,25.32763496,2.5827
20.36,84.83336,25.30282413,2.58017
20.4,84.99992,25.25153535,2.57494
20.44,85.16661,25.10659306,2.56016
20.48,85.33336,25.17229762,2.56686
20.52,85.50012,25.22643033,2.57238
20.56,85.66661,25.26448013,2.57626
20.6,85.83331,25.48915048,2.59917
20.64,86.00005,25.41344314,2.59145
20.68,86.16667,25.43737137,2.59389
20.72,86.3333,25.64262455,2.61482
20.76,86.49998,25.56338682,2.60674
20.8,86.66655,25.45502334,2.59569
20.84,86.83329,25.52651382,2.60298
20.88,87.00005,25.57976393,2.60841
20.92,87.16667,25.63075851,2.61361
20.96,87.33337,25.86131285,2.63712
21,87.50005,25.70538711,2.62122
21.04,87.66661,25.65772679,2.61636
21.08,87.83337,25.91054223,2.64214
21.12,88.00011,25.98105204,2.64933
21.16,88.16668,25.70479871,2.62116
21.2,88.3333,25.94770943,2.64593
21.24,88.49998,25.90534471,2.64161
21.28,88.66668,26.01174686,2.65246
21.32,88.83336,26.06303564,2.65769
21.36,89.00011,26.00556867,2.65183
21.4,89.16655,26.07745141,2.65916
21.44,89.33323,26.27789934,2.6796
21.48,89.49999,26.10030091,2.66149
21.52,89.66668,26.30702509,2.68257
21.56,89.83342,26.2010152,2.67176
21.6,89.99999,26.33997543,2.68593
21.64,90.16655,26.24132054,2.67587
21.68,90.3333,26.39146035,2.69118
21.72,90.50005,26.19366022,2.67101
21.76,90.66667,26.51551447,2.70383
21.8,90.83336,26.44353366,2.69649
21.84,90.99999,26.90699594,2.74375
21.88,91.16654,26.5376775,2.70609
21.92,91.3333,26.56876458,2.70926
21.96,91.50005,26.51355314,2.70363
22,91.66667,26.61887656,2.71437
22.04,91.83336,26.90228875,2.74327
22.08,92.00005,26.81177337,2.73404
22.12,92.16661,26.64908104,2.71745
22.16,92.33336,26.61691523,2.71417
22.2,92.50017,26.80559518,2.73341
22.24,92.66668,26.72214059,2.7249
22.28,92.8333,26.86384668,2.73935
22.32,92.99998,27.08439824,2.76184
22.36,93.16674,27.02555834,2.75584
22.4,93.33342,27.00584697,2.75383
22.44,93.49999,27.01369229,2.75463
22.48,93.66655,27.08175044,2.76157
22.52,93.83329,27.03928765,2.75724
22.56,94.00005,27.12176157,2.76565
22.6,94.16667,27.04134704,2.75745
22.64,94.33337,26.99809972,2.75304
22.68,94.50004,27.09665655,2.76309
22.72,94.66661,27.19550758,2.77317
22.76,94.8333,27.31730617,2.78559
22.8,95.00004,27.11872151,2.76534
22.84,95.16668,27.41772627,2.79583
22.88,95.33335,27.44175256,2.79828
22.92,95.49998,27.39154251,2.79316
22.96,95.66661,27.5171657,2.80597
23,95.8333,27.42723872,2.7968
23.04,96.00011,27.5935595,2.81376
23.08,96.16661,27.6351397,2.818
23.12,96.33323,27.29082822,2.78289
23.16,96.49992,27.68868401,2.82346
23.2,96.66667,27.60974048,2.81541
23.24,96.83336,27.6574008,2.82027
23.28,97.00011,27.65043807,2.81956
23.32,97.16661,27.68868401,2.82346
23.36,97.3333,27.60454295,2.81488
23.4,97.50005,27.63925849,2.81842
23.44,97.66674,27.86334045,2.84127
23.48,97.83342,27.85745646,2.84067
23.52,98.00005,28.06055218,2.86138
23.56,98.16667,27.82372158,2.83723
23.6,98.33336,27.9123737,2.84627
23.64,98.5001,28.01661839,2.8569
23.68,98.66667,27.90452838,2.84547
23.72,98.83337,28.15028302,2.87053
23.76,98.99999,28.11645008,2.86708
23.8,99.16661,28.07604668,2.86296
23.84,99.33336,28.24805533,2.8805
23.88,99.50011,28.24207327,2.87989
23.92,99.66668,28.18970576,2.87455
23.96,99.8333,28.29983444,2.88578
24,99.99998,28.27502361,2.88325
24.04,100.16661,28.27257195,2.883
24.08,100.33336,28.36926552,2.89286
24.12,100.50011,28.40790372,2.8968
24.16,100.66655,28.48733759,2.9049
24.2,100.83323,28.48174779,2.90433
24.24,100.99999,28.5206802,2.9083
24.28,101.16667,28.4176123,2.89779
24.32,101.3333,28.67170261,2.9237
24.36,101.50004,28.5168556,2.90791
24.4,101.66667,28.59128808,2.9155
24.44,101.8333,28.76761164,2.93348
24.48,101.99992,28.78859787,2.93562
24.52,102.16661,28.84057312,2.94092
24.56,102.33343,29.05131803,2.96241
24.6,102.50011,28.96403884,2.95351
24.64,102.66662,28.76055085,2.93276
24.68,102.8333,29.04121718,2.96138
24.72,103.0001,28.90971,2.94797
24.76,103.16667,28.75829532,2.93253
24.8,103.33336,29.14114694,2.97157
24.84,103.49998,29.07652112,2.96498
24.88,103.66655,29.14350054,2.97181
24.92,103.8333,29.18272714,2.97581
24.96,104.00011,29.15252265,2.97273
25,104.16668,28.99640079,2.95681
25.04,104.3333,29.35640291,2.99352
25.08,104.49998,29.23705598,2.98135
25.12,104.66655,29.24362643,2.98202
25.16,104.83336,29.39317785,2.99727
25.2,105.00011,29.43240445,3.00127
25.24,105.16667,29.48006476,3.00613
25.28,105.33324,29.33502441,2.99134
25.32,105.49999,29.35395125,2.99327
25.36,105.66667,29.37376068,2.99529
25.4,105.83336,29.53213808,3.01144
25.44,106.00004,29.69885113,3.02844
25.48,106.16655,29.53782593,3.01202
25.52,106.33323,29.33423988,2.99126
25.56,106.50005,29.77975599,3.03669
25.6,106.66673,29.71983736,3.03058
25.64,106.83335,29.83202543,3.04202
25.68,106.99999,29.77828499,3.03654
25.72,107.16654,29.98530337,3.05765
25.76,107.33336,29.79476016,3.03822
25.8,107.50011,29.84624508,3.04347
25.84,107.66674,29.76230015,3.03491
25.88,107.83336,29.74180425,3.03282
25.92,108.00004,29.90528111,3.04949
25.96,108.16661,29.96088481,3.05516
26,108.3333,29.98030198,3.05714
26.04,108.50005,30.16888386,3.07637
26.08,108.66667,30.1655496,3.07603
26.12,108.83336,30.09974698,3.06932
26.16,108.99998,30.22841023,3.08244
26.2,109.16654,30.09955085,3.0693
26.24,109.33336,30.18212284,3.07772
26.28,109.5001,30.11582988,3.07096
26.32,109.66667,30.00040561,3.05919
26.36,109.83324,30.16074434,3.07554
26.4,109.99999,30.28548493,3.08826
26.44,110.16667,30.23743234,3.08336
26.48,110.33342,30.34050024,3.09387
26.52,110.49992,30.16966839,3.07645
26.56,110.66649,30.46131816,3.10619
26.6,110.8333,30.39296581,3.09922
26.64,111.00005,30.62754088,3.12314
26.68,111.16668,30.46347563,3.10641
26.72,111.33336,30.48985552,3.1091
26.76,111.49999,30.6184207,3.12221
26.8,111.66655,30.68667498,3.12917
26.84,111.8333,30.56203246,3.11646
26.88,112.00011,30.62832541,3.12322
26.92,112.16667,30.56232666,3.11649
26.96,112.3333,30.48769805,3.10888
27,112.50004,30.64489865,3.12491
27.04,112.66667,30.63999533,3.12441
27.08,112.83342,30.79268487,3.13998
27.12,113.00012,30.55918853,3.11617
27.16,113.16661,30.61332124,3.12169
27.2,113.33324,30.68922471,3.12943
27.24,113.49998,30.50642875,3.11079
27.28,113.66667,30.7949404,3.14021
27.32,113.83336,30.72560738,3.13314
27.36,114.00005,30.61253671,3.12161
27.4,114.16661,30.45533611,3.10558
27.44,114.33329,30.54290949,3.11451
27.48,114.50005,30.36550719,3.09642
27.52,114.66661,30.37276411,3.09716
27.56,114.8333,30.34559969,3.09439
27.6,115.00005,6.901528004,0.70376
27.64,115.16668,-2.494321428,-0.25435
27.68,115.33336,-1.070395848,-0.10915
27.72,115.49998,-1.239168294,-0.12636
27.76,115.66667,-1.119036832,-0.11411
27.8,115.83336,-1.387837108,-0.14152
27.84,115.99999,-1.287024746,-0.13124
27.88,116.16655,-0.920059903,-0.09382
27.92,116.33329,-1.262017789,-0.12869
27.96,116.50004,-1.238285696,-0.12627
28,116.66667,-1.328016543,-0.13542
28.04,116.8333,-1.124724689,-0.11469
28.08,116.99999,-1.13561007,-0.1158
28.12,117.16668,-1.299577258,-0.13252
28.16,117.33342,-1.154634971,-0.11774
28.2,117.50011,-1.324780349,-0.13509
28.24,117.66661,-1.137767533,-0.11602
28.28,117.8333,-1.227596447,-0.12518
28.32,118.00005,-1.414903462,-0.14428
28.36,118.16667,-1.319582824,-0.13456
28.4,118.33336,-1.100698396,-0.11224
28.44,118.50005,-1.052743878,-0.10735
28.48,118.66667,-1.122567226,-0.11447
28.52,118.8333,-0.969093153,-0.09882
28.56,118.99993,-0.983803128,-0.10032
28.6,119.16667,-1.165226153,-0.11882
28.64,119.33336,-1.241227691,-0.12657
28.68,119.50005,-1.218378196,-0.12424
28.72,119.66655,-1.184447187,-0.12078
28.76,119.83329,-1.02381426,-0.1044
28.8,120.00011,-1.042152696,-0.10627
28.84,120.16667,-1.361947552,-0.13888
28.88,120.33329,-1.188075648,-0.12115
28.92,120.49999,-1.198176497,-0.12218
28.96,120.66661,-1.28467115,-0.131
29,120.83329,-1.184349121,-0.12077
29.04,121.00005,-1.09246081,-0.1114
29.08,121.16667,-1.13002028,-0.11523
29.12,121.3333,-1.095304739,-0.11169
29.16,121.49998,-1.244758085,-0.12693
29.2,121.6666,-1.252897604,-0.12776
29.24,121.83336,-1.135708137,-0.11581
29.28,122.00011,-1.289770608,-0.13152
29.32,122.16668,-1.137669467,-0.11601
29.36,122.3333,-1.306147714,-0.13319
29.4,122.50005,-1.281533022,-0.13068
29.44,122.66673,-1.030580849,-0.10509
29.48,122.83336,-1.152281375,-0.1175
29.52,123.00004,-1.180426461,-0.12037
29.56,123.16661,-1.226517716,-0.12507
29.578,123.24173,-1.243090954,-0.12676