File: EPR/EPR/RDSO EPR Tensile Multi.is_tens_RawData/Specimen_RawData_2.csv
Time,Extension,Load,Tensile strain,Tensile stress,Corrected Position
(sec),(mm),(N),(mm/mm),(MPa),(mm)
0.00000,0.00000,-0.02675,0.00000,-0.00297,0.00000
0.39000,0.32475,1.01001,0.00282,0.11222,0.32475
0.78000,0.65006,1.82446,0.00565,0.20272,0.65006
1.17000,0.97506,2.26403,0.00848,0.25156,0.97506
1.56000,1.30006,2.66931,0.01130,0.29659,1.30006
1.95000,1.62506,2.93288,0.01413,0.32588,1.62506
2.34000,1.94994,3.45572,0.01696,0.38397,1.94994
2.73000,2.27506,3.82598,0.01978,0.42511,2.27506
3.12000,2.60006,4.09526,0.02261,0.45503,2.60006
3.51000,2.92506,4.45283,0.02544,0.49476,2.92506
3.90000,3.25006,4.49872,0.02826,0.49986,3.25006
4.29000,3.57500,4.81365,0.03109,0.53485,3.57500
4.68000,3.90000,5.19591,0.03391,0.57732,3.90000
5.07000,4.22512,5.58978,0.03674,0.62109,4.22512
5.46000,4.55006,5.79634,0.03957,0.64404,4.55006
5.85000,4.87506,5.88162,0.04239,0.65351,4.87506
6.24000,5.20006,6.27925,0.04522,0.69769,5.20006
6.63000,5.52487,6.43215,0.04804,0.71468,5.52487
7.02000,5.85012,6.60611,0.05087,0.73401,5.85012
7.41000,6.17506,6.82670,0.05370,0.75852,6.17506
7.80000,6.50000,7.15961,0.05652,0.79551,6.50000
8.19000,6.82500,7.19471,0.05935,0.79941,6.82500
8.58000,7.15006,7.46024,0.06217,0.82892,7.15006
8.97000,7.47506,7.51691,0.06500,0.83521,7.47506
9.36000,7.80012,7.98153,0.06783,0.88684,7.80012
9.75000,8.12500,7.98141,0.07065,0.88682,8.12500
10.14000,8.45006,8.11829,0.07348,0.90203,8.45006
10.53000,8.77500,8.09424,0.07630,0.89936,8.77500
10.92000,9.10000,8.36551,0.07913,0.92950,9.10000
11.31000,9.42519,8.76067,0.08196,0.97341,9.42519
11.70000,9.75006,8.61385,0.08478,0.95709,9.75006
12.09000,10.07494,8.79638,0.08761,0.97738,10.07494
12.48000,10.40012,8.86718,0.09044,0.98524,10.40012
12.87000,10.72506,9.11655,0.09326,1.01295,10.72506
13.26000,11.05006,9.28250,0.09609,1.03139,11.05006
13.65000,11.37506,9.41706,0.09891,1.04634,11.37506
14.04000,11.69994,9.55754,0.10174,1.06195,11.69994
14.43000,12.02506,9.49665,0.10457,1.05518,12.02506
14.82000,12.35012,9.59447,0.10739,1.06605,12.35012
15.21000,12.67506,9.93794,0.11022,1.10422,12.67506
15.60000,13.00006,9.94996,0.11304,1.10555,13.00006
15.99000,13.32500,10.11814,0.11587,1.12424,13.32500
16.38000,13.65000,10.16610,0.11870,1.12957,13.65000
16.77000,13.97512,10.30873,0.12152,1.14541,13.97512
17.16000,14.30006,10.41591,0.12435,1.15732,14.30006
17.55000,14.62500,10.69709,0.12717,1.18857,14.62500
17.94000,14.95006,10.73267,0.13000,1.19252,14.95006
18.33000,15.27500,10.78824,0.13283,1.19869,15.27500
18.72000,15.60006,10.87237,0.13565,1.20804,15.60006
19.11000,15.92512,11.16541,0.13848,1.24060,15.92512
19.50000,16.25006,11.17613,0.14130,1.24179,16.25006
19.89000,16.57500,11.22421,0.14413,1.24713,16.57500
20.28000,16.90006,11.61688,0.14696,1.29076,16.90006
20.67000,17.22500,11.75599,0.14978,1.30622,17.22500
21.06000,17.55006,11.82792,0.15261,1.31421,17.55006
21.45000,17.87506,11.77960,0.15544,1.30884,17.87506
21.84000,18.20000,11.90269,0.15826,1.32252,18.20000
22.23000,18.52512,12.16288,0.16109,1.35143,18.52512
22.62000,18.85006,12.24841,0.16391,1.36093,18.85006
23.01000,19.17506,12.30545,0.16674,1.36727,19.17506
23.40000,19.50012,12.54727,0.16957,1.39414,19.50012
23.79000,19.82500,12.63245,0.17239,1.40361,19.82500
24.18000,20.15006,12.70333,0.17522,1.41148,20.15006
24.57000,20.47506,12.81346,0.17804,1.42372,20.47506
24.96000,20.80000,12.67448,0.18087,1.40828,20.80000
25.35000,21.12512,12.85476,0.18370,1.42831,21.12512
25.74000,21.45000,13.07471,0.18652,1.45275,21.45000
26.13000,21.77500,13.05669,0.18935,1.45074,21.77500
26.52000,22.10018,13.08843,0.19218,1.45427,22.10018
26.91000,22.42506,13.26601,0.19500,1.47400,22.42506
27.30000,22.75006,13.40561,0.19783,1.48951,22.75006
27.69000,23.07500,13.61161,0.20065,1.51240,23.07500
28.08000,23.40000,13.69644,0.20348,1.52183,23.40000
28.47000,23.72512,13.64776,0.20631,1.51642,23.72512
28.86000,24.05006,13.76291,0.20913,1.52921,24.05006
29.25000,24.37500,13.76583,0.21196,1.52954,24.37500
29.64000,24.70006,13.78096,0.21478,1.53122,24.70006
30.03000,25.02500,13.87369,0.21761,1.54152,25.02500
30.42000,25.35012,14.11882,0.22044,1.56876,25.35012
30.81000,25.67512,14.02362,0.22326,1.55818,25.67512
31.20000,26.00000,14.35501,0.22609,1.59500,26.00000
31.59000,26.32500,14.14617,0.22891,1.57180,26.32500
31.98000,26.65012,14.21335,0.23174,1.57926,26.65012
32.37000,26.97499,14.37989,0.23457,1.59777,26.97499
32.76000,27.30006,14.39895,0.23739,1.59988,27.30006
33.15000,27.62506,14.49645,0.24022,1.61072,27.62506
33.54000,27.95000,14.73739,0.24304,1.63749,27.95000
33.93000,28.27506,14.49757,0.24587,1.61084,28.27506
34.32000,28.60000,14.71030,0.24870,1.63448,28.60000
34.71000,28.92512,14.79338,0.25152,1.64371,28.92512
35.10000,29.25012,14.78253,0.25435,1.64250,29.25012
35.49000,29.57500,14.88275,0.25717,1.65364,29.57500
35.88000,29.90006,14.88049,0.26000,1.65339,29.90006
36.27000,30.22512,14.92308,0.26283,1.65812,30.22512
36.66000,30.55006,14.95166,0.26565,1.66130,30.55006
37.05000,30.87500,15.09065,0.26848,1.67674,30.87500
37.44000,31.20006,15.21384,0.27130,1.69043,31.20006
37.83000,31.52499,15.30392,0.27413,1.70044,31.52499
38.22000,31.85006,15.24686,0.27696,1.69410,31.85006
38.61000,32.17506,15.35773,0.27978,1.70641,32.17506
39.00000,32.50006,15.47560,0.28261,1.71951,32.50006
39.39000,32.82506,15.39821,0.28544,1.71091,32.82506
39.78000,33.15000,15.71248,0.28826,1.74583,33.15000
40.17000,33.47512,15.69921,0.29109,1.74436,33.47512
40.56000,33.80012,15.76195,0.29391,1.75133,33.80012
40.95000,34.12499,15.84133,0.29674,1.76015,34.12499
41.34000,34.45006,15.79007,0.29957,1.75445,34.45006
41.73000,34.77506,15.98274,0.30239,1.77586,34.77506
42.12000,35.09999,16.00584,0.30522,1.77843,35.09999
42.51000,35.42512,16.13591,0.30804,1.79288,35.42512
42.90000,35.75006,16.18932,0.31087,1.79881,35.75006
43.29000,36.07500,16.24896,0.31370,1.80544,36.07500
43.68000,36.40012,16.27477,0.31652,1.80831,36.40012
44.07000,36.72505,16.25577,0.31935,1.80620,36.72505
44.46000,37.05006,16.34920,0.32217,1.81658,37.05006
44.85000,37.37506,16.44966,0.32500,1.82774,37.37506
45.24000,37.69993,16.66347,0.32783,1.85150,37.69993
45.63000,38.02506,16.75380,0.33065,1.86153,38.02506
46.02000,38.35012,16.79408,0.33348,1.86601,38.35012
46.41000,38.67506,16.83337,0.33630,1.87037,38.67506
46.80000,39.00006,17.00505,0.33913,1.88945,39.00006
47.19000,39.32506,16.88022,0.34196,1.87558,39.32506
47.58000,39.65006,16.92651,0.34478,1.88072,39.65006
47.97000,39.97512,16.90072,0.34761,1.87786,39.97512
48.36000,40.29999,17.08058,0.35043,1.89784,40.29999
48.75000,40.62506,17.12026,0.35326,1.90225,40.62506
49.14000,40.95005,17.25797,0.35609,1.91755,40.95005
49.53000,41.27499,17.28440,0.35891,1.92049,41.27499
49.92000,41.60006,17.51211,0.36174,1.94579,41.60006
50.31000,41.92505,17.57094,0.36457,1.95233,41.92505
50.70000,42.24999,17.59127,0.36739,1.95459,42.24999
51.09000,42.57499,17.58718,0.37022,1.95413,42.57499
51.48000,42.90000,17.68184,0.37304,1.96465,42.90000
51.87000,43.22506,17.65188,0.37587,1.96132,43.22506
52.26000,43.55012,17.90069,0.37870,1.98897,43.55012
52.65000,43.87506,18.11653,0.38152,2.01295,43.87506
53.04000,44.20000,17.86876,0.38435,1.98542,44.20000
53.43000,44.52506,18.10879,0.38717,2.01209,44.52506
53.82000,44.85006,18.16059,0.39000,2.01784,44.85006
54.21000,45.17518,17.95722,0.39283,1.99525,45.17518
54.60000,45.50005,18.20926,0.39565,2.02325,45.50005
54.99000,45.82493,18.29823,0.39848,2.03314,45.82493
55.38000,46.15012,18.61035,0.40131,2.06782,46.15012
55.77000,46.47505,18.58439,0.40413,2.06493,46.47505
56.16000,46.79999,18.59786,0.40696,2.06643,46.79999
56.55000,47.12512,18.59759,0.40978,2.06640,47.12512
56.94000,47.44993,18.69609,0.41261,2.07734,47.44993
57.33000,47.77499,18.69340,0.41543,2.07704,47.77499
57.72000,48.10011,19.03115,0.41826,2.11457,48.10011
58.11000,48.42505,19.08266,0.42109,2.12030,48.42505
58.50000,48.75006,19.14026,0.42391,2.12670,48.75006
58.89000,49.07506,19.31219,0.42674,2.14580,49.07506
59.28000,49.39999,19.17908,0.42957,2.13101,49.39999
59.67000,49.72518,19.27979,0.43239,2.14220,49.72518
60.06000,50.05006,19.35924,0.43522,2.15103,50.05006
60.45000,50.37500,19.41777,0.43804,2.15753,50.37500
60.84000,50.70006,19.62639,0.44087,2.18071,50.70006
61.23000,51.02499,19.60483,0.44370,2.17831,51.02499
61.62000,51.35012,19.85104,0.44652,2.20567,51.35012
62.01000,51.67512,19.71352,0.44935,2.19039,51.67512
62.40000,51.99999,19.96169,0.45217,2.21797,51.99999
62.79000,52.32512,19.83184,0.45500,2.20354,52.32512
63.18000,52.65005,20.05841,0.45783,2.22871,52.65005
63.57000,52.97506,20.01920,0.46065,2.22436,52.97506
63.96000,53.30012,20.08386,0.46348,2.23154,53.30012
64.35001,53.62500,20.44042,0.46630,2.27116,53.62500
64.74000,53.94999,20.34696,0.46913,2.26077,53.94999
65.13000,54.27506,20.33655,0.47196,2.25962,54.27506
65.52000,54.60005,20.58666,0.47478,2.28741,54.60005
65.91000,54.92512,20.70047,0.47761,2.30005,54.92512
66.30000,55.25006,20.73155,0.48044,2.30351,55.25006
66.69000,55.57499,20.82427,0.48326,2.31381,55.57499
67.08000,55.90005,20.97362,0.48609,2.33040,55.90005
67.47000,56.22506,21.07538,0.48891,2.34171,56.22506
67.86000,56.55006,21.04734,0.49174,2.33859,56.55006
68.25000,56.87505,21.34961,0.49457,2.37218,56.87505
68.64001,57.19993,21.30579,0.49739,2.36731,57.19993
69.03001,57.52506,21.33180,0.50022,2.37020,57.52506
69.42001,57.85012,21.35098,0.50304,2.37233,57.85012
69.81001,58.17506,21.51906,0.50587,2.39101,58.17506
70.20001,58.50005,21.58815,0.50870,2.39868,58.50005
70.59001,58.82499,21.57444,0.51152,2.39716,58.82499
70.98000,59.15005,21.72880,0.51435,2.41431,59.15005
71.37000,59.47512,22.09556,0.51717,2.45506,59.47512
71.76000,59.80005,22.20569,0.52000,2.46730,59.80005
72.15000,60.12493,22.24187,0.52283,2.47132,60.12493
72.54000,60.45006,22.23166,0.52565,2.47018,60.45006
72.93000,60.77499,22.16053,0.52848,2.46228,60.77499
73.32000,61.10006,22.47304,0.53130,2.49700,61.10006
73.71001,61.42518,22.27976,0.53413,2.47553,61.42518
74.10001,61.74999,22.45149,0.53696,2.49461,61.74999
74.49001,62.07499,22.57211,0.53978,2.50801,62.07499
74.88001,62.40006,22.64685,0.54261,2.51632,62.40006
75.27001,62.72506,22.73502,0.54544,2.52611,62.72506
75.66000,63.05011,22.77315,0.54826,2.53035,63.05011
76.05000,63.37499,23.00726,0.55109,2.55636,63.37499
76.44000,63.69993,22.94298,0.55391,2.54922,63.69993
76.83000,64.02511,23.21199,0.55674,2.57911,64.02511
77.22000,64.35005,23.20777,0.55957,2.57864,64.35005
77.61000,64.67511,23.26090,0.56239,2.58454,64.67511
78.00000,65.00012,23.41771,0.56522,2.60197,65.00012
78.39001,65.32493,23.60691,0.56804,2.62299,65.32493
78.78001,65.65006,23.53794,0.57087,2.61533,65.65006
79.17001,65.97505,23.66823,0.57370,2.62980,65.97505
79.56001,66.30005,24.03518,0.57652,2.67058,66.30005
79.95001,66.62511,23.76145,0.57935,2.64016,66.62511
80.34001,66.95006,23.91655,0.58217,2.65739,66.95006
80.73000,67.27493,24.05556,0.58500,2.67284,67.27493
81.12000,67.60012,24.18700,0.58783,2.68744,67.60012
81.51000,67.92511,24.10195,0.59065,2.67799,67.92511
81.90000,68.25005,24.24061,0.59348,2.69340,68.25005
82.29000,68.57499,24.43461,0.59630,2.71496,68.57499
82.68000,68.89999,24.69025,0.59913,2.74336,68.89999
83.07001,69.22511,24.61117,0.60196,2.73457,69.22511
83.46001,69.55018,24.72549,0.60478,2.74728,69.55018
83.85001,69.87499,24.69794,0.60761,2.74422,69.87499
84.24001,70.19999,25.13422,0.61043,2.79269,70.19999
84.63001,70.52499,25.13001,0.61326,2.79222,70.52499
85.02001,70.85005,25.25638,0.61609,2.80626,70.85005
85.41000,71.17511,25.03283,0.61891,2.78143,71.17511
85.80000,71.49999,25.52943,0.62174,2.83660,71.49999
86.19000,71.82499,25.07711,0.62457,2.78635,71.82499
86.58000,72.15005,25.48479,0.62739,2.83164,72.15005
86.97000,72.47505,25.50215,0.63022,2.83357,72.47505
87.36000,72.80005,25.85363,0.63304,2.87263,72.80005
87.75001,73.12505,25.91836,0.63587,2.87982,73.12505
88.14001,73.44999,25.66396,0.63870,2.85155,73.44999
88.53001,73.77499,25.96024,0.64152,2.88447,73.77499
88.92001,74.10006,26.12300,0.64435,2.90256,74.10006
89.31001,74.42505,26.14394,0.64717,2.90488,74.42505
89.70001,74.75005,26.10704,0.65000,2.90078,74.75005
90.09001,75.07499,26.35863,0.65283,2.92874,75.07499
90.48000,75.40006,26.36424,0.65565,2.92936,75.40006
90.87000,75.72512,26.65466,0.65848,2.96163,75.72512
91.26000,76.04999,26.52725,0.66130,2.94747,76.04999
91.65000,76.37505,26.83655,0.66413,2.98184,76.37505
92.04000,76.70005,26.81529,0.66696,2.97948,76.70005
92.43001,77.02499,26.96295,0.66978,2.99588,77.02499
92.82001,77.35012,26.95071,0.67261,2.99452,77.35012
93.21001,77.67505,27.09670,0.67544,3.01074,77.67505
93.60001,78.00005,27.07884,0.67826,3.00876,78.00005
93.99001,78.32498,27.34577,0.68109,3.03842,78.32498
94.38001,78.64999,27.42160,0.68391,3.04684,78.64999
94.77001,78.97511,27.46137,0.68674,3.05126,78.97511
95.16000,79.30011,27.67141,0.68957,3.07460,79.30011
95.55000,79.62499,27.54660,0.69239,3.06073,79.62499
95.94000,79.95005,27.85406,0.69522,3.09490,79.95005
96.33000,80.27505,27.96557,0.69804,3.10729,80.27505
96.72000,80.59992,28.08611,0.70087,3.12068,80.59992
97.11001,80.92511,28.13510,0.70370,3.12612,80.92511
97.50001,81.25004,28.34415,0.70652,3.14935,81.25004
97.89001,81.57493,28.16328,0.70935,3.12925,81.57493
98.28001,81.90005,28.47998,0.71217,3.16444,81.90005
98.67001,82.22511,28.50016,0.71500,3.16668,82.22511
99.06001,82.55005,28.53398,0.71783,3.17044,82.55005
99.45001,82.87505,28.82611,0.72065,3.20290,82.87505
99.84001,83.19993,28.88776,0.72348,3.20975,83.19993
100.23000,83.52505,28.93904,0.72630,3.21545,83.52505
100.62000,83.85004,28.97054,0.72913,3.21895,83.85004
101.01000,84.17505,29.15971,0.73196,3.23997,84.17505
101.40000,84.50005,29.13433,0.73478,3.23715,84.50005
101.79001,84.82506,29.35453,0.73761,3.26161,84.82506
102.18001,85.14998,29.46590,0.74043,3.27399,85.14998
102.57001,85.47512,29.48125,0.74326,3.27569,85.47512
102.96001,85.80005,29.69969,0.74609,3.29997,85.80005
103.35001,86.12505,29.62234,0.74891,3.29137,86.12505
103.74001,86.45005,29.91038,0.75174,3.32338,86.45005
104.13001,86.77498,29.87921,0.75457,3.31991,86.77498
104.52001,87.09999,30.03311,0.75739,3.33701,87.09999
104.91000,87.42511,30.13365,0.76022,3.34818,87.42511
105.30000,87.75004,30.15145,0.76304,3.35016,87.75004
105.69000,88.07499,30.27616,0.76587,3.36402,88.07499
106.08000,88.40005,30.38368,0.76870,3.37596,88.40005
106.47001,88.72511,30.47047,0.77152,3.38561,88.72511
106.86001,89.05006,30.55230,0.77435,3.39470,89.05006
107.25001,89.37499,30.78154,0.77717,3.42017,89.37499
107.64001,89.70005,30.86554,0.78000,3.42950,89.70005
108.03001,90.02505,30.91744,0.78283,3.43527,90.02505
108.42001,90.34999,30.93737,0.78565,3.43749,90.34999
108.81001,90.67511,31.05101,0.78848,3.45011,90.67511
109.20001,91.00005,31.33670,0.79130,3.48186,91.00005
109.59001,91.32498,31.17976,0.79413,3.46442,91.32498
109.98000,91.65011,31.33699,0.79696,3.48189,91.65011
110.37000,91.97504,31.56599,0.79978,3.50733,91.97504
110.76000,92.29999,31.49685,0.80261,3.49965,92.29999
111.15000,92.62505,31.68844,0.80544,3.52094,92.62505
111.54001,92.94999,31.90671,0.80826,3.54519,92.94999
111.93001,93.27505,31.79811,0.81109,3.53312,93.27505
112.32001,93.60005,32.07555,0.81391,3.56395,93.60005
112.71001,93.92505,32.13227,0.81674,3.57025,93.92505
113.10001,94.25011,32.22005,0.81957,3.58001,94.25011
113.49001,94.57499,32.27976,0.82239,3.58664,94.57499
113.88001,94.89998,32.33182,0.82522,3.59242,94.89998
114.27001,95.22517,32.48705,0.82804,3.60967,95.22517
114.66000,95.55005,32.54245,0.83087,3.61583,95.55005
115.05000,95.87498,32.60436,0.83370,3.62271,95.87498
115.44000,96.20004,32.74489,0.83652,3.63832,96.20004
115.83000,96.52499,32.83796,0.83935,3.64866,96.52499
116.22001,96.85005,33.07445,0.84217,3.67494,96.85005
116.61001,97.17517,33.04290,0.84500,3.67143,97.17517
117.00001,97.49998,33.34150,0.84783,3.70461,97.49998
117.39001,97.82499,33.36398,0.85065,3.70711,97.82499
117.78001,98.15005,33.45915,0.85348,3.71768,98.15005
118.17001,98.47505,33.40841,0.85630,3.71205,98.47505
118.56001,98.80004,33.87501,0.85913,3.76389,98.80004
118.95001,99.12498,33.82304,0.86196,3.75812,99.12498
119.34001,99.44992,33.94290,0.86478,3.77143,99.44992
119.73000,99.77505,33.93526,0.86761,3.77058,99.77505
120.12000,100.10004,34.11600,0.87044,3.79067,100.10004
120.51000,100.42504,34.23493,0.87326,3.80388,100.42504
120.90001,100.75005,34.18967,0.87609,3.79885,100.75005
121.29001,101.07499,34.37639,0.87891,3.81960,101.07499
121.68001,101.40005,34.81293,0.88174,3.86810,101.40005
122.07001,101.72511,34.62846,0.88457,3.84761,101.72511
122.46001,102.05004,34.70737,0.88739,3.85637,102.05004
122.85001,102.37498,34.68596,0.89022,3.85400,102.37498
123.24001,102.69999,34.90149,0.89304,3.87794,102.69999
123.63001,103.02499,34.95615,0.89587,3.88402,103.02499
124.02001,103.35010,35.04784,0.89870,3.89420,103.35010
124.41000,103.67511,35.15090,0.90152,3.90566,103.67511
124.80000,103.99998,35.32724,0.90435,3.92525,103.99998
125.19000,104.32504,35.44578,0.90717,3.93842,104.32504
125.58001,104.64999,35.59561,0.91000,3.95507,104.64999
125.97001,104.97510,35.45925,0.91283,3.93992,104.97510
126.36001,105.30011,35.66786,0.91565,3.96310,105.30011
126.75001,105.62498,35.64704,0.91848,3.96078,105.62498
127.14001,105.95005,35.91150,0.92130,3.99017,105.95005
127.53001,106.27499,35.89881,0.92413,3.98876,106.27499
127.92001,106.60005,36.15646,0.92696,4.01738,106.60005
128.31002,106.92517,35.99438,0.92978,3.99938,106.92517
128.70002,107.24999,36.33755,0.93261,4.03751,107.24999
129.09001,107.57498,36.47489,0.93543,4.05277,107.57498
129.48001,107.90011,36.57124,0.93826,4.06347,107.90011
129.87001,108.22505,36.52696,0.94109,4.05855,108.22505
130.26001,108.55004,36.52103,0.94391,4.05789,108.55004
130.65001,108.87499,36.80670,0.94674,4.08963,108.87499
131.04001,109.19998,36.90432,0.94957,4.10048,109.19998
131.43002,109.52511,36.99435,0.95239,4.11048,109.52511
131.82000,109.85005,37.11852,0.95522,4.12428,109.85005
132.21000,110.17511,37.33135,0.95804,4.14793,110.17511
132.60000,110.50005,37.24925,0.96087,4.13881,110.50005
132.99000,110.82493,37.35746,0.96370,4.15083,110.82493
133.38000,111.15004,37.47423,0.96652,4.16380,111.15004
133.77000,111.47510,37.73256,0.96935,4.19251,111.47510
134.16000,111.79999,37.61334,0.97217,4.17926,111.79999
134.55000,112.12505,37.83831,0.97500,4.20426,112.12505
134.94000,112.45005,37.91977,0.97783,4.21331,112.45005
135.33000,112.77499,37.80682,0.98065,4.20076,112.77499
135.72000,113.10005,38.27744,0.98348,4.25305,113.10005
136.11000,113.42505,38.32417,0.98630,4.25824,113.42505
136.50000,113.75004,38.47107,0.98913,4.27456,113.75004
136.89000,114.07498,38.18487,0.99196,4.24276,114.07498
137.28002,114.39999,38.53088,0.99478,4.28121,114.39999
137.67002,114.72511,38.53984,0.99761,4.28220,114.72511
138.06002,115.05011,38.52612,1.00044,4.28068,115.05011
138.45002,115.37499,38.95452,1.00326,4.32828,115.37499
138.84002,115.69999,38.89746,1.00609,4.32194,115.69999
139.23002,116.02499,39.11563,1.00891,4.34618,116.02499
139.62002,116.35005,39.15422,1.01174,4.35047,116.35005
140.01002,116.67517,39.33154,1.01457,4.37017,116.67517
140.40002,116.99999,39.20762,1.01739,4.35640,116.99999
140.79002,117.32493,39.47070,1.02022,4.38563,117.32493
141.18002,117.65005,39.49460,1.02304,4.38829,117.65005
141.57000,117.97504,39.62827,1.02587,4.40314,117.97504
141.96000,118.30010,39.71135,1.02870,4.41237,118.30010
142.35000,118.62505,39.78810,1.03152,4.42090,118.62505
142.74000,118.94993,39.95543,1.03435,4.43949,118.94993
143.13000,119.27504,39.96302,1.03717,4.44034,119.27504
143.52000,119.60011,40.19715,1.04000,4.46635,119.60011
143.91000,119.92505,40.09801,1.04283,4.45534,119.92505
144.30000,120.25005,40.31089,1.04565,4.47899,120.25005
144.69000,120.57498,40.20587,1.04848,4.46732,120.57498
145.08000,120.89998,40.21038,1.05130,4.46782,120.89998
145.47000,121.22517,40.56844,1.05413,4.50760,121.22517
145.86000,121.55005,40.66288,1.05696,4.51810,121.55005
146.25000,121.87504,40.86689,1.05978,4.54077,121.87504
146.64000,122.20005,40.79381,1.06261,4.53265,122.20005
147.03002,122.52492,40.88575,1.06543,4.54286,122.52492
147.42002,122.85011,40.96334,1.06826,4.55148,122.85011
147.81002,123.17511,40.98342,1.07109,4.55371,123.17511
148.20002,123.49999,41.05131,1.07391,4.56126,123.49999
148.59002,123.82505,41.46937,1.07674,4.60771,123.82505
148.98002,124.15005,41.37219,1.07957,4.59691,124.15005
149.37002,124.47505,41.46070,1.08239,4.60674,124.47505
149.76002,124.80005,41.67079,1.08522,4.63009,124.80005
150.15002,125.12498,41.72467,1.08804,4.63607,125.12498
150.54002,125.45004,41.76576,1.09087,4.64064,125.45004
150.93002,125.77504,41.88097,1.09370,4.65344,125.77504
151.32000,126.09998,41.74152,1.09652,4.63795,126.09998
151.71000,126.42517,41.98418,1.09935,4.66491,126.42517
152.10000,126.75004,42.08126,1.10217,4.67570,126.75004
152.49000,127.07491,42.30697,1.10500,4.70077,127.07491
152.88000,127.40004,42.48041,1.10783,4.72005,127.40004
153.27000,127.72503,42.49682,1.11065,4.72187,127.72503
153.66000,128.05005,42.53238,1.11348,4.72582,128.05005
154.05000,128.37504,42.57906,1.11630,4.73101,128.37504
154.44000,128.69991,42.75540,1.11913,4.75060,128.69991
154.83000,129.02498,42.82118,1.12196,4.75791,129.02498
155.22000,129.35004,42.95731,1.12478,4.77303,129.35004
155.61000,129.67511,42.74693,1.12761,4.74966,129.67511
156.00000,130.00011,43.10827,1.13044,4.78981,130.00011
156.39002,130.32498,43.29626,1.13326,4.81070,130.32498
156.78002,130.64998,43.11072,1.13609,4.79008,130.64998
157.17002,130.97510,43.51928,1.13891,4.83548,130.97510
157.56002,131.30005,43.61989,1.14174,4.84665,131.30005
157.95002,131.62498,43.65276,1.14457,4.85031,131.62498
158.34002,131.95003,43.84918,1.14739,4.87213,131.95003
158.73002,132.27505,43.89517,1.15022,4.87724,132.27505
159.12002,132.60010,44.15600,1.15304,4.90622,132.60010
159.51002,132.92511,43.94807,1.15587,4.88312,132.92511
159.90002,133.24998,44.17466,1.15870,4.90830,133.24998
160.29002,133.57504,44.13396,1.16152,4.90377,133.57504
160.68002,133.90005,44.29428,1.16435,4.92159,133.90005
161.07000,134.22504,44.30613,1.16717,4.92290,134.22504
161.46000,134.55017,44.43564,1.17000,4.93729,134.55017
161.85000,134.87498,44.65665,1.17283,4.96185,134.87498
162.24000,135.19992,44.72806,1.17565,4.96978,135.19992
162.63000,135.52511,44.80937,1.17848,4.97882,135.52511
163.02000,135.85004,44.72596,1.18130,4.96955,135.85004
163.41000,136.17510,45.03459,1.18413,5.00384,136.17510
163.80000,136.50010,45.13746,1.18696,5.01527,136.50010
164.19000,136.82499,45.21103,1.18978,5.02345,136.82499
164.58000,137.15011,45.17405,1.19261,5.01934,137.15011
164.97000,137.47505,45.44556,1.19544,5.04951,137.47505
165.36000,137.79998,45.31845,1.19826,5.03538,137.79998
165.75002,138.12511,45.38207,1.20109,5.04245,138.12511
166.14002,138.44999,45.40559,1.20391,5.04507,138.44999
166.53002,138.77498,45.66358,1.20674,5.07373,138.77498
166.92002,139.10010,45.69468,1.20957,5.07719,139.10010
167.31002,139.42504,45.73313,1.21239,5.08146,139.42504
167.70002,139.75004,45.69787,1.21522,5.07754,139.75004
168.09002,140.07499,46.01312,1.21804,5.11257,140.07499
168.48002,140.39998,46.08536,1.22087,5.12060,140.39998
168.87002,140.72510,46.27032,1.22370,5.14115,140.72510
169.26002,141.05010,46.28889,1.22652,5.14321,141.05010
169.65002,141.37504,46.42006,1.22935,5.15778,141.37504
170.04002,141.69998,46.40247,1.23217,5.15583,141.69998
170.43002,142.02492,46.56578,1.23500,5.17398,142.02492
170.82000,142.34997,46.72556,1.23783,5.19173,142.34997
171.21000,142.67516,46.88348,1.24065,5.20928,142.67516
171.60000,142.99998,46.78273,1.24348,5.19808,142.99998
171.99000,143.32497,47.07397,1.24630,5.23044,143.32497
172.38000,143.64998,46.90768,1.24913,5.21196,143.64998
172.77000,143.97511,47.12339,1.25196,5.23593,143.97511
173.16000,144.30004,47.37012,1.25478,5.26335,144.30004
173.55000,144.62504,47.45417,1.25761,5.27269,144.62504
173.94000,144.94997,47.65280,1.26043,5.29475,144.94997
174.33000,145.27504,47.40113,1.26326,5.26679,145.27504
174.72000,145.60004,47.49115,1.26609,5.27679,145.60004
175.11002,145.92505,47.51045,1.26891,5.27894,145.92505
175.50002,146.25010,46.52390,1.27174,5.16932,146.25010
175.89002,146.57497,47.18046,1.27456,5.24227,146.57497
176.28002,146.90004,47.17772,1.27739,5.24197,146.90004
176.67002,147.22504,47.72407,1.28022,5.30267,147.22504
177.06002,147.54998,47.61621,1.28304,5.29069,147.54998
177.45002,147.87504,47.85945,1.28587,5.31772,147.87504
177.84002,148.19997,48.00321,1.28870,5.33369,148.19997
178.23002,148.52499,48.25880,1.29152,5.36209,148.52499
178.62002,148.85016,48.14781,1.29435,5.34976,148.85016
179.01002,149.17503,48.35765,1.29717,5.37307,149.17503
179.40002,149.50004,48.37626,1.30000,5.37514,149.50004
179.79002,149.82509,48.62010,1.30283,5.40223,149.82509
180.18002,150.14998,48.55392,1.30565,5.39488,150.14998
180.57000,150.47510,48.55451,1.30848,5.39495,150.47510
180.96000,150.80011,48.83420,1.31131,5.42602,150.80011
181.35000,151.12499,48.95499,1.31413,5.43944,151.12499
181.74000,151.45004,49.02782,1.31696,5.44754,151.45004
182.13000,151.77505,49.15214,1.31978,5.46135,151.77505
182.52000,152.10005,49.19103,1.32261,5.46567,152.10005
182.91000,152.42510,49.17683,1.32544,5.46409,152.42510
183.30000,152.74997,49.09821,1.32826,5.45536,152.74997
183.69000,153.07498,49.41072,1.33109,5.49008,153.07498
184.08000,153.40003,49.54748,1.33391,5.50528,153.40003
184.47000,153.72504,49.58608,1.33674,5.50956,153.72504
184.86002,154.05010,49.46788,1.33957,5.49643,154.05010
185.25002,154.37511,49.69232,1.34239,5.52137,154.37511
185.64002,154.69993,49.84112,1.34522,5.53790,154.69993
186.03002,155.02498,49.91641,1.34804,5.54627,155.02498
186.42002,155.35011,49.90819,1.35087,5.54535,155.35011
186.81002,155.67510,50.07468,1.35370,5.56385,155.67510
187.20002,156.00003,50.21369,1.35652,5.57930,156.00003
187.59002,156.32497,50.22128,1.35935,5.58014,156.32497
187.98002,156.65004,50.20497,1.36217,5.57833,156.65004
188.37002,156.97503,50.30910,1.36500,5.58990,156.97503
188.76002,157.30003,50.46492,1.36783,5.60721,157.30003
189.15002,157.62497,50.51674,1.37065,5.61297,157.62497
189.54002,157.94998,50.57552,1.37348,5.61950,157.94998
189.93002,158.27497,50.80539,1.37630,5.64504,158.27497
190.32000,158.60002,50.86589,1.37913,5.65177,158.60002
190.71000,158.92504,50.98207,1.38196,5.66467,158.92504
191.10000,159.25003,50.97860,1.38478,5.66429,159.25003
191.49000,159.57505,51.04163,1.38761,5.67129,159.57505
191.88000,159.89998,51.11917,1.39043,5.67991,159.89998
192.27000,160.22503,51.39289,1.39326,5.71032,160.22503
192.66000,160.55010,51.22375,1.39609,5.69153,160.55010
193.05000,160.87504,51.46039,1.39891,5.71782,160.87504
193.44000,161.20004,51.51907,1.40174,5.72434,161.20004
193.83000,161.52503,51.53787,1.40457,5.72643,161.52503
194.22002,161.84997,51.50422,1.40739,5.72269,161.84997
194.61002,162.17509,51.49727,1.41022,5.72192,162.17509
195.00002,162.49998,51.75516,1.41304,5.75057,162.49998
195.39002,162.82497,51.75369,1.41587,5.75041,162.82497
195.78002,163.15004,52.01496,1.41870,5.77944,163.15004
196.17002,163.47503,51.95388,1.42152,5.77265,163.47503
196.56002,163.80005,52.05723,1.42435,5.78414,163.80005
196.95002,164.12510,52.09480,1.42717,5.78831,164.12510
197.34002,164.44998,52.26937,1.43000,5.80771,164.44998
197.73002,164.77505,52.40687,1.43283,5.82299,164.77505
198.12002,165.10017,52.48695,1.43565,5.83188,165.10017
198.51002,165.42491,52.63081,1.43848,5.84787,165.42491
198.90002,165.75010,52.87328,1.44131,5.87481,165.75010
199.29002,166.07497,52.57042,1.44413,5.84116,166.07497
199.68002,166.40004,52.62435,1.44696,5.84715,166.40004
200.07000,166.72509,52.89302,1.44978,5.87700,166.72509
200.46000,167.05003,52.78795,1.45261,5.86533,167.05003
200.85000,167.37504,52.93108,1.45544,5.88123,167.37504
201.24000,167.69998,53.06715,1.45826,5.89635,167.69998
201.63000,168.02497,52.85393,1.46109,5.87266,168.02497
202.02000,168.35010,52.96659,1.46391,5.88518,168.35010
202.41000,168.67509,53.31020,1.46674,5.92336,168.67509
202.80000,168.99990,53.47321,1.46956,5.94147,168.99990
203.19000,169.32504,53.52371,1.47239,5.94708,169.32504
203.58002,169.65004,53.43349,1.47522,5.93705,169.65004
203.97002,169.97503,53.51514,1.47804,5.94613,169.97503
204.36002,170.30010,53.50682,1.48087,5.94520,170.30010
204.75002,170.62496,53.61458,1.48370,5.95718,170.62496
205.14002,170.94998,53.75383,1.48652,5.97265,170.94998
205.53002,171.27503,53.93590,1.48935,5.99288,171.27503
205.92002,171.60010,53.86522,1.49217,5.98502,171.60010
206.31002,171.92503,54.06208,1.49500,6.00690,171.92503
206.70002,172.24997,54.09353,1.49783,6.01039,172.24997
207.09002,172.57499,54.15314,1.50065,6.01701,172.57499
207.48002,172.90004,54.11919,1.50348,6.01324,172.90004
207.87002,173.22505,54.25379,1.50630,6.02820,173.22505
208.26002,173.55010,54.08980,1.50913,6.00998,173.55010
208.65002,173.87511,54.20339,1.51196,6.02260,173.87511
209.04002,174.19990,54.26222,1.51478,6.02914,174.19990
209.43002,174.52497,54.55827,1.51761,6.06203,174.52497
209.82000,174.85010,54.50542,1.52044,6.05616,174.85010
210.21000,175.17503,54.69503,1.52326,6.07723,175.17503
210.60000,175.50003,54.54607,1.52609,6.06067,175.50003
210.99000,175.82497,54.72427,1.52891,6.08047,175.82497
211.38000,176.14998,54.72010,1.53174,6.08001,176.14998
211.77000,176.47510,55.01429,1.53457,6.11270,176.47510
212.16000,176.80010,55.26616,1.53739,6.14068,176.80010
212.55000,177.12498,55.06504,1.54022,6.11834,177.12498
212.94002,177.45005,55.18377,1.54304,6.13153,177.45005
213.33002,177.77497,54.97692,1.54587,6.10855,177.77497
213.72002,178.10004,55.07572,1.54870,6.11952,178.10004
214.11002,178.42516,55.37103,1.55152,6.15234,178.42516
214.50002,178.75003,55.31049,1.55435,6.14561,178.75003
214.89002,179.07497,55.36628,1.55717,6.15181,179.07497
215.28002,179.40003,55.64729,1.56000,6.18303,179.40003
215.67002,179.72503,55.58464,1.56283,6.17607,179.72503
216.06002,180.05010,55.67394,1.56565,6.18599,180.05010
216.45002,180.37498,55.70205,1.56848,6.18912,180.37498
216.84002,180.69997,55.70283,1.57130,6.18920,180.69997
217.23002,181.02510,55.86531,1.57413,6.20726,181.02510
217.62002,181.35004,56.01466,1.57696,6.22385,181.35004
218.01002,181.67511,55.95882,1.57978,6.21765,181.67511
218.40002,182.00004,56.09533,1.58261,6.23281,182.00004
218.79002,182.32496,56.09048,1.58543,6.23228,182.32496
219.18002,182.65011,56.11836,1.58826,6.23537,182.65011
219.57000,182.97510,56.26780,1.59109,6.25198,182.97510
219.96000,183.29997,56.25746,1.59391,6.25083,183.29997
220.35000,183.62503,56.27465,1.59674,6.25274,183.62503
220.74000,183.94997,56.37179,1.59957,6.26353,183.94997
221.13000,184.27504,56.67582,1.60239,6.29731,184.27504
221.52000,184.60009,56.68219,1.60522,6.29802,184.60009
221.91000,184.92503,56.74038,1.60804,6.30449,184.92503
222.30000,185.25004,56.61768,1.61087,6.29085,185.25004
222.69002,185.57504,56.67930,1.61370,6.29770,185.57504
223.08002,185.90003,56.84662,1.61652,6.31629,185.90003
223.47002,186.22505,57.04240,1.61935,6.33804,186.22505
223.86002,186.55004,56.91858,1.62217,6.32429,186.55004
224.25002,186.87496,57.09893,1.62500,6.34433,186.87496
224.64002,187.19997,57.05931,1.62783,6.33992,187.19997
225.03002,187.52497,57.03809,1.63065,6.33757,187.52497
225.42002,187.85004,57.29824,1.63348,6.36647,187.85004
225.81002,188.17516,57.26302,1.63631,6.36256,188.17516
226.20002,188.49997,57.37367,1.63913,6.37485,188.49997
226.59002,188.82491,57.33326,1.64196,6.37036,188.82491
226.98002,189.15009,57.46693,1.64478,6.38521,189.15009
227.37002,189.47504,57.59326,1.64761,6.39925,189.47504
227.76002,189.80004,57.52875,1.65044,6.39208,189.80004
228.15002,190.12503,57.70841,1.65326,6.41205,190.12503
228.54002,190.44997,57.73354,1.65609,6.41484,190.44997
228.93002,190.77502,57.81868,1.65891,6.42430,190.77502
229.32000,191.10003,57.86222,1.66174,6.42914,191.10003
229.71000,191.42509,57.99124,1.66457,6.44347,191.42509
230.10000,191.75010,57.92198,1.66739,6.43578,191.75010
230.49000,192.07485,57.96435,1.67022,6.44048,192.07485
230.88000,192.40003,58.15910,1.67304,6.46212,192.40003
231.27000,192.72510,58.24580,1.67587,6.47176,192.72510
231.66000,193.05004,58.16302,1.67870,6.46256,193.05004
232.05002,193.37503,58.31016,1.68152,6.47891,193.37503
232.44002,193.69997,58.30684,1.68435,6.47854,193.69997
232.83002,194.02497,58.39402,1.68717,6.48822,194.02497
233.22002,194.35011,58.38261,1.69000,6.48696,194.35011
233.61002,194.67510,58.44873,1.69283,6.49430,194.67510
234.00002,195.00002,58.74194,1.69565,6.52688,195.00002
234.39002,195.32504,58.78760,1.69848,6.53196,195.32504
234.78002,195.64997,58.69179,1.70130,6.52131,195.64997
235.17002,195.97508,58.81502,1.70413,6.53500,195.97508
235.56002,196.30009,59.04686,1.70696,6.56076,196.30009
235.95002,196.62498,59.02384,1.70978,6.55820,196.62498
236.34002,196.95003,59.05014,1.71261,6.56113,196.95003
236.73002,197.27504,58.86974,1.71544,6.54108,197.27504
237.12002,197.59998,59.19346,1.71826,6.57705,197.59998
237.51002,197.92510,58.98612,1.72109,6.55401,197.92510
237.90002,198.25004,59.15340,1.72391,6.57260,198.25004
238.29002,198.57496,59.06532,1.72674,6.56281,198.57496
238.68002,198.90010,59.25322,1.72957,6.58369,198.90010
239.07000,199.22502,59.29921,1.73239,6.58880,199.22502
239.46000,199.55002,59.52693,1.73522,6.61410,199.55002
239.85000,199.87503,59.47286,1.73804,6.60810,199.87503
240.24000,200.19997,59.71796,1.74087,6.63533,200.19997
240.63000,200.52496,59.51586,1.74370,6.61287,200.52496
241.02000,200.85003,59.53354,1.74652,6.61484,200.85003
241.41002,201.17510,59.75847,1.74935,6.63983,201.17510
241.80002,201.50004,59.97522,1.75217,6.66391,201.50004
242.19002,201.82490,59.93456,1.75500,6.65940,201.82490
242.58002,202.15005,60.13284,1.75783,6.68143,202.15005
242.97002,202.47510,60.10683,1.76065,6.67854,202.47510
243.36002,202.79996,60.22772,1.76348,6.69197,202.79996
243.75002,203.12503,60.46538,1.76630,6.71838,203.12503
244.14002,203.45002,60.29713,1.76913,6.69968,203.45002
244.53002,203.77496,60.41601,1.77196,6.71289,203.77496
244.92002,204.10003,60.75272,1.77478,6.75030,204.10003
245.31002,204.42508,60.67228,1.77761,6.74136,204.42508
245.70002,204.74996,60.63188,1.78043,6.73688,204.74996
246.09002,205.07498,60.81330,1.78326,6.75703,205.07498
246.48002,205.40003,60.91210,1.78609,6.76801,205.40003
246.87002,205.72504,60.90265,1.78891,6.76696,205.72504
247.26002,206.05009,61.01874,1.79174,6.77986,206.05009
247.65002,206.37497,61.13639,1.79456,6.79293,206.37497
248.04002,206.69997,61.09353,1.79739,6.78817,206.69997
248.43002,207.02504,61.42524,1.80022,6.82503,207.02504
248.82000,207.34996,61.43979,1.80304,6.82664,207.34996
249.21000,207.67516,61.62470,1.80587,6.84719,207.67516
249.60000,208.00002,61.56210,1.80870,6.84023,208.00002
249.99000,208.32490,61.54882,1.81152,6.83876,208.32490
250.38000,208.65008,61.51302,1.81435,6.83478,208.65008
250.77002,208.97510,61.58174,1.81717,6.84242,208.97510
251.16002,209.30003,61.64826,1.82000,6.84981,209.30003
251.55002,209.62503,61.75421,1.82283,6.86158,209.62503
251.94002,209.94997,61.76968,1.82565,6.86330,209.94997
252.33002,210.27504,61.91291,1.82848,6.87921,210.27504
252.72002,210.60003,62.04933,1.83130,6.89437,210.60003
253.11002,210.92504,62.21116,1.83413,6.91235,210.92504
253.50002,211.25009,62.27214,1.83696,6.91913,211.25009
253.89002,211.57496,62.32720,1.83978,6.92524,211.57496
254.28002,211.89997,62.50770,1.84261,6.94530,211.89997
254.67002,212.22509,62.58333,1.84544,6.95370,212.22509
255.06002,212.55009,62.40435,1.84826,6.93382,212.55009
255.45002,212.87503,62.63294,1.85109,6.95922,212.87503
255.84002,213.20002,62.58186,1.85391,6.95354,213.20002
256.23002,213.52498,62.71783,1.85674,6.96865,213.52498
256.62003,213.85008,63.00394,1.85957,7.00044,213.85008
257.01002,214.17510,63.00795,1.86239,7.00088,214.17510
257.40003,214.49998,63.10244,1.86522,7.01138,214.49998
257.79002,214.82497,63.12326,1.86804,7.01370,214.82497
258.18002,215.15004,63.20080,1.87087,7.02231,215.15004
258.57000,215.47504,63.27398,1.87370,7.03044,215.47504
258.96002,215.80011,63.32948,1.87652,7.03661,215.80011
259.35000,216.12497,63.41622,1.87935,7.04625,216.12497
259.74002,216.44996,63.52996,1.88217,7.05888,216.44996
260.13000,216.77503,63.63493,1.88500,7.07055,216.77503
260.52002,217.10003,63.43391,1.88783,7.04821,217.10003
260.91000,217.42502,63.68920,1.89065,7.07658,217.42502
261.30002,217.75004,63.67897,1.89348,7.07544,217.75004
261.69000,218.07497,63.81954,1.89630,7.09106,218.07497
262.08002,218.40004,63.83458,1.89913,7.09273,218.40004
262.47000,218.72504,63.94499,1.90196,7.10500,218.72504
262.86003,219.04998,63.92892,1.90478,7.10321,219.04998
263.25000,219.37510,64.22149,1.90761,7.13572,219.37510
263.64000,219.69991,64.14214,1.91043,7.12690,219.69991
264.03000,220.02496,64.00078,1.91326,7.11120,220.02496
264.42000,220.35010,64.39474,1.91609,7.15497,220.35010
264.81000,220.67502,64.23888,1.91891,7.13765,220.67502
265.20000,221.00003,64.23021,1.92174,7.13669,221.00003
265.59003,221.32503,64.59268,1.92457,7.17696,221.32503
265.98000,221.64997,64.77127,1.92739,7.19681,221.64997
266.37003,221.97509,64.93203,1.93022,7.21467,221.97509
266.76000,222.30003,64.67115,1.93304,7.18568,222.30003
267.15003,222.62497,64.89206,1.93587,7.21023,222.62497
267.54000,222.95004,65.00359,1.93870,7.22262,222.95004
267.93003,223.27503,65.05747,1.94152,7.22861,223.27503
268.32000,223.60004,65.12115,1.94435,7.23568,223.60004
268.71003,223.92510,65.26285,1.94717,7.25143,223.92510
269.10000,224.24996,65.16396,1.95000,7.24044,224.24996
269.49003,224.57497,65.60147,1.95283,7.28905,224.57497
269.88000,224.90002,65.47774,1.95565,7.27530,224.90002
270.27003,225.22509,65.35337,1.95848,7.26149,225.22509
270.66000,225.55009,65.55797,1.96131,7.28422,225.55009
271.05003,225.87502,65.63644,1.96413,7.29294,225.87502
271.44000,226.19996,65.62904,1.96696,7.29212,226.19996
271.83003,226.52503,65.62057,1.96978,7.29117,226.52503
272.22000,226.84997,66.02267,1.97261,7.33585,226.84997
272.61003,227.17509,65.96384,1.97544,7.32932,227.17509
273.00000,227.50009,66.16325,1.97826,7.35147,227.50009
273.39000,227.82490,66.06964,1.98109,7.34107,227.82490
273.78000,228.15004,66.45337,1.98391,7.38371,228.15004
274.17000,228.47511,66.34973,1.98674,7.37219,228.47511
274.56003,228.80003,66.41521,1.98957,7.37947,228.80003
274.95000,229.12497,66.45709,1.99239,7.38412,229.12497
275.34003,229.44996,66.50015,1.99522,7.38891,229.44996
275.73000,229.77497,66.72243,1.99804,7.41360,229.77497
276.12003,230.10008,66.87320,2.00087,7.43036,230.10008
276.51000,230.42504,66.69598,2.00370,7.41066,230.42504
276.90003,230.75003,66.78116,2.00652,7.42013,230.75003
277.29000,231.07503,66.97562,2.00935,7.44174,231.07503
277.68003,231.39998,66.94804,2.01217,7.43867,231.39998
278.07000,231.72503,67.14696,2.01500,7.46077,231.72503
278.46003,232.05005,66.93849,2.01783,7.43761,232.05005
278.85000,232.37504,67.18203,2.02065,7.46467,232.37504
279.24003,232.70003,67.46887,2.02348,7.49654,232.70003
279.63000,233.02495,67.41651,2.02630,7.49072,233.02495
280.02003,233.34997,67.49914,2.02913,7.49990,233.34997
280.41000,233.67517,67.57364,2.03196,7.50818,233.67517
280.80003,233.99998,67.69380,2.03478,7.52153,233.99998
281.19000,234.32491,67.79411,2.03761,7.53268,234.32491
281.58003,234.65009,67.98941,2.04044,7.55438,234.65009
281.97000,234.97498,68.14051,2.04326,7.57117,234.97498
282.36003,235.30003,68.10534,2.04609,7.56726,235.30003
282.75000,235.62510,68.05186,2.04891,7.56132,235.62510
283.14000,235.94998,68.31695,2.05174,7.59077,235.94998
283.53000,236.27503,68.27674,2.05457,7.58630,236.27503
283.92000,236.60004,68.27463,2.05739,7.58607,236.60004
284.31003,236.92496,68.50024,2.06022,7.61114,236.92496
284.70000,237.25010,68.48246,2.06304,7.60916,237.25010
285.09003,237.57497,68.67325,2.06587,7.63036,237.57497
285.48000,237.90002,68.56975,2.06870,7.61886,237.90002
285.87003,238.22509,68.84297,2.07152,7.64922,238.22509
286.26000,238.54997,68.82063,2.07435,7.64674,238.54997
286.65003,238.87504,69.05737,2.07717,7.67304,238.87504
287.04000,239.20003,69.18403,2.08000,7.68711,239.20003
287.43003,239.52497,69.04904,2.08283,7.67211,239.52497
287.82000,239.85010,69.30174,2.08565,7.70019,239.85010
288.21003,240.17509,69.36301,2.08848,7.70700,240.17509
288.60000,240.50003,69.28141,2.09130,7.69793,240.50003
288.99003,240.82504,69.32985,2.09413,7.70332,240.82504
289.38000,241.15004,69.41170,2.09696,7.71241,241.15004
289.77003,241.47511,69.38486,2.09978,7.70943,241.47511
290.16000,241.80003,69.35836,2.10261,7.70648,241.80003
290.55003,242.12496,69.77074,2.10543,7.75230,242.12496
290.94000,242.44998,69.87723,2.10826,7.76414,242.44998
291.33003,242.77503,70.07448,2.11109,7.78605,242.77503
291.72000,243.10002,69.85881,2.11391,7.76209,243.10002
292.11003,243.42503,69.99518,2.11674,7.77724,243.42503
292.50000,243.74997,70.23299,2.11957,7.80367,243.74997
292.89000,244.07497,70.07507,2.12239,7.78612,244.07497
293.28000,244.40004,70.36754,2.12522,7.81862,244.40004
293.67000,244.72503,70.30073,2.12804,7.81119,244.72503
294.06003,245.05004,70.65904,2.13087,7.85100,245.05004
294.45000,245.37509,70.72708,2.13370,7.85856,245.37509
294.84003,245.69996,70.70949,2.13652,7.85661,245.69996
295.23000,246.02497,70.72408,2.13935,7.85823,246.02497
295.62003,246.35002,70.76107,2.14217,7.86234,246.35002
296.01000,246.67503,70.87103,2.14500,7.87456,246.67503
296.40003,247.00008,71.18961,2.14783,7.90996,247.00008
296.79000,247.32497,71.00696,2.15065,7.88966,247.32497
297.18003,247.65003,71.18045,2.15348,7.90894,247.65003
297.57000,247.97508,71.48787,2.15631,7.94310,247.97508
297.96003,248.30004,71.47043,2.15913,7.94116,248.30004
298.35000,248.62504,71.42208,2.16196,7.93579,248.62504
298.74003,248.94997,71.45701,2.16478,7.93967,248.94997
299.13000,249.27489,71.63570,2.16761,7.95952,249.27489
299.52003,249.60009,71.73787,2.17044,7.97087,249.60009
299.91000,249.92511,71.84024,2.17326,7.98225,249.92511
300.30003,250.24990,71.91474,2.17609,7.99053,250.24990
300.69000,250.57500,71.99415,2.17891,7.99935,250.57500
301.08003,250.90003,72.12209,2.18174,8.01357,250.90003
301.47000,251.22503,72.22774,2.18457,8.02530,251.22503
301.86003,251.55013,72.23313,2.18739,8.02590,251.55013
302.25000,251.87502,72.53080,2.19022,8.05898,251.87502
302.64000,252.19996,72.62945,2.19304,8.06994,252.19996
303.03003,252.52510,72.70003,2.19587,8.07778,252.52510
303.42000,252.85004,72.87343,2.19870,8.09705,252.85004
303.81003,253.17514,72.72447,2.20152,8.08050,253.17514
304.20000,253.50003,72.88851,2.20435,8.09872,253.50003
304.59003,253.82495,73.09233,2.20717,8.12137,253.82495
304.98000,254.15009,72.98369,2.21000,8.10930,254.15009
305.37003,254.47503,73.13671,2.21283,8.12630,254.47503
305.76000,254.80002,73.14543,2.21565,8.12727,254.80002
306.15003,255.12502,73.36702,2.21848,8.15189,255.12502
306.54000,255.44990,73.42845,2.22130,8.15872,255.44990
306.93003,255.77500,73.42370,2.22413,8.15819,255.77500
307.32000,256.10009,73.70564,2.22696,8.18952,256.10009
307.71003,256.42503,73.68188,2.22978,8.18688,256.42503
308.10000,256.75002,73.73742,2.23261,8.19305,256.75002
308.49003,257.07502,73.84034,2.23544,8.20448,257.07502
308.88000,257.39996,74.11190,2.23826,8.23466,257.39996
309.27003,257.72510,74.15936,2.24109,8.23993,257.72510
309.66000,258.05002,74.26815,2.24391,8.25202,258.05002
310.05003,258.37502,74.35303,2.24674,8.26145,258.37502
310.44000,258.69995,74.13261,2.24956,8.23696,258.69995
310.83003,259.02495,74.52119,2.25239,8.28013,259.02495
311.22000,259.35004,74.64184,2.25522,8.29354,259.35004
311.61003,259.67514,74.70830,2.25804,8.30092,259.67514
312.00000,259.99997,74.68783,2.26087,8.29865,259.99997
312.39000,260.32496,74.87690,2.26370,8.31966,260.32496
312.78003,260.64996,74.94680,2.26652,8.32742,260.64996
313.17000,260.97501,74.94993,2.26935,8.32777,260.97501
313.56003,261.30009,75.12177,2.27217,8.34686,261.30009
313.95000,261.62503,75.11926,2.27500,8.34658,261.62503
314.34003,261.94990,75.23056,2.27783,8.35895,261.94990
314.73000,262.27502,75.51161,2.28065,8.39018,262.27502
315.12003,262.60002,75.32621,2.28348,8.36958,262.60002
315.51000,262.92508,75.83778,2.28631,8.42642,262.92508
315.90003,263.25002,75.59533,2.28913,8.39948,263.25002
316.29000,263.57491,75.64999,2.29196,8.40555,263.57491
316.68003,263.90001,76.00761,2.29478,8.44529,263.90001
317.07000,264.22506,75.86933,2.29761,8.42993,264.22506
317.46003,264.55004,76.23180,2.30044,8.47020,264.55004
317.85000,264.87509,76.21044,2.30326,8.46783,264.87509
318.24003,265.19990,76.16215,2.30609,8.46246,265.19990
318.63000,265.52496,76.21005,2.30891,8.46778,265.52496
319.02003,265.85016,76.36626,2.31174,8.48514,265.85016
319.41000,266.17510,76.57810,2.31457,8.50868,266.17510
319.80003,266.50002,76.63826,2.31739,8.51536,266.50002
320.19000,266.82502,76.77996,2.32022,8.53111,266.82502
320.58003,267.14996,76.68459,2.32304,8.52051,267.14996
320.97000,267.47501,77.00449,2.32587,8.55606,267.47501
321.36003,267.80009,77.13484,2.32870,8.57054,267.80009
321.75003,268.12498,77.16359,2.33152,8.57373,268.12498
322.14000,268.45003,77.44778,2.33435,8.60531,268.45003
322.53003,268.77496,77.22271,2.33717,8.58030,268.77496
322.92000,269.10001,77.36158,2.34000,8.59573,269.10001
323.31003,269.42510,77.59649,2.34283,8.62183,269.42510
323.70000,269.75004,77.60801,2.34565,8.62311,269.75004
324.09003,270.07503,77.67021,2.34848,8.63002,270.07503
324.48000,270.40008,77.82779,2.35131,8.64753,270.40008
324.87003,270.72495,77.84204,2.35413,8.64912,270.72495
325.26000,271.05007,77.90582,2.35696,8.65620,271.05007
325.65003,271.37509,78.09994,2.35978,8.67777,271.37509
326.04000,271.69997,78.28450,2.36261,8.69828,271.69997
326.43003,272.02496,78.15602,2.36543,8.68400,272.02496
326.82000,272.35001,78.36316,2.36826,8.70702,272.35001
327.21003,272.67506,78.59044,2.37109,8.73227,272.67506
327.60000,273.00004,78.57251,2.37391,8.73028,273.00004
327.99003,273.32498,78.67131,2.37674,8.74126,273.32498
328.38000,273.65003,78.73749,2.37957,8.74861,273.65003
328.77003,273.97508,78.87156,2.38239,8.76351,273.97508
329.16000,274.30002,78.94150,2.38522,8.77128,274.30002
329.55003,274.62501,79.09570,2.38804,8.78841,274.62501
329.94000,274.94997,79.23142,2.39087,8.80349,274.94997
330.33003,275.27502,79.27502,2.39370,8.80834,275.27502
330.72000,275.60009,79.33649,2.39652,8.81517,275.60009
331.11003,275.92501,79.49691,2.39935,8.83299,275.92501
331.50003,276.25000,79.49358,2.40217,8.83262,276.25000
331.89000,276.57503,79.68446,2.40500,8.85383,276.57503
332.28003,276.89997,79.70940,2.40783,8.85660,276.89997
332.67000,277.22502,79.59698,2.41065,8.84411,277.22502
333.06003,277.55007,79.80412,2.41348,8.86712,277.55007
333.45000,277.87495,79.99761,2.41630,8.88862,277.87495
333.84003,278.19995,80.15601,2.41913,8.90622,278.19995
334.23000,278.52504,80.22738,2.42196,8.91415,278.52504
334.62003,278.85003,80.13015,2.42478,8.90335,278.85003
335.01000,279.17508,80.41807,2.42761,8.93534,279.17508
335.40003,279.50002,80.56752,2.43043,8.95195,279.50002
335.79000,279.82494,80.39720,2.43326,8.93302,279.82494
336.18003,280.15008,80.76114,2.43609,8.97346,280.15008
336.57000,280.47502,80.53136,2.43891,8.94793,280.47502
336.96003,280.80001,80.73572,2.44174,8.97064,280.80001
337.35000,281.12506,80.88693,2.44457,8.98744,281.12506
337.74003,281.44989,81.04230,2.44739,9.00470,281.44989
338.13000,281.77503,80.90167,2.45022,8.98907,281.77503
338.52003,282.10003,81.12655,2.45304,9.01406,282.10003
338.91000,282.42502,81.42657,2.45587,9.04740,282.42502
339.30003,282.75002,81.35843,2.45870,9.03983,282.75002
339.69000,283.07496,81.48510,2.46152,9.05390,283.07496
340.08003,283.40003,81.43127,2.46435,9.04792,283.40003
340.47000,283.72502,81.60849,2.46717,9.06761,283.72502
340.86003,284.05001,81.75984,2.47000,9.08443,284.05001
341.25003,284.37508,81.92662,2.47283,9.10296,284.37508
341.64000,284.70000,81.83787,2.47565,9.09310,284.70000
342.03003,285.02489,81.88739,2.47848,9.09860,285.02489
342.42000,285.35008,82.04947,2.48131,9.11661,285.35008
342.81003,285.67508,82.19442,2.48413,9.13271,285.67508
343.20000,285.99996,82.22625,2.48696,9.13625,285.99996
343.59003,286.32501,82.27166,2.48978,9.14130,286.32501
343.98000,286.65004,82.37907,2.49261,9.15323,286.65004
344.37003,286.97504,82.40851,2.49543,9.15650,286.97504
344.76000,287.30003,82.51838,2.49826,9.16871,287.30003
345.15003,287.62503,82.62658,2.50109,9.18073,287.62503
345.54000,287.94995,82.82418,2.50391,9.20269,287.94995
345.93003,288.27501,83.00781,2.50674,9.22309,288.27501
346.32000,288.60003,82.98543,2.50957,9.22060,288.60003
346.71003,288.92508,82.99894,2.51239,9.22211,288.92508
347.10000,289.25002,83.35015,2.51522,9.26113,289.25002
347.49003,289.57490,83.16039,2.51804,9.24004,289.57490
347.88000,289.90010,83.36577,2.52087,9.26286,289.90010
348.27003,290.22504,83.42666,2.52370,9.26963,290.22504
348.66000,290.54997,83.60932,2.52652,9.28992,290.54997
349.05003,290.87503,83.58673,2.52935,9.28741,290.87503
349.44000,291.19996,83.49763,2.53217,9.27751,291.19996
349.83003,291.52496,83.67152,2.53500,9.29684,291.52496
350.22003,291.85003,83.90135,2.53783,9.32237,291.85003
350.61003,292.17497,83.76003,2.54065,9.30667,292.17497
351.00003,292.50002,84.00857,2.54348,9.33429,292.50002
351.39000,292.82495,84.21322,2.54630,9.35702,292.82495
351.78003,293.14995,84.25720,2.54913,9.36191,293.14995
352.17000,293.47509,84.22654,2.55196,9.35850,293.47509
352.56003,293.80003,0.42154,2.55478,0.04684,293.80003
352.95000,294.12502,0.43212,2.55761,0.04801,294.12502
353.34003,294.45002,0.37892,2.56044,0.04210,294.45002
353.73000,294.77501,0.45227,2.56326,0.05025,294.77501
354.12003,295.10001,0.38955,2.56609,0.04328,295.10001
354.51000,295.42509,0.29482,2.56891,0.03276,295.42509
354.90003,295.74996,0.19517,2.57174,0.02169,295.74996
355.29000,296.07503,0.39428,2.57457,0.04381,296.07503
355.68003,296.40002,0.21902,2.57739,0.02434,296.40002
356.07000,296.72502,0.43224,2.58022,0.04803,296.72502
356.35400,296.96157,0.44228,2.58227,0.04914,296.96157