File: V_8/FR/RDSO FR Tensile 500.is_tens_RawData/Specimen_RawData_4.csv
Time,Extension,Load,Tensile strain,Tensile stress,Corrected Position
(sec),(mm),(N),(mm/mm),(MPa),(mm)
0.00000,0.00000,-0.12569,0.00000,-0.01397,0.00000
0.02000,0.01987,0.14662,0.00017,0.01629,0.01987
0.04000,0.09775,0.81682,0.00085,0.09076,0.09775
0.06000,0.23400,1.44279,0.00203,0.16031,0.23400
0.08000,0.41725,2.18710,0.00363,0.24301,0.41725
0.10000,0.62006,2.84726,0.00539,0.31636,0.62006
0.12000,0.83244,3.55263,0.00724,0.39474,0.83244
0.14000,1.05137,3.92389,0.00914,0.43599,1.05137
0.16000,1.27175,4.36133,0.01106,0.48459,1.27175
0.18000,1.47394,4.79756,0.01282,0.53306,1.47394
0.20000,1.65406,5.15748,0.01438,0.57305,1.65406
0.22000,1.82162,5.86200,0.01584,0.65133,1.82162
0.24000,1.98644,6.35439,0.01727,0.70604,1.98644
0.26000,2.15312,6.73266,0.01872,0.74807,2.15312
0.28000,2.32206,7.19262,0.02019,0.79918,2.32206
0.30000,2.49175,7.74473,0.02167,0.86053,2.49175
0.32000,2.66100,8.14107,0.02314,0.90456,2.66100
0.34000,2.82944,8.35679,0.02460,0.92853,2.82944
0.36000,2.99712,8.59641,0.02606,0.95516,2.99712
0.38000,3.16437,8.91313,0.02752,0.99035,3.16437
0.40000,3.33144,9.24885,0.02897,1.02765,3.33144
0.42000,3.49844,9.50767,0.03042,1.05641,3.49844
0.44000,3.66537,9.52364,0.03187,1.05818,3.66537
0.46000,3.83244,9.72452,0.03333,1.08050,3.83244
0.48000,3.99944,10.17496,0.03478,1.13055,3.99944
0.50000,4.16625,10.45884,0.03623,1.16209,4.16625
0.52000,4.33294,10.41424,0.03768,1.15714,4.33294
0.54000,4.49969,10.62807,0.03913,1.18090,4.49969
0.56000,4.66637,10.77744,0.04058,1.19749,4.66637
0.58000,4.83319,11.02955,0.04203,1.22551,4.83319
0.60000,4.99987,11.50074,0.04348,1.27786,4.99987
0.62000,5.16650,11.81922,0.04493,1.31325,5.16650
0.64000,5.33319,11.93139,0.04638,1.32571,5.33319
0.66000,5.49994,12.17371,0.04783,1.35263,5.49994
0.68000,5.66662,12.32678,0.04927,1.36964,5.66662
0.70000,5.83331,12.31169,0.05072,1.36797,5.83331
0.72000,6.00000,12.52236,0.05217,1.39137,6.00000
0.74000,6.16656,12.84636,0.05362,1.42737,6.16656
0.76000,6.33331,13.03494,0.05507,1.44833,6.33331
0.78000,6.50000,13.07902,0.05652,1.45322,6.50000
0.80000,6.66669,13.21864,0.05797,1.46874,6.66669
0.82000,6.83331,13.20748,0.05942,1.46750,6.83331
0.84000,7.00000,13.40284,0.06087,1.48920,7.00000
0.86000,7.16656,13.58971,0.06232,1.50997,7.16656
0.88000,7.33331,13.69277,0.06377,1.52142,7.33331
0.90000,7.50000,14.00677,0.06522,1.55631,7.50000
0.92000,7.66669,14.19489,0.06667,1.57721,7.66669
0.94000,7.83331,14.29483,0.06812,1.58831,7.83331
0.96000,7.99994,14.43943,0.06956,1.60438,7.99994
0.98000,8.16662,14.52606,0.07101,1.61401,8.16662
1.00000,8.33337,14.42197,0.07246,1.60244,8.33337
1.02000,8.50006,14.59936,0.07391,1.62215,8.50006
1.04000,8.66669,14.82874,0.07536,1.64764,8.66669
1.06000,8.83331,14.90905,0.07681,1.65656,8.83331
1.08000,9.00000,14.98355,0.07826,1.66484,9.00000
1.10000,9.16669,15.19226,0.07971,1.68803,9.16669
1.12000,9.33344,15.31991,0.08116,1.70221,9.33344
1.14000,9.50006,15.64131,0.08261,1.73792,9.50006
1.16000,9.66669,15.70878,0.08406,1.74542,9.66669
1.18000,9.83331,15.49421,0.08551,1.72158,9.83331
1.20000,10.00000,15.57562,0.08696,1.73062,10.00000
1.22000,10.16669,15.65544,0.08841,1.73949,10.16669
1.24000,10.33337,15.69438,0.08986,1.74382,10.33337
1.26000,10.50000,15.83190,0.09130,1.75910,10.50000
1.28000,10.66662,16.06726,0.09275,1.78525,10.66662
1.30000,10.83331,16.11622,0.09420,1.79069,10.83331
1.32000,11.00000,16.27553,0.09565,1.80839,11.00000
1.34000,11.16669,16.40511,0.09710,1.82279,11.16669
1.36000,11.33337,16.33029,0.09855,1.81448,11.33337
1.38000,11.49994,16.40857,0.10000,1.82317,11.49994
1.40000,11.66656,16.54777,0.10145,1.83864,11.66656
1.42000,11.83331,16.40154,0.10290,1.82239,11.83331
1.44000,12.00000,16.48001,0.10435,1.83111,12.00000
1.46000,12.16669,16.60633,0.10580,1.84515,12.16669
1.48000,12.33331,16.80603,0.10725,1.86734,12.33331
1.50000,12.49994,16.91274,0.10870,1.87919,12.49994
1.52000,12.66662,16.92175,0.11014,1.88019,12.66662
1.54000,12.83337,16.83221,0.11159,1.87025,12.83337
1.56000,13.00006,16.85448,0.11304,1.87272,13.00006
1.58000,13.16662,17.02716,0.11449,1.89191,13.16662
1.60000,13.33331,17.01453,0.11594,1.89050,13.33331
1.62000,13.50000,17.21709,0.11739,1.91301,13.50000
1.64000,13.66668,17.36945,0.11884,1.92994,13.66668
1.66000,13.83337,17.26546,0.12029,1.91838,13.83337
1.68000,14.00006,17.27874,0.12174,1.91986,14.00006
1.70000,14.16662,17.41998,0.12319,1.93555,14.16662
1.72000,14.33331,17.43526,0.12464,1.93725,14.33331
1.74000,14.50006,17.59308,0.12609,1.95479,14.50006
1.76000,14.66669,17.65833,0.12754,1.96204,14.66669
1.78000,14.83331,17.57016,0.12899,1.95224,14.83331
1.80000,15.00000,17.79082,0.13043,1.97676,15.00000
1.82000,15.16662,17.87887,0.13188,1.98654,15.16662
1.84000,15.33337,17.74493,0.13333,1.97166,15.33337
1.86000,15.50006,17.83958,0.13478,1.98218,15.50006
1.88000,15.66668,18.02234,0.13623,2.00248,15.66668
1.90000,15.83337,17.97482,0.13768,1.99720,15.83337
1.92000,16.00000,18.11087,0.13913,2.01232,16.00000
1.94000,16.16656,18.10705,0.14058,2.01189,16.16656
1.96000,16.33331,18.08709,0.14203,2.00968,16.33331
1.98000,16.50006,18.23370,0.14348,2.02597,16.50006
2.00000,16.66668,18.29443,0.14493,2.03271,16.66668
2.02000,16.83337,18.17044,0.14638,2.01894,16.83337
2.04000,17.00000,18.18048,0.14783,2.02005,17.00000
2.06000,17.16662,18.21347,0.14927,2.02372,17.16662
2.08000,17.33331,18.13970,0.15072,2.01552,17.33331
2.10000,17.50000,18.20898,0.15217,2.02322,17.50000
2.12000,17.66662,18.46315,0.15362,2.05146,17.66662
2.14000,17.83325,18.28939,0.15507,2.03215,17.83325
2.16000,17.99993,18.45737,0.15652,2.05082,17.99993
2.18000,18.16662,18.71835,0.15797,2.07982,18.16662
2.20000,18.33337,18.68499,0.15942,2.07611,18.33337
2.22000,18.50006,18.64838,0.16087,2.07204,18.50006
2.24000,18.66662,18.58563,0.16232,2.06507,18.66662
2.26000,18.83331,18.51387,0.16377,2.05710,18.83331
2.28000,19.00006,18.54858,0.16522,2.06095,19.00006
2.30000,19.16675,18.58882,0.16667,2.06542,19.16675
2.32000,19.33337,18.57762,0.16812,2.06418,19.33337
2.34000,19.50000,18.73993,0.16957,2.08221,19.50000
2.36000,19.66662,18.82552,0.17101,2.09172,19.66662
2.38000,19.83337,19.07577,0.17246,2.11953,19.83337
2.40000,20.00006,18.96904,0.17391,2.10767,20.00006
2.42000,20.16668,18.94876,0.17536,2.10542,20.16668
2.44000,20.33331,18.89510,0.17681,2.09946,20.33331
2.46000,20.50000,18.97984,0.17826,2.10887,20.50000
2.48000,20.66662,19.03218,0.17971,2.11469,20.66662
2.50000,20.83337,18.77759,0.18116,2.08640,20.83337
2.52000,21.00006,18.87262,0.18261,2.09696,21.00006
2.54000,21.16662,19.08437,0.18406,2.12049,21.16662
2.56000,21.33331,18.98415,0.18551,2.10935,21.33331
2.58000,21.49994,19.12520,0.18696,2.12502,21.49994
2.60000,21.66662,19.20450,0.18841,2.13383,21.66662
2.62000,21.83337,19.24177,0.18986,2.13797,21.83337
2.64000,22.00000,19.44787,0.19130,2.16087,22.00000
2.66000,22.16662,19.47451,0.19275,2.16383,22.16662
2.68000,22.33331,19.34319,0.19420,2.14924,22.33331
2.70000,22.49993,19.41640,0.19565,2.15738,22.49993
2.72000,22.66662,19.39742,0.19710,2.15527,22.66662
2.74000,22.83331,19.37239,0.19855,2.15249,22.83331
2.76000,23.00000,19.35140,0.20000,2.15016,23.00000
2.78000,23.16662,19.26823,0.20145,2.14091,23.16662
2.80000,23.33331,19.22931,0.20290,2.13659,23.33331
2.82000,23.50006,19.52095,0.20435,2.16899,23.50006
2.84000,23.66675,19.58624,0.20580,2.17625,23.66675
2.86000,23.83337,19.47018,0.20725,2.16335,23.83337
2.88000,24.00006,19.68183,0.20870,2.18687,24.00006
2.90000,24.16668,19.62438,0.21015,2.18049,24.16668
2.92000,24.33337,19.57628,0.21159,2.17514,24.33337
2.94000,24.50006,19.61159,0.21304,2.17907,24.50006
2.96000,24.66668,19.63834,0.21449,2.18204,24.66668
2.98000,24.83331,19.57410,0.21594,2.17490,24.83331
3.00000,24.99993,19.67328,0.21739,2.18592,24.99993
3.02000,25.16662,19.69004,0.21884,2.18778,25.16662
3.04000,25.33343,19.60177,0.22029,2.17797,25.33343
3.06000,25.50012,19.65852,0.22174,2.18428,25.50012
3.08000,25.66675,19.84673,0.22319,2.20519,25.66675
3.10000,25.83325,19.82591,0.22464,2.20288,25.83325
3.12000,25.99987,19.91139,0.22609,2.21238,25.99987
3.14000,26.16662,19.82462,0.22754,2.20273,26.16662
3.16000,26.33337,19.76951,0.22899,2.19661,26.33337
3.18000,26.50006,19.91156,0.23044,2.21240,26.50006
3.20000,26.66662,20.00921,0.23188,2.22324,26.66662
3.22000,26.83331,19.89189,0.23333,2.21021,26.83331
3.24000,27.00000,19.97183,0.23478,2.21909,27.00000
3.26000,27.16668,20.05459,0.23623,2.22829,27.16668
3.28000,27.33331,20.10996,0.23768,2.23444,27.33331
3.30000,27.49993,20.17663,0.23913,2.24185,27.49993
3.32000,27.66656,20.25135,0.24058,2.25015,27.66656
3.34000,27.83331,20.19475,0.24203,2.24386,27.83331
3.36000,28.00006,20.08381,0.24348,2.23153,28.00006
3.38000,28.16675,20.11258,0.24493,2.23473,28.16675
3.40000,28.33337,20.03041,0.24638,2.22560,28.33337
3.42000,28.50000,20.22865,0.24783,2.24763,28.50000
3.44000,28.66662,20.31441,0.24927,2.25716,28.66662
3.46000,28.83337,20.21353,0.25072,2.24595,28.83337
3.48000,29.00006,20.29553,0.25217,2.25506,29.00006
3.50000,29.16669,20.11841,0.25362,2.23538,29.16669
3.52000,29.33337,20.11741,0.25507,2.23527,29.33337
3.54000,29.50000,20.24892,0.25652,2.24988,29.50000
3.56000,29.66668,20.34427,0.25797,2.26047,29.66668
3.58000,29.83337,20.29825,0.25942,2.25536,29.83337
3.60000,30.00006,20.31052,0.26087,2.25672,30.00006
3.62000,30.16668,20.39176,0.26232,2.26575,30.16668
3.64000,30.33337,20.34936,0.26377,2.26104,30.33337
3.66000,30.49999,20.59773,0.26522,2.28864,30.49999
3.68000,30.66662,20.56942,0.26667,2.28549,30.66662
3.70000,30.83337,20.43425,0.26812,2.27047,30.83337
3.72000,31.00000,20.44992,0.26957,2.27221,31.00000
3.74000,31.16662,20.62151,0.27101,2.29128,31.16662
3.76000,31.33331,20.56415,0.27246,2.28491,31.33331
3.78000,31.49999,20.75832,0.27391,2.30648,31.49999
3.80000,31.66668,20.85283,0.27536,2.31698,31.66668
3.82000,31.83337,20.79045,0.27681,2.31005,31.83337
3.84000,31.99999,20.87710,0.27826,2.31968,31.99999
3.86000,32.16656,20.85030,0.27971,2.31670,32.16656
3.88000,32.33331,20.64595,0.28116,2.29399,32.33331
3.90000,32.50000,20.77362,0.28261,2.30818,32.50000
3.92000,32.66668,20.83816,0.28406,2.31535,32.66668
3.94000,32.83331,20.78244,0.28551,2.30916,32.83331
3.96000,32.99993,20.96110,0.28696,2.32901,32.99993
3.98000,33.16662,20.94817,0.28841,2.32757,33.16662
4.00000,33.33337,20.89958,0.28986,2.32218,33.33337
4.02000,33.50006,20.98728,0.29130,2.33192,33.50006
4.04000,33.66675,21.00768,0.29275,2.33419,33.66675
4.06000,33.83337,20.88016,0.29420,2.32002,33.83337
4.08000,34.00000,20.91166,0.29565,2.32352,34.00000
4.10000,34.16668,20.93286,0.29710,2.32587,34.16668
4.12000,34.33337,20.80597,0.29855,2.31177,34.33337
4.14000,34.50006,21.10749,0.30000,2.34528,34.50006
4.16000,34.66668,21.15404,0.30145,2.35045,34.66668
4.18000,34.83331,21.13024,0.30290,2.34780,34.83331
4.20000,34.99999,21.23592,0.30435,2.35955,34.99999
4.22000,35.16675,21.30123,0.30580,2.36680,35.16675
4.24000,35.33337,21.20447,0.30725,2.35605,35.33337
4.26000,35.49999,21.24985,0.30870,2.36109,35.49999
4.28000,35.66662,21.48786,0.31014,2.38754,35.66662
4.30000,35.83331,21.40554,0.31159,2.37839,35.83331
4.32000,35.99999,21.40525,0.31304,2.37836,35.99999
4.34000,36.16662,21.33709,0.31449,2.37079,36.16662
4.36000,36.33331,21.08684,0.31594,2.34298,36.33331
4.38000,36.50000,21.29487,0.31739,2.36610,36.50000
4.40000,36.66662,21.49572,0.31884,2.38841,36.66662
4.42000,36.83337,21.36278,0.32029,2.37364,36.83337
4.44000,36.99999,21.46430,0.32174,2.38492,36.99999
4.46000,37.16662,21.62253,0.32319,2.40250,37.16662
4.48000,37.33324,21.55136,0.32464,2.39460,37.33324
4.50000,37.49993,21.54793,0.32609,2.39421,37.49993
4.52000,37.66656,21.59354,0.32754,2.39928,37.66656
4.54000,37.83337,21.51837,0.32899,2.39093,37.83337
4.56000,38.00006,21.50005,0.33044,2.38890,38.00006
4.58000,38.16668,21.69949,0.33188,2.41105,38.16668
4.60000,38.33337,21.73972,0.33333,2.41552,38.33337
4.62000,38.50000,21.84131,0.33478,2.42681,38.50000
4.64000,38.66668,21.76319,0.33623,2.41813,38.66668
4.66000,38.83337,21.83154,0.33768,2.42573,38.83337
4.68000,39.00006,21.93695,0.33913,2.43744,39.00006
4.70000,39.16668,21.89625,0.34058,2.43292,39.16668
4.72000,39.33331,21.75043,0.34203,2.41671,39.33331
4.74000,39.49999,21.85831,0.34348,2.42870,39.49999
4.76000,39.66668,21.99247,0.34493,2.44361,39.66668
4.78000,39.83337,21.91457,0.34638,2.43495,39.83337
4.80000,39.99999,21.90668,0.34783,2.43408,39.99999
4.82000,40.16662,21.99673,0.34927,2.44408,40.16662
4.84000,40.33331,22.00033,0.35072,2.44448,40.33331
4.86000,40.50006,21.99771,0.35217,2.44419,40.50006
4.88000,40.66668,22.07298,0.35362,2.45255,40.66668
4.90000,40.83330,21.93624,0.35507,2.43736,40.83330
4.92000,40.99999,22.11067,0.35652,2.45674,40.99999
4.94000,41.16655,22.18554,0.35797,2.46506,41.16655
4.96000,41.33337,22.12215,0.35942,2.45802,41.33337
4.98000,41.50006,22.25889,0.36087,2.47321,41.50006
5.00000,41.66662,22.30290,0.36232,2.47810,41.66662
5.02000,41.83331,22.11392,0.36377,2.45710,41.83331
5.04000,41.99993,22.24030,0.36522,2.47114,41.99993
5.06000,42.16662,22.27513,0.36667,2.47501,42.16662
5.08000,42.33337,22.23089,0.36812,2.47010,42.33337
5.10000,42.50005,22.21985,0.36957,2.46887,42.50005
5.12000,42.66662,22.32345,0.37101,2.48038,42.66662
5.14000,42.83324,22.32639,0.37246,2.48071,42.83324
5.16000,42.99993,22.44314,0.37391,2.49368,42.99993
5.18000,43.16668,22.57460,0.37536,2.50829,43.16668
5.20000,43.33337,22.32719,0.37681,2.48080,43.33337
5.22000,43.50006,22.53172,0.37826,2.50352,43.50006
5.24000,43.66668,22.62843,0.37971,2.51427,43.66668
5.26000,43.83337,22.57757,0.38116,2.50862,43.83337
5.28000,44.00006,22.74278,0.38261,2.52698,44.00006
5.30000,44.16674,22.85495,0.38406,2.53944,44.16674
5.32000,44.33337,22.66608,0.38551,2.51845,44.33337
5.34000,44.49999,22.71619,0.38696,2.52402,44.49999
5.36000,44.66662,22.70397,0.38841,2.52266,44.66662
5.38000,44.83331,22.59571,0.38985,2.51063,44.83331
5.40000,44.99999,22.64475,0.39130,2.51608,44.99999
5.42000,45.16668,22.92478,0.39275,2.54720,45.16668
5.44000,45.33337,22.79642,0.39420,2.53294,45.33337
5.46000,45.49999,22.83029,0.39565,2.53670,45.49999
5.48000,45.66662,22.91136,0.39710,2.54571,45.66662
5.50000,45.83331,22.92698,0.39855,2.54744,45.83331
5.52000,46.00006,23.01576,0.40000,2.55731,46.00006
5.54000,46.16662,23.03384,0.40145,2.55932,46.16662
5.56000,46.33330,22.93967,0.40290,2.54885,46.33330
5.58000,46.49993,23.04567,0.40435,2.56063,46.49993
5.60000,46.66662,23.21933,0.40580,2.57993,46.66662
5.62000,46.83343,23.09487,0.40725,2.56610,46.83343
5.64000,47.00006,23.05137,0.40870,2.56126,47.00006
5.66000,47.16662,23.11649,0.41014,2.56850,47.16662
5.68000,47.33324,23.10905,0.41159,2.56767,47.33324
5.70000,47.49993,23.06861,0.41304,2.56318,47.49993
5.72000,47.66662,23.16606,0.41449,2.57401,47.66662
5.74000,47.83337,23.08676,0.41594,2.56520,47.83337
5.76000,47.99999,23.29871,0.41739,2.58875,47.99999
5.78000,48.16662,23.63994,0.41884,2.62666,48.16662
5.80000,48.33330,23.61190,0.42029,2.62354,48.33330
5.82000,48.50006,23.69875,0.42174,2.63319,48.50006
5.84000,48.66675,23.51078,0.42319,2.61231,48.66675
5.86000,48.83343,23.35998,0.42464,2.59555,48.83343
5.88000,49.00006,23.56458,0.42609,2.61829,49.00006
5.90000,49.16662,23.64616,0.42754,2.62735,49.16662
5.92000,49.33337,23.56125,0.42899,2.61792,49.33337
5.94000,49.50006,23.66368,0.43044,2.62930,49.50006
5.96000,49.66668,23.59436,0.43188,2.62160,49.66668
5.98000,49.83330,23.46848,0.43333,2.60761,49.83330
6.00000,49.99993,23.63044,0.43478,2.62560,49.99993
6.02000,50.16662,23.67986,0.43623,2.63110,50.16662
6.04000,50.33337,23.69309,0.43768,2.63257,50.33337
6.06000,50.50005,23.82022,0.43913,2.64669,50.50005
6.08000,50.66662,23.86786,0.44058,2.65198,50.66662
6.10000,50.83330,23.71520,0.44203,2.63502,50.83330
6.12000,50.99999,23.80261,0.44348,2.64473,50.99999
6.14000,51.16662,24.01515,0.44493,2.66835,51.16662
6.16000,51.33331,23.87011,0.44638,2.65223,51.33331
6.18000,51.49999,23.87239,0.44783,2.65249,51.49999
6.20000,51.66662,23.91194,0.44927,2.65688,51.66662
6.22000,51.83330,23.93376,0.45072,2.65931,51.83330
6.24000,51.99999,24.05237,0.45217,2.67249,51.99999
6.26000,52.16668,24.28565,0.45362,2.69841,52.16668
6.28000,52.33337,24.26212,0.45507,2.69579,52.33337
6.30000,52.49999,24.23623,0.45652,2.69291,52.49999
6.32000,52.66655,24.28918,0.45797,2.69880,52.66655
6.34000,52.83324,24.25981,0.45942,2.69553,52.83324
6.36000,52.99999,24.34186,0.46087,2.70465,52.99999
6.38000,53.16668,24.56355,0.46232,2.72928,53.16668
6.40000,53.33337,24.62076,0.46377,2.73564,53.33337
6.42000,53.50005,24.56617,0.46522,2.72957,53.50005
6.44000,53.66668,24.58087,0.46667,2.73121,53.66668
6.46000,53.83343,24.42241,0.46812,2.71360,53.83343
6.48000,54.00012,24.60315,0.46957,2.73368,54.00012
6.50000,54.16668,24.73651,0.47101,2.74850,54.16668
6.52000,54.33330,24.69108,0.47246,2.74345,54.33330
6.54000,54.49993,24.70420,0.47391,2.74491,54.49993
6.56000,54.66662,24.69980,0.47536,2.74442,54.66662
6.58000,54.83337,24.54604,0.47681,2.72734,54.83337
6.60000,55.00006,24.62150,0.47826,2.73572,55.00006
6.62000,55.16668,24.62250,0.47971,2.73583,55.16668
6.64000,55.33330,24.69206,0.48116,2.74356,55.33330
6.66000,55.49999,24.88399,0.48261,2.76489,55.49999
6.68000,55.66668,24.91473,0.48406,2.76830,55.66668
6.70000,55.83337,24.72441,0.48551,2.74716,55.83337
6.72000,55.99999,24.80920,0.48696,2.75658,55.99999
6.74000,56.16656,24.93778,0.48840,2.77086,56.16656
6.76000,56.33324,24.98710,0.48985,2.77634,56.33324
6.78000,56.49999,25.07395,0.49130,2.78599,56.49999
6.80000,56.66668,25.14343,0.49275,2.79371,56.66668
6.82000,56.83336,25.03883,0.49420,2.78209,56.83336
6.84000,56.99999,25.13704,0.49565,2.79300,56.99999
6.86000,57.16662,25.29192,0.49710,2.81021,57.16662
6.88000,57.33330,25.21940,0.49855,2.80216,57.33330
6.90000,57.49999,25.30495,0.50000,2.81166,57.49999
6.92000,57.66662,25.40147,0.50145,2.82239,57.66662
6.94000,57.83331,25.32035,0.50290,2.81337,57.83331
6.96000,57.99993,25.42194,0.50435,2.82466,57.99993
6.98000,58.16662,25.45155,0.50580,2.82795,58.16662
7.00000,58.33337,25.37139,0.50725,2.81904,58.33337
7.02000,58.50011,25.57298,0.50870,2.84144,58.50011
7.04000,58.66668,25.69886,0.51015,2.85543,58.66668
7.06000,58.83337,25.60051,0.51159,2.84450,58.83337
7.08000,58.99999,25.77263,0.51304,2.86363,58.99999
7.10000,59.16668,25.90885,0.51449,2.87876,59.16668
7.12000,59.33343,25.73491,0.51594,2.85943,59.33343
7.14000,59.50006,25.67082,0.51739,2.85231,59.50006
7.16000,59.66661,25.68598,0.51884,2.85400,59.66661
7.18000,59.83330,25.69651,0.52029,2.85517,59.83330
7.20000,59.99999,25.99907,0.52174,2.88879,59.99999
7.22000,60.16674,25.97843,0.52319,2.88649,60.16674
7.24000,60.33343,25.92538,0.52464,2.88060,60.33343
7.26000,60.50006,25.86413,0.52609,2.87379,60.50006
7.28000,60.66662,25.91558,0.52754,2.87951,60.66662
7.30000,60.83325,26.01218,0.52898,2.89024,60.83325
7.32000,60.99993,26.27467,0.53043,2.91941,60.99993
7.34000,61.16662,26.39507,0.53188,2.93279,61.16662
7.36000,61.33331,26.21372,0.53333,2.91264,61.33331
7.38000,61.49993,26.16804,0.53478,2.90756,61.49993
7.40000,61.66662,26.12660,0.53623,2.90296,61.66662
7.42000,61.83337,26.17615,0.53768,2.90846,61.83337
7.44000,62.00006,26.25011,0.53913,2.91668,62.00006
7.46000,62.16674,26.44202,0.54058,2.93800,62.16674
7.48000,62.33331,26.45317,0.54203,2.93924,62.33331
7.50000,62.49987,26.49091,0.54348,2.94343,62.49987
7.52000,62.66662,26.54895,0.54493,2.94988,62.66662
7.54000,62.83336,26.45797,0.54638,2.93977,62.83336
7.56000,63.00006,26.64395,0.54783,2.96044,63.00006
7.58000,63.16668,26.78397,0.54928,2.97600,63.16668
7.60000,63.33330,26.79315,0.55072,2.97702,63.33330
7.62000,63.50006,26.74299,0.55217,2.97144,63.50006
7.64000,63.66674,26.61363,0.55362,2.95707,63.66674
7.66000,63.83349,26.63540,0.55507,2.95949,63.83349
7.68000,64.00005,26.85475,0.55652,2.98386,64.00005
7.70000,64.16661,26.87596,0.55797,2.98622,64.16661
7.72000,64.33330,26.74608,0.55942,2.97179,64.33330
7.74000,64.49999,26.89033,0.56087,2.98781,64.49999
7.76000,64.66668,26.94319,0.56232,2.99369,64.66668
7.78000,64.83336,26.95820,0.56377,2.99536,64.83336
7.80000,64.99999,26.99565,0.56522,2.99952,64.99999
7.82000,65.16661,27.19434,0.56667,3.02159,65.16661
7.84000,65.33330,27.22451,0.56812,3.02495,65.33330
7.86000,65.49999,27.29098,0.56957,3.03233,65.49999
7.88000,65.66667,27.32748,0.57101,3.03639,65.66667
7.90000,65.83330,27.34553,0.57246,3.03839,65.83330
7.92000,65.99993,27.54905,0.57391,3.06101,65.99993
7.94000,66.16662,27.57151,0.57536,3.06350,66.16662
7.96000,66.33330,27.26657,0.57681,3.02962,66.33330
7.98000,66.50005,27.35995,0.57826,3.03999,66.50005
8.00000,66.66668,27.31486,0.57971,3.03498,66.66668
8.02000,66.83331,27.33296,0.58116,3.03700,66.83331
8.04000,66.99999,27.62362,0.58261,3.06929,66.99999
8.06000,67.16661,27.78943,0.58406,3.08771,67.16661
8.08000,67.33336,27.64385,0.58551,3.07154,67.33336
8.10000,67.49999,27.58113,0.58696,3.06457,67.49999
8.12000,67.66662,27.70741,0.58841,3.07860,67.66662
8.14000,67.83330,27.55970,0.58985,3.06219,67.83330
8.16000,67.99993,27.71093,0.59130,3.07899,67.99993
8.18000,68.16661,27.88044,0.59275,3.09783,68.16661
8.20000,68.33337,27.91115,0.59420,3.10124,68.33337
8.22000,68.50005,28.18849,0.59565,3.13205,68.50005
8.24000,68.66661,28.25172,0.59710,3.13908,68.66661
8.26000,68.83330,28.09045,0.59855,3.12116,68.83330
8.28000,69.00005,28.09713,0.60000,3.12190,69.00005
8.30000,69.16674,28.22900,0.60145,3.13655,69.16674
8.32000,69.33343,28.19280,0.60290,3.13253,69.33343
8.34000,69.49999,28.17017,0.60435,3.13002,69.49999
8.36000,69.66662,28.27594,0.60580,3.14177,69.66662
8.38000,69.83330,28.15006,0.60725,3.12778,69.83330
8.40000,69.99999,28.40822,0.60870,3.15647,69.99999
8.42000,70.16674,28.64887,0.61015,3.18321,70.16674
8.44000,70.33336,28.58796,0.61159,3.17644,70.33336
8.46000,70.49999,28.69793,0.61304,3.18866,70.49999
8.48000,70.66668,28.71960,0.61449,3.19107,70.66668
8.50000,70.83336,28.61845,0.61594,3.17983,70.83336
8.52000,70.99999,28.81179,0.61739,3.20131,70.99999
8.54000,71.16661,28.87698,0.61884,3.20855,71.16661
8.56000,71.33324,28.69391,0.62029,3.18821,71.33324
8.58000,71.49999,28.76293,0.62174,3.19588,71.49999
8.60000,71.66667,28.78017,0.62319,3.19780,71.66667
8.62000,71.83337,28.69207,0.62464,3.18801,71.83337
8.64000,71.99999,28.72068,0.62609,3.19119,71.99999
8.66000,72.16662,28.96106,0.62754,3.21790,72.16662
8.68000,72.33330,29.12221,0.62899,3.23580,72.33330
8.70000,72.49999,29.03889,0.63043,3.22654,72.49999
8.72000,72.66662,28.91835,0.63188,3.21315,72.66662
8.74000,72.83330,28.84350,0.63333,3.20483,72.83330
8.76000,72.99999,29.23347,0.63478,3.24816,72.99999
8.78000,73.16655,29.36683,0.63623,3.26298,73.16655
8.80000,73.33330,29.14261,0.63768,3.23807,73.33330
8.82000,73.49999,29.11344,0.63913,3.23483,73.49999
8.84000,73.66668,29.35723,0.64058,3.26191,73.66668
8.86000,73.83343,29.42063,0.64203,3.26896,73.83343
8.88000,74.00006,29.46570,0.64348,3.27397,74.00006
8.90000,74.16668,29.45483,0.64493,3.27276,74.16668
8.92000,74.33336,29.27565,0.64638,3.25285,74.33336
8.94000,74.50006,29.48522,0.64783,3.27614,74.50006
8.96000,74.66668,29.76721,0.64928,3.30747,74.66668
8.98000,74.83337,29.65342,0.65072,3.29482,74.83337
9.00000,74.99999,29.61103,0.65217,3.29011,74.99999
9.02000,75.16661,29.69261,0.65362,3.29918,75.16661
9.04000,75.33337,29.64438,0.65507,3.29382,75.33337
9.06000,75.50005,29.83625,0.65652,3.31514,75.50005
9.08000,75.66662,29.92354,0.65797,3.32484,75.66662
9.10000,75.83330,29.88369,0.65942,3.32041,75.83330
9.12000,75.99999,30.06786,0.66087,3.34087,75.99999
9.14000,76.16668,30.08148,0.66232,3.34239,76.16668
9.16000,76.33343,30.09730,0.66377,3.34414,76.33343
9.18000,76.50005,30.10308,0.66522,3.34479,76.50005
9.20000,76.66655,30.41691,0.66667,3.37966,76.66655
9.22000,76.83324,30.37192,0.66812,3.37466,76.83324
9.24000,76.99999,30.25919,0.66957,3.36213,76.99999
9.26000,77.16668,30.13825,0.67101,3.34869,77.16668
9.28000,77.33336,30.18723,0.67246,3.35414,77.33336
9.30000,77.49998,30.38818,0.67391,3.37646,77.49998
9.32000,77.66661,30.40603,0.67536,3.37845,77.66661
9.34000,77.83331,30.44500,0.67681,3.38278,77.83331
9.36000,77.99999,30.54314,0.67826,3.39368,77.99999
9.38000,78.16661,30.55137,0.67971,3.39460,78.16661
9.40000,78.33330,30.39954,0.68116,3.37773,78.33330
9.42000,78.49999,30.59935,0.68261,3.39993,78.49999
9.44000,78.66661,30.63356,0.68406,3.40373,78.66661
9.46000,78.83336,30.67598,0.68551,3.40844,78.83336
9.48000,79.00012,30.83044,0.68696,3.42560,79.00012
9.50000,79.16674,30.94364,0.68841,3.43818,79.16674
9.52000,79.33330,30.91557,0.68985,3.43506,79.33330
9.54000,79.49992,30.90556,0.69130,3.43395,79.49992
9.56000,79.66661,30.70174,0.69275,3.41130,79.66661
9.58000,79.83336,30.75709,0.69420,3.41745,79.83336
9.60000,79.99999,31.03803,0.69565,3.44867,79.99999
9.62000,80.16667,31.11006,0.69710,3.45667,80.16667
9.64000,80.33336,31.17351,0.69855,3.46372,80.33336
9.66000,80.49999,31.23597,0.70000,3.47066,80.49999
9.68000,80.66667,31.41686,0.70145,3.49076,80.66667
9.70000,80.83336,31.27486,0.70290,3.47498,80.83336
9.72000,80.99998,31.29759,0.70435,3.47751,80.99998
9.74000,81.16661,31.34995,0.70580,3.48333,81.16661
9.76000,81.33323,31.21892,0.70725,3.46877,81.33323
9.78000,81.49993,31.46535,0.70869,3.49615,81.49993
9.80000,81.66668,31.67152,0.71015,3.51906,81.66668
9.82000,81.83336,31.46697,0.71159,3.49633,81.83336
9.84000,81.99993,31.43582,0.71304,3.49287,81.99993
9.86000,82.16655,31.54436,0.71449,3.50493,82.16655
9.88000,82.33330,31.59785,0.71594,3.51087,82.33330
9.90000,82.49999,31.77173,0.71739,3.53019,82.49999
9.92000,82.66667,31.74313,0.71884,3.52701,82.66667
9.94000,82.83329,31.65109,0.72029,3.51679,82.83329
9.96000,82.99992,32.00803,0.72174,3.55645,82.99992
9.98000,83.16656,32.11834,0.72319,3.56870,83.16656
10.00000,83.33330,32.07298,0.72464,3.56366,83.33330
10.02000,83.50004,32.00411,0.72609,3.55601,83.50004
10.04000,83.66668,32.09174,0.72754,3.56575,83.66668
10.06000,83.83336,32.12157,0.72899,3.56906,83.83336
10.08000,83.99999,32.24716,0.73043,3.58302,83.99999
10.10000,84.16668,32.31265,0.73188,3.59029,84.16668
10.12000,84.33343,32.27312,0.73333,3.58590,84.33343
10.14000,84.50005,32.52293,0.73478,3.61366,84.50005
10.16000,84.66667,32.56383,0.73623,3.61820,84.66667
10.18000,84.83330,32.33846,0.73768,3.59316,84.83330
10.20000,84.99999,32.32141,0.73913,3.59127,84.99999
10.22000,85.16667,32.50916,0.74058,3.61213,85.16667
10.24000,85.33343,32.49942,0.74203,3.61105,85.33343
10.26000,85.50005,32.62070,0.74348,3.62452,85.50005
10.28000,85.66661,32.65518,0.74493,3.62835,85.66661
10.30000,85.83331,32.59763,0.74638,3.62196,85.83331
10.32000,86.00005,32.70343,0.74783,3.63371,86.00005
10.34000,86.16667,32.85513,0.74928,3.65057,86.16667
10.36000,86.33330,32.85478,0.75072,3.65053,86.33330
10.38000,86.49998,32.99556,0.75217,3.66617,86.49998
10.40000,86.66655,33.01402,0.75362,3.66822,86.66655
10.42000,86.83329,32.88706,0.75507,3.65412,86.83329
10.44000,87.00005,33.12717,0.75652,3.68080,87.00005
10.46000,87.16667,33.16905,0.75797,3.68545,87.16667
10.48000,87.33329,33.10111,0.75942,3.67790,87.33329
10.50000,87.49999,33.26491,0.76087,3.69610,87.49999
10.52000,87.66667,33.22323,0.76232,3.69147,87.66667
10.54000,87.83330,33.07148,0.76377,3.67461,87.83330
10.56000,87.99999,33.22024,0.76522,3.69114,87.99999
10.58000,88.16655,33.46936,0.76667,3.71882,88.16655
10.60000,88.33330,33.43243,0.76812,3.71471,88.33330
10.62000,88.49998,33.47416,0.76957,3.71935,88.49998
10.64000,88.66668,33.59598,0.77101,3.73289,88.66668
10.66000,88.83343,33.66470,0.77246,3.74052,88.83343
10.68000,89.00005,33.79372,0.77391,3.75486,89.00005
10.70000,89.16668,33.80759,0.77536,3.75640,89.16668
10.72000,89.33330,33.74308,0.77681,3.74923,89.33330
10.74000,89.49999,33.71697,0.77826,3.74633,89.49999
10.76000,89.66668,33.81498,0.77971,3.75722,89.66668
10.78000,89.83336,33.72598,0.78116,3.74733,89.83336
10.80000,89.99999,33.87929,0.78261,3.76437,89.99999
10.82000,90.16661,34.04393,0.78406,3.78266,90.16661
10.84000,90.33336,34.00738,0.78551,3.77860,90.33336
10.86000,90.50005,34.13640,0.78696,3.79293,90.50005
10.88000,90.66674,34.24568,0.78841,3.80508,90.66674
10.90000,90.83336,34.14738,0.78986,3.79415,90.83336
10.92000,90.99999,34.21424,0.79130,3.80158,90.99999
10.94000,91.16654,34.45155,0.79275,3.82795,91.16654
10.96000,91.33330,34.40933,0.79420,3.82326,91.33330
10.98000,91.50005,34.45670,0.79565,3.82852,91.50005
11.00000,91.66667,34.48050,0.79710,3.83117,91.66667
11.02000,91.83330,34.48433,0.79855,3.83159,91.83330
11.04000,91.99998,34.60291,0.80000,3.84477,91.99998
11.06000,92.16661,34.49804,0.80145,3.83312,92.16661
11.08000,92.33336,34.38665,0.80290,3.82074,92.33336
11.10000,92.49998,34.60120,0.80435,3.84458,92.49998
11.12000,92.66655,34.88343,0.80580,3.87594,92.66655
11.14000,92.83324,34.74114,0.80725,3.86013,92.83324
11.16000,92.99993,34.84440,0.80870,3.87160,92.99993
11.18000,93.16668,34.79468,0.81015,3.86608,93.16668
11.20000,93.33342,34.74682,0.81159,3.86076,93.33342
11.22000,93.50005,34.92340,0.81304,3.88038,93.50005
11.24000,93.66661,34.89720,0.81449,3.87747,93.66661
11.26000,93.83336,34.99012,0.81594,3.88779,93.83336
11.28000,94.00005,35.13599,0.81739,3.90400,94.00005
11.30000,94.16673,35.20569,0.81884,3.91174,94.16673
11.32000,94.33342,35.32075,0.82029,3.92453,94.33342
11.34000,94.49999,35.34019,0.82174,3.92669,94.49999
11.36000,94.66661,35.35484,0.82319,3.92832,94.66661
11.38000,94.83336,35.38555,0.82464,3.93173,94.83336
11.40000,95.00004,35.40686,0.82609,3.93410,95.00004
11.42000,95.16673,35.47186,0.82754,3.94132,95.16673
11.44000,95.33335,35.56287,0.82899,3.95143,95.33335
11.46000,95.49998,35.57418,0.83043,3.95269,95.49998
11.48000,95.66661,35.74489,0.83188,3.97165,95.66661
11.50000,95.83330,35.73205,0.83333,3.97023,95.83330
11.52000,96.00005,35.73484,0.83478,3.97054,96.00005
11.54000,96.16667,35.79078,0.83623,3.97675,96.16667
11.56000,96.33330,35.80998,0.83768,3.97889,96.33330
11.58000,96.49992,35.84785,0.83913,3.98309,96.49992
11.60000,96.66661,35.93591,0.84058,3.99288,96.66661
11.62000,96.83336,35.80494,0.84203,3.97833,96.83336
11.64000,97.00004,35.92181,0.84348,3.99131,97.00004
11.66000,97.16661,36.12714,0.84493,4.01413,97.16661
11.68000,97.33323,36.18068,0.84638,4.02008,97.33323
11.70000,97.49993,36.24328,0.84783,4.02703,97.49993
11.72000,97.66667,36.31396,0.84928,4.03488,97.66667
11.74000,97.83336,36.28403,0.85072,4.03156,97.83336
11.76000,97.99998,36.43759,0.85217,4.04862,97.99998
11.78000,98.16654,36.38944,0.85362,4.04327,98.16654
11.80000,98.33329,36.47384,0.85507,4.05265,98.33329
11.82000,98.49999,36.40458,0.85652,4.04495,98.49999
11.84000,98.66673,36.56813,0.85797,4.06313,98.66673
11.86000,98.83337,36.58861,0.85942,4.06540,98.83337
11.88000,98.99999,36.77836,0.86087,4.08648,98.99999
11.90000,99.16661,36.84885,0.86232,4.09432,99.16661
11.92000,99.33336,36.66639,0.86377,4.07404,99.33336
11.94000,99.50005,36.77792,0.86522,4.08644,99.50005
11.96000,99.66673,36.73364,0.86667,4.08152,99.66673
11.98000,99.83336,36.78199,0.86812,4.08689,99.83336
12.00000,99.99998,37.07245,0.86957,4.11916,99.99998
12.02000,100.16668,37.16444,0.87101,4.12938,100.16668
12.04000,100.33342,36.94941,0.87246,4.10549,100.33342
12.06000,100.50005,37.15513,0.87391,4.12835,100.50005
12.08000,100.66668,37.25986,0.87536,4.13998,100.66668
12.10000,100.83330,37.05839,0.87681,4.11760,100.83330
12.12000,100.99999,37.29238,0.87826,4.14360,100.99999
12.14000,101.16667,37.48576,0.87971,4.16508,101.16667
12.16000,101.33336,37.37780,0.88116,4.15309,101.33336
12.18000,101.50004,37.46686,0.88261,4.16298,101.50004
12.20000,101.66667,37.66048,0.88406,4.18450,101.66667
12.22000,101.83336,37.49350,0.88551,4.16594,101.83336
12.24000,101.99999,37.43531,0.88696,4.15948,101.99999
12.26000,102.16661,37.63653,0.88841,4.18184,102.16661
12.28000,102.33330,37.70707,0.88985,4.18967,102.33330
12.30000,102.49998,37.93121,0.89130,4.21458,102.49998
12.32000,102.66654,37.90304,0.89275,4.21145,102.66654
12.34000,102.83330,37.72205,0.89420,4.19134,102.83330
12.36000,102.99998,37.92949,0.89565,4.21439,102.99998
12.38000,103.16667,38.02457,0.89710,4.22495,103.16667
12.40000,103.33329,37.93748,0.89855,4.21528,103.33329
12.42000,103.49998,37.97843,0.90000,4.21983,103.49998
12.44000,103.66655,38.06571,0.90145,4.22952,103.66655
12.46000,103.83330,38.15839,0.90290,4.23982,103.83330
12.48000,104.00005,38.28858,0.90435,4.25429,104.00005
12.50000,104.16673,38.33066,0.90580,4.25896,104.16673
12.52000,104.33336,38.31376,0.90725,4.25708,104.33336
12.54000,104.49998,38.41540,0.90870,4.26838,104.49998
12.56000,104.66667,38.54520,0.91014,4.28280,104.66667
12.58000,104.83336,38.46565,0.91159,4.27396,104.83336
12.60000,105.00005,38.58282,0.91304,4.28698,105.00005
12.62000,105.16667,38.54021,0.91449,4.28225,105.16667
12.64000,105.33329,38.41403,0.91594,4.26823,105.33329
12.66000,105.49999,38.63597,0.91739,4.29289,105.49999
12.68000,105.66667,38.69612,0.91884,4.29957,105.66667
12.70000,105.83336,38.63974,0.92029,4.29330,105.83336
12.72000,106.00004,38.79447,0.92174,4.31050,106.00004
12.74000,106.16661,39.00093,0.92319,4.33344,106.16661
12.76000,106.33330,38.93966,0.92464,4.32663,106.33330
12.78000,106.50005,39.05849,0.92609,4.33983,106.50005
12.80000,106.66667,39.04139,0.92754,4.33793,106.66667
12.82000,106.83330,39.04644,0.92899,4.33849,106.83330
12.84000,106.99992,39.19304,0.93043,4.35478,106.99992
12.86000,107.16654,39.30256,0.93188,4.36695,107.16654
12.88000,107.33330,39.17673,0.93333,4.35297,107.33330
12.90000,107.50005,39.23659,0.93478,4.35962,107.50005
12.92000,107.66667,39.36580,0.93623,4.37398,107.66667
12.94000,107.83336,39.18295,0.93768,4.35366,107.83336
12.96000,107.99998,39.29159,0.93913,4.36573,107.99998
12.98000,108.16661,39.44451,0.94058,4.38272,108.16661
13.00000,108.33336,39.46092,0.94203,4.38455,108.33336
13.02000,108.50005,39.62031,0.94348,4.40226,108.50005
13.04000,108.66667,39.68473,0.94493,4.40941,108.66667
13.06000,108.83336,39.63800,0.94638,4.40422,108.83336
13.08000,108.99998,39.71000,0.94783,4.41222,108.99998
13.10000,109.16667,39.91573,0.94928,4.43508,109.16667
13.12000,109.33336,39.91533,0.95072,4.43504,109.33336
13.14000,109.50005,39.96373,0.95217,4.44041,109.50005
13.16000,109.66667,39.99179,0.95362,4.44353,109.66667
13.18000,109.83329,39.97284,0.95507,4.44143,109.83329
13.20000,109.99999,40.09863,0.95652,4.45540,109.99999
13.22000,110.16667,40.25904,0.95797,4.47323,110.16667
13.24000,110.33342,40.30935,0.95942,4.47882,110.33342
13.26000,110.50005,40.33462,0.96087,4.48162,110.50005
13.28000,110.66660,40.22877,0.96232,4.46986,110.66660
13.30000,110.83330,40.19683,0.96377,4.46631,110.83330
13.32000,111.00005,40.28113,0.96522,4.47568,111.00005
13.34000,111.16668,40.55343,0.96667,4.50594,111.16668
13.36000,111.33336,40.53530,0.96812,4.50392,111.33336
13.38000,111.49999,40.55612,0.96957,4.50624,111.49999
13.40000,111.66661,40.49337,0.97101,4.49926,111.66661
13.42000,111.83330,40.65237,0.97246,4.51693,111.83330
13.44000,112.00004,40.87534,0.97391,4.54170,112.00004
13.46000,112.16667,40.92579,0.97536,4.54731,112.16667
13.48000,112.33330,40.83209,0.97681,4.53690,112.33330
13.50000,112.49992,40.93167,0.97826,4.54796,112.49992
13.52000,112.66661,41.09478,0.97971,4.56609,112.66661
13.54000,112.83336,40.97418,0.98116,4.55269,112.83336
13.56000,113.00005,40.90585,0.98261,4.54509,113.00005
13.58000,113.16667,40.99529,0.98406,4.55503,113.16667
13.60000,113.33330,41.02424,0.98551,4.55825,113.33330
13.62000,113.49998,41.11143,0.98696,4.56794,113.49998
13.64000,113.66667,41.22732,0.98841,4.58081,113.66667
13.66000,113.83343,41.10879,0.98986,4.56764,113.83343
13.68000,114.00005,41.31143,0.99130,4.59016,114.00005
13.70000,114.16667,41.52323,0.99275,4.61369,114.16667
13.72000,114.33336,41.48615,0.99420,4.60957,114.33336
13.74000,114.50005,41.50564,0.99565,4.61174,114.50005
13.76000,114.66674,41.46700,0.99710,4.60744,114.66674
13.78000,114.83336,41.62124,0.99855,4.62458,114.83336
13.80000,114.99998,41.79175,1.00000,4.64353,114.99998
13.82000,115.16660,41.68678,1.00145,4.63186,115.16660
13.84000,115.33336,41.62976,1.00290,4.62553,115.33336
13.86000,115.50005,41.83686,1.00435,4.64854,115.50005
13.88000,115.66673,41.88393,1.00580,4.65377,115.66673
13.90000,115.83336,41.75173,1.00725,4.63908,115.83336
13.92000,115.99999,41.81477,1.00870,4.64609,115.99999
13.94000,116.16661,41.94712,1.01014,4.66079,116.16661
13.96000,116.33329,41.88138,1.01159,4.65349,116.33329
13.98000,116.50004,42.14995,1.01304,4.68333,116.50004
14.00000,116.66667,42.23557,1.01449,4.69284,116.66667
14.02000,116.83336,42.28818,1.01594,4.69869,116.83336
14.04000,116.99999,42.39619,1.01739,4.71069,116.99999
14.06000,117.16661,42.55004,1.01884,4.72778,117.16661
14.08000,117.33330,42.43924,1.02029,4.71547,117.33330
14.10000,117.49999,42.53290,1.02174,4.72588,117.49999
14.12000,117.66661,42.51458,1.02319,4.72384,117.66661
14.14000,117.83324,42.46564,1.02464,4.71840,117.83324
14.16000,117.99992,42.56028,1.02609,4.72892,117.99992
14.18000,118.16661,42.65232,1.02754,4.73915,118.16661
14.20000,118.33336,42.58820,1.02899,4.73202,118.33336
14.22000,118.50005,42.65516,1.03044,4.73946,118.50005
14.24000,118.66667,42.82155,1.03188,4.75795,118.66667
14.26000,118.83336,42.81322,1.03333,4.75702,118.83336
14.28000,119.00004,42.92745,1.03478,4.76972,119.00004
14.30000,119.16674,42.89027,1.03623,4.76559,119.16674
14.32000,119.33336,42.85295,1.03768,4.76144,119.33336
14.34000,119.49998,43.00984,1.03913,4.77887,119.49998
14.36000,119.66661,42.97364,1.04058,4.77485,119.66661
14.38000,119.83336,43.09174,1.04203,4.78797,119.83336
14.40000,120.00005,43.20435,1.04348,4.80048,120.00005
14.42000,120.16674,43.30505,1.04493,4.81167,120.16674
14.44000,120.33336,43.25406,1.04638,4.80601,120.33336
14.46000,120.49999,43.34811,1.04783,4.81646,120.49999
14.48000,120.66661,43.50926,1.04927,4.83436,120.66661
14.50000,120.83329,43.55521,1.05072,4.83947,120.83329
14.52000,121.00005,43.77959,1.05217,4.86440,121.00005
14.54000,121.16661,43.88226,1.05362,4.87581,121.16661
14.56000,121.33330,43.71543,1.05507,4.85727,121.33330
14.58000,121.49998,43.77724,1.05652,4.86414,121.49998
14.60000,121.66668,43.79914,1.05797,4.86657,121.66668
14.62000,121.83336,43.60620,1.05942,4.84513,121.83336
14.64000,121.99998,43.86100,1.06087,4.87345,121.99998
14.66000,122.16661,43.84474,1.06232,4.87164,122.16661
14.68000,122.33323,43.83313,1.06377,4.87035,122.33323
14.70000,122.49999,44.02651,1.06522,4.89183,122.49999
14.72000,122.66668,44.08578,1.06667,4.89842,122.66668
14.74000,122.83330,44.18164,1.06812,4.90907,122.83330
14.76000,122.99999,44.37718,1.06957,4.93080,122.99999
14.78000,123.16661,44.41362,1.07101,4.93485,123.16661
14.80000,123.33330,44.15470,1.07246,4.90608,123.33330
14.82000,123.50004,44.35347,1.07391,4.92816,123.50004
14.84000,123.66667,44.47103,1.07536,4.94123,123.66667
14.86000,123.83336,44.46549,1.07681,4.94061,123.83336
14.88000,123.99998,44.54102,1.07826,4.94900,123.99998
14.90000,124.16661,44.52187,1.07971,4.94687,124.16661
14.92000,124.33330,44.59108,1.08116,4.95457,124.33330
14.94000,124.50005,44.71516,1.08261,4.96835,124.50005
14.96000,124.66667,44.73485,1.08406,4.97054,124.66667
14.98000,124.83336,44.60078,1.08551,4.95564,124.83336
15.00000,124.99998,44.68689,1.08696,4.96521,124.99998
15.02000,125.16660,44.65021,1.08841,4.96113,125.16660
15.04000,125.33336,44.72402,1.08986,4.96934,125.33336
15.06000,125.50004,44.87327,1.09130,4.98592,125.50004
15.08000,125.66666,44.95595,1.09275,4.99511,125.66666
15.10000,125.83329,44.93122,1.09420,4.99236,125.83329
15.12000,125.99997,45.08448,1.09565,5.00939,125.99997
15.14000,126.16660,45.13934,1.09710,5.01548,126.16660
15.16000,126.33336,45.35619,1.09855,5.03958,126.33336
15.18000,126.50005,45.44964,1.10000,5.04996,126.50005
15.20000,126.66660,45.42550,1.10145,5.04728,126.66660
15.22000,126.83329,45.28570,1.10290,5.03174,126.83329
15.24000,127.00004,45.34673,1.10435,5.03853,127.00004
15.26000,127.16666,45.52140,1.10580,5.05793,127.16666
15.28000,127.33336,45.48633,1.10725,5.05404,127.33336
15.30000,127.49991,45.71283,1.10869,5.07920,127.49991
15.32000,127.66654,45.77200,1.11014,5.08578,127.66654
15.34000,127.83323,45.70230,1.11159,5.07803,127.83323
15.36000,128.00003,45.85928,1.11304,5.09548,128.00003
15.38000,128.16672,45.95485,1.11449,5.10609,128.16672
15.40000,128.33335,45.90822,1.11594,5.10091,128.33335
15.42000,128.50004,45.88696,1.11739,5.09855,128.50004
15.44000,128.66667,46.02416,1.11884,5.11380,128.66667
15.46000,128.83342,46.23542,1.12029,5.13727,128.83342
15.48000,129.00010,46.22827,1.12174,5.13647,129.00010
15.50000,129.16672,46.16670,1.12319,5.12963,129.16672
15.52000,129.33329,46.20745,1.12464,5.13416,129.33329
15.54000,129.49998,46.29004,1.12609,5.14334,129.49998
15.56000,129.66667,46.34543,1.12754,5.14949,129.66667
15.58000,129.83342,46.21029,1.12899,5.13448,129.83342
15.60000,130.00011,46.28915,1.13044,5.14324,130.00011
15.62000,130.16666,46.43223,1.13188,5.15914,130.16666
15.64000,130.33330,46.50815,1.13333,5.16757,130.33330
15.66000,130.49997,46.69551,1.13478,5.18839,130.49997
15.68000,130.66660,46.64065,1.13623,5.18229,130.66660
15.70000,130.83328,46.61689,1.13768,5.17965,130.83328
15.72000,130.99998,46.57717,1.13913,5.17524,130.99998
15.74000,131.16661,46.68346,1.14058,5.18705,131.16661
15.76000,131.33329,46.74067,1.14203,5.19341,131.33329
15.78000,131.49998,47.11357,1.14348,5.23484,131.49998
15.80000,131.66666,47.11068,1.14493,5.23452,131.66666
15.82000,131.83336,46.91887,1.14638,5.21321,131.83336
15.84000,131.99999,46.94115,1.14783,5.21568,131.99999
15.86000,132.16654,47.07581,1.14927,5.23065,132.16654
15.88000,132.33324,47.17309,1.15072,5.24145,132.33324
15.90000,132.49998,47.26081,1.15217,5.25120,132.49998
15.92000,132.66660,47.25112,1.15362,5.25012,132.66660
15.94000,132.83329,47.34903,1.15507,5.26100,132.83329
15.96000,132.99991,47.36730,1.15652,5.26303,132.99991
15.98000,133.16660,47.40908,1.15797,5.26768,133.16660
16.00000,133.33336,47.47428,1.15942,5.27492,133.33336
16.02000,133.50010,47.73080,1.16087,5.30342,133.50010
16.04000,133.66672,47.73389,1.16232,5.30376,133.66672
16.06000,133.83329,47.50690,1.16377,5.27854,133.83329
16.08000,133.99998,47.85438,1.16522,5.31715,133.99998
16.10000,134.16666,48.01671,1.16667,5.33519,134.16666
16.12000,134.33342,47.72546,1.16812,5.30283,134.33342
16.14000,134.50004,47.89215,1.16957,5.32135,134.50004
16.16000,134.66661,47.83048,1.17101,5.31450,134.66661
16.18000,134.83330,47.87838,1.17246,5.31982,134.83330
16.20000,134.99998,47.91561,1.17391,5.32396,134.99998
16.22000,135.16666,47.88220,1.17536,5.32024,135.16666
16.24000,135.33342,47.86383,1.17681,5.31820,135.33342
16.26000,135.50005,48.04791,1.17826,5.33866,135.50005
16.28000,135.66661,48.19231,1.17971,5.35470,135.66661
16.30000,135.83335,48.18849,1.18116,5.35428,135.83335
16.32000,135.99998,48.21695,1.18261,5.35744,135.99998
16.34000,136.16666,48.26686,1.18406,5.36298,136.16666
16.36000,136.33335,48.29360,1.18551,5.36596,136.33335
16.38000,136.49997,48.41724,1.18696,5.37969,136.49997
16.40000,136.66660,48.37629,1.18841,5.37514,136.66660
16.42000,136.83336,48.24859,1.18986,5.36095,136.83336
16.44000,137.00004,48.47842,1.19130,5.38649,137.00004
16.46000,137.16667,48.53489,1.19275,5.39277,137.16667
16.48000,137.33329,48.52774,1.19420,5.39197,137.33329
16.50000,137.49992,48.55370,1.19565,5.39486,137.49992
16.52000,137.66654,35.16229,1.19710,3.90692,137.66654
16.54000,137.83336,10.49665,1.19855,1.16629,137.83336
16.56000,138.00004,-0.39566,1.20000,-0.04396,138.00004
16.58000,138.16667,-1.98376,1.20145,-0.22042,138.16667
16.60000,138.33336,-0.91575,1.20290,-0.10175,138.33336
16.62000,138.50003,-0.08146,1.20435,-0.00905,138.50003
16.64000,138.66673,0.21635,1.20580,0.02404,138.66673
16.66000,138.83342,0.09962,1.20725,0.01107,138.83342
16.68000,139.00004,0.19291,1.20870,0.02143,139.00004
16.70000,139.16673,0.08140,1.21015,0.00904,139.16673
16.72000,139.33335,0.11687,1.21159,0.01299,139.33335
16.74000,139.50004,0.29200,1.21304,0.03244,139.50004
16.76000,139.66672,0.24684,1.21449,0.02743,139.66672
16.78000,139.83342,0.01030,1.21594,0.00114,139.83342
16.80000,140.00005,0.03470,1.21739,0.00386,140.00005
16.82000,140.16667,0.09242,1.21884,0.01027,140.16667
16.84000,140.33335,0.07866,1.22029,0.00874,140.33335
16.86000,140.50004,0.06355,1.22174,0.00706,140.50004
16.88000,140.66666,0.06614,1.22319,0.00735,140.66666
16.90000,140.83335,0.13136,1.22464,0.01460,140.83335
16.92000,140.99992,0.23790,1.22609,0.02643,140.99992
16.94000,141.16654,0.11224,1.22754,0.01247,141.16654
16.96000,141.33330,-0.13451,1.22899,-0.01495,141.33330
16.98000,141.50004,-0.04174,1.23044,-0.00464,141.50004
17.00000,141.66673,0.06147,1.23188,0.00683,141.66673
17.02000,141.83329,-0.03265,1.23333,-0.00363,141.83329
17.04000,141.99992,0.00058,1.23478,0.00006,141.99992
17.06000,142.16661,0.19627,1.23623,0.02181,142.16661
17.08000,142.33336,0.06805,1.23768,0.00756,142.33336
17.10000,142.50005,0.18569,1.23913,0.02063,142.50005
17.12000,142.66667,0.26778,1.24058,0.02975,142.66667
17.14000,142.83329,0.06788,1.24203,0.00754,142.83329
17.16000,142.99998,0.18331,1.24348,0.02037,142.99998
17.18000,143.16666,0.20400,1.24493,0.02267,143.16666
17.20000,143.33342,0.03012,1.24638,0.00335,143.33342
17.22000,143.50004,0.06585,1.24783,0.00732,143.50004
17.24000,143.66659,0.20467,1.24927,0.02274,143.66659
17.26000,143.83336,0.03068,1.25072,0.00341,143.83336
17.28000,144.00004,0.05338,1.25217,0.00593,144.00004
17.30000,144.16672,0.00837,1.25362,0.00093,144.16672
17.32000,144.33335,-0.04159,1.25507,-0.00462,144.33335
17.34000,144.49998,0.33457,1.25652,0.03717,144.49998
17.36000,144.66654,0.52293,1.25797,0.05810,144.66654
17.38000,144.83330,0.26107,1.25942,0.02901,144.83330
17.40000,145.00004,0.24204,1.26087,0.02689,145.00004
17.42000,145.16667,0.14030,1.26232,0.01559,145.16667
17.44000,145.33335,-0.03716,1.26377,-0.00413,145.33335
17.46000,145.49998,0.09568,1.26522,0.01063,145.49998
17.48000,145.66660,0.23697,1.26667,0.02633,145.66660
17.50000,145.83336,0.20347,1.26812,0.02261,145.83336
17.52000,146.00004,0.08679,1.26957,0.00964,146.00004
17.54000,146.16667,-0.00993,1.27101,-0.00110,146.16667
17.56000,146.33330,0.00710,1.27246,0.00079,146.33330
17.58000,146.49997,0.19090,1.27391,0.02121,146.49997
17.60000,146.66666,0.10357,1.27536,0.01151,146.66666
17.62000,146.83335,0.01121,1.27681,0.00125,146.83335
17.64000,147.00005,0.18022,1.27826,0.02002,147.00005
17.66000,147.16660,0.19649,1.27971,0.02183,147.16660
17.68000,147.33324,0.08346,1.28116,0.00927,147.33324
17.70000,147.49992,0.16323,1.28261,0.01814,147.49992
17.72000,147.66661,0.08512,1.28406,0.00946,147.66661
17.74000,147.83335,0.00511,1.28551,0.00057,147.83335
17.76000,148.00005,0.06886,1.28696,0.00765,148.00005
17.78000,148.16660,0.20851,1.28841,0.02317,148.16660
17.80000,148.33330,0.11077,1.28985,0.01231,148.33330
17.82000,148.50005,0.29607,1.29130,0.03290,148.50005
17.84000,148.66672,0.25223,1.29275,0.02803,148.66672
17.86000,148.83341,0.05397,1.29420,0.00600,148.83341
17.88000,148.99998,0.07511,1.29565,0.00835,148.99998
17.90000,149.16660,0.27645,1.29710,0.03072,149.16660
17.92000,149.33336,0.06796,1.29855,0.00755,149.33336
17.94000,149.50004,0.12970,1.30000,0.01441,149.50004
17.96000,149.66667,0.13869,1.30145,0.01541,149.66667
17.98000,149.83329,0.01790,1.30290,0.00199,149.83329
18.00000,149.99998,0.04640,1.30435,0.00516,149.99998
18.02000,150.16660,0.34738,1.30580,0.03860,150.16660
18.04000,150.33342,0.17422,1.30725,0.01936,150.33342
18.04400,150.36672,0.18253,1.30754,0.02028,150.36672